Workbook

Sheet 202412
A1: 序号 | B1: 计薪 周期 | C1: 工号 | D1: 姓名 | E1: 身份证号 | F1: 劳动合同起始日期 | G1: 劳动合同结束日期 | H1: 离职日期 | I1: 社保缴纳地 | J1: 星级费用 | K1: 考核费用 | L1: OKR费用 | M1: 量化费用 | N1: 专项费用 | AA1: 当月税前工资合计 | AB1: 社保基数(个人) | AC1: 养老保险(个人) | AD1: 医疗保险(个人) | AE1: 失业保险(个人) | AF1: 公积金基数(个人) | AG1: 住房公积金(个人) | AH1: 员工五险一金合计 | AI1: 本月个人所得税-系统导出 | AJ1: 税后增加 | AK1: 税后扣减 | AL1: 员工实发合计 | AM1: 社保基数 | AN1: 公积金基数 | AO1: 养老缴费 | AP1: 医疗缴费 | AQ1: 失业保险 | AR1: 工伤保险 | AS1: 生育保险 | AT1: 公积金 | AU1: 残保金 | AV1: 企业五险一金合计 | AW1: 工会费 | AX1: 代收付合计 | AY1: 备注 | AZ1: 上月垫付 | BA1: 社保备注 | BB1: 外包服务费 | BC1: 税前项合计 | BD1: 增值税 | BE1: 总计
A2: NO. | B2: Salary Cycle | C2: Employee No. | D2: Name | E2: ID No. | F2: Contract Starting Date | G2: Contract Expiry Date | H2: Exit Date | I2: Social Insurance City | J2: Contract Salary | K2: Assessment fees | M2: Quantifying costs | N2: 支局专项 | O2: 1+1激励 | P2: 体检费 | Q2: 通信费 | R2: 高温费及清凉饮料费 （6-9月） | S2: 伙食补贴 | T2: 独生子女奖励 | U2: 保险费 | V2: 其他费用 | W2: 补发费用 | X2: 劳防用品 | Y2: 保障补差 | Z2: 其他扣款 | AA2: Pre-tax Total | AB2: Social Insurance Base | AC2: Pension Employee | AD2: Medical Employee | AE2: Umemployment Employee | AF2: Housing Fund Base | AG2: Housing Fund Employee | AH2: Total Amount of Social Insurance(EE) | AI2: Personal Income Tax | AJ2: Increase After-tax payment | AK2: Reduction After-tax payment | AL2: After-tax total Income | AM2: Social Insurance Base | AN2: Housing Fund Base | AO2: Pension Employer | AP2: Medical Employer | AQ2: Umemployment Employer | AR2: Injury Employer | AS2: Maternity Insurance Employer | AT2: Housing Fund Employer | AU2: Disabled people&Back pay Fund | AV2: Total Amount of Social Insurance(ER) | AW2: Union Fee | AX2: Payment Total | BA2: Social Security remark | BB2: Service Fee | BC2: Total | BD2: VAT | BE2: Subtotal
A3: =ROW()-2 -> 1 | B3: 2412 | C3: WB016994 | D3: 王邹强 | E3: 310108198909220554 | F3: 45444 | G3: 45808 | I3: 上海 | J3: 1300 | K3: 4406.4 | L3: 5680 | M3: 1224 | P3: 0 | S3: 630 | X3: 150 | Y3: 0 | AA3: =SUM(J3:Z3) -> 13390.4 | AB3: 8707 | AC3: 696.56 | AD3: 174.14 | AE3: 43.54 | AF3: 8707 | AG3: =ROUND(AF3*7%,0) -> 609 | AH3: =AC3+AD3+AE3+AG3 -> 1523.24 | AL3: =AA3-AH3-AI3 -> 11867.16 | AM3: 8707 | AN3: 8707 | AO3: =ROUND(AM3*16%,2) -> 1393.12 | AP3: 783.64 | AQ3: =ROUND(AM3*0.5%,2) -> 43.54 | AR3: =ROUND(AM3*0.256%,2) -> 22.29 | AT3: =ROUND(AN3*7%,0) -> 609 | AU3: =ROUND(IF(AM3<24366,AM3*1.5%,24366*1.5%),2) -> 130.61 | AV3: =SUM(AO3:AU3) -> 2982.2 | AW3: 252 | AX3: =AV3+AA3+AJ3-AK3+AW3 -> 16624.6 | BB3: 255 | BC3: =ROUND(AX3+BB3+AZ3,2) -> 16879.6 | BD3: =ROUND(BC3*6%,2) -> 1012.78 | BE3: =ROUND(SUM(BC3:BD3),2) -> 17892.38
A4: =ROW()-2 -> 2 | B4: 2412 | C4: WB022665 | D4: 熊伟 | E4: 310109198905074533 | F4: 45444 | G4: 45808 | I4: 上海 | J4: 1030 | K4: 1117.2 | L4: 0 | M4: 673.32 | P4: 0 | S4: 630 | X4: 150 | Y4: 1424.72 | AA4: =SUM(J4:Z4) -> 5025.24 | AB4: 8888 | AC4: 711.04 | AD4: 177.76 | AE4: 44.44 | AF4: 8888 | AG4: =ROUND(AF4*7%,0) -> 622 | AH4: =AC4+AD4+AE4+AG4 -> 1555.24 | AL4: =AA4-AH4-AI4 -> 3470 | AM4: 8888 | AN4: 8888 | AO4: =ROUND(AM4*16%,2) -> 1422.08 | AP4: =ROUND(AM4*9%,2) -> 799.92 | AQ4: =ROUND(AM4*0.5%,2) -> 44.44 | AR4: =ROUND(AM4*0.256%,2) -> 22.75 | AT4: =ROUND(AN4*7%,0) -> 622 | AU4: =ROUND(IF(AM4<24366,AM4*1.5%,24366*1.5%),2) -> 133.32 | AV4: =SUM(AO4:AU4) -> 3044.51 | AW4: 85 | AX4: =AV4+AA4+AJ4-AK4+AW4 -> 8154.75 | BB4: 255 | BC4: =ROUND(AX4+BB4+AZ4,2) -> 8409.75 | BD4: =ROUND(BC4*6%,2) -> 504.59 | BE4: =ROUND(SUM(BC4:BD4),2) -> 8914.34
A5: =ROW()-2 -> 3 | B5: 2412 | C5: WB016995 | D5: 杭亮 | E5: 310110198004027057 | F5: 45444 | G5: 45808 | I5: 上海 | J5: 1030 | K5: 3084.48 | L5: 5476 | M5: 765.54 | P5: 0 | S5: 630 | X5: 150 | Y5: 0 | AA5: =SUM(J5:Z5) -> 11136.02 | AB5: 9226 | AC5: 738.08 | AD5: 184.52 | AE5: 46.13 | AF5: 9226 | AG5: =ROUND(AF5*7%,0) -> 646 | AH5: =AC5+AD5+AE5+AG5 -> 1614.73 | AL5: =AA5-AH5-AI5 -> 9521.29 | AM5: 9226 | AN5: 9226 | AO5: =ROUND(AM5*16%,2) -> 1476.16 | AP5: =ROUND(AM5*9%,2) -> 830.34 | AQ5: =ROUND(AM5*0.5%,2) -> 46.13 | AR5: =ROUND(AM5*0.256%,2) -> 23.62 | AT5: =ROUND(AN5*7%,0) -> 646 | AU5: =ROUND(IF(AM5<24366,AM5*1.5%,24366*1.5%),2) -> 138.39 | AV5: =SUM(AO5:AU5) -> 3160.64 | AW5: 207 | AX5: =AV5+AA5+AJ5-AK5+AW5 -> 14503.66 | BB5: 255 | BC5: =ROUND(AX5+BB5+AZ5,2) -> 14758.66 | BD5: =ROUND(BC5*6%,2) -> 885.52 | BE5: =ROUND(SUM(BC5:BD5),2) -> 15644.18
A6: =ROW()-2 -> 4 | B6: 2412 | C6: WB007082 | D6: 朱春红 | E6: 310230197703304160 | F6: 45444 | G6: 45808 | I6: 上海 | J6: 1030 | K6: 3190.2 | L6: 6170 | M6: 2240.64 | P6: 0 | S6: 630 | X6: 150 | Y6: 0 | AA6: =SUM(J6:Z6) -> 13410.84 | AB6: 10979 | AC6: 878.32 | AD6: 219.58 | AE6: 54.9 | AF6: 10979 | AG6: =ROUND(AF6*7%,0) -> 769 | AH6: =AC6+AD6+AE6+AG6 -> 1921.8 | AL6: =AA6-AH6-AI6 -> 11489.04 | AM6: 10979 | AN6: 10979 | AO6: =ROUND(AM6*16%,2) -> 1756.64 | AP6: 988.12 | AQ6: =ROUND(AM6*0.5%,2) -> 54.9 | AR6: =ROUND(AM6*0.256%,2) -> 28.11 | AT6: =ROUND(AN6*7%,0) -> 769 | AU6: =ROUND(IF(AM6<24366,AM6*1.5%,24366*1.5%),2) -> 164.69 | AV6: =SUM(AO6:AU6) -> 3761.46 | AW6: 253 | AX6: =AV6+AA6+AJ6-AK6+AW6 -> 17425.3 | BB6: 255 | BC6: =ROUND(AX6+BB6+AZ6,2) -> 17680.3 | BD6: =ROUND(BC6*6%,2) -> 1060.82 | BE6: =ROUND(SUM(BC6:BD6),2) -> 18741.12
A7: =ROW()-2 -> 5 | B7: 2412 | C7: WB017012 | D7: 王一峰 | E7: 310230198106182913 | F7: 45444 | G7: 45808 | I7: 上海 | J7: 1030 | K7: 3322.8 | L7: 15000 | M7: 3030.75 | P7: 0 | S7: 630 | X7: 150 | Y7: 0 | AA7: =SUM(J7:Z7) -> 23163.55 | AB7: 16443 | AC7: 1315.44 | AD7: 328.86 | AE7: 82.22 | AF7: 16443 | AG7: =ROUND(AF7*7%,0) -> 1151 | AH7: =AC7+AD7+AE7+AG7 -> 2877.52 | AL7: =AA7-AH7-AI7 -> 20286.03 | AM7: 16443 | AN7: 16443 | AO7: =ROUND(AM7*16%,2) -> 2630.88 | AP7: 1479.88 | AQ7: =ROUND(AM7*0.5%,2) -> 82.22 | AR7: =ROUND(AM7*0.256%,2) -> 42.09 | AT7: =ROUND(AN7*7%,0) -> 1151 | AU7: =ROUND(IF(AM7<24366,AM7*1.5%,24366*1.5%),2) -> 246.65 | AV7: =SUM(AO7:AU7) -> 5632.72 | AW7: 448 | AX7: =AV7+AA7+AJ7-AK7+AW7 -> 29244.27 | BB7: 255 | BC7: =ROUND(AX7+BB7+AZ7,2) -> 29499.27 | BD7: =ROUND(BC7*6%,2) -> 1769.96 | BE7: =ROUND(SUM(BC7:BD7),2) -> 31269.23
A8: =ROW()-2 -> 6 | B8: 2412 | C8: WB019180 | D8: 王偲 | E8: 310109198908200531 | F8: 45444 | G8: 45808 | I8: 上海 | J8: 1030 | K8: 3151.2 | L8: 10252 | M8: 1862.16 | P8: 0 | S8: 630 | X8: 150 | Y8: 0 | AA8: =SUM(J8:Z8) -> 17075.36 | AB8: 8261 | AC8: 660.88 | AD8: 165.22 | AE8: 41.31 | AF8: 8261 | AG8: =ROUND(AF8*7%,0) -> 578 | AH8: =AC8+AD8+AE8+AG8 -> 1445.41 | AL8: =AA8-AH8-AI8 -> 15629.95 | AM8: 8261 | AN8: 8261 | AO8: =ROUND(AM8*16%,2) -> 1321.76 | AP8: 743.5 | AQ8: =ROUND(AM8*0.5%,2) -> 41.31 | AR8: =ROUND(AM8*0.256%,2) -> 21.15 | AT8: =ROUND(AN8*7%,0) -> 578 | AU8: =ROUND(IF(AM8<24366,AM8*1.5%,24366*1.5%),2) -> 123.92 | AV8: =SUM(AO8:AU8) -> 2829.64 | AW8: 326 | AX8: =AV8+AA8+AJ8-AK8+AW8 -> 20231 | BB8: 255 | BC8: =ROUND(AX8+BB8+AZ8,2) -> 20486 | BD8: =ROUND(BC8*6%,2) -> 1229.16 | BE8: =ROUND(SUM(BC8:BD8),2) -> 21715.16
A9: =ROW()-2 -> 7 | B9: 2412 | C9: WB024266 | D9: 王凤凌 | E9: 31011019870909564X | F9: 45444 | G9: 45808 | I9: 上海 | J9: 1030 | K9: 1428 | L9: 3901 | M9: 541.74 | P9: 0 | S9: 630 | X9: 150 | Y9: 0 | AA9: =SUM(J9:Z9) -> 7680.74 | AB9: 7384 | AC9: 590.72 | AD9: 147.68 | AE9: 36.92 | AF9: 4686 | AG9: =ROUND(AF9*7%,0) -> 328 | AH9: =AC9+AD9+AE9+AG9 -> 1103.32 | AL9: =AA9-AH9-AI9 -> 6577.42 | AM9: 7384 | AN9: 4686 | AO9: =ROUND(AM9*16%,2) -> 1181.44 | AP9: =ROUND(AM9*9%,2) -> 664.56 | AQ9: =ROUND(AM9*0.5%,2) -> 36.92 | AR9: =ROUND(AM9*0.256%,2) -> 18.9 | AT9: =ROUND(AN9*7%,0) -> 328 | AU9: =ROUND(IF(AM9<24366,AM9*1.5%,24366*1.5%),2) -> 110.76 | AV9: =SUM(AO9:AU9) -> 2340.58 | AW9: 138 | AX9: =AV9+AA9+AJ9-AK9+AW9 -> 10159.32 | BB9: 255 | BC9: =ROUND(AX9+BB9+AZ9,2) -> 10414.32 | BD9: =ROUND(BC9*6%,2) -> 624.86 | BE9: =ROUND(SUM(BC9:BD9),2) -> 11039.18
A10: =ROW()-2 -> 8 | B10: 2412 | C10: WB033751 | D10: 高雄飞 | E10: 310101198402231014 | F10: 45444 | G10: 45808 | I10: 上海 | J10: 1300 | K10: 2834.48 | L10: 0 | M10: 204.9 | P10: 0 | S10: 630 | X10: 150 | Y10: 0.14 | AA10: =SUM(J10:Z10) -> 5119.52 | AB10: 9424 | AC10: 753.92 | AD10: 188.48 | AE10: 47.12 | AF10: 9424 | AG10: =ROUND(AF10*7%,0) -> 660 | AH10: =AC10+AD10+AE10+AG10 -> 1649.52 | AL10: =AA10-AH10-AI10 -> 3470 | AM10: 9424 | AN10: 9424 | AO10: =ROUND(AM10*16%,2) -> 1507.84 | AP10: =ROUND(AM10*9%,2) -> 848.16 | AQ10: =ROUND(AM10*0.5%,2) -> 47.12 | AR10: =ROUND(AM10*0.256%,2) -> 24.13 | AT10: =ROUND(AN10*7%,0) -> 660 | AU10: =ROUND(IF(AM10<24366,AM10*1.5%,24366*1.5%),2) -> 141.36 | AV10: =SUM(AO10:AU10) -> 3228.61 | AW10: 87 | AX10: =AV10+AA10+AJ10-AK10+AW10 -> 8435.13 | BB10: 255 | BC10: =ROUND(AX10+BB10+AZ10,2) -> 8690.13 | BD10: =ROUND(BC10*6%,2) -> 521.41 | BE10: =ROUND(SUM(BC10:BD10),2) -> 9211.54
A11: =ROW()-2 -> 9 | B11: 2412 | C11: WB017080 | D11: 季华 | E11: 310115198609170130 | F11: 45444 | G11: 45808 | I11: 上海 | J11: 1300 | K11: 4956 | L11: 12055 | M11: 698.88 | P11: 0 | S11: 630 | X11: 150 | Y11: 0 | AA11: =SUM(J11:Z11) -> 19789.88 | AB11: 10475 | AC11: 838 | AD11: 209.5 | AE11: 52.38 | AF11: 10475 | AG11: =ROUND(AF11*7%,0) -> 733 | AH11: =AC11+AD11+AE11+AG11 -> 1832.88 | AL11: =AA11-AH11-AI11 -> 17957 | AM11: 10475 | AN11: 10475 | AO11: =ROUND(AM11*16%,2) -> 1676 | AP11: 942.76 | AQ11: =ROUND(AM11*0.5%,2) -> 52.38 | AR11: =ROUND(AM11*0.256%,2) -> 26.82 | AT11: =ROUND(AN11*7%,0) -> 733 | AU11: =ROUND(IF(AM11<24366,AM11*1.5%,24366*1.5%),2) -> 157.13 | AV11: =SUM(AO11:AU11) -> 3588.09 | AW11: 380 | AX11: =AV11+AA11+AJ11-AK11+AW11 -> 23757.97 | BB11: 255 | BC11: =ROUND(AX11+BB11+AZ11,2) -> 24012.97 | BD11: =ROUND(BC11*6%,2) -> 1440.78 | BE11: =ROUND(SUM(BC11:BD11),2) -> 25453.75
A12: =ROW()-2 -> 10 | B12: 2412 | C12: WB017076 | D12: 杨晓燕 | E12: 34222519770913404X | F12: 45444 | G12: 45808 | I12: 上海 | J12: 1030 | K12: 2130 | L12: 9480 | M12: 2105.97 | P12: 0 | S12: 630 | X12: 150 | Y12: 0 | AA12: =SUM(J12:Z12) -> 15525.97 | AB12: 8472 | AC12: 677.76 | AD12: 169.44 | AE12: 42.36 | AF12: 8472 | AG12: =ROUND(AF12*7%,0) -> 593 | AH12: =AC12+AD12+AE12+AG12 -> 1482.56 | AL12: =AA12-AH12-AI12 -> 14043.41 | AM12: 8472 | AN12: 8472 | AO12: =ROUND(AM12*16%,2) -> 1355.52 | AP12: =ROUND(AM12*9%,2) -> 762.48 | AQ12: =ROUND(AM12*0.5%,2) -> 42.36 | AR12: =ROUND(AM12*0.256%,2) -> 21.69 | AT12: =ROUND(AN12*7%,0) -> 593 | AU12: =ROUND(IF(AM12<24366,AM12*1.5%,24366*1.5%),2) -> 127.08 | AV12: =SUM(AO12:AU12) -> 2902.13 | AW12: 295 | AX12: =AV12+AA12+AJ12-AK12+AW12 -> 18723.1 | BB12: 255 | BC12: =ROUND(AX12+BB12+AZ12,2) -> 18978.1 | BD12: =ROUND(BC12*6%,2) -> 1138.69 | BE12: =ROUND(SUM(BC12:BD12),2) -> 20116.79
A13: =ROW()-2 -> 11 | B13: 2412 | C13: WB025472 | D13: 孟浩杰 | E13: 510108198209090637 | F13: 45444 | G13: 45808 | I13: 上海 | J13: 1300 | K13: 4057.2 | L13: 10030 | M13: 1590.54 | P13: 0 | S13: 630 | X13: 150 | Y13: 0 | AA13: =SUM(J13:Z13) -> 17757.74 | AB13: 9241 | AC13: 739.28 | AD13: 184.82 | AE13: 46.21 | AF13: 9241 | AG13: =ROUND(AF13*7%,0) -> 647 | AH13: =AC13+AD13+AE13+AG13 -> 1617.31 | AL13: =AA13-AH13-AI13 -> 16140.43 | AM13: 9241 | AN13: 9241 | AO13: =ROUND(AM13*16%,2) -> 1478.56 | AP13: 831.7 | AQ13: =ROUND(AM13*0.5%,2) -> 46.21 | AR13: =ROUND(AM13*0.256%,2) -> 23.66 | AT13: =ROUND(AN13*7%,0) -> 647 | AU13: =ROUND(IF(AM13<24366,AM13*1.5%,24366*1.5%),2) -> 138.62 | AV13: =SUM(AO13:AU13) -> 3165.75 | AW13: 340 | AX13: =AV13+AA13+AJ13-AK13+AW13 -> 21263.49 | BB13: 255 | BC13: =ROUND(AX13+BB13+AZ13,2) -> 21518.49 | BD13: =ROUND(BC13*6%,2) -> 1291.11 | BE13: =ROUND(SUM(BC13:BD13),2) -> 22809.6
A14: =ROW()-2 -> 12 | B14: 2412 | C14: WB021004 | D14: 周雨薇 | E14: 310104199212304829 | F14: 45444 | G14: 45808 | I14: 上海 | J14: 1030 | K14: 1680 | L14: 2505 | M14: 1253.82 | P14: 0 | S14: 630 | X14: 150 | Y14: 0 | AA14: =SUM(J14:Z14) -> 7248.82 | AB14: 7384 | AC14: 590.72 | AD14: 147.68 | AE14: 36.92 | AF14: 6830 | AG14: =ROUND(AF14*7%,0) -> 478 | AH14: =AC14+AD14+AE14+AG14 -> 1253.32 | AL14: =AA14-AH14-AI14 -> 5995.5 | AM14: 7384 | AN14: 6830 | AO14: =ROUND(AM14*16%,2) -> 1181.44 | AP14: =ROUND(AM14*9%,2) -> 664.56 | AQ14: =ROUND(AM14*0.5%,2) -> 36.92 | AR14: =ROUND(AM14*0.256%,2) -> 18.9 | AT14: =ROUND(AN14*7%,0) -> 478 | AU14: =ROUND(IF(AM14<24366,AM14*1.5%,24366*1.5%),2) -> 110.76 | AV14: =SUM(AO14:AU14) -> 2490.58 | AW14: 129 | AX14: =AV14+AA14+AJ14-AK14+AW14 -> 9868.4 | BB14: 255 | BC14: =ROUND(AX14+BB14+AZ14,2) -> 10123.4 | BD14: =ROUND(BC14*6%,2) -> 607.4 | BE14: =ROUND(SUM(BC14:BD14),2) -> 10730.8
A15: =ROW()-2 -> 13 | B15: 2412 | C15: WB017081 | D15: 王姗姗 | E15: 34112519880604436X | F15: 45444 | G15: 45808 | I15: 上海 | J15: 1300 | K15: 4293.24 | L15: 0 | M15: 253.35 | P15: 0 | S15: 630 | X15: 150 | Y15: 0.61 | AA15: =SUM(J15:Z15) -> 6627.2 | AB15: 18040 | AC15: 1443.2 | AD15: 360.8 | AE15: 90.2 | AF15: 18040 | AG15: =ROUND(AF15*7%,0) -> 1263 | AH15: =AC15+AD15+AE15+AG15 -> 3157.2 | AL15: =AA15-AH15-AI15 -> 3470 | AM15: 18040 | AN15: 18040 | AO15: =ROUND(AM15*16%,2) -> 2886.4 | AP15: =ROUND(AM15*9%,2) -> 1623.6 | AQ15: =ROUND(AM15*0.5%,2) -> 90.2 | AR15: =ROUND(AM15*0.256%,2) -> 46.18 | AT15: =ROUND(AN15*7%,0) -> 1263 | AU15: =ROUND(IF(AM15<24366,AM15*1.5%,24366*1.5%),2) -> 270.6 | AV15: =SUM(AO15:AU15) -> 6179.98 | AW15: 117 | AX15: =AV15+AA15+AJ15-AK15+AW15 -> 12924.18 | BB15: 255 | BC15: =ROUND(AX15+BB15+AZ15,2) -> 13179.18 | BD15: =ROUND(BC15*6%,2) -> 790.75 | BE15: =ROUND(SUM(BC15:BD15),2) -> 13969.93
A16: =ROW()-2 -> 14 | B16: 2412 | C16: WB017085 | D16: 邱杭佳 | E16: 31010819830921103X | F16: 45444 | G16: 45808 | I16: 上海 | J16: 1030 | K16: 2124 | L16: 5100.54 | M16: 916.5 | P16: 0 | S16: 630 | X16: 150 | Y16: 0 | AA16: =SUM(J16:Z16) -> 9951.04 | AB16: 7474 | AC16: 597.92 | AD16: 149.48 | AE16: 37.37 | AF16: 7474 | AG16: =ROUND(AF16*7%,0) -> 523 | AH16: =AC16+AD16+AE16+AG16 -> 1307.77 | AL16: =AA16-AH16-AI16 -> 8643.27 | AM16: 7474 | AN16: 7474 | AO16: =ROUND(AM16*16%,2) -> 1195.84 | AP16: =ROUND(AM16*9%,2) -> 672.66 | AQ16: =ROUND(AM16*0.5%,2) -> 37.37 | AR16: =ROUND(AM16*0.256%,2) -> 19.13 | AT16: =ROUND(AN16*7%,0) -> 523 | AU16: =ROUND(IF(AM16<24366,AM16*1.5%,24366*1.5%),2) -> 112.11 | AV16: =SUM(AO16:AU16) -> 2560.11 | AW16: 183 | AX16: =AV16+AA16+AJ16-AK16+AW16 -> 12694.15 | BB16: 255 | BC16: =ROUND(AX16+BB16+AZ16,2) -> 12949.15 | BD16: =ROUND(BC16*6%,2) -> 776.95 | BE16: =ROUND(SUM(BC16:BD16),2) -> 13726.1
A17: =ROW()-2 -> 15 | B17: 2412 | C17: WB008065 | D17: 戚继英 | E17: 310102198004243227 | F17: 45444 | G17: 45808 | I17: 上海 | J17: 1300 | K17: 2736 | L17: 14743.4 | M17: 2121.03 | P17: 0 | S17: 630 | X17: 150 | Y17: 0 | AA17: =SUM(J17:Z17) -> 21680.43 | AB17: 11152 | AC17: 892.16 | AD17: 223.04 | AE17: 55.76 | AF17: 11152 | AG17: =ROUND(AF17*7%,0) -> 781 | AH17: =AC17+AD17+AE17+AG17 -> 1951.96 | AL17: =AA17-AH17-AI17 -> 19728.47 | AM17: 11152 | AN17: 11152 | AO17: =ROUND(AM17*16%,2) -> 1784.32 | AP17: =ROUND(AM17*9%,2) -> 1003.68 | AQ17: =ROUND(AM17*0.5%,2) -> 55.76 | AR17: =ROUND(AM17*0.256%,2) -> 28.55 | AT17: =ROUND(AN17*7%,0) -> 781 | AU17: =ROUND(IF(AM17<24366,AM17*1.5%,24366*1.5%),2) -> 167.28 | AV17: =SUM(AO17:AU17) -> 3820.59 | AW17: 418 | AX17: =AV17+AA17+AJ17-AK17+AW17 -> 25919.02 | BB17: 255 | BC17: =ROUND(AX17+BB17+AZ17,2) -> 26174.02 | BD17: =ROUND(BC17*6%,2) -> 1570.44 | BE17: =ROUND(SUM(BC17:BD17),2) -> 27744.46
A18: =ROW()-2 -> 16 | B18: 2412 | C18: WB045238 | D18: 戈婷婷 | E18: 320821199610185147 | F18: 45444 | G18: 45808 | I18: 上海 | J18: 1030 | K18: 3416.4 | L18: 14873.27 | M18: 2376.72 | P18: 0 | S18: 630 | X18: 150 | Y18: 0 | AA18: =SUM(J18:Z18) -> 22476.39 | AB18: 10443 | AC18: 835.44 | AD18: 208.86 | AE18: 52.22 | AF18: 10443 | AG18: =ROUND(AF18*7%,0) -> 731 | AH18: =AC18+AD18+AE18+AG18 -> 1827.52 | AL18: =AA18-AH18-AI18 -> 20648.87 | AM18: 10443 | AN18: 10443 | AO18: =ROUND(AM18*16%,2) -> 1670.88 | AP18: 939.88 | AQ18: =ROUND(AM18*0.5%,2) -> 52.22 | AR18: =ROUND(AM18*0.256%,2) -> 26.73 | AT18: =ROUND(AN18*7%,0) -> 731 | AU18: =ROUND(IF(AM18<24366,AM18*1.5%,24366*1.5%),2) -> 156.65 | AV18: =SUM(AO18:AU18) -> 3577.36 | AW18: 434 | AX18: =AV18+AA18+AJ18-AK18+AW18 -> 26487.75 | BB18: 255 | BC18: =ROUND(AX18+BB18+AZ18,2) -> 26742.75 | BD18: =ROUND(BC18*6%,2) -> 1604.57 | BE18: =ROUND(SUM(BC18:BD18),2) -> 28347.32
A19: =ROW()-2 -> 17 | B19: 2412 | C19: WB013266 | D19: 吴裕刚 | E19: 31010219810818361X | F19: 45444 | G19: 45808 | I19: 上海 | J19: 1030 | K19: 4751.04 | L19: 11609.11 | M19: 836.4 | P19: 0 | S19: 630 | X19: 150 | Y19: 0 | AA19: =SUM(J19:Z19) -> 19006.55 | AB19: 8102 | AC19: 648.16 | AD19: 162.04 | AE19: 40.51 | AF19: 8102 | AG19: =ROUND(AF19*7%,0) -> 567 | AH19: =AC19+AD19+AE19+AG19 -> 1417.71 | AL19: =AA19-AH19-AI19 -> 17588.84 | AM19: 8102 | AN19: 8102 | AO19: =ROUND(AM19*16%,2) -> 1296.32 | AP19: =ROUND(AM19*9%,2) -> 729.18 | AQ19: =ROUND(AM19*0.5%,2) -> 40.51 | AR19: =ROUND(AM19*0.256%,2) -> 20.74 | AT19: =ROUND(AN19*7%,0) -> 567 | AU19: =ROUND(IF(AM19<24366,AM19*1.5%,24366*1.5%),2) -> 121.53 | AV19: =SUM(AO19:AU19) -> 2775.28 | AW19: 365 | AX19: =AV19+AA19+AJ19-AK19+AW19 -> 22146.83 | BB19: 255 | BC19: =ROUND(AX19+BB19+AZ19,2) -> 22401.83 | BD19: =ROUND(BC19*6%,2) -> 1344.11 | BE19: =ROUND(SUM(BC19:BD19),2) -> 23745.94
A20: =ROW()-2 -> 18 | B20: 2412 | C20: WB017007 | D20: 贺彦 | E20: 310108198901250513 | F20: 45444 | G20: 45808 | I20: 上海 | J20: 800 | K20: 1620 | L20: 0 | M20: 1196.16 | P20: 0 | S20: 630 | X20: 150 | Y20: 192.16 | AA20: =SUM(J20:Z20) -> 4588.32 | AB20: 7384 | AC20: 590.72 | AD20: 147.68 | AE20: 36.92 | AF20: 4906 | AG20: =ROUND(AF20*7%,0) -> 343 | AH20: =AC20+AD20+AE20+AG20 -> 1118.32 | AL20: =AA20-AH20-AI20 -> 3470 | AM20: 7384 | AN20: 4906 | AO20: =ROUND(AM20*16%,2) -> 1181.44 | AP20: =ROUND(AM20*9%,2) -> 664.56 | AQ20: =ROUND(AM20*0.5%,2) -> 36.92 | AR20: =ROUND(AM20*0.256%,2) -> 18.9 | AT20: =ROUND(AN20*7%,0) -> 343 | AU20: =ROUND(IF(AM20<24366,AM20*1.5%,24366*1.5%),2) -> 110.76 | AV20: =SUM(AO20:AU20) -> 2355.58 | AW20: 76 | AX20: =AV20+AA20+AJ20-AK20+AW20 -> 7019.9 | BB20: 255 | BC20: =ROUND(AX20+BB20+AZ20,2) -> 7274.9 | BD20: =ROUND(BC20*6%,2) -> 436.49 | BE20: =ROUND(SUM(BC20:BD20),2) -> 7711.39
A21: =ROW()-2 -> 19 | B21: 2412 | C21: WB017000 | D21: 叶毅 | E21: 310110198502133266 | F21: 45444 | G21: 45808 | I21: 上海 | J21: 1030 | K21: 2136 | L21: 9820 | M21: 654.24 | P21: 700 | S21: 630 | X21: 150 | Y21: 0 | AA21: =SUM(J21:Z21) -> 15120.24 | AB21: 7759 | AC21: 620.72 | AD21: 155.18 | AE21: 38.8 | AF21: 7759 | AG21: =ROUND(AF21*7%,0) -> 543 | AH21: =AC21+AD21+AE21+AG21 -> 1357.7 | AL21: =AA21-AH21-AI21 -> 13762.54 | AM21: 7759 | AN21: 7759 | AO21: =ROUND(AM21*16%,2) -> 1241.44 | AP21: 698.32 | AQ21: =ROUND(AM21*0.5%,2) -> 38.8 | AR21: =ROUND(AM21*0.256%,2) -> 19.86 | AT21: =ROUND(AN21*7%,0) -> 543 | AU21: =ROUND(IF(AM21<24366,AM21*1.5%,24366*1.5%),2) -> 116.39 | AV21: =SUM(AO21:AU21) -> 2657.81 | AW21: 287 | AX21: =AV21+AA21+AJ21-AK21+AW21 -> 18065.05 | BB21: 255 | BC21: =ROUND(AX21+BB21+AZ21,2) -> 18320.05 | BD21: =ROUND(BC21*6%,2) -> 1099.2 | BE21: =ROUND(SUM(BC21:BD21),2) -> 19419.25
A22: =ROW()-2 -> 20 | B22: 2412 | C22: WB017001 | D22: 陈世碧 | E22: 513023197709136722 | F22: 45444 | G22: 45808 | I22: 上海 | J22: 1030 | K22: 2769 | L22: 12150 | M22: 2009.16 | P22: 0 | S22: 630 | X22: 150 | Y22: 0 | AA22: =SUM(J22:Z22) -> 18738.16 | AB22: 10043 | AC22: 803.44 | AD22: 200.86 | AE22: 50.22 | AF22: 10043 | AG22: =ROUND(AF22*7%,0) -> 703 | AH22: =AC22+AD22+AE22+AG22 -> 1757.52 | AL22: =AA22-AH22-AI22 -> 16980.64 | AM22: 10043 | AN22: 10043 | AO22: =ROUND(AM22*16%,2) -> 1606.88 | AP22: 903.88 | AQ22: =ROUND(AM22*0.5%,2) -> 50.22 | AR22: =ROUND(AM22*0.256%,2) -> 25.71 | AT22: =ROUND(AN22*7%,0) -> 703 | AU22: =ROUND(IF(AM22<24366,AM22*1.5%,24366*1.5%),2) -> 150.65 | AV22: =SUM(AO22:AU22) -> 3440.34 | AW22: 359 | AX22: =AV22+AA22+AJ22-AK22+AW22 -> 22537.5 | BB22: 255 | BC22: =ROUND(AX22+BB22+AZ22,2) -> 22792.5 | BD22: =ROUND(BC22*6%,2) -> 1367.55 | BE22: =ROUND(SUM(BC22:BD22),2) -> 24160.05
A23: =ROW()-2 -> 21 | B23: 2412 | C23: WB017004 | D23: 顾陆慧 | E23: 310230197904164766 | F23: 45444 | G23: 45808 | I23: 上海 | J23: 1300 | K23: 5396 | L23: 15000 | M23: 615.51 | P23: 0 | S23: 630 | X23: 150 | Y23: 0 | AA23: =SUM(J23:Z23) -> 23091.51 | AB23: 12136 | AC23: 970.88 | AD23: 242.72 | AE23: 60.68 | AF23: 12136 | AG23: =ROUND(AF23*7%,0) -> 850 | AH23: =AC23+AD23+AE23+AG23 -> 2124.28 | AL23: =AA23-AH23-AI23 -> 20967.23 | AM23: 12136 | AN23: 12136 | AO23: =ROUND(AM23*16%,2) -> 1941.76 | AP23: =ROUND(AM23*9%,2) -> 1092.24 | AQ23: =ROUND(AM23*0.5%,2) -> 60.68 | AR23: =ROUND(AM23*0.256%,2) -> 31.07 | AT23: =ROUND(AN23*7%,0) -> 850 | AU23: =ROUND(IF(AM23<24366,AM23*1.5%,24366*1.5%),2) -> 182.04 | AV23: =SUM(AO23:AU23) -> 4157.79 | AW23: 446 | AX23: =AV23+AA23+AJ23-AK23+AW23 -> 27695.3 | BB23: 255 | BC23: =ROUND(AX23+BB23+AZ23,2) -> 27950.3 | BD23: =ROUND(BC23*6%,2) -> 1677.02 | BE23: =ROUND(SUM(BC23:BD23),2) -> 29627.32
A24: =ROW()-2 -> 22 | B24: 2412 | C24: WB017006 | D24: 程祖云 | E24: 411524198609258442 | F24: 45444 | G24: 45808 | I24: 上海 | J24: 1200 | K24: 3777.2 | L24: 11290 | M24: 1036.62 | P24: 0 | S24: 630 | X24: 150 | Y24: 0 | AA24: =SUM(J24:Z24) -> 18083.82 | AB24: 9608 | AC24: 768.64 | AD24: 192.16 | AE24: 48.04 | AF24: 9608 | AG24: =ROUND(AF24*7%,0) -> 673 | AH24: =AC24+AD24+AE24+AG24 -> 1681.84 | AL24: =AA24-AH24-AI24 -> 16401.98 | AM24: 9608 | AN24: 9608 | AO24: =ROUND(AM24*16%,2) -> 1537.28 | AP24: =ROUND(AM24*9%,2) -> 864.72 | AQ24: =ROUND(AM24*0.5%,2) -> 48.04 | AR24: =ROUND(AM24*0.256%,2) -> 24.6 | AT24: =ROUND(AN24*7%,0) -> 673 | AU24: =ROUND(IF(AM24<24366,AM24*1.5%,24366*1.5%),2) -> 144.12 | AV24: =SUM(AO24:AU24) -> 3291.76 | AW24: 346 | AX24: =AV24+AA24+AJ24-AK24+AW24 -> 21721.58 | BB24: 255 | BC24: =ROUND(AX24+BB24+AZ24,2) -> 21976.58 | BD24: =ROUND(BC24*6%,2) -> 1318.59 | BE24: =ROUND(SUM(BC24:BD24),2) -> 23295.17
A25: =ROW()-2 -> 23 | B25: 2412 | C25: WB003572 | D25: 谢俊敏 | E25: 310110198911171036 | F25: 45444 | G25: 45808 | I25: 上海 | J25: 1030 | K25: 2040 | L25: 7846 | M25: 858.78 | P25: 500 | S25: 630 | X25: 150 | Y25: 0 | AA25: =SUM(J25:Z25) -> 13054.78 | AB25: 7974 | AC25: 637.92 | AD25: 159.48 | AE25: 39.87 | AF25: 7974 | AG25: =ROUND(AF25*7%,0) -> 558 | AH25: =AC25+AD25+AE25+AG25 -> 1395.27 | AL25: =AA25-AH25-AI25 -> 11659.51 | AM25: 7974 | AN25: 7974 | AO25: =ROUND(AM25*16%,2) -> 1275.84 | AP25: =ROUND(AM25*9%,2) -> 717.66 | AQ25: =ROUND(AM25*0.5%,2) -> 39.87 | AR25: =ROUND(AM25*0.256%,2) -> 20.41 | AT25: =ROUND(AN25*7%,0) -> 558 | AU25: =ROUND(IF(AM25<24366,AM25*1.5%,24366*1.5%),2) -> 119.61 | AV25: =SUM(AO25:AU25) -> 2731.39 | AW25: 245 | AX25: =AV25+AA25+AJ25-AK25+AW25 -> 16031.17 | BB25: 255 | BC25: =ROUND(AX25+BB25+AZ25,2) -> 16286.17 | BD25: =ROUND(BC25*6%,2) -> 977.17 | BE25: =ROUND(SUM(BC25:BD25),2) -> 17263.34
A26: =ROW()-2 -> 24 | B26: 2412 | C26: WB039916 | D26: 梁裔杰 | E26: 310113198509301719 | F26: 45444 | G26: 45808 | I26: 上海 | J26: 1030 | K26: 2652 | L26: 8807 | M26: 907.08 | P26: 500 | S26: 630 | X26: 150 | Y26: 0 | AA26: =SUM(J26:Z26) -> 14676.08 | AB26: 7384 | AC26: 590.72 | AD26: 147.68 | AE26: 36.92 | AF26: 7139 | AG26: =ROUND(AF26*7%,0) -> 500 | AH26: =AC26+AD26+AE26+AG26 -> 1275.32 | AL26: =AA26-AH26-AI26 -> 13400.76 | AM26: 7384 | AN26: 7139 | AO26: =ROUND(AM26*16%,2) -> 1181.44 | AP26: =ROUND(AM26*9%,2) -> 664.56 | AQ26: =ROUND(AM26*0.5%,2) -> 36.92 | AR26: =ROUND(AM26*0.256%,2) -> 18.9 | AT26: =ROUND(AN26*7%,0) -> 500 | AU26: =ROUND(IF(AM26<24366,AM26*1.5%,24366*1.5%),2) -> 110.76 | AV26: =SUM(AO26:AU26) -> 2512.58 | AW26: 278 | AX26: =AV26+AA26+AJ26-AK26+AW26 -> 17466.66 | BB26: 255 | BC26: =ROUND(AX26+BB26+AZ26,2) -> 17721.66 | BD26: =ROUND(BC26*6%,2) -> 1063.3 | BE26: =ROUND(SUM(BC26:BD26),2) -> 18784.96
A27: =ROW()-2 -> 25 | B27: 2412 | C27: WB017057 | D27: 朱云 | E27: 310110198810200045 | F27: 45444 | G27: 45808 | I27: 上海 | J27: 1030 | K27: 1344 | L27: 5417 | M27: 723.84 | P27: 0 | S27: 630 | X27: 150 | Y27: 0 | AA27: =SUM(J27:Z27) -> 9294.84 | AB27: 11909 | AC27: 952.72 | AD27: 238.18 | AE27: 59.55 | AF27: 11909 | AG27: =ROUND(AF27*7%,0) -> 834 | AH27: =AC27+AD27+AE27+AG27 -> 2084.45 | AL27: =AA27-AH27-AI27 -> 7210.39 | AM27: 11909 | AN27: 11909 | AO27: =ROUND(AM27*16%,2) -> 1905.44 | AP27: 1071.82 | AQ27: =ROUND(AM27*0.5%,2) -> 59.55 | AR27: =ROUND(AM27*0.256%,2) -> 30.49 | AT27: =ROUND(AN27*7%,0) -> 834 | AU27: =ROUND(IF(AM27<24366,AM27*1.5%,24366*1.5%),2) -> 178.64 | AV27: =SUM(AO27:AU27) -> 4079.94 | AW27: 170 | AX27: =AV27+AA27+AJ27-AK27+AW27 -> 13544.78 | BB27: 255 | BC27: =ROUND(AX27+BB27+AZ27,2) -> 13799.78 | BD27: =ROUND(BC27*6%,2) -> 827.99 | BE27: =ROUND(SUM(BC27:BD27),2) -> 14627.77
A28: =ROW()-2 -> 26 | B28: 2412 | C28: WB017068 | D28: 罗文彬 | E28: 310110198902103234 | F28: 45444 | G28: 45808 | I28: 上海 | J28: 1200 | K28: 2548 | L28: 7945 | M28: 643.8 | P28: 0 | S28: 630 | X28: 150 | Y28: 0 | AA28: =SUM(J28:Z28) -> 13116.8 | AB28: 14537 | AC28: 1162.96 | AD28: 290.74 | AE28: 72.69 | AF28: 14537 | AG28: =ROUND(AF28*7%,0) -> 1018 | AH28: =AC28+AD28+AE28+AG28 -> 2544.39 | AL28: =AA28-AH28-AI28 -> 10572.41 | AM28: 14537 | AN28: 14537 | AO28: =ROUND(AM28*16%,2) -> 2325.92 | AP28: 1308.34 | AQ28: =ROUND(AM28*0.5%,2) -> 72.69 | AR28: =ROUND(AM28*0.256%,2) -> 37.21 | AT28: =ROUND(AN28*7%,0) -> 1018 | AU28: =ROUND(IF(AM28<24366,AM28*1.5%,24366*1.5%),2) -> 218.06 | AV28: =SUM(AO28:AU28) -> 4980.22 | AW28: 247 | AX28: =AV28+AA28+AJ28-AK28+AW28 -> 18344.02 | BB28: 255 | BC28: =ROUND(AX28+BB28+AZ28,2) -> 18599.02 | BD28: =ROUND(BC28*6%,2) -> 1115.94 | BE28: =ROUND(SUM(BC28:BD28),2) -> 19714.96
A29: =ROW()-2 -> 27 | B29: 2412 | C29: WB054689 | D29: 张梦诏 | E29: 342423200108298172 | F29: 45444 | G29: 45808 | I29: 上海 | J29: 800 | K29: 1929.9 | L29: 9695.65 | M29: 1886.64 | P29: 0 | S29: 630 | X29: 150 | Y29: 0 | AA29: =SUM(J29:Z29) -> 15092.19 | AB29: 7384 | AC29: 590.72 | AD29: 147.68 | AE29: 36.92 | AF29: 5239 | AG29: =ROUND(AF29*7%,0) -> 367 | AH29: =AC29+AD29+AE29+AG29 -> 1142.32 | AL29: =AA29-AH29-AI29 -> 13949.87 | AM29: 7384 | AN29: 5239 | AO29: =ROUND(AM29*16%,2) -> 1181.44 | AP29: =ROUND(AM29*9%,2) -> 664.56 | AQ29: =ROUND(AM29*0.5%,2) -> 36.92 | AR29: =ROUND(AM29*0.256%,2) -> 18.9 | AT29: =ROUND(AN29*7%,0) -> 367 | AU29: =ROUND(IF(AM29<24366,AM29*1.5%,24366*1.5%),2) -> 110.76 | AV29: =SUM(AO29:AU29) -> 2379.58 | AW29: 286 | AX29: =AV29+AA29+AJ29-AK29+AW29 -> 17757.77 | BB29: 255 | BC29: =ROUND(AX29+BB29+AZ29,2) -> 18012.77 | BD29: =ROUND(BC29*6%,2) -> 1080.77 | BE29: =ROUND(SUM(BC29:BD29),2) -> 19093.54
A30: 合计 | AA30: =SUBTOTAL(9,AA3:AA29) -> 380922.43 | AH30: =SUBTOTAL(9,AH3:AH29) -> 46020.42 | AL30: =SUBTOTAL(9,AL3:AL29) -> 334902.01 | AV30: =SUBTOTAL(9,AV3:AV29) -> 90627.22 | AW30: =SUM(AW3:AW29) -> 7197 | AX30: =SUBTOTAL(9,AX3:AX29) -> 478746.65 | AZ30: =SUBTOTAL(9,AZ3:AZ29) -> 0 | BB30: =SUBTOTAL(9,BB3:BB29) -> 6885 | BC30: =SUBTOTAL(9,BC3:BC29) -> 485631.65 | BD30: =SUBTOTAL(9,BD3:BD29) -> 29137.92 | BE30: =SUBTOTAL(9,BE3:BE29) -> 514769.57
AW31: 22743

Sheet 对账单
A1: 科目 | B1: 手工账单 | C1: 速创账单 | D1: 155 | E1: 系统已有金额（不做一次性） | F1: 4-11月工会费 | G1: 12月工会费 | H1: 合计 | I1: 差异
A2: 管理费 | B2: ='202412'!BD30+B10*0.06 -> 30502.5 | C2: =系统!E43 -> 31146.85 | H2: =SUM(C2:G2) -> 31146.85 | I2: =B2-C2 -> -644.35
A3: 风险费 | B3: ='202412'!BB30 -> 6885 | C3: 0 | D3: =27*155 -> 4185 | H3: =SUM(C3:G3) -> 4185 | I3: =B3-C3 -> 6885
A4: 个人四金 | B4: ='202412'!AH30 -> 46020.42 | C4: =系统!V43 -> 46020.42 | H4: =SUM(C4:G4) -> 46020.42 | I4: =B4-C4 -> 0
A5: 公司四金 | B5: ='202412'!AV30 -> 90627.22 | C5: =系统!O43 -> 90627.22 | H5: =SUM(C5:E5) -> 90627.22 | I5: =B5-C5 -> 0
A6: 残保金 | H6: =SUM(C6:G6) -> 0 | I6: =B6-C6 -> 0
A7: 代发工资 | B7: ='202412'!AA30-'202412'!AH30 -> 334902.01 | C7: =系统!W43 -> 334767.01 | D7: =5*27+0.05 -> 135.05 | H7: =SUM(C7:G7) -> 334902.06 | I7: =B7-C7 -> 135
A8: 上月垫付 | H8: =SUM(C8:G8) -> 0 | I8: =B8-C8 -> 0
A9: 12月工会费 | B9: ='202412'!AW30 -> 7197 | F9: =B10 -> 22743 | G9: =B9 -> 7197 | H9: =SUM(C9:G9) -> 29940 | I9: =B9-C9 -> 7197
A10: 4-11月工会费 | B10: =22743 -> 22743 | H10: =SUM(C10:G10) -> 0 | I10: =B10-C10 -> 22743
A11: 小计 | B11: =SUM(B2:B10) -> 538877.15 | C11: =SUM(C2:C10) -> 502561.5 | D11: =SUM(D2:D10) -> 4320.05 | F11: =F9 -> 22743 | G11: =G9 -> 7197 | H11: =SUM(C11:G11) -> 536821.55
A12: 附加税
A13: 增值税 | D13: =ROUND((D11+D12)*6%,2) -> 259.2 | F13: =ROUND((F11+F12)*6%,2) -> 1364.58 | G13: =ROUND((G11+G12)*6%,2) -> 431.82 | H13: =SUM(C13:G13) -> 2055.6
A14: 总计 | B14: =SUM(B11:B13) -> 538877.15 | C14: =SUM(C11:C13) -> 502561.5 | D14: =SUM(D11:D13) -> 4579.25 | F14: =SUM(F11:F13) -> 24107.58 | G14: =SUM(G11:G13) -> 7628.82 | H14: =SUM(C14:G14) -> 538877.15
A15: 给客户账单金额 | H15: =B14 -> 538877.15
A16: 差异 | H16: =H15-H14 -> 0
A17: 不含税差异 | H17: =ROUND(H16/1.06,2) -> 0

Sheet 系统
A1: 200070
A2: 寄：梅园路77号人才大厦
B3: 中国电信股份有限公司上海分公司 王慧珏 收
D6: 上海外服布列吉科技有限公司
C7: Shanghai Foreign Service Bridge Technology Co,Ltd.
E9: 收款通知书
E10: ADVISE ON COLLECTION
E11: 2024年12月
A13: 公司名称：中国电信股份有限公司上海分公司 | J13: 帐单号：202412CH6594403
A14: 序号 | B14: 姓名 | C14: 发生年月 | D14: 入职日期 | E14: 管理费 | F14: 当月社保基数 | G14: 当月公积金基数 | H14: 社保类 公司支付 Social Insurance Premiums Paid by Employer | N14: 公积金类 公司支付 Provident Fund Paid by Employer | O14: 公司合计 | P14: 社保类 个人支付 Social Insurance Premiums Paid by Employee | U14: 公积金类 个人支付 Provident Fund Paid by Employee | V14: 个人合计 | W14: 代办薪酬 | X14: 其他 | Y14: 总计 | Z14: 备注 | AA14: 外服工号 | AB14: 证件号码 | AC14: 应纳税金额 | AD14: 税率 | AE14: 增值税
A15: S/N | B15: Name | C15: YYYYMM | D15: Employment Start Date | E15: Adm Fee | F15: Social Insurance Base Amount of Current Month | G15: Provident Fund Base Amount of Current Month | H15: 养老保险 Endowment | I15: 医疗保险 Medical | J15: 失业保险 Unemploy-ment | K15: 工伤保险 Employment Injury | L15: 医疗生育保险 Medical Maternity | M15: 保障金 Disabled people&Back pay Fund | N15: 公积金 Provident Fund | O15: Subtotal of Employer Payment | P15: 养老保险 Endowment | Q15: 医疗保险 Medical | R15: 失业保险 Unemploy-ment | S15: 工伤保险 Employment Injury | T15: 医疗生育保险 Medical Maternity | U15: 公积金 Provident Fund | V15: Subtotal of Personal Payment | W15: Agency of Wage Payment | X15: Others | Y15: Total | Z15: Remarks | AA15: SFSC ID | AB15: ID Card | AC15: Taxable Amount | AD15: Tax Rate | AE15: VAT
A16: 1 | B16: 陈世碧 | C16: 202412 | D16: 2024-06-01 | E16: 1436.41 | F16: 10043 | G16: 10043 | H16: 1606.88 | I16: 903.88 | J16: 50.22 | K16: 25.71 | M16: 150.65 | N16: 703 | O16: =SUM(H16:N16) -> 3440.34 | P16: 803.44 | Q16: 200.86 | R16: 50.22 | U16: 703 | V16: =SUM(P16:U16) -> 1757.52 | W16: 16975.64 | Y16: =SUM(E16,O16,V16:X16) -> 23609.91 | AA16: 5861127 | AB16: 513023197709136722 | AC16: 22273.51 | AD16: 6% | AE16: 1336.4
A17: 2 | B17: 程祖云 | C17: 202412 | D17: 2024-06-01 | E17: 1388.24 | F17: 9608 | G17: 9608 | H17: 1537.28 | I17: 864.72 | J17: 48.04 | K17: 24.6 | M17: 144.12 | N17: 673 | O17: =SUM(H17:N17) -> 3291.76 | P17: 768.64 | Q17: 192.16 | R17: 48.04 | U17: 673 | V17: =SUM(P17:U17) -> 1681.84 | W17: 16396.98 | Y17: =SUM(E17,O17,V17:X17) -> 22758.82 | AA17: 5861128 | AB17: 411524198609258442 | AC17: 21470.58 | AD17: 6% | AE17: 1288.24
A18: 3 | B18: 高雄飞 | C18: 202412 | D18: 2024-06-01 | E18: 606.59 | F18: 9424 | G18: 9424 | H18: 1507.84 | I18: 848.16 | J18: 47.12 | K18: 24.13 | M18: 141.36 | N18: 660 | O18: =SUM(H18:N18) -> 3228.61 | P18: 753.92 | Q18: 188.48 | R18: 47.12 | U18: 660 | V18: =SUM(P18:U18) -> 1649.52 | W18: 3465 | Y18: =SUM(E18,O18,V18:X18) -> 8949.72 | AA18: 5544585 | AB18: 310101198402231014 | AC18: 8443.12 | AD18: 6% | AE18: 506.6
A19: 4 | B19: 戈婷婷 | C19: 202412 | D19: 2024-06-01 | E19: 1668.92 | F19: 10443 | G19: 10443 | H19: 1670.88 | I19: 939.88 | J19: 52.22 | K19: 26.73 | M19: 156.65 | N19: 731 | O19: =SUM(H19:N19) -> 3577.36 | P19: 835.44 | Q19: 208.86 | R19: 52.22 | U19: 731 | V19: =SUM(P19:U19) -> 1827.52 | W19: 20643.87 | Y19: =SUM(E19,O19,V19:X19) -> 27717.67 | AA19: 5544594 | AB19: 320821199610185147 | AC19: 26148.76 | AD19: 6% | AE19: 1568.91
A20: 5 | B20: 顾陆慧 | C20: 202412 | D20: 2024-06-01 | E20: 1740.65 | F20: 12136 | G20: 12136 | H20: 1941.76 | I20: 1092.24 | J20: 60.68 | K20: 31.07 | M20: 182.04 | N20: 850 | O20: =SUM(H20:N20) -> 4157.79 | P20: 970.88 | Q20: 242.72 | R20: 60.68 | U20: 850 | V20: =SUM(P20:U20) -> 2124.28 | W20: 20962.23 | Y20: =SUM(E20,O20,V20:X20) -> 28984.95 | AA20: 5863338 | AB20: 310230197904164766 | AC20: 27344.31 | AD20: 6% | AE20: 1640.64
A21: 6 | B21: 杭亮 | C21: 202412 | D21: 2024-06-01 | E21: 963.5 | F21: 9226 | G21: 9226 | H21: 1476.16 | I21: 830.34 | J21: 46.13 | K21: 23.62 | M21: 138.39 | N21: 646 | O21: =SUM(H21:N21) -> 3160.64 | P21: 738.08 | Q21: 184.52 | R21: 46.13 | U21: 646 | V21: =SUM(P21:U21) -> 1614.73 | W21: 9516.29 | Y21: =SUM(E21,O21,V21:X21) -> 15255.16 | AA21: 5544580 | AB21: 310110198004027057 | AC21: 14391.66 | AD21: 6% | AE21: 863.5
A22: 7 | B22: 贺彦 | C22: 202412 | D22: 2024-06-01 | E22: 522.33 | F22: 7384 | G22: 4906 | H22: 1181.44 | I22: 664.56 | J22: 36.92 | K22: 18.9 | M22: 110.76 | N22: 343 | O22: =SUM(H22:N22) -> 2355.58 | P22: 590.72 | Q22: 147.68 | R22: 36.92 | U22: 343 | V22: =SUM(P22:U22) -> 1118.32 | W22: 3465 | Y22: =SUM(E22,O22,V22:X22) -> 7461.23 | AA22: 5701787 | AB22: 310108198901250513 | AC22: 7038.89 | AD22: 6% | AE22: 422.34
A23: 8 | B23: 季华 | C23: 202412 | D23: 2024-06-01 | E23: 1508.38 | F23: 10475 | G23: 10475 | H23: 1676 | I23: 942.76 | J23: 52.38 | K23: 26.82 | M23: 157.13 | N23: 733 | O23: =SUM(H23:N23) -> 3588.09 | P23: 838 | Q23: 209.5 | R23: 52.38 | U23: 733 | V23: =SUM(P23:U23) -> 1832.88 | W23: 17952 | Y23: =SUM(E23,O23,V23:X23) -> 24881.35 | AA23: 5544586 | AB23: 310115198609170130 | AC23: 23472.97 | AD23: 6% | AE23: 1408.38
A24: 9 | B24: 梁裔杰 | C24: 202412 | D24: 2024-06-01 | E24: 1137.02 | F24: 7384 | G24: 7139 | H24: 1181.44 | I24: 664.56 | J24: 36.92 | K24: 18.9 | M24: 110.76 | N24: 500 | O24: =SUM(H24:N24) -> 2512.58 | P24: 590.72 | Q24: 147.68 | R24: 36.92 | U24: 500 | V24: =SUM(P24:U24) -> 1275.32 | W24: 13395.76 | Y24: =SUM(E24,O24,V24:X24) -> 18320.68 | AA24: 5861130 | AB24: 310113198509301719 | AC24: 17283.65 | AD24: 6% | AE24: 1037.03
A25: 10 | B25: 罗文彬 | C25: 202412 | D25: 2024-06-01 | E25: 1191.52 | F25: 14537 | G25: 14537 | H25: 2325.92 | I25: 1308.34 | J25: 72.69 | K25: 37.21 | M25: 218.06 | N25: 1018 | O25: =SUM(H25:N25) -> 4980.22 | P25: 1162.96 | Q25: 290.74 | R25: 72.69 | U25: 1018 | V25: =SUM(P25:U25) -> 2544.39 | W25: 10567.41 | Y25: =SUM(E25,O25,V25:X25) -> 19283.54 | AA25: 5922255 | AB25: 310110198902103234 | AC25: 18192.03 | AD25: 6% | AE25: 1091.51
A26: 11 | B26: 孟浩杰 | C26: 202412 | D26: 2024-06-01 | E26: 1361.11 | F26: 9241 | G26: 9241 | H26: 1478.56 | I26: 831.7 | J26: 46.21 | K26: 23.66 | M26: 138.62 | N26: 647 | O26: =SUM(H26:N26) -> 3165.75 | P26: 739.28 | Q26: 184.82 | R26: 46.21 | U26: 647 | V26: =SUM(P26:U26) -> 1617.31 | W26: 16135.43 | Y26: =SUM(E26,O26,V26:X26) -> 22279.6 | AA26: 5544588 | AB26: 510108198209090637 | AC26: 21018.49 | AD26: 6% | AE26: 1261.11
A27: 12 | B27: 戚继英 | C27: 202412 | D27: 2024-06-01 | E27: 1635.76 | F27: 11152 | G27: 11152 | H27: 1784.32 | I27: 1003.68 | J27: 55.76 | K27: 28.55 | M27: 167.28 | N27: 781 | O27: =SUM(H27:N27) -> 3820.59 | P27: 892.16 | Q27: 223.04 | R27: 55.76 | U27: 781 | V27: =SUM(P27:U27) -> 1951.96 | W27: 19723.47 | Y27: =SUM(E27,O27,V27:X27) -> 27131.78 | AA27: 5544593 | AB27: 310102198004243227 | AC27: 25596.01 | AD27: 6% | AE27: 1535.77
... A42: 27 | B42: 朱云 | C42: 202412 | D42: 2024-06-01 | E42: 908.18 | F42: 11909 | G42: 11909 | H42: 1905.44 | I42: 1071.82 | J42: 59.55 | K42: 30.49 | M42: 178.64 | N42: 834 | O42: =SUM(H42:N42) -> 4079.94 | P42: 952.72 | Q42: 238.18 | R42: 59.55 | U42: 834 | V42: =SUM(P42:U42) -> 2084.45 | W42: 7205.39 | Y42: =SUM(E42,O42,V42:X42) -> 14277.96 | AA42: 5922254 | AB42: 310110198810200045 | AC42: 13469.78 | AD42: 6% | AE42: 808.18
A43: 合计（RMB） | E43: =SUM(E16:E42) -> 31146.85 | H43: =SUM(H16:H42) -> 42594.08 | I43: =SUM(I16:I42) -> 23959.28 | J43: =SUM(J16:J42) -> 1331.12 | K43: =SUM(K16:K42) -> 681.49 | L43: =SUM(L16:L42) -> 0 | M43: =SUM(M16:M42) -> 3993.25 | N43: =SUM(N16:N42) -> 18068 | O43: =SUM(O16:O42) -> 90627.22 | ... Y43: =SUM(Y16:Y42) -> 502561.5 | AC43: =SUM(AC16:AC42) -> 474114.61 | AE43: =SUM(AE16:AE42) -> 28446.89
A44: 总计（RMB）已包含历月补收人民币伍拾万贰仟伍佰陆拾壹圆伍角整 | Y44: 502561.5
A46: 其他费用
A47: 序号 | B47: 发生年月 | C47: 费用项目 | D47: 金额 | E47: 备注 | F47: 应纳税金额 | G47: 税率 | H47: 增值税
A48: S/N | B48: YYYYMM | C48: Item | D48: Amount | E48: Remarks | F48: Taxable Amount | G48: Tax Rate | H48: VAT
A49: 1 | B49: 202412 | C49: 税差调整6% | D49: 0 | F49: 0.01 | G49: 0.06 | H49: -0.01
A50: 合计（RMB） | D50: =SUM(D49:D49) -> 0 | F50: =SUM(F49:F49) -> 0.01 | H50: =SUM(H49:H49) -> -0.01
A51: 总计（RMB）人民币零 | D51: 0 | F51: 0.01 | H51: -0.01
A53: 增值税：
A54: 序号 S/N | B54: 应纳税额 | C54: 税率 | D54: 税金
A56: 1 | B56: 474114.62 | C56: 6% | D56: 28446.88
A57: 小计（RMB） | B57: 474114.62 | D57: 28446.88
A58: 总计(RMB) | D58: 28446.88
A59: 本次价税合计(RMB):人民币伍拾万贰仟伍佰陆拾壹圆伍角整
A60: 502561.5
A61: 本月价税合计（RMB）：502561.50 其中已开票502561.50
...
