Workbook

Sheet 202412
A1: 序号 | B1: 计薪 周期 | C1: 工号 | D1: 姓名 | E1: 身份证号 | F1: 劳动合同起始日期 | G1: 劳动合同结束日期 | H1: 离职日期 | I1: 社保缴纳地 | J1: 星级费用 | K1: 考核费用 | L1: 量化费用 | M1: 专项费用 | Z1: 当月税前工资合计 | AA1: 社保基数(个人) | AB1: 养老保险(个人) | AC1: 医疗保险(个人) | AD1: 失业保险(个人) | AE1: 公积金基数(个人) | AF1: 住房公积金(个人) | AG1: 员工五险一金合计 | AH1: 本月个人所得税-系统导出 | AI1: 税后增加 | AJ1: 税后扣减 | AK1: 员工实发合计 | AL1: 社保基数 | AM1: 公积金基数 | AN1: 养老缴费 | AO1: 医疗缴费 | AP1: 失业保险 | AQ1: 工伤保险 | AR1: 生育保险 | AS1: 公积金 | AT1: 残保金 | AU1: 企业五险一金合计 | AV1: 工会费 | AW1: 代收付合计 | AX1: 供应商补差 | AY1: 社保备注 | AZ1: 外包服务费 | BA1: 税前项合计 | BB1: 增值税 | BC1: 总计
A2: NO. | B2: Salary Cycle | C2: Employee No. | D2: Name | E2: ID No. | F2: Contract Starting Date | G2: Contract Expiry Date | H2: Exit Date | I2: Social Insurance City | J2: Contract Salary | K2: Assessment fees | L2: Quantifying costs | M2: 支局专项 | N2: 部门加奖 | O2: 交通费 | P2: 效能补贴 | Q2: 高温费及清凉饮料费 （6-9月） | R2: 伙食补贴 | S2: 独生子女奖励 | T2: 保险费 | U2: 其他费用 | V2: 补发费用 | W2: 劳防用品 | X2: 保障补差 | Y2: 其他扣款 | Z2: Pre-tax Total | AA2: Social Insurance Base | AB2: Pension Employee | AC2: Medical Employee | AD2: Umemployment Employee | AE2: Housing Fund Base | AF2: Housing Fund Employee | AG2: Total Amount of Social Insurance(EE) | AH2: Personal Income Tax | AI2: Increase After-tax payment | AJ2: Reduction After-tax payment | AK2: After-tax total Income | AL2: Social Insurance Base | AM2: Housing Fund Base | AN2: Pension Employer | AO2: Medical Employer | AP2: Umemployment Employer | AQ2: Injury Employer | AR2: Maternity Insurance Employer | AS2: Housing Fund Employer | AT2: Disabled people&Back pay Fund | AU2: Total Amount of Social Insurance(ER) | AV2: Union Fee | AW2: Payment Total | AY2: Social Security remark | AZ2: Service Fee | BA2: Total | BB2: VAT | BC2: Subtotal
A3: =ROW()-2 -> 1 | B3: 2412 | C3: WB007174 | D3: 傅强 | E3: 342501197805270274 | F3: 45444 | G3: 45808 | I3: 上海 | J3: 950 | L3: 1618.2 | U3: 650 | V3: 1353.12 | Z3: =SUM(J3:Y3) -> 4571.32 | AA3: 7384 | AB3: 590.72 | AC3: 147.68 | AD3: 36.92 | AE3: 6520 | AF3: =ROUND(AE3*7%,0) -> 456 | AG3: =AB3+AC3+AD3+AF3 -> 1231.32 | AK3: =Z3-AG3-AH3 -> 3340 | AL3: 7384 | AM3: 6520 | AN3: =ROUND(AL3*16%,2) -> 1181.44 | AO3: =ROUND(AL3*9%,2) -> 664.56 | AP3: =ROUND(AL3*0.5%,2) -> 36.92 | AQ3: =ROUND(AL3*0.256%,2) -> 18.9 | AS3: =ROUND(AM3*7%,0) -> 456 | AT3: =ROUND(IF(AL3<22792,AL3*1.5%,22792*1.5%),2) -> 110.76 | AU3: =SUM(AN3:AT3) -> 2468.58 | AV3: =91+423 -> 514 | AW3: =AU3+Z3+AI3-AJ3+AV3 -> 7553.9 | AZ3: 60 | BA3: =ROUND(AW3+AZ3+AX3,2) -> 7613.9 | BB3: =ROUND(BA3*6%,2) -> 456.83 | BC3: =ROUND(SUM(BA3:BB3),2) -> 8070.73
A4: =ROW()-2 -> 2 | B4: 2412 | C4: WB007141 | D4: 汤熙荣 | E4: 310108197210073613 | F4: 45383 | G4: 45747 | I4: 上海 | J4: 950 | U4: 650 | V4: 2981.32 | Z4: =SUM(J4:Y4) -> 4581.32 | AA4: 7384 | AB4: 590.72 | AC4: 147.68 | AD4: 36.92 | AE4: 6653 | AF4: =ROUND(AE4*7%,0) -> 466 | AG4: =AB4+AC4+AD4+AF4 -> 1241.32 | AK4: =Z4-AG4-AH4 -> 3340 | AL4: 7384 | AM4: 6653 | AN4: =ROUND(AL4*16%,2) -> 1181.44 | AO4: =ROUND(AL4*9%,2) -> 664.56 | AP4: =ROUND(AL4*0.5%,2) -> 36.92 | AQ4: =ROUND(AL4*0.256%,2) -> 18.9 | AS4: =ROUND(AM4*7%,0) -> 466 | AT4: =ROUND(IF(AL4<22792,AL4*1.5%,22792*1.5%),2) -> 110.76 | AU4: =SUM(AN4:AT4) -> 2478.58 | AV4: =92+551 -> 643 | AW4: =AU4+Z4+AI4-AJ4+AV4 -> 7702.9 | AZ4: 60 | BA4: =ROUND(AW4+AZ4+AX4,2) -> 7762.9 | BB4: =ROUND(BA4*6%,2) -> 465.77 | BC4: =ROUND(SUM(BA4:BB4),2) -> 8228.67
A6: 合计 | Z6: =SUBTOTAL(9,Z3:Z4) -> 9152.64 | AG6: =SUBTOTAL(9,AG3:AG4) -> 2472.64 | AK6: =SUBTOTAL(9,AK3:AK4) -> 6680 | AU6: =SUBTOTAL(9,AU3:AU4) -> 4947.16 | AV6: =SUM(AV3:AV4) -> 1157 | AW6: =SUBTOTAL(9,AW3:AW4) -> 15256.8 | AX6: =SUBTOTAL(9,AX3:AX4) -> 0 | AZ6: =SUBTOTAL(9,AZ3:AZ4) -> 120 | BA6: =SUBTOTAL(9,BA3:BA4) -> 15376.8 | BB6: =SUBTOTAL(9,BB3:BB4) -> 922.6 | BC6: =SUBTOTAL(9,BC3:BC4) -> 16299.4
AZ8: 实际结算 | BA8: 303434.72
AZ9: 差额下月补 | BA9: 111.61

Sheet 对账单
A1: 科目 | B1: 手工账单 | C1: 7月速创账单 | D1: 155 | E1: 系统已有金额（不做一次性） | F1: 4-11月工会费 | G1: 12月工会费 | H1: 合计 | I1: 差异
A2: 管理费 | B2: ='202412'!BB6 -> 922.6 | C2: =系统!E18+C9*6%+C10*0.06 -> 1042.6 | H2: =SUM(C2:G2) -> 1042.6 | I2: =B2-C2 -> -120
A3: 风险费 | B3: ='202412'!AZ6 -> 120 | C3: 0 | H3: =SUM(C3:G3) -> 0 | I3: =B3-C3 -> 120
A4: 个人四金 | B4: ='202412'!AG6 -> 2472.64 | C4: =系统!V18 -> 2472.64 | H4: =SUM(C4:G4) -> 2472.64 | I4: =B4-C4 -> 0
A5: 公司四金 | B5: ='202412'!AU6 -> 4947.16 | C5: =系统!O18 -> 4947.16 | H5: =SUM(C5:E5) -> 4947.16 | I5: =B5-C5 -> 0
A6: 残保金 | H6: =SUM(C6:G6) -> 0 | I6: =B6-C6 -> 0
A7: 代发工资 | B7: ='202412'!AK6 -> 6680 | C7: =系统!W18 -> 6670 | H7: =SUM(C7:G7) -> 6670 | I7: =B7-C7 -> 10
A8: 上月垫付 | H8: =SUM(C8:G8) -> 0 | I8: =B8-C8 -> 0
A9: 4-11月工会费 | B9: ='202412'!AV6 -> 1157 | C9: =系统!F25 -> 1157 | H9: =SUM(C9:G9) -> 1157 | I9: =B9-C9 -> 0
A10: 工资扣5计入风险金 | C10: =2*5 -> 10 | H10: =SUM(C10:G10) -> 10 | I10: =B10-C10 -> -10
A11: 小计 | B11: =SUM(B2:B10) -> 16299.4 | C11: =SUM(C2:C10) -> 16299.4 | F11: =F9 -> 0 | G11: =G9 -> 0 | H11: =SUM(C11:G11) -> 16299.4
A12: 附加税
A13: 增值税 | D13: =ROUND((D11+D12)*6%,2) -> 0 | F13: =ROUND((F11+F12)*6%,2) -> 0 | G13: =ROUND((G11+G12)*6%,2) -> 0 | H13: =SUM(C13:G13) -> 0
A14: 总计 | B14: =SUM(B11:B13) -> 16299.4 | C14: =SUM(C11:C13) -> 16299.4 | D14: =SUM(D11:D13) -> 0 | F14: =SUM(F11:F13) -> 0 | G14: =SUM(G11:G13) -> 0 | H14: =SUM(C14:G14) -> 16299.4
A15: 给客户账单金额 | H15: =B14 -> 16299.4
A16: 差异 | H16: =H15-H14 -> 0
A17: 不含税差异 | H17: =ROUND(H16/1.06,2) -> 0

Sheet 系统
A1: 200070
A2: 寄：梅园路77号人才大厦
B3: 中国电信股份有限公司上海分公司 王慧珏 收
D6: 上海外服布列吉科技有限公司
C7: Shanghai Foreign Service Bridge Technology Co,Ltd.
E9: 收款通知书
E10: ADVISE ON COLLECTION
E11: 2024年12月
A13: 公司名称：中国电信股份有限公司上海分公司 | J13: 帐单号：202412CH6596305
A14: 序号 | B14: 姓名 | C14: 发生年月 | D14: 入职日期 | E14: 管理费 | F14: 当月社保基数 | G14: 当月公积金基数 | H14: 社保类 公司支付 Social Insurance Premiums Paid by Employer | N14: 公积金类 公司支付 Provident Fund Paid by Employer | O14: 公司合计 | P14: 社保类 个人支付 Social Insurance Premiums Paid by Employee | U14: 公积金类 个人支付 Provident Fund Paid by Employee | V14: 个人合计 | W14: 代办薪酬 | X14: 其他 | Y14: 总计 | Z14: 备注 | AA14: 外服工号 | AB14: 证件号码 | AC14: 应纳税金额 | AD14: 税率 | AE14: 增值税
A15: S/N | B15: Name | C15: YYYYMM | D15: Employment Start Date | E15: Adm Fee | F15: Social Insurance Base Amount of Current Month | G15: Provident Fund Base Amount of Current Month | H15: 养老保险 Endowment | I15: 医疗保险 Medical | J15: 失业保险 Unemploy-ment | K15: 工伤保险 Employment Injury | L15: 医疗生育保险 Medical Maternity | M15: 保障金 Disabled people&Back pay Fund | N15: 公积金 Provident Fund | O15: Subtotal of Employer Payment | P15: 养老保险 Endowment | Q15: 医疗保险 Medical | R15: 失业保险 Unemploy-ment | S15: 工伤保险 Employment Injury | T15: 医疗生育保险 Medical Maternity | U15: 公积金 Provident Fund | V15: Subtotal of Personal Payment | W15: Agency of Wage Payment | X15: Others | Y15: Total | Z15: Remarks | AA15: SFSC ID | AB15: ID Card | AC15: Taxable Amount | AD15: Tax Rate | AE15: VAT
A16: 1 | B16: 傅强 | C16: 202412 | D16: 2024-06-01 | E16: 485.69 | F16: 7384 | G16: 6520 | H16: 1181.44 | I16: 664.56 | J16: 36.92 | K16: 18.9 | M16: 110.76 | N16: 456 | O16: =SUM(H16:N16) -> 2468.58 | P16: 590.72 | Q16: 147.68 | R16: 36.92 | U16: 456 | V16: =SUM(P16:U16) -> 1231.32 | W16: 3335 | Y16: =SUM(E16,O16,V16:X16) -> 7520.59 | AA16: 6031699 | AB16: 342501197805270274 | AC16: 7094.89 | AD16: 6% | AE16: 425.7
A17: 2 | B17: 汤熙荣 | C17: 202412 | D17: 2024-04-01 | E17: 486.89 | F17: 7384 | G17: 6653 | H17: 1181.44 | I17: 664.56 | J17: 36.92 | K17: 18.9 | M17: 110.76 | N17: 466 | O17: =SUM(H17:N17) -> 2478.58 | P17: 590.72 | Q17: 147.68 | R17: 36.92 | U17: 466 | V17: =SUM(P17:U17) -> 1241.32 | W17: 3335 | Y17: =SUM(E17,O17,V17:X17) -> 7541.79 | AA17: 5987320 | AB17: 310108197210073613 | AC17: 7114.89 | AD17: 6% | AE17: 426.9
A18: 合计（RMB） | E18: =SUM(E16:E17) -> 972.58 | H18: =SUM(H16:H17) -> 2362.88 | I18: =SUM(I16:I17) -> 1329.12 | J18: =SUM(J16:J17) -> 73.84 | K18: =SUM(K16:K17) -> 37.8 | L18: =SUM(L16:L17) -> 0 | M18: =SUM(M16:M17) -> 221.52 | N18: =SUM(N16:N17) -> 922 | O18: =SUM(O16:O17) -> 4947.16 | ... Y18: =SUM(Y16:Y17) -> 15062.38 | AC18: =SUM(AC16:AC17) -> 14209.78 | AE18: =SUM(AE16:AE17) -> 852.6
A19: 总计（RMB）已包含历月补收人民币壹万伍仟零陆拾贰圆叁角捌分 | Y19: 15062.38
A21: 其他费用
A22: 序号 | B22: 发生年月 | C22: 费用项目 | D22: 金额 | E22: 备注 | F22: 应纳税金额 | G22: 税率 | H22: 增值税
A23: S/N | B23: YYYYMM | C23: Item | D23: Amount | E23: Remarks | F23: Taxable Amount | G23: Tax Rate | H23: VAT | R23: =Y19+D28 -> 16299.4
A24: 1 | B24: 202412 | C24: 风险金 | D24: 10.6 | F24: 10 | G24: 0.06 | H24: 0.6
A25: 2 | B25: 202412 | C25: 服务费 | D25: 1226.42 | F25: 1157 | G25: 0.06 | H25: 69.42
A26: 3 | B26: 202412 | C26: 税差调整6% | D26: 0 | F26: 0.01 | G26: 0.06 | H26: -0.01
A27: 合计（RMB） | D27: =SUM(D24:D26) -> 1237.02 | F27: =SUM(F24:F26) -> 1167.01 | H27: =SUM(H24:H26) -> 70.01
A28: 总计（RMB）人民币壹仟贰佰叁拾柒圆零贰分 | D28: 1237.02 | F28: 1167.01 | H28: 70.01
A30: 增值税：
A31: 序号 S/N | B31: 应纳税额 | C31: 税率 | D31: 税金
A33: 1 | B33: 15376.79 | C33: 6% | D33: 922.61
A34: 小计（RMB） | B34: 15376.79 | D34: 922.61
A35: 总计(RMB) | D35: 922.61
A36: 本次价税合计(RMB):人民币壹万陆仟贰佰玖拾玖圆肆角整
A37: 16299.4
A38: 本月价税合计（RMB）：16299.40 其中已开票16299.40
A40: 本月总计（RMB）人民币壹万陆仟贰佰玖拾玖圆肆角整 ￥16299.40
A42: 制单人： | J42: 制单日期：2024-12-20
A44: 户名：上海外服（集团）有限公司 | G44: 户名：上海外服（集团）有限公司
A45: 美金收款账号：449459237031 | G45: 外币/人民币收款账号：083651120100303014006
A46: 开户银行：中国银行上海市分行 | G46: 开户银行：中国光大银行上海分行营业部
A47: SWIFT CODE：BKCHCNBJ300 | G47: SWIFT CODE：EVERCNBJSH1
A48: 地址：中国上海市黄浦区中山东一路23号 | G48: 地址：中国上海市浦东新区世纪大道1118号
A50: 户名：上海外服（集团）有限公司
A51: 外币/人民币收款账号：1001244329006580566
...
