Workbook

Sheet 202412
A1: 序号 | B1: 计薪 周期 | C1: 工号 | D1: 姓名 | E1: 身份证号 | F1: 劳动合同起始日期 | G1: 劳动合同结束日期 | H1: 离职日期 | I1: 社保缴纳地 | J1: 星级费用 | K1: 考核费用 | L1: 量化费用 | M1: 专项费用 | Z1: 当月税前工资合计 | AA1: 社保基数(个人) | AB1: 养老保险(个人) | AC1: 医疗保险(个人) | AD1: 失业保险(个人) | AE1: 公积金基数(个人) | AF1: 住房公积金(个人) | AG1: 员工五险一金合计 | AH1: 本月个人所得税-系统导出 | AI1: 税后增加 | AJ1: 税后扣减 | AK1: 员工实发合计 | AL1: 社保基数 | AM1: 公积金基数 | AN1: 养老缴费 | AO1: 医疗缴费 | AP1: 失业保险 | AQ1: 工伤保险 | AR1: 生育保险 | AS1: 公积金 | AT1: 残保金 | AU1: 企业五险一金合计 | AV1: 工会费 | AW1: 代收付合计 | AX1: 供应商补差 | AY1: 社保备注 | AZ1: 外包服务费 | BA1: 税前项合计 | BB1: 增值税 | BC1: 总计
A2: NO. | B2: Salary Cycle | C2: Employee No. | D2: Name | E2: ID No. | F2: Contract Starting Date | G2: Contract Expiry Date | H2: Exit Date | I2: Social Insurance City | J2: Contract Salary | K2: Assessment fees | L2: Quantifying costs | M2: 支局专项 | N2: 部门加奖 | O2: 其他费用 | P2: 效能补贴 | Q2: 高温费及清凉饮料费 （6-9月） | R2: 伙食补贴 | S2: 独生子女奖励 | T2: 保险费 | U2: 体检费用 | V2: 补发费用 | W2: 劳防用品 | X2: 保障补差 | Y2: 其他扣款 | Z2: Pre-tax Total | AA2: Social Insurance Base | AB2: Pension Employee | AC2: Medical Employee | AD2: Umemployment Employee | AE2: Housing Fund Base | AF2: Housing Fund Employee | AG2: Total Amount of Social Insurance(EE) | AH2: Personal Income Tax | AI2: Increase After-tax payment | AJ2: Reduction After-tax payment | AK2: After-tax total Income | AL2: Social Insurance Base | AM2: Housing Fund Base | AN2: Pension Employer | AO2: Medical Employer | AP2: Umemployment Employer | AQ2: Injury Employer | AR2: Maternity Insurance Employer | AS2: Housing Fund Employer | AT2: Disabled people&Back pay Fund | AU2: Total Amount of Social Insurance(ER) | AV2: Union Fee | AW2: Payment Total | AY2: Social Security remark | AZ2: Service Fee | BA2: Total | BB2: VAT | BC2: Subtotal
A3: =ROW()-2 -> 1 | B3: 2412 | C3: WB023742 | D3: 陈翔宇 | E3: 421024199409102039 | F3: 45383 | G3: 45747 | I3: 上海 | J3: 1510 | K3: 1048.5 | L3: 798.07 | O3: 0 | R3: 630 | U3: 0 | W3: 150 | X3: 602.75 | Y3: -83 | Z3: =SUM(J3:Y3) -> 4656.32 | AA3: 7384 | AB3: 590.72 | AC3: 147.68 | AD3: 36.92 | AE3: 5865 | AF3: 411 | AG3: =AB3+AC3+AD3+AF3 -> 1186.32 | AK3: =Z3-AG3-AH3 -> 3470 | AL3: 7384 | AM3: 5865 | AN3: =ROUND(AL3*16%,2) -> 1181.44 | AO3: =ROUND(AL3*9%,2) -> 664.56 | AP3: =ROUND(AL3*0.5%,2) -> 36.92 | AQ3: =ROUND(AL3*0.256%,2) -> 18.9 | AS3: =ROUND(AM3*7%,0) -> 411 | AT3: =ROUND(IF(AL3<22792,AL3*1.5%,22792*1.5%),2) -> 110.76 | AU3: =SUM(AN3:AT3) -> 2423.58 | AV3: 78 | AW3: =AU3+Z3+AI3-AJ3+AV3 -> 7157.9 | AZ3: 255 | BA3: =ROUND(AW3+AZ3+AX3,2) -> 7412.9 | BB3: =ROUND(BA3*6%,2) -> 444.77 | BC3: =ROUND(SUM(BA3:BB3),2) -> 7857.67
A4: =ROW()-2 -> 2 | B4: 2412 | C4: WB053401 | D4: 汪思思 | E4: 362334198307140025 | F4: 45444 | G4: 45808 | I4: 上海 | J4: 900 | K4: 2446.56 | L4: 848.78 | O4: 989.43 | R4: 630 | U4: 0 | W4: 150 | X4: 0 | Y4: 0 | Z4: =SUM(J4:Y4) -> 5964.77 | AA4: 7384 | AB4: 590.72 | AC4: 147.68 | AD4: 36.92 | AE4: 6776 | AF4: 474 | AG4: =AB4+AC4+AD4+AF4 -> 1249.32 | AK4: =Z4-AG4-AH4 -> 4715.45 | AL4: 7384 | AM4: 6776 | AN4: =ROUND(AL4*16%,2) -> 1181.44 | AO4: =ROUND(AL4*9%,2) -> 664.56 | AP4: =ROUND(AL4*0.5%,2) -> 36.92 | AQ4: =ROUND(AL4*0.256%,2) -> 18.9 | AS4: =ROUND(AM4*7%,0) -> 474 | AT4: =ROUND(IF(AL4<22792,AL4*1.5%,22792*1.5%),2) -> 110.76 | AU4: =SUM(AN4:AT4) -> 2486.58 | AV4: 104 | AW4: =AU4+Z4+AI4-AJ4+AV4 -> 8555.35 | AZ4: 255 | BA4: =ROUND(AW4+AZ4+AX4,2) -> 8810.35 | BB4: =ROUND(BA4*6%,2) -> 528.62 | BC4: =ROUND(SUM(BA4:BB4),2) -> 9338.97
A5: =ROW()-2 -> 3 | B5: 2412 | C5: WB002504 | D5: 颜双徐 | E5: 31010919920227201X | F5: 45444 | G5: 45808 | I5: 上海 | J5: 1030 | K5: 2016 | L5: 1146.5 | O5: 989.43 | R5: 630 | U5: 0 | W5: 150 | X5: 995.5 | Y5: -45 | Z5: =SUM(J5:Y5) -> 6912.43 | AA5: 14019 | AB5: 1121.52 | AC5: 280.38 | AD5: 70.1 | AE5: 14019 | AF5: 981 | AG5: =AB5+AC5+AD5+AF5 -> 2453 | AK5: =Z5-AG5-AH5 -> 4459.43 | AL5: 14019 | AM5: 14019 | AN5: =ROUND(AL5*16%,2) -> 2243.04 | AO5: 1261.72 | AP5: =ROUND(AL5*0.5%,2) -> 70.1 | AQ5: =ROUND(AL5*0.256%,2) -> 35.89 | AS5: =ROUND(AM5*7%,0) -> 981 | AT5: =ROUND(IF(AL5<22792,AL5*1.5%,22792*1.5%),2) -> 210.29 | AU5: =SUM(AN5:AT5) -> 4802.04 | AV5: 123 | AW5: =AU5+Z5+AI5-AJ5+AV5 -> 11837.47 | AZ5: 255 | BA5: =ROUND(AW5+AZ5+AX5,2) -> 12092.47 | BB5: =ROUND(BA5*6%,2) -> 725.55 | BC5: =ROUND(SUM(BA5:BB5),2) -> 12818.02
A6: =ROW()-2 -> 4 | B6: 2412 | C6: WB047229 | D6: 曾娓 | E6: 362529198711200026 | F6: 45444 | G6: 45808 | I6: 上海 | J6: 1030 | K6: 2520 | L6: 1948.35 | O6: 989.43 | R6: 630 | U6: 0 | W6: 150 | X6: 0 | Y6: 0 | Z6: =SUM(J6:Y6) -> 7267.78 | AA6: 10618 | AB6: 849.44 | AC6: 212.36 | AD6: 53.09 | AE6: 10618 | AF6: 743 | AG6: =AB6+AC6+AD6+AF6 -> 1857.89 | AK6: =Z6-AG6-AH6 -> 5409.89 | AL6: 10618 | AM6: 10618 | AN6: =ROUND(AL6*16%,2) -> 1698.88 | AO6: =ROUND(AL6*9%,2) -> 955.62 | AP6: =ROUND(AL6*0.5%,2) -> 53.09 | AQ6: =ROUND(AL6*0.256%,2) -> 27.18 | AS6: =ROUND(AM6*7%,0) -> 743 | AT6: =ROUND(IF(AL6<22792,AL6*1.5%,22792*1.5%),2) -> 159.27 | AU6: =SUM(AN6:AT6) -> 3637.04 | AV6: 130 | AW6: =AU6+Z6+AI6-AJ6+AV6 -> 11034.82 | AZ6: 255 | BA6: =ROUND(AW6+AZ6+AX6,2) -> 11289.82 | BB6: =ROUND(BA6*6%,2) -> 677.39 | BC6: =ROUND(SUM(BA6:BB6),2) -> 11967.21
A7: =ROW()-2 -> 5 | B7: 2412 | C7: WB019304 | D7: 顾杰 | E7: 310225198410064814 | F7: 45444 | G7: 45808 | I7: 上海 | J7: 1300 | K7: 8820 | L7: 1583.01 | O7: 989.43 | R7: 630 | U7: 0 | W7: 150 | X7: 0 | Y7: 0 | Z7: =SUM(J7:Y7) -> 13472.44 | AA7: 18333 | AB7: 1466.64 | AC7: 366.66 | AD7: 91.67 | AE7: 18333 | AF7: 1283 | AG7: =AB7+AC7+AD7+AF7 -> 3207.97 | AK7: =Z7-AG7-AH7 -> 10264.47 | AL7: 18333 | AM7: 18333 | AN7: =ROUND(AL7*16%,2) -> 2933.28 | AO7: 1649.98 | AP7: =ROUND(AL7*0.5%,2) -> 91.67 | AQ7: =ROUND(AL7*0.256%,2) -> 46.93 | AS7: =ROUND(AM7*7%,0) -> 1283 | AT7: =ROUND(IF(AL7<22792,AL7*1.5%,22792*1.5%),2) -> 275 | AU7: =SUM(AN7:AT7) -> 6279.86 | AV7: 254 | AW7: =AU7+Z7+AI7-AJ7+AV7 -> 20006.3 | AZ7: 255 | BA7: =ROUND(AW7+AZ7+AX7,2) -> 20261.3 | BB7: =ROUND(BA7*6%,2) -> 1215.68 | BC7: =ROUND(SUM(BA7:BB7),2) -> 21476.98
A8: =ROW()-2 -> 6 | B8: 2412 | C8: WB038424 | D8: 赵俊 | E8: 310102198712184475 | F8: 45444 | G8: 45808 | I8: 上海 | J8: 1030 | K8: 2736 | L8: 1713.95 | O8: 989.43 | R8: 630 | U8: 0 | W8: 150 | X8: 0 | Y8: -118.4 | Z8: =SUM(J8:Y8) -> 7130.98 | AA8: 10115 | AB8: 809.2 | AC8: 202.3 | AD8: 50.58 | AE8: 10115 | AF8: 708 | AG8: =AB8+AC8+AD8+AF8 -> 1770.08 | AK8: =Z8-AG8-AH8 -> 5360.9 | AL8: 10115 | AM8: 10115 | AN8: =ROUND(AL8*16%,2) -> 1618.4 | AO8: 910.36 | AP8: =ROUND(AL8*0.5%,2) -> 50.58 | AQ8: =ROUND(AL8*0.256%,2) -> 25.89 | AS8: =ROUND(AM8*7%,0) -> 708 | AT8: =ROUND(IF(AL8<22792,AL8*1.5%,22792*1.5%),2) -> 151.73 | AU8: =SUM(AN8:AT8) -> 3464.96 | AV8: 127 | AW8: =AU8+Z8+AI8-AJ8+AV8 -> 10722.94 | AZ8: 255 | BA8: =ROUND(AW8+AZ8+AX8,2) -> 10977.94 | BB8: =ROUND(BA8*6%,2) -> 658.68 | BC8: =ROUND(SUM(BA8:BB8),2) -> 11636.62
A9: =ROW()-2 -> 7 | B9: 2412 | C9: WB013461 | D9: 陈斌 | E9: 310106198410231614 | F9: 45444 | G9: 45808 | I9: 上海 | J9: 1030 | K9: 1368 | L9: 565.2 | O9: 575.88 | R9: 630 | U9: 0 | W9: 150 | X9: 886.12 | Y9: 0 | Z9: =SUM(J9:Y9) -> 5205.2 | AA9: 7384 | AB9: 590.72 | AC9: 147.68 | AD9: 36.92 | AE9: 5487 | AF9: 384 | AG9: =AB9+AC9+AD9+AF9 -> 1159.32 | AK9: =Z9-AG9-AH9 -> 4045.88 | AL9: 7384 | AM9: 5487 | AN9: =ROUND(AL9*16%,2) -> 1181.44 | AO9: =ROUND(AL9*9%,2) -> 664.56 | AP9: =ROUND(AL9*0.5%,2) -> 36.92 | AQ9: =ROUND(AL9*0.256%,2) -> 18.9 | AS9: =ROUND(AM9*7%,0) -> 384 | AT9: =ROUND(IF(AL9<22792,AL9*1.5%,22792*1.5%),2) -> 110.76 | AU9: =SUM(AN9:AT9) -> 2396.58 | AV9: 89 | AW9: =AU9+Z9+AI9-AJ9+AV9 -> 7690.78 | AZ9: 255 | BA9: =ROUND(AW9+AZ9+AX9,2) -> 7945.78 | BB9: =ROUND(BA9*6%,2) -> 476.75 | BC9: =ROUND(SUM(BA9:BB9),2) -> 8422.53
A10: =ROW()-2 -> 8 | B10: 2412 | C10: WB050221 | D10: 胡颖琦 | E10: 310101197211151615 | F10: 45444 | G10: 45808 | I10: 上海 | J10: 950 | K10: 1080 | L10: 2008.2 | O10: 0 | R10: 630 | U10: 0 | W10: 150 | X10: 0 | Y10: 0 | Z10: =SUM(J10:Y10) -> 4818.2 | AA10: 7384 | AB10: 590.72 | AC10: 147.68 | AD10: 36.92 | AE10: 7234 | AF10: 506 | AG10: =AB10+AC10+AD10+AF10 -> 1281.32 | AK10: =Z10-AG10-AH10 -> 3536.88 | AL10: 7384 | AM10: 7234 | AN10: =ROUND(AL10*16%,2) -> 1181.44 | AO10: =ROUND(AL10*9%,2) -> 664.56 | AP10: =ROUND(AL10*0.5%,2) -> 36.92 | AQ10: =ROUND(AL10*0.256%,2) -> 18.9 | AS10: =ROUND(AM10*7%,0) -> 506 | AT10: =ROUND(IF(AL10<22792,AL10*1.5%,22792*1.5%),2) -> 110.76 | AU10: =SUM(AN10:AT10) -> 2518.58 | AV10: 81 | AW10: =AU10+Z10+AI10-AJ10+AV10 -> 7417.78 | AZ10: 255 | BA10: =ROUND(AW10+AZ10+AX10,2) -> 7672.78 | BB10: =ROUND(BA10*6%,2) -> 460.37 | BC10: =ROUND(SUM(BA10:BB10),2) -> 8133.15
A11: =ROW()-2 -> 9 | B11: 2412 | C11: WB003568 | D11: 陈敏 | E11: 330327198311300617 | F11: 45444 | G11: 45808 | I11: 上海 | J11: 1030 | K11: 2424 | L11: 1197.86 | O11: 0 | R11: 630 | U11: 0 | W11: 150 | X11: 0 | Y11: -231.26 | Z11: =SUM(J11:Y11) -> 5200.6 | AA11: 7384 | AB11: 590.72 | AC11: 147.68 | AD11: 36.92 | AE11: 6812 | AF11: 477 | AG11: =AB11+AC11+AD11+AF11 -> 1252.32 | AK11: =Z11-AG11-AH11 -> 3948.28 | AL11: 7384 | AM11: 6812 | AN11: =ROUND(AL11*16%,2) -> 1181.44 | AO11: =ROUND(AL11*9%,2) -> 664.56 | AP11: =ROUND(AL11*0.5%,2) -> 36.92 | AQ11: =ROUND(AL11*0.256%,2) -> 18.9 | AS11: =ROUND(AM11*7%,0) -> 477 | AT11: =ROUND(IF(AL11<22792,AL11*1.5%,22792*1.5%),2) -> 110.76 | AU11: =SUM(AN11:AT11) -> 2489.58 | AV11: 88 | AW11: =AU11+Z11+AI11-AJ11+AV11 -> 7778.18 | AZ11: 255 | BA11: =ROUND(AW11+AZ11+AX11,2) -> 8033.18 | BB11: =ROUND(BA11*6%,2) -> 481.99 | BC11: =ROUND(SUM(BA11:BB11),2) -> 8515.17
A12: =ROW()-2 -> 10 | B12: 2412 | C12: WB019309 | D12: 黄晓菲 | E12: 310114198604103821 | F12: 45444 | G12: 45808 | I12: 上海 | J12: 1300 | K12: 11960 | L12: 4610.44 | O12: 989.43 | R12: 630 | U12: 0 | W12: 150 | X12: 0 | Y12: -42.16 | Z12: =SUM(J12:Y12) -> 19597.71 | AA12: 19290 | AB12: 1543.2 | AC12: 385.8 | AD12: 96.45 | AE12: 19290 | AF12: 1350 | AG12: =AB12+AC12+AD12+AF12 -> 3375.45 | AK12: =Z12-AG12-AH12 -> 16222.26 | AL12: 19290 | AM12: 19290 | AN12: =ROUND(AL12*16%,2) -> 3086.4 | AO12: =ROUND(AL12*9%,2) -> 1736.1 | AP12: =ROUND(AL12*0.5%,2) -> 96.45 | AQ12: =ROUND(AL12*0.256%,2) -> 49.38 | AS12: =ROUND(AM12*7%,0) -> 1350 | AT12: =ROUND(IF(AL12<22792,AL12*1.5%,22792*1.5%),2) -> 289.35 | AU12: =SUM(AN12:AT12) -> 6607.68 | AV12: 376 | AW12: =AU12+Z12+AI12-AJ12+AV12 -> 26581.39 | AZ12: 255 | BA12: =ROUND(AW12+AZ12+AX12,2) -> 26836.39 | BB12: =ROUND(BA12*6%,2) -> 1610.18 | BC12: =ROUND(SUM(BA12:BB12),2) -> 28446.57
A13: =ROW()-2 -> 11 | B13: 2412 | C13: WB002502 | D13: 万珺 | E13: 310104199005144025 | F13: 45444 | G13: 45808 | I13: 上海 | J13: 1030 | K13: 2520 | L13: 1121.48 | O13: 989.43 | R13: 630 | U13: 0 | W13: 150 | X13: 0 | Y13: -390.82 | Z13: =SUM(J13:Y13) -> 6050.09 | AA13: 7384 | AB13: 590.72 | AC13: 147.68 | AD13: 36.92 | AE13: 6424 | AF13: 450 | AG13: =AB13+AC13+AD13+AF13 -> 1225.32 | AK13: =Z13-AG13-AH13 -> 4824.77 | AL13: 7384 | AM13: 6424 | AN13: =ROUND(AL13*16%,2) -> 1181.44 | AO13: =ROUND(AL13*9%,2) -> 664.56 | AP13: =ROUND(AL13*0.5%,2) -> 36.92 | AQ13: =ROUND(AL13*0.256%,2) -> 18.9 | AS13: =ROUND(AM13*7%,0) -> 450 | AT13: =ROUND(IF(AL13<22792,AL13*1.5%,22792*1.5%),2) -> 110.76 | AU13: =SUM(AN13:AT13) -> 2462.58 | AV13: 105 | AW13: =AU13+Z13+AI13-AJ13+AV13 -> 8617.67 | AZ13: 255 | BA13: =ROUND(AW13+AZ13+AX13,2) -> 8872.67 | BB13: =ROUND(BA13*6%,2) -> 532.36 | BC13: =ROUND(SUM(BA13:BB13),2) -> 9405.03
A14: =ROW()-2 -> 12 | B14: 2412 | C14: WB025262 | D14: 王俊 | E14: 310107197803012414 | F14: 45444 | G14: 45808 | I14: 上海 | J14: 1030 | K14: 3024 | L14: 2226.35 | O14: 989.43 | R14: 630 | U14: 0 | W14: 150 | X14: 0 | Y14: -2 | Z14: =SUM(J14:Y14) -> 8047.78 | AA14: 7384 | AB14: 590.72 | AC14: 147.68 | AD14: 36.92 | AE14: 5565 | AF14: 390 | AG14: =AB14+AC14+AD14+AF14 -> 1165.32 | AK14: =Z14-AG14-AH14 -> 6882.46 | AL14: 7384 | AM14: 5565 | AN14: =ROUND(AL14*16%,2) -> 1181.44 | AO14: =ROUND(AL14*9%,2) -> 664.56 | AP14: =ROUND(AL14*0.5%,2) -> 36.92 | AQ14: =ROUND(AL14*0.256%,2) -> 18.9 | AS14: =ROUND(AM14*7%,0) -> 390 | AT14: =ROUND(IF(AL14<22792,AL14*1.5%,22792*1.5%),2) -> 110.76 | AU14: =SUM(AN14:AT14) -> 2402.58 | AV14: 145 | AW14: =AU14+Z14+AI14-AJ14+AV14 -> 10595.36 | AZ14: 255 | BA14: =ROUND(AW14+AZ14+AX14,2) -> 10850.36 | BB14: =ROUND(BA14*6%,2) -> 651.02 | BC14: =ROUND(SUM(BA14:BB14),2) -> 11501.38
A15: =ROW()-2 -> 13 | B15: 2412 | C15: WB002503 | D15: 诸振 | E15: 310104198909022851 | F15: 45444 | G15: 45808 | I15: 上海 | J15: 1030 | K15: 2124 | L15: 969.92 | O15: 0 | R15: 630 | U15: 0 | W15: 150 | X15: 61.36 | Y15: -248.96 | Z15: =SUM(J15:Y15) -> 4716.32 | AA15: 7384 | AB15: 590.72 | AC15: 147.68 | AD15: 36.92 | AE15: 6727 | AF15: 471 | AG15: =AB15+AC15+AD15+AF15 -> 1246.32 | AK15: =Z15-AG15-AH15 -> 3470 | AL15: 7384 | AM15: 6727 | AN15: =ROUND(AL15*16%,2) -> 1181.44 | AO15: =ROUND(AL15*9%,2) -> 664.56 | AP15: =ROUND(AL15*0.5%,2) -> 36.92 | AQ15: =ROUND(AL15*0.256%,2) -> 18.9 | AS15: =ROUND(AM15*7%,0) -> 471 | AT15: =ROUND(IF(AL15<22792,AL15*1.5%,22792*1.5%),2) -> 110.76 | AU15: =SUM(AN15:AT15) -> 2483.58 | AV15: 79 | AW15: =AU15+Z15+AI15-AJ15+AV15 -> 7278.9 | AZ15: 255 | BA15: =ROUND(AW15+AZ15+AX15,2) -> 7533.9 | BB15: =ROUND(BA15*6%,2) -> 452.03 | BC15: =ROUND(SUM(BA15:BB15),2) -> 7985.93
A16: =ROW()-2 -> 14 | B16: 2412 | C16: WB053339 | D16: 李斌 | E16: 310107197703162810 | F16: 45444 | G16: 45808 | I16: 上海 | J16: 900 | K16: 1878 | L16: 902.58 | O16: 989.43 | R16: 630 | U16: 0 | W16: 150 | X16: 220.74 | Y16: 0 | Z16: =SUM(J16:Y16) -> 5670.75 | AA16: 7384 | AB16: 590.72 | AC16: 147.68 | AD16: 36.92 | AE16: 6228 | AF16: 436 | AG16: =AB16+AC16+AD16+AF16 -> 1211.32 | AK16: =Z16-AG16-AH16 -> 4459.43 | AL16: 7384 | AM16: 6228 | AN16: =ROUND(AL16*16%,2) -> 1181.44 | AO16: =ROUND(AL16*9%,2) -> 664.56 | AP16: =ROUND(AL16*0.5%,2) -> 36.92 | AQ16: =ROUND(AL16*0.256%,2) -> 18.9 | AS16: =ROUND(AM16*7%,0) -> 436 | AT16: =ROUND(IF(AL16<22792,AL16*1.5%,22792*1.5%),2) -> 110.76 | AU16: =SUM(AN16:AT16) -> 2448.58 | AV16: 98 | AW16: =AU16+Z16+AI16-AJ16+AV16 -> 8217.33 | AZ16: 255 | BA16: =ROUND(AW16+AZ16+AX16,2) -> 8472.33 | BB16: =ROUND(BA16*6%,2) -> 508.34 | BC16: =ROUND(SUM(BA16:BB16),2) -> 8980.67
A17: =ROW()-2 -> 15 | B17: 2412 | C17: WB053251 | D17: 李亮 | E17: 341222198207144154 | F17: 45444 | G17: 45808 | I17: 上海 | J17: 900 | K17: 2322.72 | L17: 2223.4 | O17: 989.43 | R17: 630 | U17: 0 | W17: 150 | X17: 60.65 | Y17: 0 | Z17: =SUM(J17:Y17) -> 7276.2 | AA17: 16093 | AB17: 1287.44 | AC17: 321.86 | AD17: 80.47 | AE17: 16093 | AF17: 1127 | AG17: =AB17+AC17+AD17+AF17 -> 2816.77 | AK17: =Z17-AG17-AH17 -> 4459.43 | AL17: 16093 | AM17: 16093 | AN17: =ROUND(AL17*16%,2) -> 2574.88 | AO17: 1448.38 | AP17: =ROUND(AL17*0.5%,2) -> 80.47 | AQ17: =ROUND(AL17*0.256%,2) -> 41.2 | AS17: =ROUND(AM17*7%,0) -> 1127 | AT17: =ROUND(IF(AL17<22792,AL17*1.5%,22792*1.5%),2) -> 241.4 | AU17: =SUM(AN17:AT17) -> 5513.33 | AV17: 130 | AW17: =AU17+Z17+AI17-AJ17+AV17 -> 12919.53 | AZ17: 255 | BA17: =ROUND(AW17+AZ17+AX17,2) -> 13174.53 | BB17: =ROUND(BA17*6%,2) -> 790.47 | BC17: =ROUND(SUM(BA17:BB17),2) -> 13965
A18: =ROW()-2 -> 16 | B18: 2412 | C18: WB029437 | D18: 王永其 | E18: 310114199401273219 | F18: 45444 | G18: 45808 | I18: 上海 | J18: 1030 | K18: 1897.5 | L18: 1176.39 | O18: 0 | R18: 630 | U18: 0 | W18: 150 | X18: 0 | Y18: -157.5 | Z18: =SUM(J18:Y18) -> 4726.39 | AA18: 7384 | AB18: 590.72 | AC18: 147.68 | AD18: 36.92 | AE18: 6661 | AF18: 466 | AG18: =AB18+AC18+AD18+AF18 -> 1241.32 | AK18: =Z18-AG18-AH18 -> 3485.07 | AL18: 7384 | AM18: 6661 | AN18: =ROUND(AL18*16%,2) -> 1181.44 | AO18: =ROUND(AL18*9%,2) -> 664.56 | AP18: =ROUND(AL18*0.5%,2) -> 36.92 | AQ18: =ROUND(AL18*0.256%,2) -> 18.9 | AS18: =ROUND(AM18*7%,0) -> 466 | AT18: =ROUND(IF(AL18<22792,AL18*1.5%,22792*1.5%),2) -> 110.76 | AU18: =SUM(AN18:AT18) -> 2478.58 | AV18: 79 | AW18: =AU18+Z18+AI18-AJ18+AV18 -> 7283.97 | AZ18: 255 | BA18: =ROUND(AW18+AZ18+AX18,2) -> 7538.97 | BB18: =ROUND(BA18*6%,2) -> 452.34 | BC18: =ROUND(SUM(BA18:BB18),2) -> 7991.31
A19: =ROW()-2 -> 17 | B19: 2412 | C19: WB002497 | D19: 张弘开 | E19: 310102199503181635 | F19: 45444 | G19: 45808 | I19: 上海 | J19: 950 | K19: 1905 | L19: 973.38 | O19: 0 | R19: 630 | U19: 0 | W19: 150 | X19: 265.8 | Y19: -162.86 | Z19: =SUM(J19:Y19) -> 4711.32 | AA19: 7384 | AB19: 590.72 | AC19: 147.68 | AD19: 36.92 | AE19: 6654 | AF19: 466 | AG19: =AB19+AC19+AD19+AF19 -> 1241.32 | AK19: =Z19-AG19-AH19 -> 3470 | AL19: 7384 | AM19: 6654 | AN19: =ROUND(AL19*16%,2) -> 1181.44 | AO19: =ROUND(AL19*9%,2) -> 664.56 | AP19: =ROUND(AL19*0.5%,2) -> 36.92 | AQ19: =ROUND(AL19*0.256%,2) -> 18.9 | AS19: =ROUND(AM19*7%,0) -> 466 | AT19: =ROUND(IF(AL19<22792,AL19*1.5%,22792*1.5%),2) -> 110.76 | AU19: =SUM(AN19:AT19) -> 2478.58 | AV19: 79 | AW19: =AU19+Z19+AI19-AJ19+AV19 -> 7268.9 | AZ19: 255 | BA19: =ROUND(AW19+AZ19+AX19,2) -> 7523.9 | BB19: =ROUND(BA19*6%,2) -> 451.43 | BC19: =ROUND(SUM(BA19:BB19),2) -> 7975.33
A20: =ROW()-2 -> 18 | B20: 2412 | C20: WB002499 | D20: 周浩帆 | E20: 440582198302042610 | F20: 45444 | G20: 45808 | I20: 上海 | J20: 1200 | K20: 5860 | L20: 1148.74 | O20: 0 | R20: 630 | U20: 0 | W20: 150 | X20: 0 | Y20: -275.2 | Z20: =SUM(J20:Y20) -> 8713.54 | AA20: 7923 | AB20: 633.84 | AC20: 158.46 | AD20: 39.62 | AE20: 7923 | AF20: 555 | AG20: =AB20+AC20+AD20+AF20 -> 1386.92 | AK20: =Z20-AG20-AH20 -> 7326.62 | AL20: 7923 | AM20: 7923 | AN20: =ROUND(AL20*16%,2) -> 1267.68 | AO20: 713.08 | AP20: =ROUND(AL20*0.5%,2) -> 39.62 | AQ20: =ROUND(AL20*0.256%,2) -> 20.28 | AS20: =ROUND(AM20*7%,0) -> 555 | AT20: =ROUND(IF(AL20<22792,AL20*1.5%,22792*1.5%),2) -> 118.85 | AU20: =SUM(AN20:AT20) -> 2714.51 | AV20: 159 | AW20: =AU20+Z20+AI20-AJ20+AV20 -> 11587.05 | AZ20: 255 | BA20: =ROUND(AW20+AZ20+AX20,2) -> 11842.05 | BB20: =ROUND(BA20*6%,2) -> 710.52 | BC20: =ROUND(SUM(BA20:BB20),2) -> 12552.57
A21: =ROW()-2 -> 19 | B21: 2412 | C21: WB044167 | D21: 高妮彬 | E21: 310107197911290905 | F21: 45444 | G21: 45808 | I21: 上海 | J21: 1030 | K21: 2548.8 | L21: 1399.86 | O21: 0 | R21: 630 | U21: 0 | W21: 150 | X21: 0 | Y21: -361.16 | Z21: =SUM(J21:Y21) -> 5397.5 | AA21: 7670 | AB21: 613.6 | AC21: 153.4 | AD21: 38.35 | AE21: 7670 | AF21: 537 | AG21: =AB21+AC21+AD21+AF21 -> 1342.35 | AK21: =Z21-AG21-AH21 -> 4055.15 | AL21: 7670 | AM21: 7670 | AN21: =ROUND(AL21*16%,2) -> 1227.2 | AO21: =ROUND(AL21*9%,2) -> 690.3 | AP21: =ROUND(AL21*0.5%,2) -> 38.35 | AQ21: =ROUND(AL21*0.256%,2) -> 19.64 | AS21: =ROUND(AM21*7%,0) -> 537 | AT21: =ROUND(IF(AL21<22792,AL21*1.5%,22792*1.5%),2) -> 115.05 | AU21: =SUM(AN21:AT21) -> 2627.54 | AV21: 92 | AW21: =AU21+Z21+AI21-AJ21+AV21 -> 8117.04 | AZ21: 255 | BA21: =ROUND(AW21+AZ21+AX21,2) -> 8372.04 | BB21: =ROUND(BA21*6%,2) -> 502.32 | BC21: =ROUND(SUM(BA21:BB21),2) -> 8874.36
A22: =ROW()-2 -> 20 | B22: 2412 | C22: WB013277 | D22: 顾恺凯 | E22: 310105198204080011 | F22: 45444 | G22: 45808 | I22: 上海 | J22: 1300 | K22: 6760 | L22: 701.86 | O22: 0 | R22: 630 | U22: 600 | W22: 150 | X22: 0 | Y22: -798.96 | Z22: =SUM(J22:Y22) -> 9342.9 | AA22: 9323 | AB22: 745.84 | AC22: 186.46 | AD22: 46.62 | AE22: 9323 | AF22: 653 | AG22: =AB22+AC22+AD22+AF22 -> 1631.92 | AK22: =Z22-AG22-AH22 -> 7710.98 | AL22: 9323 | AM22: 9323 | AN22: =ROUND(AL22*16%,2) -> 1491.68 | AO22: 839.08 | AP22: =ROUND(AL22*0.5%,2) -> 46.62 | AQ22: =ROUND(AL22*0.256%,2) -> 23.87 | AS22: =ROUND(AM22*7%,0) -> 653 | AT22: =ROUND(IF(AL22<22792,AL22*1.5%,22792*1.5%),2) -> 139.85 | AU22: =SUM(AN22:AT22) -> 3194.1 | AV22: 171 | AW22: =AU22+Z22+AI22-AJ22+AV22 -> 12708 | AZ22: 255 | BA22: =ROUND(AW22+AZ22+AX22,2) -> 12963 | BB22: =ROUND(BA22*6%,2) -> 777.78 | BC22: =ROUND(SUM(BA22:BB22),2) -> 13740.78
A23: =ROW()-2 -> 21 | B23: 2412 | C23: WB025394 | D23: 许晓春 | E23: 310104198302137214 | F23: 45444 | G23: 45808 | I23: 上海 | J23: 1000 | K23: 2026.8 | L23: 1362.63 | O23: 0 | R23: 630 | U23: 800 | W23: 150 | X23: 0 | Y23: -293.5 | Z23: =SUM(J23:Y23) -> 5675.93 | AA23: 7384 | AB23: 590.72 | AC23: 147.68 | AD23: 36.92 | AE23: 7055 | AF23: 494 | AG23: =AB23+AC23+AD23+AF23 -> 1269.32 | AK23: =Z23-AG23-AH23 -> 4406.61 | AL23: 7384 | AM23: 7055 | AN23: =ROUND(AL23*16%,2) -> 1181.44 | AO23: =ROUND(AL23*9%,2) -> 664.56 | AP23: =ROUND(AL23*0.5%,2) -> 36.92 | AQ23: =ROUND(AL23*0.256%,2) -> 18.9 | AS23: =ROUND(AM23*7%,0) -> 494 | AT23: =ROUND(IF(AL23<22792,AL23*1.5%,22792*1.5%),2) -> 110.76 | AU23: =SUM(AN23:AT23) -> 2506.58 | AV23: 98 | AW23: =AU23+Z23+AI23-AJ23+AV23 -> 8280.51 | AZ23: 255 | BA23: =ROUND(AW23+AZ23+AX23,2) -> 8535.51 | BB23: =ROUND(BA23*6%,2) -> 512.13 | BC23: =ROUND(SUM(BA23:BB23),2) -> 9047.64
A24: =ROW()-2 -> 22 | B24: 2412 | C24: WB013289 | D24: 张英 | E24: 310226197901044123 | F24: 45444 | G24: 45808 | I24: 上海 | J24: 1300 | K24: 2808 | L24: 1261.72 | O24: 0 | R24: 630 | U24: 1000 | W24: 150 | X24: 0 | Y24: -336.27 | Z24: =SUM(J24:Y24) -> 6813.45 | AA24: 14011 | AB24: 1120.88 | AC24: 280.22 | AD24: 70.06 | AE24: 14011 | AF24: 981 | AG24: =AB24+AC24+AD24+AF24 -> 2452.16 | AK24: =Z24-AG24-AH24 -> 4361.29 | AL24: 14011 | AM24: 14011 | AN24: =ROUND(AL24*16%,2) -> 2241.76 | AO24: 1261 | AP24: =ROUND(AL24*0.5%,2) -> 70.06 | AQ24: =ROUND(AL24*0.256%,2) -> 35.87 | AS24: =ROUND(AM24*7%,0) -> 981 | AT24: =ROUND(IF(AL24<22792,AL24*1.5%,22792*1.5%),2) -> 210.17 | AU24: =SUM(AN24:AT24) -> 4799.86 | AV24: 121 | AW24: =AU24+Z24+AI24-AJ24+AV24 -> 11734.31 | AZ24: 255 | BA24: =ROUND(AW24+AZ24+AX24,2) -> 11989.31 | BB24: =ROUND(BA24*6%,2) -> 719.36 | BC24: =ROUND(SUM(BA24:BB24),2) -> 12708.67
A25: =ROW()-2 -> 23 | B25: 2412 | C25: WB040885 | D25: 黄良剑 | E25: 362321198304151616 | F25: 45444 | G25: 45808 | I25: 上海 | J25: 800 | K25: 1770 | L25: 1209.4 | O25: 0 | R25: 630 | U25: 0 | W25: 150 | X25: 415.32 | Y25: -2.5 | Z25: =SUM(J25:Y25) -> 4972.22 | AA25: 8583 | AB25: 686.64 | AC25: 171.66 | AD25: 42.92 | AE25: 8583 | AF25: 601 | AG25: =AB25+AC25+AD25+AF25 -> 1502.22 | AK25: =Z25-AG25-AH25 -> 3470 | AL25: 8583 | AM25: 8583 | AN25: =ROUND(AL25*16%,2) -> 1373.28 | AO25: 772.48 | AP25: =ROUND(AL25*0.5%,2) -> 42.92 | AQ25: =ROUND(AL25*0.256%,2) -> 21.97 | AS25: =ROUND(AM25*7%,0) -> 601 | AT25: =ROUND(IF(AL25<22792,AL25*1.5%,22792*1.5%),2) -> 128.75 | AU25: =SUM(AN25:AT25) -> 2940.4 | AV25: 84 | AW25: =AU25+Z25+AI25-AJ25+AV25 -> 7996.62 | AZ25: 255 | BA25: =ROUND(AW25+AZ25+AX25,2) -> 8251.62 | BB25: =ROUND(BA25*6%,2) -> 495.1 | BC25: =ROUND(SUM(BA25:BB25),2) -> 8746.72
A26: =ROW()-2 -> 24 | B26: 2412 | C26: WB063833 | D26: 张渊然 | E26: 310102197903070054 | F26: 45444 | G26: 45808 | I26: 上海 | J26: 900 | K26: 1791 | L26: 1744.3 | O26: 989.43 | R26: 630 | U26: 0 | W26: 150 | X26: 0 | Y26: -4.95 | Z26: =SUM(J26:Y26) -> 6199.78 | AA26: 7384 | AB26: 590.72 | AC26: 147.68 | AD26: 36.92 | AE26: 2690 | AF26: 188 | AG26: =AB26+AC26+AD26+AF26 -> 963.32 | AK26: =Z26-AG26-AH26 -> 5236.46 | AL26: 7384 | AM26: 2690 | AN26: =ROUND(AL26*16%,2) -> 1181.44 | AO26: =ROUND(AL26*9%,2) -> 664.56 | AP26: =ROUND(AL26*0.5%,2) -> 36.92 | AQ26: =ROUND(AL26*0.256%,2) -> 18.9 | AS26: =ROUND(AM26*7%,0) -> 188 | AT26: =ROUND(IF(AL26<22792,AL26*1.5%,22792*1.5%),2) -> 110.76 | AU26: =SUM(AN26:AT26) -> 2200.58 | AV26: 108 | AW26: =AU26+Z26+AI26-AJ26+AV26 -> 8508.36 | AZ26: 255 | BA26: =ROUND(AW26+AZ26+AX26,2) -> 8763.36 | BB26: =ROUND(BA26*6%,2) -> 525.8 | BC26: =ROUND(SUM(BA26:BB26),2) -> 9289.16
A27: =ROW()-2 -> 25 | B27: 2412 | C27: WB050054 | D27: 郑克铭 | E27: 31010119770301561X | F27: 45474 | G27: 45900 | I27: 上海 | J27: 800 | K27: 2760 | L27: 1722.8 | O27: 989.43 | R27: 630 | U27: 0 | W27: 150 | X27: 0 | Y27: 0 | Z27: =SUM(J27:Y27) -> 7052.23 | AA27: 12197 | AB27: 975.76 | AC27: 243.94 | AD27: 60.99 | AE27: 12197 | AF27: 854 | AG27: =AB27+AC27+AD27+AF27 -> 2134.69 | AK27: =Z27-AG27-AH27 -> 4917.54 | AL27: 12197 | AM27: 12197 | AN27: =ROUND(AL27*16%,2) -> 1951.52 | AO27: 1097.74 | AP27: =ROUND(AL27*0.5%,2) -> 60.99 | AQ27: =ROUND(AL27*0.256%,2) -> 31.22 | AS27: =ROUND(AM27*7%,0) -> 854 | AT27: =ROUND(IF(AL27<22792,AL27*1.5%,22792*1.5%),2) -> 182.96 | AU27: =SUM(AN27:AT27) -> 4178.43 | AV27: 125 | AW27: =AU27+Z27+AI27-AJ27+AV27 -> 11355.66 | AZ27: 255 | BA27: =ROUND(AW27+AZ27+AX27,2) -> 11610.66 | BB27: =ROUND(BA27*6%,2) -> 696.64 | BC27: =ROUND(SUM(BA27:BB27),2) -> 12307.3
A29: 合计 | Z29: =SUBTOTAL(9,Z3:Z27) -> 175592.83 | AG29: =SUBTOTAL(9,AG3:AG27) -> 41623.58 | AK29: =SUBTOTAL(9,AK2:AK27) -> 133969.25 | AU29: =SUBTOTAL(9,AU3:AU27) -> 82536.29 | AV29: =SUM(AV3:AV27) -> 3123 | AW29: =SUBTOTAL(9,AW3:AW27) -> 261252.12 | AX29: =SUBTOTAL(9,AX3:AX27) -> 0 | AZ29: =SUBTOTAL(9,AZ3:AZ27) -> 6375 | BA29: =SUBTOTAL(9,BA3:BA27) -> 267627.12 | BB29: =SUBTOTAL(9,BB3:BB27) -> 16057.62 | BC29: =SUBTOTAL(9,BC3:BC27) -> 283684.74
AV30: 29701
AZ31: 实际结算
AZ32: 差额下月补
AV33: =AV29+AV30 -> 32824

Sheet 对账单
A1: 科目 | B1: 手工账单 | C1: 速创账单 | D1: 155 | E1: 系统已有金额（不做一次性） | F1: 4-11月工会费 | G1: 12月工会费 | H1: 合计 | I1: 差异
A2: 管理费 | B2: ='202412'!BB29+B10*0.06 -> 17839.68 | C2: =系统!E41 -> 18130.23 | H2: =SUM(C2:G2) -> 18130.23 | I2: =B2-C2 -> -290.55
A3: 风险费 | B3: ='202412'!AZ29 -> 6375 | C3: 0 | D3: =25*155 -> 3875 | H3: =SUM(C3:G3) -> 3875 | I3: =B3-C3 -> 6375
A4: 个人四金 | B4: ='202412'!AG29 -> 41623.58 | C4: =系统!V41 -> 41623.58 | H4: =SUM(C4:G4) -> 41623.58 | I4: =B4-C4 -> 0
A5: 公司四金 | B5: ='202412'!AU29 -> 82536.29 | C5: =系统!O41 -> 82536.29 | H5: =SUM(C5:E5) -> 82536.29 | I5: =B5-C5 -> 0
A6: 残保金 | H6: =SUM(C6:G6) -> 0 | I6: =B6-C6 -> 0
A7: 代发工资 | B7: ='202412'!Z29-'202412'!AG29 -> 133969.25 | C7: =系统!W41 -> 133844.25 | D7: =5*25+0.01 -> 125.01 | H7: =SUM(C7:G7) -> 133969.26 | I7: =B7-C7 -> 125
A8: 上月垫付 | H8: =SUM(C8:G8) -> 0 | I8: =B8-C8 -> 0
A9: 12月工会费 | B9: ='202412'!AV29 -> 3123 | F9: =B10 -> 29701 | G9: =B9 -> 3123 | H9: =SUM(C9:G9) -> 32824 | I9: =B9-C9 -> 3123
A10: 4-11月工会费 | B10: ='202412'!AV30 -> 29701 | H10: =SUM(C10:G10) -> 0 | I10: =B10-C10 -> 29701
A11: 小计 | B11: =SUM(B2:B10) -> 315167.8 | C11: =SUM(C2:C10) -> 276134.35 | D11: =SUM(D2:D10) -> 4000.01 | F11: =F9 -> 29701 | G11: =G9 -> 3123 | H11: =SUM(C11:G11) -> 312958.36
A12: 附加税
A13: 增值税 | D13: =ROUND((D11+D12)*6%,2) -> 240 | F13: =ROUND((F11+F12)*6%,2) -> 1782.06 | G13: =ROUND((G11+G12)*6%,2) -> 187.38 | H13: =SUM(C13:G13) -> 2209.44
A14: 总计 | B14: =SUM(B11:B13) -> 315167.8 | C14: =SUM(C11:C13) -> 276134.35 | D14: =SUM(D11:D13) -> 4240.01 | F14: =SUM(F11:F13) -> 31483.06 | G14: =SUM(G11:G13) -> 3310.38 | H14: =SUM(C14:G14) -> 315167.8
A15: 给客户账单金额 | H15: =B14 -> 315167.8
A16: 差异 | H16: =H15-H14 -> 0
A17: 不含税差异 | H17: =ROUND(H16/1.06,2) -> 0
A19: 备注（工会费已+，差风险金）

Sheet 系统
A1: 200070
A2: 寄：梅园路77号人才大厦
B3: 中国电信股份有限公司上海分公司 王慧珏 收
D6: 上海外服布列吉科技有限公司
C7: Shanghai Foreign Service Bridge Technology Co,Ltd.
E9: 收款通知书
E10: ADVISE ON COLLECTION
E11: 2024年12月
A13: 公司名称：中国电信股份有限公司上海分公司 | J13: 帐单号：202412CH6596104
A14: 序号 | B14: 姓名 | C14: 发生年月 | D14: 入职日期 | E14: 管理费 | F14: 当月社保基数 | G14: 当月公积金基数 | H14: 社保类 公司支付 Social Insurance Premiums Paid by Employer | N14: 公积金类 公司支付 Provident Fund Paid by Employer | O14: 公司合计 | P14: 社保类 个人支付 Social Insurance Premiums Paid by Employee | U14: 公积金类 个人支付 Provident Fund Paid by Employee | V14: 个人合计 | W14: 代办薪酬 | X14: 其他 | Y14: 总计 | Z14: 备注 | AA14: 外服工号 | AB14: 证件号码 | AC14: 应纳税金额 | AD14: 税率 | AE14: 增值税
A15: S/N | B15: Name | C15: YYYYMM | D15: Employment Start Date | E15: Adm Fee | F15: Social Insurance Base Amount of Current Month | G15: Provident Fund Base Amount of Current Month | H15: 养老保险 Endowment | I15: 医疗保险 Medical | J15: 失业保险 Unemploy-ment | K15: 工伤保险 Employment Injury | L15: 医疗生育保险 Medical Maternity | M15: 保障金 Disabled people&Back pay Fund | N15: 公积金 Provident Fund | O15: Subtotal of Employer Payment | P15: 养老保险 Endowment | Q15: 医疗保险 Medical | R15: 失业保险 Unemploy-ment | S15: 工伤保险 Employment Injury | T15: 医疗生育保险 Medical Maternity | U15: 公积金 Provident Fund | V15: Subtotal of Personal Payment | W15: Agency of Wage Payment | X15: Others | Y15: Total | Z15: Remarks | AA15: SFSC ID | AB15: ID Card | AC15: Taxable Amount | AD15: Tax Rate | AE15: VAT
A16: 1 | B16: 陈斌 | C16: 202412 | D16: 2024-06-01 | E16: 561.8 | F16: 7384 | G16: 5487 | H16: 1181.44 | I16: 664.56 | J16: 36.92 | K16: 18.9 | M16: 110.76 | N16: 384 | O16: =SUM(H16:N16) -> 2396.58 | P16: 590.72 | Q16: 147.68 | R16: 36.92 | U16: 384 | V16: =SUM(P16:U16) -> 1159.32 | W16: 4040.88 | Y16: =SUM(E16,O16,V16:X16) -> 8158.58 | AA16: 5570941 | AB16: 310106198410231614 | AC16: 7696.77 | AD16: 6% | AE16: 461.81
A17: 2 | B17: 陈敏 | C17: 202412 | D17: 2024-06-01 | E17: 567.11 | F17: 7384 | G17: 6812 | H17: 1181.44 | I17: 664.56 | J17: 36.92 | K17: 18.9 | M17: 110.76 | N17: 477 | O17: =SUM(H17:N17) -> 2489.58 | P17: 590.72 | Q17: 147.68 | R17: 36.92 | U17: 477 | V17: =SUM(P17:U17) -> 1252.32 | W17: 3943.28 | Y17: =SUM(E17,O17,V17:X17) -> 8252.29 | AA17: 5543037 | AB17: 330327198311300617 | AC17: 7785.17 | AD17: 6% | AE17: 467.12
A18: 3 | B18: 陈翔宇 | C18: 202412 | D18: 2024-04-01 | E18: 530.49 | F18: 7384 | G18: 5865 | H18: 1181.44 | I18: 664.56 | J18: 36.92 | K18: 18.9 | M18: 110.76 | N18: 411 | O18: =SUM(H18:N18) -> 2423.58 | P18: 590.72 | Q18: 147.68 | R18: 36.92 | U18: 411 | V18: =SUM(P18:U18) -> 1186.32 | W18: 3465 | Y18: =SUM(E18,O18,V18:X18) -> 7605.39 | AA18: 5687584 | AB18: 421024199409102039 | AC18: 7174.89 | AD18: 6% | AE18: 430.5
A19: 4 | B19: 高妮彬 | C19: 202412 | D19: 2024-06-01 | E19: 587.2 | F19: 7670 | G19: 7670 | H19: 1227.2 | I19: 690.3 | J19: 38.35 | K19: 19.64 | M19: 115.05 | N19: 537 | O19: =SUM(H19:N19) -> 2627.54 | P19: 613.6 | Q19: 153.4 | R19: 38.35 | U19: 537 | V19: =SUM(P19:U19) -> 1342.35 | W19: 4050.15 | Y19: =SUM(E19,O19,V19:X19) -> 8607.24 | AA19: 5545659 | AB19: 310107197911290905 | AC19: 8120.04 | AD19: 6% | AE19: 487.2
A20: 5 | B20: 顾杰 | C20: 202412 | D20: 2024-06-01 | E20: 1290.84 | F20: 18333 | G20: 18333 | H20: 2933.28 | I20: 1649.98 | J20: 91.67 | K20: 46.93 | M20: 275 | N20: 1283 | O20: =SUM(H20:N20) -> 6279.86 | P20: 1466.64 | Q20: 366.66 | R20: 91.67 | U20: 1283 | V20: =SUM(P20:U20) -> 3207.97 | W20: 10259.47 | Y20: =SUM(E20,O20,V20:X20) -> 21038.14 | AA20: 5570939 | AB20: 310225198410064814 | AC20: 19847.29 | AD20: 6% | AE20: 1190.85
A21: 6 | B21: 顾恺凯 | C21: 202412 | D21: 2024-06-01 | E21: 857.92 | F21: 9323 | G21: 9323 | H21: 1491.68 | I21: 839.08 | J21: 46.62 | K21: 23.87 | M21: 139.85 | N21: 653 | O21: =SUM(H21:N21) -> 3194.1 | P21: 745.84 | Q21: 186.46 | R21: 46.62 | U21: 653 | V21: =SUM(P21:U21) -> 1631.92 | W21: 7705.98 | Y21: =SUM(E21,O21,V21:X21) -> 13389.92 | AA21: 5545661 | AB21: 310105198204080011 | AC21: 12632 | AD21: 6% | AE21: 757.92
A22: 7 | B22: 胡颖琦 | C22: 202412 | D22: 2024-06-01 | E22: 545.9 | F22: 7384 | G22: 7234 | H22: 1181.44 | I22: 664.56 | J22: 36.92 | K22: 18.9 | M22: 110.76 | N22: 506 | O22: =SUM(H22:N22) -> 2518.58 | P22: 590.72 | Q22: 147.68 | R22: 36.92 | U22: 506 | V22: =SUM(P22:U22) -> 1281.32 | W22: 3531.88 | Y22: =SUM(E22,O22,V22:X22) -> 7877.68 | AA22: D05847 | AB22: 310101197211151615 | AC22: 7431.77 | AD22: 6% | AE22: 445.91
A23: 8 | B23: 黄良剑 | C23: 202412 | D23: 2024-06-01 | E23: 580.46 | F23: 8583 | G23: 8583 | H23: 1373.28 | I23: 772.48 | J23: 42.92 | K23: 21.97 | M23: 128.75 | N23: 601 | O23: =SUM(H23:N23) -> 2940.4 | P23: 686.64 | Q23: 171.66 | R23: 42.92 | U23: 601 | V23: =SUM(P23:U23) -> 1502.22 | W23: 3465 | Y23: =SUM(E23,O23,V23:X23) -> 8488.08 | AA23: 5780654 | AB23: 362321198304151616 | AC23: 8007.6 | AD23: 6% | AE23: 480.48
A24: 9 | B24: 黄晓菲 | C24: 202412 | D24: 2024-06-01 | E24: 1678.03 | F24: 19290 | G24: 19290 | H24: 3086.4 | I24: 1736.1 | J24: 96.45 | K24: 49.38 | M24: 289.35 | N24: 1350 | O24: =SUM(H24:N24) -> 6607.68 | P24: 1543.2 | Q24: 385.8 | R24: 96.45 | U24: 1350 | V24: =SUM(P24:U24) -> 3375.45 | W24: 16217.26 | Y24: =SUM(E24,O24,V24:X24) -> 27878.42 | AA24: 5543034 | AB24: 310114198604103821 | AC24: 26300.39 | AD24: 6% | AE24: 1578.03
A25: 10 | B25: 李斌 | C25: 202412 | D25: 2024-06-01 | E25: 592.86 | F25: 7384 | G25: 6228 | H25: 1181.44 | I25: 664.56 | J25: 36.92 | K25: 18.9 | M25: 110.76 | N25: 436 | O25: =SUM(H25:N25) -> 2448.58 | P25: 590.72 | Q25: 147.68 | R25: 36.92 | U25: 436 | V25: =SUM(P25:U25) -> 1211.32 | W25: 4454.43 | Y25: =SUM(E25,O25,V25:X25) -> 8707.19 | AA25: 5571016 | AB25: 310107197703162810 | AC25: 8214.32 | AD25: 6% | AE25: 492.87
A26: 11 | B26: 李亮 | C26: 202412 | D26: 2024-06-01 | E26: 873.08 | F26: 16093 | G26: 16093 | H26: 2574.88 | I26: 1448.38 | J26: 80.47 | K26: 41.2 | M26: 241.4 | N26: 1127 | O26: =SUM(H26:N26) -> 5513.33 | P26: 1287.44 | Q26: 321.86 | R26: 80.47 | U26: 1127 | V26: =SUM(P26:U26) -> 2816.77 | W26: 4454.43 | Y26: =SUM(E26,O26,V26:X26) -> 13657.61 | AA26: 5566064 | AB26: 341222198207144154 | AC26: 12884.54 | AD26: 6% | AE26: 773.07
A27: 12 | B27: 万珺 | C27: 202412 | D27: 2024-06-01 | E27: 616.46 | F27: 7384 | G27: 6424 | H27: 1181.44 | I27: 664.56 | J27: 36.92 | K27: 18.9 | M27: 110.76 | N27: 450 | O27: =SUM(H27:N27) -> 2462.58 | P27: 590.72 | Q27: 147.68 | R27: 36.92 | U27: 450 | V27: =SUM(P27:U27) -> 1225.32 | W27: 4819.77 | Y27: =SUM(E27,O27,V27:X27) -> 9124.13 | AA27: 5543035 | AB27: 310104199005144025 | AC27: 8607.66 | AD27: 6% | AE27: 516.47
... A40: 25 | B40: 诸振 | C40: 202412 | D40: 2024-06-01 | E40: 537.69 | F40: 7384 | G40: 6727 | H40: 1181.44 | I40: 664.56 | J40: 36.92 | K40: 18.9 | M40: 110.76 | N40: 471 | O40: =SUM(H40:N40) -> 2483.58 | P40: 590.72 | Q40: 147.68 | R40: 36.92 | U40: 471 | V40: =SUM(P40:U40) -> 1246.32 | W40: 3465 | Y40: =SUM(E40,O40,V40:X40) -> 7732.59 | AA40: 5543036 | AB40: 310104198909022851 | AC40: 7294.89 | AD40: 6% | AE40: 437.7
A41: 合计（RMB） | E41: =SUM(E16:E40) -> 18130.23 | H41: =SUM(H16:H40) -> 39066.72 | I41: =SUM(I16:I40) -> 21975.12 | J41: =SUM(J16:J40) -> 1220.88 | K41: =SUM(K16:K40) -> 625.02 | L41: =SUM(L16:L40) -> 0 | M41: =SUM(M16:M40) -> 3662.55 | N41: =SUM(N16:N40) -> 15986 | O41: =SUM(O16:O40) -> 82536.29 | ... Y41: =SUM(Y16:Y40) -> 276134.35 | AC41: =SUM(AC16:AC40) -> 260503.99 | AE41: =SUM(AE16:AE40) -> 15630.36
A42: 总计（RMB）已包含历月补收人民币贰拾柒万陆仟壹佰叁拾肆圆叁角伍分 | Y42: 276134.35
A44: 其他费用
A45: 序号 | B45: 发生年月 | C45: 费用项目 | D45: 金额 | E45: 备注 | F45: 应纳税金额 | G45: 税率 | H45: 增值税
A46: S/N | B46: YYYYMM | C46: Item | D46: Amount | E46: Remarks | F46: Taxable Amount | G46: Tax Rate | H46: VAT
A47: 1 | B47: 202412 | C47: 税差调整6% | D47: 0 | F47: 0.11 | G47: 0.06 | H47: -0.11
A48: 合计（RMB） | D48: =SUM(D47:D47) -> 0 | F48: =SUM(F47:F47) -> 0.11 | H48: =SUM(H47:H47) -> -0.11
A49: 总计（RMB）人民币零 | D49: 0 | F49: 0.11 | H49: -0.11
A51: 增值税：
A52: 序号 S/N | B52: 应纳税额 | C52: 税率 | D52: 税金
A54: 1 | B54: 260504.1 | C54: 6% | D54: 15630.25
A55: 小计（RMB） | B55: 260504.1 | D55: 15630.25
A56: 总计(RMB) | D56: 15630.25
A57: 本次价税合计(RMB):人民币贰拾柒万陆仟壹佰叁拾肆圆叁角伍分
A58: 276134.35
A59: 本月价税合计（RMB）：276134.35 其中已开票276134.35
...
