Workbook

Sheet Sheet1
A1: month | B1: bank_name | C1: bank_amount | D1: bank_account_no | E1: bank_page | F1: pdf_date | J1: 差异
A2: 2025-11 | B2: 田文洁 | C2: 12926.38 | D2: 6222620110057853716 | E2: 1 | F2: 202511 | G2: =_xlfn.XLOOKUP(B2,[1]总表!$C:$C,[1]总表!$E:$E) -> 12926.38 | H2: =C2-G2 -> 0 | I2: 中国电信
A3: 2025-11 | B3: 张慧 | C3: 4768.7 | D3: 6228480038486983679 | E3: 1 | F3: 202511 | G3: =_xlfn.XLOOKUP(B3,[1]总表!$C:$C,[1]总表!$E:$E) -> 4768.7 | H3: =C3-G3 -> 0 | I3: 中国电信
A4: 2025-11 | B4: 季开梅 | C4: 22092.13 | D4: 6222020101125555596 | E4: 1 | F4: 202511 | G4: =_xlfn.XLOOKUP(B4,[1]总表!$C:$C,[1]总表!$E:$E) -> 22092.13 | H4: =C4-G4 -> 0 | I4: 中国电信
A5: 2025-11 | B5: 周振军 | C5: 19572.3 | D5: 6222620110078353423 | E5: 1 | F5: 202511 | G5: =_xlfn.XLOOKUP(B5,[1]总表!$C:$C,[1]总表!$E:$E) -> 19572.3 | H5: =C5-G5 -> 0 | I5: 中国电信
A6: 2025-11 | B6: 吴洁娴 | C6: 6073 | D6: 6221882900066459637 | E6: 1 | F6: 202511 | G6: =_xlfn.XLOOKUP(B6,[1]总表!$C:$C,[1]总表!$E:$E) -> 6073 | H6: =C6-G6 -> 0 | I6: 政企
A7: 2025-11 | B7: 钱玲琳 | C7: 6186.16 | D7: 6221502900003262326 | E7: 1 | F7: 202511 | G7: =_xlfn.XLOOKUP(B7,[1]总表!$C:$C,[1]总表!$E:$E) -> 6186.16 | H7: =C7-G7 -> 0 | I7: 政企
A8: 2025-11 | B8: 程艳菁 | C8: 8957.27 | D8: 6221502900017673880 | E8: 1 | F8: 202511 | G8: =_xlfn.XLOOKUP(B8,[1]总表!$C:$C,[1]总表!$E:$E) -> 8957.27 | H8: =C8-G8 -> 0 | I8: 政企
A9: 2025-11 | B9: 蒋丹琴 | C9: 7407.17 | D9: 6217992900045085268 | E9: 1 | F9: 202511 | G9: =_xlfn.XLOOKUP(B9,[1]总表!$C:$C,[1]总表!$E:$E) -> 7407.17 | H9: =C9-G9 -> 0 | I9: 政企
A10: 2025-11 | B10: 袁雪燕 | C10: 5707.05 | D10: 6221502900005923305 | E10: 1 | F10: 202511 | G10: =_xlfn.XLOOKUP(B10,[1]总表!$C:$C,[1]总表!$E:$E) -> 5707.05 | H10: =C10-G10 -> 0 | I10: 政企
A11: 2025-11 | B11: 王仲炎 | C11: 6556.99 | D11: 6221802900001336749 | E11: 1 | F11: 202511 | G11: =_xlfn.XLOOKUP(B11,[1]总表!$C:$C,[1]总表!$E:$E) -> 6556.99 | H11: =C11-G11 -> 0 | I11: 政企
A12: 2025-11 | B12: 张荣熙 | C12: 8405.25 | D12: 6217992900058063186 | E12: 1 | F12: 202511 | G12: =_xlfn.XLOOKUP(B12,[1]总表!$C:$C,[1]总表!$E:$E) -> 8405.25 | H12: =C12-G12 -> 0 | I12: 中国电信
A13: 2025-11 | B13: 康梅 | C13: 9879.36 | D13: 6217992900053274135 | E13: 1 | F13: 202511 | G13: =_xlfn.XLOOKUP(B13,[1]总表!$C:$C,[1]总表!$E:$E) -> 9879.36 | H13: =C13-G13 -> 0 | I13: 中国电信
... A39: 2025-11 | B39: 唐溏 | C39: 6662.15 | D39: 6221502900019186089 | E39: 1 | F39: 202511 | G39: =_xlfn.XLOOKUP(B39,[1]总表!$C:$C,[1]总表!$E:$E) -> 6662.15 | H39: =C39-G39 -> 0 | I39: 政企
A40: 2025-11 | B40: 陈辰 | C40: 3642.2 | D40: 6217231001007288940 | E40: 2 | F40: 202511 | G40: 3642.2 | H40: =C40-G40 -> 0 | I40: 中国电信
A41: 2025-11 | B41: 周贵阳 | C41: 2740 | D41: 6222030302001187143 | E41: 2 | F41: 202511 | G41: =_xlfn.XLOOKUP(B41,[1]总表!$C:$C,[1]总表!$E:$E) -> #N/A | H41: =C41-G41 -> #N/A | I41: =_xlfn.XLOOKUP(B41,[2]总表!$E:$E,[2]总表!$A:$A) -> #N/A
A42: 2025-11 | B42: 丁黎 | C42: 13722.08 | D42: 6212261001070460297 | E42: 2 | F42: 202511 | G42: =_xlfn.XLOOKUP(B42,[1]总表!$C:$C,[1]总表!$E:$E) -> 13722.08 | H42: =C42-G42 -> 0 | I42: 中国电信
A43: 2025-11 | B43: 王君 | C43: 10707.98 | D43: 620522001034822512 | E43: 2 | F43: 202511 | G43: =_xlfn.XLOOKUP(B43,[1]总表!$C:$C,[1]总表!$E:$E) -> 10707.98 | H43: =C43-G43 -> 0 | I43: 中国电信
A44: 2025-11 | B44: 陈永明 | C44: 17632.95 | D44: 6222600110032067253 | E44: 2 | F44: 202511 | G44: =_xlfn.XLOOKUP(B44,[1]总表!$C:$C,[1]总表!$E:$E) -> 17632.95 | H44: =C44-G44 -> 0 | I44: 中国电信
A45: 2025-11 | B45: 陈琳 | C45: 5119.76 | D45: 6217001210004063275 | E45: 2 | F45: 202511 | G45: =_xlfn.XLOOKUP(B45,[1]总表!$C:$C,[1]总表!$E:$E) -> 5119.76 | H45: =C45-G45 -> 0 | I45: 中国电信
A46: 2025-11 | B46: 路春春 | C46: 660 | D46: 6222620110077780477 | E46: 2 | F46: 202511 | G46: =_xlfn.XLOOKUP(B46,[1]总表!$C:$C,[1]总表!$E:$E) -> 660 | H46: =C46-G46 -> 0 | I46: 中国电信
A47: 2025-11 | B47: 范俊伟 | C47: 4354 | D47: 62170012100075739654 | E47: 2 | F47: 202511 | G47: =_xlfn.XLOOKUP(B47,[1]总表!$C:$C,[1]总表!$E:$E) -> 4354 | H47: =C47-G47 -> 0 | I47: 中国电信
A48: 2025-11 | B48: 赵懿 | C48: 3937.2 | D48: 6222031001007240463 | E48: 2 | F48: 202511 | G48: =_xlfn.XLOOKUP(B48,[1]总表!$C:$C,[1]总表!$E:$E) -> 3937.2 | H48: =C48-G48 -> 0 | I48: 中国电信
A49: 2025-11 | B49: 俞建强 | C49: 4702.3 | D49: 6212261001053808942 | E49: 2 | F49: 202511 | G49: =_xlfn.XLOOKUP(B49,[1]总表!$C:$C,[1]总表!$E:$E) -> 4702.3 | H49: =C49-G49 -> 0 | I49: 中国电信
A50: 2025-11 | B50: 侯俊轩 | C50: 72 | D50: 6217900800004173371 | E50: 2 | F50: 202511 | G50: =_xlfn.XLOOKUP(B50,[1]总表!$C:$C,[1]总表!$E:$E) -> 72 | H50: =C50-G50 -> 0 | I50: 中国电信
A51: 2025-11 | B51: 万杜娟 | C51: 6152.1 | D51: 6222021001119086749 | E51: 2 | F51: 202511 | G51: =_xlfn.XLOOKUP(B51,[1]总表!$C:$C,[1]总表!$E:$E) -> 6152.1 | H51: =C51-G51 -> 0 | I51: 中国电信
A52: 2025-11 | B52: 闻蕾 | C52: 13382.5 | D52: 6222031001025704987 | E52: 2 | F52: 202511 | G52: =_xlfn.XLOOKUP(B52,[1]总表!$C:$C,[1]总表!$E:$E) -> 13382.5 | H52: =C52-G52 -> 0 | I52: 中国电信
A53: 2025-11 | B53: 周莹 | C53: 7649.32 | D53: 6222031001055282748 | E53: 2 | F53: 202511 | G53: =_xlfn.XLOOKUP(B53,[1]总表!$C:$C,[1]总表!$E:$E) -> 7649.32 | H53: =C53-G53 -> 0 | I53: 中国电信
... A83: 2025-11 | B83: 朱琳 | C83: 8749.92 | D83: 6222620110027019836 | E83: 3 | F83: 202511 | G83: =_xlfn.XLOOKUP(B83,[1]总表!$C:$C,[1]总表!$E:$E) -> 8749.92 | H83: =C83-G83 -> 0 | I83: 中国电信
A84: 2025-11 | B84: 韩璐 | C84: 2740 | D84: 6212263500009893476 | E84: 3 | F84: 202511 | G84: =_xlfn.XLOOKUP(B84,[1]总表!$C:$C,[1]总表!$E:$E) -> #N/A | H84: =C84-G84 -> #N/A | I84: =_xlfn.XLOOKUP(B84,[2]总表!$E:$E,[2]总表!$A:$A) -> #N/A
A85: 2025-11 | B85: 何金成 | C85: 2740 | D85: 6212263500033128659 | E85: 3 | F85: 202511 | G85: =_xlfn.XLOOKUP(B85,[1]总表!$C:$C,[1]总表!$E:$E) -> #N/A | H85: =C85-G85 -> #N/A | I85: =_xlfn.XLOOKUP(B85,[2]总表!$E:$E,[2]总表!$A:$A) -> #N/A
A86: 2025-11 | B86: 杨洁 | C86: 14765.11 | D86: 6228480038117786277 | E86: 3 | F86: 202511 | G86: 14765.11 | H86: =C86-G86 -> 0 | I86: 中国电信
A87: 2025-11 | B87: 丁瑜静 | C87: 4275.86 | D87: 6227001216160404749 | E87: 3 | F87: 202511 | G87: =_xlfn.XLOOKUP(B87,[1]总表!$C:$C,[1]总表!$E:$E) -> 4275.86 | H87: =C87-G87 -> 0 | I87: 中国电信
A88: 2025-11 | B88: 赵丽 | C88: 15955.18 | D88: 620522001034994352 | E88: 3 | F88: 202511 | G88: =_xlfn.XLOOKUP(B88,[1]总表!$C:$C,[1]总表!$E:$E) -> 15955.18 | H88: =C88-G88 -> 0 | I88: 中国电信
A89: 2025-11 | B89: 季漪岚 | C89: 3744.66 | D89: 620522001021746161 | E89: 3 | F89: 202511 | G89: =_xlfn.XLOOKUP(B89,[1]总表!$C:$C,[1]总表!$E:$E) -> 3744.66 | H89: =C89-G89 -> 0 | I89: 中国电信
A90: 2025-11 | B90: 朱晶晶 | C90: 5572.4 | D90: 6221802900008286103 | E90: 3 | F90: 202511 | G90: =_xlfn.XLOOKUP(B90,[1]总表!$C:$C,[1]总表!$E:$E) -> 5572.4 | H90: =C90-G90 -> 0 | I90: 中国电信
A91: 2025-11 | B91: 施泽龙 | C91: 3520 | D91: 6222620110026472754 | E91: 3 | F91: 202511 | G91: =_xlfn.XLOOKUP(B91,[1]总表!$C:$C,[1]总表!$E:$E) -> 3520 | H91: =C91-G91 -> 0 | I91: 中国电信
A92: 2025-11 | B92: 谈颐添 | C92: 3744.66 | D92: 6217001180085864802 | E92: 3 | F92: 202511 | G92: =_xlfn.XLOOKUP(B92,[1]总表!$C:$C,[1]总表!$E:$E) -> 3744.66 | H92: =C92-G92 -> 0 | I92: 中国电信
A93: 2025-11 | B93: 李王飞 | C93: 19731.79 | D93: 6217992900039713396 | E93: 3 | F93: 202511 | G93: =_xlfn.XLOOKUP(B93,[1]总表!$C:$C,[1]总表!$E:$E) -> 19731.79 | H93: =C93-G93 -> 0 | I93: 中国电信
A94: 2025-11 | B94: 储佳璐 | C94: 3754.24 | D94: 6217920196930106 | E94: 3 | F94: 202511 | G94: =_xlfn.XLOOKUP(B94,[1]总表!$C:$C,[1]总表!$E:$E) -> 3754.24 | H94: =C94-G94 -> 0 | I94: 中国电信
...
