Workbook

Sheet Sheet1
A1: month | B1: bank_name | C1: bank_amount | D1: bank_account_no | E1: bank_page | F1: pdf_date
A2: 2024-10 | B2: 徐梁 | C2: 7448.51 | D2: 4367421218504256577 | E2: 1 | F2: 202410 | G2: =_xlfn.XLOOKUP(B2,[1]总表!$B:$B,[1]总表!$I:$I) -> 7448.51 | H2: =C2-G2 -> 0 | I2: =_xlfn.XLOOKUP(B2,[1]总表!$B:$B,[1]总表!$E:$E) -> 中国电信-触点莘闵
A3: 2024-10 | B3: 陶君妮 | C3: 6007.13 | D3: 620522001031357736 | E3: 1 | F3: 202410 | G3: =_xlfn.XLOOKUP(B3,[1]总表!$B:$B,[1]总表!$I:$I) -> 6007.13 | H3: =C3-G3 -> 0 | I3: =_xlfn.XLOOKUP(B3,[1]总表!$B:$B,[1]总表!$E:$E) -> 中国电信-触点嘉定
A4: 2024-10 | B4: 沈静 | C4: 8318.97 | D4: 6212261001014535485 | E4: 1 | F4: 202410 | G4: =_xlfn.XLOOKUP(B4,[1]总表!$B:$B,[1]总表!$I:$I) -> 8318.97 | H4: =C4-G4 -> 0 | I4: =_xlfn.XLOOKUP(B4,[1]总表!$B:$B,[1]总表!$E:$E) -> 中国电信-触点崇明
A5: 2024-10 | B5: 袁伟 | C5: 6797.42 | D5: 620522001012262871 | E5: 1 | F5: 202410 | G5: =_xlfn.XLOOKUP(B5,[1]总表!$B:$B,[1]总表!$I:$I) -> 6797.42 | H5: =C5-G5 -> 0 | I5: =_xlfn.XLOOKUP(B5,[1]总表!$B:$B,[1]总表!$E:$E) -> 中国电信-触点浦东
A6: 2024-10 | B6: 陈慧 | C6: 11905.66 | D6: 6212261001100244257 | E6: 1 | F6: 202410 | G6: =_xlfn.XLOOKUP(B6,[1]总表!$B:$B,[1]总表!$I:$I) -> 11905.66 | H6: =C6-G6 -> 0 | I6: =_xlfn.XLOOKUP(B6,[1]总表!$B:$B,[1]总表!$E:$E) -> 中国电信-触点莘闵
A7: 2024-10 | B7: 孙治虹 | C7: 16929.91 | D7: 6212261001021036154 | E7: 1 | F7: 202410 | G7: =_xlfn.XLOOKUP(B7,[1]总表!$B:$B,[1]总表!$I:$I) -> 16929.91 | H7: =C7-G7 -> 0 | I7: =_xlfn.XLOOKUP(B7,[1]总表!$B:$B,[1]总表!$E:$E) -> 中国电信-触点浦东
A8: 2024-10 | B8: 曾娓 | C8: 13279.47 | D8: 620522001031378591 | E8: 1 | F8: 202410 | G8: =_xlfn.XLOOKUP(B8,[1]总表!$B:$B,[1]总表!$I:$I) -> 13279.47 | H8: =C8-G8 -> 0 | I8: =_xlfn.XLOOKUP(B8,[1]总表!$B:$B,[1]总表!$E:$E) -> 中国电信-触点南区
A9: 2024-10 | B9: 张玉美 | C9: 9552.36 | D9: 6212261001023879221 | E9: 1 | F9: 202410 | G9: =_xlfn.XLOOKUP(B9,[1]总表!$B:$B,[1]总表!$I:$I) -> 9552.36 | H9: =C9-G9 -> 0 | I9: =_xlfn.XLOOKUP(B9,[1]总表!$B:$B,[1]总表!$E:$E) -> 中国电信-触点崇明
A10: 2024-10 | B10: 曹国祯 | C10: 5797.94 | D10: 620522001010059642 | E10: 1 | F10: 202410 | G10: =_xlfn.XLOOKUP(B10,[1]总表!$B:$B,[1]总表!$I:$I) -> 5797.94 | H10: =C10-G10 -> 0 | I10: =_xlfn.XLOOKUP(B10,[1]总表!$B:$B,[1]总表!$E:$E) -> 中国电信-触点北区
A11: 2024-10 | B11: 姚嘉雯 | C11: 7800.19 | D11: 6212261001025158194 | E11: 1 | F11: 202410 | G11: =_xlfn.XLOOKUP(B11,[1]总表!$B:$B,[1]总表!$I:$I) -> 7800.19 | H11: =C11-G11 -> 0 | I11: =_xlfn.XLOOKUP(B11,[1]总表!$B:$B,[1]总表!$E:$E) -> 中国电信-触点崇明
A12: 2024-10 | B12: 聂俐敏 | C12: 6464.41 | D12: 620522001016484109 | E12: 1 | F12: 202410 | G12: =_xlfn.XLOOKUP(B12,[1]总表!$B:$B,[1]总表!$I:$I) -> 6464.41 | H12: =C12-G12 -> 0 | I12: =_xlfn.XLOOKUP(B12,[1]总表!$B:$B,[1]总表!$E:$E) -> 中国电信-触点浦东
A13: 2024-10 | B13: 孙雨萍 | C13: 7773.11 | D13: 6212261001099484328 | E13: 1 | F13: 202410 | G13: =_xlfn.XLOOKUP(B13,[1]总表!$B:$B,[1]总表!$I:$I) -> 7773.11 | H13: =C13-G13 -> 0 | I13: =_xlfn.XLOOKUP(B13,[1]总表!$B:$B,[1]总表!$E:$E) -> 中国电信-触点奉贤
... A25: 2024-10 | B25: 王俊 | C25: 12155.42 | D25: 620522001031179536 | E25: 1 | F25: 202410 | G25: =_xlfn.XLOOKUP(B25,[1]总表!$B:$B,[1]总表!$I:$I) -> 12155.42 | H25: =C25-G25 -> 0 | I25: =_xlfn.XLOOKUP(B25,[1]总表!$B:$B,[1]总表!$E:$E) -> 中国电信-触点南区
A26: 2024-10 | B26: 韩璐 | C26: 2690 | D26: 6212263500009893476 | E26: 1 | F26: 202410 | G26: =_xlfn.XLOOKUP(B26,[1]总表!$B:$B,[1]总表!$I:$I) -> #N/A | H26: =C26-G26 -> #N/A | I26: =_xlfn.XLOOKUP(B26,[1]总表!$B:$B,[1]总表!$E:$E) -> #N/A | J26: 未匹配到
A27: 2024-10 | B27: 牟金丽 | C27: 5173.64 | D27: 6217001180059480700 | E27: 1 | F27: 202410 | G27: =_xlfn.XLOOKUP(B27,[1]总表!$B:$B,[1]总表!$I:$I) -> 5173.64 | H27: =C27-G27 -> 0 | I27: =_xlfn.XLOOKUP(B27,[1]总表!$B:$B,[1]总表!$E:$E) -> 中国电信-触点松江
A28: 2024-10 | B28: 姚旭蒙 | C28: 3370 | D28: 6217001180060548800 | E28: 1 | F28: 202410 | G28: =_xlfn.XLOOKUP(B28,[1]总表!$B:$B,[1]总表!$I:$I) -> 3370 | H28: =C28-G28 -> 0 | I28: =_xlfn.XLOOKUP(B28,[1]总表!$B:$B,[1]总表!$E:$E) -> 中国电信-触点松江
A29: 2024-10 | B29: 何金成 | C29: 2690 | D29: 6212263500033128659 | E29: 1 | F29: 202410 | G29: =_xlfn.XLOOKUP(B29,[1]总表!$B:$B,[1]总表!$I:$I) -> #N/A | H29: =C29-G29 -> #N/A | I29: =_xlfn.XLOOKUP(B29,[1]总表!$B:$B,[1]总表!$E:$E) -> #N/A | J29: 未匹配到
A30: 2024-10 | B30: 封春燕 | C30: 14383.97 | D30: 6217001180061348812 | E30: 1 | F30: 202410 | G30: =_xlfn.XLOOKUP(B30,[1]总表!$B:$B,[1]总表!$I:$I) -> 14383.97 | H30: =C30-G30 -> 0 | I30: =_xlfn.XLOOKUP(B30,[1]总表!$B:$B,[1]总表!$E:$E) -> 中国电信-触点松江
A31: 2024-10 | B31: 华珺 | C31: 5379.95 | D31: 620522004003214554 | E31: 1 | F31: 202410 | G31: =_xlfn.XLOOKUP(B31,[1]总表!$B:$B,[1]总表!$I:$I) -> 5379.95 | H31: =C31-G31 -> 0 | I31: =_xlfn.XLOOKUP(B31,[1]总表!$B:$B,[1]总表!$E:$E) -> 中国电信-触点嘉定
A32: 2024-10 | B32: 万筱筱 | C32: 5687.15 | D32: 620522004003214562 | E32: 1 | F32: 202410 | G32: =_xlfn.XLOOKUP(B32,[1]总表!$B:$B,[1]总表!$I:$I) -> 5687.15 | H32: =C32-G32 -> 0 | I32: =_xlfn.XLOOKUP(B32,[1]总表!$B:$B,[1]总表!$E:$E) -> 中国电信-触点嘉定
A33: 2024-10 | B33: 黄晓菲 | C33: 19171.75 | D33: 620522001031179551 | E33: 1 | F33: 202410 | G33: =_xlfn.XLOOKUP(B33,[1]总表!$B:$B,[1]总表!$I:$I) -> 19171.75 | H33: =C33-G33 -> 0 | I33: =_xlfn.XLOOKUP(B33,[1]总表!$B:$B,[1]总表!$E:$E) -> 中国电信-触点南区
A34: 2024-10 | B34: 胡颖琦 | C34: 6445.69 | D34: 620522004003326879 | E34: 1 | F34: 202410 | G34: =_xlfn.XLOOKUP(B34,[1]总表!$B:$B,[1]总表!$I:$I) -> 6445.69 | H34: =C34-G34 -> 0 | I34: =_xlfn.XLOOKUP(B34,[1]总表!$B:$B,[1]总表!$E:$E) -> 中国电信-触点南区
A35: 2024-10 | B35: 张钦 | C35: 6680.6 | D35: 620522005005522852 | E35: 1 | F35: 202410 | G35: =_xlfn.XLOOKUP(B35,[1]总表!$B:$B,[1]总表!$I:$I) -> 6680.6 | H35: =C35-G35 -> 0 | I35: =_xlfn.XLOOKUP(B35,[1]总表!$B:$B,[1]总表!$E:$E) -> 中国电信-触点北区
A36: 2024-10 | B36: 赵俊 | C36: 9355.69 | D36: 620522001031179569 | E36: 1 | F36: 202410 | G36: =_xlfn.XLOOKUP(B36,[1]总表!$B:$B,[1]总表!$I:$I) -> 9355.69 | H36: =C36-G36 -> 0 | I36: =_xlfn.XLOOKUP(B36,[1]总表!$B:$B,[1]总表!$E:$E) -> 中国电信-触点南区
A37: 2024-10 | B37: 陈斌 | C37: 6224.18 | D37: 620522006221359897 | E37: 1 | F37: 202410 | G37: =_xlfn.XLOOKUP(B37,[1]总表!$B:$B,[1]总表!$I:$I) -> 6224.18 | H37: =C37-G37 -> 0 | I37: =_xlfn.XLOOKUP(B37,[1]总表!$B:$B,[1]总表!$E:$E) -> 中国电信-触点南区
A38: 2024-10 | B38: 刘志强 | C38: 9559.93 | D38: 6217001180063036928 | E38: 1 | F38: 202410 | G38: =_xlfn.XLOOKUP(B38,[1]总表!$B:$B,[1]总表!$I:$I) -> 9559.93 | H38: =C38-G38 -> 0 | I38: =_xlfn.XLOOKUP(B38,[1]总表!$B:$B,[1]总表!$E:$E) -> 中国电信-触点莘闵
A39: 2024-10 | B39: 李怡 | C39: 158.8 | D39: 620522007005038343 | E39: 1 | F39: 202410 | G39: =_xlfn.XLOOKUP(B39,[1]总表!$B:$B,[1]总表!$I:$I) -> 158.8 | H39: =C39-G39 -> 0 | I39: =_xlfn.XLOOKUP(B39,[1]总表!$B:$B,[1]总表!$E:$E) -> 中国电信-触点北区
A40: 2024-10 | B40: 杨叮 | C40: 4542.19 | D40: 620522001030541330 | E40: 2 | F40: 202410 | G40: =_xlfn.XLOOKUP(B40,[1]总表!$B:$B,[1]总表!$I:$I) -> 4542.19 | H40: =C40-G40 -> 0 | I40: =_xlfn.XLOOKUP(B40,[1]总表!$B:$B,[1]总表!$E:$E) -> 中国电信-触点嘉定
A41: 2024-10 | B41: 林建海 | C41: 3320 | D41: 6217001180015013777 | E41: 2 | F41: 202410 | G41: =_xlfn.XLOOKUP(B41,[1]总表!$B:$B,[1]总表!$I:$I) -> 3320 | H41: =C41-G41 -> 0 | I41: =_xlfn.XLOOKUP(B41,[1]总表!$B:$B,[1]总表!$E:$E) -> 中国电信-触点北区
... A101: 2024-10 | B101: 姚丽 | C101: 10835.88 | D101: 6222031001002082100 | E101: 3 | F101: 202410 | G101: =_xlfn.XLOOKUP(B101,[1]总表!$B:$B,[1]总表!$I:$I) -> 10835.88 | H101: =C101-G101 -> 0 | I101: =_xlfn.XLOOKUP(B101,[1]总表!$B:$B,[1]总表!$E:$E) -> 中国电信-触点浦东
A102: 2024-10 | B102: 晁文龙 | C102: 2690 | D102: 6222022712005457930 | E102: 3 | F102: 202410 | G102: =_xlfn.XLOOKUP(B102,[1]总表!$B:$B,[1]总表!$I:$I) -> #N/A | H102: =C102-G102 -> #N/A | I102: =_xlfn.XLOOKUP(B102,[1]总表!$B:$B,[1]总表!$E:$E) -> #N/A | J102: 未匹配到
A103: 2024-10 | B103: 高明 | C103: 6417.64 | D103: 6222021001134896361 | E103: 3 | F103: 202410 | G103: =_xlfn.XLOOKUP(B103,[1]总表!$B:$B,[1]总表!$I:$I) -> 6417.64 | H103: =C103-G103 -> 0 | I103: =_xlfn.XLOOKUP(B103,[1]总表!$B:$B,[1]总表!$E:$E) -> 中国电信-触点北区
A104: 2024-10 | B104: 沈明捷 | C104: 5592.86 | D104: 6226200207944613 | E104: 3 | F104: 202410 | G104: =_xlfn.XLOOKUP(B104,[1]总表!$B:$B,[1]总表!$I:$I) -> 5592.86 | H104: =C104-G104 -> 0 | I104: =_xlfn.XLOOKUP(B104,[1]总表!$B:$B,[1]总表!$E:$E) -> 中国电信-触点莘闵
A105: 2024-10 | B105: 万杜娟 | C105: 5563.63 | D105: 6222021001119086749 | E105: 3 | F105: 202410 | G105: =_xlfn.XLOOKUP(B105,[1]总表!$B:$B,[1]总表!$I:$I) -> 5563.63 | H105: =C105-G105 -> 0 | I105: =_xlfn.XLOOKUP(B105,[1]总表!$B:$B,[1]总表!$E:$E) -> 中国电信-触点崇明
A106: 2024-10 | B106: 许晓春 | C106: 3810.38 | D106: 6226200205546808 | E106: 3 | F106: 202410 | G106: =_xlfn.XLOOKUP(B106,[1]总表!$B:$B,[1]总表!$I:$I) -> 3810.38 | H106: =C106-G106 -> 0 | I106: =_xlfn.XLOOKUP(B106,[1]总表!$B:$B,[1]总表!$E:$E) -> 中国电信-触点南区
A107: 2024-10 | B107: 陆佩红 | C107: 3320 | D107: 6222021001116493633 | E107: 3 | F107: 202410 | G107: =_xlfn.XLOOKUP(B107,[1]总表!$B:$B,[1]总表!$I:$I) -> 3320 | H107: =C107-G107 -> 0 | I107: =_xlfn.XLOOKUP(B107,[1]总表!$B:$B,[1]总表!$E:$E) -> 中国电信-触点浦东
A108: 2024-10 | B108: 倪燕 | C108: 9268.74 | D108: 6222031001015360188 | E108: 3 | F108: 202410 | G108: =_xlfn.XLOOKUP(B108,[1]总表!$B:$B,[1]总表!$I:$I) -> 9268.74 | H108: =C108-G108 -> 0 | I108: =_xlfn.XLOOKUP(B108,[1]总表!$B:$B,[1]总表!$E:$E) -> 中国电信-触点浦东
A109: 2024-10 | B109: 顾恺凯 | C109: 10170.76 | D109: 6226220222317629 | E109: 3 | F109: 202410 | G109: =_xlfn.XLOOKUP(B109,[1]总表!$B:$B,[1]总表!$I:$I) -> 10170.76 | H109: =C109-G109 -> 0 | I109: =_xlfn.XLOOKUP(B109,[1]总表!$B:$B,[1]总表!$E:$E) -> 中国电信-触点南区
A110: 2024-10 | B110: 张弘开 | C110: 5691.9 | D110: 6222620110038336583 | E110: 3 | F110: 202410 | G110: =_xlfn.XLOOKUP(B110,[1]总表!$B:$B,[1]总表!$I:$I) -> 5691.9 | H110: =C110-G110 -> 0 | I110: =_xlfn.XLOOKUP(B110,[1]总表!$B:$B,[1]总表!$E:$E) -> 中国电信-触点南区
...
