Workbook

Sheet 202502
A1: 序号 | B1: 计薪 周期 | C1: 工号 | D1: 姓名 | E1: 身份证号 | F1: 劳动合同起始日期 | G1: 劳动合同结束日期 | H1: 离职日期 | I1: 社保缴纳地 | J1: 星级费用 | K1: 考核费用 | L1: 量化费用 | M1: 专项费用 | Z1: 当月税前工资合计 | AA1: 社保基数(个人) | AB1: 养老保险(个人) | AC1: 医疗保险(个人) | AD1: 失业保险(个人) | AE1: 公积金基数(个人) | AF1: 住房公积金(个人) | AG1: 员工五险一金合计 | AH1: 本月个人所得税-系统导出 | AI1: 税后增加 | AJ1: 税后扣减 | AK1: 员工实发合计 | AL1: 社保基数 | AM1: 公积金基数 | AN1: 养老缴费 | AO1: 医疗缴费 | AP1: 失业保险 | AQ1: 工伤保险 | AR1: 生育保险 | AS1: 公积金 | AT1: 残保金 | AU1: 企业五险一金合计 | AV1: 工会费 | AW1: 代收付合计 | AX1: 本月垫付下月收 | AY1: 本月多收下月退 | AZ1: 本月多收，下月退 | BA1: 社保备注 | BB1: 外包服务费 | BC1: 税前项合计 | BD1: 增值税 | BE1: 总计 | BF1: 保障补差公式
A2: NO. | B2: Salary Cycle | C2: Employee No. | D2: Name | E2: ID No. | F2: Contract Starting Date | G2: Contract Expiry Date | H2: Exit Date | I2: Social Insurance City | J2: Contract Salary | K2: Assessment fees | L2: Quantifying costs | M2: 支局专项 | N2: 1+1激励 | O2: 交通费 | P2: 效能补贴 | Q2: 高温费及清凉饮料费 （6-9月） | R2: 伙食补贴 | S2: 独生子女奖励 | T2: 保险费 | U2: 其他费用 | V2: 补发费用 | W2: 劳防用品 | X2: 保障补差 | Y2: 其他扣款 | Z2: Pre-tax Total | AA2: Social Insurance Base | AB2: Pension Employee | AC2: Medical Employee | AD2: Umemployment Employee | AE2: Housing Fund Base | AF2: Housing Fund Employee | AG2: Total Amount of Social Insurance(EE) | AH2: Personal Income Tax | AI2: Increase After-tax payment | AJ2: Reduction After-tax payment | AK2: After-tax total Income | AL2: Social Insurance Base | AM2: Housing Fund Base | AN2: Pension Employer | AO2: Medical Employer | AP2: Umemployment Employer | AQ2: Injury Employer | AR2: Maternity Insurance Employer | AS2: Housing Fund Employer | AT2: Disabled people&Back pay Fund | AU2: Total Amount of Social Insurance(ER) | AV2: Union Fee | AW2: Payment Total | BA2: Social Security remark | BB2: Service Fee | BC2: Total | BD2: VAT | BE2: Subtotal
A3: =ROW()-2 -> 1 | B3: 2502 | C3: WB016994 | D3: 王邹强 | E3: 310108198909220554 | F3: 45444 | G3: 45808 | I3: 上海 | J3: 1300 | K3: =4371.2-U3 -> 4371.2 | L3: 839.64 | R3: 630 | X3: =IF((SUM(J3:L3,U3,R3)-AG3)<3325,3325-(SUM(J3:L3,R3,U3)-AG3),"") | Z3: =SUM(J3:Y3) -> 7140.84 | AA3: 8707 | AB3: 696.56 | AC3: 174.14 | AD3: 43.54 | AE3: 8707 | AF3: =ROUND(AE3*7%,0) -> 609 | AG3: =AB3+AC3+AD3+AF3 -> 1523.24 | AK3: =Z3-AG3-AH3-AJ3 -> 5617.6 | AL3: 8707 | AM3: 8707 | AN3: =ROUND(AL3*16%,2) -> 1393.12 | AO3: 783.64 | AP3: =ROUND(AL3*0.5%,2) -> 43.54 | AQ3: 17.41 | AS3: =ROUND(AM3*7%,0) -> 609 | AT3: =ROUND(IF(AL3<24366,AL3*1.5%,24366*1.5%),2) -> 130.61 | AU3: =SUM(AN3:AT3) -> 2977.32 | AV3: =VLOOKUP(D3,[1]Sheet1!$F:$Q,12,0) -> 130 | AW3: =AU3+Z3+AI3-AJ3+AV3 -> 10248.16 | AY3: -4.88 | BA3: 工伤利率调整，1月多收2月退 | BB3: 255 | BC3: =ROUND(AW3+BB3+AX3+AY3+AZ3,2) -> 10498.28 | BD3: =ROUND(BC3*6%,2) -> 629.9 | BE3: =ROUND(SUM(BC3:BD3),2) -> 11128.18 | BF3: =IF((AK3-P3-Q3-R3-S3-T3-V3-W3)<2690,2690-(AK3-P3-Q3-R3-S3-T3-U3-W3),"")
A4: =ROW()-2 -> 2 | B4: 2502 | C4: WB022665 | D4: 熊伟 | E4: 310109198905074533 | F4: 45444 | G4: 45808 | I4: 上海 | J4: 1030 | K4: =974.4 -> 974.4 | L4: 369.54 | R4: 630 | X4: =IF((SUM(J4:L4,R4)-AG4)<3325,3325-(SUM(J4:L4,R4)-AG4),"") -> 1876.3 | Z4: =SUM(J4:Y4) -> 4880.24 | AA4: 8888 | AB4: 711.04 | AC4: 177.76 | AD4: 44.44 | AE4: 8888 | AF4: =ROUND(AE4*7%,0) -> 622 | AG4: =AB4+AC4+AD4+AF4 -> 1555.24 | AK4: =Z4-AG4-AH4-AJ4 -> 3325 | AL4: 8888 | AM4: 8888 | AN4: =ROUND(AL4*16%,2) -> 1422.08 | AO4: =ROUND(AL4*9%,2) -> 799.92 | AP4: =ROUND(AL4*0.5%,2) -> 44.44 | AQ4: 17.78 | AS4: =ROUND(AM4*7%,0) -> 622 | AT4: =ROUND(IF(AL4<24366,AL4*1.5%,24366*1.5%),2) -> 133.32 | AU4: =SUM(AN4:AT4) -> 3039.54 | AV4: =VLOOKUP(D4,[1]Sheet1!$F:$Q,12,0) -> 85 | AW4: =AU4+Z4+AI4-AJ4+AV4 -> 8004.78 | AX4: =5 -> 5 | AY4: -4.97 | AZ4: =5 -> 5 | BA4: 本月保障补差垫付5元，下月收，工伤利率调整，1月多收2月退，2月客户总给5.03，多收5元，下月退 | BB4: 255 | BC4: =ROUND(AW4+BB4+AX4+AY4+AZ4,2) -> 8264.81 | BD4: =ROUND(BC4*6%,2) -> 495.89 | BE4: =ROUND(SUM(BC4:BD4),2) -> 8760.7 | BF4: =IF((AK4-P4-Q4-R4-S4-T4-V4-W4)<2690,2690-(AK4-P4-Q4-R4-S4-T4-U4-W4),"")
A5: =ROW()-2 -> 3 | B5: 2502 | C5: WB016995 | D5: 杭亮 | E5: 310110198004027057 | F5: 45444 | G5: 45808 | I5: 上海 | J5: 1030 | K5: 2779.84 | L5: 1244.86 | R5: 630 | X5: =IF((SUM(J5:L5,R5)-AG5)<3325,3325-(SUM(J5:L5,R5)-AG5),"") | Z5: =SUM(J5:Y5) -> 5684.7 | AA5: 9226 | AB5: 738.08 | AC5: 184.52 | AD5: 46.13 | AE5: 9226 | AF5: =ROUND(AE5*7%,0) -> 646 | AG5: =AB5+AC5+AD5+AF5 -> 1614.73 | AK5: =Z5-AG5-AH5-AJ5 -> 4069.97 | AL5: 9226 | AM5: 9226 | AN5: =ROUND(AL5*16%,2) -> 1476.16 | AO5: =ROUND(AL5*9%,2) -> 830.34 | AP5: =ROUND(AL5*0.5%,2) -> 46.13 | AQ5: 18.45 | AS5: =ROUND(AM5*7%,0) -> 646 | AT5: =ROUND(IF(AL5<24366,AL5*1.5%,24366*1.5%),2) -> 138.39 | AU5: =SUM(AN5:AT5) -> 3155.47 | AV5: =VLOOKUP(D5,[1]Sheet1!$F:$Q,12,0) -> 101 | AW5: =AU5+Z5+AI5-AJ5+AV5 -> 8941.17 | AY5: -5.17 | BA5: 工伤利率调整，1月多收2月退 | BB5: 255 | BC5: =ROUND(AW5+BB5+AX5+AY5+AZ5,2) -> 9191 | BD5: =ROUND(BC5*6%,2) -> 551.46 | BE5: =ROUND(SUM(BC5:BD5),2) -> 9742.46 | BF5: =IF((AK5-P5-Q5-R5-S5-T5-V5-W5)<2690,2690-(AK5-P5-Q5-R5-S5-T5-U5-W5),"")
A6: =ROW()-2 -> 4 | B6: 2502 | C6: WB007082 | D6: 朱春红 | E6: 310230197703304160 | F6: 45444 | G6: 45808 | I6: 上海 | J6: 1030 | K6: 2464.8 | L6: 1514.04 | R6: 630 | X6: =IF((SUM(J6:L6,R6)-AG6)<3325,3325-(SUM(J6:L6,R6)-AG6),"") | Z6: =SUM(J6:Y6) -> 5638.84 | AA6: 10979 | AB6: 878.32 | AC6: 219.58 | AD6: 54.9 | AE6: 10979 | AF6: =ROUND(AE6*7%,0) -> 769 | AG6: =AB6+AC6+AD6+AF6 -> 1921.8 | AK6: =Z6-AG6-AH6-AJ6 -> 3717.04 | AL6: 10979 | AM6: 10979 | AN6: =ROUND(AL6*16%,2) -> 1756.64 | AO6: 988.12 | AP6: =ROUND(AL6*0.5%,2) -> 54.9 | AQ6: 21.96 | AS6: =ROUND(AM6*7%,0) -> 769 | AT6: =ROUND(IF(AL6<24366,AL6*1.5%,24366*1.5%),2) -> 164.69 | AU6: =SUM(AN6:AT6) -> 3755.31 | AV6: =VLOOKUP(D6,[1]Sheet1!$F:$Q,12,0) -> 100 | AW6: =AU6+Z6+AI6-AJ6+AV6 -> 9494.15 | AY6: -6.15 | BA6: 工伤利率调整，1月多收2月退 | BB6: 255 | BC6: =ROUND(AW6+BB6+AX6+AY6+AZ6,2) -> 9743 | BD6: =ROUND(BC6*6%,2) -> 584.58 | BE6: =ROUND(SUM(BC6:BD6),2) -> 10327.58 | BF6: =IF((AK6-P6-Q6-R6-S6-T6-V6-W6)<2690,2690-(AK6-P6-Q6-R6-S6-T6-U6-W6),"")
A7: =ROW()-2 -> 5 | B7: 2502 | C7: WB017012 | D7: 王一峰 | E7: 310230198106182913 | F7: 45444 | G7: 45808 | I7: 上海 | J7: 1030 | K7: =3143-371 -> 2772 | L7: 2156 | R7: 630 | U7: 371 | X7: =IF((SUM(J7:L7,R7)-AG7)<3325,3325-(SUM(J7:L7,R7)-AG7),"") | Z7: =SUM(J7:Y7) -> 6959 | AA7: 16443 | AB7: 1315.44 | AC7: 328.86 | AD7: 82.22 | AE7: 16443 | AF7: =ROUND(AE7*7%,0) -> 1151 | AG7: =AB7+AC7+AD7+AF7 -> 2877.52 | AK7: =Z7-AG7-AH7-AJ7 -> 4081.48 | AL7: 16443 | AM7: 16443 | AN7: =ROUND(AL7*16%,2) -> 2630.88 | AO7: 1479.88 | AP7: =ROUND(AL7*0.5%,2) -> 82.22 | AQ7: 32.89 | AS7: =ROUND(AM7*7%,0) -> 1151 | AT7: =ROUND(IF(AL7<24366,AL7*1.5%,24366*1.5%),2) -> 246.65 | AU7: =SUM(AN7:AT7) -> 5623.52 | AV7: =VLOOKUP(D7,[1]Sheet1!$F:$Q,12,0) -> 127 | AW7: =AU7+Z7+AI7-AJ7+AV7 -> 12709.52 | AY7: -9.2 | BA7: 工伤利率调整，1月多收2月退 | BB7: 255 | BC7: =ROUND(AW7+BB7+AX7+AY7+AZ7,2) -> 12955.32 | BD7: =ROUND(BC7*6%,2) -> 777.32 | BE7: =ROUND(SUM(BC7:BD7),2) -> 13732.64 | BF7: =IF((AK7-P7-Q7-R7-S7-T7-V7-W7)<2690,2690-(AK7-P7-Q7-R7-S7-T7-U7-W7),"")
A8: =ROW()-2 -> 6 | B8: 2502 | C8: WB019180 | D8: 王偲 | E8: 310109198908200531 | F8: 45444 | G8: 45808 | I8: 上海 | J8: 1030 | K8: 2605.2 | L8: 2033.74 | R8: 630 | X8: =IF((SUM(J8:L8,R8)-AG8)<3325,3325-(SUM(J8:L8,R8)-AG8),"") | Z8: =SUM(J8:Y8) -> 6298.94 | AA8: 8261 | AB8: 660.88 | AC8: 165.22 | AD8: 41.31 | AE8: 8261 | AF8: =ROUND(AE8*7%,0) -> 578 | AG8: =AB8+AC8+AD8+AF8 -> 1445.41 | AK8: =Z8-AG8-AH8-AJ8 -> 4853.53 | AL8: 8261 | AM8: 8261 | AN8: =ROUND(AL8*16%,2) -> 1321.76 | AO8: 743.5 | AP8: =ROUND(AL8*0.5%,2) -> 41.31 | AQ8: 16.52 | AS8: =ROUND(AM8*7%,0) -> 578 | AT8: =ROUND(IF(AL8<24366,AL8*1.5%,24366*1.5%),2) -> 123.92 | AU8: =SUM(AN8:AT8) -> 2825.01 | AV8: =VLOOKUP(D8,[1]Sheet1!$F:$Q,12,0) -> 113 | AW8: =AU8+Z8+AI8-AJ8+AV8 -> 9236.95 | AY8: -4.63 | BA8: 工伤利率调整，1月多收2月退 | BB8: 255 | BC8: =ROUND(AW8+BB8+AX8+AY8+AZ8,2) -> 9487.32 | BD8: =ROUND(BC8*6%,2) -> 569.24 | BE8: =ROUND(SUM(BC8:BD8),2) -> 10056.56 | BF8: =IF((AK8-P8-Q8-R8-S8-T8-V8-W8)<2690,2690-(AK8-P8-Q8-R8-S8-T8-U8-W8),"")
A9: =ROW()-2 -> 7 | B9: 2502 | C9: WB024266 | D9: 王凤凌 | E9: 31011019870909564X | F9: 45444 | G9: 45808 | I9: 上海 | J9: 1030 | K9: =1555.4-U9 -> 1184.4 | L9: 392.1 | R9: 630 | U9: 371 | X9: =IF((SUM(J9:L9,R9)-AG9)<3325,3325-(SUM(J9:L9,R9)-AG9),"") -> 1191.82 | Z9: =SUM(J9:Y9) -> 4799.32 | AA9: 7384 | AB9: 590.72 | AC9: 147.68 | AD9: 36.92 | AE9: 4686 | AF9: =ROUND(AE9*7%,0) -> 328 | AG9: =AB9+AC9+AD9+AF9 -> 1103.32 | AK9: =Z9-AG9-AH9-AJ9 -> 3696 | AL9: 7384 | AM9: 4686 | AN9: =ROUND(AL9*16%,2) -> 1181.44 | AO9: =ROUND(AL9*9%,2) -> 664.56 | AP9: =ROUND(AL9*0.5%,2) -> 36.92 | AQ9: 14.77 | AS9: =ROUND(AM9*7%,0) -> 328 | AT9: =ROUND(IF(AL9<24366,AL9*1.5%,24366*1.5%),2) -> 110.76 | AU9: =SUM(AN9:AT9) -> 2336.45 | AV9: =VLOOKUP(D9,[1]Sheet1!$F:$Q,12,0) -> 83 | AW9: =AU9+Z9+AI9-AJ9+AV9 -> 7218.77 | AX9: =5 -> 5 | AY9: -4.13 | AZ9: =5 -> 5 | BA9: 本月保障补差垫付5元，下月收，工伤利率调整，1月多收2月退，客户多给5元，下月退 | BB9: 255 | BC9: =ROUND(AW9+BB9+AX9+AY9+AZ9,2) -> 7479.64 | BD9: =ROUND(BC9*6%,2) -> 448.78 | BE9: =ROUND(SUM(BC9:BD9),2) -> 7928.42 | BF9: =IF((AK9-P9-Q9-R9-S9-T9-V9-W9)<2690,2690-(AK9-P9-Q9-R9-S9-T9-U9-W9),"")
A10: =ROW()-2 -> 8 | B10: 2502 | C10: WB033751 | D10: 高雄飞 | E10: 310101198402231014 | F10: 45444 | G10: 45808 | I10: 上海 | J10: 1300 | K10: =5334.2-U10 -> 4963.2 | L10: 1445.9 | R10: 630 | U10: 371 | X10: =IF((SUM(J10:L10,R10)-AG10)<3325,3325-(SUM(J10:L10,R10)-AG10),"") | Z10: =SUM(J10:Y10) -> 8710.1 | AA10: 9424 | AB10: 753.92 | AC10: 188.48 | AD10: 47.12 | AE10: 9424 | AF10: =ROUND(AE10*7%,0) -> 660 | AG10: =AB10+AC10+AD10+AF10 -> 1649.52 | AK10: =Z10-AG10-AH10-AJ10 -> 7060.58 | AL10: 9424 | AM10: 9424 | AN10: =ROUND(AL10*16%,2) -> 1507.84 | AO10: =ROUND(AL10*9%,2) -> 848.16 | AP10: =ROUND(AL10*0.5%,2) -> 47.12 | AQ10: 18.85 | AS10: =ROUND(AM10*7%,0) -> 660 | AT10: =ROUND(IF(AL10<24366,AL10*1.5%,24366*1.5%),2) -> 141.36 | AU10: =SUM(AN10:AT10) -> 3223.33 | AV10: =VLOOKUP(D10,[1]Sheet1!$F:$Q,12,0) -> 162 | AW10: =AU10+Z10+AI10-AJ10+AV10 -> 12095.43 | AY10: -5.28 | BA10: 工伤利率调整，1月多收2月退 | BB10: 255 | BC10: =ROUND(AW10+BB10+AX10+AY10+AZ10,2) -> 12345.15 | BD10: =ROUND(BC10*6%,2) -> 740.71 | BE10: =ROUND(SUM(BC10:BD10),2) -> 13085.86 | BF10: =IF((AK10-P10-Q10-R10-S10-T10-V10-W10)<2690,2690-(AK10-P10-Q10-R10-S10-T10-U10-W10),"")
A11: =ROW()-2 -> 9 | B11: 2502 | C11: WB017080 | D11: 季华 | E11: 310115198609170130 | F11: 45444 | G11: 45808 | I11: 上海 | J11: 1300 | K11: =8754-U12 -> 8383 | L11: 920 | R11: 630 | U11: 371 | X11: =IF((SUM(J11:L11,R11)-AG11)<3325,3325-(SUM(J11:L11,R11)-AG11),"") | Z11: =SUM(J11:Y11) -> 11604 | AA11: 10475 | AB11: 838 | AC11: 209.5 | AD11: 52.38 | AE11: 10475 | AF11: =ROUND(AE11*7%,0) -> 733 | AG11: =AB11+AC11+AD11+AF11 -> 1832.88 | AK11: =Z11-AG11-AH11-AJ11 -> 9771.12 | AL11: 10475 | AM11: 10475 | AN11: =ROUND(AL11*16%,2) -> 1676 | AO11: 942.76 | AP11: =ROUND(AL11*0.5%,2) -> 52.38 | AQ11: 20.95 | AS11: =ROUND(AM11*7%,0) -> 733 | AT11: =ROUND(IF(AL11<24366,AL11*1.5%,24366*1.5%),2) -> 157.13 | AU11: =SUM(AN11:AT11) -> 3582.22 | AV11: =VLOOKUP(D11,[1]Sheet1!$F:$Q,12,0) -> 219 | AW11: =AU11+Z11+AI11-AJ11+AV11 -> 15405.22 | AY11: -5.87 | BA11: 工伤利率调整，1月多收2月退 | BB11: 255 | BC11: =ROUND(AW11+BB11+AX11+AY11+AZ11,2) -> 15654.35 | BD11: =ROUND(BC11*6%,2) -> 939.26 | BE11: =ROUND(SUM(BC11:BD11),2) -> 16593.61 | BF11: =IF((AK11-P11-Q11-R11-S11-T11-V11-W11)<2690,2690-(AK11-P11-Q11-R11-S11-T11-U11-W11),"")
A12: =ROW()-2 -> 10 | B12: 2502 | C12: WB017076 | D12: 杨晓燕 | E12: 34222519770913404X | F12: 45444 | G12: 45808 | I12: 上海 | J12: 1030 | K12: =3928-U12 -> 3557 | L12: 2037 | R12: 630 | U12: 371 | X12: =IF((SUM(J12:L12,R12)-AG12)<3325,3325-(SUM(J12:L12,R12)-AG12),"") | Z12: =SUM(J12:Y12) -> 7625 | AA12: 8472 | AB12: 677.76 | AC12: 169.44 | AD12: 42.36 | AE12: 8472 | AF12: =ROUND(AE12*7%,0) -> 593 | AG12: =AB12+AC12+AD12+AF12 -> 1482.56 | AK12: =Z12-AG12-AH12-AJ12 -> 6142.44 | AL12: 8472 | AM12: 8472 | AN12: =ROUND(AL12*16%,2) -> 1355.52 | AO12: =ROUND(AL12*9%,2) -> 762.48 | AP12: =ROUND(AL12*0.5%,2) -> 42.36 | AQ12: 16.94 | AS12: =ROUND(AM12*7%,0) -> 593 | AT12: =ROUND(IF(AL12<24366,AL12*1.5%,24366*1.5%),2) -> 127.08 | AU12: =SUM(AN12:AT12) -> 2897.38 | AV12: =VLOOKUP(D12,[1]Sheet1!$F:$Q,12,0) -> 140 | AW12: =AU12+Z12+AI12-AJ12+AV12 -> 10662.38 | AY12: -4.75 | BA12: 工伤利率调整，1月多收2月退 | BB12: 255 | BC12: =ROUND(AW12+BB12+AX12+AY12+AZ12,2) -> 10912.63 | BD12: =ROUND(BC12*6%,2) -> 654.76 | BE12: =ROUND(SUM(BC12:BD12),2) -> 11567.39 | BF12: =IF((AK12-P12-Q12-R12-S12-T12-V12-W12)<2690,2690-(AK12-P12-Q12-R12-S12-T12-U12-W12),"")
A13: =ROW()-2 -> 11 | B13: 2502 | C13: WB025472 | D13: 孟浩杰 | E13: 510108198209090637 | F13: 45444 | G13: 45808 | I13: 上海 | J13: 1300 | K13: =5683.6-U13 -> 5312.6 | L13: 1714.74 | R13: 630 | U13: 371 | X13: =IF((SUM(J13:L13,R13)-AG13)<3325,3325-(SUM(J13:L13,R13)-AG13),"") | Z13: =SUM(J13:Y13) -> 9328.34 | AA13: 9241 | AB13: 739.28 | AC13: 184.82 | AD13: 46.21 | AE13: 9241 | AF13: =ROUND(AE13*7%,0) -> 647 | AG13: =AB13+AC13+AD13+AF13 -> 1617.31 | AK13: =Z13-AG13-AH13-AJ13 -> 7711.03 | AL13: 9241 | AM13: 9241 | AN13: =ROUND(AL13*16%,2) -> 1478.56 | AO13: 831.7 | AP13: =ROUND(AL13*0.5%,2) -> 46.21 | AQ13: 18.48 | AS13: =ROUND(AM13*7%,0) -> 647 | AT13: =ROUND(IF(AL13<24366,AL13*1.5%,24366*1.5%),2) -> 138.62 | AU13: =SUM(AN13:AT13) -> 3160.57 | AV13: =VLOOKUP(D13,[1]Sheet1!$F:$Q,12,0) -> 174 | AW13: =AU13+Z13+AI13-AJ13+AV13 -> 12662.91 | AY13: -5.18 | BA13: 工伤利率调整，1月多收2月退 | BB13: 255 | BC13: =ROUND(AW13+BB13+AX13+AY13+AZ13,2) -> 12912.73 | BD13: =ROUND(BC13*6%,2) -> 774.76 | BE13: =ROUND(SUM(BC13:BD13),2) -> 13687.49 | BF13: =IF((AK13-P13-Q13-R13-S13-T13-V13-W13)<2690,2690-(AK13-P13-Q13-R13-S13-T13-U13-W13),"")
A14: =ROW()-2 -> 12 | B14: 2502 | C14: WB021004 | D14: 周雨薇 | E14: 310104199212304829 | F14: 45444 | G14: 45808 | I14: 上海 | J14: 1030 | K14: 3364 | L14: 1187.7 | R14: 630 | X14: =IF((SUM(J14:L14,R14)-AG14)<3325,3325-(SUM(J14:L14,R14)-AG14),"") | Z14: =SUM(J14:Y14) -> 6211.7 | AA14: 7384 | AB14: 590.72 | AC14: 147.68 | AD14: 36.92 | AE14: 6830 | AF14: =ROUND(AE14*7%,0) -> 478 | AG14: =AB14+AC14+AD14+AF14 -> 1253.32 | AK14: =Z14-AG14-AH14-AJ14 -> 4958.38 | AL14: 7384 | AM14: 6830 | AN14: =ROUND(AL14*16%,2) -> 1181.44 | AO14: =ROUND(AL14*9%,2) -> 664.56 | AP14: =ROUND(AL14*0.5%,2) -> 36.92 | AQ14: 14.77 | AS14: =ROUND(AM14*7%,0) -> 478 | AT14: =ROUND(IF(AL14<24366,AL14*1.5%,24366*1.5%),2) -> 110.76 | AU14: =SUM(AN14:AT14) -> 2486.45 | AV14: =VLOOKUP(D14,[1]Sheet1!$F:$Q,12,0) -> 112 | AW14: =AU14+Z14+AI14-AJ14+AV14 -> 8810.15 | AY14: -4.13 | BA14: 工伤利率调整，1月多收2月退 | BB14: 255 | BC14: =ROUND(AW14+BB14+AX14+AY14+AZ14,2) -> 9061.02 | BD14: =ROUND(BC14*6%,2) -> 543.66 | BE14: =ROUND(SUM(BC14:BD14),2) -> 9604.68 | BF14: =IF((AK14-P14-Q14-R14-S14-T14-V14-W14)<2690,2690-(AK14-P14-Q14-R14-S14-T14-U14-W14),"")
A15: =ROW()-2 -> 13 | B15: 2502 | C15: WB017081 | D15: 王姗姗 | E15: 34112519880604436X | F15: 45444 | G15: 45808 | I15: 上海 | J15: 1300 | K15: =19582.6-U15 -> 19211.6 | L15: 2681.33 | R15: 630 | U15: 371 | X15: =IF((SUM(J15:L15,R15)-AG15)<3325,3325-(SUM(J15:L15,R15)-AG15),"") | Z15: =SUM(J15:Y15) -> 24193.93 | AA15: 18040 | AB15: 1443.2 | AC15: 360.8 | AD15: 90.2 | AE15: 18040 | AF15: =ROUND(AE15*7%,0) -> 1263 | AG15: =AB15+AC15+AD15+AF15 -> 3157.2 | AK15: =Z15-AG15-AH15-AJ15 -> 21036.73 | AL15: 18040 | AM15: 18040 | AN15: =ROUND(AL15*16%,2) -> 2886.4 | AO15: =ROUND(AL15*9%,2) -> 1623.6 | AP15: =ROUND(AL15*0.5%,2) -> 90.2 | AQ15: 36.08 | AS15: =ROUND(AM15*7%,0) -> 1263 | AT15: =ROUND(IF(AL15<24366,AL15*1.5%,24366*1.5%),2) -> 270.6 | AU15: =SUM(AN15:AT15) -> 6169.88 | AV15: =VLOOKUP(D15,[1]Sheet1!$F:$Q,12,0) -> 471 | AW15: =AU15+Z15+AI15-AJ15+AV15 -> 30834.81 | AY15: -10.1 | BA15: 工伤利率调整，1月多收2月退 | BB15: 255 | BC15: =ROUND(AW15+BB15+AX15+AY15+AZ15,2) -> 31079.71 | BD15: =ROUND(BC15*6%,2) -> 1864.78 | BE15: =ROUND(SUM(BC15:BD15),2) -> 32944.49 | BF15: =IF((AK15-P15-Q15-R15-S15-T15-V15-W15)<2690,2690-(AK15-P15-Q15-R15-S15-T15-U15-W15),"")
A16: =ROW()-2 -> 14 | B16: 2502 | C16: WB017085 | D16: 邱杭佳 | E16: 31010819830921103X | F16: 45444 | G16: 45808 | I16: 上海 | J16: 1030 | K16: =3113-U16 -> 2742 | L16: 1177.86 | R16: 630 | U16: 371 | X16: =IF((SUM(J16:L16,R16)-AG16)<3325,3325-(SUM(J16:L16,R16)-AG16),"") | Z16: =SUM(J16:Y16) -> 5950.86 | AA16: 7474 | AB16: 597.92 | AC16: 149.48 | AD16: 37.37 | AE16: 7474 | AF16: =ROUND(AE16*7%,0) -> 523 | AG16: =AB16+AC16+AD16+AF16 -> 1307.77 | AK16: =Z16-AG16-AH16-AJ16 -> 4643.09 | AL16: 7474 | AM16: 7474 | AN16: =ROUND(AL16*16%,2) -> 1195.84 | AO16: =ROUND(AL16*9%,2) -> 672.66 | AP16: =ROUND(AL16*0.5%,2) -> 37.37 | AQ16: 14.95 | AS16: =ROUND(AM16*7%,0) -> 523 | AT16: =ROUND(IF(AL16<24366,AL16*1.5%,24366*1.5%),2) -> 112.11 | AU16: =SUM(AN16:AT16) -> 2555.93 | AV16: =VLOOKUP(D16,[1]Sheet1!$F:$Q,12,0) -> 106 | AW16: =AU16+Z16+AI16-AJ16+AV16 -> 8612.79 | AY16: -4.18 | BA16: 工伤利率调整，1月多收2月退 | BB16: 255 | BC16: =ROUND(AW16+BB16+AX16+AY16+AZ16,2) -> 8863.61 | BD16: =ROUND(BC16*6%,2) -> 531.82 | BE16: =ROUND(SUM(BC16:BD16),2) -> 9395.43 | BF16: =IF((AK16-P16-Q16-R16-S16-T16-V16-W16)<2690,2690-(AK16-P16-Q16-R16-S16-T16-U16-W16),"")
A17: =ROW()-2 -> 15 | B17: 2502 | C17: WB045238 | D17: 戈婷婷 | E17: 320821199610185147 | F17: 45444 | G17: 45808 | I17: 上海 | J17: 1030 | K17: =4525-U17 -> 4154 | L17: 3010.78 | R17: 630 | U17: 371 | X17: =IF((SUM(J17:L17,R17)-AG17)<3325,3325-(SUM(J17:L17,R17)-AG17),"") | Z17: =SUM(J17:Y17) -> 9195.78 | AA17: 10443 | AB17: 835.44 | AC17: 208.86 | AD17: 52.22 | AE17: 10443 | AF17: =ROUND(AE17*7%,0) -> 731 | AG17: =AB17+AC17+AD17+AF17 -> 1827.52 | AK17: =Z17-AG17-AH17-AJ17 -> 7368.26 | AL17: 10443 | AM17: 10443 | AN17: =ROUND(AL17*16%,2) -> 1670.88 | AO17: 939.88 | AP17: =ROUND(AL17*0.5%,2) -> 52.22 | AQ17: 20.89 | AS17: =ROUND(AM17*7%,0) -> 731 | AT17: =ROUND(IF(AL17<24366,AL17*1.5%,24366*1.5%),2) -> 156.65 | AU17: =SUM(AN17:AT17) -> 3571.52 | AV17: =VLOOKUP(D17,[1]Sheet1!$F:$Q,12,0) -> 171 | AW17: =AU17+Z17+AI17-AJ17+AV17 -> 12938.3 | AY17: -5.84 | BA17: 工伤利率调整，1月多收2月退 | BB17: 255 | BC17: =ROUND(AW17+BB17+AX17+AY17+AZ17,2) -> 13187.46 | BD17: =ROUND(BC17*6%,2) -> 791.25 | BE17: =ROUND(SUM(BC17:BD17),2) -> 13978.71 | BF17: =IF((AK17-P17-Q17-R17-S17-T17-V17-W17)<2690,2690-(AK17-P17-Q17-R17-S17-T17-U17-W17),"")
A18: =ROW()-2 -> 16 | B18: 2502 | C18: WB013266 | D18: 吴裕刚 | E18: 31010219810818361X | F18: 45444 | G18: 45808 | I18: 上海 | J18: 1030 | K18: =6845.48-U18 -> 6474.48 | L18: 1345.3 | R18: 630 | U18: 371 | X18: =IF((SUM(J18:L18,R18)-AG18)<3325,3325-(SUM(J18:L18,R18)-AG18),"") | Z18: =SUM(J18:Y18) -> 9850.78 | AA18: 8102 | AB18: 648.16 | AC18: 162.04 | AD18: 40.51 | AE18: 8102 | AF18: =ROUND(AE18*7%,0) -> 567 | AG18: =AB18+AC18+AD18+AF18 -> 1417.71 | AK18: =Z18-AG18-AH18-AJ18 -> 8433.07 | AL18: 8102 | AM18: 8102 | AN18: =ROUND(AL18*16%,2) -> 1296.32 | AO18: =ROUND(AL18*9%,2) -> 729.18 | AP18: =ROUND(AL18*0.5%,2) -> 40.51 | AQ18: 16.2 | AS18: =ROUND(AM18*7%,0) -> 567 | AT18: =ROUND(IF(AL18<24366,AL18*1.5%,24366*1.5%),2) -> 121.53 | AU18: =SUM(AN18:AT18) -> 2770.74 | AV18: =VLOOKUP(D18,[1]Sheet1!$F:$Q,12,0) -> 184 | AW18: =AU18+Z18+AI18-AJ18+AV18 -> 12805.52 | AY18: -4.54 | BA18: 工伤利率调整，1月多收2月退 | BB18: 255 | BC18: =ROUND(AW18+BB18+AX18+AY18+AZ18,2) -> 13055.98 | BD18: =ROUND(BC18*6%,2) -> 783.36 | BE18: =ROUND(SUM(BC18:BD18),2) -> 13839.34 | BF18: =IF((AK18-P18-Q18-R18-S18-T18-V18-W18)<2690,2690-(AK18-P18-Q18-R18-S18-T18-U18-W18),"")
A19: =ROW()-2 -> 17 | B19: 2502 | C19: WB017007 | D19: 贺彦 | E19: 310108198901250513 | F19: 45444 | G19: 45808 | I19: 上海 | J19: 800 | K19: =1572-U19 -> 1572 | L19: 943.8 | R19: 630 | X19: =IF((SUM(J19:L19,R19)-AG19)<3325,3325-(SUM(J19:L19,R19)-AG19),"") -> 497.52 | Z19: =SUM(J19:Y19) -> 4443.32 | AA19: 7384 | AB19: 590.72 | AC19: 147.68 | AD19: 36.92 | AE19: 4906 | AF19: =ROUND(AE19*7%,0) -> 343 | AG19: =AB19+AC19+AD19+AF19 -> 1118.32 | AK19: =Z19-AG19-AH19-AJ19 -> 3325 | AL19: 7384 | AM19: 4906 | AN19: =ROUND(AL19*16%,2) -> 1181.44 | AO19: =ROUND(AL19*9%,2) -> 664.56 | AP19: =ROUND(AL19*0.5%,2) -> 36.92 | AQ19: 14.77 | AS19: =ROUND(AM19*7%,0) -> 343 | AT19: =ROUND(IF(AL19<24366,AL19*1.5%,24366*1.5%),2) -> 110.76 | AU19: =SUM(AN19:AT19) -> 2351.45 | AV19: =VLOOKUP(D19,[1]Sheet1!$F:$Q,12,0) -> 76 | AW19: =AU19+Z19+AI19-AJ19+AV19 -> 6870.77 | AY19: -4.13 | BA19: 工伤利率调整，1月多收2月退 | BB19: 255 | BC19: =ROUND(AW19+BB19+AX19+AY19+AZ19,2) -> 7121.64 | BD19: =ROUND(BC19*6%,2) -> 427.3 | BE19: =ROUND(SUM(BC19:BD19),2) -> 7548.94 | BF19: =IF((AK19-P19-Q19-R19-S19-T19-V19-W19)<2690,2690-(AK19-P19-Q19-R19-S19-T19-U19-W19),"")
A20: =ROW()-2 -> 18 | B20: 2502 | C20: WB017000 | D20: 叶毅 | E20: 310110198502133266 | F20: 45444 | G20: 45808 | I20: 上海 | J20: 1030 | K20: =4816-U20 -> 4445 | L20: 1758.84 | R20: 630 | U20: 371 | X20: =IF((SUM(J20:L20,R20)-AG20)<3325,3325-(SUM(J20:L20,R20)-AG20),"") | Z20: =SUM(J20:Y20) -> 8234.84 | AA20: 7759 | AB20: 620.72 | AC20: 155.18 | AD20: 38.8 | AE20: 7759 | AF20: =ROUND(AE20*7%,0) -> 543 | AG20: =AB20+AC20+AD20+AF20 -> 1357.7 | AK20: =Z20-AG20-AH20-AJ20 -> 6877.14 | AL20: 7759 | AM20: 7759 | AN20: =ROUND(AL20*16%,2) -> 1241.44 | AO20: 698.32 | AP20: =ROUND(AL20*0.5%,2) -> 38.8 | AQ20: 15.52 | AS20: =ROUND(AM20*7%,0) -> 543 | AT20: =ROUND(IF(AL20<24366,AL20*1.5%,24366*1.5%),2) -> 116.39 | AU20: =SUM(AN20:AT20) -> 2653.47 | AV20: =VLOOKUP(D20,[1]Sheet1!$F:$Q,12,0) -> 152 | AW20: =AU20+Z20+AI20-AJ20+AV20 -> 11040.31 | AY20: -4.34 | BA20: 工伤利率调整，1月多收2月退 | BB20: 255 | BC20: =ROUND(AW20+BB20+AX20+AY20+AZ20,2) -> 11290.97 | BD20: =ROUND(BC20*6%,2) -> 677.46 | BE20: =ROUND(SUM(BC20:BD20),2) -> 11968.43 | BF20: =IF((AK20-P20-Q20-R20-S20-T20-V20-W20)<2690,2690-(AK20-P20-Q20-R20-S20-T20-U20-W20),"")
A21: =ROW()-2 -> 19 | B21: 2502 | C21: WB017001 | D21: 陈世碧 | E21: 513023197709136722 | F21: 45444 | G21: 45808 | I21: 上海 | J21: 1030 | K21: =3946.8-U21 -> 3575.8 | L21: 3732.3 | R21: 630 | U21: 371 | X21: =IF((SUM(J21:L21,R21)-AG21)<3325,3325-(SUM(J21:L21,R21)-AG21),"") | Z21: =SUM(J21:Y21) -> 9339.1 | AA21: 10043 | AB21: 803.44 | AC21: 200.86 | AD21: 50.22 | AE21: 10043 | AF21: =ROUND(AE21*7%,0) -> 703 | AG21: =AB21+AC21+AD21+AF21 -> 1757.52 | AK21: =Z21-AG21-AH21-AJ21 -> 7581.58 | AL21: 10043 | AM21: 10043 | AN21: =ROUND(AL21*16%,2) -> 1606.88 | AO21: 903.88 | AP21: =ROUND(AL21*0.5%,2) -> 50.22 | AQ21: 20.09 | AS21: =ROUND(AM21*7%,0) -> 703 | AT21: =ROUND(IF(AL21<24366,AL21*1.5%,24366*1.5%),2) -> 150.65 | AU21: =SUM(AN21:AT21) -> 3434.72 | AV21: =VLOOKUP(D21,[1]Sheet1!$F:$Q,12,0) -> 174 | AW21: =AU21+Z21+AI21-AJ21+AV21 -> 12947.82 | AY21: -5.62 | BA21: 工伤利率调整，1月多收2月退 | BB21: 255 | BC21: =ROUND(AW21+BB21+AX21+AY21+AZ21,2) -> 13197.2 | BD21: =ROUND(BC21*6%,2) -> 791.83 | BE21: =ROUND(SUM(BC21:BD21),2) -> 13989.03 | BF21: =IF((AK21-P21-Q21-R21-S21-T21-V21-W21)<2690,2690-(AK21-P21-Q21-R21-S21-T21-U21-W21),"")
A22: =ROW()-2 -> 20 | B22: 2502 | C22: WB017004 | D22: 顾陆慧 | E22: 310230197904164766 | F22: 45444 | G22: 45808 | I22: 上海 | J22: 1300 | K22: 7900.8 | L22: 1147.14 | R22: 630 | X22: =IF((SUM(J22:L22,R22)-AG22)<3325,3325-(SUM(J22:L22,R22)-AG22),"") | Z22: =SUM(J22:Y22) -> 10977.94 | AA22: 12136 | AB22: 970.88 | AC22: 242.72 | AD22: 60.68 | AE22: 12136 | AF22: =ROUND(AE22*7%,0) -> 850 | AG22: =AB22+AC22+AD22+AF22 -> 2124.28 | AK22: =Z22-AG22-AH22-AJ22 -> 8853.66 | AL22: 12136 | AM22: 12136 | AN22: =ROUND(AL22*16%,2) -> 1941.76 | AO22: =ROUND(AL22*9%,2) -> 1092.24 | AP22: =ROUND(AL22*0.5%,2) -> 60.68 | AQ22: 24.27 | AS22: =ROUND(AM22*7%,0) -> 850 | AT22: =ROUND(IF(AL22<24366,AL22*1.5%,24366*1.5%),2) -> 182.04 | AU22: =SUM(AN22:AT22) -> 4150.99 | AV22: =VLOOKUP(D22,[1]Sheet1!$F:$Q,12,0) -> 207 | AW22: =AU22+Z22+AI22-AJ22+AV22 -> 15335.93 | AY22: -6.8 | BA22: 工伤利率调整，1月多收2月退 | BB22: 255 | BC22: =ROUND(AW22+BB22+AX22+AY22+AZ22,2) -> 15584.13 | BD22: =ROUND(BC22*6%,2) -> 935.05 | BE22: =ROUND(SUM(BC22:BD22),2) -> 16519.18 | BF22: =IF((AK22-P22-Q22-R22-S22-T22-V22-W22)<2690,2690-(AK22-P22-Q22-R22-S22-T22-U22-W22),"")
A23: =ROW()-2 -> 21 | B23: 2502 | C23: WB017006 | D23: 程祖云 | E23: 411524198609258442 | F23: 45444 | G23: 45808 | I23: 上海 | J23: 1200 | K23: 3976.96 | L23: 1807.4 | R23: 630 | X23: =IF((SUM(J23:L23,R23)-AG23)<3325,3325-(SUM(J23:L23,R23)-AG23),"") | Z23: =SUM(J23:Y23) -> 7614.36 | AA23: 9608 | AB23: 768.64 | AC23: 192.16 | AD23: 48.04 | AE23: 9608 | AF23: =ROUND(AE23*7%,0) -> 673 | AG23: =AB23+AC23+AD23+AF23 -> 1681.84 | AK23: =Z23-AG23-AH23-AJ23 -> 5932.52 | AL23: 9608 | AM23: 9608 | AN23: =ROUND(AL23*16%,2) -> 1537.28 | AO23: =ROUND(AL23*9%,2) -> 864.72 | AP23: =ROUND(AL23*0.5%,2) -> 48.04 | AQ23: 19.22 | AS23: =ROUND(AM23*7%,0) -> 673 | AT23: =ROUND(IF(AL23<24366,AL23*1.5%,24366*1.5%),2) -> 144.12 | AU23: =SUM(AN23:AT23) -> 3286.38 | AV23: =VLOOKUP(D23,[1]Sheet1!$F:$Q,12,0) -> 140 | AW23: =AU23+Z23+AI23-AJ23+AV23 -> 11040.74 | AY23: -5.38 | BA23: 工伤利率调整，1月多收2月退 | BB23: 255 | BC23: =ROUND(AW23+BB23+AX23+AY23+AZ23,2) -> 11290.36 | BD23: =ROUND(BC23*6%,2) -> 677.42 | BE23: =ROUND(SUM(BC23:BD23),2) -> 11967.78 | BF23: =IF((AK23-P23-Q23-R23-S23-T23-V23-W23)<2690,2690-(AK23-P23-Q23-R23-S23-T23-U23-W23),"")
A24: =ROW()-2 -> 22 | B24: 2502 | C24: WB003572 | D24: 谢俊敏 | E24: 310110198911171036 | F24: 45444 | G24: 45808 | I24: 上海 | J24: 1030 | K24: 3174 | L24: 1771.14 | R24: 630 | X24: =IF((SUM(J24:L24,R24)-AG24)<3325,3325-(SUM(J24:L24,R24)-AG24),"") | Z24: =SUM(J24:Y24) -> 6605.14 | AA24: 7974 | AB24: 637.92 | AC24: 159.48 | AD24: 39.87 | AE24: 7974 | AF24: =ROUND(AE24*7%,0) -> 558 | AG24: =AB24+AC24+AD24+AF24 -> 1395.27 | AK24: =Z24-AG24-AH24-AJ24 -> 5209.87 | AL24: 7974 | AM24: 7974 | AN24: =ROUND(AL24*16%,2) -> 1275.84 | AO24: =ROUND(AL24*9%,2) -> 717.66 | AP24: =ROUND(AL24*0.5%,2) -> 39.87 | AQ24: 15.95 | AS24: =ROUND(AM24*7%,0) -> 558 | AT24: =ROUND(IF(AL24<24366,AL24*1.5%,24366*1.5%),2) -> 119.61 | AU24: =SUM(AN24:AT24) -> 2726.93 | AV24: =VLOOKUP(D24,[1]Sheet1!$F:$Q,12,0) -> 120 | AW24: =AU24+Z24+AI24-AJ24+AV24 -> 9452.07 | AY24: -4.46 | BA24: 工伤利率调整，1月多收2月退 | BB24: 255 | BC24: =ROUND(AW24+BB24+AX24+AY24+AZ24,2) -> 9702.61 | BD24: =ROUND(BC24*6%,2) -> 582.16 | BE24: =ROUND(SUM(BC24:BD24),2) -> 10284.77 | BF24: =IF((AK24-P24-Q24-R24-S24-T24-V24-W24)<2690,2690-(AK24-P24-Q24-R24-S24-T24-U24-W24),"")
A25: =ROW()-2 -> 23 | B25: 2502 | C25: WB039916 | D25: 梁裔杰 | E25: 310113198509301719 | F25: 45444 | G25: 45808 | I25: 上海 | J25: 1030 | K25: =5316.8-U25 -> 4945.8 | L25: 4563.14 | R25: 630 | U25: 371 | X25: =IF((SUM(J25:L25,R25)-AG25)<3325,3325-(SUM(J25:L25,R25)-AG25),"") | Z25: =SUM(J25:Y25) -> 11539.94 | AA25: 7384 | AB25: 590.72 | AC25: 147.68 | AD25: 36.92 | AE25: 7139 | AF25: =ROUND(AE25*7%,0) -> 500 | AG25: =AB25+AC25+AD25+AF25 -> 1275.32 | AK25: =Z25-AG25-AH25-AJ25 -> 10264.62 | AL25: 7384 | AM25: 7139 | AN25: =ROUND(AL25*16%,2) -> 1181.44 | AO25: =ROUND(AL25*9%,2) -> 664.56 | AP25: =ROUND(AL25*0.5%,2) -> 36.92 | AQ25: 14.77 | AS25: =ROUND(AM25*7%,0) -> 500 | AT25: =ROUND(IF(AL25<24366,AL25*1.5%,24366*1.5%),2) -> 110.76 | AU25: =SUM(AN25:AT25) -> 2508.45 | AV25: =VLOOKUP(D25,[1]Sheet1!$F:$Q,12,0) -> 218 | AW25: =AU25+Z25+AI25-AJ25+AV25 -> 14266.39 | AY25: -4.13 | BA25: 工伤利率调整，1月多收2月退 | BB25: 255 | BC25: =ROUND(AW25+BB25+AX25+AY25+AZ25,2) -> 14517.26 | BD25: =ROUND(BC25*6%,2) -> 871.04 | BE25: =ROUND(SUM(BC25:BD25),2) -> 15388.3 | BF25: =IF((AK25-P25-Q25-R25-S25-T25-V25-W25)<2690,2690-(AK25-P25-Q25-R25-S25-T25-U25-W25),"")
A26: =ROW()-2 -> 24 | B26: 2502 | C26: WB017057 | D26: 朱云 | E26: 310110198810200045 | F26: 45444 | G26: 45808 | I26: 上海 | J26: 1030 | K26: =1882.2-U26 -> 1511.2 | L26: 893.6 | R26: 630 | U26: 371 | X26: =IF((SUM(J26:L26,R26)-AG26)<3325,3325-(SUM(J26:L26,R26)-AG26),"") -> 1344.65 | Z26: =SUM(J26:Y26) -> 5780.45 | AA26: 11909 | AB26: 952.72 | AC26: 238.18 | AD26: 59.55 | AE26: 11909 | AF26: =ROUND(AE26*7%,0) -> 834 | AG26: =AB26+AC26+AD26+AF26 -> 2084.45 | AK26: =Z26-AG26-AH26-AJ26 -> 3696 | AL26: 11909 | AM26: 11909 | AN26: =ROUND(AL26*16%,2) -> 1905.44 | AO26: 1071.82 | AP26: =ROUND(AL26*0.5%,2) -> 59.55 | AQ26: 23.82 | AS26: =ROUND(AM26*7%,0) -> 834 | AT26: =ROUND(IF(AL26<24366,AL26*1.5%,24366*1.5%),2) -> 178.64 | AU26: =SUM(AN26:AT26) -> 4073.27 | AV26: =VLOOKUP(D26,[1]Sheet1!$F:$Q,12,0) -> 103 | AW26: =AU26+Z26+AI26-AJ26+AV26 -> 9956.72 | AX26: =5 -> 5 | AY26: -6.67 | AZ26: =5 -> 5 | BA26: 本月保障补差垫付5元，下月收，工伤利率调整，1月多收2月退 | BB26: 255 | BC26: =ROUND(AW26+BB26+AX26+AY26+AZ26,2) -> 10215.05 | BD26: =ROUND(BC26*6%,2) -> 612.9 | BE26: =ROUND(SUM(BC26:BD26),2) -> 10827.95 | BF26: =IF((AK26-P26-Q26-R26-S26-T26-V26-W26)<2690,2690-(AK26-P26-Q26-R26-S26-T26-U26-W26),"")
A27: =ROW()-2 -> 25 | B27: 2502 | C27: WB017068 | D27: 罗文彬 | E27: 310110198902103234 | F27: 45444 | G27: 45808 | I27: 上海 | J27: 1200 | K27: =3768.2-U27 -> 3397.2 | L27: 1056.44 | R27: 630 | U27: 371 | X27: =IF((SUM(J27:L27,R27)-AG27)<3325,3325-(SUM(J27:L27,R27)-AG27),"") | Z27: =SUM(J27:Y27) -> 6654.64 | AA27: 14537 | AB27: 1162.96 | AC27: 290.74 | AD27: 72.69 | AE27: 14537 | AF27: =ROUND(AE27*7%,0) -> 1018 | AG27: =AB27+AC27+AD27+AF27 -> 2544.39 | AK27: =Z27-AG27-AH27-AJ27 -> 4110.25 | AL27: 14537 | AM27: 14537 | AN27: =ROUND(AL27*16%,2) -> 2325.92 | AO27: 1308.34 | AP27: =ROUND(AL27*0.5%,2) -> 72.69 | AQ27: 29.07 | AS27: =ROUND(AM27*7%,0) -> 1018 | AT27: =ROUND(IF(AL27<24366,AL27*1.5%,24366*1.5%),2) -> 218.06 | AU27: =SUM(AN27:AT27) -> 4972.08 | AV27: =VLOOKUP(D27,[1]Sheet1!$F:$Q,12,0) -> 120 | AW27: =AU27+Z27+AI27-AJ27+AV27 -> 11746.72 | AY27: -8.14 | BA27: 工伤利率调整，1月多收2月退 | BB27: 255 | BC27: =ROUND(AW27+BB27+AX27+AY27+AZ27,2) -> 11993.58 | BD27: =ROUND(BC27*6%,2) -> 719.61 | BE27: =ROUND(SUM(BC27:BD27),2) -> 12713.19 | BF27: =IF((AK27-P27-Q27-R27-S27-T27-V27-W27)<2690,2690-(AK27-P27-Q27-R27-S27-T27-U27-W27),"")
A28: =ROW()-2 -> 26 | B28: 2502 | C28: WB054689 | D28: 张梦诏 | E28: 342423200108298172 | F28: 45444 | G28: 45808 | I28: 上海 | J28: 800 | K28: =3343.4-U28 -> 2972.4 | L28: 2906.94 | R28: 630 | U28: 371 | X28: =IF((SUM(J28:L28,R28)-AG28)<3325,3325-(SUM(J28:L28,R28)-AG28),"") | Z28: =SUM(J28:Y28) -> 7680.34 | AA28: 7384 | AB28: 590.72 | AC28: 147.68 | AD28: 36.92 | AE28: 5239 | AF28: =ROUND(AE28*7%,0) -> 367 | AG28: =AB28+AC28+AD28+AF28 -> 1142.32 | AK28: =Z28-AG28-AH28-AJ28 -> 6538.02 | AL28: 7384 | AM28: 5239 | AN28: =ROUND(AL28*16%,2) -> 1181.44 | AO28: =ROUND(AL28*9%,2) -> 664.56 | AP28: =ROUND(AL28*0.5%,2) -> 36.92 | AQ28: 14.77 | AS28: =ROUND(AM28*7%,0) -> 367 | AT28: =ROUND(IF(AL28<24366,AL28*1.5%,24366*1.5%),2) -> 110.76 | AU28: =SUM(AN28:AT28) -> 2375.45 | AV28: =VLOOKUP(D28,[1]Sheet1!$F:$Q,12,0) -> 141 | AW28: =AU28+Z28+AI28-AJ28+AV28 -> 10196.79 | AY28: -4.13 | BA28: 工伤利率调整，1月多收2月退 | BB28: 255 | BC28: =ROUND(AW28+BB28+AX28+AY28+AZ28,2) -> 10447.66 | BD28: =ROUND(BC28*6%,2) -> 626.86 | BE28: =ROUND(SUM(BC28:BD28),2) -> 11074.52 | BF28: =IF((AK28-P28-Q28-R28-S28-T28-V28-W28)<2690,2690-(AK28-P28-Q28-R28-S28-T28-U28-W28),"")
A29: =ROW()-2 -> 27 | B29: 2502 | C29: WB017054 | D29: 胡佳华 | E29: 310109198103142020 | F29: 45658 | G29: 47118 | I29: 上海 | J29: 1300 | K29: 6021.6 | L29: 1015.4 | R29: 630 | X29: =IF((SUM(J29:L29,R29)-AG29)<3325,3325-(SUM(J29:L29,R29)-AG29),"") | Z29: =SUM(J29:Y29) -> 8967 | AA29: 9575 | AB29: 766 | AC29: 191.5 | AD29: 47.88 | AE29: 9575 | AF29: 670 | AG29: =AB29+AC29+AD29+AF29 -> 1675.38 | AK29: =Z29-AG29-AH29-AJ29 -> 7291.62 | AL29: 9575 | AM29: 9575 | AN29: 1532 | AO29: 861.76 | AP29: 47.88 | AQ29: 19.15 | AS29: 670 | AT29: 143.63 | AU29: =SUM(AN29:AT29) -> 3274.42 | AV29: =VLOOKUP(D29,[1]Sheet1!$F:$Q,12,0) -> 167 | AW29: =AU29+Z29+AI29-AJ29+AV29 -> 12408.42 | AX29: =3.76 -> 3.76 | AY29: 0 | BA29: 客户少给了，我们按照2%，19.15缴纳的，1月垫付了3.76，本月收 | BB29: 255 | BC29: =ROUND(AW29+BB29+AX29+AY29+AZ29,2) -> 12667.18 | BD29: =ROUND(BC29*6%,2) -> 760.03 | BE29: =ROUND(SUM(BC29:BD29),2) -> 13427.21 | BF29: =IF((AK29-P29-Q29-R29-S29-T29-V29-W29)<2690,2690-(AK29-P29-Q29-R29-S29-T29-U29-W29),"")
A30: =ROW()-2 -> 28 | B30: 2502 | C30: WB008065 | D30: 戚继英 | E30: 310102198004243227 | F30: 45444 | G30: 45808 | H30: 45661 | I30: 上海 | K30: 72 | L30: 393.9 | Z30: =SUM(J30:Y30) -> 465.9 | AG30: =AB30+AC30+AD30+AF30 -> 0 | AK30: =Z30-AG30-AH30-AJ30 -> 465.9 | AU30: =SUM(AN30:AT30) -> 0 | AV30: 9 | AW30: =AU30+Z30+AI30-AJ30+AV30 -> 474.9 | AY30: -6.25 | AZ30: =6.25 -> 6.25 | BA30: 工伤利率调整，1月多收2月退，2月没退3月退 | BB30: 0 | BC30: =ROUND(AW30+BB30+AX30+AY30+AZ30,2) -> 474.9 | BD30: =ROUND(BC30*6%,2) -> 28.49 | BE30: =ROUND(SUM(BC30:BD30),2) -> 503.39
A31: 合计 | Z31: =SUBTOTAL(9,Z3:Z30) -> 222375.34 | AG31: =SUBTOTAL(9,AG3:AG30) -> 45743.84 | AK31: =SUBTOTAL(9,AK3:AK30) -> 176631.5 | AU31: =SUBTOTAL(9,AU3:AU30) -> 89938.25 | AV31: =SUM(AV3:AV30) -> 4105 | AW31: =SUBTOTAL(9,AW3:AW30) -> 316418.59 | AX31: =SUBTOTAL(9,AX3:AX30) -> 18.76 | AY31: =SUBTOTAL(9,AY3:AY30) -> -149.05 | AZ31: =SUBTOTAL(9,AZ3:AZ30) -> 21.25 | BB31: =SUBTOTAL(9,BB3:BB30) -> 6885 | BC31: =SUBTOTAL(9,BC3:BC30) -> 323194.55 | BD31: =SUBTOTAL(9,BD3:BD30) -> 19391.68 | BE31: =SUBTOTAL(9,BE3:BE30) -> 342586.23

Sheet 对账单
A1: 科目 | B1: 手工账单 | C1: 速创账单 | D1: 155 | E1: 预收一次性 | F1: 2月工会费 | G1: 本月垫付，下月收 | H1: 本月多收，下月退 | I1: 合计 | J1: 差异
A2: 管理费 | B2: ='202502'!BD31 -> 19391.68 | C2: =系统!E44 -> 21592.73 | D2: =27*155 -> 4185 | I2: =SUM(C2:G2) -> 25777.73 | J2: =B2-C2 -> -2201.05
A3: 风险费 | B3: ='202502'!BB31 -> 6885 | C3: 0 | I3: =SUM(C3:G3) -> 0 | J3: =B3-C3 -> 6885
A4: 个人四金 | B4: ='202502'!AG31 -> 45743.84 | C4: =系统!V44 -> 45743.84 | I4: =SUM(C4:G4) -> 45743.84 | J4: =B4-C4 -> 0
A5: 公司四金 | B5: ='202502'!AU31 -> 89938.25 | C5: =系统!O44 -> 89938.25 | I5: =SUM(C5:E5) -> 89938.25 | J5: =B5-C5 -> 0
A6: 工伤退费 | I6: =SUM(C6:G6) -> 0 | J6: =B6-C6 -> 0
A7: 代发工资 | B7: ='202502'!Z31-'202502'!AG31 -> 176631.5 | C7: =系统!W44 -> 176496.5 | D7: =5*27 -> 135 | I7: =SUM(C7:G7) -> 176631.5 | J7: =B7-C7 -> 135
A8: 上月垫付 | B8: ='202502'!AX31+'202502'!AZ31 -> 40.01 | D8: =40 -> 40 | I8: =SUM(C8:G8) -> 40 | J8: =B8-C8 -> 40.01
A9: 工会费 | B9: ='202502'!AV31 -> 4105 | D9: =B10 -> -149.05 | F9: =B9 -> 4105 | I9: =SUM(C9:G9) -> 3955.95 | J9: =B9-C9 -> 4105
A10: 上月多收 | B10: ='202502'!AY31 -> -149.05 | I10: =SUM(C10:G10) -> 0 | J10: =B10-C10 -> -149.05
A11: 小计 | B11: =SUM(B2:B10) -> 342586.23 | C11: =SUM(C2:C10) -> 333771.32 | D11: =SUM(D2:D10) -> 4210.95 | E11: =E5 -> 0 | F11: =F9 -> 4105 | G11: =G9 -> 0 | H11: =H9 -> 0 | I11: =SUM(C11:G11) -> 342087.27
A12: 附加税
A13: 增值税 | D13: =ROUND((D11+D12)*6%,2) -> 252.66 | F13: =ROUND((F11+F12)*6%,2) -> 246.3 | G13: =ROUND((G11+G12)*6%,2) -> 0 | H13: =ROUND((H11+H12)*6%,2) -> 0 | I13: =SUM(C13:G13) -> 498.96
A14: 总计 | B14: =SUM(B11:B13) -> 342586.23 | C14: =SUM(C11:C13) -> 333771.32 | D14: =SUM(D11:D13) -> 4463.61 | E14: =E11 -> 0 | F14: =SUM(F11:F13) -> 4351.3 | G14: =SUM(G11:G13) -> 0 | H14: =SUM(H11:H13) -> 0 | I14: =SUM(C14:H14) -> 342586.23
A15: 给客户账单金额 | I15: =B14 -> 342586.23
A16: 差异 | I16: =I15-I14 -> 0
A17: 不含税差异 | I17: =ROUND(I16/1.06,2) -> 0

Sheet 系统
A1: 200070
A2: 寄：梅园路77号人才大厦
B3: 中国电信股份有限公司上海分公司 王慧珏 收
D6: 上海外服布列吉科技有限公司
C7: Shanghai Foreign Service Bridge Technology Co,Ltd.
E9: 收款通知书
E10: ADVISE ON COLLECTION
E11: 2025年02月
A13: 公司名称：中国电信股份有限公司上海分公司 | J13: 帐单号：202502CH6594403
A14: 序号 | B14: 姓名 | C14: 发生年月 | D14: 入职日期 | E14: 管理费 | F14: 当月社保基数 | G14: 当月公积金基数 | H14: 社保类 公司支付 Social Insurance Premiums Paid by Employer | N14: 公积金类 公司支付 Provident Fund Paid by Employer | O14: 公司合计 | P14: 社保类 个人支付 Social Insurance Premiums Paid by Employee | U14: 公积金类 个人支付 Provident Fund Paid by Employee | V14: 个人合计 | W14: 代办薪酬 | X14: 其他 | Y14: 总计 | Z14: 备注 | AA14: 外服工号 | AB14: 证件号码 | AC14: 应纳税金额 | AD14: 税率 | AE14: 增值税
A15: S/N | B15: Name | C15: YYYYMM | D15: Employment Start Date | E15: Adm Fee | F15: Social Insurance Base Amount of Current Month | G15: Provident Fund Base Amount of Current Month | H15: 养老保险 Endowment | I15: 医疗保险 Medical | J15: 失业保险 Unemploy-ment | K15: 工伤保险 Employment Injury | L15: 医疗生育保险 Medical Maternity | M15: 保障金 Disabled people&Back pay Fund | N15: 公积金 Provident Fund | O15: Subtotal of Employer Payment | P15: 养老保险 Endowment | Q15: 医疗保险 Medical | R15: 失业保险 Unemploy-ment | S15: 工伤保险 Employment Injury | T15: 医疗生育保险 Medical Maternity | U15: 公积金 Provident Fund | V15: Subtotal of Personal Payment | W15: Agency of Wage Payment | X15: Others | Y15: Total | Z15: Remarks | AA15: SFSC ID | AB15: ID Card | AC15: Taxable Amount | AD15: Tax Rate | AE15: VAT
A16: 1 | B16: 陈世碧 | C16: 202502 | D16: 2024-06-01 | E16: 872.12 | F16: 10043 | G16: 10043 | H16: 1606.88 | I16: 903.88 | J16: 50.22 | K16: 20.09 | M16: 150.65 | N16: 703 | O16: =SUM(H16:N16) -> 3434.72 | P16: 803.44 | Q16: 200.86 | R16: 50.22 | U16: 703 | V16: =SUM(P16:U16) -> 1757.52 | W16: 7576.58 | Y16: =SUM(E16,O16,V16:X16) -> 13640.94 | AA16: 5861127 | AB16: 513023197709136722 | AC16: 12868.82 | AD16: 6% | AE16: 772.12
A17: 2 | B17: 程祖云 | C17: 202502 | D17: 2024-06-01 | E17: 759.74 | F17: 9608 | G17: 9608 | H17: 1537.28 | I17: 864.72 | J17: 48.04 | K17: 19.22 | M17: 144.12 | N17: 673 | O17: =SUM(H17:N17) -> 3286.38 | P17: 768.64 | Q17: 192.16 | R17: 48.04 | U17: 673 | V17: =SUM(P17:U17) -> 1681.84 | W17: 5927.52 | Y17: =SUM(E17,O17,V17:X17) -> 11655.48 | AA17: 5861128 | AB17: 411524198609258442 | AC17: 10995.74 | AD17: 6% | AE17: 659.74
A18: 3 | B18: 高雄飞 | C18: 202502 | D18: 2024-06-01 | E18: 821.7 | F18: 9424 | G18: 9424 | H18: 1507.84 | I18: 848.16 | J18: 47.12 | K18: 18.85 | M18: 141.36 | N18: 660 | O18: =SUM(H18:N18) -> 3223.33 | P18: 753.92 | Q18: 188.48 | R18: 47.12 | U18: 660 | V18: =SUM(P18:U18) -> 1649.52 | W18: 7055.58 | Y18: =SUM(E18,O18,V18:X18) -> 12750.13 | AA18: 5544585 | AB18: 310101198402231014 | AC18: 12028.42 | AD18: 6% | AE18: 721.71
A19: 4 | B19: 戈婷婷 | C19: 202502 | D19: 2024-06-01 | E19: 871.74 | F19: 10443 | G19: 10443 | H19: 1670.88 | I19: 939.88 | J19: 52.22 | K19: 20.89 | M19: 156.65 | N19: 731 | O19: =SUM(H19:N19) -> 3571.52 | P19: 835.44 | Q19: 208.86 | R19: 52.22 | U19: 731 | V19: =SUM(P19:U19) -> 1827.52 | W19: 7363.26 | Y19: =SUM(E19,O19,V19:X19) -> 13634.04 | AA19: 5544594 | AB19: 320821199610185147 | AC19: 12862.31 | AD19: 6% | AE19: 771.73
A20: 5 | B20: 顾陆慧 | C20: 202502 | D20: 2024-06-01 | E20: 1013.44 | F20: 12136 | G20: 12136 | H20: 1941.76 | I20: 1092.24 | J20: 60.68 | K20: 24.27 | M20: 182.04 | N20: 850 | O20: =SUM(H20:N20) -> 4150.99 | P20: 970.88 | Q20: 242.72 | R20: 60.68 | U20: 850 | V20: =SUM(P20:U20) -> 2124.28 | W20: 8848.66 | Y20: =SUM(E20,O20,V20:X20) -> 16137.37 | AA20: 5863338 | AB20: 310230197904164766 | AC20: 15223.94 | AD20: 6% | AE20: 913.43
A21: 6 | B21: 杭亮 | C21: 202502 | D21: 2024-06-01 | E21: 636.11 | F21: 9226 | G21: 9226 | H21: 1476.16 | I21: 830.34 | J21: 46.13 | K21: 18.45 | M21: 138.39 | N21: 646 | O21: =SUM(H21:N21) -> 3155.47 | P21: 738.08 | Q21: 184.52 | R21: 46.13 | U21: 646 | V21: =SUM(P21:U21) -> 1614.73 | W21: 4064.97 | Y21: =SUM(E21,O21,V21:X21) -> 9471.28 | AA21: 5544580 | AB21: 310110198004027057 | AC21: 8935.17 | AD21: 6% | AE21: 536.11
A22: 7 | B22: 贺彦 | C22: 202502 | D22: 2024-06-01 | E22: 513.39 | F22: 7384 | G22: 4906 | H22: 1181.44 | I22: 664.56 | J22: 36.92 | K22: 14.77 | M22: 110.76 | N22: 343 | O22: =SUM(H22:N22) -> 2351.45 | P22: 590.72 | Q22: 147.68 | R22: 36.92 | U22: 343 | V22: =SUM(P22:U22) -> 1118.32 | W22: 3320 | Y22: =SUM(E22,O22,V22:X22) -> 7303.16 | AA22: 5701787 | AB22: 310108198901250513 | AC22: 6889.76 | AD22: 6% | AE22: 413.4
A23: 8 | B23: 胡佳华 | C23: 202502 | D23: 2025-01-01 | E23: 840.19 | F23: 9575 | G23: 9575 | H23: 1532 | I23: 861.76 | J23: 47.88 | K23: 19.15 | M23: 143.63 | N23: 670 | O23: =SUM(H23:N23) -> 3274.42 | P23: 766 | Q23: 191.5 | R23: 47.88 | U23: 670 | V23: =SUM(P23:U23) -> 1675.38 | W23: 7286.62 | Y23: =SUM(E23,O23,V23:X23) -> 13076.61 | AA23: 6242778 | AB23: 310109198103142020 | AC23: 12336.42 | AD23: 6% | AE23: 740.19
A24: 9 | B24: 季华 | C24: 202502 | D24: 2024-06-01 | E24: 1016.88 | F24: 10475 | G24: 10475 | H24: 1676 | I24: 942.76 | J24: 52.38 | K24: 20.95 | M24: 157.13 | N24: 733 | O24: =SUM(H24:N24) -> 3582.22 | P24: 838 | Q24: 209.5 | R24: 52.38 | U24: 733 | V24: =SUM(P24:U24) -> 1832.88 | W24: 9766.12 | Y24: =SUM(E24,O24,V24:X24) -> 16198.1 | AA24: 5544586 | AB24: 310115198609170130 | AC24: 15281.22 | AD24: 6% | AE24: 916.88
A25: 10 | B25: 梁裔杰 | C25: 202502 | D25: 2024-06-01 | E25: 948.61 | F25: 7384 | G25: 7139 | H25: 1181.44 | I25: 664.56 | J25: 36.92 | K25: 14.77 | M25: 110.76 | N25: 500 | O25: =SUM(H25:N25) -> 2508.45 | P25: 590.72 | Q25: 147.68 | R25: 36.92 | U25: 500 | V25: =SUM(P25:U25) -> 1275.32 | W25: 10259.62 | Y25: =SUM(E25,O25,V25:X25) -> 14992 | AA25: 5861130 | AB25: 310113198509301719 | AC25: 14143.38 | AD25: 6% | AE25: 848.62
A26: 11 | B26: 罗文彬 | C26: 202502 | D26: 2024-06-01 | E26: 803.31 | F26: 14537 | G26: 14537 | H26: 2325.92 | I26: 1308.34 | J26: 72.69 | K26: 29.07 | M26: 218.06 | N26: 1018 | O26: =SUM(H26:N26) -> 4972.08 | P26: 1162.96 | Q26: 290.74 | R26: 72.69 | U26: 1018 | V26: =SUM(P26:U26) -> 2544.39 | W26: 4105.25 | Y26: =SUM(E26,O26,V26:X26) -> 12425.03 | AA26: 5922255 | AB26: 310110198902103234 | AC26: 11721.73 | AD26: 6% | AE26: 703.3
A27: 12 | B27: 孟浩杰 | C27: 202502 | D27: 2024-06-01 | E27: 855.03 | F27: 9241 | G27: 9241 | H27: 1478.56 | I27: 831.7 | J27: 46.21 | K27: 18.48 | M27: 138.62 | N27: 647 | O27: =SUM(H27:N27) -> 3160.57 | P27: 739.28 | Q27: 184.82 | R27: 46.21 | U27: 647 | V27: =SUM(P27:U27) -> 1617.31 | W27: 7706.03 | Y27: =SUM(E27,O27,V27:X27) -> 13338.94 | AA27: 5544588 | AB27: 510108198209090637 | AC27: 12583.91 | AD27: 6% | AE27: 755.03
A28: 13 | B28: 戚继英 | C28: 202502 | D28: 2024-06-01 | E28: 27.95 | O28: =SUM(H28:N28) -> 0 | V28: =SUM(P28:U28) -> 0 | W28: 465.9 | Y28: =SUM(E28,O28,V28:X28) -> 493.85 | AA28: 5544593 | AB28: 310102198004243227 | AC28: 465.9 | AD28: 6% | AE28: 27.95
A29: 14 | B29: 邱杭佳 | C29: 202502 | D29: 2024-06-01 | E29: 616.11 | F29: 7474 | G29: 7474 | H29: 1195.84 | I29: 672.66 | J29: 37.37 | K29: 14.95 | M29: 112.11 | N29: 523 | O29: =SUM(H29:N29) -> 2555.93 | P29: 597.92 | Q29: 149.48 | R29: 37.37 | U29: 523 | V29: =SUM(P29:U29) -> 1307.77 | W29: 4638.09 | Y29: =SUM(E29,O29,V29:X29) -> 9117.9 | AA29: 5544592 | AB29: 31010819830921103X | AC29: 8601.78 | AD29: 6% | AE29: 516.12
A30: 15 | B30: 王偲 | C30: 202502 | D30: 2024-06-01 | E30: 653.14 | F30: 8261 | G30: 8261 | H30: 1321.76 | I30: 743.5 | J30: 41.31 | K30: 16.52 | M30: 123.92 | N30: 578 | O30: =SUM(H30:N30) -> 2825.01 | P30: 660.88 | Q30: 165.22 | R30: 41.31 | U30: 578 | V30: =SUM(P30:U30) -> 1445.41 | W30: 4848.53 | Y30: =SUM(E30,O30,V30:X30) -> 9772.09 | AA30: 5544583 | AB30: 310109198908200531 | AC30: 9218.95 | AD30: 6% | AE30: 553.14
A31: 16 | B31: 王凤凌 | C31: 202502 | D31: 2024-06-01 | E31: 533.85 | F31: 7384 | G31: 4686 | H31: 1181.44 | I31: 664.56 | J31: 36.92 | K31: 14.77 | M31: 110.76 | N31: 328 | O31: =SUM(H31:N31) -> 2336.45 | P31: 590.72 | Q31: 147.68 | R31: 36.92 | U31: 328 | V31: =SUM(P31:U31) -> 1103.32 | W31: 3691 | Y31: =SUM(E31,O31,V31:X31) -> 7664.62 | AA31: 5544584 | AB31: 31011019870909564X | AC31: 7230.76 | AD31: 6% | AE31: 433.86
A32: 17 | B32: 王一峰 | C32: 202502 | D32: 2024-06-01 | E32: 860.65 | F32: 16443 | G32: 16443 | H32: 2630.88 | I32: 1479.88 | J32: 82.22 | K32: 32.89 | M32: 246.65 | N32: 1151 | O32: =SUM(H32:N32) -> 5623.52 | P32: 1315.44 | Q32: 328.86 | R32: 82.22 | U32: 1151 | V32: =SUM(P32:U32) -> 2877.52 | W32: 4076.48 | Y32: =SUM(E32,O32,V32:X32) -> 13438.17 | AA32: 5544582 | AB32: 310230198106182913 | AC32: 12677.53 | AD32: 6% | AE32: 760.64
A33: 18 | B33: 王邹强 | C33: 202502 | D33: 2024-06-01 | E33: 712.79 | F33: 8707 | G33: 8707 | H33: 1393.12 | I33: 783.64 | J33: 43.54 | K33: 17.41 | M33: 130.61 | N33: 609 | O33: =SUM(H33:N33) -> 2977.32 | P33: 696.56 | Q33: 174.14 | R33: 43.54 | U33: 609 | V33: =SUM(P33:U33) -> 1523.24 | W33: 5612.6 | Y33: =SUM(E33,O33,V33:X33) -> 10825.95 | AA33: 5544577 | AB33: 310108198909220554 | AC33: 10213.16 | AD33: 6% | AE33: 612.79
A34: 19 | B34: 王姗姗 | C34: 202502 | D34: 2024-06-01 | E34: 1927.52 | F34: 18040 | G34: 18040 | H34: 2886.4 | I34: 1623.6 | J34: 90.2 | K34: 36.08 | M34: 270.6 | N34: 1263 | O34: =SUM(H34:N34) -> 6169.88 | P34: 1443.2 | Q34: 360.8 | R34: 90.2 | U34: 1263 | V34: =SUM(P34:U34) -> 3157.2 | W34: 21031.73 | Y34: =SUM(E34,O34,V34:X34) -> 32286.33 | AA34: 5544591 | AB34: 34112519880604436X | AC34: 30458.81 | AD34: 6% | AE34: 1827.52
A35: 20 | B35: 吴裕刚 | C35: 202502 | D35: 2024-06-01 | E35: 862.99 | F35: 8102 | G35: 8102 | H35: 1296.32 | I35: 729.18 | J35: 40.51 | K35: 16.2 | M35: 121.53 | N35: 567 | O35: =SUM(H35:N35) -> 2770.74 | P35: 648.16 | Q35: 162.04 | R35: 40.51 | U35: 567 | V35: =SUM(P35:U35) -> 1417.71 | W35: 8428.07 | Y35: =SUM(E35,O35,V35:X35) -> 13479.51 | AA35: 5544595 | AB35: 31010219810818361X | AC35: 12716.53 | AD35: 6% | AE35: 762.98
A36: 21 | B36: 谢俊敏 | C36: 202502 | D36: 2024-06-01 | E36: 665.62 | F36: 7974 | G36: 7974 | H36: 1275.84 | I36: 717.66 | J36: 39.87 | K36: 15.95 | M36: 119.61 | N36: 558 | O36: =SUM(H36:N36) -> 2726.93 | P36: 637.92 | Q36: 159.48 | R36: 39.87 | U36: 558 | V36: =SUM(P36:U36) -> 1395.27 | W36: 5204.87 | Y36: =SUM(E36,O36,V36:X36) -> 9992.69 | AA36: 5861129 | AB36: 310110198911171036 | AC36: 9427.06 | AD36: 6% | AE36: 565.63
A37: 22 | B37: 熊伟 | C37: 202502 | D37: 2024-06-01 | E37: 580.89 | F37: 8888 | G37: 8888 | H37: 1422.08 | I37: 799.92 | J37: 44.44 | K37: 17.78 | M37: 133.32 | N37: 622 | O37: =SUM(H37:N37) -> 3039.54 | P37: 711.04 | Q37: 177.76 | R37: 44.44 | U37: 622 | V37: =SUM(P37:U37) -> 1555.24 | W37: 3320 | Y37: =SUM(E37,O37,V37:X37) -> 8495.67 | AA37: 5544579 | AB37: 310109198905074533 | AC37: 8014.77 | AD37: 6% | AE37: 480.9
A38: 23 | B38: 杨晓燕 | C38: 202502 | D38: 2024-06-01 | E38: 737.05 | F38: 8472 | G38: 8472 | H38: 1355.52 | I38: 762.48 | J38: 42.36 | K38: 16.94 | M38: 127.08 | N38: 593 | O38: =SUM(H38:N38) -> 2897.38 | P38: 677.76 | Q38: 169.44 | R38: 42.36 | U38: 593 | V38: =SUM(P38:U38) -> 1482.56 | W38: 6137.44 | Y38: =SUM(E38,O38,V38:X38) -> 11254.43 | AA38: 5544587 | AB38: 34222519770913404X | AC38: 10617.38 | AD38: 6% | AE38: 637.05
A39: 24 | B39: 叶毅 | C39: 202502 | D39: 2024-06-01 | E39: 759 | F39: 7759 | G39: 7759 | H39: 1241.44 | I39: 698.32 | J39: 38.8 | K39: 15.52 | M39: 116.39 | N39: 543 | O39: =SUM(H39:N39) -> 2653.47 | P39: 620.72 | Q39: 155.18 | R39: 38.8 | U39: 543 | V39: =SUM(P39:U39) -> 1357.7 | W39: 6872.14 | Y39: =SUM(E39,O39,V39:X39) -> 11642.31 | AA39: 5861126 | AB39: 310110198502133266 | AC39: 10983.31 | AD39: 6% | AE39: 659
A40: 25 | B40: 张梦诏 | C40: 202502 | D40: 2024-06-01 | E40: 709.05 | F40: 7384 | G40: 5239 | H40: 1181.44 | I40: 664.56 | J40: 36.92 | K40: 14.77 | M40: 110.76 | N40: 367 | O40: =SUM(H40:N40) -> 2375.45 | P40: 590.72 | Q40: 147.68 | R40: 36.92 | U40: 367 | V40: =SUM(P40:U40) -> 1142.32 | W40: 6533.02 | Y40: =SUM(E40,O40,V40:X40) -> 10759.84 | AA40: 5726531 | AB40: 342423200108298172 | AC40: 10150.78 | AD40: 6% | AE40: 609.06
... A43: 28 | B43: 朱云 | C43: 202502 | D43: 2024-06-01 | E43: 696.92 | F43: 11909 | G43: 11909 | H43: 1905.44 | I43: 1071.82 | J43: 59.55 | K43: 23.82 | M43: 178.64 | N43: 834 | O43: =SUM(H43:N43) -> 4073.27 | P43: 952.72 | Q43: 238.18 | R43: 59.55 | U43: 834 | V43: =SUM(P43:U43) -> 2084.45 | W43: 3691 | Y43: =SUM(E43,O43,V43:X43) -> 10545.64 | AA43: 5922254 | AB43: 310110198810200045 | AC43: 9948.72 | AD43: 6% | AE43: 596.92
A44: 合计（RMB） | E44: =SUM(E16:E43) -> 21592.73 | H44: =SUM(H16:H43) -> 42341.76 | I44: =SUM(I16:I43) -> 23817.36 | J44: =SUM(J16:J43) -> 1323.24 | K44: =SUM(K16:K43) -> 529.29 | L44: =SUM(L16:L43) -> 0 | M44: =SUM(M16:M43) -> 3969.6 | N44: =SUM(N16:N43) -> 17957 | O44: =SUM(O16:O43) -> 89938.25 | ... Y44: =SUM(Y16:Y43) -> 333771.32 | AC44: =SUM(AC16:AC43) -> 314878.56 | AE44: =SUM(AE16:AE43) -> 18892.76
A45: 总计（RMB）已包含历月补收人民币叁拾叁万叁仟柒佰柒拾壹圆叁角贰分 | Y45: 333771.32
A47: 其他费用
...
