Workbook

Sheet 202502
A1: 序号 | B1: 计薪 周期 | C1: 工号 | D1: 姓名 | E1: 身份证号 | F1: 劳动合同起始日期 | G1: 劳动合同结束日期 | H1: 离职日期 | I1: 社保缴纳地 | J1: 星级费用 | K1: 考核费用 | L1: 量化费用 | M1: 专项费用 | Z1: 当月税前工资合计 | AA1: 社保基数(个人) | AB1: 养老保险(个人) | AC1: 医疗保险(个人) | AD1: 失业保险(个人) | AE1: 公积金基数(个人) | AF1: 住房公积金(个人) | AG1: 员工五险一金合计 | AH1: 本月个人所得税-系统导出 | AI1: 税后增加 | AJ1: 税后扣减 | AK1: 员工实发合计 | AL1: 社保基数 | AM1: 公积金基数 | AN1: 养老缴费 | AO1: 医疗缴费 | AP1: 失业保险 | AQ1: 工伤保险 | AR1: 生育保险 | AS1: 公积金 | AT1: 残保金 | AU1: 企业五险一金合计 | AV1: 工会费 | AW1: 代收付合计 | AX1: 本月多收，下月退 | AY1: 社保备注 | AZ1: 外包服务费 | BA1: 税前项合计 | BB1: 增值税 | BC1: 总计 | BD1: 工会费返回
A2: NO. | B2: Salary Cycle | C2: Employee No. | D2: Name | E2: ID No. | F2: Contract Starting Date | G2: Contract Expiry Date | H2: Exit Date | I2: Social Insurance City | J2: Contract Salary | K2: Assessment fees | L2: Quantifying costs | M2: 支局专项 | N2: 部门加奖 | O2: 其他费用 | P2: 效能补贴 | Q2: 高温费及清凉饮料费 （6-9月） | R2: 伙食补贴 | S2: 独生子女奖励 | T2: 保险费 | U2: 体检费用 | V2: 赔偿金 | W2: 劳防用品 | X2: 保障补差 | Y2: 其他扣款 | Z2: Pre-tax Total | AA2: Social Insurance Base | AB2: Pension Employee | AC2: Medical Employee | AD2: Umemployment Employee | AE2: Housing Fund Base | AF2: Housing Fund Employee | AG2: Total Amount of Social Insurance(EE) | AH2: Personal Income Tax | AI2: Increase After-tax payment | AJ2: Reduction After-tax payment | AK2: After-tax total Income | AL2: Social Insurance Base | AM2: Housing Fund Base | AN2: Pension Employer | AO2: Medical Employer | AP2: Umemployment Employer | AQ2: Injury Employer | AR2: Maternity Insurance Employer | AS2: Housing Fund Employer | AT2: Disabled people&Back pay Fund | AU2: Total Amount of Social Insurance(ER) | AV2: Union Fee | AW2: Payment Total | AY2: Social Security remark | AZ2: Service Fee | BA2: Total | BB2: VAT | BC2: Subtotal
A3: =ROW()-2 -> 1 | B3: 2502 | C3: WB023742 | D3: 陈翔宇 | E3: 421024199409102039 | F3: 45383 | G3: 45747 | I3: 上海 | J3: 1510 | K3: 3150 | L3: 1020.4 | O3: 742.07 | R3: 630 | Y3: -82 | Z3: =SUM(J3:Y3) -> 6970.47 | AA3: 7384 | AB3: 590.72 | AC3: 147.68 | AD3: 36.92 | AE3: 5865 | AF3: 411 | AG3: =AB3+AC3+AD3+AF3 -> 1186.32 | AK3: =Z3-AG3-AH3 -> 5784.15 | AL3: 7384 | AM3: 5865 | AN3: =ROUND(AL3*16%,2) -> 1181.44 | AO3: =ROUND(AL3*9%,2) -> 664.56 | AP3: =ROUND(AL3*0.5%,2) -> 36.92 | AQ3: 14.77 | AS3: =ROUND(AM3*7%,0) -> 411 | AT3: =ROUND(IF(AL3<22792,AL3*1.5%,22792*1.5%),2) -> 110.76 | AU3: =SUM(AN3:AT3) -> 2419.45 | AV3: 127 | AW3: =AU3+Z3+AI3-AJ3+AV3 -> 9516.92 | AX3: -4.13 | AY3: 工伤利率调整，1月多收2月退 | AZ3: 255 | BA3: =ROUND(AW3+AZ3+AX3,2) -> 9767.79 | BB3: =ROUND(BA3*6%,2) -> 586.07 | BC3: =ROUND(SUM(BA3:BB3),2) -> 10353.86 | BD3: =AV3-5 -> 122
A4: =ROW()-2 -> 2 | B4: 2502 | C4: WB053401 | D4: 汪思思 | E4: 362334198307140025 | F4: 45444 | G4: 45808 | I4: 上海 | J4: 900 | K4: 2719.75 | L4: 578 | O4: 0 | R4: 630 | Y4: 0 | Z4: =SUM(J4:Y4) -> 4827.75 | AA4: 7384 | AB4: 590.72 | AC4: 147.68 | AD4: 36.92 | AE4: 6776 | AF4: 474 | AG4: =AB4+AC4+AD4+AF4 -> 1249.32 | AK4: =Z4-AG4-AH4 -> 3578.43 | AL4: 7384 | AM4: 6776 | AN4: =ROUND(AL4*16%,2) -> 1181.44 | AO4: =ROUND(AL4*9%,2) -> 664.56 | AP4: =ROUND(AL4*0.5%,2) -> 36.92 | AQ4: 14.77 | AS4: =ROUND(AM4*7%,0) -> 474 | AT4: =ROUND(IF(AL4<22792,AL4*1.5%,22792*1.5%),2) -> 110.76 | AU4: =SUM(AN4:AT4) -> 2482.45 | AV4: 84 | AW4: =AU4+Z4+AI4-AJ4+AV4 -> 7394.2 | AX4: -4.13 | AY4: 工伤利率调整，1月多收2月退 | AZ4: 255 | BA4: =ROUND(AW4+AZ4+AX4,2) -> 7645.07 | BB4: =ROUND(BA4*6%,2) -> 458.7 | BC4: =ROUND(SUM(BA4:BB4),2) -> 8103.77 | BD4: =AV4-5 -> 79
A5: =ROW()-2 -> 3 | B5: 2502 | C5: WB002504 | D5: 颜双徐 | E5: 31010919920227201X | F5: 45444 | G5: 45808 | I5: 上海 | J5: 1030 | K5: 3671.35 | L5: 357 | O5: 0 | R5: 630 | X5: 89.65 | Y5: 0 | Z5: =SUM(J5:Y5) -> 5778 | AA5: 14019 | AB5: 1121.52 | AC5: 280.38 | AD5: 70.1 | AE5: 14019 | AF5: 981 | AG5: =AB5+AC5+AD5+AF5 -> 2453 | AK5: =Z5-AG5-AH5 -> 3325 | AL5: 14019 | AM5: 14019 | AN5: =ROUND(AL5*16%,2) -> 2243.04 | AO5: 1261.72 | AP5: =ROUND(AL5*0.5%,2) -> 70.1 | AQ5: 28.04 | AS5: =ROUND(AM5*7%,0) -> 981 | AT5: =ROUND(IF(AL5<22792,AL5*1.5%,22792*1.5%),2) -> 210.29 | AU5: =SUM(AN5:AT5) -> 4794.19 | AV5: 103 | AW5: =AU5+Z5+AI5-AJ5+AV5 -> 10675.19 | AX5: -7.85 | AY5: 工伤利率调整，1月多收2月退 | AZ5: 255 | BA5: =ROUND(AW5+AZ5+AX5,2) -> 10922.34 | BB5: =ROUND(BA5*6%,2) -> 655.34 | BC5: =ROUND(SUM(BA5:BB5),2) -> 11577.68 | BD5: =AV5-5 -> 98
A6: =ROW()-2 -> 4 | B6: 2502 | C6: WB047229 | D6: 曾娓 | E6: 362529198711200026 | F6: 45444 | G6: 45808 | I6: 上海 | J6: 1030 | K6: 3366 | L6: 359.45 | O6: 989.43 | R6: 630 | Y6: 0 | Z6: =SUM(J6:Y6) -> 6374.88 | AA6: 10618 | AB6: 849.44 | AC6: 212.36 | AD6: 53.09 | AE6: 10618 | AF6: 743 | AG6: =AB6+AC6+AD6+AF6 -> 1857.89 | AK6: =Z6-AG6-AH6 -> 4516.99 | AL6: 10618 | AM6: 10618 | AN6: =ROUND(AL6*16%,2) -> 1698.88 | AO6: =ROUND(AL6*9%,2) -> 955.62 | AP6: =ROUND(AL6*0.5%,2) -> 53.09 | AQ6: 21.24 | AS6: =ROUND(AM6*7%,0) -> 743 | AT6: =ROUND(IF(AL6<22792,AL6*1.5%,22792*1.5%),2) -> 159.27 | AU6: =SUM(AN6:AT6) -> 3631.1 | AV6: 115 | AW6: =AU6+Z6+AI6-AJ6+AV6 -> 10120.98 | AX6: -5.94 | AY6: 工伤利率调整，1月多收2月退 | AZ6: 255 | BA6: =ROUND(AW6+AZ6+AX6,2) -> 10370.04 | BB6: =ROUND(BA6*6%,2) -> 622.2 | BC6: =ROUND(SUM(BA6:BB6),2) -> 10992.24 | BD6: =AV6-5 -> 110
A7: =ROW()-2 -> 5 | B7: 2502 | C7: WB019304 | D7: 顾杰 | E7: 310225198410064814 | F7: 45444 | G7: 45808 | I7: 上海 | J7: 1300 | K7: 17414 | L7: 1173.25 | O7: 1360.46 | R7: 630 | Y7: 0 | Z7: =SUM(J7:Y7) -> 21877.71 | AA7: 18333 | AB7: 1466.64 | AC7: 366.66 | AD7: 91.67 | AE7: 18333 | AF7: 1283 | AG7: =AB7+AC7+AD7+AF7 -> 3207.97 | AK7: =Z7-AG7-AH7 -> 18669.74 | AL7: 18333 | AM7: 18333 | AN7: =ROUND(AL7*16%,2) -> 2933.28 | AO7: 1649.98 | AP7: =ROUND(AL7*0.5%,2) -> 91.67 | AQ7: 36.67 | AS7: =ROUND(AM7*7%,0) -> 1283 | AT7: =ROUND(IF(AL7<22792,AL7*1.5%,22792*1.5%),2) -> 275 | AU7: =SUM(AN7:AT7) -> 6269.6 | AV7: 425 | AW7: =AU7+Z7+AI7-AJ7+AV7 -> 28572.31 | AX7: -10.26 | AY7: 工伤利率调整，1月多收2月退 | AZ7: 255 | BA7: =ROUND(AW7+AZ7+AX7,2) -> 28817.05 | BB7: =ROUND(BA7*6%,2) -> 1729.02 | BC7: =ROUND(SUM(BA7:BB7),2) -> 30546.07 | BD7: =AV7-5 -> 420
A8: =ROW()-2 -> 6 | B8: 2502 | C8: WB038424 | D8: 赵俊 | E8: 310102198712184475 | F8: 45444 | G8: 45808 | I8: 上海 | J8: 1030 | K8: 2730.4 | L8: 668.1 | O8: 989.43 | R8: 630 | X8: 44.58 | Y8: -8 | Z8: =SUM(J8:Y8) -> 6084.51 | AA8: 10115 | AB8: 809.2 | AC8: 202.3 | AD8: 50.58 | AE8: 10115 | AF8: 708 | AG8: =AB8+AC8+AD8+AF8 -> 1770.08 | AK8: =Z8-AG8-AH8 -> 4314.43 | AL8: 10115 | AM8: 10115 | AN8: =ROUND(AL8*16%,2) -> 1618.4 | AO8: 910.36 | AP8: =ROUND(AL8*0.5%,2) -> 50.58 | AQ8: 20.23 | AS8: =ROUND(AM8*7%,0) -> 708 | AT8: =ROUND(IF(AL8<22792,AL8*1.5%,22792*1.5%),2) -> 151.73 | AU8: =SUM(AN8:AT8) -> 3459.3 | AV8: 109 | AW8: =AU8+Z8+AI8-AJ8+AV8 -> 9652.81 | AX8: -5.66 | AY8: 工伤利率调整，1月多收2月退 | AZ8: 255 | BA8: =ROUND(AW8+AZ8+AX8,2) -> 9902.15 | BB8: =ROUND(BA8*6%,2) -> 594.13 | BC8: =ROUND(SUM(BA8:BB8),2) -> 10496.28 | BD8: =AV8-5 -> 104
A9: =ROW()-2 -> 7 | B9: 2502 | C9: WB013461 | D9: 陈斌 | E9: 310106198410231614 | F9: 45444 | G9: 45808 | H9: 45684 | I9: 上海 | J9: 0 | K9: 1386 | L9: 190 | O9: 3451.6 | R9: 0 | V9: 26275 | Y9: 0 | Z9: =SUM(J9:Y9) -> 31302.6 | AG9: =AB9+AC9+AD9+AF9 -> 0 | AK9: =Z9-AG9-AH9 -> 31302.6 | AU9: =SUM(AN9:AT9) -> 0 | AV9: 626 | AW9: =AU9+Z9+AI9-AJ9+AV9 -> 31928.6 | AX9: -4.13 | AY9: 工伤利率调整，1月多收2月退 | AZ9: 0 | BA9: =ROUND(AW9+AZ9+AX9,2) -> 31924.47 | BB9: =ROUND(BA9*6%,2) -> 1915.47 | BC9: =ROUND(SUM(BA9:BB9),2) -> 33839.94 | BD9: =AV9-5 -> 621
A10: =ROW()-2 -> 8 | B10: 2502 | C10: WB050221 | D10: 胡颖琦 | E10: 310101197211151615 | F10: 45444 | G10: 45808 | I10: 上海 | J10: 950 | K10: 3078 | L10: 872 | O10: 0 | R10: 630 | Y10: -4.4 | Z10: =SUM(J10:Y10) -> 5525.6 | AA10: 7384 | AB10: 590.72 | AC10: 147.68 | AD10: 36.92 | AE10: 7234 | AF10: 506 | AG10: =AB10+AC10+AD10+AF10 -> 1281.32 | AK10: =Z10-AG10-AH10 -> 4244.28 | AL10: 7384 | AM10: 7234 | AN10: =ROUND(AL10*16%,2) -> 1181.44 | AO10: =ROUND(AL10*9%,2) -> 664.56 | AP10: =ROUND(AL10*0.5%,2) -> 36.92 | AQ10: 14.77 | AS10: =ROUND(AM10*7%,0) -> 506 | AT10: =ROUND(IF(AL10<22792,AL10*1.5%,22792*1.5%),2) -> 110.76 | AU10: =SUM(AN10:AT10) -> 2514.45 | AV10: 98 | AW10: =AU10+Z10+AI10-AJ10+AV10 -> 8138.05 | AX10: -4.13 | AY10: 工伤利率调整，1月多收2月退 | AZ10: 255 | BA10: =ROUND(AW10+AZ10+AX10,2) -> 8388.92 | BB10: =ROUND(BA10*6%,2) -> 503.34 | BC10: =ROUND(SUM(BA10:BB10),2) -> 8892.26 | BD10: =AV10-5 -> 93
A11: =ROW()-2 -> 9 | B11: 2502 | C11: WB003568 | D11: 陈敏 | E11: 330327198311300617 | F11: 45444 | G11: 45808 | I11: 上海 | J11: 1030 | K11: 2790 | L11: 2117.31 | O11: 0 | R11: 630 | Y11: -884.4 | Z11: =SUM(J11:Y11) -> 5682.91 | AA11: 7384 | AB11: 590.72 | AC11: 147.68 | AD11: 36.92 | AE11: 6812 | AF11: 477 | AG11: =AB11+AC11+AD11+AF11 -> 1252.32 | AK11: =Z11-AG11-AH11 -> 4430.59 | AL11: 7384 | AM11: 6812 | AN11: =ROUND(AL11*16%,2) -> 1181.44 | AO11: =ROUND(AL11*9%,2) -> 664.56 | AP11: =ROUND(AL11*0.5%,2) -> 36.92 | AQ11: 14.77 | AS11: =ROUND(AM11*7%,0) -> 477 | AT11: =ROUND(IF(AL11<22792,AL11*1.5%,22792*1.5%),2) -> 110.76 | AU11: =SUM(AN11:AT11) -> 2485.45 | AV11: 101 | AW11: =AU11+Z11+AI11-AJ11+AV11 -> 8269.36 | AX11: -4.13 | AY11: 工伤利率调整，1月多收2月退 | AZ11: 255 | BA11: =ROUND(AW11+AZ11+AX11,2) -> 8520.23 | BB11: =ROUND(BA11*6%,2) -> 511.21 | BC11: =ROUND(SUM(BA11:BB11),2) -> 9031.44 | BD11: =AV11-5 -> 96
A12: =ROW()-2 -> 10 | B12: 2502 | C12: WB019309 | D12: 黄晓菲 | E12: 310114198604103821 | F12: 45444 | G12: 45808 | I12: 上海 | J12: 1300 | K12: 10336 | L12: 1390.15 | O12: 989.43 | R12: 630 | Y12: -70.5 | Z12: =SUM(J12:Y12) -> 14575.08 | AA12: 19290 | AB12: 1543.2 | AC12: 385.8 | AD12: 96.45 | AE12: 19290 | AF12: 1350 | AG12: =AB12+AC12+AD12+AF12 -> 3375.45 | AK12: =Z12-AG12-AH12 -> 11199.63 | AL12: 19290 | AM12: 19290 | AN12: =ROUND(AL12*16%,2) -> 3086.4 | AO12: =ROUND(AL12*9%,2) -> 1736.1 | AP12: =ROUND(AL12*0.5%,2) -> 96.45 | AQ12: 38.58 | AS12: =ROUND(AM12*7%,0) -> 1350 | AT12: =ROUND(IF(AL12<22792,AL12*1.5%,22792*1.5%),2) -> 289.35 | AU12: =SUM(AN12:AT12) -> 6596.88 | AV12: 279 | AW12: =AU12+Z12+AI12-AJ12+AV12 -> 21450.96 | AX12: -10.8 | AY12: 工伤利率调整，1月多收2月退 | AZ12: 255 | BA12: =ROUND(AW12+AZ12+AX12,2) -> 21695.16 | BB12: =ROUND(BA12*6%,2) -> 1301.71 | BC12: =ROUND(SUM(BA12:BB12),2) -> 22996.87 | BD12: =AV12-5 -> 274
A13: =ROW()-2 -> 11 | B13: 2502 | C13: WB002502 | D13: 万珺 | E13: 310104199005144025 | F13: 45444 | G13: 45808 | I13: 上海 | J13: 1030 | K13: 2612 | L13: 1223.35 | O13: 1113.1 | R13: 630 | Y13: -612.8 | Z13: =SUM(J13:Y13) -> 5995.65 | AA13: 7384 | AB13: 590.72 | AC13: 147.68 | AD13: 36.92 | AE13: 6424 | AF13: 450 | AG13: =AB13+AC13+AD13+AF13 -> 1225.32 | AK13: =Z13-AG13-AH13 -> 4770.33 | AL13: 7384 | AM13: 6424 | AN13: =ROUND(AL13*16%,2) -> 1181.44 | AO13: =ROUND(AL13*9%,2) -> 664.56 | AP13: =ROUND(AL13*0.5%,2) -> 36.92 | AQ13: 14.77 | AS13: =ROUND(AM13*7%,0) -> 450 | AT13: =ROUND(IF(AL13<22792,AL13*1.5%,22792*1.5%),2) -> 110.76 | AU13: =SUM(AN13:AT13) -> 2458.45 | AV13: 107 | AW13: =AU13+Z13+AI13-AJ13+AV13 -> 8561.1 | AX13: -4.13 | AY13: 工伤利率调整，1月多收2月退 | AZ13: 255 | BA13: =ROUND(AW13+AZ13+AX13,2) -> 8811.97 | BB13: =ROUND(BA13*6%,2) -> 528.72 | BC13: =ROUND(SUM(BA13:BB13),2) -> 9340.69 | BD13: =AV13-5 -> 102
A14: =ROW()-2 -> 12 | B14: 2502 | C14: WB025262 | D14: 王俊 | E14: 310107197803012414 | F14: 45444 | G14: 45808 | I14: 上海 | J14: 1030 | K14: 5802.9 | L14: 448 | O14: 989.43 | R14: 630 | Y14: 0 | Z14: =SUM(J14:Y14) -> 8900.33 | AA14: 7384 | AB14: 590.72 | AC14: 147.68 | AD14: 36.92 | AE14: 5565 | AF14: 390 | AG14: =AB14+AC14+AD14+AF14 -> 1165.32 | AK14: =Z14-AG14-AH14 -> 7735.01 | AL14: 7384 | AM14: 5565 | AN14: =ROUND(AL14*16%,2) -> 1181.44 | AO14: =ROUND(AL14*9%,2) -> 664.56 | AP14: =ROUND(AL14*0.5%,2) -> 36.92 | AQ14: 14.77 | AS14: =ROUND(AM14*7%,0) -> 390 | AT14: =ROUND(IF(AL14<22792,AL14*1.5%,22792*1.5%),2) -> 110.76 | AU14: =SUM(AN14:AT14) -> 2398.45 | AV14: 165 | AW14: =AU14+Z14+AI14-AJ14+AV14 -> 11463.78 | AX14: -4.13 | AY14: 工伤利率调整，1月多收2月退 | AZ14: 255 | BA14: =ROUND(AW14+AZ14+AX14,2) -> 11714.65 | BB14: =ROUND(BA14*6%,2) -> 702.88 | BC14: =ROUND(SUM(BA14:BB14),2) -> 12417.53 | BD14: =AV14-5 -> 160
A15: =ROW()-2 -> 13 | B15: 2502 | C15: WB002503 | D15: 诸振 | E15: 310104198909022851 | F15: 45444 | G15: 45808 | I15: 上海 | J15: 1030 | K15: 2745 | L15: 1611.74 | O15: 371.03 | R15: 630 | Y15: -54.04 | Z15: =SUM(J15:Y15) -> 6333.73 | AA15: 7384 | AB15: 590.72 | AC15: 147.68 | AD15: 36.92 | AE15: 6727 | AF15: 471 | AG15: =AB15+AC15+AD15+AF15 -> 1246.32 | AK15: =Z15-AG15-AH15 -> 5087.41 | AL15: 7384 | AM15: 6727 | AN15: =ROUND(AL15*16%,2) -> 1181.44 | AO15: =ROUND(AL15*9%,2) -> 664.56 | AP15: =ROUND(AL15*0.5%,2) -> 36.92 | AQ15: 14.77 | AS15: =ROUND(AM15*7%,0) -> 471 | AT15: =ROUND(IF(AL15<22792,AL15*1.5%,22792*1.5%),2) -> 110.76 | AU15: =SUM(AN15:AT15) -> 2479.45 | AV15: 114 | AW15: =AU15+Z15+AI15-AJ15+AV15 -> 8927.18 | AX15: -4.13 | AY15: 工伤利率调整，1月多收2月退 | AZ15: 255 | BA15: =ROUND(AW15+AZ15+AX15,2) -> 9178.05 | BB15: =ROUND(BA15*6%,2) -> 550.68 | BC15: =ROUND(SUM(BA15:BB15),2) -> 9728.73 | BD15: =AV15-5 -> 109
A16: =ROW()-2 -> 14 | B16: 2502 | C16: WB053339 | D16: 李斌 | E16: 310107197703162810 | F16: 45444 | G16: 45808 | I16: 上海 | J16: 900 | K16: 2228 | L16: 291.65 | O16: 989.43 | R16: 630 | X16: 486.67 | Y16: 0 | Z16: =SUM(J16:Y16) -> 5525.75 | AA16: 7384 | AB16: 590.72 | AC16: 147.68 | AD16: 36.92 | AE16: 6228 | AF16: 436 | AG16: =AB16+AC16+AD16+AF16 -> 1211.32 | AK16: =Z16-AG16-AH16 -> 4314.43 | AL16: 7384 | AM16: 6228 | AN16: =ROUND(AL16*16%,2) -> 1181.44 | AO16: =ROUND(AL16*9%,2) -> 664.56 | AP16: =ROUND(AL16*0.5%,2) -> 36.92 | AQ16: 14.77 | AS16: =ROUND(AM16*7%,0) -> 436 | AT16: =ROUND(IF(AL16<22792,AL16*1.5%,22792*1.5%),2) -> 110.76 | AU16: =SUM(AN16:AT16) -> 2444.45 | AV16: 98 | AW16: =AU16+Z16+AI16-AJ16+AV16 -> 8068.2 | AX16: -4.13 | AY16: 工伤利率调整，1月多收2月退 | AZ16: 255 | BA16: =ROUND(AW16+AZ16+AX16,2) -> 8319.07 | BB16: =ROUND(BA16*6%,2) -> 499.14 | BC16: =ROUND(SUM(BA16:BB16),2) -> 8818.21 | BD16: =AV16-5 -> 93
A17: =ROW()-2 -> 15 | B17: 2502 | C17: WB053251 | D17: 李亮 | E17: 341222198207144154 | F17: 45444 | G17: 45808 | I17: 上海 | J17: 900 | K17: 3699 | L17: 550.4 | O17: 989.43 | R17: 630 | X17: 362.37 | Y17: 0 | Z17: =SUM(J17:Y17) -> 7131.2 | AA17: 16093 | AB17: 1287.44 | AC17: 321.86 | AD17: 80.47 | AE17: 16093 | AF17: 1127 | AG17: =AB17+AC17+AD17+AF17 -> 2816.77 | AK17: =Z17-AG17-AH17 -> 4314.43 | AL17: 16093 | AM17: 16093 | AN17: =ROUND(AL17*16%,2) -> 2574.88 | AO17: 1448.38 | AP17: =ROUND(AL17*0.5%,2) -> 80.47 | AQ17: 32.19 | AS17: =ROUND(AM17*7%,0) -> 1127 | AT17: =ROUND(IF(AL17<22792,AL17*1.5%,22792*1.5%),2) -> 241.4 | AU17: =SUM(AN17:AT17) -> 5504.32 | AV17: 130 | AW17: =AU17+Z17+AI17-AJ17+AV17 -> 12765.52 | AX17: -9.01 | AY17: 工伤利率调整，1月多收2月退 | AZ17: 255 | BA17: =ROUND(AW17+AZ17+AX17,2) -> 13011.51 | BB17: =ROUND(BA17*6%,2) -> 780.69 | BC17: =ROUND(SUM(BA17:BB17),2) -> 13792.2 | BD17: =AV17-5 -> 125
A18: =ROW()-2 -> 16 | B18: 2502 | C18: WB029437 | D18: 王永其 | E18: 310114199401273219 | F18: 45444 | G18: 45808 | I18: 上海 | J18: 1030 | K18: 2368 | L18: 923.2 | O18: 0 | R18: 630 | Y18: -259 | Z18: =SUM(J18:Y18) -> 4692.2 | AA18: 7384 | AB18: 590.72 | AC18: 147.68 | AD18: 36.92 | AE18: 6661 | AF18: 466 | AG18: =AB18+AC18+AD18+AF18 -> 1241.32 | AK18: =Z18-AG18-AH18 -> 3450.88 | AL18: 7384 | AM18: 6661 | AN18: =ROUND(AL18*16%,2) -> 1181.44 | AO18: =ROUND(AL18*9%,2) -> 664.56 | AP18: =ROUND(AL18*0.5%,2) -> 36.92 | AQ18: 14.77 | AS18: =ROUND(AM18*7%,0) -> 466 | AT18: =ROUND(IF(AL18<22792,AL18*1.5%,22792*1.5%),2) -> 110.76 | AU18: =SUM(AN18:AT18) -> 2474.45 | AV18: 81 | AW18: =AU18+Z18+AI18-AJ18+AV18 -> 7247.65 | AX18: -4.13 | AY18: 工伤利率调整，1月多收2月退 | AZ18: 255 | BA18: =ROUND(AW18+AZ18+AX18,2) -> 7498.52 | BB18: =ROUND(BA18*6%,2) -> 449.91 | BC18: =ROUND(SUM(BA18:BB18),2) -> 7948.43 | BD18: =AV18-5 -> 76
A19: =ROW()-2 -> 17 | B19: 2502 | C19: WB002497 | D19: 张弘开 | E19: 310102199503181635 | F19: 45444 | G19: 45808 | I19: 上海 | J19: 950 | K19: 3182 | L19: 1912.74 | O19: 0 | R19: 630 | Y19: -280 | Z19: =SUM(J19:Y19) -> 6394.74 | AA19: 7384 | AB19: 590.72 | AC19: 147.68 | AD19: 36.92 | AE19: 6654 | AF19: 466 | AG19: =AB19+AC19+AD19+AF19 -> 1241.32 | AK19: =Z19-AG19-AH19 -> 5153.42 | AL19: 7384 | AM19: 6654 | AN19: =ROUND(AL19*16%,2) -> 1181.44 | AO19: =ROUND(AL19*9%,2) -> 664.56 | AP19: =ROUND(AL19*0.5%,2) -> 36.92 | AQ19: 14.77 | AS19: =ROUND(AM19*7%,0) -> 466 | AT19: =ROUND(IF(AL19<22792,AL19*1.5%,22792*1.5%),2) -> 110.76 | AU19: =SUM(AN19:AT19) -> 2474.45 | AV19: 115 | AW19: =AU19+Z19+AI19-AJ19+AV19 -> 8984.19 | AX19: -4.13 | AY19: 工伤利率调整，1月多收2月退 | AZ19: 255 | BA19: =ROUND(AW19+AZ19+AX19,2) -> 9235.06 | BB19: =ROUND(BA19*6%,2) -> 554.1 | BC19: =ROUND(SUM(BA19:BB19),2) -> 9789.16 | BD19: =AV19-5 -> 110
A20: =ROW()-2 -> 18 | B20: 2502 | C20: WB002499 | D20: 周浩帆 | E20: 440582198302042610 | F20: 45444 | G20: 45808 | I20: 上海 | J20: 1200 | K20: 5810 | L20: 1661.5 | O20: 0 | R20: 630 | Y20: -878 | Z20: =SUM(J20:Y20) -> 8423.5 | AA20: 7923 | AB20: 633.84 | AC20: 158.46 | AD20: 39.62 | AE20: 7923 | AF20: 555 | AG20: =AB20+AC20+AD20+AF20 -> 1386.92 | AK20: =Z20-AG20-AH20 -> 7036.58 | AL20: 7923 | AM20: 7923 | AN20: =ROUND(AL20*16%,2) -> 1267.68 | AO20: 713.08 | AP20: =ROUND(AL20*0.5%,2) -> 39.62 | AQ20: 15.85 | AS20: =ROUND(AM20*7%,0) -> 555 | AT20: =ROUND(IF(AL20<22792,AL20*1.5%,22792*1.5%),2) -> 118.85 | AU20: =SUM(AN20:AT20) -> 2710.08 | AV20: 156 | AW20: =AU20+Z20+AI20-AJ20+AV20 -> 11289.58 | AX20: -4.43 | AY20: 工伤利率调整，1月多收2月退 | AZ20: 255 | BA20: =ROUND(AW20+AZ20+AX20,2) -> 11540.15 | BB20: =ROUND(BA20*6%,2) -> 692.41 | BC20: =ROUND(SUM(BA20:BB20),2) -> 12232.56 | BD20: =AV20-5 -> 151
A21: =ROW()-2 -> 19 | B21: 2502 | C21: WB044167 | D21: 高妮彬 | E21: 310107197911290905 | F21: 45444 | G21: 45808 | I21: 上海 | J21: 1030 | K21: 3932.2 | L21: 1777.64 | O21: 0 | R21: 630 | Y21: -616.4 | Z21: =SUM(J21:Y21) -> 6753.44 | AA21: 7670 | AB21: 613.6 | AC21: 153.4 | AD21: 38.35 | AE21: 7670 | AF21: 537 | AG21: =AB21+AC21+AD21+AF21 -> 1342.35 | AK21: =Z21-AG21-AH21 -> 5411.09 | AL21: 7670 | AM21: 7670 | AN21: =ROUND(AL21*16%,2) -> 1227.2 | AO21: =ROUND(AL21*9%,2) -> 690.3 | AP21: =ROUND(AL21*0.5%,2) -> 38.35 | AQ21: 15.34 | AS21: =ROUND(AM21*7%,0) -> 537 | AT21: =ROUND(IF(AL21<22792,AL21*1.5%,22792*1.5%),2) -> 115.05 | AU21: =SUM(AN21:AT21) -> 2623.24 | AV21: 122 | AW21: =AU21+Z21+AI21-AJ21+AV21 -> 9498.68 | AX21: -4.3 | AY21: 工伤利率调整，1月多收2月退 | AZ21: 255 | BA21: =ROUND(AW21+AZ21+AX21,2) -> 9749.38 | BB21: =ROUND(BA21*6%,2) -> 584.96 | BC21: =ROUND(SUM(BA21:BB21),2) -> 10334.34 | BD21: =AV21-5 -> 117
A22: =ROW()-2 -> 20 | B22: 2502 | C22: WB013277 | D22: 顾恺凯 | E22: 310105198204080011 | F22: 45444 | G22: 45808 | I22: 上海 | J22: 1300 | K22: 7087 | L22: 609.4 | O22: 0 | R22: 630 | Y22: -280.5 | Z22: =SUM(J22:Y22) -> 9345.9 | AA22: 9323 | AB22: 745.84 | AC22: 186.46 | AD22: 46.62 | AE22: 9323 | AF22: 653 | AG22: =AB22+AC22+AD22+AF22 -> 1631.92 | AK22: =Z22-AG22-AH22 -> 7713.98 | AL22: 9323 | AM22: 9323 | AN22: =ROUND(AL22*16%,2) -> 1491.68 | AO22: 839.08 | AP22: =ROUND(AL22*0.5%,2) -> 46.62 | AQ22: 18.65 | AS22: =ROUND(AM22*7%,0) -> 653 | AT22: =ROUND(IF(AL22<22792,AL22*1.5%,22792*1.5%),2) -> 139.85 | AU22: =SUM(AN22:AT22) -> 3188.88 | AV22: 174 | AW22: =AU22+Z22+AI22-AJ22+AV22 -> 12708.78 | AX22: -5.22 | AY22: 工伤利率调整，1月多收2月退 | AZ22: 255 | BA22: =ROUND(AW22+AZ22+AX22,2) -> 12958.56 | BB22: =ROUND(BA22*6%,2) -> 777.51 | BC22: =ROUND(SUM(BA22:BB22),2) -> 13736.07 | BD22: =AV22-5 -> 169
A23: =ROW()-2 -> 21 | B23: 2502 | C23: WB025394 | D23: 许晓春 | E23: 310104198302137214 | F23: 45444 | G23: 45808 | I23: 上海 | J23: 1000 | K23: 2087.6 | L23: 1062.9 | O23: 0 | R23: 630 | X23: 243.92 | Y23: -430.1 | Z23: =SUM(J23:Y23) -> 4594.32 | AA23: 7384 | AB23: 590.72 | AC23: 147.68 | AD23: 36.92 | AE23: 7055 | AF23: 494 | AG23: =AB23+AC23+AD23+AF23 -> 1269.32 | AK23: =Z23-AG23-AH23 -> 3325 | AL23: 7384 | AM23: 7055 | AN23: =ROUND(AL23*16%,2) -> 1181.44 | AO23: =ROUND(AL23*9%,2) -> 664.56 | AP23: =ROUND(AL23*0.5%,2) -> 36.92 | AQ23: 14.77 | AS23: =ROUND(AM23*7%,0) -> 494 | AT23: =ROUND(IF(AL23<22792,AL23*1.5%,22792*1.5%),2) -> 110.76 | AU23: =SUM(AN23:AT23) -> 2502.45 | AV23: 79 | AW23: =AU23+Z23+AI23-AJ23+AV23 -> 7175.77 | AX23: -4.13 | AY23: 工伤利率调整，1月多收2月退 | AZ23: 255 | BA23: =ROUND(AW23+AZ23+AX23,2) -> 7426.64 | BB23: =ROUND(BA23*6%,2) -> 445.6 | BC23: =ROUND(SUM(BA23:BB23),2) -> 7872.24 | BD23: =AV23-5 -> 74
A24: =ROW()-2 -> 22 | B24: 2502 | C24: WB013289 | D24: 张英 | E24: 310226197901044123 | F24: 45444 | G24: 45808 | I24: 上海 | J24: 1300 | K24: 3299.2 | L24: 1330.6 | O24: 0 | R24: 630 | Y24: -542 | Z24: =SUM(J24:Y24) -> 6017.8 | AA24: 14011 | AB24: 1120.88 | AC24: 280.22 | AD24: 70.06 | AE24: 14011 | AF24: 981 | AG24: =AB24+AC24+AD24+AF24 -> 2452.16 | AK24: =Z24-AG24-AH24 -> 3565.64 | AL24: 14011 | AM24: 14011 | AN24: =ROUND(AL24*16%,2) -> 2241.76 | AO24: 1261 | AP24: =ROUND(AL24*0.5%,2) -> 70.06 | AQ24: 28.02 | AS24: =ROUND(AM24*7%,0) -> 981 | AT24: =ROUND(IF(AL24<22792,AL24*1.5%,22792*1.5%),2) -> 210.17 | AU24: =SUM(AN24:AT24) -> 4792.01 | AV24: 108 | AW24: =AU24+Z24+AI24-AJ24+AV24 -> 10917.81 | AX24: -7.85 | AY24: 工伤利率调整，1月多收2月退 | AZ24: 255 | BA24: =ROUND(AW24+AZ24+AX24,2) -> 11164.96 | BB24: =ROUND(BA24*6%,2) -> 669.9 | BC24: =ROUND(SUM(BA24:BB24),2) -> 11834.86 | BD24: =AV24-5 -> 103
A25: =ROW()-2 -> 23 | B25: 2502 | C25: WB040885 | D25: 黄良剑 | E25: 362321198304151616 | F25: 45444 | G25: 45808 | I25: 上海 | J25: 800 | K25: 1930 | L25: 439.2 | O25: 0 | R25: 630 | X25: 1028.02 | Y25: 0 | Z25: =SUM(J25:Y25) -> 4827.22 | AA25: 8583 | AB25: 686.64 | AC25: 171.66 | AD25: 42.92 | AE25: 8583 | AF25: 601 | AG25: =AB25+AC25+AD25+AF25 -> 1502.22 | AK25: =Z25-AG25-AH25 -> 3325 | AL25: 8583 | AM25: 8583 | AN25: =ROUND(AL25*16%,2) -> 1373.28 | AO25: 772.48 | AP25: =ROUND(AL25*0.5%,2) -> 42.92 | AQ25: 17.17 | AS25: =ROUND(AM25*7%,0) -> 601 | AT25: =ROUND(IF(AL25<22792,AL25*1.5%,22792*1.5%),2) -> 128.75 | AU25: =SUM(AN25:AT25) -> 2935.6 | AV25: 84 | AW25: =AU25+Z25+AI25-AJ25+AV25 -> 7846.82 | AX25: -4.8 | AY25: 工伤利率调整，1月多收2月退 | AZ25: 255 | BA25: =ROUND(AW25+AZ25+AX25,2) -> 8097.02 | BB25: =ROUND(BA25*6%,2) -> 485.82 | BC25: =ROUND(SUM(BA25:BB25),2) -> 8582.84 | BD25: =AV25-5 -> 79
A26: =ROW()-2 -> 24 | B26: 2502 | C26: WB063833 | D26: 张渊然 | E26: 310102197903070054 | F26: 45444 | G26: 45808 | I26: 上海 | J26: 900 | K26: 3382.95 | L26: 492.75 | O26: 989.43 | R26: 630 | Y26: 0 | Z26: =SUM(J26:Y26) -> 6395.13 | AA26: 7384 | AB26: 590.72 | AC26: 147.68 | AD26: 36.92 | AE26: 2690 | AF26: 188 | AG26: =AB26+AC26+AD26+AF26 -> 963.32 | AK26: =Z26-AG26-AH26 -> 5431.81 | AL26: 7384 | AM26: 2690 | AN26: =ROUND(AL26*16%,2) -> 1181.44 | AO26: =ROUND(AL26*9%,2) -> 664.56 | AP26: =ROUND(AL26*0.5%,2) -> 36.92 | AQ26: 14.77 | AS26: =ROUND(AM26*7%,0) -> 188 | AT26: =ROUND(IF(AL26<22792,AL26*1.5%,22792*1.5%),2) -> 110.76 | AU26: =SUM(AN26:AT26) -> 2196.45 | AV26: 115 | AW26: =AU26+Z26+AI26-AJ26+AV26 -> 8706.58 | AX26: -4.13 | AY26: 工伤利率调整，1月多收2月退 | AZ26: 255 | BA26: =ROUND(AW26+AZ26+AX26,2) -> 8957.45 | BB26: =ROUND(BA26*6%,2) -> 537.45 | BC26: =ROUND(SUM(BA26:BB26),2) -> 9494.9 | BD26: =AV26-5 -> 110
A27: =ROW()-2 -> 25 | B27: 2502 | C27: WB050054 | D27: 郑克铭 | E27: 31010119770301561X | F27: 45474 | G27: 45900 | I27: 上海 | J27: 800 | K27: 4369 | L27: 615.9 | O27: 989.43 | R27: 630 | Y27: 0 | Z27: =SUM(J27:Y27) -> 7404.33 | AA27: 12197 | AB27: 975.76 | AC27: 243.94 | AD27: 60.99 | AE27: 12197 | AF27: 854 | AG27: =AB27+AC27+AD27+AF27 -> 2134.69 | AK27: =Z27-AG27-AH27 -> 5269.64 | AL27: 12197 | AM27: 12197 | AN27: =ROUND(AL27*16%,2) -> 1951.52 | AO27: 1097.74 | AP27: =ROUND(AL27*0.5%,2) -> 60.99 | AQ27: 24.39 | AS27: =ROUND(AM27*7%,0) -> 854 | AT27: =ROUND(IF(AL27<22792,AL27*1.5%,22792*1.5%),2) -> 182.96 | AU27: =SUM(AN27:AT27) -> 4171.6 | AV27: 135 | AW27: =AU27+Z27+AI27-AJ27+AV27 -> 11710.93 | AX27: -6.83 | AY27: 工伤利率调整，1月多收2月退 | AZ27: 255 | BA27: =ROUND(AW27+AZ27+AX27,2) -> 11959.1 | BB27: =ROUND(BA27*6%,2) -> 717.55 | BC27: =ROUND(SUM(BA27:BB27),2) -> 12676.65 | BD27: =AV27-5 -> 130
A29: 合计 | Z29: =SUBTOTAL(9,Z3:Z27) -> 207734.75 | AG29: =SUBTOTAL(9,AG3:AG27) -> 40464.26 | AK29: =SUBTOTAL(9,AK2:AK27) -> 167270.49 | AU29: =SUBTOTAL(9,AU3:AU27) -> 80007.2 | AV29: =SUM(AV3:AV27) -> 3850 | AW29: =SUBTOTAL(9,AW3:AW27) -> 291591.95 | AX29: =SUBTOTAL(9,AX3:AX27) -> -136.64 | AZ29: =SUBTOTAL(9,AZ3:AZ27) -> 6120 | BA29: =SUBTOTAL(9,BA3:BA27) -> 297575.31 | BB29: =SUBTOTAL(9,BB3:BB27) -> 17854.51 | BC29: =SUBTOTAL(9,BC3:BC27) -> 315429.82 | BD29: =SUBTOTAL(9,BD3:BD27) -> 3725

Sheet 对账单
A1: 科目 | B1: 手工账单 | C1: 速创账单 | D1: 155 | E1: 预收一次性 | F1: 1月工会费 | G1: 本月垫付，下月收 | H1: 本月多收，下月退 | I1: 合计 | J1: 差异
A2: 管理费 | B2: ='202502'!BB29 -> 17854.51 | C2: =系统!E41 -> 19801.4 | D2: =24*155 -> 3720 | I2: =SUM(C2:G2) -> 23521.4 | J2: =B2-C2 -> -1946.89
A3: 风险费 | B3: ='202502'!AZ29 -> 6120 | C3: 0 | I3: =SUM(C3:G3) -> 0 | J3: =B3-C3 -> 6120
A4: 个人四金 | B4: ='202502'!AG29 -> 40464.26 | C4: =系统!V41 -> 40464.26 | I4: =SUM(C4:G4) -> 40464.26 | J4: =B4-C4 -> 0
A5: 公司四金 | B5: ='202502'!AU29 -> 80007.2 | C5: =系统!O41 -> 80007.2 | I5: =SUM(C5:E5) -> 80007.2 | J5: =B5-C5 -> 0
A6: 工伤退费 | I6: =SUM(C6:G6) -> 0 | J6: =B6-C6 -> 0
A7: 代发工资 | B7: ='202502'!Z29-'202502'!AG29 -> 167270.49 | C7: =系统!W41 -> 167150.49 | D7: =5*24-0.09 -> 119.91 | I7: =SUM(C7:G7) -> 167270.4 | J7: =B7-C7 -> 120
A8: 上月垫付 | I8: =SUM(C8:G8) -> 0 | J8: =B8-C8 -> 0
A9: 工会费 | B9: ='202502'!AV29 -> 3850 | D9: =B10 -> -136.64 | F9: =B9 -> 3850 | I9: =SUM(C9:G9) -> 3713.36 | J9: =B9-C9 -> 3850
A10: 上月多收 | B10: ='202502'!AX29 -> -136.64 | I10: =SUM(C10:G10) -> 0 | J10: =B10-C10 -> -136.64
A11: 小计 | B11: =SUM(B2:B10) -> 315429.82 | C11: =SUM(C2:C10) -> 307423.35 | D11: =SUM(D2:D10) -> 3703.27 | E11: =E5 -> 0 | F11: =F9 -> 3850 | G11: =G9 -> 0 | H11: =H9 -> 0 | I11: =SUM(C11:G11) -> 314976.62
A12: 附加税
A13: 增值税 | D13: =ROUND((D11+D12)*6%,2) -> 222.2 | F13: =ROUND((F11+F12)*6%,2) -> 231 | G13: =ROUND((G11+G12)*6%,2) -> 0 | H13: =ROUND((H11+H12)*6%,2) -> 0 | I13: =SUM(C13:G13) -> 453.2
A14: 总计 | B14: =SUM(B11:B13) -> 315429.82 | C14: =SUM(C11:C13) -> 307423.35 | D14: =SUM(D11:D13) -> 3925.47 | E14: =E11 -> 0 | F14: =SUM(F11:F13) -> 4081 | G14: =SUM(G11:G13) -> 0 | H14: =SUM(H11:H13) -> 0 | I14: =SUM(C14:H14) -> 315429.82
A15: 给客户账单金额 | I15: =B14 -> 315429.82
A16: 差异 | I16: =I15-I14 -> 0
A17: 不含税差异 | I17: =ROUND(I16/1.06,2) -> 0

Sheet 系统
A1: 200070
A2: 寄：梅园路77号人才大厦
B3: 中国电信股份有限公司上海分公司 王慧珏 收
D6: 上海外服布列吉科技有限公司
C7: Shanghai Foreign Service Bridge Technology Co,Ltd.
E9: 收款通知书
E10: ADVISE ON COLLECTION
E11: 2025年02月
A13: 公司名称：中国电信股份有限公司上海分公司 | J13: 帐单号：202502CH6596103
A14: 序号 | B14: 姓名 | C14: 发生年月 | D14: 入职日期 | E14: 管理费 | F14: 当月社保基数 | G14: 当月公积金基数 | H14: 社保类 公司支付 Social Insurance Premiums Paid by Employer | N14: 公积金类 公司支付 Provident Fund Paid by Employer | O14: 公司合计 | P14: 社保类 个人支付 Social Insurance Premiums Paid by Employee | U14: 公积金类 个人支付 Provident Fund Paid by Employee | V14: 个人合计 | W14: 代办薪酬 | X14: 其他 | Y14: 总计 | Z14: 备注 | AA14: 外服工号 | AB14: 证件号码 | AC14: 应纳税金额 | AD14: 税率 | AE14: 增值税
A15: S/N | B15: Name | C15: YYYYMM | D15: Employment Start Date | E15: Adm Fee | F15: Social Insurance Base Amount of Current Month | G15: Provident Fund Base Amount of Current Month | H15: 养老保险 Endowment | I15: 医疗保险 Medical | J15: 失业保险 Unemploy-ment | K15: 工伤保险 Employment Injury | L15: 医疗生育保险 Medical Maternity | M15: 保障金 Disabled people&Back pay Fund | N15: 公积金 Provident Fund | O15: Subtotal of Employer Payment | P15: 养老保险 Endowment | Q15: 医疗保险 Medical | R15: 失业保险 Unemploy-ment | S15: 工伤保险 Employment Injury | T15: 医疗生育保险 Medical Maternity | U15: 公积金 Provident Fund | V15: Subtotal of Personal Payment | W15: Agency of Wage Payment | X15: Others | Y15: Total | Z15: Remarks | AA15: SFSC ID | AB15: ID Card | AC15: Taxable Amount | AD15: Tax Rate | AE15: VAT
A16: 1 | B16: 陈斌 | C16: 202502 | D16: 2024-06-01 | E16: 1878.16 | O16: =SUM(H16:N16) -> 0 | V16: =SUM(P16:U16) -> 0 | W16: 31302.6 | Y16: =SUM(E16,O16,V16:X16) -> 33180.76 | AA16: 5570941 | AB16: 310106198410231614 | AC16: 31302.6 | AD16: 6% | AE16: 1878.16
A17: 2 | B17: 陈敏 | C17: 202502 | D17: 2024-06-01 | E17: 595.81 | F17: 7384 | G17: 6812 | H17: 1181.44 | I17: 664.56 | J17: 36.92 | K17: 14.77 | M17: 110.76 | N17: 477 | O17: =SUM(H17:N17) -> 2485.45 | P17: 590.72 | Q17: 147.68 | R17: 36.92 | U17: 477 | V17: =SUM(P17:U17) -> 1252.32 | W17: 4425.59 | Y17: =SUM(E17,O17,V17:X17) -> 8759.17 | AA17: 5543037 | AB17: 330327198311300617 | AC17: 8263.35 | AD17: 6% | AE17: 495.82
A18: 3 | B18: 陈翔宇 | C18: 202502 | D18: 2024-04-01 | E18: 669.1 | F18: 7384 | G18: 5865 | H18: 1181.44 | I18: 664.56 | J18: 36.92 | K18: 14.77 | M18: 110.76 | N18: 411 | O18: =SUM(H18:N18) -> 2419.45 | P18: 590.72 | Q18: 147.68 | R18: 36.92 | U18: 411 | V18: =SUM(P18:U18) -> 1186.32 | W18: 5779.15 | Y18: =SUM(E18,O18,V18:X18) -> 10054.02 | AA18: 5687584 | AB18: 421024199409102039 | AC18: 9484.91 | AD18: 6% | AE18: 569.11
A19: 4 | B19: 高妮彬 | C19: 202502 | D19: 2024-06-01 | E19: 668.31 | F19: 7670 | G19: 7670 | H19: 1227.2 | I19: 690.3 | J19: 38.35 | K19: 15.34 | M19: 115.05 | N19: 537 | O19: =SUM(H19:N19) -> 2623.24 | P19: 613.6 | Q19: 153.4 | R19: 38.35 | U19: 537 | V19: =SUM(P19:U19) -> 1342.35 | W19: 5406.09 | Y19: =SUM(E19,O19,V19:X19) -> 10039.99 | AA19: 5545659 | AB19: 310107197911290905 | AC19: 9471.69 | AD19: 6% | AE19: 568.3
A20: 5 | B20: 顾杰 | C20: 202502 | D20: 2024-06-01 | E20: 1794.53 | F20: 18333 | G20: 18333 | H20: 2933.28 | I20: 1649.98 | J20: 91.67 | K20: 36.67 | M20: 275 | N20: 1283 | O20: =SUM(H20:N20) -> 6269.6 | P20: 1466.64 | Q20: 366.66 | R20: 91.67 | U20: 1283 | V20: =SUM(P20:U20) -> 3207.97 | W20: 18664.74 | Y20: =SUM(E20,O20,V20:X20) -> 29936.84 | AA20: 5570939 | AB20: 310225198410064814 | AC20: 28242.3 | AD20: 6% | AE20: 1694.54
A21: 6 | B21: 顾恺凯 | C21: 202502 | D21: 2024-06-01 | E21: 857.79 | F21: 9323 | G21: 9323 | H21: 1491.68 | I21: 839.08 | J21: 46.62 | K21: 18.65 | M21: 139.85 | N21: 653 | O21: =SUM(H21:N21) -> 3188.88 | P21: 745.84 | Q21: 186.46 | R21: 46.62 | U21: 653 | V21: =SUM(P21:U21) -> 1631.92 | W21: 7708.98 | Y21: =SUM(E21,O21,V21:X21) -> 13387.57 | AA21: 5545661 | AB21: 310105198204080011 | AC21: 12629.78 | AD21: 6% | AE21: 757.79
A22: 7 | B22: 胡颖琦 | C22: 202502 | D22: 2024-06-01 | E22: 588.11 | F22: 7384 | G22: 7234 | H22: 1181.44 | I22: 664.56 | J22: 36.92 | K22: 14.77 | M22: 110.76 | N22: 506 | O22: =SUM(H22:N22) -> 2514.45 | P22: 590.72 | Q22: 147.68 | R22: 36.92 | U22: 506 | V22: =SUM(P22:U22) -> 1281.32 | W22: 4239.28 | Y22: =SUM(E22,O22,V22:X22) -> 8623.16 | AA22: D05847 | AB22: 310101197211151615 | AC22: 8135.04 | AD22: 6% | AE22: 488.12
A23: 8 | B23: 黄良剑 | C23: 202502 | D23: 2024-06-01 | E23: 571.47 | F23: 8583 | G23: 8583 | H23: 1373.28 | I23: 772.48 | J23: 42.92 | K23: 17.17 | M23: 128.75 | N23: 601 | O23: =SUM(H23:N23) -> 2935.6 | P23: 686.64 | Q23: 171.66 | R23: 42.92 | U23: 601 | V23: =SUM(P23:U23) -> 1502.22 | W23: 3320 | Y23: =SUM(E23,O23,V23:X23) -> 8329.29 | AA23: 5780654 | AB23: 362321198304151616 | AC23: 7857.8 | AD23: 6% | AE23: 471.49
A24: 9 | B24: 黄晓菲 | C24: 202502 | D24: 2024-06-01 | E24: 1376.02 | F24: 19290 | G24: 19290 | H24: 3086.4 | I24: 1736.1 | J24: 96.45 | K24: 38.58 | M24: 289.35 | N24: 1350 | O24: =SUM(H24:N24) -> 6596.88 | P24: 1543.2 | Q24: 385.8 | R24: 96.45 | U24: 1350 | V24: =SUM(P24:U24) -> 3375.45 | W24: 11194.63 | Y24: =SUM(E24,O24,V24:X24) -> 22542.98 | AA24: 5543034 | AB24: 310114198604103821 | AC24: 21266.96 | AD24: 6% | AE24: 1276.02
A25: 10 | B25: 李斌 | C25: 202502 | D25: 2024-06-01 | E25: 583.92 | F25: 7384 | G25: 6228 | H25: 1181.44 | I25: 664.56 | J25: 36.92 | K25: 14.77 | M25: 110.76 | N25: 436 | O25: =SUM(H25:N25) -> 2444.45 | P25: 590.72 | Q25: 147.68 | R25: 36.92 | U25: 436 | V25: =SUM(P25:U25) -> 1211.32 | W25: 4309.43 | Y25: =SUM(E25,O25,V25:X25) -> 8549.12 | AA25: 5571016 | AB25: 310107197703162810 | AC25: 8065.19 | AD25: 6% | AE25: 483.93
A26: 11 | B26: 李亮 | C26: 202502 | D26: 2024-06-01 | E26: 863.84 | F26: 16093 | G26: 16093 | H26: 2574.88 | I26: 1448.38 | J26: 80.47 | K26: 32.19 | M26: 241.4 | N26: 1127 | O26: =SUM(H26:N26) -> 5504.32 | P26: 1287.44 | Q26: 321.86 | R26: 80.47 | U26: 1127 | V26: =SUM(P26:U26) -> 2816.77 | W26: 4309.43 | Y26: =SUM(E26,O26,V26:X26) -> 13494.36 | AA26: 5566064 | AB26: 341222198207144154 | AC26: 12730.53 | AD26: 6% | AE26: 763.83
A27: 12 | B27: 万珺 | C27: 202502 | D27: 2024-06-01 | E27: 612.95 | F27: 7384 | G27: 6424 | H27: 1181.44 | I27: 664.56 | J27: 36.92 | K27: 14.77 | M27: 110.76 | N27: 450 | O27: =SUM(H27:N27) -> 2458.45 | P27: 590.72 | Q27: 147.68 | R27: 36.92 | U27: 450 | V27: =SUM(P27:U27) -> 1225.32 | W27: 4765.33 | Y27: =SUM(E27,O27,V27:X27) -> 9062.05 | AA27: 5543035 | AB27: 310104199005144025 | AC27: 8549.09 | AD27: 6% | AE27: 512.96
A28: 13 | B28: 汪思思 | C28: 202502 | D28: 2024-06-01 | E28: 544.32 | F28: 7384 | G28: 6776 | H28: 1181.44 | I28: 664.56 | J28: 36.92 | K28: 14.77 | M28: 110.76 | N28: 474 | O28: =SUM(H28:N28) -> 2482.45 | P28: 590.72 | Q28: 147.68 | R28: 36.92 | U28: 474 | V28: =SUM(P28:U28) -> 1249.32 | W28: 3573.43 | Y28: =SUM(E28,O28,V28:X28) -> 7849.52 | AA28: 5578735 | AB28: 362334198307140025 | AC28: 7405.19 | AD28: 6% | AE28: 444.33
... A40: 25 | B40: 诸振 | C40: 202502 | D40: 2024-06-01 | E40: 634.49 | F40: 7384 | G40: 6727 | H40: 1181.44 | I40: 664.56 | J40: 36.92 | K40: 14.77 | M40: 110.76 | N40: 471 | O40: =SUM(H40:N40) -> 2479.45 | P40: 590.72 | Q40: 147.68 | R40: 36.92 | U40: 471 | V40: =SUM(P40:U40) -> 1246.32 | W40: 5082.41 | Y40: =SUM(E40,O40,V40:X40) -> 9442.67 | AA40: 5543036 | AB40: 310104198909022851 | AC40: 8908.17 | AD40: 6% | AE40: 534.5
A41: 合计（RMB） | E41: =SUM(E16:E40) -> 19801.4 | H41: =SUM(H16:H40) -> 37885.28 | I41: =SUM(I16:I40) -> 21310.56 | J41: =SUM(J16:J40) -> 1183.96 | K41: =SUM(K16:K40) -> 473.61 | L41: =SUM(L16:L40) -> 0 | M41: =SUM(M16:M40) -> 3551.79 | N41: =SUM(N16:N40) -> 15602 | O41: =SUM(O16:O40) -> 80007.2 | ... Y41: =SUM(Y16:Y40) -> 307423.35 | AC41: =SUM(AC16:AC40) -> 290021.84 | AE41: =SUM(AE16:AE40) -> 17401.51
A42: 总计（RMB）已包含历月补收人民币叁拾万柒仟肆佰贰拾叁圆叁角伍分 | Y42: 307423.35
A44: 其他费用
A45: 序号 | B45: 发生年月 | C45: 费用项目 | D45: 金额 | E45: 备注 | F45: 应纳税金额 | G45: 税率 | H45: 增值税
A46: S/N | B46: YYYYMM | C46: Item | D46: Amount | E46: Remarks | F46: Taxable Amount | G46: Tax Rate | H46: VAT
A47: 1 | B47: 202502 | C47: 税差调整6% | D47: 0 | F47: 0.19 | G47: 0.06 | H47: -0.19
A48: 合计（RMB） | D48: =SUM(D47:D47) -> 0 | F48: =SUM(F47:F47) -> 0.19 | H48: =SUM(H47:H47) -> -0.19
A49: 总计（RMB）人民币零 | D49: 0 | F49: 0.19 | H49: -0.19
A51: 增值税：
A52: 序号 S/N | B52: 应纳税额 | C52: 税率 | D52: 税金
A54: 1 | B54: 290022.03 | C54: 6% | D54: 17401.32
A55: 小计（RMB） | B55: 290022.03 | D55: 17401.32
A56: 总计(RMB) | D56: 17401.32
A57: 本次价税合计(RMB):人民币叁拾万柒仟肆佰贰拾叁圆叁角伍分
A58: 307423.35
...
