Workbook

Sheet 202502
A1: 序号 | B1: 计薪 周期 | C1: 工号 | D1: 姓名 | E1: 身份证号 | F1: 劳动合同起始日期 | G1: 劳动合同结束日期 | H1: 离职日期 | I1: 社保缴纳地 | J1: 星级费用 | K1: 考核费用 | L1: 量化费用 | M1: 专项费用 | AA1: 当月税前工资合计 | AB1: 社保基数(个人) | AC1: 养老保险(个人) | AD1: 医疗保险(个人) | AE1: 失业保险(个人) | AF1: 公积金基数(个人) | AG1: 住房公积金(个人) | AH1: 员工五险一金合计 | AI1: 本月个人所得税-系统导出 | AJ1: 税后增加 | AK1: 税后扣减 | AL1: 员工实发合计 | AM1: 社保基数 | AN1: 公积金基数 | AO1: 养老缴费 | AP1: 医疗缴费 | AQ1: 失业保险 | AR1: 工伤保险 | AS1: 生育保险 | AT1: 公积金 | AU1: 残保金 | AV1: 企业五险一金合计 | AW1: 工会费 | AX1: 代收付合计 | AY1: 本月月垫付下月收 | AZ1: 本月月多收下月退 | BA1: 社保备注 | BB1: 外包服务费 | BC1: 税前项合计 | BD1: 增值税 | BE1: 总计 | BF1: 工会费返回
A2: NO. | B2: Salary Cycle | C2: Employee No. | D2: Name | E2: ID No. | F2: Contract Starting Date | G2: Contract Expiry Date | H2: Exit Date | I2: Social Insurance City | J2: Contract Salary | K2: Assessment fees | L2: Quantifying costs | M2: 支局专项 | N2: 1+1激励 | O2: 交通费 | P2: 效能补贴 | Q2: 高温费及清凉饮料费 （6-9月） | R2: 伙食补贴 | S2: 独生子女奖励 | T2: 保险费 | U2: 其他费用 | V2: 补发费用 | W2: 劳防用品 | X2: 保障多收 | Z2: 其他扣款 | AA2: Pre-tax Total | AB2: Social Insurance Base | AC2: Pension Employee | AD2: Medical Employee | AE2: Umemployment Employee | AF2: Housing Fund Base | AG2: Housing Fund Employee | AH2: Total Amount of Social Insurance(EE) | AI2: Personal Income Tax | AJ2: Increase After-tax payment | AK2: Reduction After-tax payment | AL2: After-tax total Income | AM2: Social Insurance Base | AN2: Housing Fund Base | AO2: Pension Employer | AP2: Medical Employer | AQ2: Umemployment Employer | AR2: Injury Employer | AS2: Maternity Insurance Employer | AT2: Housing Fund Employer | AU2: Disabled people&Back pay Fund | AV2: Total Amount of Social Insurance(ER) | AW2: Union Fee | AX2: Payment Total | BA2: Social Security remark | BB2: Service Fee | BC2: Total | BD2: VAT | BE2: Subtotal
A3: =ROW()-2 -> 1 | B3: 2502 | C3: WB026139 | D3: 赵梅 | E3: 310227198801262829 | F3: 45413 | G3: 45777 | I3: 上海 | J3: 1200 | K3: 4368.8 | L3: 1370.8 | P3: 200 | R3: 630 | U3: 0 | Z3: 0 | AA3: =SUM(J3:Z3) -> 7769.6 | AB3: 7384 | AC3: 590.72 | AD3: 147.68 | AE3: 36.92 | AF3: 2690 | AG3: =ROUND(AF3*7%,0) -> 188 | AH3: =AC3+AD3+AE3+AG3 -> 963.32 | AL3: =AA3-AH3-AI3 -> 6806.28 | AM3: 7384 | AN3: 2690 | AO3: =ROUND(AM3*16%,2) -> 1181.44 | AP3: =ROUND(AM3*9%,2) -> 664.56 | AQ3: =ROUND(AM3*0.5%,2) -> 36.92 | AR3: 14.77 | AT3: =ROUND(AN3*7%,0) -> 188 | AU3: =ROUND(IF(AM3<24366,AM3*1.5%,24366*1.5%),2) -> 110.76 | AV3: =SUM(AO3:AU3) -> 2196.45 | AW3: 143 | AX3: =AV3+AA3+AJ3-AK3+AW3 -> 10109.05 | AZ3: -4.13 | BA3: 工伤利率调整，1月多收2月退 | BB3: 255 | BC3: =ROUND(AX3+BB3+AZ3+AY3,2) -> 10359.92 | BD3: =ROUND(BC3*6%,2) -> 621.6 | BE3: =ROUND(SUM(BC3:BD3),2) -> 10981.52 | BF3: =AW3-5 -> 138
A4: =ROW()-2 -> 2 | B4: 2502 | C4: WB032993 | D4: 施梅 | E4: 310227198805293665 | F4: 45413 | G4: 45777 | I4: 上海 | J4: 950 | K4: 1121.2 | L4: 394.48 | P4: 50 | R4: 630 | U4: 0 | X4: 1192.64 | Z4: 0 | AA4: =SUM(J4:Z4) -> 4338.32 | AB4: 7384 | AC4: 590.72 | AD4: 147.68 | AE4: 36.92 | AF4: 2690 | AG4: =ROUND(AF4*7%,0) -> 188 | AH4: =AC4+AD4+AE4+AG4 -> 963.32 | AL4: =AA4-AH4-AI4 -> 3375 | AM4: 7384 | AN4: 2690 | AO4: =ROUND(AM4*16%,2) -> 1181.44 | AP4: =ROUND(AM4*9%,2) -> 664.56 | AQ4: =ROUND(AM4*0.5%,2) -> 36.92 | AR4: 14.77 | AT4: =ROUND(AN4*7%,0) -> 188 | AU4: =ROUND(IF(AM4<24366,AM4*1.5%,24366*1.5%),2) -> 110.76 | AV4: =SUM(AO4:AU4) -> 2196.45 | AW4: 74 | AX4: =AV4+AA4+AJ4-AK4+AW4 -> 6608.77 | AY4: =5 -> 5 | AZ4: -4.13 | BA4: 本月低保补差5元，下月收，工伤利率调整，1月多收2月退 | BB4: 255 | BC4: =ROUND(AX4+BB4+AZ4+AY4,2) -> 6864.64 | BD4: =ROUND(BC4*6%,2) -> 411.88 | BE4: =ROUND(SUM(BC4:BD4),2) -> 7276.52 | BF4: =AW4-5 -> 69
A5: =ROW()-2 -> 3 | B5: 2502 | C5: WB045273 | D5: 赵燕敏 | E5: 310225198105111629 | F5: 45413 | G5: 45777 | I5: 上海 | J5: 1030 | K5: 751.6 | L5: 102.96 | P5: 50 | R5: 630 | U5: 0 | X5: 1773.76 | Z5: 0 | AA5: =SUM(J5:Z5) -> 4338.32 | AB5: 7384 | AC5: 590.72 | AD5: 147.68 | AE5: 36.92 | AF5: 2690 | AG5: =ROUND(AF5*7%,0) -> 188 | AH5: =AC5+AD5+AE5+AG5 -> 963.32 | AL5: =AA5-AH5-AI5 -> 3375 | AM5: 7384 | AN5: 2690 | AO5: =ROUND(AM5*16%,2) -> 1181.44 | AP5: =ROUND(AM5*9%,2) -> 664.56 | AQ5: =ROUND(AM5*0.5%,2) -> 36.92 | AR5: 14.77 | AT5: =ROUND(AN5*7%,0) -> 188 | AU5: =ROUND(IF(AM5<24366,AM5*1.5%,24366*1.5%),2) -> 110.76 | AV5: =SUM(AO5:AU5) -> 2196.45 | AW5: 74 | AX5: =AV5+AA5+AJ5-AK5+AW5 -> 6608.77 | AY5: =5 -> 5 | AZ5: -4.13 | BA5: 本月低保补差5元，下月收，工伤利率调整，1月多收2月退 | BB5: 255 | BC5: =ROUND(AX5+BB5+AZ5+AY5,2) -> 6864.64 | BD5: =ROUND(BC5*6%,2) -> 411.88 | BE5: =ROUND(SUM(BC5:BD5),2) -> 7276.52 | BF5: =AW5-5 -> 69
A6: =ROW()-2 -> 4 | B6: 2502 | C6: WB030755 | D6: 谭晓刚 | E6: 310227197503241611 | F6: 45413 | G6: 45777 | I6: 上海 | J6: 950 | K6: 2977.2 | L6: 843.04 | P6: 200 | R6: 630 | U6: 0 | Z6: 0 | AA6: =SUM(J6:Z6) -> 5600.24 | AB6: 7384 | AC6: 590.72 | AD6: 147.68 | AE6: 36.92 | AF6: 2690 | AG6: =ROUND(AF6*7%,0) -> 188 | AH6: =AC6+AD6+AE6+AG6 -> 963.32 | AL6: =AA6-AH6-AI6 -> 4636.92 | AM6: 7384 | AN6: 2690 | AO6: =ROUND(AM6*16%,2) -> 1181.44 | AP6: =ROUND(AM6*9%,2) -> 664.56 | AQ6: =ROUND(AM6*0.5%,2) -> 36.92 | AR6: 14.77 | AT6: =ROUND(AN6*7%,0) -> 188 | AU6: =ROUND(IF(AM6<24366,AM6*1.5%,24366*1.5%),2) -> 110.76 | AV6: =SUM(AO6:AU6) -> 2196.45 | AW6: 99 | AX6: =AV6+AA6+AJ6-AK6+AW6 -> 7895.69 | AZ6: -4.13 | BA6: 工伤利率调整，1月多收2月退 | BB6: 255 | BC6: =ROUND(AX6+BB6+AZ6+AY6,2) -> 8146.56 | BD6: =ROUND(BC6*6%,2) -> 488.79 | BE6: =ROUND(SUM(BC6:BD6),2) -> 8635.35 | BF6: =AW6-5 -> 94
A7: =ROW()-2 -> 5 | B7: 2502 | C7: WB046623 | D7: 陆丽伟 | E7: 310227198802293619 | F7: 45413 | G7: 45777 | I7: 上海 | J7: 950 | K7: 1081.8 | L7: 1105.68 | P7: 200 | R7: 630 | U7: 0 | X7: 720.84 | Z7: -200 | AA7: =SUM(J7:Z7) -> 4488.32 | AB7: 7384 | AC7: 590.72 | AD7: 147.68 | AE7: 36.92 | AF7: 2690 | AG7: =ROUND(AF7*7%,0) -> 188 | AH7: =AC7+AD7+AE7+AG7 -> 963.32 | AL7: =AA7-AH7-AI7 -> 3525 | AM7: 7384 | AN7: 2690 | AO7: =ROUND(AM7*16%,2) -> 1181.44 | AP7: =ROUND(AM7*9%,2) -> 664.56 | AQ7: =ROUND(AM7*0.5%,2) -> 36.92 | AR7: 14.77 | AT7: =ROUND(AN7*7%,0) -> 188 | AU7: =ROUND(IF(AM7<24366,AM7*1.5%,24366*1.5%),2) -> 110.76 | AV7: =SUM(AO7:AU7) -> 2196.45 | AW7: 77 | AX7: =AV7+AA7+AJ7-AK7+AW7 -> 6761.77 | AZ7: -4.13 | BA7: 工伤利率调整，1月多收2月退 | BB7: 255 | BC7: =ROUND(AX7+BB7+AZ7+AY7,2) -> 7012.64 | BD7: =ROUND(BC7*6%,2) -> 420.76 | BE7: =ROUND(SUM(BC7:BD7),2) -> 7433.4 | BF7: =AW7-5 -> 72
A8: =ROW()-2 -> 6 | B8: 2502 | C8: WB013255 | D8: 任清丽 | E8: 341223198806062763 | F8: 45444 | G8: 45808 | I8: 上海 | J8: 900 | K8: 6027.8 | L8: 3379.4 | P8: 200 | R8: 630 | U8: 649 | Z8: 0 | AA8: =SUM(J8:Z8) -> 11786.2 | AB8: 7384 | AC8: 590.72 | AD8: 147.68 | AE8: 36.92 | AF8: 6878 | AG8: =ROUND(AF8*7%,0) -> 481 | AH8: =AC8+AD8+AE8+AG8 -> 1256.32 | AL8: =AA8-AH8-AI8 -> 10529.88 | AM8: 7384 | AN8: 6878 | AO8: =ROUND(AM8*16%,2) -> 1181.44 | AP8: =ROUND(AM8*9%,2) -> 664.56 | AQ8: =ROUND(AM8*0.5%,2) -> 36.92 | AR8: 14.77 | AT8: =ROUND(AN8*7%,0) -> 481 | AU8: =ROUND(IF(AM8<24366,AM8*1.5%,24366*1.5%),2) -> 110.76 | AV8: =SUM(AO8:AU8) -> 2489.45 | AW8: 223 | AX8: =AV8+AA8+AJ8-AK8+AW8 -> 14498.65 | AZ8: -4.13 | BA8: 工伤利率调整，1月多收2月退 | BB8: 255 | BC8: =ROUND(AX8+BB8+AZ8+AY8,2) -> 14749.52 | BD8: =ROUND(BC8*6%,2) -> 884.97 | BE8: =ROUND(SUM(BC8:BD8),2) -> 15634.49 | BF8: =AW8-5 -> 218
A9: =ROW()-2 -> 7 | B9: 2502 | C9: WB022825 | D9: 张晓薇 | E9: 310229199011210247 | F9: 45444 | G9: 45808 | I9: 上海 | J9: 1200 | K9: 2952.04 | L9: 1006.6 | P9: 200 | R9: 630 | U9: 371 | Z9: 0 | AA9: =SUM(J9:Z9) -> 6359.64 | AB9: 8131 | AC9: 650.48 | AD9: 162.62 | AE9: 40.66 | AF9: 8131 | AG9: =ROUND(AF9*7%,0) -> 569 | AH9: =AC9+AD9+AE9+AG9 -> 1422.76 | AL9: =AA9-AH9-AI9 -> 4936.88 | AM9: 8131 | AN9: 8131 | AO9: =ROUND(AM9*16%,2) -> 1300.96 | AP9: 731.8 | AQ9: =ROUND(AM9*0.5%,2) -> 40.66 | AR9: 16.26 | AT9: =ROUND(AN9*7%,0) -> 569 | AU9: =ROUND(IF(AM9<24366,AM9*1.5%,24366*1.5%),2) -> 121.97 | AV9: =SUM(AO9:AU9) -> 2780.65 | AW9: 115 | AX9: =AV9+AA9+AJ9-AK9+AW9 -> 9255.29 | AZ9: -4.56 | BA9: 工伤利率调整，1月多收2月退 | BB9: 255 | BC9: =ROUND(AX9+BB9+AZ9+AY9,2) -> 9505.73 | BD9: =ROUND(BC9*6%,2) -> 570.34 | BE9: =ROUND(SUM(BC9:BD9),2) -> 10076.07 | BF9: =AW9-5 -> 110
A10: =ROW()-2 -> 8 | B10: 2502 | C10: WB023998 | D10: 戴连荣 | E10: 310227198411292010 | F10: 45444 | G10: 45808 | I10: 上海 | J10: 1300 | K10: 5296 | L10: 3349.7 | P10: 200 | R10: 630 | U10: 649 | Z10: 0 | AA10: =SUM(J10:Z10) -> 11424.7 | AB10: 12760 | AC10: 1020.8 | AD10: 255.2 | AE10: 63.8 | AF10: 12760 | AG10: =ROUND(AF10*7%,0) -> 893 | AH10: =AC10+AD10+AE10+AG10 -> 2232.8 | AL10: =AA10-AH10-AI10 -> 9191.9 | AM10: 12760 | AN10: 12760 | AO10: =ROUND(AM10*16%,2) -> 2041.6 | AP10: =ROUND(AM10*9%,2) -> 1148.4 | AQ10: =ROUND(AM10*0.5%,2) -> 63.8 | AR10: 25.52 | AT10: =ROUND(AN10*7%,0) -> 893 | AU10: =ROUND(IF(AM10<24366,AM10*1.5%,24366*1.5%),2) -> 191.4 | AV10: =SUM(AO10:AU10) -> 4363.72 | AW10: 216 | AX10: =AV10+AA10+AJ10-AK10+AW10 -> 16004.42 | AZ10: -7.15 | BA10: 工伤利率调整，1月多收2月退 | BB10: 255 | BC10: =ROUND(AX10+BB10+AZ10+AY10,2) -> 16252.27 | BD10: =ROUND(BC10*6%,2) -> 975.14 | BE10: =ROUND(SUM(BC10:BD10),2) -> 17227.41 | BF10: =AW10-5 -> 211
A11: =ROW()-2 -> 9 | B11: 2502 | C11: WB025814 | D11: 陶叶丽 | E11: 310227198510132629 | F11: 45444 | G11: 45808 | I11: 上海 | J11: 1030 | K11: 1094.6 | L11: 547.4 | P11: 200 | R11: 630 | U11: 0 | X11: 1125.32 | Z11: 0 | AA11: =SUM(J11:Z11) -> 4627.32 | AB11: 7384 | AC11: 590.72 | AD11: 147.68 | AE11: 36.92 | AF11: 4668 | AG11: =ROUND(AF11*7%,0) -> 327 | AH11: =AC11+AD11+AE11+AG11 -> 1102.32 | AL11: =AA11-AH11-AI11 -> 3525 | AM11: 7384 | AN11: 4668 | AO11: =ROUND(AM11*16%,2) -> 1181.44 | AP11: =ROUND(AM11*9%,2) -> 664.56 | AQ11: =ROUND(AM11*0.5%,2) -> 36.92 | AR11: 14.77 | AT11: =ROUND(AN11*7%,0) -> 327 | AU11: =ROUND(IF(AM11<24366,AM11*1.5%,24366*1.5%),2) -> 110.76 | AV11: =SUM(AO11:AU11) -> 2335.45 | AW11: 80 | AX11: =AV11+AA11+AJ11-AK11+AW11 -> 7042.77 | AZ11: -4.13 | BA11: 工伤利率调整，1月多收2月退 | BB11: 255 | BC11: =ROUND(AX11+BB11+AZ11+AY11,2) -> 7293.64 | BD11: =ROUND(BC11*6%,2) -> 437.62 | BE11: =ROUND(SUM(BC11:BD11),2) -> 7731.26 | BF11: =AW11-5 -> 75
A12: =ROW()-2 -> 10 | B12: 2502 | C12: WB047263 | D12: 李琴 | E12: 310227198708184424 | F12: 45689 | G12: 46053 | I12: 上海 | J12: 950 | K12: 1880 | L12: 530 | P12: 200 | R12: 630 | U12: 0 | X12: 495.32 | Z12: 0 | AA12: =SUM(J12:Z12) -> 4685.32 | AB12: 7384 | AC12: 590.72 | AD12: 147.68 | AE12: 36.92 | AF12: 5493 | AG12: 385 | AH12: =AC12+AD12+AE12+AG12 -> 1160.32 | AL12: =AA12-AH12-AI12 -> 3525 | AM12: 7384 | AN12: 5493 | AO12: 1181.44 | AP12: 664.56 | AQ12: 36.92 | AR12: 14.77 | AT12: 385 | AU12: 110.76 | AV12: =SUM(AO12:AU12) -> 2393.45 | AW12: 81 | AX12: =AV12+AA12+AJ12-AK12+AW12 -> 7159.77 | BB12: 255 | BC12: =ROUND(AX12+BB12+AZ12+AY12,2) -> 7414.77 | BD12: =ROUND(BC12*6%,2) -> 444.89 | BE12: =ROUND(SUM(BC12:BD12),2) -> 7859.66 | BF12: =AW12-5 -> 76
A13: =ROW()-2 -> 11 | B13: 2502 | C13: WB035661 | D13: 常宇航 | E13: 340321199609230533 | F13: 45444 | G13: 45808 | I13: 上海 | J13: 1030 | K13: 2993.8 | L13: 980.2 | P13: 200 | R13: 630 | U13: 0 | Z13: 0 | AA13: =SUM(J13:Z13) -> 5834 | AB13: 7384 | AC13: 590.72 | AD13: 147.68 | AE13: 36.92 | AF13: 6644 | AG13: =ROUND(AF13*7%,0) -> 465 | AH13: =AC13+AD13+AE13+AG13 -> 1240.32 | AL13: =AA13-AH13-AI13 -> 4593.68 | AM13: 7384 | AN13: 6644 | AO13: =ROUND(AM13*16%,2) -> 1181.44 | AP13: =ROUND(AM13*9%,2) -> 664.56 | AQ13: =ROUND(AM13*0.5%,2) -> 36.92 | AR13: 14.77 | AT13: =ROUND(AN13*7%,0) -> 465 | AU13: =ROUND(IF(AM13<24366,AM13*1.5%,24366*1.5%),2) -> 110.76 | AV13: =SUM(AO13:AU13) -> 2473.45 | AW13: 104 | AX13: =AV13+AA13+AJ13-AK13+AW13 -> 8411.45 | AZ13: -4.13 | BA13: 工伤利率调整，1月多收2月退 | BB13: 255 | BC13: =ROUND(AX13+BB13+AZ13+AY13,2) -> 8662.32 | BD13: =ROUND(BC13*6%,2) -> 519.74 | BE13: =ROUND(SUM(BC13:BD13),2) -> 9182.06 | BF13: =AW13-5 -> 99
A14: =ROW()-2 -> 12 | B14: 2502 | C14: WB038776 | D14: 陆晓岚 | E14: 310227199207211222 | F14: 45444 | G14: 45808 | I14: 上海 | J14: 950 | K14: 4296.6 | L14: 903.4 | P14: 250 | R14: 630 | U14: 0 | Z14: 0 | AA14: =SUM(J14:Z14) -> 7030 | AB14: 7384 | AC14: 590.72 | AD14: 147.68 | AE14: 36.92 | AF14: 5300 | AG14: =ROUND(AF14*7%,0) -> 371 | AH14: =AC14+AD14+AE14+AG14 -> 1146.32 | AL14: =AA14-AH14-AI14 -> 5883.68 | AM14: 7384 | AN14: 5300 | AO14: =ROUND(AM14*16%,2) -> 1181.44 | AP14: =ROUND(AM14*9%,2) -> 664.56 | AQ14: =ROUND(AM14*0.5%,2) -> 36.92 | AR14: 14.77 | AT14: =ROUND(AN14*7%,0) -> 371 | AU14: =ROUND(IF(AM14<24366,AM14*1.5%,24366*1.5%),2) -> 110.76 | AV14: =SUM(AO14:AU14) -> 2379.45 | AW14: 128 | AX14: =AV14+AA14+AJ14-AK14+AW14 -> 9537.45 | AZ14: -4.13 | BA14: 工伤利率调整，1月多收2月退 | BB14: 255 | BC14: =ROUND(AX14+BB14+AZ14+AY14,2) -> 9788.32 | BD14: =ROUND(BC14*6%,2) -> 587.3 | BE14: =ROUND(SUM(BC14:BD14),2) -> 10375.62 | BF14: =AW14-5 -> 123
A15: =ROW()-2 -> 13 | B15: 2502 | C15: WB044812 | D15: 曹克洋 | E15: 341226199712081318 | F15: 45444 | G15: 45808 | I15: 上海 | J15: 1200 | K15: 1718.2 | L15: 685 | P15: 200 | R15: 630 | U15: 0 | X15: 242.12 | Z15: 0 | AA15: =SUM(J15:Z15) -> 4675.32 | AB15: 7384 | AC15: 590.72 | AD15: 147.68 | AE15: 36.92 | AF15: 5351 | AG15: =ROUND(AF15*7%,0) -> 375 | AH15: =AC15+AD15+AE15+AG15 -> 1150.32 | AL15: =AA15-AH15-AI15 -> 3525 | AM15: 7384 | AN15: 5351 | AO15: =ROUND(AM15*16%,2) -> 1181.44 | AP15: =ROUND(AM15*9%,2) -> 664.56 | AQ15: =ROUND(AM15*0.5%,2) -> 36.92 | AR15: 14.77 | AT15: =ROUND(AN15*7%,0) -> 375 | AU15: =ROUND(IF(AM15<24366,AM15*1.5%,24366*1.5%),2) -> 110.76 | AV15: =SUM(AO15:AU15) -> 2383.45 | AW15: 81 | AX15: =AV15+AA15+AJ15-AK15+AW15 -> 7139.77 | AZ15: -4.13 | BA15: 工伤利率调整，1月多收2月退 | BB15: 255 | BC15: =ROUND(AX15+BB15+AZ15+AY15,2) -> 7390.64 | BD15: =ROUND(BC15*6%,2) -> 443.44 | BE15: =ROUND(SUM(BC15:BD15),2) -> 7834.08 | BF15: =AW15-5 -> 76
A16: =ROW()-2 -> 14 | B16: 2502 | C16: WB045176 | D16: 张春花 | E16: 32062619761225622X | F16: 45444 | G16: 45808 | I16: 上海 | J16: 1030 | K16: 3909 | L16: 1175.8 | P16: 200 | R16: 630 | U16: 0 | Z16: 0 | AA16: =SUM(J16:Z16) -> 6944.8 | AB16: 12769 | AC16: 1021.52 | AD16: 255.38 | AE16: 63.85 | AF16: 12769 | AG16: =ROUND(AF16*7%,0) -> 894 | AH16: =AC16+AD16+AE16+AG16 -> 2234.75 | AL16: =AA16-AH16-AI16 -> 4710.05 | AM16: 12769 | AN16: 12769 | AO16: =ROUND(AM16*16%,2) -> 2043.04 | AP16: 1149.22 | AQ16: =ROUND(AM16*0.5%,2) -> 63.85 | AR16: 25.54 | AT16: =ROUND(AN16*7%,0) -> 894 | AU16: =ROUND(IF(AM16<24366,AM16*1.5%,24366*1.5%),2) -> 191.54 | AV16: =SUM(AO16:AU16) -> 4367.19 | AW16: 126 | AX16: =AV16+AA16+AJ16-AK16+AW16 -> 11437.99 | AZ16: -7.15 | BA16: 工伤利率调整，1月多收2月退 | BB16: 255 | BC16: =ROUND(AX16+BB16+AZ16+AY16,2) -> 11685.84 | BD16: =ROUND(BC16*6%,2) -> 701.15 | BE16: =ROUND(SUM(BC16:BD16),2) -> 12386.99 | BF16: =AW16-5 -> 121
A17: =ROW()-2 -> 15 | B17: 2502 | C17: WB045370 | D17: 陆智俊 | E17: 310227199807124616 | F17: 45444 | G17: 45808 | I17: 上海 | J17: 1030 | K17: 2349.05 | L17: 1180.84 | P17: 200 | R17: 630 | U17: 0 | Z17: 0 | AA17: =SUM(J17:Z17) -> 5389.89 | AB17: 7556 | AC17: 604.48 | AD17: 151.12 | AE17: 37.78 | AF17: 7556 | AG17: =ROUND(AF17*7%,0) -> 529 | AH17: =AC17+AD17+AE17+AG17 -> 1322.38 | AL17: =AA17-AH17-AI17 -> 4067.51 | AM17: 7556 | AN17: 7556 | AO17: =ROUND(AM17*16%,2) -> 1208.96 | AP17: =ROUND(AM17*9%,2) -> 680.04 | AQ17: =ROUND(AM17*0.5%,2) -> 37.78 | AR17: 15.11 | AT17: =ROUND(AN17*7%,0) -> 529 | AU17: =ROUND(IF(AM17<24366,AM17*1.5%,24366*1.5%),2) -> 113.34 | AV17: =SUM(AO17:AU17) -> 2584.23 | AW17: 95 | AX17: =AV17+AA17+AJ17-AK17+AW17 -> 8069.12 | AZ17: -4.23 | BA17: 工伤利率调整，1月多收2月退 | BB17: 255 | BC17: =ROUND(AX17+BB17+AZ17+AY17,2) -> 8319.89 | BD17: =ROUND(BC17*6%,2) -> 499.19 | BE17: =ROUND(SUM(BC17:BD17),2) -> 8819.08 | BF17: =AW17-5 -> 90
A18: =ROW()-2 -> 16 | B18: 2502 | C18: WB045583 | D18: 王春燕 | E18: 310227198405021222 | F18: 45444 | G18: 45808 | I18: 上海 | J18: 1030 | K18: 1007.45 | L18: 542.8 | P18: 200 | R18: 630 | U18: 0 | X18: 1252.07 | Z18: 0 | AA18: =SUM(J18:Z18) -> 4662.32 | AB18: 7384 | AC18: 590.72 | AD18: 147.68 | AE18: 36.92 | AF18: 5176 | AG18: =ROUND(AF18*7%,0) -> 362 | AH18: =AC18+AD18+AE18+AG18 -> 1137.32 | AL18: =AA18-AH18-AI18 -> 3525 | AM18: 7384 | AN18: 5176 | AO18: =ROUND(AM18*16%,2) -> 1181.44 | AP18: =ROUND(AM18*9%,2) -> 664.56 | AQ18: =ROUND(AM18*0.5%,2) -> 36.92 | AR18: 14.77 | AT18: =ROUND(AN18*7%,0) -> 362 | AU18: =ROUND(IF(AM18<24366,AM18*1.5%,24366*1.5%),2) -> 110.76 | AV18: =SUM(AO18:AU18) -> 2370.45 | AW18: 81 | AX18: =AV18+AA18+AJ18-AK18+AW18 -> 7113.77 | AY18: =5 -> 5 | AZ18: -4.13 | BA18: 本月低保补差5元，下月收，工伤利率调整，1月多收2月退 | BB18: 255 | BC18: =ROUND(AX18+BB18+AZ18+AY18,2) -> 7369.64 | BD18: =ROUND(BC18*6%,2) -> 442.18 | BE18: =ROUND(SUM(BC18:BD18),2) -> 7811.82 | BF18: =AW18-5 -> 76
A19: =ROW()-2 -> 17 | B19: 2502 | C19: WB046624 | D19: 孔祥杰 | E19: 310110198408153236 | F19: 45444 | G19: 45808 | I19: 上海 | J19: 950 | K19: 1385.6 | L19: 668.78 | P19: 200 | R19: 630 | U19: 0 | X19: 968.94 | Z19: 0 | AA19: =SUM(J19:Z19) -> 4803.32 | AB19: 7384 | AC19: 590.72 | AD19: 147.68 | AE19: 36.92 | AF19: 7189 | AG19: =ROUND(AF19*7%,0) -> 503 | AH19: =AC19+AD19+AE19+AG19 -> 1278.32 | AL19: =AA19-AH19-AI19 -> 3525 | AM19: 7384 | AN19: 7189 | AO19: =ROUND(AM19*16%,2) -> 1181.44 | AP19: =ROUND(AM19*9%,2) -> 664.56 | AQ19: =ROUND(AM19*0.5%,2) -> 36.92 | AR19: 14.77 | AT19: =ROUND(AN19*7%,0) -> 503 | AU19: =ROUND(IF(AM19<24366,AM19*1.5%,24366*1.5%),2) -> 110.76 | AV19: =SUM(AO19:AU19) -> 2511.45 | AW19: 83 | AX19: =AV19+AA19+AJ19-AK19+AW19 -> 7397.77 | AZ19: -4.13 | BA19: 工伤利率调整，1月多收2月退 | BB19: 255 | BC19: =ROUND(AX19+BB19+AZ19+AY19,2) -> 7648.64 | BD19: =ROUND(BC19*6%,2) -> 458.92 | BE19: =ROUND(SUM(BC19:BD19),2) -> 8107.56 | BF19: =AW19-5 -> 78
A20: =ROW()-2 -> 18 | B20: 2502 | C20: WB047109 | D20: 谢桃丽 | E20: 530322199401231344 | F20: 45444 | G20: 45808 | I20: 上海 | J20: 1030 | K20: 2065.2 | L20: 1004.72 | P20: 200 | R20: 630 | U20: 0 | Z20: 0 | AA20: =SUM(J20:Z20) -> 4929.92 | AB20: 7384 | AC20: 590.72 | AD20: 147.68 | AE20: 36.92 | AF20: 5148 | AG20: =ROUND(AF20*7%,0) -> 360 | AH20: =AC20+AD20+AE20+AG20 -> 1135.32 | AL20: =AA20-AH20-AI20 -> 3794.6 | AM20: 7384 | AN20: 5148 | AO20: =ROUND(AM20*16%,2) -> 1181.44 | AP20: =ROUND(AM20*9%,2) -> 664.56 | AQ20: =ROUND(AM20*0.5%,2) -> 36.92 | AR20: 14.77 | AT20: =ROUND(AN20*7%,0) -> 360 | AU20: =ROUND(IF(AM20<24366,AM20*1.5%,24366*1.5%),2) -> 110.76 | AV20: =SUM(AO20:AU20) -> 2368.45 | AW20: 86 | AX20: =AV20+AA20+AJ20-AK20+AW20 -> 7384.37 | AZ20: -4.13 | BA20: 工伤利率调整，1月多收2月退 | BB20: 255 | BC20: =ROUND(AX20+BB20+AZ20+AY20,2) -> 7635.24 | BD20: =ROUND(BC20*6%,2) -> 458.11 | BE20: =ROUND(SUM(BC20:BD20),2) -> 8093.35 | BF20: =AW20-5 -> 81
A21: =ROW()-2 -> 19 | B21: 2502 | C21: WB049118 | D21: 顾诗瑶 | E21: 310227199812152021 | F21: 45444 | G21: 45808 | I21: 上海 | J21: 900 | K21: 0 | L21: 0 | P21: 200 | R21: 0 | U21: 0 | X21: 2352.32 | Z21: 0 | AA21: =SUM(J21:Z21) -> 3452.32 | AB21: 7384 | AC21: 590.72 | AD21: 147.68 | AE21: 36.92 | AF21: 4570 | AG21: =ROUND(AF21*7%,0) -> 320 | AH21: =AC21+AD21+AE21+AG21 -> 1095.32 | AL21: =AA21-AH21-AI21 -> 2357 | AM21: 7384 | AN21: 4570 | AO21: =ROUND(AM21*16%,2) -> 1181.44 | AP21: =ROUND(AM21*9%,2) -> 664.56 | AQ21: =ROUND(AM21*0.5%,2) -> 36.92 | AR21: 14.77 | AT21: =ROUND(AN21*7%,0) -> 320 | AU21: =ROUND(IF(AM21<24366,AM21*1.5%,24366*1.5%),2) -> 110.76 | AV21: =SUM(AO21:AU21) -> 2328.45 | AW21: 69 | AX21: =AV21+AA21+AJ21-AK21+AW21 -> 5849.77 | AY21: =5 -> 5 | AZ21: -4.13 | BA21: 本月低保补差5元，下月收，工伤利率调整，1月多收2月退 | BB21: 255 | BC21: =ROUND(AX21+BB21+AZ21+AY21,2) -> 6105.64 | BD21: =ROUND(BC21*6%,2) -> 366.34 | BE21: =ROUND(SUM(BC21:BD21),2) -> 6471.98 | BF21: =AW21-5 -> 64
A22: =ROW()-2 -> 20 | B22: 2502 | C22: WB049498 | D22: 曾灿 | E22: 362322200010120626 | F22: 45444 | G22: 45808 | I22: 上海 | J22: 900 | K22: 2397.32 | L22: 1203.44 | P22: 200 | R22: 630 | U22: 0 | Z22: 0 | AA22: =SUM(J22:Z22) -> 5330.76 | AB22: 8182 | AC22: 654.56 | AD22: 163.64 | AE22: 40.91 | AF22: 8182 | AG22: =ROUND(AF22*7%,0) -> 573 | AH22: =AC22+AD22+AE22+AG22 -> 1432.11 | AL22: =AA22-AH22-AI22 -> 3898.65 | AM22: 8182 | AN22: 8182 | AO22: =ROUND(AM22*16%,2) -> 1309.12 | AP22: =ROUND(AM22*9%,2) -> 736.38 | AQ22: =ROUND(AM22*0.5%,2) -> 40.91 | AR22: 16.36 | AT22: =ROUND(AN22*7%,0) -> 573 | AU22: =ROUND(IF(AM22<24366,AM22*1.5%,24366*1.5%),2) -> 122.73 | AV22: =SUM(AO22:AU22) -> 2798.5 | AW22: 94 | AX22: =AV22+AA22+AJ22-AK22+AW22 -> 8223.26 | AZ22: -4.59 | BA22: 1月工伤利率下调多收4.59，2月退 | BB22: 255 | BC22: =ROUND(AX22+BB22+AZ22+AY22,2) -> 8473.67 | BD22: =ROUND(BC22*6%,2) -> 508.42 | BE22: =ROUND(SUM(BC22:BD22),2) -> 8982.09 | BF22: =AW22-5 -> 89
A23: =ROW()-2 -> 21 | B23: 2502 | C23: WB027831 | D23: 倪跃新 | E23: 310229197208182017 | F23: 45444 | G23: 45808 | I23: 上海 | J23: 950 | K23: 3580 | L23: 1344.48 | P23: 200 | R23: 630 | U23: 371 | Z23: 0 | AA23: =SUM(J23:Z23) -> 7075.48 | AB23: 7384 | AC23: 590.72 | AD23: 147.68 | AE23: 36.92 | AF23: 6353 | AG23: =ROUND(AF23*7%,0) -> 445 | AH23: =AC23+AD23+AE23+AG23 -> 1220.32 | AL23: =AA23-AH23-AI23 -> 5855.16 | AM23: 7384 | AN23: 6353 | AO23: =ROUND(AM23*16%,2) -> 1181.44 | AP23: =ROUND(AM23*9%,2) -> 664.56 | AQ23: =ROUND(AM23*0.5%,2) -> 36.92 | AR23: 14.77 | AT23: =ROUND(AN23*7%,0) -> 445 | AU23: =ROUND(IF(AM23<24366,AM23*1.5%,24366*1.5%),2) -> 110.76 | AV23: =SUM(AO23:AU23) -> 2453.45 | AW23: 129 | AX23: =AV23+AA23+AJ23-AK23+AW23 -> 9657.93 | AZ23: -4.13 | BA23: 1月工伤利率下调多收4.13，2月退 | BB23: 255 | BC23: =ROUND(AX23+BB23+AZ23+AY23,2) -> 9908.8 | BD23: =ROUND(BC23*6%,2) -> 594.53 | BE23: =ROUND(SUM(BC23:BD23),2) -> 10503.33 | BF23: =AW23-5 -> 124
A24: =ROW()-2 -> 22 | B24: 2502 | C24: WB046625 | D24: 李秋梅 | E24: 320321198010030887 | F24: 45444 | G24: 45808 | I24: 上海 | J24: 1030 | K24: 3175.2 | L24: 959.36 | P24: 200 | R24: 630 | U24: 0 | Z24: -200 | AA24: =SUM(J24:Z24) -> 5794.56 | AB24: 7384 | AC24: 590.72 | AD24: 147.68 | AE24: 36.92 | AF24: 7034 | AG24: =ROUND(AF24*7%,0) -> 492 | AH24: =AC24+AD24+AE24+AG24 -> 1267.32 | AL24: =AA24-AH24-AI24 -> 4527.24 | AM24: 7384 | AN24: 7034 | AO24: =ROUND(AM24*16%,2) -> 1181.44 | AP24: =ROUND(AM24*9%,2) -> 664.56 | AQ24: =ROUND(AM24*0.5%,2) -> 36.92 | AR24: 14.77 | AT24: =ROUND(AN24*7%,0) -> 492 | AU24: =ROUND(IF(AM24<24366,AM24*1.5%,24366*1.5%),2) -> 110.76 | AV24: =SUM(AO24:AU24) -> 2500.45 | AW24: 103 | AX24: =AV24+AA24+AJ24-AK24+AW24 -> 8398.01 | AY24: =5 -> 5 | AZ24: -4.13 | BA24: 本月低保补差5元，下月收，工伤利率调整，1月多收2月退 | BB24: 255 | BC24: =ROUND(AX24+BB24+AZ24+AY24,2) -> 8653.88 | BD24: =ROUND(BC24*6%,2) -> 519.23 | BE24: =ROUND(SUM(BC24:BD24),2) -> 9173.11 | BF24: =AW24-5 -> 98
A25: =ROW()-2 -> 23 | B25: 2502 | C25: WB037444 | D25: 高国强 | E25: 65010319750517061X | F25: 45444 | G25: 45808 | I25: 上海 | J25: 950 | K25: 976 | L25: 257.68 | P25: 50 | R25: 630 | U25: 371 | X25: 1628.64 | Z25: 0 | AA25: =SUM(J25:Z25) -> 4863.32 | AB25: 7384 | AC25: 590.72 | AD25: 147.68 | AE25: 36.92 | AF25: 4880 | AG25: =ROUND(AF25*7%,0) -> 342 | AH25: =AC25+AD25+AE25+AG25 -> 1117.32 | AL25: =AA25-AH25-AI25 -> 3746 | AM25: 7384 | AN25: 4880 | AO25: =ROUND(AM25*16%,2) -> 1181.44 | AP25: =ROUND(AM25*9%,2) -> 664.56 | AQ25: =ROUND(AM25*0.5%,2) -> 36.92 | AR25: 14.77 | AT25: =ROUND(AN25*7%,0) -> 342 | AU25: =ROUND(IF(AM25<24366,AM25*1.5%,24366*1.5%),2) -> 110.76 | AV25: =SUM(AO25:AU25) -> 2350.45 | AW25: 85 | AX25: =AV25+AA25+AJ25-AK25+AW25 -> 7298.77 | AY25: =5 -> 5 | AZ25: -4.13 | BA25: 本月低保补差5元，下月收，工伤利率调整，1月多收2月退 | BB25: 255 | BC25: =ROUND(AX25+BB25+AZ25+AY25,2) -> 7554.64 | BD25: =ROUND(BC25*6%,2) -> 453.28 | BE25: =ROUND(SUM(BC25:BD25),2) -> 8007.92 | BF25: =AW25-5 -> 80
A26: =ROW()-2 -> 24 | B26: 2502 | C26: WB046626 | D26: 姜金玲 | E26: 310227198902274028 | F26: 45444 | G26: 45808 | I26: 上海 | J26: 950 | K26: 897.2 | L26: 845.12 | P26: 200 | R26: 630 | U26: 0 | X26: 1091 | Z26: 0 | AA26: =SUM(J26:Z26) -> 4613.32 | AB26: 7384 | AC26: 590.72 | AD26: 147.68 | AE26: 36.92 | AF26: 4467 | AG26: =ROUND(AF26*7%,0) -> 313 | AH26: =AC26+AD26+AE26+AG26 -> 1088.32 | AL26: =AA26-AH26-AI26 -> 3525 | AM26: 7384 | AN26: 4467 | AO26: =ROUND(AM26*16%,2) -> 1181.44 | AP26: =ROUND(AM26*9%,2) -> 664.56 | AQ26: =ROUND(AM26*0.5%,2) -> 36.92 | AR26: 14.77 | AT26: =ROUND(AN26*7%,0) -> 313 | AU26: =ROUND(IF(AM26<24366,AM26*1.5%,24366*1.5%),2) -> 110.76 | AV26: =SUM(AO26:AU26) -> 2321.45 | AW26: 80 | AX26: =AV26+AA26+AJ26-AK26+AW26 -> 7014.77 | AZ26: -4.13 | BA26: 工伤利率调整，1月多收2月退 | BB26: 255 | BC26: =ROUND(AX26+BB26+AZ26+AY26,2) -> 7265.64 | BD26: =ROUND(BC26*6%,2) -> 435.94 | BE26: =ROUND(SUM(BC26:BD26),2) -> 7701.58 | BF26: =AW26-5 -> 75
A27: =ROW()-2 -> 25 | B27: 2502 | C27: WB037461 | D27: 牟金丽 | E27: 422802198502180068 | F27: 45444 | G27: 45808 | I27: 上海 | J27: 950 | K27: 1569.26 | L27: 718.6 | P27: 200 | R27: 630 | U27: 0 | X27: 546.46 | Z27: 0 | AA27: =SUM(J27:Z27) -> 4614.32 | AB27: 7384 | AC27: 590.72 | AD27: 147.68 | AE27: 36.92 | AF27: 4492 | AG27: =ROUND(AF27*7%,0) -> 314 | AH27: =AC27+AD27+AE27+AG27 -> 1089.32 | AL27: =AA27-AH27-AI27 -> 3525 | AM27: 7384 | AN27: 4492 | AO27: =ROUND(AM27*16%,2) -> 1181.44 | AP27: =ROUND(AM27*9%,2) -> 664.56 | AQ27: =ROUND(AM27*0.5%,2) -> 36.92 | AR27: 14.77 | AT27: =ROUND(AN27*7%,0) -> 314 | AU27: =ROUND(IF(AM27<24366,AM27*1.5%,24366*1.5%),2) -> 110.76 | AV27: =SUM(AO27:AU27) -> 2322.45 | AW27: 80 | AX27: =AV27+AA27+AJ27-AK27+AW27 -> 7016.77 | AZ27: -4.13 | BA27: 工伤利率调整，1月多收2月退 | BB27: 255 | BC27: =ROUND(AX27+BB27+AZ27+AY27,2) -> 7267.64 | BD27: =ROUND(BC27*6%,2) -> 436.06 | BE27: =ROUND(SUM(BC27:BD27),2) -> 7703.7 | BF27: =AW27-5 -> 75
A28: =ROW()-2 -> 26 | B28: 2502 | C28: WB047234 | D28: 高峰 | E28: 342501197909046816 | F28: 45444 | G28: 45808 | I28: 上海 | J28: 1030 | K28: 11536 | L28: 1544.24 | P28: 200 | R28: 630 | U28: 1484 | Z28: -150 | AA28: =SUM(J28:Z28) -> 16274.24 | AB28: 13877 | AC28: 1110.16 | AD28: 277.54 | AE28: 69.39 | AF28: 13877 | AG28: =ROUND(AF28*7%,0) -> 971 | AH28: =AC28+AD28+AE28+AG28 -> 2428.09 | AL28: =AA28-AH28-AI28 -> 13846.15 | AM28: 13877 | AN28: 13877 | AO28: =ROUND(AM28*16%,2) -> 2220.32 | AP28: 1248.94 | AQ28: =ROUND(AM28*0.5%,2) -> 69.39 | AR28: 27.75 | AT28: =ROUND(AN28*7%,0) -> 971 | AU28: =ROUND(IF(AM28<24366,AM28*1.5%,24366*1.5%),2) -> 208.16 | AV28: =SUM(AO28:AU28) -> 4745.56 | AW28: 313 | AX28: =AV28+AA28+AJ28-AK28+AW28 -> 21332.8 | AZ28: -7.78 | BA28: 工伤利率调整，1月多收2月退 | BB28: 255 | BC28: =ROUND(AX28+BB28+AZ28+AY28,2) -> 21580.02 | BD28: =ROUND(BC28*6%,2) -> 1294.8 | BE28: =ROUND(SUM(BC28:BD28),2) -> 22874.82 | BF28: =AW28-5 -> 308
A29: =ROW()-2 -> 27 | B29: 2502 | C29: WB043358 | D29: 李龙燕 | E29: 320681199310316032 | F29: 45444 | G29: 45808 | I29: 上海 | J29: 950 | K29: 5176 | L29: 1572.56 | P29: 200 | R29: 630 | U29: 371 | Z29: 0 | AA29: =SUM(J29:Z29) -> 8899.56 | AB29: 8878 | AC29: 710.24 | AD29: 177.56 | AE29: 44.39 | AF29: 8878 | AG29: =ROUND(AF29*7%,0) -> 621 | AH29: =AC29+AD29+AE29+AG29 -> 1553.19 | AL29: =AA29-AH29-AI29 -> 7346.37 | AM29: 8878 | AN29: 8878 | AO29: =ROUND(AM29*16%,2) -> 1420.48 | AP29: =ROUND(AM29*9%,2) -> 799.02 | AQ29: =ROUND(AM29*0.5%,2) -> 44.39 | AR29: 17.76 | AT29: =ROUND(AN29*7%,0) -> 621 | AU29: =ROUND(IF(AM29<24366,AM29*1.5%,24366*1.5%),2) -> 133.17 | AV29: =SUM(AO29:AU29) -> 3035.82 | AW29: 165 | AX29: =AV29+AA29+AJ29-AK29+AW29 -> 12100.38 | AZ29: -4.97 | BA29: 工伤利率调整，1月多收2月退 | BB29: 255 | BC29: =ROUND(AX29+BB29+AZ29+AY29,2) -> 12350.41 | BD29: =ROUND(BC29*6%,2) -> 741.02 | BE29: =ROUND(SUM(BC29:BD29),2) -> 13091.43 | BF29: =AW29-5 -> 160
A30: =ROW()-2 -> 28 | B30: 2502 | C30: WB027701 | D30: 蒋萍萍 | E30: 310227199108114021 | F30: 45444 | G30: 45808 | I30: 上海 | J30: 950 | K30: 5220 | L30: 1065.44 | P30: 200 | R30: 630 | U30: 371 | Z30: -30 | AA30: =SUM(J30:Z30) -> 8406.44 | AB30: 8677 | AC30: 694.16 | AD30: 173.54 | AE30: 43.39 | AF30: 8677 | AG30: =ROUND(AF30*7%,0) -> 607 | AH30: =AC30+AD30+AE30+AG30 -> 1518.09 | AL30: =AA30-AH30-AI30 -> 6888.35 | AM30: 8677 | AN30: 8677 | AO30: =ROUND(AM30*16%,2) -> 1388.32 | AP30: 780.94 | AQ30: =ROUND(AM30*0.5%,2) -> 43.39 | AR30: 17.35 | AT30: =ROUND(AN30*7%,0) -> 607 | AU30: =ROUND(IF(AM30<24366,AM30*1.5%,24366*1.5%),2) -> 130.16 | AV30: =SUM(AO30:AU30) -> 2967.16 | AW30: 156 | AX30: =AV30+AA30+AJ30-AK30+AW30 -> 11529.6 | AZ30: -4.86 | BA30: 工伤利率调整，1月多收2月退 | BB30: 255 | BC30: =ROUND(AX30+BB30+AZ30+AY30,2) -> 11779.74 | BD30: =ROUND(BC30*6%,2) -> 706.78 | BE30: =ROUND(SUM(BC30:BD30),2) -> 12486.52 | BF30: =AW30-5 -> 151
A31: =ROW()-2 -> 29 | B31: 2502 | C31: WB041723 | D31: 封春燕 | E31: 310227198610224213 | F31: 45444 | G31: 45808 | I31: 上海 | J31: 950 | K31: 15222 | L31: 1700.48 | P31: 200 | R31: 630 | U31: 371 | Z31: 0 | AA31: =SUM(J31:Z31) -> 19073.48 | AB31: 7384 | AC31: 590.72 | AD31: 147.68 | AE31: 36.92 | AF31: 5109 | AG31: =ROUND(AF31*7%,0) -> 358 | AH31: =AC31+AD31+AE31+AG31 -> 1133.32 | AL31: =AA31-AH31-AI31 -> 17940.16 | AM31: 7384 | AN31: 5109 | AO31: =ROUND(AM31*16%,2) -> 1181.44 | AP31: =ROUND(AM31*9%,2) -> 664.56 | AQ31: =ROUND(AM31*0.5%,2) -> 36.92 | AR31: 14.77 | AT31: =ROUND(AN31*7%,0) -> 358 | AU31: =ROUND(IF(AM31<24366,AM31*1.5%,24366*1.5%),2) -> 110.76 | AV31: =SUM(AO31:AU31) -> 2366.45 | AW31: 369 | AX31: =AV31+AA31+AJ31-AK31+AW31 -> 21808.93 | AZ31: -4.13 | BA31: 工伤利率调整，1月多收2月退 | BB31: 255 | BC31: =ROUND(AX31+BB31+AZ31+AY31,2) -> 22059.8 | BD31: =ROUND(BC31*6%,2) -> 1323.59 | BE31: =ROUND(SUM(BC31:BD31),2) -> 23383.39 | BF31: =AW31-5 -> 364
A32: =ROW()-2 -> 30 | B32: 2502 | C32: WB051748 | D32: 姚臻敏 | E32: 310227198009300019 | F32: 45444 | G32: 45808 | I32: 上海 | J32: 800 | K32: 1462 | L32: 855.84 | P32: 200 | R32: 630 | U32: 0 | X32: 732.48 | Z32: 0 | AA32: =SUM(J32:Z32) -> 4680.32 | AB32: 7384 | AC32: 590.72 | AD32: 147.68 | AE32: 36.92 | AF32: 5432 | AG32: =ROUND(AF32*7%,0) -> 380 | AH32: =AC32+AD32+AE32+AG32 -> 1155.32 | AL32: =AA32-AH32-AI32 -> 3525 | AM32: 7384 | AN32: 5432 | AO32: =ROUND(AM32*16%,2) -> 1181.44 | AP32: =ROUND(AM32*9%,2) -> 664.56 | AQ32: =ROUND(AM32*0.5%,2) -> 36.92 | AR32: 14.77 | AT32: =ROUND(AN32*7%,0) -> 380 | AU32: =ROUND(IF(AM32<24366,AM32*1.5%,24366*1.5%),2) -> 110.76 | AV32: =SUM(AO32:AU32) -> 2388.45 | AW32: 81 | AX32: =AV32+AA32+AJ32-AK32+AW32 -> 7149.77 | AY32: =5 -> 5 | AZ32: -4.13 | BA32: 本月低保补差5元，下月收，工伤利率调整，1月多收2月退 | BB32: 255 | BC32: =ROUND(AX32+BB32+AZ32+AY32,2) -> 7405.64 | BD32: =ROUND(BC32*6%,2) -> 444.34 | BE32: =ROUND(SUM(BC32:BD32),2) -> 7849.98 | BF32: =AW32-5 -> 76
A33: =ROW()-2 -> 31 | B33: 2502 | C33: WB049347 | D33: 王紫怡 | E33: 331082199904274040 | F33: 45444 | G33: 45808 | I33: 上海 | J33: 900 | K33: 2084.25 | L33: 1180.4 | P33: 200 | R33: 630 | U33: 0 | Z33: 0 | AA33: =SUM(J33:Z33) -> 4994.65 | AB33: 7606 | AC33: 608.48 | AD33: 152.12 | AE33: 38.03 | AF33: 7606 | AG33: =ROUND(AF33*7%,0) -> 532 | AH33: =AC33+AD33+AE33+AG33 -> 1330.63 | AL33: =AA33-AH33-AI33 -> 3664.02 | AM33: 7606 | AN33: 7606 | AO33: =ROUND(AM33*16%,2) -> 1216.96 | AP33: =ROUND(AM33*9%,2) -> 684.54 | AQ33: =ROUND(AM33*0.5%,2) -> 38.03 | AR33: 15.21 | AT33: =ROUND(AN33*7%,0) -> 532 | AU33: =ROUND(IF(AM33<24366,AM33*1.5%,24366*1.5%),2) -> 114.09 | AV33: =SUM(AO33:AU33) -> 2600.83 | AW33: 87 | AX33: =AV33+AA33+AJ33-AK33+AW33 -> 7682.48 | AZ33: -4.26 | BA33: 工伤利率调整，1月多收2月退 | BB33: 255 | BC33: =ROUND(AX33+BB33+AZ33+AY33,2) -> 7933.22 | BD33: =ROUND(BC33*6%,2) -> 475.99 | BE33: =ROUND(SUM(BC33:BD33),2) -> 8409.21 | BF33: =AW33-5 -> 82
A34: =ROW()-2 -> 32 | B34: 2502 | C34: WB034583 | D34: 沈婕妤 | E34: 310230198011070660 | F34: 45444 | G34: 45808 | I34: 上海 | J34: 1030 | K34: 1216 | L34: 1407.52 | P34: 200 | R34: 630 | U34: 0 | X34: 394.8 | Z34: -200 | AA34: =SUM(J34:Z34) -> 4678.32 | AB34: 7384 | AC34: 590.72 | AD34: 147.68 | AE34: 36.92 | AF34: 5402 | AG34: =ROUND(AF34*7%,0) -> 378 | AH34: =AC34+AD34+AE34+AG34 -> 1153.32 | AL34: =AA34-AH34-AI34 -> 3525 | AM34: 7384 | AN34: 5402 | AO34: =ROUND(AM34*16%,2) -> 1181.44 | AP34: =ROUND(AM34*9%,2) -> 664.56 | AQ34: =ROUND(AM34*0.5%,2) -> 36.92 | AR34: 14.77 | AT34: =ROUND(AN34*7%,0) -> 378 | AU34: =ROUND(IF(AM34<24366,AM34*1.5%,24366*1.5%),2) -> 110.76 | AV34: =SUM(AO34:AU34) -> 2386.45 | AW34: 81 | AX34: =AV34+AA34+AJ34-AK34+AW34 -> 7145.77 | AZ34: -4.13 | BA34: 工伤利率调整，1月多收2月退 | BB34: 255 | BC34: =ROUND(AX34+BB34+AZ34+AY34,2) -> 7396.64 | BD34: =ROUND(BC34*6%,2) -> 443.8 | BE34: =ROUND(SUM(BC34:BD34),2) -> 7840.44 | BF34: =AW34-5 -> 76
A35: =ROW()-2 -> 33 | B35: 2502 | C35: WB026293 | D35: 曹雪晨 | E35: 310227199101043419 | F35: 45444 | G35: 45808 | I35: 上海 | J35: 1030 | K35: 10020 | L35: 1245.04 | P35: 200 | R35: 630 | U35: 742 | Z35: -500 | AA35: =SUM(J35:Z35) -> 13367.04 | AB35: 10751 | AC35: 860.08 | AD35: 215.02 | AE35: 53.76 | AF35: 10751 | AG35: =ROUND(AF35*7%,0) -> 753 | AH35: =AC35+AD35+AE35+AG35 -> 1881.86 | AL35: =AA35-AH35-AI35 -> 11485.18 | AM35: 10751 | AN35: 10751 | AO35: =ROUND(AM35*16%,2) -> 1720.16 | AP35: 967.6 | AQ35: =ROUND(AM35*0.5%,2) -> 53.76 | AR35: 21.5 | AT35: =ROUND(AN35*7%,0) -> 753 | AU35: =ROUND(IF(AM35<24366,AM35*1.5%,24366*1.5%),2) -> 161.27 | AV35: =SUM(AO35:AU35) -> 3677.29 | AW35: 255 | AX35: =AV35+AA35+AJ35-AK35+AW35 -> 17299.33 | AZ35: -6.02 | BA35: 工伤利率调整，1月多收2月退 | BB35: 255 | BC35: =ROUND(AX35+BB35+AZ35+AY35,2) -> 17548.31 | BD35: =ROUND(BC35*6%,2) -> 1052.9 | BE35: =ROUND(SUM(BC35:BD35),2) -> 18601.21 | BF35: =AW35-5 -> 250
A36: =ROW()-2 -> 34 | B36: 2502 | C36: WB046608 | D36: 邹莉 | E36: 511126198605207327 | F36: 45444 | G36: 45808 | I36: 上海 | J36: 1030 | K36: 1216 | L36: 688 | P36: 200 | R36: 630 | U36: 371 | X36: 905.32 | Z36: -30 | AA36: =SUM(J36:Z36) -> 5010.32 | AB36: 7384 | AC36: 590.72 | AD36: 147.68 | AE36: 36.92 | AF36: 4849 | AG36: =ROUND(AF36*7%,0) -> 339 | AH36: =AC36+AD36+AE36+AG36 -> 1114.32 | AL36: =AA36-AH36-AI36 -> 3896 | AM36: 7384 | AN36: 4849 | AO36: =ROUND(AM36*16%,2) -> 1181.44 | AP36: =ROUND(AM36*9%,2) -> 664.56 | AQ36: =ROUND(AM36*0.5%,2) -> 36.92 | AR36: 14.77 | AT36: =ROUND(AN36*7%,0) -> 339 | AU36: =ROUND(IF(AM36<24366,AM36*1.5%,24366*1.5%),2) -> 110.76 | AV36: =SUM(AO36:AU36) -> 2347.45 | AW36: 88 | AX36: =AV36+AA36+AJ36-AK36+AW36 -> 7445.77 | AZ36: -4.13 | BA36: 工伤利率调整，1月多收2月退 | BB36: 255 | BC36: =ROUND(AX36+BB36+AZ36+AY36,2) -> 7696.64 | BD36: =ROUND(BC36*6%,2) -> 461.8 | BE36: =ROUND(SUM(BC36:BD36),2) -> 8158.44 | BF36: =AW36-5 -> 83
A37: =ROW()-2 -> 35 | B37: 2502 | C37: WB005376 | D37: 吴萍萍 | E37: 310227198801103668 | F37: 45444 | G37: 45808 | I37: 上海 | J37: 1510 | K37: 4471.8 | L37: 3248.4 | P37: 200 | R37: 630 | U37: 325 | Z37: 0 | AA37: =SUM(J37:Z37) -> 10385.2 | AB37: 12662 | AC37: 1012.96 | AD37: 253.24 | AE37: 63.31 | AF37: 12662 | AG37: =ROUND(AF37*7%,0) -> 886 | AH37: =AC37+AD37+AE37+AG37 -> 2215.51 | AL37: =AA37-AH37-AI37 -> 8169.69 | AM37: 12662 | AN37: 12662 | AO37: =ROUND(AM37*16%,2) -> 2025.92 | AP37: =ROUND(AM37*9%,2) -> 1139.58 | AQ37: =ROUND(AM37*0.5%,2) -> 63.31 | AR37: 25.32 | AT37: =ROUND(AN37*7%,0) -> 886 | AU37: =ROUND(IF(AM37<24366,AM37*1.5%,24366*1.5%),2) -> 189.93 | AV37: =SUM(AO37:AU37) -> 4330.06 | AW37: 195 | AX37: =AV37+AA37+AJ37-AK37+AW37 -> 14910.26 | AZ37: -7.09 | BA37: 工伤利率调整，1月多收2月退 | BB37: 255 | BC37: =ROUND(AX37+BB37+AZ37+AY37,2) -> 15158.17 | BD37: =ROUND(BC37*6%,2) -> 909.49 | BE37: =ROUND(SUM(BC37:BD37),2) -> 16067.66 | BF37: =AW37-5 -> 190
A38: =ROW()-2 -> 36 | B38: 2502 | C38: WB030495 | D38: 马一伟 | E38: 310110198101160036 | F38: 45444 | G38: 45808 | I38: 上海 | J38: 1200 | K38: 2073 | L38: 864.8 | P38: 200 | R38: 630 | U38: 0 | Z38: 0 | AA38: =SUM(J38:Z38) -> 4967.8 | AB38: 7384 | AC38: 590.72 | AD38: 147.68 | AE38: 36.92 | AF38: 2690 | AG38: =ROUND(AF38*7%,0) -> 188 | AH38: =AC38+AD38+AE38+AG38 -> 963.32 | AL38: =AA38-AH38-AI38 -> 4004.48 | AM38: 7384 | AN38: 2690 | AO38: =ROUND(AM38*16%,2) -> 1181.44 | AP38: =ROUND(AM38*9%,2) -> 664.56 | AQ38: =ROUND(AM38*0.5%,2) -> 36.92 | AR38: 14.77 | AT38: =ROUND(AN38*7%,0) -> 188 | AU38: =ROUND(IF(AM38<24366,AM38*1.5%,24366*1.5%),2) -> 110.76 | AV38: =SUM(AO38:AU38) -> 2196.45 | AW38: 87 | AX38: =AV38+AA38+AJ38-AK38+AW38 -> 7251.25 | AZ38: -4.13 | BA38: 工伤利率调整，1月多收2月退 | BB38: 255 | BC38: =ROUND(AX38+BB38+AZ38+AY38,2) -> 7502.12 | BD38: =ROUND(BC38*6%,2) -> 450.13 | BE38: =ROUND(SUM(BC38:BD38),2) -> 7952.25 | BF38: =AW38-5 -> 82
A39: =ROW()-2 -> 37 | B39: 2502 | C39: WB038316 | D39: 王乐意 | E39: 310227199806014028 | F39: 45444 | G39: 45808 | I39: 上海 | J39: 950 | K39: 1038.24 | L39: 407.2 | P39: 200 | R39: 630 | U39: 0 | X39: 1432.88 | Z39: 0 | AA39: =SUM(J39:Z39) -> 4658.32 | AB39: 7384 | AC39: 590.72 | AD39: 147.68 | AE39: 36.92 | AF39: 5121 | AG39: =ROUND(AF39*7%,0) -> 358 | AH39: =AC39+AD39+AE39+AG39 -> 1133.32 | AL39: =AA39-AH39-AI39 -> 3525 | AM39: 7384 | AN39: 5121 | AO39: =ROUND(AM39*16%,2) -> 1181.44 | AP39: =ROUND(AM39*9%,2) -> 664.56 | AQ39: =ROUND(AM39*0.5%,2) -> 36.92 | AR39: 14.77 | AT39: =ROUND(AN39*7%,0) -> 358 | AU39: =ROUND(IF(AM39<24366,AM39*1.5%,24366*1.5%),2) -> 110.76 | AV39: =SUM(AO39:AU39) -> 2366.45 | AW39: 81 | AX39: =AV39+AA39+AJ39-AK39+AW39 -> 7105.77 | AZ39: -4.13 | BA39: 工伤利率调整，1月多收2月退 | BB39: 255 | BC39: =ROUND(AX39+BB39+AZ39+AY39,2) -> 7356.64 | BD39: =ROUND(BC39*6%,2) -> 441.4 | BE39: =ROUND(SUM(BC39:BD39),2) -> 7798.04 | BF39: =AW39-5 -> 76
A40: =ROW()-2 -> 38 | B40: 2502 | C40: WB035781 | D40: 潘奇伟 | E40: 310227199011142819 | F40: 45474 | G40: 45838 | I40: 上海 | J40: 950 | K40: 1534.24 | L40: 1196.64 | P40: 200 | R40: 630 | U40: 0 | Z40: 0 | AA40: =SUM(J40:Z40) -> 4510.88 | AB40: 7384 | AC40: 590.72 | AD40: 147.68 | AE40: 36.92 | AF40: 2690 | AG40: =ROUND(AF40*7%,0) -> 188 | AH40: =AC40+AD40+AE40+AG40 -> 963.32 | AL40: =AA40-AH40-AI40 -> 3547.56 | AM40: 7384 | AN40: 2690 | AO40: =ROUND(AM40*16%,2) -> 1181.44 | AP40: =ROUND(AM40*9%,2) -> 664.56 | AQ40: =ROUND(AM40*0.5%,2) -> 36.92 | AR40: 14.77 | AT40: =ROUND(AN40*7%,0) -> 188 | AU40: =ROUND(IF(AM40<24366,AM40*1.5%,24366*1.5%),2) -> 110.76 | AV40: =SUM(AO40:AU40) -> 2196.45 | AW40: 78 | AX40: =AV40+AA40+AJ40-AK40+AW40 -> 6785.33 | AZ40: -4.13 | BA40: 工伤利率调整，1月多收2月退 | BB40: 255 | BC40: =ROUND(AX40+BB40+AZ40+AY40,2) -> 7036.2 | BD40: =ROUND(BC40*6%,2) -> 422.17 | BE40: =ROUND(SUM(BC40:BD40),2) -> 7458.37 | BF40: =AW40-5 -> 73
...

Sheet 对账单
A1: 科目 | B1: 手工账单 | C1: 速创账单 | D1: 155 | E1: 预收一次性 | F1: 1月工会费 | G1: 本月垫付，下月收 | H1: 本月多收，下月退 | I1: 合计 | J1: 差异
A2: 管理费 | B2: ='202502'!BD45 -> 24039.46 | C2: =系统!E57 -> 27358.73 | D2: =40*155 -> 6200 | I2: =SUM(C2:G2) -> 33558.73 | J2: =B2-C2 -> -3319.27
A3: 风险费 | B3: ='202502'!BB45 -> 10200 | C3: 0 | I3: =SUM(C3:G3) -> 0 | J3: =B3-C3 -> 10200
A4: 个人四金 | B4: ='202502'!AH45 -> 51887.71 | C4: =系统!V57 -> 51887.71 | I4: =SUM(C4:G4) -> 51887.71 | J4: =B4-C4 -> 0
A5: 公司四金 | B5: ='202502'!AV45 -> 106462.92 | C5: =系统!O57 -> 106462.92 | I5: =SUM(C5:E5) -> 106462.92 | J5: =B5-C5 -> 0
A6: 工伤退费 | I6: =SUM(C6:G6) -> 0 | J6: =B6-C6 -> 0
A7: 代发工资 | B7: ='202502'!AA45-'202502'!AH45 -> 227159.81 | C7: =系统!W57 -> 226959.81 | D7: =5*40 -> 200 | I7: =SUM(C7:G7) -> 227159.81 | J7: =B7-C7 -> 200
A8: 上月垫付 | B8: ='202502'!AY45 -> 40 | D8: =40 -> 40 | I8: =SUM(C8:G8) -> 40 | J8: =B8-C8 -> 40
A9: 工会费 | B9: ='202502'!AW45 -> 5090 | D9: =B10 -> -182.89 | F9: =B9 -> 5090 | I9: =SUM(C9:G9) -> 4907.11 | J9: =B9-C9 -> 5090
A10: 上月多收 | B10: ='202502'!AZ45 -> -182.89 | I10: =SUM(C10:G10) -> 0 | J10: =B10-C10 -> -182.89
A11: 小计 | B11: =SUM(B2:B10) -> 424697.01 | C11: =SUM(C2:C10) -> 412669.17 | D11: =SUM(D2:D10) -> 6257.11 | E11: =E5 -> 0 | F11: =F9 -> 5090 | G11: =G9 -> 0 | H11: =H9 -> 0 | I11: =SUM(C11:G11) -> 424016.28
A12: 附加税
A13: 增值税 | D13: =ROUND((D11+D12)*6%,2) -> 375.43 | F13: =ROUND((F11+F12)*6%,2) -> 305.4 | G13: =ROUND((G11+G12)*6%,2) -> 0 | H13: =ROUND((H11+H12)*6%,2) -> 0 | I13: =SUM(C13:G13) -> 680.83
A14: 总计 | B14: =SUM(B11:B13) -> 424697.01 | C14: =SUM(C11:C13) -> 412669.17 | D14: =SUM(D11:D13) -> 6632.54 | E14: =E11 -> 0 | F14: =SUM(F11:F13) -> 5395.4 | G14: =SUM(G11:G13) -> 0 | H14: =SUM(H11:H13) -> 0 | I14: =SUM(C14:H14) -> 424697.11
A15: 给客户账单金额 | I15: =B14 -> 424697.01
A16: 差异 | I16: =I15-I14 -> -0.1
A17: 不含税差异 | I17: =ROUND(I16/1.06,2) -> -0.09

Sheet 系统
A1: 200070
A2: 寄：梅园路77号人才大厦
B3: 中国电信股份有限公司上海分公司 王慧珏 收
D6: 上海外服布列吉科技有限公司
C7: Shanghai Foreign Service Bridge Technology Co,Ltd.
E9: 收款通知书
E10: ADVISE ON COLLECTION
E11: 2025年02月
A13: 公司名称：中国电信股份有限公司上海分公司 | J13: 帐单号：202502CH6565005
A14: 序号 | B14: 姓名 | C14: 发生年月 | D14: 入职日期 | E14: 管理费 | F14: 当月社保基数 | G14: 当月公积金基数 | H14: 社保类 公司支付 Social Insurance Premiums Paid by Employer | N14: 公积金类 公司支付 Provident Fund Paid by Employer | O14: 公司合计 | P14: 社保类 个人支付 Social Insurance Premiums Paid by Employee | U14: 公积金类 个人支付 Provident Fund Paid by Employee | V14: 个人合计 | W14: 代办薪酬 | X14: 其他 | Y14: 总计 | Z14: 备注 | AA14: 外服工号 | AB14: 证件号码 | AC14: 内部工号 | AD14: 应纳税金额 | AE14: 税率 | AF14: 增值税
A15: S/N | B15: Name | C15: YYYYMM | D15: Employment Start Date | E15: Adm Fee | F15: Social Insurance Base Amount of Current Month | G15: Provident Fund Base Amount of Current Month | H15: 养老保险 Endowment | I15: 医疗保险 Medical | J15: 失业保险 Unemploy-ment | K15: 工伤保险 Employment Injury | L15: 医疗生育保险 Medical Maternity | M15: 保障金 Disabled people&Back pay Fund | N15: 公积金 Provident Fund | O15: Subtotal of Employer Payment | P15: 养老保险 Endowment | Q15: 医疗保险 Medical | R15: 失业保险 Unemploy-ment | S15: 工伤保险 Employment Injury | T15: 医疗生育保险 Medical Maternity | U15: 公积金 Provident Fund | V15: Subtotal of Personal Payment | W15: Agency of Wage Payment | X15: Others | Y15: Total | Z15: Remarks | AA15: SFSC ID | AB15: ID Card | AC15: Internal ID | AD15: Taxable Amount | AE15: Tax Rate | AF15: VAT
A16: 1 | B16: 曹克洋 | C16: 202502 | D16: 2024-06-01 | E16: 529.23 | F16: 7384 | G16: 5351 | H16: 1181.44 | I16: 664.56 | J16: 36.92 | K16: 14.77 | M16: 110.76 | N16: 375 | O16: =SUM(H16:N16) -> 2383.45 | P16: 590.72 | Q16: 147.68 | R16: 36.92 | U16: 375 | V16: =SUM(P16:U16) -> 1150.32 | W16: 3520 | Y16: =SUM(E16,O16,V16:X16) -> 7583 | AA16: 5545179 | AB16: 341226199712081318 | AD16: 7153.76 | AE16: 6% | AF16: 429.24
A17: 2 | B17: 曹雪晨 | C17: 202502 | D17: 2024-06-01 | E17: 1128.36 | F17: 10751 | G17: 10751 | H17: 1720.16 | I17: 967.6 | J17: 53.76 | K17: 21.5 | M17: 161.27 | N17: 753 | O17: =SUM(H17:N17) -> 3677.29 | P17: 860.08 | Q17: 215.02 | R17: 53.76 | U17: 753 | V17: =SUM(P17:U17) -> 1881.86 | W17: 11480.18 | Y17: =SUM(E17,O17,V17:X17) -> 18167.69 | AA17: 5573404 | AB17: 310227199101043419 | AD17: 17139.32 | AE17: 6% | AF17: 1028.37
A18: 3 | B18: 常宇航 | C18: 202502 | D18: 2024-06-01 | E18: 604.15 | F18: 7384 | G18: 6644 | H18: 1181.44 | I18: 664.56 | J18: 36.92 | K18: 14.77 | M18: 110.76 | N18: 465 | O18: =SUM(H18:N18) -> 2473.45 | P18: 590.72 | Q18: 147.68 | R18: 36.92 | U18: 465 | V18: =SUM(P18:U18) -> 1240.32 | W18: 4588.68 | Y18: =SUM(E18,O18,V18:X18) -> 8906.6 | AA18: 5545178 | AB18: 340321199609230533 | AD18: 8402.44 | AE18: 6% | AF18: 504.16
A19: 4 | B19: 陈喆昕 | C19: 202502 | D19: 2024-07-01 | E19: 497.79 | F19: 7384 | G19: 2690 | H19: 1181.44 | I19: 664.56 | J19: 36.92 | K19: 14.77 | M19: 110.76 | N19: 188 | O19: =SUM(H19:N19) -> 2196.45 | P19: 590.72 | Q19: 147.68 | R19: 36.92 | U19: 188 | V19: =SUM(P19:U19) -> 963.32 | W19: 3370 | Y19: =SUM(E19,O19,V19:X19) -> 7027.56 | AA19: 6063573 | AB19: 310227198312160012 | AD19: 6629.76 | AE19: 6% | AF19: 397.8
A20: 5 | B20: 戴连荣 | C20: 202502 | D20: 2024-06-01 | E20: 1053 | F20: 12760 | G20: 12760 | H20: 2041.6 | I20: 1148.4 | J20: 63.8 | K20: 25.52 | M20: 191.4 | N20: 893 | O20: =SUM(H20:N20) -> 4363.72 | P20: 1020.8 | Q20: 255.2 | R20: 63.8 | U20: 893 | V20: =SUM(P20:U20) -> 2232.8 | W20: 9186.9 | Y20: =SUM(E20,O20,V20:X20) -> 16836.42 | AA20: 5517492 | AB20: 310227198411292010 | AD20: 15883.42 | AE20: 6% | AF20: 953
A21: 6 | B21: 封春燕 | C21: 202502 | D21: 2024-06-01 | E21: 1392.1 | F21: 7384 | G21: 5109 | H21: 1181.44 | I21: 664.56 | J21: 36.92 | K21: 14.77 | M21: 110.76 | N21: 358 | O21: =SUM(H21:N21) -> 2366.45 | P21: 590.72 | Q21: 147.68 | R21: 36.92 | U21: 358 | V21: =SUM(P21:U21) -> 1133.32 | W21: 17935.16 | Y21: =SUM(E21,O21,V21:X21) -> 22827.03 | AA21: 5573397 | AB21: 310227198610224213 | AD21: 21534.92 | AE21: 6% | AF21: 1292.11
A22: 7 | B22: 高峰 | C22: 202502 | D22: 2024-06-01 | E22: 1366.89 | F22: 13877 | G22: 13877 | H22: 2220.32 | I22: 1248.94 | J22: 69.39 | K22: 27.75 | M22: 208.16 | N22: 971 | O22: =SUM(H22:N22) -> 4745.56 | P22: 1110.16 | Q22: 277.54 | R22: 69.39 | U22: 971 | V22: =SUM(P22:U22) -> 2428.09 | W22: 13841.15 | Y22: =SUM(E22,O22,V22:X22) -> 22381.69 | AA22: 5573394 | AB22: 342501197909046816 | AD22: 21114.8 | AE22: 6% | AF22: 1266.89
A23: 8 | B23: 高国强 | C23: 202502 | D23: 2024-06-01 | E23: 538.53 | F23: 7384 | G23: 4880 | H23: 1181.44 | I23: 664.56 | J23: 36.92 | K23: 14.77 | M23: 110.76 | N23: 342 | O23: =SUM(H23:N23) -> 2350.45 | P23: 590.72 | Q23: 147.68 | R23: 36.92 | U23: 342 | V23: =SUM(P23:U23) -> 1117.32 | W23: 3741 | Y23: =SUM(E23,O23,V23:X23) -> 7747.3 | AA23: 5573388 | AB23: 65010319750517061X | AD23: 7308.76 | AE23: 6% | AF23: 438.54
A24: 9 | B24: 顾诗瑶 | C24: 202502 | D24: 2024-06-01 | E24: 452.55 | F24: 7384 | G24: 4570 | H24: 1181.44 | I24: 664.56 | J24: 36.92 | K24: 14.77 | M24: 110.76 | N24: 320 | O24: =SUM(H24:N24) -> 2328.45 | P24: 590.72 | Q24: 147.68 | R24: 36.92 | U24: 320 | V24: =SUM(P24:U24) -> 1095.32 | W24: 2352 | Y24: =SUM(E24,O24,V24:X24) -> 6228.32 | AA24: 5517495 | AB24: 310227199812152021 | AD24: 5875.76 | AE24: 6% | AF24: 352.56
A25: 10 | B25: 何军利 | C25: 202502 | D25: 2024-06-01 | E25: 58.44 | O25: =SUM(H25:N25) -> 0 | V25: =SUM(P25:U25) -> 0 | W25: 974 | Y25: =SUM(E25,O25,V25:X25) -> 1032.44 | AA25: 5545181 | AB25: 310227197512314245 | AD25: 974 | AE25: 6% | AF25: 58.44
A26: 11 | B26: 姜金玲 | C26: 202502 | D26: 2024-06-01 | E26: 521.79 | F26: 7384 | G26: 4467 | H26: 1181.44 | I26: 664.56 | J26: 36.92 | K26: 14.77 | M26: 110.76 | N26: 313 | O26: =SUM(H26:N26) -> 2321.45 | P26: 590.72 | Q26: 147.68 | R26: 36.92 | U26: 313 | V26: =SUM(P26:U26) -> 1088.32 | W26: 3520 | Y26: =SUM(E26,O26,V26:X26) -> 7451.56 | AA26: 5573391 | AB26: 310227198902274028 | AD26: 7029.76 | AE26: 6% | AF26: 421.8
A27: 12 | B27: 蒋萍萍 | C27: 202502 | D27: 2024-06-01 | E27: 788.12 | F27: 8677 | G27: 8677 | H27: 1388.32 | I27: 780.94 | J27: 43.39 | K27: 17.35 | M27: 130.16 | N27: 607 | O27: =SUM(H27:N27) -> 2967.16 | P27: 694.16 | Q27: 173.54 | R27: 43.39 | U27: 607 | V27: =SUM(P27:U27) -> 1518.09 | W27: 6883.35 | Y27: =SUM(E27,O27,V27:X27) -> 12156.72 | AA27: 5573396 | AB27: 310227199108114021 | AD27: 11468.61 | AE27: 6% | AF27: 688.11
A28: 13 | B28: 孔祥杰 | C28: 202502 | D28: 2024-06-01 | E28: 544.59 | F28: 7384 | G28: 7189 | H28: 1181.44 | I28: 664.56 | J28: 36.92 | K28: 14.77 | M28: 110.76 | N28: 503 | O28: =SUM(H28:N28) -> 2511.45 | P28: 590.72 | Q28: 147.68 | R28: 36.92 | U28: 503 | V28: =SUM(P28:U28) -> 1278.32 | W28: 3520 | Y28: =SUM(E28,O28,V28:X28) -> 7854.36 | AA28: 5545173 | AB28: 310110198408153236 | AD28: 7409.76 | AE28: 6% | AF28: 444.6
A29: 14 | B29: 李龙燕 | C29: 202502 | D29: 2024-06-01 | E29: 821.82 | F29: 8878 | G29: 8878 | H29: 1420.48 | I29: 799.02 | J29: 44.39 | K29: 17.76 | M29: 133.17 | N29: 621 | O29: =SUM(H29:N29) -> 3035.82 | P29: 710.24 | Q29: 177.56 | R29: 44.39 | U29: 621 | V29: =SUM(P29:U29) -> 1553.19 | W29: 7341.37 | Y29: =SUM(E29,O29,V29:X29) -> 12752.2 | AA29: 5573395 | AB29: 320681199310316032 | AD29: 12030.39 | AE29: 6% | AF29: 721.81
A30: 15 | B30: 李琴 | C30: 202502 | D30: 2025-02-01 | E30: 530.43 | F30: 7384 | G30: 5493 | H30: 1181.44 | I30: 664.56 | J30: 36.92 | K30: 14.77 | M30: 110.76 | N30: 385 | O30: =SUM(H30:N30) -> 2393.45 | P30: 590.72 | Q30: 147.68 | R30: 36.92 | U30: 385 | V30: =SUM(P30:U30) -> 1160.32 | W30: 3520 | Y30: =SUM(E30,O30,V30:X30) -> 7604.2 | AA30: 6283726 | AB30: 310227198708184424 | AD30: 7173.76 | AE30: 6% | AF30: 430.44
A31: 16 | B31: 李秋梅 | C31: 202502 | D31: 2024-06-01 | E31: 603.4 | F31: 7384 | G31: 7034 | H31: 1181.44 | I31: 664.56 | J31: 36.92 | K31: 14.77 | M31: 110.76 | N31: 492 | O31: =SUM(H31:N31) -> 2500.45 | P31: 590.72 | Q31: 147.68 | R31: 36.92 | U31: 492 | V31: =SUM(P31:U31) -> 1267.32 | W31: 4522.24 | Y31: =SUM(E31,O31,V31:X31) -> 8893.41 | AA31: 5573387 | AB31: 320321198010030887 | AD31: 8390 | AE31: 6% | AF31: 503.41
A32: 17 | B32: 陆丽伟 | C32: 202502 | D32: 2024-05-01 | E32: 506.79 | F32: 7384 | G32: 2690 | H32: 1181.44 | I32: 664.56 | J32: 36.92 | K32: 14.77 | M32: 110.76 | N32: 188 | O32: =SUM(H32:N32) -> 2196.45 | P32: 590.72 | Q32: 147.68 | R32: 36.92 | U32: 188 | V32: =SUM(P32:U32) -> 963.32 | W32: 3520 | Y32: =SUM(E32,O32,V32:X32) -> 7186.56 | AA32: 6010738 | AB32: 310227198802293619 | AD32: 6779.76 | AE32: 6% | AF32: 406.8
A33: 18 | B33: 陆晓岚 | C33: 202502 | D33: 2024-06-01 | E33: 670.27 | F33: 7384 | G33: 5300 | H33: 1181.44 | I33: 664.56 | J33: 36.92 | K33: 14.77 | M33: 110.76 | N33: 371 | O33: =SUM(H33:N33) -> 2379.45 | P33: 590.72 | Q33: 147.68 | R33: 36.92 | U33: 371 | V33: =SUM(P33:U33) -> 1146.32 | W33: 5878.68 | Y33: =SUM(E33,O33,V33:X33) -> 10074.72 | AA33: 1881345 | AB33: 310227199207211222 | AD33: 9504.44 | AE33: 6% | AF33: 570.28
A34: 19 | B34: 陆智俊 | C34: 202502 | D34: 2024-06-01 | E34: 584.15 | F34: 7556 | G34: 7556 | H34: 1208.96 | I34: 680.04 | J34: 37.78 | K34: 15.11 | M34: 113.34 | N34: 529 | O34: =SUM(H34:N34) -> 2584.23 | P34: 604.48 | Q34: 151.12 | R34: 37.78 | U34: 529 | V34: =SUM(P34:U34) -> 1322.38 | W34: 4062.51 | Y34: =SUM(E34,O34,V34:X34) -> 8553.27 | AA34: 5545180 | AB34: 310227199807124616 | AD34: 8069.11 | AE34: 6% | AF34: 484.16
A35: 20 | B35: 马一伟 | C35: 202502 | D35: 2024-06-01 | E35: 535.56 | F35: 7384 | G35: 2690 | H35: 1181.44 | I35: 664.56 | J35: 36.92 | K35: 14.77 | M35: 110.76 | N35: 188 | O35: =SUM(H35:N35) -> 2196.45 | P35: 590.72 | Q35: 147.68 | R35: 36.92 | U35: 188 | V35: =SUM(P35:U35) -> 963.32 | W35: 3999.48 | Y35: =SUM(E35,O35,V35:X35) -> 7694.81 | AA35: 5862530 | AB35: 310110198101160036 | AD35: 7259.24 | AE35: 6% | AF35: 435.57
A36: 21 | B36: 牟金丽 | C36: 202502 | D36: 2024-06-01 | E36: 521.91 | F36: 7384 | G36: 4492 | H36: 1181.44 | I36: 664.56 | J36: 36.92 | K36: 14.77 | M36: 110.76 | N36: 314 | O36: =SUM(H36:N36) -> 2322.45 | P36: 590.72 | Q36: 147.68 | R36: 36.92 | U36: 314 | V36: =SUM(P36:U36) -> 1089.32 | W36: 3520 | Y36: =SUM(E36,O36,V36:X36) -> 7453.68 | AA36: 5573393 | AB36: 422802198502180068 | AD36: 7031.76 | AE36: 6% | AF36: 421.92
A37: 22 | B37: 倪跃新 | C37: 202502 | D37: 2024-06-01 | E37: 677.44 | F37: 7384 | G37: 6353 | H37: 1181.44 | I37: 664.56 | J37: 36.92 | K37: 14.77 | M37: 110.76 | N37: 445 | O37: =SUM(H37:N37) -> 2453.45 | P37: 590.72 | Q37: 147.68 | R37: 36.92 | U37: 445 | V37: =SUM(P37:U37) -> 1220.32 | W37: 5850.16 | Y37: =SUM(E37,O37,V37:X37) -> 10201.37 | AA37: 5573386 | AB37: 310229197208182017 | AD37: 9623.92 | AE37: 6% | AF37: 577.45
... A56: 41 | B56: 邹莉 | C56: 202502 | D56: 2024-06-01 | E56: 547.17 | F56: 7384 | G56: 4849 | H56: 1181.44 | I56: 664.56 | J56: 36.92 | K56: 14.77 | M56: 110.76 | N56: 339 | O56: =SUM(H56:N56) -> 2347.45 | P56: 590.72 | Q56: 147.68 | R56: 36.92 | U56: 339 | V56: =SUM(P56:U56) -> 1114.32 | W56: 3891 | Y56: =SUM(E56,O56,V56:X56) -> 7899.94 | AA56: 5573405 | AB56: 511126198605207327 | AD56: 7452.76 | AE56: 6% | AF56: 447.18
A57: 合计（RMB） | E57: =SUM(E16:E56) -> 27358.73 | H57: =SUM(H16:H56) -> 52287.52 | I57: =SUM(I16:I56) -> 29411.78 | J57: =SUM(J16:J56) -> 1634.01 | K57: =SUM(K16:K56) -> 653.63 | L57: =SUM(L16:L56) -> 0 | M57: =SUM(M16:M56) -> 4901.98 | N57: =SUM(N16:N56) -> 17574 | O57: =SUM(O16:O56) -> 106462.92 | ... Y57: =SUM(Y16:Y56) -> 412669.17 | AD57: =SUM(AD16:AD56) -> 389310.16 | AF57: =SUM(AF16:AF56) -> 23359.01
A58: 总计（RMB）已包含历月补收人民币肆拾壹万贰仟陆佰陆拾玖圆壹角柒分 | Y58: 412669.17
A60: 其他费用
A61: 序号 | B61: 发生年月 | C61: 费用项目 | D61: 金额 | E61: 备注 | F61: 应纳税金额 | G61: 税率 | H61: 增值税
A62: S/N | B62: YYYYMM | C62: Item | D62: Amount | E62: Remarks | F62: Taxable Amount | G62: Tax Rate | H62: VAT
A63: 1 | B63: 202502 | C63: 税差调整6% | D63: 0 | F63: 0.38 | G63: 0.06 | H63: -0.38
...
