Workbook

Sheet 202503
A1: 序号 | B1: 计薪 周期 | C1: 工号 | D1: 姓名 | E1: 身份证号 | F1: 劳动合同起始日期 | G1: 劳动合同结束日期 | H1: 离职日期 | I1: 社保缴纳地 | J1: 星级费用 | K1: 考核费用 | L1: 量化费用 | M1: 专项费用 | Z1: 当月税前工资合计 | AA1: 社保基数(个人) | AB1: 养老保险(个人) | AC1: 医疗保险(个人) | AD1: 失业保险(个人) | AE1: 公积金基数(个人) | AF1: 住房公积金(个人) | AG1: 员工五险一金合计 | AH1: 本月个人所得税-系统导出 | AI1: 税后增加 | AJ1: 税后扣减 | AK1: 员工实发合计 | AL1: 社保基数 | AM1: 公积金基数 | AN1: 养老缴费 | AO1: 医疗缴费 | AP1: 失业保险 | AQ1: 工伤保险 | AR1: 生育保险 | AS1: 公积金 | AT1: 残保金 | AU1: 企业五险一金合计 | AV1: 工会费 | AW1: 代收付合计 | AX1: 平台清算 | AY1: 社保备注 | AZ1: 外包服务费 | BA1: 税前项合计 | BB1: 增值税 | BC1: 总计 | BD1: 工会费返回
A2: NO. | B2: Salary Cycle | C2: Employee No. | D2: Name | E2: ID No. | F2: Contract Starting Date | G2: Contract Expiry Date | H2: Exit Date | I2: Social Insurance City | J2: Contract Salary | K2: Assessment fees | L2: Quantifying costs | M2: 支局专项 | N2: 1+1激励 | O2: 交通费 | P2: 效能补贴 | Q2: 高温费及清凉饮料费 （6-9月） | R2: 伙食补贴 | S2: 独生子女奖励 | T2: 保险费 | U2: 其他费用 | V2: 补发费用 | W2: 劳防用品 | X2: 保障多收 | Y2: 其他扣款 | Z2: Pre-tax Total | AA2: Social Insurance Base | AB2: Pension Employee | AC2: Medical Employee | AD2: Umemployment Employee | AE2: Housing Fund Base | AF2: Housing Fund Employee | AG2: Total Amount of Social Insurance(EE) | AH2: Personal Income Tax | AI2: Increase After-tax payment | AJ2: Reduction After-tax payment | AK2: After-tax total Income | AL2: Social Insurance Base | AM2: Housing Fund Base | AN2: Pension Employer | AO2: Medical Employer | AP2: Umemployment Employer | AQ2: Injury Employer | AR2: Maternity Insurance Employer | AS2: Housing Fund Employer | AT2: Disabled people&Back pay Fund | AU2: Total Amount of Social Insurance(ER) | AV2: Union Fee | AW2: Payment Total | AY2: Social Security remark | AZ2: Service Fee | BA2: Total | BB2: VAT | BC2: Subtotal
A3: =ROW()-2 -> 1 | B3: 2502 | C3: WB026139 | D3: 赵梅 | E3: 310227198801262829 | F3: 45413 | G3: 45777 | I3: 上海 | J3: 1200 | K3: 6009.73 | L3: 2681.68 | P3: 200 | R3: 630 | X3: 0 | Y3: 0 | Z3: =SUM(J3:Y3) -> 10721.41 | AA3: 7384 | AB3: 590.72 | AC3: 147.68 | AD3: 36.92 | AE3: 2690 | AF3: =ROUND(AE3*7%,0) -> 188 | AG3: =AB3+AC3+AD3+AF3 -> 963.32 | AK3: =Z3-AG3-AH3 -> 9758.09 | AL3: 7384 | AM3: 2690 | AN3: =ROUND(AL3*16%,2) -> 1181.44 | AO3: =ROUND(AL3*9%,2) -> 664.56 | AP3: =ROUND(AL3*0.5%,2) -> 36.92 | AQ3: 14.77 | AS3: =ROUND(AM3*7%,0) -> 188 | AT3: =ROUND(IF(AL3<24366,AL3*1.5%,24366*1.5%),2) -> 110.76 | AU3: =SUM(AN3:AT3) -> 2196.45 | AV3: 202 | AW3: =AU3+Z3+AI3-AJ3+AV3 -> 13119.86 | AZ3: 255 | BA3: =ROUND(AW3+AZ3+AX3,2) -> 13374.86 | BB3: =ROUND(BA3*6%,2) -> 802.49 | BC3: =ROUND(SUM(BA3:BB3),2) -> 14177.35 | BD3: =AV3-5 -> 197
A4: =ROW()-2 -> 2 | B4: 2503 | C4: WB032993 | D4: 施梅 | E4: 310227198805293665 | F4: 45413 | G4: 45777 | I4: 上海 | J4: 950 | K4: 1913.56 | L4: 924.8 | P4: 200 | R4: 630 | X4: 0 | Y4: 0 | Z4: =SUM(J4:Y4) -> 4618.36 | AA4: 7384 | AB4: 590.72 | AC4: 147.68 | AD4: 36.92 | AE4: 2690 | AF4: =ROUND(AE4*7%,0) -> 188 | AG4: =AB4+AC4+AD4+AF4 -> 963.32 | AK4: =Z4-AG4-AH4 -> 3655.04 | AL4: 7384 | AM4: 2690 | AN4: =ROUND(AL4*16%,2) -> 1181.44 | AO4: =ROUND(AL4*9%,2) -> 664.56 | AP4: =ROUND(AL4*0.5%,2) -> 36.92 | AQ4: 14.77 | AS4: =ROUND(AM4*7%,0) -> 188 | AT4: =ROUND(IF(AL4<24366,AL4*1.5%,24366*1.5%),2) -> 110.76 | AU4: =SUM(AN4:AT4) -> 2196.45 | AV4: 80 | AW4: =AU4+Z4+AI4-AJ4+AV4 -> 6894.81 | AZ4: 255 | BA4: =ROUND(AW4+AZ4+AX4,2) -> 7149.81 | BB4: =ROUND(BA4*6%,2) -> 428.99 | BC4: =ROUND(SUM(BA4:BB4),2) -> 7578.8 | BD4: =AV4-5 -> 75
A5: =ROW()-2 -> 3 | B5: 2503 | C5: WB045273 | D5: 赵燕敏 | E5: 310225198105111629 | F5: 45413 | G5: 45777 | I5: 上海 | J5: 1030 | K5: 2369.8 | L5: 1295.6 | P5: 200 | R5: 630 | X5: 0 | Y5: 0 | Z5: =SUM(J5:Y5) -> 5525.4 | AA5: 7384 | AB5: 590.72 | AC5: 147.68 | AD5: 36.92 | AE5: 2690 | AF5: =ROUND(AE5*7%,0) -> 188 | AG5: =AB5+AC5+AD5+AF5 -> 963.32 | AK5: =Z5-AG5-AH5 -> 4562.08 | AL5: 7384 | AM5: 2690 | AN5: =ROUND(AL5*16%,2) -> 1181.44 | AO5: =ROUND(AL5*9%,2) -> 664.56 | AP5: =ROUND(AL5*0.5%,2) -> 36.92 | AQ5: 14.77 | AS5: =ROUND(AM5*7%,0) -> 188 | AT5: =ROUND(IF(AL5<24366,AL5*1.5%,24366*1.5%),2) -> 110.76 | AU5: =SUM(AN5:AT5) -> 2196.45 | AV5: 98 | AW5: =AU5+Z5+AI5-AJ5+AV5 -> 7819.85 | AZ5: 255 | BA5: =ROUND(AW5+AZ5+AX5,2) -> 8074.85 | BB5: =ROUND(BA5*6%,2) -> 484.49 | BC5: =ROUND(SUM(BA5:BB5),2) -> 8559.34 | BD5: =AV5-5 -> 93
A6: =ROW()-2 -> 4 | B6: 2503 | C6: WB030755 | D6: 谭晓刚 | E6: 310227197503241611 | F6: 45413 | G6: 45777 | I6: 上海 | J6: 950 | K6: 5175 | L6: 1310.32 | P6: 200 | R6: 630 | X6: 0 | Y6: 0 | Z6: =SUM(J6:Y6) -> 8265.32 | AA6: 7384 | AB6: 590.72 | AC6: 147.68 | AD6: 36.92 | AE6: 2690 | AF6: =ROUND(AE6*7%,0) -> 188 | AG6: =AB6+AC6+AD6+AF6 -> 963.32 | AK6: =Z6-AG6-AH6 -> 7302 | AL6: 7384 | AM6: 2690 | AN6: =ROUND(AL6*16%,2) -> 1181.44 | AO6: =ROUND(AL6*9%,2) -> 664.56 | AP6: =ROUND(AL6*0.5%,2) -> 36.92 | AQ6: 14.77 | AS6: =ROUND(AM6*7%,0) -> 188 | AT6: =ROUND(IF(AL6<24366,AL6*1.5%,24366*1.5%),2) -> 110.76 | AU6: =SUM(AN6:AT6) -> 2196.45 | AV6: 153 | AW6: =AU6+Z6+AI6-AJ6+AV6 -> 10614.77 | AZ6: 255 | BA6: =ROUND(AW6+AZ6+AX6,2) -> 10869.77 | BB6: =ROUND(BA6*6%,2) -> 652.19 | BC6: =ROUND(SUM(BA6:BB6),2) -> 11521.96 | BD6: =AV6-5 -> 148
A7: =ROW()-2 -> 5 | B7: 2503 | C7: WB046623 | D7: 陆丽伟 | E7: 310227198802293619 | F7: 45413 | G7: 45777 | I7: 上海 | J7: 950 | K7: 473.04 | L7: 0 | P7: 200 | R7: 630 | X7: 2235.28 | Y7: 0 | Z7: =SUM(J7:Y7) -> 4488.32 | AA7: 7384 | AB7: 590.72 | AC7: 147.68 | AD7: 36.92 | AE7: 2690 | AF7: =ROUND(AE7*7%,0) -> 188 | AG7: =AB7+AC7+AD7+AF7 -> 963.32 | AK7: =Z7-AG7-AH7 -> 3525 | AL7: 7384 | AM7: 2690 | AN7: =ROUND(AL7*16%,2) -> 1181.44 | AO7: =ROUND(AL7*9%,2) -> 664.56 | AP7: =ROUND(AL7*0.5%,2) -> 36.92 | AQ7: 14.77 | AS7: =ROUND(AM7*7%,0) -> 188 | AT7: =ROUND(IF(AL7<24366,AL7*1.5%,24366*1.5%),2) -> 110.76 | AU7: =SUM(AN7:AT7) -> 2196.45 | AV7: 77 | AW7: =AU7+Z7+AI7-AJ7+AV7 -> 6761.77 | AZ7: 255 | BA7: =ROUND(AW7+AZ7+AX7,2) -> 7016.77 | BB7: =ROUND(BA7*6%,2) -> 421.01 | BC7: =ROUND(SUM(BA7:BB7),2) -> 7437.78 | BD7: =AV7-5 -> 72
A8: =ROW()-2 -> 6 | B8: 2503 | C8: WB013255 | D8: 任清丽 | E8: 341223198806062763 | F8: 45444 | G8: 45808 | I8: 上海 | J8: 900 | K8: 4576 | L8: 4081.6 | P8: 200 | R8: 630 | X8: 0 | Y8: 0 | Z8: =SUM(J8:Y8) -> 10387.6 | AA8: 7384 | AB8: 590.72 | AC8: 147.68 | AD8: 36.92 | AE8: 6878 | AF8: =ROUND(AE8*7%,0) -> 481 | AG8: =AB8+AC8+AD8+AF8 -> 1256.32 | AK8: =Z8-AG8-AH8 -> 9131.28 | AL8: 7384 | AM8: 6878 | AN8: =ROUND(AL8*16%,2) -> 1181.44 | AO8: =ROUND(AL8*9%,2) -> 664.56 | AP8: =ROUND(AL8*0.5%,2) -> 36.92 | AQ8: 14.77 | AS8: =ROUND(AM8*7%,0) -> 481 | AT8: =ROUND(IF(AL8<24366,AL8*1.5%,24366*1.5%),2) -> 110.76 | AU8: =SUM(AN8:AT8) -> 2489.45 | AV8: 195 | AW8: =AU8+Z8+AI8-AJ8+AV8 -> 13072.05 | AZ8: 255 | BA8: =ROUND(AW8+AZ8+AX8,2) -> 13327.05 | BB8: =ROUND(BA8*6%,2) -> 799.62 | BC8: =ROUND(SUM(BA8:BB8),2) -> 14126.67 | BD8: =AV8-5 -> 190
A9: =ROW()-2 -> 7 | B9: 2503 | C9: WB022825 | D9: 张晓薇 | E9: 310229199011210247 | F9: 45444 | G9: 45808 | I9: 上海 | J9: 1200 | K9: 3801.13 | L9: 2179.04 | P9: 200 | R9: 630 | X9: 0 | Y9: 0 | Z9: =SUM(J9:Y9) -> 8010.17 | AA9: 8131 | AB9: 650.48 | AC9: 162.62 | AD9: 40.66 | AE9: 8131 | AF9: =ROUND(AE9*7%,0) -> 569 | AG9: =AB9+AC9+AD9+AF9 -> 1422.76 | AK9: =Z9-AG9-AH9 -> 6587.41 | AL9: 8131 | AM9: 8131 | AN9: =ROUND(AL9*16%,2) -> 1300.96 | AO9: 731.8 | AP9: =ROUND(AL9*0.5%,2) -> 40.66 | AQ9: 16.26 | AS9: =ROUND(AM9*7%,0) -> 569 | AT9: =ROUND(IF(AL9<24366,AL9*1.5%,24366*1.5%),2) -> 121.97 | AU9: =SUM(AN9:AT9) -> 2780.65 | AV9: 148 | AW9: =AU9+Z9+AI9-AJ9+AV9 -> 10938.82 | AZ9: 255 | BA9: =ROUND(AW9+AZ9+AX9,2) -> 11193.82 | BB9: =ROUND(BA9*6%,2) -> 671.63 | BC9: =ROUND(SUM(BA9:BB9),2) -> 11865.45 | BD9: =AV9-5 -> 143
A10: =ROW()-2 -> 8 | B10: 2503 | C10: WB023998 | D10: 戴连荣 | E10: 310227198411292010 | F10: 45444 | G10: 45808 | I10: 上海 | J10: 1300 | K10: 4066 | L10: 3961.68 | P10: 200 | R10: 630 | X10: 0 | Y10: -200 | Z10: =SUM(J10:Y10) -> 9957.68 | AA10: 12760 | AB10: 1020.8 | AC10: 255.2 | AD10: 63.8 | AE10: 12760 | AF10: =ROUND(AE10*7%,0) -> 893 | AG10: =AB10+AC10+AD10+AF10 -> 2232.8 | AK10: =Z10-AG10-AH10 -> 7724.88 | AL10: 12760 | AM10: 12760 | AN10: =ROUND(AL10*16%,2) -> 2041.6 | AO10: =ROUND(AL10*9%,2) -> 1148.4 | AP10: =ROUND(AL10*0.5%,2) -> 63.8 | AQ10: 25.52 | AS10: =ROUND(AM10*7%,0) -> 893 | AT10: =ROUND(IF(AL10<24366,AL10*1.5%,24366*1.5%),2) -> 191.4 | AU10: =SUM(AN10:AT10) -> 4363.72 | AV10: 187 | AW10: =AU10+Z10+AI10-AJ10+AV10 -> 14508.4 | AZ10: 255 | BA10: =ROUND(AW10+AZ10+AX10,2) -> 14763.4 | BB10: =ROUND(BA10*6%,2) -> 885.8 | BC10: =ROUND(SUM(BA10:BB10),2) -> 15649.2 | BD10: =AV10-5 -> 182
A11: =ROW()-2 -> 9 | B11: 2503 | C11: WB025814 | D11: 陶叶丽 | E11: 310227198510132629 | F11: 45444 | G11: 45808 | I11: 上海 | J11: 1030 | K11: 1701.2 | L11: 1176.24 | P11: 200 | R11: 630 | X11: 0 | Y11: 0 | Z11: =SUM(J11:Y11) -> 4737.44 | AA11: 7384 | AB11: 590.72 | AC11: 147.68 | AD11: 36.92 | AE11: 4668 | AF11: =ROUND(AE11*7%,0) -> 327 | AG11: =AB11+AC11+AD11+AF11 -> 1102.32 | AK11: =Z11-AG11-AH11 -> 3635.12 | AL11: 7384 | AM11: 4668 | AN11: =ROUND(AL11*16%,2) -> 1181.44 | AO11: =ROUND(AL11*9%,2) -> 664.56 | AP11: =ROUND(AL11*0.5%,2) -> 36.92 | AQ11: 14.77 | AS11: =ROUND(AM11*7%,0) -> 327 | AT11: =ROUND(IF(AL11<24366,AL11*1.5%,24366*1.5%),2) -> 110.76 | AU11: =SUM(AN11:AT11) -> 2335.45 | AV11: 82 | AW11: =AU11+Z11+AI11-AJ11+AV11 -> 7154.89 | AZ11: 255 | BA11: =ROUND(AW11+AZ11+AX11,2) -> 7409.89 | BB11: =ROUND(BA11*6%,2) -> 444.59 | BC11: =ROUND(SUM(BA11:BB11),2) -> 7854.48 | BD11: =AV11-5 -> 77
A12: =ROW()-2 -> 10 | B12: 2503 | C12: WB047263 | D12: 李琴 | E12: 310227198708184424 | F12: 45689 | G12: 46053 | I12: 上海 | J12: 950 | K12: 7692 | L12: 1959.24 | P12: 200 | R12: 630 | X12: 0 | Y12: -200 | Z12: =SUM(J12:Y12) -> 11231.24 | AA12: 7384 | AB12: 590.72 | AC12: 147.68 | AD12: 36.92 | AE12: 5493 | AF12: 385 | AG12: =AB12+AC12+AD12+AF12 -> 1160.32 | AK12: =Z12-AG12-AH12 -> 10070.92 | AL12: 7384 | AM12: 5493 | AN12: 1181.44 | AO12: 664.56 | AP12: 36.92 | AQ12: 14.77 | AS12: 385 | AT12: 110.76 | AU12: =SUM(AN12:AT12) -> 2393.45 | AV12: 212 | AW12: =AU12+Z12+AI12-AJ12+AV12 -> 13836.69 | AZ12: 255 | BA12: =ROUND(AW12+AZ12+AX12,2) -> 14091.69 | BB12: =ROUND(BA12*6%,2) -> 845.5 | BC12: =ROUND(SUM(BA12:BB12),2) -> 14937.19 | BD12: =AV12-5 -> 207
A13: =ROW()-2 -> 11 | B13: 2503 | C13: WB035661 | D13: 常宇航 | E13: 340321199609230533 | F13: 45444 | G13: 45808 | I13: 上海 | J13: 1030 | K13: 1784.8 | L13: 1042 | P13: 200 | R13: 630 | X13: 78.52 | Y13: 0 | Z13: =SUM(J13:Y13) -> 4765.32 | AA13: 7384 | AB13: 590.72 | AC13: 147.68 | AD13: 36.92 | AE13: 6644 | AF13: =ROUND(AE13*7%,0) -> 465 | AG13: =AB13+AC13+AD13+AF13 -> 1240.32 | AK13: =Z13-AG13-AH13 -> 3525 | AL13: 7384 | AM13: 6644 | AN13: =ROUND(AL13*16%,2) -> 1181.44 | AO13: =ROUND(AL13*9%,2) -> 664.56 | AP13: =ROUND(AL13*0.5%,2) -> 36.92 | AQ13: 14.77 | AS13: =ROUND(AM13*7%,0) -> 465 | AT13: =ROUND(IF(AL13<24366,AL13*1.5%,24366*1.5%),2) -> 110.76 | AU13: =SUM(AN13:AT13) -> 2473.45 | AV13: 83 | AW13: =AU13+Z13+AI13-AJ13+AV13 -> 7321.77 | AZ13: 255 | BA13: =ROUND(AW13+AZ13+AX13,2) -> 7576.77 | BB13: =ROUND(BA13*6%,2) -> 454.61 | BC13: =ROUND(SUM(BA13:BB13),2) -> 8031.38 | BD13: =AV13-5 -> 78
A14: =ROW()-2 -> 12 | B14: 2503 | C14: WB038776 | D14: 陆晓岚 | E14: 310227199207211222 | F14: 45444 | G14: 45808 | I14: 上海 | J14: 950 | K14: 2713.6 | L14: 1777.2 | P14: 200 | R14: 630 | X14: 0 | Y14: 0 | Z14: =SUM(J14:Y14) -> 6270.8 | AA14: 7384 | AB14: 590.72 | AC14: 147.68 | AD14: 36.92 | AE14: 5300 | AF14: =ROUND(AE14*7%,0) -> 371 | AG14: =AB14+AC14+AD14+AF14 -> 1146.32 | AK14: =Z14-AG14-AH14 -> 5124.48 | AL14: 7384 | AM14: 5300 | AN14: =ROUND(AL14*16%,2) -> 1181.44 | AO14: =ROUND(AL14*9%,2) -> 664.56 | AP14: =ROUND(AL14*0.5%,2) -> 36.92 | AQ14: 14.77 | AS14: =ROUND(AM14*7%,0) -> 371 | AT14: =ROUND(IF(AL14<24366,AL14*1.5%,24366*1.5%),2) -> 110.76 | AU14: =SUM(AN14:AT14) -> 2379.45 | AV14: 113 | AW14: =AU14+Z14+AI14-AJ14+AV14 -> 8763.25 | AZ14: 255 | BA14: =ROUND(AW14+AZ14+AX14,2) -> 9018.25 | BB14: =ROUND(BA14*6%,2) -> 541.1 | BC14: =ROUND(SUM(BA14:BB14),2) -> 9559.35 | BD14: =AV14-5 -> 108
A15: =ROW()-2 -> 13 | B15: 2503 | C15: WB044812 | D15: 曹克洋 | E15: 341226199712081318 | F15: 45444 | G15: 45808 | I15: 上海 | J15: 1200 | K15: 1946.4 | L15: 1028.48 | P15: 200 | R15: 630 | X15: 0 | Y15: 0 | Z15: =SUM(J15:Y15) -> 5004.88 | AA15: 7384 | AB15: 590.72 | AC15: 147.68 | AD15: 36.92 | AE15: 5351 | AF15: =ROUND(AE15*7%,0) -> 375 | AG15: =AB15+AC15+AD15+AF15 -> 1150.32 | AK15: =Z15-AG15-AH15 -> 3854.56 | AL15: 7384 | AM15: 5351 | AN15: =ROUND(AL15*16%,2) -> 1181.44 | AO15: =ROUND(AL15*9%,2) -> 664.56 | AP15: =ROUND(AL15*0.5%,2) -> 36.92 | AQ15: 14.77 | AS15: =ROUND(AM15*7%,0) -> 375 | AT15: =ROUND(IF(AL15<24366,AL15*1.5%,24366*1.5%),2) -> 110.76 | AU15: =SUM(AN15:AT15) -> 2383.45 | AV15: 87 | AW15: =AU15+Z15+AI15-AJ15+AV15 -> 7475.33 | AZ15: 255 | BA15: =ROUND(AW15+AZ15+AX15,2) -> 7730.33 | BB15: =ROUND(BA15*6%,2) -> 463.82 | BC15: =ROUND(SUM(BA15:BB15),2) -> 8194.15 | BD15: =AV15-5 -> 82
A16: =ROW()-2 -> 14 | B16: 2503 | C16: WB045176 | D16: 张春花 | E16: 32062619761225622X | F16: 45444 | G16: 45808 | I16: 上海 | J16: 1030 | K16: 4089.2 | L16: 3036 | P16: 200 | R16: 630 | X16: 0 | Y16: 0 | Z16: =SUM(J16:Y16) -> 8985.2 | AA16: 12769 | AB16: 1021.52 | AC16: 255.38 | AD16: 63.85 | AE16: 12769 | AF16: =ROUND(AE16*7%,0) -> 894 | AG16: =AB16+AC16+AD16+AF16 -> 2234.75 | AK16: =Z16-AG16-AH16 -> 6750.45 | AL16: 12769 | AM16: 12769 | AN16: =ROUND(AL16*16%,2) -> 2043.04 | AO16: 1149.22 | AP16: =ROUND(AL16*0.5%,2) -> 63.85 | AQ16: 25.54 | AS16: =ROUND(AM16*7%,0) -> 894 | AT16: =ROUND(IF(AL16<24366,AL16*1.5%,24366*1.5%),2) -> 191.54 | AU16: =SUM(AN16:AT16) -> 4367.19 | AV16: 167 | AW16: =AU16+Z16+AI16-AJ16+AV16 -> 13519.39 | AZ16: 255 | BA16: =ROUND(AW16+AZ16+AX16,2) -> 13774.39 | BB16: =ROUND(BA16*6%,2) -> 826.46 | BC16: =ROUND(SUM(BA16:BB16),2) -> 14600.85 | BD16: =AV16-5 -> 162
A17: =ROW()-2 -> 15 | B17: 2503 | C17: WB045370 | D17: 陆智俊 | E17: 310227199807124616 | F17: 45444 | G17: 45808 | I17: 上海 | J17: 1030 | K17: 1874.58 | L17: 1053.76 | P17: 200 | R17: 630 | X17: 59.04 | Y17: 0 | Z17: =SUM(J17:Y17) -> 4847.38 | AA17: 7556 | AB17: 604.48 | AC17: 151.12 | AD17: 37.78 | AE17: 7556 | AF17: =ROUND(AE17*7%,0) -> 529 | AG17: =AB17+AC17+AD17+AF17 -> 1322.38 | AK17: =Z17-AG17-AH17 -> 3525 | AL17: 7556 | AM17: 7556 | AN17: =ROUND(AL17*16%,2) -> 1208.96 | AO17: =ROUND(AL17*9%,2) -> 680.04 | AP17: =ROUND(AL17*0.5%,2) -> 37.78 | AQ17: 15.11 | AS17: =ROUND(AM17*7%,0) -> 529 | AT17: =ROUND(IF(AL17<24366,AL17*1.5%,24366*1.5%),2) -> 113.34 | AU17: =SUM(AN17:AT17) -> 2584.23 | AV17: 84 | AW17: =AU17+Z17+AI17-AJ17+AV17 -> 7515.61 | AZ17: 255 | BA17: =ROUND(AW17+AZ17+AX17,2) -> 7770.61 | BB17: =ROUND(BA17*6%,2) -> 466.24 | BC17: =ROUND(SUM(BA17:BB17),2) -> 8236.85 | BD17: =AV17-5 -> 79
A18: =ROW()-2 -> 16 | B18: 2503 | C18: WB045583 | D18: 王春燕 | E18: 310227198405021222 | F18: 45444 | G18: 45808 | I18: 上海 | J18: 1030 | K18: 2587.15 | L18: 1537.6 | P18: 200 | R18: 630 | X18: 0 | Y18: -400 | Z18: =SUM(J18:Y18) -> 5584.75 | AA18: 7384 | AB18: 590.72 | AC18: 147.68 | AD18: 36.92 | AE18: 5176 | AF18: =ROUND(AE18*7%,0) -> 362 | AG18: =AB18+AC18+AD18+AF18 -> 1137.32 | AK18: =Z18-AG18-AH18 -> 4447.43 | AL18: 7384 | AM18: 5176 | AN18: =ROUND(AL18*16%,2) -> 1181.44 | AO18: =ROUND(AL18*9%,2) -> 664.56 | AP18: =ROUND(AL18*0.5%,2) -> 36.92 | AQ18: 14.77 | AS18: =ROUND(AM18*7%,0) -> 362 | AT18: =ROUND(IF(AL18<24366,AL18*1.5%,24366*1.5%),2) -> 110.76 | AU18: =SUM(AN18:AT18) -> 2370.45 | AV18: 99 | AW18: =AU18+Z18+AI18-AJ18+AV18 -> 8054.2 | AZ18: 255 | BA18: =ROUND(AW18+AZ18+AX18,2) -> 8309.2 | BB18: =ROUND(BA18*6%,2) -> 498.55 | BC18: =ROUND(SUM(BA18:BB18),2) -> 8807.75 | BD18: =AV18-5 -> 94
A19: =ROW()-2 -> 17 | B19: 2503 | C19: WB046624 | D19: 孔祥杰 | E19: 310110198408153236 | F19: 45444 | G19: 45808 | I19: 上海 | J19: 950 | K19: 2573.2 | L19: 1964 | P19: 200 | R19: 630 | X19: 0 | Y19: 0 | Z19: =SUM(J19:Y19) -> 6317.2 | AA19: 7384 | AB19: 590.72 | AC19: 147.68 | AD19: 36.92 | AE19: 7189 | AF19: =ROUND(AE19*7%,0) -> 503 | AG19: =AB19+AC19+AD19+AF19 -> 1278.32 | AK19: =Z19-AG19-AH19 -> 5038.88 | AL19: 7384 | AM19: 7189 | AN19: =ROUND(AL19*16%,2) -> 1181.44 | AO19: =ROUND(AL19*9%,2) -> 664.56 | AP19: =ROUND(AL19*0.5%,2) -> 36.92 | AQ19: 14.77 | AS19: =ROUND(AM19*7%,0) -> 503 | AT19: =ROUND(IF(AL19<24366,AL19*1.5%,24366*1.5%),2) -> 110.76 | AU19: =SUM(AN19:AT19) -> 2511.45 | AV19: 114 | AW19: =AU19+Z19+AI19-AJ19+AV19 -> 8942.65 | AZ19: 255 | BA19: =ROUND(AW19+AZ19+AX19,2) -> 9197.65 | BB19: =ROUND(BA19*6%,2) -> 551.86 | BC19: =ROUND(SUM(BA19:BB19),2) -> 9749.51 | BD19: =AV19-5 -> 109
A20: =ROW()-2 -> 18 | B20: 2503 | C20: WB047109 | D20: 谢桃丽 | E20: 530322199401231344 | F20: 45444 | G20: 45808 | I20: 上海 | J20: 1030 | K20: 3534.64 | L20: 2900.64 | P20: 200 | R20: 630 | X20: 0 | Y20: 0 | Z20: =SUM(J20:Y20) -> 8295.28 | AA20: 7384 | AB20: 590.72 | AC20: 147.68 | AD20: 36.92 | AE20: 5148 | AF20: =ROUND(AE20*7%,0) -> 360 | AG20: =AB20+AC20+AD20+AF20 -> 1135.32 | AK20: =Z20-AG20-AH20 -> 7159.96 | AL20: 7384 | AM20: 5148 | AN20: =ROUND(AL20*16%,2) -> 1181.44 | AO20: =ROUND(AL20*9%,2) -> 664.56 | AP20: =ROUND(AL20*0.5%,2) -> 36.92 | AQ20: 14.77 | AS20: =ROUND(AM20*7%,0) -> 360 | AT20: =ROUND(IF(AL20<24366,AL20*1.5%,24366*1.5%),2) -> 110.76 | AU20: =SUM(AN20:AT20) -> 2368.45 | AV20: 153 | AW20: =AU20+Z20+AI20-AJ20+AV20 -> 10816.73 | AZ20: 255 | BA20: =ROUND(AW20+AZ20+AX20,2) -> 11071.73 | BB20: =ROUND(BA20*6%,2) -> 664.3 | BC20: =ROUND(SUM(BA20:BB20),2) -> 11736.03 | BD20: =AV20-5 -> 148
A21: =ROW()-2 -> 19 | B21: 2503 | C21: WB049118 | D21: 顾诗瑶 | E21: 310227199812152021 | F21: 45444 | G21: 45808 | I21: 上海 | J21: 900 | K21: 50.4 | L21: 0 | P21: 0 | R21: 0 | X21: 2301.92 | Y21: 0 | Z21: =SUM(J21:Y21) -> 3252.32 | AA21: 7384 | AB21: 590.72 | AC21: 147.68 | AD21: 36.92 | AE21: 4570 | AF21: =ROUND(AE21*7%,0) -> 320 | AG21: =AB21+AC21+AD21+AF21 -> 1095.32 | AK21: =Z21-AG21-AH21 -> 2157 | AL21: 7384 | AM21: 4570 | AN21: =ROUND(AL21*16%,2) -> 1181.44 | AO21: =ROUND(AL21*9%,2) -> 664.56 | AP21: =ROUND(AL21*0.5%,2) -> 36.92 | AQ21: 14.77 | AS21: =ROUND(AM21*7%,0) -> 320 | AT21: =ROUND(IF(AL21<24366,AL21*1.5%,24366*1.5%),2) -> 110.76 | AU21: =SUM(AN21:AT21) -> 2328.45 | AV21: 65 | AW21: =AU21+Z21+AI21-AJ21+AV21 -> 5645.77 | AZ21: 255 | BA21: =ROUND(AW21+AZ21+AX21,2) -> 5900.77 | BB21: =ROUND(BA21*6%,2) -> 354.05 | BC21: =ROUND(SUM(BA21:BB21),2) -> 6254.82 | BD21: =AV21-5 -> 60
A22: =ROW()-2 -> 20 | B22: 2503 | C22: WB049498 | D22: 曾灿 | E22: 362322200010120626 | F22: 45444 | G22: 45808 | I22: 上海 | J22: 900 | K22: 856 | L22: 577.36 | P22: 200 | R22: 630 | X22: 1919.75 | Y22: -126 | Z22: =SUM(J22:Y22) -> 4957.11 | AA22: 8182 | AB22: 654.56 | AC22: 163.64 | AD22: 40.91 | AE22: 8182 | AF22: =ROUND(AE22*7%,0) -> 573 | AG22: =AB22+AC22+AD22+AF22 -> 1432.11 | AK22: =Z22-AG22-AH22 -> 3525 | AL22: 8182 | AM22: 8182 | AN22: =ROUND(AL22*16%,2) -> 1309.12 | AO22: =ROUND(AL22*9%,2) -> 736.38 | AP22: =ROUND(AL22*0.5%,2) -> 40.91 | AQ22: 16.36 | AS22: =ROUND(AM22*7%,0) -> 573 | AT22: =ROUND(IF(AL22<24366,AL22*1.5%,24366*1.5%),2) -> 122.73 | AU22: =SUM(AN22:AT22) -> 2798.5 | AV22: 87 | AW22: =AU22+Z22+AI22-AJ22+AV22 -> 7842.61 | AZ22: 255 | BA22: =ROUND(AW22+AZ22+AX22,2) -> 8097.61 | BB22: =ROUND(BA22*6%,2) -> 485.86 | BC22: =ROUND(SUM(BA22:BB22),2) -> 8583.47 | BD22: =AV22-5 -> 82
A23: =ROW()-2 -> 21 | B23: 2503 | C23: WB027831 | D23: 倪跃新 | E23: 310229197208182017 | F23: 45444 | G23: 45808 | I23: 上海 | J23: 950 | K23: 5288 | L23: 3165.68 | P23: 200 | R23: 630 | X23: 0 | Y23: 0 | Z23: =SUM(J23:Y23) -> 10233.68 | AA23: 7384 | AB23: 590.72 | AC23: 147.68 | AD23: 36.92 | AE23: 6353 | AF23: =ROUND(AE23*7%,0) -> 445 | AG23: =AB23+AC23+AD23+AF23 -> 1220.32 | AK23: =Z23-AG23-AH23 -> 9013.36 | AL23: 7384 | AM23: 6353 | AN23: =ROUND(AL23*16%,2) -> 1181.44 | AO23: =ROUND(AL23*9%,2) -> 664.56 | AP23: =ROUND(AL23*0.5%,2) -> 36.92 | AQ23: 14.77 | AS23: =ROUND(AM23*7%,0) -> 445 | AT23: =ROUND(IF(AL23<24366,AL23*1.5%,24366*1.5%),2) -> 110.76 | AU23: =SUM(AN23:AT23) -> 2453.45 | AV23: 192 | AW23: =AU23+Z23+AI23-AJ23+AV23 -> 12879.13 | AZ23: 255 | BA23: =ROUND(AW23+AZ23+AX23,2) -> 13134.13 | BB23: =ROUND(BA23*6%,2) -> 788.05 | BC23: =ROUND(SUM(BA23:BB23),2) -> 13922.18 | BD23: =AV23-5 -> 187
A24: =ROW()-2 -> 22 | B24: 2503 | C24: WB046625 | D24: 李秋梅 | E24: 320321198010030887 | F24: 45444 | G24: 45808 | I24: 上海 | J24: 1030 | K24: 1615.08 | L24: 1285.52 | P24: 200 | R24: 630 | X24: 31.72 | Y24: 0 | Z24: =SUM(J24:Y24) -> 4792.32 | AA24: 7384 | AB24: 590.72 | AC24: 147.68 | AD24: 36.92 | AE24: 7034 | AF24: =ROUND(AE24*7%,0) -> 492 | AG24: =AB24+AC24+AD24+AF24 -> 1267.32 | AK24: =Z24-AG24-AH24 -> 3525 | AL24: 7384 | AM24: 7034 | AN24: =ROUND(AL24*16%,2) -> 1181.44 | AO24: =ROUND(AL24*9%,2) -> 664.56 | AP24: =ROUND(AL24*0.5%,2) -> 36.92 | AQ24: 14.77 | AS24: =ROUND(AM24*7%,0) -> 492 | AT24: =ROUND(IF(AL24<24366,AL24*1.5%,24366*1.5%),2) -> 110.76 | AU24: =SUM(AN24:AT24) -> 2500.45 | AV24: 83 | AW24: =AU24+Z24+AI24-AJ24+AV24 -> 7375.77 | AZ24: 255 | BA24: =ROUND(AW24+AZ24+AX24,2) -> 7630.77 | BB24: =ROUND(BA24*6%,2) -> 457.85 | BC24: =ROUND(SUM(BA24:BB24),2) -> 8088.62 | BD24: =AV24-5 -> 78
A25: =ROW()-2 -> 23 | B25: 2503 | C25: WB037444 | D25: 高国强 | E25: 65010319750517061X | F25: 45444 | G25: 45808 | I25: 上海 | J25: 950 | K25: 1414.6 | L25: 1292.8 | P25: 200 | R25: 630 | X25: 154.92 | Y25: 0 | Z25: =SUM(J25:Y25) -> 4642.32 | AA25: 7384 | AB25: 590.72 | AC25: 147.68 | AD25: 36.92 | AE25: 4880 | AF25: =ROUND(AE25*7%,0) -> 342 | AG25: =AB25+AC25+AD25+AF25 -> 1117.32 | AK25: =Z25-AG25-AH25 -> 3525 | AL25: 7384 | AM25: 4880 | AN25: =ROUND(AL25*16%,2) -> 1181.44 | AO25: =ROUND(AL25*9%,2) -> 664.56 | AP25: =ROUND(AL25*0.5%,2) -> 36.92 | AQ25: 14.77 | AS25: =ROUND(AM25*7%,0) -> 342 | AT25: =ROUND(IF(AL25<24366,AL25*1.5%,24366*1.5%),2) -> 110.76 | AU25: =SUM(AN25:AT25) -> 2350.45 | AV25: 80 | AW25: =AU25+Z25+AI25-AJ25+AV25 -> 7072.77 | AZ25: 255 | BA25: =ROUND(AW25+AZ25+AX25,2) -> 7327.77 | BB25: =ROUND(BA25*6%,2) -> 439.67 | BC25: =ROUND(SUM(BA25:BB25),2) -> 7767.44 | BD25: =AV25-5 -> 75
A26: =ROW()-2 -> 24 | B26: 2503 | C26: WB046626 | D26: 姜金玲 | E26: 310227198902274028 | F26: 45444 | G26: 45808 | I26: 上海 | J26: 950 | K26: 1060.52 | L26: 288.48 | P26: 200 | R26: 630 | X26: 1484.32 | Y26: 0 | Z26: =SUM(J26:Y26) -> 4613.32 | AA26: 7384 | AB26: 590.72 | AC26: 147.68 | AD26: 36.92 | AE26: 4467 | AF26: =ROUND(AE26*7%,0) -> 313 | AG26: =AB26+AC26+AD26+AF26 -> 1088.32 | AK26: =Z26-AG26-AH26 -> 3525 | AL26: 7384 | AM26: 4467 | AN26: =ROUND(AL26*16%,2) -> 1181.44 | AO26: =ROUND(AL26*9%,2) -> 664.56 | AP26: =ROUND(AL26*0.5%,2) -> 36.92 | AQ26: 14.77 | AS26: =ROUND(AM26*7%,0) -> 313 | AT26: =ROUND(IF(AL26<24366,AL26*1.5%,24366*1.5%),2) -> 110.76 | AU26: =SUM(AN26:AT26) -> 2321.45 | AV26: 80 | AW26: =AU26+Z26+AI26-AJ26+AV26 -> 7014.77 | AZ26: 255 | BA26: =ROUND(AW26+AZ26+AX26,2) -> 7269.77 | BB26: =ROUND(BA26*6%,2) -> 436.19 | BC26: =ROUND(SUM(BA26:BB26),2) -> 7705.96 | BD26: =AV26-5 -> 75
A27: =ROW()-2 -> 25 | B27: 2503 | C27: WB037461 | D27: 牟金丽 | E27: 422802198502180068 | F27: 45444 | G27: 45808 | I27: 上海 | J27: 950 | K27: 1268.86 | L27: 768.48 | P27: 200 | R27: 630 | X27: 796.98 | Y27: 0 | Z27: =SUM(J27:Y27) -> 4614.32 | AA27: 7384 | AB27: 590.72 | AC27: 147.68 | AD27: 36.92 | AE27: 4492 | AF27: =ROUND(AE27*7%,0) -> 314 | AG27: =AB27+AC27+AD27+AF27 -> 1089.32 | AK27: =Z27-AG27-AH27 -> 3525 | AL27: 7384 | AM27: 4492 | AN27: =ROUND(AL27*16%,2) -> 1181.44 | AO27: =ROUND(AL27*9%,2) -> 664.56 | AP27: =ROUND(AL27*0.5%,2) -> 36.92 | AQ27: 14.77 | AS27: =ROUND(AM27*7%,0) -> 314 | AT27: =ROUND(IF(AL27<24366,AL27*1.5%,24366*1.5%),2) -> 110.76 | AU27: =SUM(AN27:AT27) -> 2322.45 | AV27: 80 | AW27: =AU27+Z27+AI27-AJ27+AV27 -> 7016.77 | AZ27: 255 | BA27: =ROUND(AW27+AZ27+AX27,2) -> 7271.77 | BB27: =ROUND(BA27*6%,2) -> 436.31 | BC27: =ROUND(SUM(BA27:BB27),2) -> 7708.08 | BD27: =AV27-5 -> 75
A28: =ROW()-2 -> 26 | B28: 2503 | C28: WB047234 | D28: 高峰 | E28: 342501197909046816 | F28: 45444 | G28: 45808 | I28: 上海 | J28: 1030 | K28: 8802 | L28: 3384.68 | P28: 200 | R28: 630 | X28: 0 | Y28: -120 | Z28: =SUM(J28:Y28) -> 13926.68 | AA28: 13877 | AB28: 1110.16 | AC28: 277.54 | AD28: 69.39 | AE28: 13877 | AF28: =ROUND(AE28*7%,0) -> 971 | AG28: =AB28+AC28+AD28+AF28 -> 2428.09 | AK28: =Z28-AG28-AH28 -> 11498.59 | AL28: 13877 | AM28: 13877 | AN28: =ROUND(AL28*16%,2) -> 2220.32 | AO28: 1248.94 | AP28: =ROUND(AL28*0.5%,2) -> 69.39 | AQ28: 27.75 | AS28: =ROUND(AM28*7%,0) -> 971 | AT28: =ROUND(IF(AL28<24366,AL28*1.5%,24366*1.5%),2) -> 208.16 | AU28: =SUM(AN28:AT28) -> 4745.56 | AV28: 266 | AW28: =AU28+Z28+AI28-AJ28+AV28 -> 18938.24 | AZ28: 255 | BA28: =ROUND(AW28+AZ28+AX28,2) -> 19193.24 | BB28: =ROUND(BA28*6%,2) -> 1151.59 | BC28: =ROUND(SUM(BA28:BB28),2) -> 20344.83 | BD28: =AV28-5 -> 261
A29: =ROW()-2 -> 27 | B29: 2503 | C29: WB043358 | D29: 李龙燕 | E29: 320681199310316032 | F29: 45444 | G29: 45808 | I29: 上海 | J29: 950 | K29: 7821.92 | L29: 2685.44 | P29: 200 | R29: 630 | X29: 0 | Y29: -210 | Z29: =SUM(J29:Y29) -> 12077.36 | AA29: 8878 | AB29: 710.24 | AC29: 177.56 | AD29: 44.39 | AE29: 8878 | AF29: =ROUND(AE29*7%,0) -> 621 | AG29: =AB29+AC29+AD29+AF29 -> 1553.19 | AK29: =Z29-AG29-AH29 -> 10524.17 | AL29: 8878 | AM29: 8878 | AN29: =ROUND(AL29*16%,2) -> 1420.48 | AO29: =ROUND(AL29*9%,2) -> 799.02 | AP29: =ROUND(AL29*0.5%,2) -> 44.39 | AQ29: 17.76 | AS29: =ROUND(AM29*7%,0) -> 621 | AT29: =ROUND(IF(AL29<24366,AL29*1.5%,24366*1.5%),2) -> 133.17 | AU29: =SUM(AN29:AT29) -> 3035.82 | AV29: 229 | AW29: =AU29+Z29+AI29-AJ29+AV29 -> 15342.18 | AZ29: 255 | BA29: =ROUND(AW29+AZ29+AX29,2) -> 15597.18 | BB29: =ROUND(BA29*6%,2) -> 935.83 | BC29: =ROUND(SUM(BA29:BB29),2) -> 16533.01 | BD29: =AV29-5 -> 224
A30: =ROW()-2 -> 28 | B30: 2503 | C30: WB027701 | D30: 蒋萍萍 | E30: 310227199108114021 | F30: 45444 | G30: 45808 | I30: 上海 | J30: 950 | K30: 7742 | L30: 2208.56 | P30: 200 | R30: 630 | X30: 0 | Y30: 0 | Z30: =SUM(J30:Y30) -> 11730.56 | AA30: 8677 | AB30: 694.16 | AC30: 173.54 | AD30: 43.39 | AE30: 8677 | AF30: =ROUND(AE30*7%,0) -> 607 | AG30: =AB30+AC30+AD30+AF30 -> 1518.09 | AK30: =Z30-AG30-AH30 -> 10212.47 | AL30: 8677 | AM30: 8677 | AN30: =ROUND(AL30*16%,2) -> 1388.32 | AO30: 780.94 | AP30: =ROUND(AL30*0.5%,2) -> 43.39 | AQ30: 17.35 | AS30: =ROUND(AM30*7%,0) -> 607 | AT30: =ROUND(IF(AL30<24366,AL30*1.5%,24366*1.5%),2) -> 130.16 | AU30: =SUM(AN30:AT30) -> 2967.16 | AV30: 222 | AW30: =AU30+Z30+AI30-AJ30+AV30 -> 14919.72 | AZ30: 255 | BA30: =ROUND(AW30+AZ30+AX30,2) -> 15174.72 | BB30: =ROUND(BA30*6%,2) -> 910.48 | BC30: =ROUND(SUM(BA30:BB30),2) -> 16085.2 | BD30: =AV30-5 -> 217
A31: =ROW()-2 -> 29 | B31: 2503 | C31: WB041723 | D31: 封春燕 | E31: 310227198610224213 | F31: 45444 | G31: 45808 | I31: 上海 | J31: 950 | K31: 10204 | L31: 2167.52 | P31: 200 | R31: 630 | X31: 0 | Y31: 0 | Z31: =SUM(J31:Y31) -> 14151.52 | AA31: 7384 | AB31: 590.72 | AC31: 147.68 | AD31: 36.92 | AE31: 5109 | AF31: =ROUND(AE31*7%,0) -> 358 | AG31: =AB31+AC31+AD31+AF31 -> 1133.32 | AK31: =Z31-AG31-AH31 -> 13018.2 | AL31: 7384 | AM31: 5109 | AN31: =ROUND(AL31*16%,2) -> 1181.44 | AO31: =ROUND(AL31*9%,2) -> 664.56 | AP31: =ROUND(AL31*0.5%,2) -> 36.92 | AQ31: 14.77 | AS31: =ROUND(AM31*7%,0) -> 358 | AT31: =ROUND(IF(AL31<24366,AL31*1.5%,24366*1.5%),2) -> 110.76 | AU31: =SUM(AN31:AT31) -> 2366.45 | AV31: 270 | AW31: =AU31+Z31+AI31-AJ31+AV31 -> 16787.97 | AZ31: 255 | BA31: =ROUND(AW31+AZ31+AX31,2) -> 17042.97 | BB31: =ROUND(BA31*6%,2) -> 1022.58 | BC31: =ROUND(SUM(BA31:BB31),2) -> 18065.55 | BD31: =AV31-5 -> 265
A32: =ROW()-2 -> 30 | B32: 2503 | C32: WB051748 | D32: 姚臻敏 | E32: 310227198009300019 | F32: 45444 | G32: 45808 | I32: 上海 | J32: 800 | K32: 642.03 | L32: 953.76 | P32: 200 | R32: 630 | X32: 1454.53 | Y32: 0 | Z32: =SUM(J32:Y32) -> 4680.32 | AA32: 7384 | AB32: 590.72 | AC32: 147.68 | AD32: 36.92 | AE32: 5432 | AF32: =ROUND(AE32*7%,0) -> 380 | AG32: =AB32+AC32+AD32+AF32 -> 1155.32 | AK32: =Z32-AG32-AH32 -> 3525 | AL32: 7384 | AM32: 5432 | AN32: =ROUND(AL32*16%,2) -> 1181.44 | AO32: =ROUND(AL32*9%,2) -> 664.56 | AP32: =ROUND(AL32*0.5%,2) -> 36.92 | AQ32: 14.77 | AS32: =ROUND(AM32*7%,0) -> 380 | AT32: =ROUND(IF(AL32<24366,AL32*1.5%,24366*1.5%),2) -> 110.76 | AU32: =SUM(AN32:AT32) -> 2388.45 | AV32: 81 | AW32: =AU32+Z32+AI32-AJ32+AV32 -> 7149.77 | AZ32: 255 | BA32: =ROUND(AW32+AZ32+AX32,2) -> 7404.77 | BB32: =ROUND(BA32*6%,2) -> 444.29 | BC32: =ROUND(SUM(BA32:BB32),2) -> 7849.06 | BD32: =AV32-5 -> 76
A33: =ROW()-2 -> 31 | B33: 2503 | C33: WB049347 | D33: 王紫怡 | E33: 331082199904274040 | F33: 45444 | G33: 45808 | I33: 上海 | J33: 900 | K33: 2439 | L33: 1326.8 | P33: 200 | R33: 630 | X33: 0 | Y33: 0 | Z33: =SUM(J33:Y33) -> 5495.8 | AA33: 7606 | AB33: 608.48 | AC33: 152.12 | AD33: 38.03 | AE33: 7606 | AF33: =ROUND(AE33*7%,0) -> 532 | AG33: =AB33+AC33+AD33+AF33 -> 1330.63 | AK33: =Z33-AG33-AH33 -> 4165.17 | AL33: 7606 | AM33: 7606 | AN33: =ROUND(AL33*16%,2) -> 1216.96 | AO33: =ROUND(AL33*9%,2) -> 684.54 | AP33: =ROUND(AL33*0.5%,2) -> 38.03 | AQ33: 15.21 | AS33: =ROUND(AM33*7%,0) -> 532 | AT33: =ROUND(IF(AL33<24366,AL33*1.5%,24366*1.5%),2) -> 114.09 | AU33: =SUM(AN33:AT33) -> 2600.83 | AV33: 97 | AW33: =AU33+Z33+AI33-AJ33+AV33 -> 8193.63 | AZ33: 255 | BA33: =ROUND(AW33+AZ33+AX33,2) -> 8448.63 | BB33: =ROUND(BA33*6%,2) -> 506.92 | BC33: =ROUND(SUM(BA33:BB33),2) -> 8955.55 | BD33: =AV33-5 -> 92
A34: =ROW()-2 -> 32 | B34: 2503 | C34: WB034583 | D34: 沈婕妤 | E34: 310230198011070660 | F34: 45444 | G34: 45808 | I34: 上海 | J34: 1030 | K34: 8234 | L34: 1484.48 | P34: 200 | R34: 630 | X34: 0 | Y34: -30 | Z34: =SUM(J34:Y34) -> 11548.48 | AA34: 7384 | AB34: 590.72 | AC34: 147.68 | AD34: 36.92 | AE34: 5402 | AF34: =ROUND(AE34*7%,0) -> 378 | AG34: =AB34+AC34+AD34+AF34 -> 1153.32 | AK34: =Z34-AG34-AH34 -> 10395.16 | AL34: 7384 | AM34: 5402 | AN34: =ROUND(AL34*16%,2) -> 1181.44 | AO34: =ROUND(AL34*9%,2) -> 664.56 | AP34: =ROUND(AL34*0.5%,2) -> 36.92 | AQ34: 14.77 | AS34: =ROUND(AM34*7%,0) -> 378 | AT34: =ROUND(IF(AL34<24366,AL34*1.5%,24366*1.5%),2) -> 110.76 | AU34: =SUM(AN34:AT34) -> 2386.45 | AV34: 218 | AW34: =AU34+Z34+AI34-AJ34+AV34 -> 14152.93 | AZ34: 255 | BA34: =ROUND(AW34+AZ34+AX34,2) -> 14407.93 | BB34: =ROUND(BA34*6%,2) -> 864.48 | BC34: =ROUND(SUM(BA34:BB34),2) -> 15272.41 | BD34: =AV34-5 -> 213
A35: =ROW()-2 -> 33 | B35: 2503 | C35: WB026293 | D35: 曹雪晨 | E35: 310227199101043419 | F35: 45444 | G35: 45808 | I35: 上海 | J35: 1030 | K35: 10391.92 | L35: 3022.96 | P35: 200 | R35: 630 | X35: 0 | Y35: -200 | Z35: =SUM(J35:Y35) -> 15074.88 | AA35: 10751 | AB35: 860.08 | AC35: 215.02 | AD35: 53.76 | AE35: 10751 | AF35: =ROUND(AE35*7%,0) -> 753 | AG35: =AB35+AC35+AD35+AF35 -> 1881.86 | AK35: =Z35-AG35-AH35 -> 13193.02 | AL35: 10751 | AM35: 10751 | AN35: =ROUND(AL35*16%,2) -> 1720.16 | AO35: 967.6 | AP35: =ROUND(AL35*0.5%,2) -> 53.76 | AQ35: 21.5 | AS35: =ROUND(AM35*7%,0) -> 753 | AT35: =ROUND(IF(AL35<24366,AL35*1.5%,24366*1.5%),2) -> 161.27 | AU35: =SUM(AN35:AT35) -> 3677.29 | AV35: 289 | AW35: =AU35+Z35+AI35-AJ35+AV35 -> 19041.17 | AZ35: 255 | BA35: =ROUND(AW35+AZ35+AX35,2) -> 19296.17 | BB35: =ROUND(BA35*6%,2) -> 1157.77 | BC35: =ROUND(SUM(BA35:BB35),2) -> 20453.94 | BD35: =AV35-5 -> 284
A36: =ROW()-2 -> 34 | B36: 2503 | C36: WB046608 | D36: 邹莉 | E36: 511126198605207327 | F36: 45444 | G36: 45808 | I36: 上海 | J36: 1030 | K36: 7649.92 | L36: 1022 | P36: 200 | R36: 630 | X36: 0 | Y36: 0 | Z36: =SUM(J36:Y36) -> 10531.92 | AA36: 7384 | AB36: 590.72 | AC36: 147.68 | AD36: 36.92 | AE36: 4849 | AF36: =ROUND(AE36*7%,0) -> 339 | AG36: =AB36+AC36+AD36+AF36 -> 1114.32 | AK36: =Z36-AG36-AH36 -> 9417.6 | AL36: 7384 | AM36: 4849 | AN36: =ROUND(AL36*16%,2) -> 1181.44 | AO36: =ROUND(AL36*9%,2) -> 664.56 | AP36: =ROUND(AL36*0.5%,2) -> 36.92 | AQ36: 14.77 | AS36: =ROUND(AM36*7%,0) -> 339 | AT36: =ROUND(IF(AL36<24366,AL36*1.5%,24366*1.5%),2) -> 110.76 | AU36: =SUM(AN36:AT36) -> 2347.45 | AV36: 198 | AW36: =AU36+Z36+AI36-AJ36+AV36 -> 13077.37 | AZ36: 255 | BA36: =ROUND(AW36+AZ36+AX36,2) -> 13332.37 | BB36: =ROUND(BA36*6%,2) -> 799.94 | BC36: =ROUND(SUM(BA36:BB36),2) -> 14132.31 | BD36: =AV36-5 -> 193
A37: =ROW()-2 -> 35 | B37: 2503 | C37: WB005376 | D37: 吴萍萍 | E37: 310227198801103668 | F37: 45444 | G37: 45808 | I37: 上海 | J37: 1510 | K37: 1873.44 | L37: 1793.6 | P37: 200 | R37: 630 | X37: 0 | Y37: 0 | Z37: =SUM(J37:Y37) -> 6007.04 | AA37: 12662 | AB37: 1012.96 | AC37: 253.24 | AD37: 63.31 | AE37: 12662 | AF37: =ROUND(AE37*7%,0) -> 886 | AG37: =AB37+AC37+AD37+AF37 -> 2215.51 | AK37: =Z37-AG37-AH37 -> 3791.53 | AL37: 12662 | AM37: 12662 | AN37: =ROUND(AL37*16%,2) -> 2025.92 | AO37: =ROUND(AL37*9%,2) -> 1139.58 | AP37: =ROUND(AL37*0.5%,2) -> 63.31 | AQ37: 25.32 | AS37: =ROUND(AM37*7%,0) -> 886 | AT37: =ROUND(IF(AL37<24366,AL37*1.5%,24366*1.5%),2) -> 189.93 | AU37: =SUM(AN37:AT37) -> 4330.06 | AV37: 108 | AW37: =AU37+Z37+AI37-AJ37+AV37 -> 10445.1 | AZ37: 255 | BA37: =ROUND(AW37+AZ37+AX37,2) -> 10700.1 | BB37: =ROUND(BA37*6%,2) -> 642.01 | BC37: =ROUND(SUM(BA37:BB37),2) -> 11342.11 | BD37: =AV37-5 -> 103
A38: =ROW()-2 -> 36 | B38: 2503 | C38: WB030495 | D38: 马一伟 | E38: 310110198101160036 | F38: 45444 | G38: 45808 | I38: 上海 | J38: 1200 | K38: 1873.6 | L38: 1306.8 | P38: 200 | R38: 630 | X38: 0 | Y38: 0 | Z38: =SUM(J38:Y38) -> 5210.4 | AA38: 7384 | AB38: 590.72 | AC38: 147.68 | AD38: 36.92 | AE38: 2690 | AF38: =ROUND(AE38*7%,0) -> 188 | AG38: =AB38+AC38+AD38+AF38 -> 963.32 | AK38: =Z38-AG38-AH38 -> 4247.08 | AL38: 7384 | AM38: 2690 | AN38: =ROUND(AL38*16%,2) -> 1181.44 | AO38: =ROUND(AL38*9%,2) -> 664.56 | AP38: =ROUND(AL38*0.5%,2) -> 36.92 | AQ38: 14.77 | AS38: =ROUND(AM38*7%,0) -> 188 | AT38: =ROUND(IF(AL38<24366,AL38*1.5%,24366*1.5%),2) -> 110.76 | AU38: =SUM(AN38:AT38) -> 2196.45 | AV38: 92 | AW38: =AU38+Z38+AI38-AJ38+AV38 -> 7498.85 | AZ38: 255 | BA38: =ROUND(AW38+AZ38+AX38,2) -> 7753.85 | BB38: =ROUND(BA38*6%,2) -> 465.23 | BC38: =ROUND(SUM(BA38:BB38),2) -> 8219.08 | BD38: =AV38-5 -> 87
A39: =ROW()-2 -> 37 | B39: 2503 | C39: WB038316 | D39: 王乐意 | E39: 310227199806014028 | F39: 45444 | G39: 45808 | I39: 上海 | J39: 950 | K39: 668.96 | L39: 298.3 | P39: 200 | R39: 630 | X39: 2133.06 | Y39: -222 | Z39: =SUM(J39:Y39) -> 4658.32 | AA39: 7384 | AB39: 590.72 | AC39: 147.68 | AD39: 36.92 | AE39: 5121 | AF39: =ROUND(AE39*7%,0) -> 358 | AG39: =AB39+AC39+AD39+AF39 -> 1133.32 | AK39: =Z39-AG39-AH39 -> 3525 | AL39: 7384 | AM39: 5121 | AN39: =ROUND(AL39*16%,2) -> 1181.44 | AO39: =ROUND(AL39*9%,2) -> 664.56 | AP39: =ROUND(AL39*0.5%,2) -> 36.92 | AQ39: 14.77 | AS39: =ROUND(AM39*7%,0) -> 358 | AT39: =ROUND(IF(AL39<24366,AL39*1.5%,24366*1.5%),2) -> 110.76 | AU39: =SUM(AN39:AT39) -> 2366.45 | AV39: 81 | AW39: =AU39+Z39+AI39-AJ39+AV39 -> 7105.77 | AZ39: 255 | BA39: =ROUND(AW39+AZ39+AX39,2) -> 7360.77 | BB39: =ROUND(BA39*6%,2) -> 441.65 | BC39: =ROUND(SUM(BA39:BB39),2) -> 7802.42 | BD39: =AV39-5 -> 76
A40: =ROW()-2 -> 38 | B40: 2503 | C40: WB035781 | D40: 潘奇伟 | E40: 310227199011142819 | F40: 45474 | G40: 45838 | I40: 上海 | J40: 950 | K40: 1255.81 | L40: 804.96 | P40: 200 | R40: 630 | X40: 647.55 | Y40: 0 | Z40: =SUM(J40:Y40) -> 4488.32 | AA40: 7384 | AB40: 590.72 | AC40: 147.68 | AD40: 36.92 | AE40: 2690 | AF40: =ROUND(AE40*7%,0) -> 188 | AG40: =AB40+AC40+AD40+AF40 -> 963.32 | AK40: =Z40-AG40-AH40 -> 3525 | AL40: 7384 | AM40: 2690 | AN40: =ROUND(AL40*16%,2) -> 1181.44 | AO40: =ROUND(AL40*9%,2) -> 664.56 | AP40: =ROUND(AL40*0.5%,2) -> 36.92 | AQ40: 14.77 | AS40: =ROUND(AM40*7%,0) -> 188 | AT40: =ROUND(IF(AL40<24366,AL40*1.5%,24366*1.5%),2) -> 110.76 | AU40: =SUM(AN40:AT40) -> 2196.45 | AV40: 77 | AW40: =AU40+Z40+AI40-AJ40+AV40 -> 6761.77 | AZ40: 255 | BA40: =ROUND(AW40+AZ40+AX40,2) -> 7016.77 | BB40: =ROUND(BA40*6%,2) -> 421.01 | BC40: =ROUND(SUM(BA40:BB40),2) -> 7437.78 | BD40: =AV40-5 -> 72
...

Sheet 对账单
A1: 科目 | B1: 手工账单 | C1: 速创账单 | D1: 155 | E1: 预收一次性 | F1: 2月工会费 | G1: 本月垫付，下月收 | H1: 本月多收，下月退 | I1: 合计 | J1: 差异
A2: 管理费 | B2: ='202503'!BB44 -> 25995.76 | C2: =系统!E57 -> 29268.16 | D2: =40*155 -> 6200 | I2: =SUM(C2:G2) -> 35468.16 | J2: =B2-C2 -> -3272.4
A3: 风险费 | B3: ='202503'!AZ44 -> 10200 | C3: 0 | I3: =SUM(C3:G3) -> 0 | J3: =B3-C3 -> 10200
A4: 个人四金 | B4: ='202503'!AG44 -> 51887.71 | C4: =系统!V57 -> 51887.71 | I4: =SUM(C4:G4) -> 51887.71 | J4: =B4-C4 -> 0
A5: 公司四金 | B5: ='202503'!AU44 -> 106462.92 | C5: =系统!O57 -> 106462.92 | I5: =SUM(C5:E5) -> 106462.92 | J5: =B5-C5 -> 0
A6: 工伤退费 | I6: =SUM(C6:G6) -> 0 | J6: =B6-C6 -> 0
A7: 代发工资 | B7: ='202503'!Z44-'202503'!AG44 -> 258983.43 | C7: =系统!W57 -> 258783.43 | D7: =5*40 -> 200 | I7: =SUM(C7:G7) -> 258983.43 | J7: =B7-C7 -> 200
A8: 本月垫付 | I8: =SUM(C8:G8) -> 0 | J8: =B8-C8 -> 0
A9: 工会费 | B9: ='202503'!AV44 -> 5728 | D9: =B10 -> 0 | F9: =B9 -> 5728 | I9: =SUM(C9:G9) -> 5728 | J9: =B9-C9 -> 5728
A10: 上月多收 | I10: =SUM(C10:G10) -> 0 | J10: =B10-C10 -> 0
A11: 小计 | B11: =SUM(B2:B10) -> 459257.82 | C11: =SUM(C2:C10) -> 446402.22 | D11: =SUM(D2:D10) -> 6400 | E11: =E5 -> 0 | F11: =F9 -> 5728 | G11: =G9 -> 0 | H11: =H9 -> 0 | I11: =SUM(C11:G11) -> 458530.22
A12: 附加税
A13: 增值税 | D13: =ROUND((D11+D12)*6%,2) -> 384 | F13: =ROUND((F11+F12)*6%,2) -> 343.68 | G13: =ROUND((G11+G12)*6%,2) -> 0 | H13: =ROUND((H11+H12)*6%,2) -> 0 | I13: =SUM(C13:G13) -> 727.68
A14: 总计 | B14: =SUM(B11:B13) -> 459257.82 | C14: =SUM(C11:C13) -> 446402.22 | D14: =SUM(D11:D13) -> 6784 | E14: =E11 -> 0 | F14: =SUM(F11:F13) -> 6071.68 | G14: =SUM(G11:G13) -> 0 | H14: =SUM(H11:H13) -> 0 | I14: =SUM(C14:H14) -> 459257.9
A15: 给客户账单金额 | I15: =B14 -> 459257.82
A16: 差异 | I16: =I15-I14 -> -0.08
A17: 不含税差异 | I17: =ROUND(I16/1.06,2) -> -0.08

Sheet 系统
A1: 200070
A2: 寄：梅园路77号人才大厦
B3: 中国电信股份有限公司上海分公司 王慧珏 收
D6: 上海外服布列吉科技有限公司
C7: Shanghai Foreign Service Bridge Technology Co,Ltd.
E9: 收款通知书
E10: ADVISE ON COLLECTION
E11: 2025年03月
A13: 公司名称：中国电信股份有限公司上海分公司 | J13: 帐单号：202503CH6565005
A14: 序号 | B14: 姓名 | C14: 发生年月 | D14: 入职日期 | E14: 管理费 | F14: 当月社保基数 | G14: 当月公积金基数 | H14: 社保类 公司支付 Social Insurance Premiums Paid by Employer | N14: 公积金类 公司支付 Provident Fund Paid by Employer | O14: 公司合计 | P14: 社保类 个人支付 Social Insurance Premiums Paid by Employee | U14: 公积金类 个人支付 Provident Fund Paid by Employee | V14: 个人合计 | W14: 代办薪酬 | X14: 其他 | Y14: 总计 | Z14: 备注 | AA14: 外服工号 | AB14: 证件号码 | AC14: 内部工号 | AD14: 应纳税金额 | AE14: 税率 | AF14: 增值税
A15: S/N | B15: Name | C15: YYYYMM | D15: Employment Start Date | E15: Adm Fee | F15: Social Insurance Base Amount of Current Month | G15: Provident Fund Base Amount of Current Month | H15: 养老保险 Endowment | I15: 医疗保险 Medical | J15: 失业保险 Unemploy-ment | K15: 工伤保险 Employment Injury | L15: 医疗生育保险 Medical Maternity | M15: 保障金 Disabled people&Back pay Fund | N15: 公积金 Provident Fund | O15: Subtotal of Employer Payment | P15: 养老保险 Endowment | Q15: 医疗保险 Medical | R15: 失业保险 Unemploy-ment | S15: 工伤保险 Employment Injury | T15: 医疗生育保险 Medical Maternity | U15: 公积金 Provident Fund | V15: Subtotal of Personal Payment | W15: Agency of Wage Payment | X15: Others | Y15: Total | Z15: Remarks | AA15: SFSC ID | AB15: ID Card | AC15: Internal ID | AD15: Taxable Amount | AE15: Tax Rate | AF15: VAT
A16: 1 | B16: 曹克洋 | C16: 202503 | D16: 2024-06-01 | E16: 549 | F16: 7384 | G16: 5351 | H16: 1181.44 | I16: 664.56 | J16: 36.92 | K16: 14.77 | M16: 110.76 | N16: 375 | O16: =SUM(H16:N16) -> 2383.45 | P16: 590.72 | Q16: 147.68 | R16: 36.92 | U16: 375 | V16: =SUM(P16:U16) -> 1150.32 | W16: 3849.56 | Y16: =SUM(E16,O16,V16:X16) -> 7932.33 | AA16: 5545179 | AB16: 341226199712081318 | AD16: 7483.32 | AE16: 6% | AF16: 449.01
A17: 2 | B17: 曹雪晨 | C17: 202503 | D17: 2024-06-01 | E17: 1230.83 | F17: 10751 | G17: 10751 | H17: 1720.16 | I17: 967.6 | J17: 53.76 | K17: 21.5 | M17: 161.27 | N17: 753 | O17: =SUM(H17:N17) -> 3677.29 | P17: 860.08 | Q17: 215.02 | R17: 53.76 | U17: 753 | V17: =SUM(P17:U17) -> 1881.86 | W17: 13188.02 | Y17: =SUM(E17,O17,V17:X17) -> 19978 | AA17: 5573404 | AB17: 310227199101043419 | AD17: 18847.16 | AE17: 6% | AF17: 1130.84
A18: 3 | B18: 常宇航 | C18: 202503 | D18: 2024-06-01 | E18: 540.03 | F18: 7384 | G18: 6644 | H18: 1181.44 | I18: 664.56 | J18: 36.92 | K18: 14.77 | M18: 110.76 | N18: 465 | O18: =SUM(H18:N18) -> 2473.45 | P18: 590.72 | Q18: 147.68 | R18: 36.92 | U18: 465 | V18: =SUM(P18:U18) -> 1240.32 | W18: 3520 | Y18: =SUM(E18,O18,V18:X18) -> 7773.8 | AA18: 5545178 | AB18: 340321199609230533 | AD18: 7333.76 | AE18: 6% | AF18: 440.04
A19: 4 | B19: 陈喆昕 | C19: 202503 | D19: 2024-07-01 | E19: 615.87 | F19: 7384 | G19: 2690 | H19: 1181.44 | I19: 664.56 | J19: 36.92 | K19: 14.77 | M19: 110.76 | N19: 188 | O19: =SUM(H19:N19) -> 2196.45 | P19: 590.72 | Q19: 147.68 | R19: 36.92 | U19: 188 | V19: =SUM(P19:U19) -> 963.32 | W19: 5338.08 | Y19: =SUM(E19,O19,V19:X19) -> 9113.72 | AA19: 6063573 | AB19: 310227198312160012 | AD19: 8597.84 | AE19: 6% | AF19: 515.88
A20: 5 | B20: 戴连荣 | C20: 202503 | D20: 2024-06-01 | E20: 964.98 | F20: 12760 | G20: 12760 | H20: 2041.6 | I20: 1148.4 | J20: 63.8 | K20: 25.52 | M20: 191.4 | N20: 893 | O20: =SUM(H20:N20) -> 4363.72 | P20: 1020.8 | Q20: 255.2 | R20: 63.8 | U20: 893 | V20: =SUM(P20:U20) -> 2232.8 | W20: 7719.88 | Y20: =SUM(E20,O20,V20:X20) -> 15281.38 | AA20: 5517492 | AB20: 310227198411292010 | AD20: 14416.4 | AE20: 6% | AF20: 864.98
A21: 6 | B21: 封春燕 | C21: 202503 | D21: 2024-06-01 | E21: 1096.78 | F21: 7384 | G21: 5109 | H21: 1181.44 | I21: 664.56 | J21: 36.92 | K21: 14.77 | M21: 110.76 | N21: 358 | O21: =SUM(H21:N21) -> 2366.45 | P21: 590.72 | Q21: 147.68 | R21: 36.92 | U21: 358 | V21: =SUM(P21:U21) -> 1133.32 | W21: 13013.2 | Y21: =SUM(E21,O21,V21:X21) -> 17609.75 | AA21: 5573397 | AB21: 310227198610224213 | AD21: 16612.96 | AE21: 6% | AF21: 996.79
A22: 7 | B22: 高峰 | C22: 202503 | D22: 2024-06-01 | E22: 1226.04 | F22: 13877 | G22: 13877 | H22: 2220.32 | I22: 1248.94 | J22: 69.39 | K22: 27.75 | M22: 208.16 | N22: 971 | O22: =SUM(H22:N22) -> 4745.56 | P22: 1110.16 | Q22: 277.54 | R22: 69.39 | U22: 971 | V22: =SUM(P22:U22) -> 2428.09 | W22: 11493.59 | Y22: =SUM(E22,O22,V22:X22) -> 19893.28 | AA22: 5573394 | AB22: 342501197909046816 | AD22: 18767.24 | AE22: 6% | AF22: 1126.04
A23: 8 | B23: 高国强 | C23: 202503 | D23: 2024-06-01 | E23: 525.27 | F23: 7384 | G23: 4880 | H23: 1181.44 | I23: 664.56 | J23: 36.92 | K23: 14.77 | M23: 110.76 | N23: 342 | O23: =SUM(H23:N23) -> 2350.45 | P23: 590.72 | Q23: 147.68 | R23: 36.92 | U23: 342 | V23: =SUM(P23:U23) -> 1117.32 | W23: 3520 | Y23: =SUM(E23,O23,V23:X23) -> 7513.04 | AA23: 5573388 | AB23: 65010319750517061X | AD23: 7087.76 | AE23: 6% | AF23: 425.28
A24: 9 | B24: 顾诗瑶 | C24: 202503 | D24: 2024-06-01 | E24: 440.55 | F24: 7384 | G24: 4570 | H24: 1181.44 | I24: 664.56 | J24: 36.92 | K24: 14.77 | M24: 110.76 | N24: 320 | O24: =SUM(H24:N24) -> 2328.45 | P24: 590.72 | Q24: 147.68 | R24: 36.92 | U24: 320 | V24: =SUM(P24:U24) -> 1095.32 | W24: 2152 | Y24: =SUM(E24,O24,V24:X24) -> 6016.32 | AA24: 5517495 | AB24: 310227199812152021 | AD24: 5675.76 | AE24: 6% | AF24: 340.56
A25: 10 | B25: 何军利 | C25: 202503 | D25: 2024-06-01 | E25: 300 | O25: =SUM(H25:N25) -> 0 | V25: =SUM(P25:U25) -> 0 | W25: 5000 | Y25: =SUM(E25,O25,V25:X25) -> 5300 | AA25: 5545181 | AB25: 310227197512314245 | AD25: 5000 | AE25: 6% | AF25: 300
A26: 11 | B26: 姜金玲 | C26: 202503 | D26: 2024-06-01 | E26: 521.79 | F26: 7384 | G26: 4467 | H26: 1181.44 | I26: 664.56 | J26: 36.92 | K26: 14.77 | M26: 110.76 | N26: 313 | O26: =SUM(H26:N26) -> 2321.45 | P26: 590.72 | Q26: 147.68 | R26: 36.92 | U26: 313 | V26: =SUM(P26:U26) -> 1088.32 | W26: 3520 | Y26: =SUM(E26,O26,V26:X26) -> 7451.56 | AA26: 5573391 | AB26: 310227198902274028 | AD26: 7029.76 | AE26: 6% | AF26: 421.8
A27: 12 | B27: 蒋萍萍 | C27: 202503 | D27: 2024-06-01 | E27: 987.57 | F27: 8677 | G27: 8677 | H27: 1388.32 | I27: 780.94 | J27: 43.39 | K27: 17.35 | M27: 130.16 | N27: 607 | O27: =SUM(H27:N27) -> 2967.16 | P27: 694.16 | Q27: 173.54 | R27: 43.39 | U27: 607 | V27: =SUM(P27:U27) -> 1518.09 | W27: 10207.47 | Y27: =SUM(E27,O27,V27:X27) -> 15680.29 | AA27: 5573396 | AB27: 310227199108114021 | AD27: 14792.73 | AE27: 6% | AF27: 887.56
A28: 13 | B28: 孔祥杰 | C28: 202503 | D28: 2024-06-01 | E28: 635.42 | F28: 7384 | G28: 7189 | H28: 1181.44 | I28: 664.56 | J28: 36.92 | K28: 14.77 | M28: 110.76 | N28: 503 | O28: =SUM(H28:N28) -> 2511.45 | P28: 590.72 | Q28: 147.68 | R28: 36.92 | U28: 503 | V28: =SUM(P28:U28) -> 1278.32 | W28: 5033.88 | Y28: =SUM(E28,O28,V28:X28) -> 9459.07 | AA28: 5545173 | AB28: 310110198408153236 | AD28: 8923.64 | AE28: 6% | AF28: 535.43
A29: 14 | B29: 李龙燕 | C29: 202503 | D29: 2024-06-01 | E29: 1012.49 | F29: 8878 | G29: 8878 | H29: 1420.48 | I29: 799.02 | J29: 44.39 | K29: 17.76 | M29: 133.17 | N29: 621 | O29: =SUM(H29:N29) -> 3035.82 | P29: 710.24 | Q29: 177.56 | R29: 44.39 | U29: 621 | V29: =SUM(P29:U29) -> 1553.19 | W29: 10519.17 | Y29: =SUM(E29,O29,V29:X29) -> 16120.67 | AA29: 5573395 | AB29: 320681199310316032 | AD29: 15208.19 | AE29: 6% | AF29: 912.48
A30: 15 | B30: 李琴 | C30: 202503 | D30: 2025-02-01 | E30: 923.19 | F30: 7384 | G30: 5493 | H30: 1181.44 | I30: 664.56 | J30: 36.92 | K30: 14.77 | M30: 110.76 | N30: 385 | O30: =SUM(H30:N30) -> 2393.45 | P30: 590.72 | Q30: 147.68 | R30: 36.92 | U30: 385 | V30: =SUM(P30:U30) -> 1160.32 | W30: 10065.92 | Y30: =SUM(E30,O30,V30:X30) -> 14542.88 | AA30: 6283726 | AB30: 310227198708184424 | AD30: 13719.68 | AE30: 6% | AF30: 823.2
A31: 16 | B31: 李秋梅 | C31: 202503 | D31: 2024-06-01 | E31: 543.27 | F31: 7384 | G31: 7034 | H31: 1181.44 | I31: 664.56 | J31: 36.92 | K31: 14.77 | M31: 110.76 | N31: 492 | O31: =SUM(H31:N31) -> 2500.45 | P31: 590.72 | Q31: 147.68 | R31: 36.92 | U31: 492 | V31: =SUM(P31:U31) -> 1267.32 | W31: 3520 | Y31: =SUM(E31,O31,V31:X31) -> 7831.04 | AA31: 5573387 | AB31: 320321198010030887 | AD31: 7387.76 | AE31: 6% | AF31: 443.28
A32: 17 | B32: 陆丽伟 | C32: 202503 | D32: 2024-05-01 | E32: 506.79 | F32: 7384 | G32: 2690 | H32: 1181.44 | I32: 664.56 | J32: 36.92 | K32: 14.77 | M32: 110.76 | N32: 188 | O32: =SUM(H32:N32) -> 2196.45 | P32: 590.72 | Q32: 147.68 | R32: 36.92 | U32: 188 | V32: =SUM(P32:U32) -> 963.32 | W32: 3520 | Y32: =SUM(E32,O32,V32:X32) -> 7186.56 | AA32: 6010738 | AB32: 310227198802293619 | AD32: 6779.76 | AE32: 6% | AF32: 406.8
A33: 18 | B33: 陆晓岚 | C33: 202503 | D33: 2024-06-01 | E33: 624.72 | F33: 7384 | G33: 5300 | H33: 1181.44 | I33: 664.56 | J33: 36.92 | K33: 14.77 | M33: 110.76 | N33: 371 | O33: =SUM(H33:N33) -> 2379.45 | P33: 590.72 | Q33: 147.68 | R33: 36.92 | U33: 371 | V33: =SUM(P33:U33) -> 1146.32 | W33: 5119.48 | Y33: =SUM(E33,O33,V33:X33) -> 9269.97 | AA33: 1881345 | AB33: 310227199207211222 | AD33: 8745.24 | AE33: 6% | AF33: 524.73
A34: 19 | B34: 陆智俊 | C34: 202503 | D34: 2024-06-01 | E34: 551.6 | F34: 7556 | G34: 7556 | H34: 1208.96 | I34: 680.04 | J34: 37.78 | K34: 15.11 | M34: 113.34 | N34: 529 | O34: =SUM(H34:N34) -> 2584.23 | P34: 604.48 | Q34: 151.12 | R34: 37.78 | U34: 529 | V34: =SUM(P34:U34) -> 1322.38 | W34: 3520 | Y34: =SUM(E34,O34,V34:X34) -> 7978.21 | AA34: 5545180 | AB34: 310227199807124616 | AD34: 7526.6 | AE34: 6% | AF34: 451.61
A35: 20 | B35: 马一伟 | C35: 202503 | D35: 2024-06-01 | E35: 550.11 | F35: 7384 | G35: 2690 | H35: 1181.44 | I35: 664.56 | J35: 36.92 | K35: 14.77 | M35: 110.76 | N35: 188 | O35: =SUM(H35:N35) -> 2196.45 | P35: 590.72 | Q35: 147.68 | R35: 36.92 | U35: 188 | V35: =SUM(P35:U35) -> 963.32 | W35: 4242.08 | Y35: =SUM(E35,O35,V35:X35) -> 7951.96 | AA35: 5862530 | AB35: 310110198101160036 | AD35: 7501.84 | AE35: 6% | AF35: 450.12
A36: 21 | B36: 牟金丽 | C36: 202503 | D36: 2024-06-01 | E36: 521.91 | F36: 7384 | G36: 4492 | H36: 1181.44 | I36: 664.56 | J36: 36.92 | K36: 14.77 | M36: 110.76 | N36: 314 | O36: =SUM(H36:N36) -> 2322.45 | P36: 590.72 | Q36: 147.68 | R36: 36.92 | U36: 314 | V36: =SUM(P36:U36) -> 1089.32 | W36: 3520 | Y36: =SUM(E36,O36,V36:X36) -> 7453.68 | AA36: 5573393 | AB36: 422802198502180068 | AD36: 7031.76 | AE36: 6% | AF36: 421.92
A37: 22 | B37: 倪跃新 | C37: 202503 | D37: 2024-06-01 | E37: 866.93 | F37: 7384 | G37: 6353 | H37: 1181.44 | I37: 664.56 | J37: 36.92 | K37: 14.77 | M37: 110.76 | N37: 445 | O37: =SUM(H37:N37) -> 2453.45 | P37: 590.72 | Q37: 147.68 | R37: 36.92 | U37: 445 | V37: =SUM(P37:U37) -> 1220.32 | W37: 9008.36 | Y37: =SUM(E37,O37,V37:X37) -> 13549.06 | AA37: 5573386 | AB37: 310229197208182017 | AD37: 12782.12 | AE37: 6% | AF37: 766.94
... A56: 41 | B56: 邹莉 | C56: 202503 | D56: 2024-06-01 | E56: 878.47 | F56: 7384 | G56: 4849 | H56: 1181.44 | I56: 664.56 | J56: 36.92 | K56: 14.77 | M56: 110.76 | N56: 339 | O56: =SUM(H56:N56) -> 2347.45 | P56: 590.72 | Q56: 147.68 | R56: 36.92 | U56: 339 | V56: =SUM(P56:U56) -> 1114.32 | W56: 9412.6 | Y56: =SUM(E56,O56,V56:X56) -> 13752.84 | AA56: 5573405 | AB56: 511126198605207327 | AD56: 12974.36 | AE56: 6% | AF56: 778.48
A57: 合计（RMB） | E57: =SUM(E16:E56) -> 29268.16 | H57: =SUM(H16:H56) -> 52287.52 | I57: =SUM(I16:I56) -> 29411.78 | J57: =SUM(J16:J56) -> 1634.01 | K57: =SUM(K16:K56) -> 653.63 | L57: =SUM(L16:L56) -> 0 | M57: =SUM(M16:M56) -> 4901.98 | N57: =SUM(N16:N56) -> 17574 | O57: =SUM(O16:O56) -> 106462.92 | ... Y57: =SUM(Y16:Y56) -> 446402.22 | AD57: =SUM(AD16:AD56) -> 421133.78 | AF57: =SUM(AF16:AF56) -> 25268.44
A58: 总计（RMB）已包含历月补收人民币肆拾肆万陆仟肆佰零贰圆贰角贰分 | Y58: 446402.22
A60: 其他费用
A61: 序号 | B61: 发生年月 | C61: 费用项目 | D61: 金额 | E61: 备注 | F61: 应纳税金额 | G61: 税率 | H61: 增值税
A62: S/N | B62: YYYYMM | C62: Item | D62: Amount | E62: Remarks | F62: Taxable Amount | G62: Tax Rate | H62: VAT
A63: 1 | B63: 202503 | C63: 税差调整6% | D63: 0 | F63: 0.39 | G63: 0.06 | H63: -0.39
...
