Workbook

Sheet 202503
A1: 序号 | B1: 计薪 周期 | C1: 工号 | D1: 姓名 | E1: 身份证号 | F1: 劳动合同起始日期 | G1: 劳动合同结束日期 | H1: 离职日期 | I1: 社保缴纳地 | J1: 星级费用 | K1: 考核费用 | L1: 量化费用 | M1: 专项费用 | Z1: 当月税前工资合计 | AA1: 社保基数(个人) | AB1: 养老保险(个人) | AC1: 医疗保险(个人) | AD1: 失业保险(个人) | AE1: 公积金基数(个人) | AF1: 住房公积金(个人) | AG1: 员工五险一金合计 | AH1: 本月个人所得税-系统导出 | AI1: 税后增加 | AJ1: 税后扣减 | AK1: 员工实发合计 | AL1: 社保基数 | AM1: 公积金基数 | AN1: 养老缴费 | AO1: 医疗缴费 | AP1: 失业保险 | AQ1: 工伤保险 | AR1: 生育保险 | AS1: 公积金 | AT1: 残保金 | AU1: 企业五险一金合计 | AV1: 工会费 | AW1: 代收付合计 | AX1: 本月垫付下月收 | AY1: 本月多收下月退 | AZ1: 社保备注 | BA1: 外包服务费 | BB1: 税前项合计 | BC1: 增值税 | BD1: 总计
A2: NO. | B2: Salary Cycle | C2: Employee No. | D2: Name | E2: ID No. | F2: Contract Starting Date | G2: Contract Expiry Date | H2: Exit Date | I2: Social Insurance City | J2: Contract Salary | K2: Assessment fees | L2: Quantifying costs | M2: 支局专项 | N2: 部门加奖 | O2: 交通费 | P2: 效能补贴 | Q2: 高温费及清凉饮料费 （6-9月） | R2: 伙食补贴 | S2: 独生子女奖励 | T2: 保险费 | U2: 其他费用 | V2: 补发费用 | W2: 劳防用品 | X2: 保障补差 | Y2: 其他扣款 | Z2: Pre-tax Total | AA2: Social Insurance Base | AB2: Pension Employee | AC2: Medical Employee | AD2: Umemployment Employee | AE2: Housing Fund Base | AF2: Housing Fund Employee | AG2: Total Amount of Social Insurance(EE) | AH2: Personal Income Tax | AI2: Increase After-tax payment | AJ2: Reduction After-tax payment | AK2: After-tax total Income | AL2: Social Insurance Base | AM2: Housing Fund Base | AN2: Pension Employer | AO2: Medical Employer | AP2: Umemployment Employer | AQ2: Injury Employer | AR2: Maternity Insurance Employer | AS2: Housing Fund Employer | AT2: Disabled people&Back pay Fund | AU2: Total Amount of Social Insurance(ER) | AV2: Union Fee | AW2: Payment Total | AZ2: Social Security remark | BA2: Service Fee | BB2: Total | BC2: VAT | BD2: Subtotal
A3: =ROW()-2 -> 1 | B3: 2503 | C3: WB007174 | D3: 傅强 | E3: 342501197805270274 | F3: 45444 | G3: 45808 | I3: 上海 | J3: 950 | L3: 475.3 | X3: 2501.02 | Z3: =SUM(J3:Y3) -> 3926.32 | AA3: 7384 | AB3: 590.72 | AC3: 147.68 | AD3: 36.92 | AE3: 6520 | AF3: =ROUND(AE3*7%,0) -> 456 | AG3: =AB3+AC3+AD3+AF3 -> 1231.32 | AK3: =Z3-AG3-AH3 -> 2695 | AL3: 7384 | AM3: 6520 | AN3: =ROUND(AL3*16%,2) -> 1181.44 | AO3: =ROUND(AL3*9%,2) -> 664.56 | AP3: =ROUND(AL3*0.5%,2) -> 36.92 | AQ3: 14.77 | AS3: =ROUND(AM3*7%,0) -> 456 | AT3: =ROUND(IF(AL3<22792,AL3*1.5%,22792*1.5%),2) -> 110.76 | AU3: =SUM(AN3:AT3) -> 2464.45 | AV3: 79 | AW3: =AU3+Z3+AI3-AJ3+AV3 -> 6469.77 | BA3: 60 | BB3: =ROUND(AW3+BA3+AX3+AY3,2) -> 6529.77 | BC3: =ROUND(BB3*6%,2) -> 391.79 | BD3: =ROUND(SUM(BB3:BC3),2) -> 6921.56
A4: =ROW()-2 -> 2 | B4: 2503 | C4: WB007141 | D4: 汤熙荣 | E4: 310108197210073613 | F4: 45383 | G4: 45747 | H4: 45716 | I4: 上海 | U4: 66000 | Z4: =SUM(J4:Y4) -> 66000 | AG4: =AB4+AC4+AD4+AF4 -> 0 | AK4: =Z4-AG4-AH4 -> 66000 | AU4: =SUM(AN4:AT4) -> 0 | BA4: 0 | BB4: =ROUND(AW4+BA4+AX4+AY4,2) -> 0 | BC4: =ROUND(BB4*6%,2) -> 0 | BD4: =ROUND(SUM(BB4:BC4),2) -> 0
A6: 合计 | Z6: =SUBTOTAL(9,Z3:Z4) -> 69926.32 | AG6: =SUBTOTAL(9,AG3:AG4) -> 1231.32 | AK6: =SUBTOTAL(9,AK3:AK4) -> 68695 | AU6: =SUBTOTAL(9,AU3:AU4) -> 2464.45 | AV6: =SUM(AV3:AV4) -> 79 | AW6: =SUBTOTAL(9,AW3:AW4) -> 6469.77 | AX6: =SUBTOTAL(9,AX3:AX4) -> 0 | AY6: =SUBTOTAL(9,AY3:AY4) -> 0 | BA6: =SUBTOTAL(9,BA3:BA4) -> 60 | BB6: =SUBTOTAL(9,BB3:BB4) -> 6529.77 | BC6: =SUBTOTAL(9,BC3:BC4) -> 391.79 | BD6: =SUBTOTAL(9,BD3:BD4) -> 6921.56
BA8: 实际结算 | BB8: 303434.72
BA9: 差额下月补 | BB9: 111.61

Sheet 对账单
A1: 科目 | B1: 手工账单 | C1: 速创账单 | D1: 155 | E1: 预收一次性 | F1: 2月工会费 | G1: 本月垫付，下月收 | H1: 本月多收，下月退 | I1: 合计 | J1: 差异
A2: 管理费 | B2: ='202503'!BC6 -> 391.79 | C2: =系统!E17 -> 446.75 | I2: =SUM(C2:G2) -> 446.75 | J2: =B2-C2 -> -54.96
A3: 风险费 | B3: ='202503'!BA6 -> 60 | C3: 0 | I3: =SUM(C3:G3) -> 0 | J3: =B3-C3 -> 60
A4: 个人四金 | B4: ='202503'!AG6 -> 1231.32 | C4: =系统!V17 -> 1231.32 | I4: =SUM(C4:G4) -> 1231.32 | J4: =B4-C4 -> 0
A5: 公司四金 | B5: ='202503'!AU6 -> 2464.45 | C5: =系统!O17 -> 2464.45 | I5: =SUM(C5:E5) -> 2464.45 | J5: =B5-C5 -> 0
A6: 工伤退费 | I6: =SUM(C6:G6) -> 0 | J6: =B6-C6 -> 0
A7: 代发工资 | B7: ='202503'!Z3-'202503'!AG3 -> 2695 | C7: =2690 -> 2690 | D7: =5 -> 5 | I7: =SUM(C7:G7) -> 2695 | J7: =B7-C7 -> 5
A8: 上月垫付 | D8: =B10 -> 0 | I8: =SUM(C8:G8) -> 0 | J8: =B8-C8 -> 0
A9: 工会费 | B9: ='202503'!AV6 -> 79 | D9: =B8 -> 0 | F9: =B9 -> 79 | I9: =SUM(C9:G9) -> 79 | J9: =B9-C9 -> 79
A10: 上月多收 | I10: =SUM(C10:G10) -> 0 | J10: =B10-C10 -> 0
A11: 小计 | B11: =SUM(B2:B10) -> 6921.56 | C11: =SUM(C2:C10) -> 6832.52 | D11: =SUM(D2:D10) -> 5 | E11: =E5 -> 0 | F11: =F9 -> 79 | G11: =G9 -> 0 | H11: =H9 -> 0 | I11: =SUM(C11:G11) -> 6916.52
A12: 附加税
A13: 增值税 | D13: =ROUND((D11+D12)*6%,2) -> 0.3 | F13: =ROUND((F11+F12)*6%,2) -> 4.74 | G13: =ROUND((G11+G12)*6%,2) -> 0 | H13: =ROUND((H11+H12)*6%,2) -> 0 | I13: =SUM(C13:G13) -> 5.04
A14: 总计 | B14: =SUM(B11:B13) -> 6921.56 | C14: =SUM(C11:C13) -> 6832.52 | D14: =SUM(D11:D13) -> 5.3 | E14: =E11 -> 0 | F14: =SUM(F11:F13) -> 83.74 | G14: =SUM(G11:G13) -> 0 | H14: =SUM(H11:H13) -> 0 | I14: =SUM(C14:H14) -> 6921.56
A15: 给客户账单金额 | I15: =B14 -> 6921.56
A16: 差异 | I16: =I15-I14 -> 0
A17: 不含税差异 | I17: =ROUND(I16/1.06,2) -> 0

Sheet 系统
A1: 200070
A2: 寄：梅园路77号人才大厦
B3: 中国电信股份有限公司上海分公司 王慧珏 收
D6: 上海外服布列吉科技有限公司
C7: Shanghai Foreign Service Bridge Technology Co,Ltd.
E9: 收款通知书
E10: ADVISE ON COLLECTION
E11: 2025年03月
A13: 公司名称：中国电信股份有限公司上海分公司 | J13: 帐单号：202503CH6596303
A14: 序号 | B14: 姓名 | C14: 发生年月 | D14: 入职日期 | E14: 管理费 | F14: 当月社保基数 | G14: 当月公积金基数 | H14: 社保类 公司支付 Social Insurance Premiums Paid by Employer | N14: 公积金类 公司支付 Provident Fund Paid by Employer | O14: 公司合计 | P14: 社保类 个人支付 Social Insurance Premiums Paid by Employee | U14: 公积金类 个人支付 Provident Fund Paid by Employee | V14: 个人合计 | W14: 代办薪酬 | X14: 其他 | Y14: 总计 | Z14: 备注 | AA14: 外服工号 | AB14: 证件号码 | AC14: 应纳税金额 | AD14: 税率 | AE14: 增值税
A15: S/N | B15: Name | C15: YYYYMM | D15: Employment Start Date | E15: Adm Fee | F15: Social Insurance Base Amount of Current Month | G15: Provident Fund Base Amount of Current Month | H15: 养老保险 Endowment | I15: 医疗保险 Medical | J15: 失业保险 Unemploy-ment | K15: 工伤保险 Employment Injury | L15: 医疗生育保险 Medical Maternity | M15: 保障金 Disabled people&Back pay Fund | N15: 公积金 Provident Fund | O15: Subtotal of Employer Payment | P15: 养老保险 Endowment | Q15: 医疗保险 Medical | R15: 失业保险 Unemploy-ment | S15: 工伤保险 Employment Injury | T15: 医疗生育保险 Medical Maternity | U15: 公积金 Provident Fund | V15: Subtotal of Personal Payment | W15: Agency of Wage Payment | X15: Others | Y15: Total | Z15: Remarks | AA15: SFSC ID | AB15: ID Card | AC15: Taxable Amount | AD15: Tax Rate | AE15: VAT
A16: 1 | B16: 傅强 | C16: 202503 | D16: 2024-06-01 | E16: 446.75 | F16: 7384 | G16: 6520 | H16: 1181.44 | I16: 664.56 | J16: 36.92 | K16: 14.77 | M16: 110.76 | N16: 456 | O16: =SUM(H16:N16) -> 2464.45 | P16: 590.72 | Q16: 147.68 | R16: 36.92 | U16: 456 | V16: =SUM(P16:U16) -> 1231.32 | W16: 2690 | Y16: =SUM(E16,O16,V16:X16) -> 6832.52 | AA16: 6031699 | AB16: 342501197805270274 | AC16: 6445.76 | AD16: 6% | AE16: 386.76
A17: 合计（RMB） | E17: =SUM(E16:E16) -> 446.75 | H17: =SUM(H16:H16) -> 1181.44 | I17: =SUM(I16:I16) -> 664.56 | J17: =SUM(J16:J16) -> 36.92 | K17: =SUM(K16:K16) -> 14.77 | L17: =SUM(L16:L16) -> 0 | M17: =SUM(M16:M16) -> 110.76 | N17: =SUM(N16:N16) -> 456 | O17: =SUM(O16:O16) -> 2464.45 | ... Y17: =SUM(Y16:Y16) -> 6832.52 | AC17: =SUM(AC16:AC16) -> 6445.76 | AE17: =SUM(AE16:AE16) -> 386.76
A18: 总计（RMB）已包含历月补收人民币陆仟捌佰叁拾贰圆伍角贰分 | Y18: 6832.52
A20: 其他费用
A21: 序号 | B21: 发生年月 | C21: 费用项目 | D21: 金额 | E21: 备注 | F21: 应纳税金额 | G21: 税率 | H21: 增值税
A22: S/N | B22: YYYYMM | C22: Item | D22: Amount | E22: Remarks | F22: Taxable Amount | G22: Tax Rate | H22: VAT
A23: 1 | B23: 202503 | C23: 税差调整6% | D23: 0 | F23: 0.01 | G23: 0.06 | H23: -0.01
A24: 合计（RMB） | D24: =SUM(D23:D23) -> 0 | F24: =SUM(F23:F23) -> 0.01 | H24: =SUM(H23:H23) -> -0.01
A25: 总计（RMB）人民币零 | D25: 0 | F25: 0.01 | H25: -0.01
A27: 增值税：
A28: 序号 S/N | B28: 应纳税额 | C28: 税率 | D28: 税金
A30: 1 | B30: 6445.77 | C30: 6% | D30: 386.75
A31: 小计（RMB） | B31: 6445.77 | D31: 386.75
A32: 总计(RMB) | D32: 386.75
A33: 本次价税合计(RMB):人民币陆仟捌佰叁拾贰圆伍角贰分
A34: 6832.52
A35: 本月价税合计（RMB）：6832.52 其中已开票6832.52
A37: 本月总计（RMB）人民币陆仟捌佰叁拾贰圆伍角贰分 ￥6832.52
A39: 减少人员
A40: 序号 | B40: 姓名 | C40: 离职日期
A41: 1 | B41: 汤熙荣 | C41: 2025-03-01
A43: 制单人： | J43: 制单日期：2025-03-20
A45: 户名：上海外服（集团）有限公司 | G45: 户名：上海外服（集团）有限公司
A46: 美金收款账号：449459237031 | G46: 外币/人民币收款账号：083651120100303014006
A47: 开户银行：中国银行上海市分行 | G47: 开户银行：中国光大银行上海分行营业部
A48: SWIFT CODE：BKCHCNBJ300 | G48: SWIFT CODE：EVERCNBJSH1
A49: 地址：中国上海市黄浦区中山东一路23号 | G49: 地址：中国上海市浦东新区世纪大道1118号
A51: 户名：上海外服（集团）有限公司
A52: 外币/人民币收款账号：1001244329006580566
...
