Workbook

Sheet 202503
A1: 序号 | B1: 计薪 周期 | C1: 工号 | D1: 姓名 | E1: 身份证号 | F1: 劳动合同起始日期 | G1: 劳动合同结束日期 | H1: 离职日期 | I1: 社保缴纳地 | J1: 星级费用 | K1: 考核费用 | L1: 量化费用 | M1: 专项费用 | Z1: 当月税前工资合计 | AA1: 社保基数(个人) | AB1: 养老保险(个人) | AC1: 医疗保险(个人) | AD1: 失业保险(个人) | AE1: 公积金基数(个人) | AF1: 住房公积金(个人) | AG1: 员工五险一金合计 | AH1: 本月个人所得税-系统导出 | AI1: 税后增加 | AJ1: 税后扣减 | AK1: 员工实发合计 | AL1: 社保基数 | AM1: 公积金基数 | AN1: 养老缴费 | AO1: 医疗缴费 | AP1: 失业保险 | AQ1: 工伤保险 | AR1: 生育保险 | AS1: 公积金 | AT1: 残保金 | AU1: 企业五险一金合计 | AV1: 工会费 | AW1: 代收付合计 | AX1: 2月垫付，3月收 | AY1: 3月垫付，4月补收 | AZ1: 社保备注 | BA1: 外包服务费 | BB1: 税前项合计 | BC1: 增值税 | BD1: 总计 | BE1: 工会费退回
A2: NO. | B2: Salary Cycle | C2: Employee No. | D2: Name | E2: ID No. | F2: Contract Starting Date | G2: Contract Expiry Date | H2: Exit Date | I2: Social Insurance City | J2: Contract Salary | K2: Assessment fees | L2: Quantifying costs | M2: 支局专项 | N2: 1+1激励 | O2: 交通费 | P2: 效能补贴 | Q2: 伙食补贴 | R2: 高温费及清凉饮料费 （6-9月） | S2: 独生子女奖励 | T2: 保险费 | U2: 其他费用 | V2: 补发费用 | W2: 劳防用品 | X2: 保障补差 | Y2: 其他扣款 | Z2: Pre-tax Total | AA2: Social Insurance Base | AB2: Pension Employee | AC2: Medical Employee | AD2: Umemployment Employee | AE2: Housing Fund Base | AF2: Housing Fund Employee | AG2: Total Amount of Social Insurance(EE) | AH2: Personal Income Tax | AI2: Increase After-tax payment | AJ2: Reduction After-tax payment | AK2: After-tax total Income | AL2: Social Insurance Base | AM2: Housing Fund Base | AN2: Pension Employer | AO2: Medical Employer | AP2: Umemployment Employer | AQ2: Injury Employer | AR2: Maternity Insurance Employer | AS2: Housing Fund Employer | AT2: Disabled people&Back pay Fund | AU2: Total Amount of Social Insurance(ER) | AV2: Union Fee | AW2: Payment Total | AZ2: Social Security remark | BA2: Service Fee | BB2: Total | BC2: VAT | BD2: Subtotal
A3: =ROW()-2 -> 1 | B3: 2503 | C3: WB007244 | D3: 周伟丰 | E3: 310107198106192557 | F3: 45444 | G3: 45808 | I3: 上海 | J3: 1400 | K3: 6433.5 | L3: 1583.7 | Q3: 630 | Y3: 0 | Z3: =SUM(J3:Y3) -> 10047.2 | AA3: 13804 | AB3: 1104.32 | AC3: 276.08 | AD3: 69.02 | AE3: 13804 | AF3: 966 | AG3: =AB3+AC3+AD3+AF3 -> 2415.42 | AK3: =Z3-AG3-AH3 -> 7631.78 | AL3: 13804 | AM3: 13804 | AN3: =ROUND(AL3*16%,2) -> 2208.64 | AO3: =ROUND(AL3*9%,2) -> 1242.36 | AP3: =ROUND(AL3*0.5%,2) -> 69.02 | AQ3: 27.61 | AS3: =ROUND(AM3*7%,0) -> 966 | AT3: =ROUND(IF(AL3<24366,AL3*1.5%,24366*1.5%),2) -> 207.06 | AU3: =SUM(AN3:AT3) -> 4720.69 | AV3: =VLOOKUP(D3,'[1]202503'!$D$3:$AW$19,46,0) -> 188 | AW3: =AU3+Z3+AI3-AJ3+AV3 -> 14955.89 | BA3: 255 | BB3: =ROUND(AW3+BA3+AY3+AX3,2) -> 15210.89 | BC3: =ROUND(BB3*6%,2) -> 912.65 | BD3: =ROUND(SUM(BB3:BC3),2) -> 16123.54 | BE3: =AV3-5 -> 183 | BF3: 纵向攻击团队
A4: =ROW()-2 -> 2 | B4: 2503 | C4: WB007262 | D4: 顾燕 | E4: 310113198111034825 | F4: 45444 | G4: 45808 | I4: 上海 | J4: 1030 | K4: 4837 | L4: 698.2 | Q4: 630 | Y4: -164.2 | Z4: =SUM(J4:Y4) -> 7031 | AA4: 10363 | AB4: 829.04 | AC4: 207.26 | AD4: 51.82 | AE4: 10363 | AF4: 725 | AG4: =AB4+AC4+AD4+AF4 -> 1813.12 | AK4: =Z4-AG4-AH4 -> 5217.88 | AL4: 10363 | AM4: 10363 | AN4: =ROUND(AL4*16%,2) -> 1658.08 | AO4: 932.68 | AP4: =ROUND(AL4*0.5%,2) -> 51.82 | AQ4: 20.73 | AS4: =ROUND(AM4*7%,0) -> 725 | AT4: =ROUND(IF(AL4<24366,AL4*1.5%,24366*1.5%),2) -> 155.45 | AU4: =SUM(AN4:AT4) -> 3543.76 | AV4: =VLOOKUP(D4,'[1]202503'!$D$3:$AW$19,46,0) -> 128 | AW4: =AU4+Z4+AI4-AJ4+AV4 -> 10702.76 | BA4: 255 | BB4: =ROUND(AW4+BA4+AY4+AX4,2) -> 10957.76 | BC4: =ROUND(BB4*6%,2) -> 657.47 | BD4: =ROUND(SUM(BB4:BC4),2) -> 11615.23 | BE4: =AV4-5 -> 123 | BF4: 纵向攻击团队
A5: =ROW()-2 -> 3 | B5: 2503 | C5: WB026438 | D5: 沈娟娟 | E5: 32068119890825242X | F5: 45444 | G5: 45808 | I5: 上海 | J5: 1200 | K5: 4398 | L5: 15.3 | Q5: 630 | Y5: -262.3 | Z5: =SUM(J5:Y5) -> 5981 | AA5: 11829 | AB5: 946.32 | AC5: 236.58 | AD5: 59.15 | AE5: 11829 | AF5: 828 | AG5: =AB5+AC5+AD5+AF5 -> 2070.05 | AK5: =Z5-AG5-AH5 -> 3910.95 | AL5: 11829 | AM5: 11829 | AN5: =ROUND(AL5*16%,2) -> 1892.64 | AO5: 1064.62 | AP5: =ROUND(AL5*0.5%,2) -> 59.15 | AQ5: 23.66 | AS5: =ROUND(AM5*7%,0) -> 828 | AT5: =ROUND(IF(AL5<24366,AL5*1.5%,24366*1.5%),2) -> 177.44 | AU5: =SUM(AN5:AT5) -> 4045.51 | AV5: =VLOOKUP(D5,'[1]202503'!$D$3:$AW$19,46,0) -> 107 | AW5: =AU5+Z5+AI5-AJ5+AV5 -> 10133.51 | BA5: 255 | BB5: =ROUND(AW5+BA5+AY5+AX5,2) -> 10388.51 | BC5: =ROUND(BB5*6%,2) -> 623.31 | BD5: =ROUND(SUM(BB5:BC5),2) -> 11011.82 | BE5: =AV5-5 -> 102 | BF5: 纵向攻击团队
A6: =ROW()-2 -> 4 | B6: 2503 | C6: WB027558 | D6: 陈云 | E6: 320681198911257029 | F6: 45444 | G6: 45808 | I6: 上海 | J6: 1030 | K6: 5888.5 | L6: 368.7 | Q6: 630 | Y6: -21.1 | Z6: =SUM(J6:Y6) -> 7896.1 | AA6: 11367 | AB6: 909.36 | AC6: 227.34 | AD6: 56.84 | AE6: 11367 | AF6: 796 | AG6: =AB6+AC6+AD6+AF6 -> 1989.54 | AK6: =Z6-AG6-AH6 -> 5906.56 | AL6: 11367 | AM6: 11367 | AN6: =ROUND(AL6*16%,2) -> 1818.72 | AO6: 1023.04 | AP6: =ROUND(AL6*0.5%,2) -> 56.84 | AQ6: 22.73 | AS6: =ROUND(AM6*7%,0) -> 796 | AT6: =ROUND(IF(AL6<24366,AL6*1.5%,24366*1.5%),2) -> 170.51 | AU6: =SUM(AN6:AT6) -> 3887.84 | AV6: =VLOOKUP(D6,'[1]202503'!$D$3:$AW$19,46,0) -> 145 | AW6: =AU6+Z6+AI6-AJ6+AV6 -> 11928.94 | BA6: 255 | BB6: =ROUND(AW6+BA6+AY6+AX6,2) -> 12183.94 | BC6: =ROUND(BB6*6%,2) -> 731.04 | BD6: =ROUND(SUM(BB6:BC6),2) -> 12914.98 | BE6: =AV6-5 -> 140 | BF6: 纵向攻击团队
A7: =ROW()-2 -> 5 | B7: 2503 | C7: WB036282 | D7: 张海荣 | E7: 320681198311146835 | F7: 45444 | G7: 45808 | I7: 上海 | J7: 950 | K7: 5736.5 | L7: 548.9 | Q7: 630 | Y7: -410.3 | Z7: =SUM(J7:Y7) -> 7455.1 | AA7: 11730 | AB7: 938.4 | AC7: 234.6 | AD7: 58.65 | AE7: 11730 | AF7: 821 | AG7: =AB7+AC7+AD7+AF7 -> 2052.65 | AK7: =Z7-AG7-AH7 -> 5402.45 | AL7: 11730 | AM7: 11730 | AN7: =ROUND(AL7*16%,2) -> 1876.8 | AO7: =ROUND(AL7*9%,2) -> 1055.7 | AP7: =ROUND(AL7*0.5%,2) -> 58.65 | AQ7: 23.46 | AS7: =ROUND(AM7*7%,0) -> 821 | AT7: =ROUND(IF(AL7<24366,AL7*1.5%,24366*1.5%),2) -> 175.95 | AU7: =SUM(AN7:AT7) -> 4011.56 | AV7: =VLOOKUP(D7,'[1]202503'!$D$3:$AW$19,46,0) -> 137 | AW7: =AU7+Z7+AI7-AJ7+AV7 -> 11603.66 | BA7: 255 | BB7: =ROUND(AW7+BA7+AY7+AX7,2) -> 11858.66 | BC7: =ROUND(BB7*6%,2) -> 711.52 | BD7: =ROUND(SUM(BB7:BC7),2) -> 12570.18 | BE7: =AV7-5 -> 132 | BF7: 纵向攻击团队
A8: =ROW()-2 -> 6 | B8: 2503 | C8: WB044295 | D8: 龚林花 | E8: 310230198502244987 | F8: 45444 | G8: 45808 | I8: 上海 | J8: 860 | K8: 5639 | L8: 470.3 | Q8: 630 | Y8: -418.2 | Z8: =SUM(J8:Y8) -> 7181.1 | AA8: 7963 | AB8: 637.04 | AC8: 159.26 | AD8: 39.82 | AE8: 7963 | AF8: 557 | AG8: =AB8+AC8+AD8+AF8 -> 1393.12 | AK8: =Z8-AG8-AH8 -> 5787.98 | AL8: 7963 | AM8: 7963 | AN8: =ROUND(AL8*16%,2) -> 1274.08 | AO8: 716.68 | AP8: =ROUND(AL8*0.5%,2) -> 39.82 | AQ8: 15.93 | AS8: =ROUND(AM8*7%,0) -> 557 | AT8: =ROUND(IF(AL8<24366,AL8*1.5%,24366*1.5%),2) -> 119.45 | AU8: =SUM(AN8:AT8) -> 2722.96 | AV8: =VLOOKUP(D8,'[1]202503'!$D$3:$AW$19,46,0) -> 131 | AW8: =AU8+Z8+AI8-AJ8+AV8 -> 10035.06 | BA8: 255 | BB8: =ROUND(AW8+BA8+AY8+AX8,2) -> 10290.06 | BC8: =ROUND(BB8*6%,2) -> 617.4 | BD8: =ROUND(SUM(BB8:BC8),2) -> 10907.46 | BE8: =AV8-5 -> 126 | BF8: 纵向攻击团队
A9: =ROW()-2 -> 7 | B9: 2503 | C9: WB046059 | D9: 宋莉莉 | E9: 370883199010065887 | F9: 45444 | G9: 45808 | I9: 上海 | J9: 800 | K9: 3738 | L9: 123.9 | Q9: 630 | X9: 265.33 | Y9: -239.7 | Z9: =SUM(J9:Y9) -> 5317.53 | AA9: 11386 | AB9: 910.88 | AC9: 227.72 | AD9: 56.93 | AE9: 11386 | AF9: 797 | AG9: =AB9+AC9+AD9+AF9 -> 1992.53 | AK9: =Z9-AG9-AH9 -> 3325 | AL9: 11386 | AM9: 11386 | AN9: =ROUND(AL9*16%,2) -> 1821.76 | AO9: =ROUND(AL9*9%,2) -> 1024.74 | AP9: =ROUND(AL9*0.5%,2) -> 56.93 | AQ9: 22.77 | AS9: =ROUND(AM9*7%,0) -> 797 | AT9: =ROUND(IF(AL9<24366,AL9*1.5%,24366*1.5%),2) -> 170.79 | AU9: =SUM(AN9:AT9) -> 3893.99 | AV9: =VLOOKUP(D9,'[1]202503'!$D$3:$AW$19,46,0) -> 94 | AW9: =AU9+Z9+AI9-AJ9+AV9 -> 9305.52 | BA9: 255 | BB9: =ROUND(AW9+BA9+AY9+AX9,2) -> 9560.52 | BC9: =ROUND(BB9*6%,2) -> 573.63 | BD9: =ROUND(SUM(BB9:BC9),2) -> 10134.15 | BE9: =AV9-5 -> 89 | BF9: 纵向攻击团队
A10: =ROW()-2 -> 8 | B10: 2503 | C10: WB053301 | D10: 林峰 | E10: 320681199806210215 | F10: 45444 | G10: 45808 | I10: 上海 | J10: 900 | K10: 3948 | L10: 270 | Q10: 630 | X10: 393.93 | Y10: -1496.6 | Z10: =SUM(J10:Y10) -> 4645.33 | AA10: 7546 | AB10: 603.68 | AC10: 150.92 | AD10: 37.73 | AE10: 7546 | AF10: 528 | AG10: =AB10+AC10+AD10+AF10 -> 1320.33 | AK10: =Z10-AG10-AH10 -> 3325 | AL10: 7546 | AM10: 7546 | AN10: =ROUND(AL10*16%,2) -> 1207.36 | AO10: =ROUND(AL10*9%,2) -> 679.14 | AP10: =ROUND(AL10*0.5%,2) -> 37.73 | AQ10: 15.09 | AS10: =ROUND(AM10*7%,0) -> 528 | AT10: =ROUND(IF(AL10<24366,AL10*1.5%,24366*1.5%),2) -> 113.19 | AU10: =SUM(AN10:AT10) -> 2580.51 | AV10: =VLOOKUP(D10,'[1]202503'!$D$3:$AW$19,46,0) -> 80 | AW10: =AU10+Z10+AI10-AJ10+AV10 -> 7305.84 | BA10: 255 | BB10: =ROUND(AW10+BA10+AY10+AX10,2) -> 7560.84 | BC10: =ROUND(BB10*6%,2) -> 453.65 | BD10: =ROUND(SUM(BB10:BC10),2) -> 8014.49 | BE10: =AV10-5 -> 75 | BF10: 纵向攻击团队
A11: =ROW()-2 -> 9 | B11: 2503 | C11: WB007259 | D11: 茅柳 | E11: 310230198208264565 | F11: 45444 | G11: 45808 | I11: 上海 | J11: 900 | K11: 5008 | L11: -76.2 | Q11: 630 | Y11: -589.7 | Z11: =SUM(J11:Y11) -> 5872.1 | AA11: 7594 | AB11: 607.52 | AC11: 151.88 | AD11: 37.97 | AE11: 7594 | AF11: 532 | AG11: =AB11+AC11+AD11+AF11 -> 1329.37 | AK11: =Z11-AG11-AH11 -> 4542.73 | AL11: 7594 | AM11: 7594 | AN11: =ROUND(AL11*16%,2) -> 1215.04 | AO11: =ROUND(AL11*9%,2) -> 683.46 | AP11: =ROUND(AL11*0.5%,2) -> 37.97 | AQ11: 15.19 | AS11: =ROUND(AM11*7%,0) -> 532 | AT11: =ROUND(IF(AL11<24366,AL11*1.5%,24366*1.5%),2) -> 113.91 | AU11: =SUM(AN11:AT11) -> 2597.57 | AV11: =VLOOKUP(D11,'[1]202503'!$D$3:$AW$19,46,0) -> 105 | AW11: =AU11+Z11+AI11-AJ11+AV11 -> 8574.67 | BA11: 255 | BB11: =ROUND(AW11+BA11+AY11+AX11,2) -> 8829.67 | BC11: =ROUND(BB11*6%,2) -> 529.78 | BD11: =ROUND(SUM(BB11:BC11),2) -> 9359.45 | BE11: =AV11-5 -> 100 | BF11: 纵向攻击团队
A12: =ROW()-2 -> 10 | B12: 2503 | C12: WB045138 | D12: 沙玉莲 | E12: 320681198001296045 | F12: 45444 | G12: 45808 | I12: 上海 | J12: 900 | K12: 9691 | L12: 950.1 | Q12: 630 | Y12: -26 | Z12: =SUM(J12:Y12) -> 12145.1 | AA12: 11264 | AB12: 901.12 | AC12: 225.28 | AD12: 56.32 | AE12: 11264 | AF12: 788 | AG12: =AB12+AC12+AD12+AF12 -> 1970.72 | AK12: =Z12-AG12-AH12 -> 10174.38 | AL12: 11264 | AM12: 11264 | AN12: =ROUND(AL12*16%,2) -> 1802.24 | AO12: =ROUND(AL12*9%,2) -> 1013.76 | AP12: =ROUND(AL12*0.5%,2) -> 56.32 | AQ12: 22.53 | AS12: =ROUND(AM12*7%,0) -> 788 | AT12: =ROUND(IF(AL12<24366,AL12*1.5%,24366*1.5%),2) -> 168.96 | AU12: =SUM(AN12:AT12) -> 3851.81 | AV12: =VLOOKUP(D12,'[1]202503'!$D$3:$AW$19,46,0) -> 230 | AW12: =AU12+Z12+AI12-AJ12+AV12 -> 16226.91 | BA12: 255 | BB12: =ROUND(AW12+BA12+AY12+AX12,2) -> 16481.91 | BC12: =ROUND(BB12*6%,2) -> 988.91 | BD12: =ROUND(SUM(BB12:BC12),2) -> 17470.82 | BE12: =AV12-5 -> 225 | BF12: 纵向攻击团队
A13: =ROW()-2 -> 11 | B13: 2503 | C13: WB044028 | D13: 王凌波 | E13: 320681198005016055 | F13: 45444 | G13: 45808 | I13: 上海 | J13: 900 | K13: 11589.5 | L13: 1241.2 | Q13: 630 | Y13: -337.3 | Z13: =SUM(J13:Y13) -> 14023.4 | AA13: 11463 | AB13: 917.04 | AC13: 229.26 | AD13: 57.32 | AE13: 11463 | AF13: 802 | AG13: =AB13+AC13+AD13+AF13 -> 2005.62 | AK13: =Z13-AG13-AH13 -> 12017.78 | AL13: 11463 | AM13: 11463 | AN13: =ROUND(AL13*16%,2) -> 1834.08 | AO13: 1031.68 | AP13: =ROUND(AL13*0.5%,2) -> 57.32 | AQ13: 22.93 | AS13: =ROUND(AM13*7%,0) -> 802 | AT13: =ROUND(IF(AL13<24366,AL13*1.5%,24366*1.5%),2) -> 171.95 | AU13: =SUM(AN13:AT13) -> 3919.96 | AV13: =VLOOKUP(D13,'[1]202503'!$D$3:$AW$19,46,0) -> 268 | AW13: =AU13+Z13+AI13-AJ13+AV13 -> 18211.36 | BA13: 255 | BB13: =ROUND(AW13+BA13+AY13+AX13,2) -> 18466.36 | BC13: =ROUND(BB13*6%,2) -> 1107.98 | BD13: =ROUND(SUM(BB13:BC13),2) -> 19574.34 | BE13: =AV13-5 -> 263 | BF13: 纵向攻击团队
A14: =ROW()-2 -> 12 | B14: 2503 | C14: WB048620 | D14: 郁金华 | E14: 320681197812267024 | F14: 45444 | G14: 45808 | I14: 上海 | J14: 900 | K14: 5351 | L14: 643.8 | Q14: 630 | Y14: -26 | Z14: =SUM(J14:Y14) -> 7498.8 | AA14: 7384 | AB14: 590.72 | AC14: 147.68 | AD14: 36.92 | AE14: 6573 | AF14: 460 | AG14: =AB14+AC14+AD14+AF14 -> 1235.32 | AK14: =Z14-AG14-AH14 -> 6263.48 | AL14: 7384 | AM14: 6573 | AN14: =ROUND(AL14*16%,2) -> 1181.44 | AO14: =ROUND(AL14*9%,2) -> 664.56 | AP14: =ROUND(AL14*0.5%,2) -> 36.92 | AQ14: 14.77 | AS14: =ROUND(AM14*7%,0) -> 460 | AT14: =ROUND(IF(AL14<24366,AL14*1.5%,24366*1.5%),2) -> 110.76 | AU14: =SUM(AN14:AT14) -> 2468.45 | AV14: =VLOOKUP(D14,'[1]202503'!$D$3:$AW$19,46,0) -> 137 | AW14: =AU14+Z14+AI14-AJ14+AV14 -> 10104.25 | BA14: 255 | BB14: =ROUND(AW14+BA14+AY14+AX14,2) -> 10359.25 | BC14: =ROUND(BB14*6%,2) -> 621.56 | BD14: =ROUND(SUM(BB14:BC14),2) -> 10980.81 | BE14: =AV14-5 -> 132 | BF14: 纵向攻击团队
A15: =ROW()-2 -> 13 | B15: 2503 | C15: WB041713 | D15: 翁杰 | E15: 32068119830326361X | F15: 45444 | G15: 45808 | I15: 上海 | J15: 900 | K15: 4957.5 | L15: 577 | Q15: 630 | Y15: -187.3 | Z15: =SUM(J15:Y15) -> 6877.2 | AA15: 8179 | AB15: 654.32 | AC15: 163.58 | AD15: 40.9 | AE15: 8179 | AF15: 573 | AG15: =AB15+AC15+AD15+AF15 -> 1431.8 | AK15: =Z15-AG15-AH15 -> 5445.4 | AL15: 8179 | AM15: 8179 | AN15: =ROUND(AL15*16%,2) -> 1308.64 | AO15: 736.12 | AP15: =ROUND(AL15*0.5%,2) -> 40.9 | AQ15: 16.36 | AS15: =ROUND(AM15*7%,0) -> 573 | AT15: =ROUND(IF(AL15<24366,AL15*1.5%,24366*1.5%),2) -> 122.69 | AU15: =SUM(AN15:AT15) -> 2797.71 | AV15: =VLOOKUP(D15,'[1]202503'!$D$3:$AW$19,46,0) -> 125 | AW15: =AU15+Z15+AI15-AJ15+AV15 -> 9799.91 | BA15: 255 | BB15: =ROUND(AW15+BA15+AY15+AX15,2) -> 10054.91 | BC15: =ROUND(BB15*6%,2) -> 603.29 | BD15: =ROUND(SUM(BB15:BC15),2) -> 10658.2 | BE15: =AV15-5 -> 120 | BF15: 纵向攻击团队
A16: =ROW()-2 -> 14 | B16: 2503 | C16: WB050058 | D16: 周海松 | E16: 320626197411023016 | F16: 45444 | G16: 45808 | I16: 上海 | J16: 800 | K16: 4809 | L16: 264.5 | Q16: 630 | Y16: -639.7 | Z16: =SUM(J16:Y16) -> 5863.8 | AA16: 7384 | AB16: 590.72 | AC16: 147.68 | AD16: 36.92 | AE16: 4848 | AF16: 339 | AG16: =AB16+AC16+AD16+AF16 -> 1114.32 | AK16: =Z16-AG16-AH16 -> 4749.48 | AL16: 7384 | AM16: 4848 | AN16: =ROUND(AL16*16%,2) -> 1181.44 | AO16: =ROUND(AL16*9%,2) -> 664.56 | AP16: =ROUND(AL16*0.5%,2) -> 36.92 | AQ16: 14.77 | AS16: =ROUND(AM16*7%,0) -> 339 | AT16: =ROUND(IF(AL16<24366,AL16*1.5%,24366*1.5%),2) -> 110.76 | AU16: =SUM(AN16:AT16) -> 2347.45 | AV16: =VLOOKUP(D16,'[1]202503'!$D$3:$AW$19,46,0) -> 105 | AW16: =AU16+Z16+AI16-AJ16+AV16 -> 8316.25 | BA16: 255 | BB16: =ROUND(AW16+BA16+AY16+AX16,2) -> 8571.25 | BC16: =ROUND(BB16*6%,2) -> 514.28 | BD16: =ROUND(SUM(BB16:BC16),2) -> 9085.53 | BE16: =AV16-5 -> 100 | BF16: 纵向攻击团队
A17: =ROW()-2 -> 15 | B17: 2503 | D17: 钱运成 | E17: 13058219830615043X | F17: 45717 | G17: 46081 | I17: 上海 | J17: 1030 | K17: 2399.5 | L17: 1025.9 | Q17: 630 | Y17: -595.6 | Z17: =SUM(J17:Y17) -> 4489.8 | AA17: 7384 | AB17: 590.72 | AC17: 147.68 | AD17: 36.92 | AE17: 5000 | AF17: 350 | AG17: =AB17+AC17+AD17+AF17 -> 1125.32 | AK17: =Z17-AG17-AH17 -> 3364.48 | AL17: 7384 | AM17: 5000 | AN17: 1181.44 | AO17: 664.56 | AP17: 36.92 | AQ17: 14.77 | AS17: 350 | AT17: 110.76 | AU17: =SUM(AN17:AT17) -> 2358.45 | AV17: 77 | AW17: =AU17+Z17+AI17-AJ17+AV17 -> 6925.25 | BA17: 255 | BB17: =ROUND(AW17+BA17+AY17+AX17,2) -> 7180.25 | BC17: =ROUND(BB17*6%,2) -> 430.82 | BD17: =ROUND(SUM(BB17:BC17),2) -> 7611.07 | BE17: =AV17-5 -> 72
A18: =ROW()-2 -> 16 | B18: 2503 | D18: 吴婷 | E18: 310113198908164344 | F18: 45717 | G18: 46081 | I18: 上海 | J18: 1400 | K18: 3569 | L18: 1970 | Q18: 630 | Y18: -226 | Z18: =SUM(J18:Y18) -> 7343 | AA18: 14476.16 | AB18: 1158.09 | AC18: 289.52 | AD18: 72.38 | AE18: 14476.16 | AF18: 1013 | AG18: =AB18+AC18+AD18+AF18 -> 2532.99 | AK18: =Z18-AG18-AH18 -> 4810.01 | AL18: 14476.16 | AM18: 14476.16 | AN18: 2316.19 | AO18: 1302.85 | AP18: 72.38 | AQ18: 28.95 | AS18: 1013 | AT18: 217.14 | AU18: =SUM(AN18:AT18) -> 4950.51 | AV18: 134 | AW18: =AU18+Z18+AI18-AJ18+AV18 -> 12427.51 | BA18: 255 | BB18: =ROUND(AW18+BA18+AY18+AX18,2) -> 12682.51 | BC18: =ROUND(BB18*6%,2) -> 760.95 | BD18: =ROUND(SUM(BB18:BC18),2) -> 13443.46 | BE18: =AV18-5 -> 129
A19: =ROW()-2 -> 17 | B19: 2503 | D19: 朱国芹 | E19: 32092319790724512X | F19: 45717 | G19: 46081 | I19: 上海 | J19: 1030 | K19: 2866 | L19: 1660 | Q19: 630 | Y19: -226 | Z19: =SUM(J19:Y19) -> 5960 | AA19: 9821.49 | AB19: 785.72 | AC19: 196.43 | AD19: 49.11 | AE19: 9821.49 | AF19: 688 | AG19: =AB19+AC19+AD19+AF19 -> 1719.26 | AK19: =Z19-AG19-AH19 -> 4240.74 | AL19: 9821.49 | AM19: 9821.49 | AN19: 1571.44 | AO19: 883.94 | AP19: 49.11 | AQ19: 19.64 | AS19: 688 | AT19: 147.32 | AU19: =SUM(AN19:AT19) -> 3359.45 | AV19: 107 | AW19: =AU19+Z19+AI19-AJ19+AV19 -> 9426.45 | BA19: 255 | BB19: =ROUND(AW19+BA19+AY19+AX19,2) -> 9681.45 | BC19: =ROUND(BB19*6%,2) -> 580.89 | BD19: =ROUND(SUM(BB19:BC19),2) -> 10262.34 | BE19: =AV19-5 -> 102
A20: =ROW()-2 -> 18 | B20: 2503 | C20: WB038749 | D20: 叶挺 | E20: 34080219811208081X | F20: 45413 | G20: 45777 | I20: 上海 | J20: 800 | K20: 10854 | L20: 1818.05 | Q20: 630 | Y20: -394.25 | Z20: =SUM(J20:Y20) -> 13707.8 | AA20: 9889 | AB20: 791.12 | AC20: 197.78 | AD20: 49.45 | AE20: 9889 | AF20: 692 | AG20: =AB20+AC20+AD20+AF20 -> 1730.35 | AK20: =Z20-AG20-AH20 -> 11977.45 | AL20: 9889 | AM20: 9889 | AN20: =ROUND(AL20*16%,2) -> 1582.24 | AO20: 890.02 | AP20: =ROUND(AL20*0.5%,2) -> 49.45 | AQ20: 19.78 | AS20: =ROUND(AM20*7%,0) -> 692 | AT20: =ROUND(IF(AL20<24366,AL20*1.5%,24366*1.5%),2) -> 148.34 | AU20: =SUM(AN20:AT20) -> 3381.83 | AV20: =VLOOKUP(D20,[2]布列吉绩效清单!$F$7:$W$27,18,0) -> 262 | AW20: =AU20+Z20+AI20-AJ20+AV20 -> 17351.63 | BA20: 255 | BB20: =ROUND(AW20+BA20+AY20+AX20,2) -> 17606.63 | BC20: =ROUND(BB20*6%,2) -> 1056.4 | BD20: =ROUND(SUM(BB20:BC20),2) -> 18663.03 | BE20: =AV20-5 -> 257
A21: =ROW()-2 -> 19 | B21: 2503 | C21: WB068630 | D21: 王艳 | E21: 342222199402106028 | F21: 45427 | G21: 46521 | I21: 上海 | J21: 800 | K21: 13696.9 | L21: 2852.2 | Q21: 630 | Y21: -491 | Z21: =SUM(J21:Y21) -> 17488.1 | AA21: 7384 | AB21: 590.72 | AC21: 147.68 | AD21: 36.92 | AE21: 2690 | AF21: 188 | AG21: =AB21+AC21+AD21+AF21 -> 963.32 | AK21: =Z21-AG21-AH21 -> 16524.78 | AL21: 7384 | AM21: 2690 | AN21: =ROUND(AL21*16%,2) -> 1181.44 | AO21: =ROUND(AL21*9%,2) -> 664.56 | AP21: =ROUND(AL21*0.5%,2) -> 36.92 | AQ21: 14.77 | AS21: =ROUND(AM21*7%,0) -> 188 | AT21: =ROUND(IF(AL21<24366,AL21*1.5%,24366*1.5%),2) -> 110.76 | AU21: =SUM(AN21:AT21) -> 2196.45 | AV21: =VLOOKUP(D21,[2]布列吉绩效清单!$F$7:$W$27,18,0) -> 337 | AW21: =AU21+Z21+AI21-AJ21+AV21 -> 20021.55 | BA21: 255 | BB21: =ROUND(AW21+BA21+AY21+AX21,2) -> 20276.55 | BC21: =ROUND(BB21*6%,2) -> 1216.59 | BD21: =ROUND(SUM(BB21:BC21),2) -> 21493.14 | BE21: =AV21-5 -> 332
A22: =ROW()-2 -> 20 | B22: 2503 | C22: WB007293 | D22: 王海婷 | E22: 310113198812035548 | F22: 45444 | G22: 45808 | I22: 上海 | J22: 1200 | K22: 5477.61 | L22: 2835.2 | Q22: 630 | Y22: -312.83 | Z22: =SUM(J22:Y22) -> 9829.98 | AA22: 7661 | AB22: 612.88 | AC22: 153.22 | AD22: 38.31 | AE22: 7661 | AF22: 536 | AG22: =AB22+AC22+AD22+AF22 -> 1340.41 | AK22: =Z22-AG22-AH22 -> 8489.57 | AL22: 7661 | AM22: 7661 | AN22: =ROUND(AL22*16%,2) -> 1225.76 | AO22: 689.5 | AP22: =ROUND(AL22*0.5%,2) -> 38.31 | AQ22: 15.32 | AS22: =ROUND(AM22*7%,0) -> 536 | AT22: =ROUND(IF(AL22<24366,AL22*1.5%,24366*1.5%),2) -> 114.92 | AU22: =SUM(AN22:AT22) -> 2619.81 | AV22: =VLOOKUP(D22,[2]布列吉绩效清单!$F$7:$W$27,18,0) -> 184 | AW22: =AU22+Z22+AI22-AJ22+AV22 -> 12633.79 | BA22: 255 | BB22: =ROUND(AW22+BA22+AY22+AX22,2) -> 12888.79 | BC22: =ROUND(BB22*6%,2) -> 773.33 | BD22: =ROUND(SUM(BB22:BC22),2) -> 13662.12 | BE22: =AV22-5 -> 179
A23: =ROW()-2 -> 21 | B23: 2503 | C23: WB023775 | D23: 张杰 | E23: 31011319860815411X | F23: 45444 | G23: 45808 | I23: 上海 | J23: 1300 | K23: 8238.38 | L23: 6064.7 | Q23: 630 | Y23: -75.13 | Z23: =SUM(J23:Y23) -> 16157.95 | AA23: 17497 | AB23: 1399.76 | AC23: 349.94 | AD23: 87.49 | AE23: 17497 | AF23: 1225 | AG23: =AB23+AC23+AD23+AF23 -> 3062.19 | AK23: =Z23-AG23-AH23 -> 13095.76 | AL23: 17497 | AM23: 17497 | AN23: =ROUND(AL23*16%,2) -> 2799.52 | AO23: 1574.74 | AP23: =ROUND(AL23*0.5%,2) -> 87.49 | AQ23: 34.99 | AS23: =ROUND(AM23*7%,0) -> 1225 | AT23: =ROUND(IF(AL23<24366,AL23*1.5%,24366*1.5%),2) -> 262.46 | AU23: =SUM(AN23:AT23) -> 5984.2 | AV23: =VLOOKUP(D23,[2]布列吉绩效清单!$F$7:$W$27,18,0) -> 311 | AW23: =AU23+Z23+AI23-AJ23+AV23 -> 22453.15 | BA23: 255 | BB23: =ROUND(AW23+BA23+AY23+AX23,2) -> 22708.15 | BC23: =ROUND(BB23*6%,2) -> 1362.49 | BD23: =ROUND(SUM(BB23:BC23),2) -> 24070.64 | BE23: =AV23-5 -> 306
A24: =ROW()-2 -> 22 | B24: 2503 | C24: WB030437 | D24: 李娟 | E24: 310230197802072529 | F24: 45444 | G24: 45808 | I24: 上海 | J24: 1030 | K24: 2872.51 | L24: 1658.7 | Q24: 630 | Y24: -332.83 | Z24: =SUM(J24:Y24) -> 5858.38 | AA24: 10038 | AB24: 803.04 | AC24: 200.76 | AD24: 50.19 | AE24: 10038 | AF24: 703 | AG24: =AB24+AC24+AD24+AF24 -> 1756.99 | AK24: =Z24-AG24-AH24 -> 4101.39 | AL24: 10038 | AM24: 10038 | AN24: =ROUND(AL24*16%,2) -> 1606.08 | AO24: =ROUND(AL24*9%,2) -> 903.42 | AP24: =ROUND(AL24*0.5%,2) -> 50.19 | AQ24: 20.08 | AS24: =ROUND(AM24*7%,0) -> 703 | AT24: =ROUND(IF(AL24<24366,AL24*1.5%,24366*1.5%),2) -> 150.57 | AU24: =SUM(AN24:AT24) -> 3433.34 | AV24: =VLOOKUP(D24,[2]布列吉绩效清单!$F$7:$W$27,18,0) -> 105 | AW24: =AU24+Z24+AI24-AJ24+AV24 -> 9396.72 | AX24: 1780.28 | AZ24: 2月垫付保障补差，3月已收 | BA24: 255 | BB24: =ROUND(AW24+BA24+AY24+AX24,2) -> 11432 | BC24: =ROUND(BB24*6%,2) -> 685.92 | BD24: =ROUND(SUM(BB24:BC24),2) -> 12117.92 | BE24: =AV24-5 -> 100
A25: =ROW()-2 -> 23 | B25: 2503 | C25: WB045407 | D25: 王佳睿 | E25: 320681200309147011 | F25: 45444 | G25: 45808 | I25: 上海 | J25: 900 | K25: 6435.41 | L25: 2184.4 | Q25: 630 | Y25: -1362.83 | Z25: =SUM(J25:Y25) -> 8786.98 | AA25: 7384 | AB25: 590.72 | AC25: 147.68 | AD25: 36.92 | AE25: 7375 | AF25: 516 | AG25: =AB25+AC25+AD25+AF25 -> 1291.32 | AK25: =Z25-AG25-AH25 -> 7495.66 | AL25: 7384 | AM25: 7375 | AN25: =ROUND(AL25*16%,2) -> 1181.44 | AO25: 664.56 | AP25: =ROUND(AL25*0.5%,2) -> 36.92 | AQ25: 14.77 | AS25: =ROUND(AM25*7%,0) -> 516 | AT25: =ROUND(IF(AL25<24366,AL25*1.5%,24366*1.5%),2) -> 110.76 | AU25: =SUM(AN25:AT25) -> 2524.45 | AV25: =VLOOKUP(D25,[2]布列吉绩效清单!$F$7:$W$27,18,0) -> 163 | AW25: =AU25+Z25+AI25-AJ25+AV25 -> 11474.43 | BA25: 255 | BB25: =ROUND(AW25+BA25+AY25+AX25,2) -> 11729.43 | BC25: =ROUND(BB25*6%,2) -> 703.77 | BD25: =ROUND(SUM(BB25:BC25),2) -> 12433.2 | BE25: =AV25-5 -> 158
A26: =ROW()-2 -> 24 | B26: 2503 | C26: WB033013 | D26: 朱娟 | E26: 310113198511225727 | F26: 45444 | G26: 45808 | I26: 上海 | J26: 970 | K26: 15690.86 | L26: 1436.8 | Q26: 630 | Y26: -984.61 | Z26: =SUM(J26:Y26) -> 17743.05 | AA26: 12999 | AB26: 1039.92 | AC26: 259.98 | AD26: 65 | AE26: 12999 | AF26: 910 | AG26: =AB26+AC26+AD26+AF26 -> 2274.9 | AK26: =Z26-AG26-AH26 -> 15468.15 | AL26: 12999 | AM26: 12999 | AN26: =ROUND(AL26*16%,2) -> 2079.84 | AO26: 1169.92 | AP26: =ROUND(AL26*0.5%,2) -> 65 | AQ26: 26 | AS26: =ROUND(AM26*7%,0) -> 910 | AT26: =ROUND(IF(AL26<24366,AL26*1.5%,24366*1.5%),2) -> 194.99 | AU26: =SUM(AN26:AT26) -> 4445.75 | AV26: =VLOOKUP(D26,[2]布列吉绩效清单!$F$7:$W$27,18,0) -> 342 | AW26: =AU26+Z26+AI26-AJ26+AV26 -> 22530.8 | BA26: 255 | BB26: =ROUND(AW26+BA26+AY26+AX26,2) -> 22785.8 | BC26: =ROUND(BB26*6%,2) -> 1367.15 | BD26: =ROUND(SUM(BB26:BC26),2) -> 24152.95 | BE26: =AV26-5 -> 337
A27: =ROW()-2 -> 25 | B27: 2503 | C27: WB054275 | D27: 姚嘉豪 | E27: 310113199804301716 | F27: 45444 | G27: 45808 | I27: 上海 | J27: 800 | K27: 3022.94 | L27: 1408.9 | Q27: 630 | Y27: -219.74 | Z27: =SUM(J27:Y27) -> 5642.1 | AA27: 7384 | AB27: 590.72 | AC27: 147.68 | AD27: 36.92 | AE27: 3607 | AF27: 252 | AG27: =AB27+AC27+AD27+AF27 -> 1027.32 | AK27: =Z27-AG27-AH27 -> 4614.78 | AL27: 7384 | AM27: 3607 | AN27: =ROUND(AL27*16%,2) -> 1181.44 | AO27: =ROUND(AL27*9%,2) -> 664.56 | AP27: =ROUND(AL27*0.5%,2) -> 36.92 | AQ27: 14.77 | AS27: =ROUND(AM27*7%,0) -> 252 | AT27: =ROUND(IF(AL27<24366,AL27*1.5%,24366*1.5%),2) -> 110.76 | AU27: =SUM(AN27:AT27) -> 2260.45 | AV27: =VLOOKUP(D27,[2]布列吉绩效清单!$F$7:$W$27,18,0) -> 100 | AW27: =AU27+Z27+AI27-AJ27+AV27 -> 8002.55 | BA27: 255 | BB27: =ROUND(AW27+BA27+AY27+AX27,2) -> 8257.55 | BC27: =ROUND(BB27*6%,2) -> 495.45 | BD27: =ROUND(SUM(BB27:BC27),2) -> 8753 | BE27: =AV27-5 -> 95
A28: =ROW()-2 -> 26 | B28: 2503 | C28: WB007248 | D28: 魏玲 | E28: 310108198612173363 | F28: 45444 | G28: 45808 | I28: 上海 | J28: 1030 | K28: 9760.8 | L28: 2010.5 | Q28: 630 | Y28: 0 | Z28: =SUM(J28:Y28) -> 13431.3 | AA28: 7384 | AB28: 590.72 | AC28: 147.68 | AD28: 36.92 | AE28: 6207 | AF28: 434 | AG28: =AB28+AC28+AD28+AF28 -> 1209.32 | AK28: =Z28-AG28-AH28 -> 12221.98 | AL28: 7384 | AM28: 6207 | AN28: =ROUND(AL28*16%,2) -> 1181.44 | AO28: =ROUND(AL28*9%,2) -> 664.56 | AP28: =ROUND(AL28*0.5%,2) -> 36.92 | AQ28: 14.77 | AS28: =ROUND(AM28*7%,0) -> 434 | AT28: =ROUND(IF(AL28<24366,AL28*1.5%,24366*1.5%),2) -> 110.76 | AU28: =SUM(AN28:AT28) -> 2442.45 | AV28: =VLOOKUP(D28,[2]布列吉绩效清单!$F$7:$W$27,18,0) -> 256 | AW28: =AU28+Z28+AI28-AJ28+AV28 -> 16129.75 | AX28: 805.42 | AZ28: 2月垫付保障补差，3月已收 | BA28: 255 | BB28: =ROUND(AW28+BA28+AY28+AX28,2) -> 17190.17 | BC28: =ROUND(BB28*6%,2) -> 1031.41 | BD28: =ROUND(SUM(BB28:BC28),2) -> 18221.58 | BE28: =AV28-5 -> 251
A29: =ROW()-2 -> 27 | B29: 2503 | C29: WB007254 | D29: 朱焱炎 | E29: 320681198812140829 | F29: 45444 | G29: 45808 | I29: 上海 | J29: 950 | K29: 1887.6 | L29: 1239.5 | Q29: 630 | Y29: -93.11 | Z29: =SUM(J29:Y29) -> 4613.99 | AA29: 7384 | AB29: 590.72 | AC29: 147.68 | AD29: 36.92 | AE29: 4997 | AF29: 350 | AG29: =AB29+AC29+AD29+AF29 -> 1125.32 | AK29: =Z29-AG29-AH29 -> 3488.67 | AL29: 7384 | AM29: 4997 | AN29: =ROUND(AL29*16%,2) -> 1181.44 | AO29: =ROUND(AL29*9%,2) -> 664.56 | AP29: =ROUND(AL29*0.5%,2) -> 36.92 | AQ29: 14.77 | AS29: =ROUND(AM29*7%,0) -> 350 | AT29: =ROUND(IF(AL29<24366,AL29*1.5%,24366*1.5%),2) -> 110.76 | AU29: =SUM(AN29:AT29) -> 2358.45 | AV29: =VLOOKUP(D29,[2]布列吉绩效清单!$F$7:$W$27,18,0) -> 80 | AW29: =AU29+Z29+AI29-AJ29+AV29 -> 7052.44 | AX29: 1148.07 | AZ29: 2月垫付保障补差，3月已收 | BA29: 255 | BB29: =ROUND(AW29+BA29+AY29+AX29,2) -> 8455.51 | BC29: =ROUND(BB29*6%,2) -> 507.33 | BD29: =ROUND(SUM(BB29:BC29),2) -> 8962.84 | BE29: =AV29-5 -> 75
A30: =ROW()-2 -> 28 | B30: 2503 | C30: WB022966 | D30: 赵杭顺 | E30: 310102198702193618 | F30: 45444 | G30: 45808 | I30: 上海 | J30: 1030 | K30: 14481.1 | L30: 2710.5 | Q30: 630 | Y30: 0 | Z30: =SUM(J30:Y30) -> 18851.6 | AA30: 11395 | AB30: 911.6 | AC30: 227.9 | AD30: 56.98 | AE30: 11395 | AF30: 798 | AG30: =AB30+AC30+AD30+AF30 -> 1994.48 | AK30: =Z30-AG30-AH30 -> 16857.12 | AL30: 11395 | AM30: 11395 | AN30: =ROUND(AL30*16%,2) -> 1823.2 | AO30: 1025.56 | AP30: =ROUND(AL30*0.5%,2) -> 56.98 | AQ30: 22.79 | AS30: =ROUND(AM30*7%,0) -> 798 | AT30: =ROUND(IF(AL30<24366,AL30*1.5%,24366*1.5%),2) -> 170.93 | AU30: =SUM(AN30:AT30) -> 3897.46 | AV30: =VLOOKUP(D30,[2]布列吉绩效清单!$F$7:$W$27,18,0) -> 364 | AW30: =AU30+Z30+AI30-AJ30+AV30 -> 23113.06 | BA30: 255 | BB30: =ROUND(AW30+BA30+AY30+AX30,2) -> 23368.06 | BC30: =ROUND(BB30*6%,2) -> 1402.08 | BD30: =ROUND(SUM(BB30:BC30),2) -> 24770.14 | BE30: =AV30-5 -> 359
A31: =ROW()-2 -> 29 | B31: 2503 | C31: WB016859 | D31: 陆燕 | E31: 310113197802064324 | F31: 45444 | G31: 45808 | I31: 上海 | J31: 1400 | K31: 12845.6 | L31: 829.5 | Q31: 630 | Y31: -2033.81 | Z31: =SUM(J31:Y31) -> 13671.29 | AA31: 7384 | AB31: 590.72 | AC31: 147.68 | AD31: 36.92 | AE31: 6844 | AF31: 479 | AG31: =AB31+AC31+AD31+AF31 -> 1254.32 | AK31: =Z31-AG31-AH31 -> 12416.97 | AL31: 7384 | AM31: 6844 | AN31: =ROUND(AL31*16%,2) -> 1181.44 | AO31: =ROUND(AL31*9%,2) -> 664.56 | AP31: =ROUND(AL31*0.5%,2) -> 36.92 | AQ31: 14.77 | AS31: =ROUND(AM31*7%,0) -> 479 | AT31: =ROUND(IF(AL31<24366,AL31*1.5%,24366*1.5%),2) -> 110.76 | AU31: =SUM(AN31:AT31) -> 2487.45 | AV31: =VLOOKUP(D31,[2]布列吉绩效清单!$F$7:$W$27,18,0) -> 261 | AW31: =AU31+Z31+AI31-AJ31+AV31 -> 16419.74 | BA31: 255 | BB31: =ROUND(AW31+BA31+AY31+AX31,2) -> 16674.74 | BC31: =ROUND(BB31*6%,2) -> 1000.48 | BD31: =ROUND(SUM(BB31:BC31),2) -> 17675.22 | BE31: =AV31-5 -> 256
A32: =ROW()-2 -> 30 | B32: 2503 | C32: WB016826 | D32: 成瀛 | E32: 140103198304204830 | F32: 45444 | G32: 45808 | I32: 上海 | J32: 1300 | K32: 7607.6 | L32: 2057.5 | Q32: 630 | Y32: -47.31 | Z32: =SUM(J32:Y32) -> 11547.79 | AA32: 7384 | AB32: 590.72 | AC32: 147.68 | AD32: 36.92 | AE32: 5131 | AF32: 359 | AG32: =AB32+AC32+AD32+AF32 -> 1134.32 | AK32: =Z32-AG32-AH32 -> 10413.47 | AL32: 7384 | AM32: 5131 | AN32: =ROUND(AL32*16%,2) -> 1181.44 | AO32: =ROUND(AL32*9%,2) -> 664.56 | AP32: =ROUND(AL32*0.5%,2) -> 36.92 | AQ32: 14.77 | AS32: =ROUND(AM32*7%,0) -> 359 | AT32: =ROUND(IF(AL32<24366,AL32*1.5%,24366*1.5%),2) -> 110.76 | AU32: =SUM(AN32:AT32) -> 2367.45 | AV32: =VLOOKUP(D32,[2]布列吉绩效清单!$F$7:$W$27,18,0) -> 218 | AW32: =AU32+Z32+AI32-AJ32+AV32 -> 14133.24 | AX32: 307.32 | AZ32: 2月垫付保障补差，3月已收 | BA32: 255 | BB32: =ROUND(AW32+BA32+AY32+AX32,2) -> 14695.56 | BC32: =ROUND(BB32*6%,2) -> 881.73 | BD32: =ROUND(SUM(BB32:BC32),2) -> 15577.29 | BE32: =AV32-5 -> 213
A33: =ROW()-2 -> 31 | B33: 2503 | C33: WB044433 | D33: 张枚 | E33: 340223199003157228 | F33: 45444 | G33: 45808 | I33: 上海 | J33: 1030 | K33: 5722.6 | L33: 1118.6 | Q33: 630 | Y33: -350 | Z33: =SUM(J33:Y33) -> 8151.2 | AA33: 7384 | AB33: 590.72 | AC33: 147.68 | AD33: 36.92 | AE33: 4082 | AF33: 286 | AG33: =AB33+AC33+AD33+AF33 -> 1061.32 | AK33: =Z33-AG33-AH33 -> 7089.88 | AL33: 7384 | AM33: 4082 | AN33: =ROUND(AL33*16%,2) -> 1181.44 | AO33: =ROUND(AL33*9%,2) -> 664.56 | AP33: =ROUND(AL33*0.5%,2) -> 36.92 | AQ33: 14.77 | AS33: =ROUND(AM33*7%,0) -> 286 | AT33: =ROUND(IF(AL33<24366,AL33*1.5%,24366*1.5%),2) -> 110.76 | AU33: =SUM(AN33:AT33) -> 2294.45 | AV33: =VLOOKUP(D33,[2]布列吉绩效清单!$F$7:$W$27,18,0) -> 150 | AW33: =AU33+Z33+AI33-AJ33+AV33 -> 10595.65 | BA33: 255 | BB33: =ROUND(AW33+BA33+AY33+AX33,2) -> 10850.65 | BC33: =ROUND(BB33*6%,2) -> 651.04 | BD33: =ROUND(SUM(BB33:BC33),2) -> 11501.69 | BE33: =AV33-5 -> 145
A34: =ROW()-2 -> 32 | B34: 2503 | C34: WB039094 | D34: 张欢 | E34: 340321199602189283 | F34: 45444 | G34: 45808 | I34: 上海 | J34: 950 | K34: 7971.6 | L34: 1207.4 | Q34: 630 | Y34: -45 | Z34: =SUM(J34:Y34) -> 10714 | AA34: 7384 | AB34: 590.72 | AC34: 147.68 | AD34: 36.92 | AE34: 4035 | AF34: 282 | AG34: =AB34+AC34+AD34+AF34 -> 1057.32 | AK34: =Z34-AG34-AH34 -> 9656.68 | AL34: 7384 | AM34: 4035 | AN34: =ROUND(AL34*16%,2) -> 1181.44 | AO34: =ROUND(AL34*9%,2) -> 664.56 | AP34: =ROUND(AL34*0.5%,2) -> 36.92 | AQ34: 14.77 | AS34: =ROUND(AM34*7%,0) -> 282 | AT34: =ROUND(IF(AL34<24366,AL34*1.5%,24366*1.5%),2) -> 110.76 | AU34: =SUM(AN34:AT34) -> 2290.45 | AV34: =VLOOKUP(D34,[2]布列吉绩效清单!$F$7:$W$27,18,0) -> 202 | AW34: =AU34+Z34+AI34-AJ34+AV34 -> 13206.45 | BA34: 255 | BB34: =ROUND(AW34+BA34+AY34+AX34,2) -> 13461.45 | BC34: =ROUND(BB34*6%,2) -> 807.69 | BD34: =ROUND(SUM(BB34:BC34),2) -> 14269.14 | BE34: =AV34-5 -> 197
A35: =ROW()-2 -> 33 | B35: 2503 | C35: WB009624 | D35: 金霞 | E35: 310113198309114628 | F35: 45444 | G35: 45808 | I35: 上海 | J35: 1030 | K35: 3594 | L35: 785.5 | Q35: 369.27 | X35: 547.87 | Y35: -1977.05 | Z35: =SUM(J35:Y35) -> 4349.59 | AA35: 7384 | AB35: 590.72 | AC35: 147.68 | AD35: 36.92 | AE35: 7287 | AF35: 510 | AG35: =AB35+AC35+AD35+AF35 -> 1285.32 | AK35: =Z35-AG35-AH35 -> 3064.27 | AL35: 7384 | AM35: 7287 | AN35: =ROUND(AL35*16%,2) -> 1181.44 | AO35: =ROUND(AL35*9%,2) -> 664.56 | AP35: =ROUND(AL35*0.5%,2) -> 36.92 | AQ35: 14.77 | AS35: =ROUND(AM35*7%,0) -> 510 | AT35: =ROUND(IF(AL35<24366,AL35*1.5%,24366*1.5%),2) -> 110.76 | AU35: =SUM(AN35:AT35) -> 2518.45 | AV35: =VLOOKUP(D35,[2]布列吉绩效清单!$F$7:$W$27,18,0) -> 69 | AW35: =AU35+Z35+AI35-AJ35+AV35 -> 6937.04 | AY35: =-X35 -> -547.87 | AZ35: 3月垫付保障补差，4月收 | BA35: 255 | BB35: =ROUND(AW35+BA35+AY35+AX35,2) -> 6644.17 | BC35: =ROUND(BB35*6%,2) -> 398.65 | BD35: =ROUND(SUM(BB35:BC35),2) -> 7042.82 | BE35: =AV35-5 -> 64
A36: =ROW()-2 -> 34 | B36: 2503 | C36: WB009626 | D36: 殷颖 | E36: 310109198006192026 | F36: 45444 | G36: 45808 | I36: 上海 | J36: 1300 | K36: 1940 | L36: 1010.2 | Q36: 630 | X36: 1339.93 | Y36: -1660.81 | Z36: =SUM(J36:Y36) -> 4559.32 | AA36: 7384 | AB36: 590.72 | AC36: 147.68 | AD36: 36.92 | AE36: 6558 | AF36: 459 | AG36: =AB36+AC36+AD36+AF36 -> 1234.32 | AK36: =Z36-AG36-AH36 -> 3325 | AL36: 7384 | AM36: 6558 | AN36: =ROUND(AL36*16%,2) -> 1181.44 | AO36: =ROUND(AL36*9%,2) -> 664.56 | AP36: =ROUND(AL36*0.5%,2) -> 36.92 | AQ36: 14.77 | AS36: =ROUND(AM36*7%,0) -> 459 | AT36: =ROUND(IF(AL36<24366,AL36*1.5%,24366*1.5%),2) -> 110.76 | AU36: =SUM(AN36:AT36) -> 2467.45 | AV36: =VLOOKUP(D36,[2]布列吉绩效清单!$F$7:$W$27,18,0) -> 52 | AW36: =AU36+Z36+AI36-AJ36+AV36 -> 7078.77 | AX36: 79.48 | AY36: =-X36 -> -1339.93 | AZ36: 3月垫付保障补差，4月收，2月垫付保障补差，3月已收 | BA36: 255 | BB36: =ROUND(AW36+BA36+AY36+AX36,2) -> 6073.32 | BC36: =ROUND(BB36*6%,2) -> 364.4 | BD36: =ROUND(SUM(BB36:BC36),2) -> 6437.72 | BE36: =AV36-5 -> 47
A37: =ROW()-2 -> 35 | B37: 2503 | C37: WB009627 | D37: 夏士梅 | E37: 310113197707080027 | F37: 45444 | G37: 45808 | I37: 上海 | J37: 1030 | K37: 4966 | L37: 1699.5 | Q37: 601.03 | Y37: -62.41 | Z37: =SUM(J37:Y37) -> 8234.12 | AA37: 7399 | AB37: 591.92 | AC37: 147.98 | AD37: 37 | AE37: 7399 | AF37: 518 | AG37: =AB37+AC37+AD37+AF37 -> 1294.9 | AK37: =Z37-AG37-AH37 -> 6939.22 | AL37: 7399 | AM37: 7399 | AN37: =ROUND(AL37*16%,2) -> 1183.84 | AO37: 665.92 | AP37: =ROUND(AL37*0.5%,2) -> 37 | AQ37: 14.8 | AS37: =ROUND(AM37*7%,0) -> 518 | AT37: =ROUND(IF(AL37<24366,AL37*1.5%,24366*1.5%),2) -> 110.99 | AU37: =SUM(AN37:AT37) -> 2530.55 | AV37: =VLOOKUP(D37,[2]布列吉绩效清单!$F$7:$W$27,18,0) -> 153 | AW37: =AU37+Z37+AI37-AJ37+AV37 -> 10917.67 | BA37: 255 | BB37: =ROUND(AW37+BA37+AY37+AX37,2) -> 11172.67 | BC37: =ROUND(BB37*6%,2) -> 670.36 | BD37: =ROUND(SUM(BB37:BC37),2) -> 11843.03 | BE37: =AV37-5 -> 148
A38: =ROW()-2 -> 36 | B38: 2503 | C38: WB009631 | D38: 杨晨晖 | E38: 310113199401265319 | F38: 45444 | G38: 45808 | I38: 上海 | J38: 1030 | K38: 4450.4 | L38: 1290 | Q38: 630 | Y38: -365.05 | Z38: =SUM(J38:Y38) -> 7035.35 | AA38: 7384 | AB38: 590.72 | AC38: 147.68 | AD38: 36.92 | AE38: 7155 | AF38: 501 | AG38: =AB38+AC38+AD38+AF38 -> 1276.32 | AK38: =Z38-AG38-AH38 -> 5759.03 | AL38: 7384 | AM38: 7155 | AN38: =ROUND(AL38*16%,2) -> 1181.44 | AO38: =ROUND(AL38*9%,2) -> 664.56 | AP38: =ROUND(AL38*0.5%,2) -> 36.92 | AQ38: 14.77 | AS38: =ROUND(AM38*7%,0) -> 501 | AT38: =ROUND(IF(AL38<24366,AL38*1.5%,24366*1.5%),2) -> 110.76 | AU38: =SUM(AN38:AT38) -> 2509.45 | AV38: =VLOOKUP(D38,[2]布列吉绩效清单!$F$7:$W$27,18,0) -> 128 | AW38: =AU38+Z38+AI38-AJ38+AV38 -> 9672.8 | BA38: 255 | BB38: =ROUND(AW38+BA38+AY38+AX38,2) -> 9927.8 | BC38: =ROUND(BB38*6%,2) -> 595.67 | BD38: =ROUND(SUM(BB38:BC38),2) -> 10523.47 | BE38: =AV38-5 -> 123
A39: =ROW()-2 -> 37 | B39: 2503 | C39: WB030237 | D39: 顾文君 | E39: 310110198605095645 | F39: 45444 | G39: 45808 | I39: 上海 | J39: 1300 | K39: 8232 | L39: 1615.7 | Q39: 630 | Y39: -1700 | Z39: =SUM(J39:Y39) -> 10077.7 | AA39: 13189 | AB39: 1055.12 | AC39: 263.78 | AD39: 65.95 | AE39: 13189 | AF39: 923 | AG39: =AB39+AC39+AD39+AF39 -> 2307.85 | AK39: =Z39-AG39-AH39 -> 7769.85 | AL39: 13189 | AM39: 13189 | AN39: =ROUND(AL39*16%,2) -> 2110.24 | AO39: 1187.02 | AP39: =ROUND(AL39*0.5%,2) -> 65.95 | AQ39: 26.38 | AS39: =ROUND(AM39*7%,0) -> 923 | AT39: =ROUND(IF(AL39<24366,AL39*1.5%,24366*1.5%),2) -> 197.84 | AU39: =SUM(AN39:AT39) -> 4510.43 | AV39: =VLOOKUP(D39,[2]布列吉绩效清单!$F$7:$W$27,18,0) -> 189 | AW39: =AU39+Z39+AI39-AJ39+AV39 -> 14777.13 | BA39: 255 | BB39: =ROUND(AW39+BA39+AY39+AX39,2) -> 15032.13 | BC39: =ROUND(BB39*6%,2) -> 901.93 | BD39: =ROUND(SUM(BB39:BC39),2) -> 15934.06 | BE39: =AV39-5 -> 184
A40: =ROW()-2 -> 38 | B40: 2503 | C40: WB016896 | D40: 朱琳 | E40: 310115197811118649 | F40: 45444 | G40: 45808 | I40: 上海 | J40: 1080 | K40: 0 | L40: 3656.7 | Q40: 0 | Y40: 0 | Z40: =SUM(J40:Y40) -> 4736.7 | AA40: 9758 | AB40: 780.64 | AC40: 195.16 | AD40: 48.79 | AE40: 9758 | AF40: 683 | AG40: =AB40+AC40+AD40+AF40 -> 1707.59 | AK40: =Z40-AG40-AH40 -> 3029.11 | AL40: 9758 | AM40: 9758 | AN40: =ROUND(AL40*16%,2) -> 1561.28 | AO40: =ROUND(AL40*9%,2) -> 878.22 | AP40: =ROUND(AL40*0.5%,2) -> 48.79 | AQ40: 19.52 | AS40: =ROUND(AM40*7%,0) -> 683 | AT40: =ROUND(IF(AL40<24366,AL40*1.5%,24366*1.5%),2) -> 146.37 | AU40: =SUM(AN40:AT40) -> 3337.18 | AV40: =VLOOKUP(D40,[2]布列吉绩效清单!$F$7:$W$27,18,0) -> 95 | AW40: =AU40+Z40+AI40-AJ40+AV40 -> 8168.88 | BA40: 60 | BB40: =ROUND(AW40+BA40+AY40+AX40,2) -> 8228.88 | BC40: =ROUND(BB40*6%,2) -> 493.73 | BD40: =ROUND(SUM(BB40:BC40),2) -> 8722.61 | BE40: =AV40-5 -> 90
...

Sheet 对账单
A1: 科目 | B1: 手工账单 | C1: 速创账单 | D1: 155 | E1: 预收一次性 | F1: 工会费 | G1: 本月垫付，下月收 | H1: 本月多收，下月退 | I1: 合计 | J1: 差异
A2: 管理费 | B2: ='202503'!BC45 -> 28786.73 | C2: =系统!E54 -> 31678.16 | D2: =155*37 -> 5735 | I2: =SUM(C2:G2) -> 37413.16 | J2: =B2-C2 -> -2891.43
A3: 风险费 | B3: ='202503'!BA45 -> 9495 | C3: 0 | I3: =SUM(C3:G3) -> 0 | J3: =B3-C3 -> 9495
A4: 个人四金 | B4: ='202503'!AG45 -> 60900.98 | C4: =系统!V54 -> 60900.98 | I4: =SUM(C4:G4) -> 60900.98 | J4: =B4-C4 -> 0
A5: 公司四金 | B5: ='202503'!AU45 -> 120916.13 | C5: =系统!O54 -> 120916.13 | E5: =B10 -> 4120.57 | I5: =SUM(C5:E5) -> 125036.7 | J5: =B5-C5 -> 0
A6: 工伤退费 | I6: =SUM(C6:G6) -> 0 | J6: =B6-C6 -> 0
A7: 代发工资 | B7: ='202503'!Z45-'202503'!AG45 -> 279914.87 | C7: =系统!W54 -> 279724.87 | D7: =38*5 -> 190 | I7: =SUM(C7:G7) -> 279914.87 | J7: =B7-C7 -> 190
A8: 3月垫付 | B8: ='202503'!AY45 -> -1887.8 | I8: =SUM(C8:G8) -> 0 | J8: =B8-C8 -> -1887.8
A9: 工会费 | B9: ='202503'!AV45 -> 6319 | F9: =B9 -> 6319 | G9: =B8 -> -1887.8 | I9: =SUM(C9:G9) -> 4431.2 | J9: =B9-C9 -> 6319
A10: 2月垫付，3月收 | B10: ='202503'!AX45 -> 4120.57 | I10: =SUM(C10:G10) -> 0 | J10: =B10-C10 -> 4120.57
A11: 小计 | B11: =SUM(B2:B10) -> 508565.48 | C11: =SUM(C2:C10) -> 493220.14 | D11: =SUM(D2:D10) -> 5925 | E11: =E5 -> 4120.57 | F11: =F9 -> 6319 | G11: =G9 -> -1887.8 | H11: =H9 -> 0 | I11: =SUM(C11:H11) -> 507696.91
A12: 附加税
A13: 增值税 | D13: =ROUND((D11+D12)*6%,2) -> 355.5 | E13: =ROUND((E11+E12)*6%,2) -> 247.23 | F13: =ROUND((F11+F12)*6%,2) -> 379.14 | G13: =ROUND((G11+G12)*6%,2) -> -113.27 | H13: =ROUND((H11+H12)*6%,2) -> 0 | I13: =SUM(C13:G13) -> 868.6
A14: 总计 | B14: =SUM(B11:B13) -> 508565.48 | C14: =SUM(C11:C13) -> 493220.14 | D14: =SUM(D11:D13) -> 6280.5 | E14: =E11+E13 -> 4367.8 | F14: =SUM(F11:F13) -> 6698.14 | G14: =SUM(G11:G13) -> -2001.07 | H14: =SUM(H11:H13) -> 0 | I14: =SUM(C14:H14) -> 508565.51
A15: 给客户账单金额 | I15: =B14 -> 508565.48
A16: 差异 | I16: =I15-I14 -> -0.03
A17: 不含税差异 | I17: =ROUND(I16/1.06,2) -> -0.03

Sheet 系统
A1: 200070
A2: 寄：梅园路77号人才大厦
B3: 中国电信股份有限公司上海分公司 王慧珏 收
D6: 上海外服布列吉科技有限公司
C7: Shanghai Foreign Service Bridge Technology Co,Ltd.
E9: 收款通知书
E10: ADVISE ON COLLECTION
E11: 2025年03月
A13: 公司名称：中国电信股份有限公司上海分公司 | J13: 帐单号：202503CH6593507
A14: 序号 | B14: 姓名 | C14: 发生年月 | D14: 入职日期 | E14: 管理费 | F14: 当月社保基数 | G14: 当月公积金基数 | H14: 社保类 公司支付 Social Insurance Premiums Paid by Employer | N14: 公积金类 公司支付 Provident Fund Paid by Employer | O14: 公司合计 | P14: 社保类 个人支付 Social Insurance Premiums Paid by Employee | U14: 公积金类 个人支付 Provident Fund Paid by Employee | V14: 个人合计 | W14: 代办薪酬 | X14: 其他 | Y14: 总计 | Z14: 备注 | AA14: 外服工号 | AB14: 证件号码 | AC14: 应纳税金额 | AD14: 税率 | AE14: 增值税
A15: S/N | B15: Name | C15: YYYYMM | D15: Employment Start Date | E15: Adm Fee | F15: Social Insurance Base Amount of Current Month | G15: Provident Fund Base Amount of Current Month | H15: 养老保险 Endowment | I15: 医疗保险 Medical | J15: 失业保险 Unemploy-ment | K15: 工伤保险 Employment Injury | L15: 医疗生育保险 Medical Maternity | M15: 保障金 Disabled people&Back pay Fund | N15: 公积金 Provident Fund | O15: Subtotal of Employer Payment | P15: 养老保险 Endowment | Q15: 医疗保险 Medical | R15: 失业保险 Unemploy-ment | S15: 工伤保险 Employment Injury | T15: 医疗生育保险 Medical Maternity | U15: 公积金 Provident Fund | V15: Subtotal of Personal Payment | W15: Agency of Wage Payment | X15: Others | Y15: Total | Z15: Remarks | AA15: SFSC ID | AB15: ID Card | AC15: Taxable Amount | AD15: Tax Rate | AE15: VAT
A16: 1 | B16: 陈云 | C16: 202503 | D16: 2024-06-01 | E16: 812.73 | F16: 11367 | G16: 11367 | H16: 1818.72 | I16: 1023.04 | J16: 56.84 | K16: 22.73 | M16: 170.51 | N16: 796 | O16: =SUM(H16:N16) -> 3887.84 | P16: 909.36 | Q16: 227.34 | R16: 56.84 | U16: 796 | V16: =SUM(P16:U16) -> 1989.54 | W16: 5901.56 | Y16: =SUM(E16,O16,V16:X16) -> 12591.67 | AA16: 5545723 | AB16: 320681198911257029 | AC16: 11878.95 | AD16: 6% | AE16: 712.72
A17: 2 | B17: 成瀛 | C17: 202503 | D17: 2024-06-01 | E17: 940.62 | F17: 7384 | G17: 5131 | H17: 1181.44 | I17: 664.56 | J17: 36.92 | K17: 14.77 | M17: 110.76 | N17: 359 | O17: =SUM(H17:N17) -> 2367.45 | P17: 590.72 | Q17: 147.68 | R17: 36.92 | U17: 359 | V17: =SUM(P17:U17) -> 1134.32 | W17: 10408.47 | Y17: =SUM(E17,O17,V17:X17) -> 14850.86 | AA17: 5756133 | AB17: 140103198304204830 | AC17: 14010.23 | AD17: 6% | AE17: 840.63
A18: 3 | B18: 龚林花 | C18: 202503 | D18: 2024-06-01 | E18: 699.94 | F18: 7963 | G18: 7963 | H18: 1274.08 | I18: 716.68 | J18: 39.82 | K18: 15.93 | M18: 119.45 | N18: 557 | O18: =SUM(H18:N18) -> 2722.96 | P18: 637.04 | Q18: 159.26 | R18: 39.82 | U18: 557 | V18: =SUM(P18:U18) -> 1393.12 | W18: 5782.98 | Y18: =SUM(E18,O18,V18:X18) -> 10599 | AA18: 5545720 | AB18: 310230198502244987 | AC18: 9999.05 | AD18: 6% | AE18: 599.95
A19: 4 | B19: 顾文君 | C19: 202503 | D19: 2024-06-01 | E19: 980.99 | F19: 13189 | G19: 13189 | H19: 2110.24 | I19: 1187.02 | J19: 65.95 | K19: 26.38 | M19: 197.84 | N19: 923 | O19: =SUM(H19:N19) -> 4510.43 | P19: 1055.12 | Q19: 263.78 | R19: 65.95 | U19: 923 | V19: =SUM(P19:U19) -> 2307.85 | W19: 7764.85 | Y19: =SUM(E19,O19,V19:X19) -> 15564.12 | AA19: 5545704 | AB19: 310110198605095645 | AC19: 14683.13 | AD19: 6% | AE19: 880.99
A20: 5 | B20: 顾燕 | C20: 202503 | D20: 2024-06-01 | E20: 740.18 | F20: 10363 | G20: 10363 | H20: 1658.08 | I20: 932.68 | J20: 51.82 | K20: 20.73 | M20: 155.45 | N20: 725 | O20: =SUM(H20:N20) -> 3543.76 | P20: 829.04 | Q20: 207.26 | R20: 51.82 | U20: 725 | V20: =SUM(P20:U20) -> 1813.12 | W20: 5212.88 | Y20: =SUM(E20,O20,V20:X20) -> 11309.94 | AA20: 5545718 | AB20: 310113198111034825 | AC20: 10669.76 | AD20: 6% | AE20: 640.18
A21: 6 | B21: 金霞 | C21: 202503 | D21: 2024-06-01 | E21: 517.78 | F21: 7384 | G21: 7287 | H21: 1181.44 | I21: 664.56 | J21: 36.92 | K21: 14.77 | M21: 110.76 | N21: 510 | O21: =SUM(H21:N21) -> 2518.45 | P21: 590.72 | Q21: 147.68 | R21: 36.92 | U21: 510 | V21: =SUM(P21:U21) -> 1285.32 | W21: 3059.27 | Y21: =SUM(E21,O21,V21:X21) -> 7380.82 | AA21: 5545705 | AB21: 310113198309114628 | AC21: 6963.03 | AD21: 6% | AE21: 417.79
A22: 7 | B22: 李娟 | C22: 202503 | D22: 2024-06-01 | E22: 663.2 | F22: 10038 | G22: 10038 | H22: 1606.08 | I22: 903.42 | J22: 50.19 | K22: 20.08 | M22: 150.57 | N22: 703 | O22: =SUM(H22:N22) -> 3433.34 | P22: 803.04 | Q22: 200.76 | R22: 50.19 | U22: 703 | V22: =SUM(P22:U22) -> 1756.99 | W22: 4096.39 | Y22: =SUM(E22,O22,V22:X22) -> 9949.92 | AA22: 5545725 | AB22: 310230197802072529 | AC22: 9386.73 | AD22: 6% | AE22: 563.19
A23: 8 | B23: 林峰 | C23: 202503 | D23: 2024-06-01 | E23: 539.25 | F23: 7546 | G23: 7546 | H23: 1207.36 | I23: 679.14 | J23: 37.73 | K23: 15.09 | M23: 113.19 | N23: 528 | O23: =SUM(H23:N23) -> 2580.51 | P23: 603.68 | Q23: 150.92 | R23: 37.73 | U23: 528 | V23: =SUM(P23:U23) -> 1320.33 | W23: 3320 | Y23: =SUM(E23,O23,V23:X23) -> 7760.09 | AA23: 5572476 | AB23: 320681199806210215 | AC23: 7320.84 | AD23: 6% | AE23: 439.25
A24: 9 | B24: 陆燕 | C24: 202503 | D24: 2024-06-01 | E24: 1075.23 | F24: 7384 | G24: 6844 | H24: 1181.44 | I24: 664.56 | J24: 36.92 | K24: 14.77 | M24: 110.76 | N24: 479 | O24: =SUM(H24:N24) -> 2487.45 | P24: 590.72 | Q24: 147.68 | R24: 36.92 | U24: 479 | V24: =SUM(P24:U24) -> 1254.32 | W24: 12411.97 | Y24: =SUM(E24,O24,V24:X24) -> 17228.97 | AA24: 5756132 | AB24: 310113197802064324 | AC24: 16253.73 | AD24: 6% | AE24: 975.24
A25: 10 | B25: 茅柳 | C25: 202503 | D25: 2024-06-01 | E25: 613.88 | F25: 7594 | G25: 7594 | H25: 1215.04 | I25: 683.46 | J25: 37.97 | K25: 15.19 | M25: 113.91 | N25: 532 | O25: =SUM(H25:N25) -> 2597.57 | P25: 607.52 | Q25: 151.88 | R25: 37.97 | U25: 532 | V25: =SUM(P25:U25) -> 1329.37 | W25: 4537.73 | Y25: =SUM(E25,O25,V25:X25) -> 9078.55 | AA25: 5572477 | AB25: 310230198208264565 | AC25: 8564.68 | AD25: 6% | AE25: 513.87
A26: 11 | B26: 钱运成 | C26: 202503 | D26: 2025-03-01 | E26: 516.6 | F26: 7384 | G26: 5000 | H26: 1181.44 | I26: 664.56 | J26: 36.92 | K26: 14.77 | M26: 110.76 | N26: 350 | O26: =SUM(H26:N26) -> 2358.45 | P26: 590.72 | Q26: 147.68 | R26: 36.92 | U26: 350 | V26: =SUM(P26:U26) -> 1125.32 | W26: 3359.48 | Y26: =SUM(E26,O26,V26:X26) -> 7359.85 | AA26: 6307840 | AB26: 13058219830615043X | AC26: 6943.24 | AD26: 6% | AE26: 416.61
A27: 12 | B27: 沙玉莲 | C27: 202503 | D27: 2024-06-01 | E27: 1065.51 | F27: 11264 | G27: 11264 | H27: 1802.24 | I27: 1013.76 | J27: 56.32 | K27: 22.53 | M27: 168.96 | N27: 788 | O27: =SUM(H27:N27) -> 3851.81 | P27: 901.12 | Q27: 225.28 | R27: 56.32 | U27: 788 | V27: =SUM(P27:U27) -> 1970.72 | W27: 10169.38 | Y27: =SUM(E27,O27,V27:X27) -> 17057.42 | AA27: 5572479 | AB27: 320681198001296045 | AC27: 16091.9 | AD27: 6% | AE27: 965.52
... A53: 38 | B53: 朱焱炎 | C53: 202503 | D53: 2024-06-01 | E53: 524.05 | F53: 7384 | G53: 4997 | H53: 1181.44 | I53: 664.56 | J53: 36.92 | K53: 14.77 | M53: 110.76 | N53: 350 | O53: =SUM(H53:N53) -> 2358.45 | P53: 590.72 | Q53: 147.68 | R53: 36.92 | U53: 350 | V53: =SUM(P53:U53) -> 1125.32 | W53: 3483.67 | Y53: =SUM(E53,O53,V53:X53) -> 7491.49 | AA53: 5545716 | AB53: 320681198812140829 | AC53: 7067.43 | AD53: 6% | AE53: 424.06
A54: 合计（RMB） | E54: =SUM(E16:E53) -> 31678.16 | H54: =SUM(H16:H53) -> 57499.31 | I54: =SUM(I16:I53) -> 32343.49 | J54: =SUM(J16:J53) -> 1796.92 | K54: =SUM(K16:K53) -> 718.79 | L54: =SUM(L16:L53) -> 0 | M54: =SUM(M16:M53) -> 5390.62 | N54: =SUM(N16:N53) -> 23167 | O54: =SUM(O16:O53) -> 120916.13 | ... Y54: =SUM(Y16:Y53) -> 493220.14 | AC54: =SUM(AC16:AC53) -> 465301.75 | AE54: =SUM(AE16:AE53) -> 27918.39
A55: 总计（RMB）已包含历月补收人民币肆拾玖万叁仟贰佰贰拾圆壹角肆分 | Y55: 493220.14
A57: 其他费用
A58: 序号 | B58: 发生年月 | C58: 费用项目 | D58: 金额 | E58: 备注 | F58: 应纳税金额 | G58: 税率 | H58: 增值税
A59: S/N | B59: YYYYMM | C59: Item | D59: Amount | E59: Remarks | F59: Taxable Amount | G59: Tax Rate | H59: VAT
A60: 1 | B60: 202503 | C60: 税差调整6% | D60: 0 | F60: 0.27 | G60: 0.06 | H60: -0.27
A61: 合计（RMB） | D61: =SUM(D60:D60) -> 0 | F61: =SUM(F60:F60) -> 0.27 | H61: =SUM(H60:H60) -> -0.27
A62: 总计（RMB）人民币零 | D62: 0 | F62: 0.27 | H62: -0.27
A64: 增值税：
A65: 序号 S/N | B65: 应纳税额 | C65: 税率 | D65: 税金
A67: 1 | B67: 465302.02 | C67: 6% | D67: 27918.12
A68: 小计（RMB） | B68: 465302.02 | D68: 27918.12
A69: 总计(RMB) | D69: 27918.12
A70: 本次价税合计(RMB):人民币肆拾玖万叁仟贰佰贰拾圆壹角肆分
A71: 493220.14
A72: 本月价税合计（RMB）：493220.14 其中已开票493220.14
...
