Workbook

Sheet 202410
A1: 序号 | B1: 计薪 周期 | C1: 工号 | D1: 姓名 | E1: 身份证号 | F1: 劳动合同起始日期 | G1: 劳动合同结束日期 | H1: 离职日期 | I1: 社保缴纳地 | J1: 星级费用 | K1: 考核费用 | L1: 量化费用 | M1: 专项费用 | Z1: 当月税前工资合计 | AA1: 社保基数(个人) | AB1: 养老保险(个人) | AC1: 医疗保险(个人) | AD1: 失业保险(个人) | AE1: 公积金基数(个人) | AF1: 住房公积金(个人) | AG1: 员工五险一金合计 | AH1: 本月个人所得税-系统导出 | AI1: 税后增加 | AJ1: 税后扣减 | AK1: 员工实发合计 | AL1: 社保基数 | AM1: 公积金基数 | AN1: 养老缴费 | AO1: 医疗缴费 | AP1: 失业保险 | AQ1: 工伤保险 | AR1: 生育保险 | AS1: 公积金 | AT1: 残保金 | AU1: 企业五险一金合计 | AV1: 工会费 | AW1: 代收付合计 | AX1: 供应商补差 | AY1: 社保备注 | AZ1: 外包服务费 | BA1: 税前项合计 | BB1: 增值税 | BC1: 总计
A2: NO. | B2: Salary Cycle | C2: Employee No. | D2: Name | E2: ID No. | F2: Contract Starting Date | G2: Contract Expiry Date | H2: Exit Date | I2: Social Insurance City | J2: Contract Salary | K2: Assessment fees | L2: Quantifying costs | M2: 支局专项 | N2: 部门加奖 | O2: 加班费 | P2: 效能补贴 | Q2: 高温费及清凉饮料费 （6-9月） | R2: 伙食补贴 | S2: 独生子女奖励 | T2: 保险费 | U2: 其他费用 | V2: 补发费用 | W2: 劳防用品 | X2: 保障补差 | Y2: 其他扣款 | Z2: Pre-tax Total | AA2: Social Insurance Base | AB2: Pension Employee | AC2: Medical Employee | AD2: Umemployment Employee | AE2: Housing Fund Base | AF2: Housing Fund Employee | AG2: Total Amount of Social Insurance(EE) | AH2: Personal Income Tax | AI2: Increase After-tax payment | AJ2: Reduction After-tax payment | AK2: After-tax total Income | AL2: Social Insurance Base | AM2: Housing Fund Base | AN2: Pension Employer | AO2: Medical Employer | AP2: Umemployment Employer | AQ2: Injury Employer | AR2: Maternity Insurance Employer | AS2: Housing Fund Employer | AT2: Disabled people&Back pay Fund | AU2: Total Amount of Social Insurance(ER) | AV2: Union Fee | AW2: Payment Total | AY2: Social Security remark | AZ2: Service Fee | BA2: Total | BB2: VAT | BC2: Subtotal
A3: =ROW()-2 -> 1 | B3: 2410 | C3: WB002509 | D3: 郗冬梅 | E3: 321027197512232145 | F3: 45078 | G3: 45443 | I3: 上海 | J3: 1030 | K3: 0 | L3: 0 | R3: 630 | V3: 4500 | X3: 0 | Y3: 0 | Z3: =SUM(J3:Y3) -> 6160 | AA3: 9311 | AB3: =ROUND(AA3*8%,2) -> 744.88 | AC3: =ROUND(AA3*2%,2) -> 186.22 | AD3: =ROUND(AA3*0.5%,2) -> 46.56 | AE3: 9311 | AF3: =ROUND(AE3*7%,0) -> 652 | AG3: =AB3+AC3+AD3+AF3 -> 1629.66 | AK3: =Z3-AG3-AH3 -> 4530.34 | AL3: 9311 | AM3: 9311 | AN3: =ROUND(AL3*16%,2) -> 1489.76 | AO3: 838 | AP3: =ROUND(AL3*0.5%,2) -> 46.56 | AQ3: =ROUND(AL3*0.32%,2) -> 29.8 | AS3: =ROUND(AM3*7%,0) -> 652 | AT3: =ROUND(IF(AL3<22792,AL3*1.5%,22792*1.5%),2) -> 139.67 | AU3: =SUM(AN3:AT3) -> 3195.79 | AV3: 111 | AW3: =AU3+Z3+AI3-AJ3+AV3 -> 9466.79 | AZ3: 255 | BA3: =ROUND(AW3+AZ3+AX3,2) -> 9721.79 | BB3: =ROUND(BA3*6%,2) -> 583.31 | BC3: =ROUND(SUM(BA3:BB3),2) -> 10305.1
A5: 合计 | AU5: 3195.79
AZ7: 实际结算 | BA7: 303434.72
AZ8: 差额下月补 | BA8: 111.61

Sheet 对账单
A1: 科目 | B1: 手工账单 | C1: 7月速创账单 | D1: 155 | E1: 系统已有金额（不做一次性） | F1: 工会费扣除 | G1: 工会费 | H1: 合计 | I1: 差异
A2: 管理费 | B2: ='202410'!BB3 -> 583.31 | C2: =系统!E17 -> 667.05 | H2: =SUM(C2:F2) -> 667.05 | I2: =B2-C2 -> -83.74
A3: 风险费 | B3: ='202410'!AZ3 -> 255 | C3: 0 | D3: =1*155+5 -> 160 | H3: =SUM(C3:F3) -> 160 | I3: =B3-C3 -> 255
A4: 个人四金 | B4: ='202410'!AG3 -> 1629.66 | C4: =系统!V17 -> 1629.66 | H4: =SUM(C4:F4) -> 1629.66 | I4: =B4-C4 -> 0
A5: 公司四金 | B5: ='202410'!AU3 -> 3195.79 | C5: =系统!O17 -> 3195.79 | H5: =SUM(C5:E5) -> 3195.79 | I5: =B5-C5 -> 0
A6: 残保金 | H6: =SUM(C6:F6) -> 0 | I6: =B6-C6 -> 0
A7: 代发工资 | B7: ='202410'!AK3 -> 4530.34 | C7: =系统!W17 -> 4525.34 | H7: =SUM(C7:F7) -> 4525.34 | I7: =B7-C7 -> 5
A8: 上月垫付 | H8: =SUM(C8:F8) -> 0 | I8: =B8-C8 -> 0
A9: 工会费 | B9: ='202410'!AV3 -> 111 | G9: =B9 -> 111 | H9: =SUM(C9:F9) -> 0 | I9: =B9-C9 -> 111
A10: 预收（做预收一次性） | H10: =SUM(C10:G10) -> 0 | I10: =B10-C10 -> 0
A11: 小计 | B11: =SUM(B2:B10) -> 10305.1 | C11: =SUM(C2:C10) -> 10017.84 | D11: =SUM(D2:D10) -> 160 | E11: =SUM(E2:E10) -> 0 | F11: =SUM(F2:F10) -> 0 | G11: =SUM(G2:G10) -> 111 | H11: =SUM(C11:G11) -> 10288.84
A12: 附加税 | D12: 0
A13: 增值税 | D13: =ROUND((D11+D12)*6%,2) -> 9.6 | E13: =ROUND((E11+E12)*6%,2) -> 0 | F13: =ROUND((F11+F12)*6%,2) -> 0 | G13: =ROUND((G11+G12)*6%,2) -> 6.66 | H13: =SUM(C13:F13) -> 9.6
A14: 总计 | B14: =SUM(B11:B13) -> 10305.1 | C14: =SUM(C11:C13) -> 10017.84 | D14: =SUM(D11:D13) -> 169.6 | E14: =SUM(E11:E13) -> 0 | F14: =SUM(F11:F13) -> 0 | G14: =SUM(G11:G13) -> 117.66 | H14: =SUM(C14:G14) -> 10305.1
A15: 给客户账单金额 | H15: =B14 -> 10305.1
A16: 差异 | H16: =H15-H14 -> 0
A17: 不含税差异 | H17: =ROUND(H16/1.06,2) -> 0

Sheet 系统
A1: 200070
A2: 寄：梅园路77号人才大厦
B3: 中国电信股份有限公司上海分公司 财务 收
D6: 上海东浩人力资源管理服务有限公司
C7: Shanghai Donghao HR Management Service Co., Ltd
E9: 收款通知书
E10: ADVISE ON COLLECTION
E11: 2024年10月
A13: 公司名称：中国电信股份有限公司上海分公司 | J13: 帐单号：202410CH5960903
A14: 序号 | B14: 姓名 | C14: 发生年月 | D14: 入职日期 | E14: 管理费 | F14: 当月社保基数 | G14: 当月公积金基数 | H14: 社保类 公司支付 Social Insurance Premiums Paid by Employer | N14: 公积金类 公司支付 Provident Fund Paid by Employer | O14: 公司合计 | P14: 社保类 个人支付 Social Insurance Premiums Paid by Employee | U14: 公积金类 个人支付 Provident Fund Paid by Employee | V14: 个人合计 | W14: 代办薪酬 | X14: 其他 | Y14: 总计 | Z14: 备注 | AA14: 外服工号 | AB14: 证件号码 | AC14: 应纳税金额 | AD14: 税率 | AE14: 增值税
A15: S/N | B15: Name | C15: YYYYMM | D15: Employment Start Date | E15: Adm Fee | F15: Social Insurance Base Amount of Current Month | G15: Provident Fund Base Amount of Current Month | H15: 养老保险 Endowment | I15: 医疗保险 Medical | J15: 失业保险 Unemploy-ment | K15: 工伤保险 Employment Injury | L15: 医疗生育保险 Medical Maternity | M15: 保障金 Disabled people&Back pay Fund | N15: 公积金 Provident Fund | O15: Subtotal of Employer Payment | P15: 养老保险 Endowment | Q15: 医疗保险 Medical | R15: 失业保险 Unemploy-ment | S15: 工伤保险 Employment Injury | T15: 医疗生育保险 Medical Maternity | U15: 公积金 Provident Fund | V15: Subtotal of Personal Payment | W15: Agency of Wage Payment | X15: Others | Y15: Total | Z15: Remarks | AA15: SFSC ID | AB15: ID Card | AC15: Taxable Amount | AD15: Tax Rate | AE15: VAT
A16: 1 | B16: 郗冬梅 | C16: 202410 | D16: 2023-06-01 | E16: 667.05 | F16: 9311 | G16: 9311 | H16: 1489.76 | I16: 838 | J16: 46.56 | K16: 29.8 | M16: 139.67 | N16: 652 | O16: =SUM(H16:N16) -> 3195.79 | P16: 744.88 | Q16: 186.22 | R16: 46.56 | U16: 652 | V16: =SUM(P16:U16) -> 1629.66 | W16: 4525.34 | Y16: =SUM(E16,O16,V16:X16) -> 10017.84 | AA16: 5543041 | AB16: 321027197512232145 | AC16: 9450.8 | AD16: 6% | AE16: 567.04
A17: 合计（RMB） | E17: =SUM(E16:E16) -> 667.05 | H17: =SUM(H16:H16) -> 1489.76 | I17: =SUM(I16:I16) -> 838 | J17: =SUM(J16:J16) -> 46.56 | K17: =SUM(K16:K16) -> 29.8 | L17: =SUM(L16:L16) -> 0 | M17: =SUM(M16:M16) -> 139.67 | N17: =SUM(N16:N16) -> 652 | O17: =SUM(O16:O16) -> 3195.79 | ... Y17: =SUM(Y16:Y16) -> 10017.84 | AC17: =SUM(AC16:AC16) -> 9450.8 | AE17: =SUM(AE16:AE16) -> 567.04
A18: 总计（RMB）已包含历月补收人民币壹万零壹拾柒圆捌角肆分 | Y18: 10017.84
A20: 其他费用
A21: 序号 | B21: 发生年月 | C21: 费用项目 | D21: 金额 | E21: 备注 | F21: 应纳税金额 | G21: 税率 | H21: 增值税
A22: S/N | B22: YYYYMM | C22: Item | D22: Amount | E22: Remarks | F22: Taxable Amount | G22: Tax Rate | H22: VAT
A23: 1 | B23: 202410 | C23: 税差调整6% | D23: 0 | F23: -0.01 | G23: 0.06 | H23: 0.01
A24: 合计（RMB） | D24: =SUM(D23:D23) -> 0 | F24: =SUM(F23:F23) -> -0.01 | H24: =SUM(H23:H23) -> 0.01
A25: 总计（RMB）人民币零 | D25: 0 | F25: -0.01 | H25: 0.01
A27: 增值税：
A28: 序号 S/N | B28: 应纳税额 | C28: 税率 | D28: 税金
A30: 1 | B30: 9450.79 | C30: 6% | D30: 567.05
A31: 小计（RMB） | B31: 9450.79 | D31: 567.05
A32: 总计(RMB) | D32: 567.05
A33: 本次价税合计(RMB):人民币壹万零壹拾柒圆捌角肆分
A34: 10017.84
A35: 本月价税合计（RMB）：10017.84 其中已开票10017.84
A37: 本月总计（RMB）人民币壹万零壹拾柒圆捌角肆分 ￥10017.84
A39: 制单人：王思君 | J39: 制单日期：2024-10-20
A41: 户名：上海东浩人力资源管理服务有限公司
A42: 人民币收款账号：1001215509300846227
A43: 开户银行：工商银行闸北天目东路支行
A44: SWIFT CODE：
A45: 地址：
A47: 管理部：东浩人力资源管理-灵活用工部 | D47: 负责人：滕中伟 | G47: 上海东浩人力资源管理服务有限公司
A48: 地 址：上海市静安区梅园路77号人才大厦24楼 | G48: 地 址：上海市黄浦区会馆街55号T3座
A49: 邮 编：200070 | D49: 财 务：王思君 | G49: 邮 编：200437
A50: 电 话：63813311 | D50: 传 真：32303891 | G50: 电 话：63721888 | J50: 传 真：63856522
A52: 注意： | B52: 1、务必请将当月人员变动信息，在15日前通知所在业务部。
...
