Workbook

Sheet 202502
A1: 序号 | B1: 计薪 周期 | C1: 工号 | D1: 姓名 | E1: 身份证号 | F1: 劳动合同起始日期 | G1: 劳动合同结束日期 | H1: 离职日期 | I1: 社保缴纳地 | J1: 星级费用 | K1: 考核费用 | L1: 量化费用 | M1: 专项费用 | Z1: 当月税前工资合计 | AA1: 社保基数(个人) | AB1: 养老保险(个人) | AC1: 医疗保险(个人) | AD1: 失业保险(个人) | AE1: 公积金基数(个人) | AF1: 住房公积金(个人) | AG1: 员工五险一金合计 | AH1: 本月个人所得税-系统导出 | AI1: 税后增加 | AJ1: 税后扣减 | AK1: 员工实发合计 | AL1: 社保基数 | AM1: 公积金基数 | AN1: 养老缴费 | AO1: 医疗缴费 | AP1: 失业保险 | AQ1: 工伤保险 | AR1: 生育保险 | AS1: 公积金 | AT1: 残保金 | AU1: 企业五险一金合计 | AV1: 工会费 | AW1: 代收付合计 | AX1: 上月垫付，本月已收 | AY1: 本月多收，下月退 | AZ1: 社保备注 | BA1: 外包服务费 | BB1: 税前项合计 | BC1: 增值税 | BD1: 总计
A2: NO. | B2: Salary Cycle | C2: Employee No. | D2: Name | E2: ID No. | F2: Contract Starting Date | G2: Contract Expiry Date | H2: Exit Date | I2: Social Insurance City | J2: Contract Salary | K2: Assessment fees | L2: Quantifying costs | M2: 支局专项 | N2: 1+1激励 | O2: 交通费 | P2: 效能补贴 | Q2: 伙食补贴 | R2: 高温费及清凉饮料费 （6-9月） | S2: 独生子女奖励 | T2: 保险费 | U2: 其他费用 | V2: 补发费用 | W2: 劳防用品 | X2: 保障补差 | Y2: 其他扣款 | Z2: Pre-tax Total | AA2: Social Insurance Base | AB2: Pension Employee | AC2: Medical Employee | AD2: Umemployment Employee | AE2: Housing Fund Base | AF2: Housing Fund Employee | AG2: Total Amount of Social Insurance(EE) | AH2: Personal Income Tax | AI2: Increase After-tax payment | AJ2: Reduction After-tax payment | AK2: After-tax total Income | AL2: Social Insurance Base | AM2: Housing Fund Base | AN2: Pension Employer | AO2: Medical Employer | AP2: Umemployment Employer | AQ2: Injury Employer | AR2: Maternity Insurance Employer | AS2: Housing Fund Employer | AT2: Disabled people&Back pay Fund | AU2: Total Amount of Social Insurance(ER) | AV2: Union Fee | AW2: Payment Total | AZ2: Social Security remark | BA2: Service Fee | BB2: Total | BC2: VAT | BD2: Subtotal
A3: =ROW()-2 -> 1 | B3: 2502 | C3: WB007244 | D3: 周伟丰 | E3: 310107198106192557 | F3: 45444 | G3: 45808 | I3: 上海 | Z3: =SUM(J3:Y3) -> 0 | AA3: 13804 | AB3: 1104.32 | AC3: 276.08 | AD3: 69.02 | AE3: 13804 | AF3: 966 | AG3: =AB3+AC3+AD3+AF3 -> 2415.42 | AK3: =Z3-AG3-AH3 -> -2415.42 | AL3: 13804 | AM3: 13804 | AN3: =ROUND(AL3*16%,2) -> 2208.64 | AO3: =ROUND(AL3*9%,2) -> 1242.36 | AP3: =ROUND(AL3*0.5%,2) -> 69.02 | AQ3: 27.61 | AS3: =ROUND(AM3*7%,0) -> 966 | AT3: =ROUND(IF(AL3<24366,AL3*1.5%,24366*1.5%),2) -> 207.06 | AU3: =SUM(AN3:AT3) -> 4720.69 | AV3: 256 | AW3: =AU3+Z3+AI3-AJ3+AV3 -> 4976.69 | AY3: -7.73 | AZ3: 工伤利率调整，1月多收2月退 | BA3: 255 | BB3: =ROUND(AW3+BA3+AY3+AX3,2) -> 5223.96 | BC3: =ROUND(BB3*6%,2) -> 313.44 | BD3: =ROUND(SUM(BB3:BC3),2) -> 5537.4 | BE3: 纵向攻击团队
A4: =ROW()-2 -> 2 | B4: 2502 | C4: WB007262 | D4: 顾燕 | E4: 310113198111034825 | F4: 45444 | G4: 45808 | I4: 上海 | Z4: =SUM(J4:Y4) -> 0 | AA4: 10363 | AB4: 829.04 | AC4: 207.26 | AD4: 51.82 | AE4: 10363 | AF4: 725 | AG4: =AB4+AC4+AD4+AF4 -> 1813.12 | AK4: =Z4-AG4-AH4 -> -1813.12 | AL4: 10363 | AM4: 10363 | AN4: =ROUND(AL4*16%,2) -> 1658.08 | AO4: 932.68 | AP4: =ROUND(AL4*0.5%,2) -> 51.82 | AQ4: 20.73 | AS4: =ROUND(AM4*7%,0) -> 725 | AT4: =ROUND(IF(AL4<24366,AL4*1.5%,24366*1.5%),2) -> 155.45 | AU4: =SUM(AN4:AT4) -> 3543.76 | AV4: 174 | AW4: =AU4+Z4+AI4-AJ4+AV4 -> 3717.76 | AY4: -5.8 | AZ4: 工伤利率调整，1月多收2月退 | BA4: 255 | BB4: =ROUND(AW4+BA4+AY4+AX4,2) -> 3966.96 | BC4: =ROUND(BB4*6%,2) -> 238.02 | BD4: =ROUND(SUM(BB4:BC4),2) -> 4204.98 | BE4: 纵向攻击团队
A5: =ROW()-2 -> 3 | B5: 2502 | C5: WB026438 | D5: 沈娟娟 | E5: 32068119890825242X | F5: 45444 | G5: 45808 | I5: 上海 | Z5: =SUM(J5:Y5) -> 0 | AA5: 11829 | AB5: 946.32 | AC5: 236.58 | AD5: 59.15 | AE5: 11829 | AF5: 828 | AG5: =AB5+AC5+AD5+AF5 -> 2070.05 | AK5: =Z5-AG5-AH5 -> -2070.05 | AL5: 11829 | AM5: 11829 | AN5: =ROUND(AL5*16%,2) -> 1892.64 | AO5: 1064.62 | AP5: =ROUND(AL5*0.5%,2) -> 59.15 | AQ5: 23.66 | AS5: =ROUND(AM5*7%,0) -> 828 | AT5: =ROUND(IF(AL5<24366,AL5*1.5%,24366*1.5%),2) -> 177.44 | AU5: =SUM(AN5:AT5) -> 4045.51 | AV5: 141 | AW5: =AU5+Z5+AI5-AJ5+AV5 -> 4186.51 | AY5: -6.62 | AZ5: 工伤利率调整，1月多收2月退 | BA5: 255 | BB5: =ROUND(AW5+BA5+AY5+AX5,2) -> 4434.89 | BC5: =ROUND(BB5*6%,2) -> 266.09 | BD5: =ROUND(SUM(BB5:BC5),2) -> 4700.98 | BE5: 纵向攻击团队
A6: =ROW()-2 -> 4 | B6: 2502 | C6: WB027558 | D6: 陈云 | E6: 320681198911257029 | F6: 45444 | G6: 45808 | I6: 上海 | Z6: =SUM(J6:Y6) -> 0 | AA6: 11367 | AB6: 909.36 | AC6: 227.34 | AD6: 56.84 | AE6: 11367 | AF6: 796 | AG6: =AB6+AC6+AD6+AF6 -> 1989.54 | AK6: =Z6-AG6-AH6 -> -1989.54 | AL6: 11367 | AM6: 11367 | AN6: =ROUND(AL6*16%,2) -> 1818.72 | AO6: 1023.04 | AP6: =ROUND(AL6*0.5%,2) -> 56.84 | AQ6: 22.73 | AS6: =ROUND(AM6*7%,0) -> 796 | AT6: =ROUND(IF(AL6<24366,AL6*1.5%,24366*1.5%),2) -> 170.51 | AU6: =SUM(AN6:AT6) -> 3887.84 | AV6: 168 | AW6: =AU6+Z6+AI6-AJ6+AV6 -> 4055.84 | AY6: -6.37 | AZ6: 工伤利率调整，1月多收2月退 | BA6: 255 | BB6: =ROUND(AW6+BA6+AY6+AX6,2) -> 4304.47 | BC6: =ROUND(BB6*6%,2) -> 258.27 | BD6: =ROUND(SUM(BB6:BC6),2) -> 4562.74 | BE6: 纵向攻击团队
A7: =ROW()-2 -> 5 | B7: 2502 | C7: WB036282 | D7: 张海荣 | E7: 320681198311146835 | F7: 45444 | G7: 45808 | I7: 上海 | Z7: =SUM(J7:Y7) -> 0 | AA7: 11730 | AB7: 938.4 | AC7: 234.6 | AD7: 58.65 | AE7: 11730 | AF7: 821 | AG7: =AB7+AC7+AD7+AF7 -> 2052.65 | AK7: =Z7-AG7-AH7 -> -2052.65 | AL7: 11730 | AM7: 11730 | AN7: =ROUND(AL7*16%,2) -> 1876.8 | AO7: =ROUND(AL7*9%,2) -> 1055.7 | AP7: =ROUND(AL7*0.5%,2) -> 58.65 | AQ7: 23.46 | AS7: =ROUND(AM7*7%,0) -> 821 | AT7: =ROUND(IF(AL7<24366,AL7*1.5%,24366*1.5%),2) -> 175.95 | AU7: =SUM(AN7:AT7) -> 4011.56 | AV7: 157 | AW7: =AU7+Z7+AI7-AJ7+AV7 -> 4168.56 | AY7: -6.57 | AZ7: 工伤利率调整，1月多收2月退 | BA7: 255 | BB7: =ROUND(AW7+BA7+AY7+AX7,2) -> 4416.99 | BC7: =ROUND(BB7*6%,2) -> 265.02 | BD7: =ROUND(SUM(BB7:BC7),2) -> 4682.01 | BE7: 纵向攻击团队
A8: =ROW()-2 -> 6 | B8: 2502 | C8: WB044295 | D8: 龚林花 | E8: 310230198502244987 | F8: 45444 | G8: 45808 | I8: 上海 | Z8: =SUM(J8:Y8) -> 0 | AA8: 7963 | AB8: 637.04 | AC8: 159.26 | AD8: 39.82 | AE8: 7963 | AF8: 557 | AG8: =AB8+AC8+AD8+AF8 -> 1393.12 | AK8: =Z8-AG8-AH8 -> -1393.12 | AL8: 7963 | AM8: 7963 | AN8: =ROUND(AL8*16%,2) -> 1274.08 | AO8: 716.68 | AP8: =ROUND(AL8*0.5%,2) -> 39.82 | AQ8: 15.93 | AS8: =ROUND(AM8*7%,0) -> 557 | AT8: =ROUND(IF(AL8<24366,AL8*1.5%,24366*1.5%),2) -> 119.45 | AU8: =SUM(AN8:AT8) -> 2722.96 | AV8: 156 | AW8: =AU8+Z8+AI8-AJ8+AV8 -> 2878.96 | AY8: -4.46 | AZ8: 工伤利率调整，1月多收2月退 | BA8: 255 | BB8: =ROUND(AW8+BA8+AY8+AX8,2) -> 3129.5 | BC8: =ROUND(BB8*6%,2) -> 187.77 | BD8: =ROUND(SUM(BB8:BC8),2) -> 3317.27 | BE8: 纵向攻击团队
A9: =ROW()-2 -> 7 | B9: 2502 | C9: WB046059 | D9: 宋莉莉 | E9: 370883199010065887 | F9: 45444 | G9: 45808 | I9: 上海 | Z9: =SUM(J9:Y9) -> 0 | AA9: 11386 | AB9: 910.88 | AC9: 227.72 | AD9: 56.93 | AE9: 11386 | AF9: 797 | AG9: =AB9+AC9+AD9+AF9 -> 1992.53 | AK9: =Z9-AG9-AH9 -> -1992.53 | AL9: 11386 | AM9: 11386 | AN9: =ROUND(AL9*16%,2) -> 1821.76 | AO9: =ROUND(AL9*9%,2) -> 1024.74 | AP9: =ROUND(AL9*0.5%,2) -> 56.93 | AQ9: 22.77 | AS9: =ROUND(AM9*7%,0) -> 797 | AT9: =ROUND(IF(AL9<24366,AL9*1.5%,24366*1.5%),2) -> 170.79 | AU9: =SUM(AN9:AT9) -> 3893.99 | AV9: 172 | AW9: =AU9+Z9+AI9-AJ9+AV9 -> 4065.99 | AY9: -6.38 | AZ9: 工伤利率调整，1月多收2月退 | BA9: 255 | BB9: =ROUND(AW9+BA9+AY9+AX9,2) -> 4314.61 | BC9: =ROUND(BB9*6%,2) -> 258.88 | BD9: =ROUND(SUM(BB9:BC9),2) -> 4573.49 | BE9: 纵向攻击团队
A10: =ROW()-2 -> 8 | B10: 2502 | C10: WB053301 | D10: 林峰 | E10: 320681199806210215 | F10: 45444 | G10: 45808 | I10: 上海 | Z10: =SUM(J10:Y10) -> 0 | AA10: 7546 | AB10: 603.68 | AC10: 150.92 | AD10: 37.73 | AE10: 7546 | AF10: 528 | AG10: =AB10+AC10+AD10+AF10 -> 1320.33 | AK10: =Z10-AG10-AH10 -> -1320.33 | AL10: 7546 | AM10: 7546 | AN10: =ROUND(AL10*16%,2) -> 1207.36 | AO10: =ROUND(AL10*9%,2) -> 679.14 | AP10: =ROUND(AL10*0.5%,2) -> 37.73 | AQ10: 15.09 | AS10: =ROUND(AM10*7%,0) -> 528 | AT10: =ROUND(IF(AL10<24366,AL10*1.5%,24366*1.5%),2) -> 113.19 | AU10: =SUM(AN10:AT10) -> 2580.51 | AV10: 87 | AW10: =AU10+Z10+AI10-AJ10+AV10 -> 2667.51 | AY10: -4.23 | AZ10: 工伤利率调整，1月多收2月退 | BA10: 255 | BB10: =ROUND(AW10+BA10+AY10+AX10,2) -> 2918.28 | BC10: =ROUND(BB10*6%,2) -> 175.1 | BD10: =ROUND(SUM(BB10:BC10),2) -> 3093.38 | BE10: 纵向攻击团队
A11: =ROW()-2 -> 9 | B11: 2502 | C11: WB007259 | D11: 茅柳 | E11: 310230198208264565 | F11: 45444 | G11: 45808 | I11: 上海 | Z11: =SUM(J11:Y11) -> 0 | AA11: 7594 | AB11: 607.52 | AC11: 151.88 | AD11: 37.97 | AE11: 7594 | AF11: 532 | AG11: =AB11+AC11+AD11+AF11 -> 1329.37 | AK11: =Z11-AG11-AH11 -> -1329.37 | AL11: 7594 | AM11: 7594 | AN11: =ROUND(AL11*16%,2) -> 1215.04 | AO11: =ROUND(AL11*9%,2) -> 683.46 | AP11: =ROUND(AL11*0.5%,2) -> 37.97 | AQ11: 15.19 | AS11: =ROUND(AM11*7%,0) -> 532 | AT11: =ROUND(IF(AL11<24366,AL11*1.5%,24366*1.5%),2) -> 113.91 | AU11: =SUM(AN11:AT11) -> 2597.57 | AV11: 129 | AW11: =AU11+Z11+AI11-AJ11+AV11 -> 2726.57 | AY11: -4.25 | AZ11: 工伤利率调整，1月多收2月退 | BA11: 255 | BB11: =ROUND(AW11+BA11+AY11+AX11,2) -> 2977.32 | BC11: =ROUND(BB11*6%,2) -> 178.64 | BD11: =ROUND(SUM(BB11:BC11),2) -> 3155.96 | BE11: 纵向攻击团队
A12: =ROW()-2 -> 10 | B12: 2502 | C12: WB045138 | D12: 沙玉莲 | E12: 320681198001296045 | F12: 45444 | G12: 45808 | I12: 上海 | Z12: =SUM(J12:Y12) -> 0 | AA12: 11264 | AB12: 901.12 | AC12: 225.28 | AD12: 56.32 | AE12: 11264 | AF12: 788 | AG12: =AB12+AC12+AD12+AF12 -> 1970.72 | AK12: =Z12-AG12-AH12 -> -1970.72 | AL12: 11264 | AM12: 11264 | AN12: =ROUND(AL12*16%,2) -> 1802.24 | AO12: =ROUND(AL12*9%,2) -> 1013.76 | AP12: =ROUND(AL12*0.5%,2) -> 56.32 | AQ12: 22.53 | AS12: =ROUND(AM12*7%,0) -> 788 | AT12: =ROUND(IF(AL12<24366,AL12*1.5%,24366*1.5%),2) -> 168.96 | AU12: =SUM(AN12:AT12) -> 3851.81 | AV12: 170 | AW12: =AU12+Z12+AI12-AJ12+AV12 -> 4021.81 | AY12: -6.31 | AZ12: 工伤利率调整，1月多收2月退 | BA12: 255 | BB12: =ROUND(AW12+BA12+AY12+AX12,2) -> 4270.5 | BC12: =ROUND(BB12*6%,2) -> 256.23 | BD12: =ROUND(SUM(BB12:BC12),2) -> 4526.73 | BE12: 纵向攻击团队
A13: =ROW()-2 -> 11 | B13: 2502 | C13: WB044028 | D13: 王凌波 | E13: 320681198005016055 | F13: 45444 | G13: 45808 | I13: 上海 | Z13: =SUM(J13:Y13) -> 0 | AA13: 11463 | AB13: 917.04 | AC13: 229.26 | AD13: 57.32 | AE13: 11463 | AF13: 802 | AG13: =AB13+AC13+AD13+AF13 -> 2005.62 | AK13: =Z13-AG13-AH13 -> -2005.62 | AL13: 11463 | AM13: 11463 | AN13: =ROUND(AL13*16%,2) -> 1834.08 | AO13: 1031.68 | AP13: =ROUND(AL13*0.5%,2) -> 57.32 | AQ13: 22.93 | AS13: =ROUND(AM13*7%,0) -> 802 | AT13: =ROUND(IF(AL13<24366,AL13*1.5%,24366*1.5%),2) -> 171.95 | AU13: =SUM(AN13:AT13) -> 3919.96 | AV13: 310 | AW13: =AU13+Z13+AI13-AJ13+AV13 -> 4229.96 | AY13: -6.42 | AZ13: 工伤利率调整，1月多收2月退 | BA13: 255 | BB13: =ROUND(AW13+BA13+AY13+AX13,2) -> 4478.54 | BC13: =ROUND(BB13*6%,2) -> 268.71 | BD13: =ROUND(SUM(BB13:BC13),2) -> 4747.25 | BE13: 纵向攻击团队
A14: =ROW()-2 -> 12 | B14: 2502 | C14: WB048620 | D14: 郁金华 | E14: 320681197812267024 | F14: 45444 | G14: 45808 | I14: 上海 | Z14: =SUM(J14:Y14) -> 0 | AA14: 7384 | AB14: 590.72 | AC14: 147.68 | AD14: 36.92 | AE14: 6573 | AF14: 460 | AG14: =AB14+AC14+AD14+AF14 -> 1235.32 | AK14: =Z14-AG14-AH14 -> -1235.32 | AL14: 7384 | AM14: 6573 | AN14: =ROUND(AL14*16%,2) -> 1181.44 | AO14: =ROUND(AL14*9%,2) -> 664.56 | AP14: =ROUND(AL14*0.5%,2) -> 36.92 | AQ14: 14.77 | AS14: =ROUND(AM14*7%,0) -> 460 | AT14: =ROUND(IF(AL14<24366,AL14*1.5%,24366*1.5%),2) -> 110.76 | AU14: =SUM(AN14:AT14) -> 2468.45 | AV14: 190 | AW14: =AU14+Z14+AI14-AJ14+AV14 -> 2658.45 | AY14: -4.13 | AZ14: 工伤利率调整，1月多收2月退 | BA14: 255 | BB14: =ROUND(AW14+BA14+AY14+AX14,2) -> 2909.32 | BC14: =ROUND(BB14*6%,2) -> 174.56 | BD14: =ROUND(SUM(BB14:BC14),2) -> 3083.88 | BE14: 纵向攻击团队
A15: =ROW()-2 -> 13 | B15: 2502 | C15: WB041713 | D15: 翁杰 | E15: 32068119830326361X | F15: 45444 | G15: 45808 | I15: 上海 | Z15: =SUM(J15:Y15) -> 0 | AA15: 8179 | AB15: 654.32 | AC15: 163.58 | AD15: 40.9 | AE15: 8179 | AF15: 573 | AG15: =AB15+AC15+AD15+AF15 -> 1431.8 | AK15: =Z15-AG15-AH15 -> -1431.8 | AL15: 8179 | AM15: 8179 | AN15: =ROUND(AL15*16%,2) -> 1308.64 | AO15: 736.12 | AP15: =ROUND(AL15*0.5%,2) -> 40.9 | AQ15: 16.36 | AS15: =ROUND(AM15*7%,0) -> 573 | AT15: =ROUND(IF(AL15<24366,AL15*1.5%,24366*1.5%),2) -> 122.69 | AU15: =SUM(AN15:AT15) -> 2797.71 | AV15: 205 | AW15: =AU15+Z15+AI15-AJ15+AV15 -> 3002.71 | AY15: -4.58 | AZ15: 工伤利率调整，1月多收2月退 | BA15: 255 | BB15: =ROUND(AW15+BA15+AY15+AX15,2) -> 3253.13 | BC15: =ROUND(BB15*6%,2) -> 195.19 | BD15: =ROUND(SUM(BB15:BC15),2) -> 3448.32 | BE15: 纵向攻击团队
A16: =ROW()-2 -> 14 | B16: 2502 | C16: WB050058 | D16: 周海松 | E16: 320626197411023016 | F16: 45444 | G16: 45808 | I16: 上海 | Z16: =SUM(J16:Y16) -> 0 | AA16: 7384 | AB16: 590.72 | AC16: 147.68 | AD16: 36.92 | AE16: 4848 | AF16: 339 | AG16: =AB16+AC16+AD16+AF16 -> 1114.32 | AK16: =Z16-AG16-AH16 -> -1114.32 | AL16: 7384 | AM16: 4848 | AN16: =ROUND(AL16*16%,2) -> 1181.44 | AO16: =ROUND(AL16*9%,2) -> 664.56 | AP16: =ROUND(AL16*0.5%,2) -> 36.92 | AQ16: 14.77 | AS16: =ROUND(AM16*7%,0) -> 339 | AT16: =ROUND(IF(AL16<24366,AL16*1.5%,24366*1.5%),2) -> 110.76 | AU16: =SUM(AN16:AT16) -> 2347.45 | AV16: 92 | AW16: =AU16+Z16+AI16-AJ16+AV16 -> 2439.45 | AY16: -4.13 | AZ16: 工伤利率调整，1月多收2月退 | BA16: 255 | BB16: =ROUND(AW16+BA16+AY16+AX16,2) -> 2690.32 | BC16: =ROUND(BB16*6%,2) -> 161.42 | BD16: =ROUND(SUM(BB16:BC16),2) -> 2851.74 | BE16: 纵向攻击团队
A17: =ROW()-2 -> 15 | B17: 2502 | C17: WB038749 | D17: 叶挺 | E17: 34080219811208081X | F17: 45413 | G17: 45777 | I17: 上海 | Z17: =SUM(J17:Y17) -> 0 | AA17: 9889 | AB17: 791.12 | AC17: 197.78 | AD17: 49.45 | AE17: 9889 | AF17: 692 | AG17: =AB17+AC17+AD17+AF17 -> 1730.35 | AK17: =Z17-AG17-AH17 -> -1730.35 | AL17: 9889 | AM17: 9889 | AN17: =ROUND(AL17*16%,2) -> 1582.24 | AO17: 890.02 | AP17: =ROUND(AL17*0.5%,2) -> 49.45 | AQ17: 19.78 | AS17: =ROUND(AM17*7%,0) -> 692 | AT17: =ROUND(IF(AL17<24366,AL17*1.5%,24366*1.5%),2) -> 148.34 | AU17: =SUM(AN17:AT17) -> 3381.83 | AV17: =VLOOKUP(D17,[1]布列吉绩效清单!$F$7:$X$28,19,0) -> 341 | AW17: =AU17+Z17+AI17-AJ17+AV17 -> 3722.83 | AY17: -5.54 | AZ17: 工伤利率调整，1月多收2月退 | BA17: 255 | BB17: =ROUND(AW17+BA17+AY17+AX17,2) -> 3972.29 | BC17: =ROUND(BB17*6%,2) -> 238.34 | BD17: =ROUND(SUM(BB17:BC17),2) -> 4210.63
A18: =ROW()-2 -> 16 | B18: 2502 | C18: WB007457 | D18: 钱善晖 | E18: 341127198508043038 | F18: 45413 | G18: 45777 | I18: 上海 | Z18: =SUM(J18:Y18) -> 0 | AA18: 7788 | AB18: 623.04 | AC18: 155.76 | AD18: 38.94 | AE18: 7788 | AF18: 545 | AG18: =AB18+AC18+AD18+AF18 -> 1362.74 | AK18: =Z18-AG18-AH18 -> -1362.74 | AL18: 7788 | AM18: 7788 | AN18: =ROUND(AL18*16%,2) -> 1246.08 | AO18: =ROUND(AL18*9%,2) -> 700.92 | AP18: =ROUND(AL18*0.5%,2) -> 38.94 | AQ18: 15.58 | AS18: =ROUND(AM18*7%,0) -> 545 | AT18: =ROUND(IF(AL18<24366,AL18*1.5%,24366*1.5%),2) -> 116.82 | AU18: =SUM(AN18:AT18) -> 2663.34 | AV18: =VLOOKUP(D18,[1]布列吉绩效清单!$F$7:$X$28,19,0) -> 151 | AW18: =AU18+Z18+AI18-AJ18+AV18 -> 2814.34 | AY18: -4.36 | AZ18: 工伤利率调整，1月多收2月退 | BA18: 255 | BB18: =ROUND(AW18+BA18+AY18+AX18,2) -> 3064.98 | BC18: =ROUND(BB18*6%,2) -> 183.9 | BD18: =ROUND(SUM(BB18:BC18),2) -> 3248.88
A19: =ROW()-2 -> 17 | B19: 2502 | C19: WB068630 | D19: 王艳 | E19: 342222199402106028 | F19: 45427 | G19: 46521 | I19: 上海 | Z19: =SUM(J19:Y19) -> 0 | AA19: 7384 | AB19: 590.72 | AC19: 147.68 | AD19: 36.92 | AE19: 2690 | AF19: 188 | AG19: =AB19+AC19+AD19+AF19 -> 963.32 | AK19: =Z19-AG19-AH19 -> -963.32 | AL19: 7384 | AM19: 2690 | AN19: =ROUND(AL19*16%,2) -> 1181.44 | AO19: =ROUND(AL19*9%,2) -> 664.56 | AP19: =ROUND(AL19*0.5%,2) -> 36.92 | AQ19: 14.77 | AS19: =ROUND(AM19*7%,0) -> 188 | AT19: =ROUND(IF(AL19<24366,AL19*1.5%,24366*1.5%),2) -> 110.76 | AU19: =SUM(AN19:AT19) -> 2196.45 | AV19: =VLOOKUP(D19,[1]布列吉绩效清单!$F$7:$X$28,19,0) -> 478 | AW19: =AU19+Z19+AI19-AJ19+AV19 -> 2674.45 | AY19: -4.13 | AZ19: 工伤利率调整，1月多收2月退 | BA19: 255 | BB19: =ROUND(AW19+BA19+AY19+AX19,2) -> 2925.32 | BC19: =ROUND(BB19*6%,2) -> 175.52 | BD19: =ROUND(SUM(BB19:BC19),2) -> 3100.84
A20: =ROW()-2 -> 18 | B20: 2502 | C20: WB007293 | D20: 王海婷 | E20: 310113198812035548 | F20: 45444 | G20: 45808 | I20: 上海 | Z20: =SUM(J20:Y20) -> 0 | AA20: 7661 | AB20: 612.88 | AC20: 153.22 | AD20: 38.31 | AE20: 7661 | AF20: 536 | AG20: =AB20+AC20+AD20+AF20 -> 1340.41 | AK20: =Z20-AG20-AH20 -> -1340.41 | AL20: 7661 | AM20: 7661 | AN20: =ROUND(AL20*16%,2) -> 1225.76 | AO20: 689.5 | AP20: =ROUND(AL20*0.5%,2) -> 38.31 | AQ20: 15.32 | AS20: =ROUND(AM20*7%,0) -> 536 | AT20: =ROUND(IF(AL20<24366,AL20*1.5%,24366*1.5%),2) -> 114.92 | AU20: =SUM(AN20:AT20) -> 2619.81 | AV20: =VLOOKUP(D20,[1]布列吉绩效清单!$F$7:$X$28,19,0) -> 211 | AW20: =AU20+Z20+AI20-AJ20+AV20 -> 2830.81 | AY20: -4.29 | AZ20: 工伤利率调整，1月多收2月退 | BA20: 255 | BB20: =ROUND(AW20+BA20+AY20+AX20,2) -> 3081.52 | BC20: =ROUND(BB20*6%,2) -> 184.89 | BD20: =ROUND(SUM(BB20:BC20),2) -> 3266.41
A21: =ROW()-2 -> 19 | B21: 2502 | C21: WB023775 | D21: 张杰 | E21: 31011319860815411X | F21: 45444 | G21: 45808 | I21: 上海 | Z21: =SUM(J21:Y21) -> 0 | AA21: 17497 | AB21: 1399.76 | AC21: 349.94 | AD21: 87.49 | AE21: 17497 | AF21: 1225 | AG21: =AB21+AC21+AD21+AF21 -> 3062.19 | AK21: =Z21-AG21-AH21 -> -3062.19 | AL21: 17497 | AM21: 17497 | AN21: =ROUND(AL21*16%,2) -> 2799.52 | AO21: 1574.74 | AP21: =ROUND(AL21*0.5%,2) -> 87.49 | AQ21: 34.99 | AS21: =ROUND(AM21*7%,0) -> 1225 | AT21: =ROUND(IF(AL21<24366,AL21*1.5%,24366*1.5%),2) -> 262.46 | AU21: =SUM(AN21:AT21) -> 5984.2 | AV21: =VLOOKUP(D21,[1]布列吉绩效清单!$F$7:$X$28,19,0) -> 430 | AW21: =AU21+Z21+AI21-AJ21+AV21 -> 6414.2 | AY21: -9.8 | AZ21: 工伤利率调整，1月多收2月退 | BA21: 255 | BB21: =ROUND(AW21+BA21+AY21+AX21,2) -> 6659.4 | BC21: =ROUND(BB21*6%,2) -> 399.56 | BD21: =ROUND(SUM(BB21:BC21),2) -> 7058.96
A22: =ROW()-2 -> 20 | B22: 2502 | C22: WB030437 | D22: 李娟 | E22: 310230197802072529 | F22: 45444 | G22: 45808 | I22: 上海 | Z22: =SUM(J22:Y22) -> 0 | AA22: 10038 | AB22: 803.04 | AC22: 200.76 | AD22: 50.19 | AE22: 10038 | AF22: 703 | AG22: =AB22+AC22+AD22+AF22 -> 1756.99 | AK22: =Z22-AG22-AH22 -> -1756.99 | AL22: 10038 | AM22: 10038 | AN22: =ROUND(AL22*16%,2) -> 1606.08 | AO22: =ROUND(AL22*9%,2) -> 903.42 | AP22: =ROUND(AL22*0.5%,2) -> 50.19 | AQ22: 20.08 | AS22: =ROUND(AM22*7%,0) -> 703 | AT22: =ROUND(IF(AL22<24366,AL22*1.5%,24366*1.5%),2) -> 150.57 | AU22: =SUM(AN22:AT22) -> 3433.34 | AV22: =VLOOKUP(D22,[1]布列吉绩效清单!$F$7:$X$28,19,0) -> 135 | AW22: =AU22+Z22+AI22-AJ22+AV22 -> 3568.34 | AY22: -5.62 | AZ22: 工伤利率调整，1月多收2月退 | BA22: 255 | BB22: =ROUND(AW22+BA22+AY22+AX22,2) -> 3817.72 | BC22: =ROUND(BB22*6%,2) -> 229.06 | BD22: =ROUND(SUM(BB22:BC22),2) -> 4046.78
A23: =ROW()-2 -> 21 | B23: 2502 | C23: WB045407 | D23: 王佳睿 | E23: 320681200309147011 | F23: 45444 | G23: 45808 | I23: 上海 | Z23: =SUM(J23:Y23) -> 0 | AA23: 7384 | AB23: 590.72 | AC23: 147.68 | AD23: 36.92 | AE23: 7375 | AF23: 516 | AG23: =AB23+AC23+AD23+AF23 -> 1291.32 | AK23: =Z23-AG23-AH23 -> -1291.32 | AL23: 7384 | AM23: 7375 | AN23: =ROUND(AL23*16%,2) -> 1181.44 | AO23: 664.56 | AP23: =ROUND(AL23*0.5%,2) -> 36.92 | AQ23: 14.77 | AS23: =ROUND(AM23*7%,0) -> 516 | AT23: =ROUND(IF(AL23<24366,AL23*1.5%,24366*1.5%),2) -> 110.76 | AU23: =SUM(AN23:AT23) -> 2524.45 | AV23: =VLOOKUP(D23,[1]布列吉绩效清单!$F$7:$X$28,19,0) -> 113 | AW23: =AU23+Z23+AI23-AJ23+AV23 -> 2637.45 | AY23: -4.13 | AZ23: 工伤利率调整，1月多收2月退 | BA23: 255 | BB23: =ROUND(AW23+BA23+AY23+AX23,2) -> 2888.32 | BC23: =ROUND(BB23*6%,2) -> 173.3 | BD23: =ROUND(SUM(BB23:BC23),2) -> 3061.62
A24: =ROW()-2 -> 22 | B24: 2502 | C24: WB033013 | D24: 朱娟 | E24: 310113198511225727 | F24: 45444 | G24: 45808 | I24: 上海 | Z24: =SUM(J24:Y24) -> 0 | AA24: 12999 | AB24: 1039.92 | AC24: 259.98 | AD24: 65 | AE24: 12999 | AF24: 910 | AG24: =AB24+AC24+AD24+AF24 -> 2274.9 | AK24: =Z24-AG24-AH24 -> -2274.9 | AL24: 12999 | AM24: 12999 | AN24: =ROUND(AL24*16%,2) -> 2079.84 | AO24: 1169.92 | AP24: =ROUND(AL24*0.5%,2) -> 65 | AQ24: 26 | AS24: =ROUND(AM24*7%,0) -> 910 | AT24: =ROUND(IF(AL24<24366,AL24*1.5%,24366*1.5%),2) -> 194.99 | AU24: =SUM(AN24:AT24) -> 4445.75 | AV24: =VLOOKUP(D24,[1]布列吉绩效清单!$F$7:$X$28,19,0) -> 359 | AW24: =AU24+Z24+AI24-AJ24+AV24 -> 4804.75 | AY24: -7.28 | AZ24: 工伤利率调整，1月多收2月退 | BA24: 255 | BB24: =ROUND(AW24+BA24+AY24+AX24,2) -> 5052.47 | BC24: =ROUND(BB24*6%,2) -> 303.15 | BD24: =ROUND(SUM(BB24:BC24),2) -> 5355.62
A25: =ROW()-2 -> 23 | B25: 2502 | C25: WB054275 | D25: 姚嘉豪 | E25: 310113199804301716 | F25: 45444 | G25: 45808 | I25: 上海 | Z25: =SUM(J25:Y25) -> 0 | AA25: 7384 | AB25: 590.72 | AC25: 147.68 | AD25: 36.92 | AE25: 3607 | AF25: 252 | AG25: =AB25+AC25+AD25+AF25 -> 1027.32 | AK25: =Z25-AG25-AH25 -> -1027.32 | AL25: 7384 | AM25: 3607 | AN25: =ROUND(AL25*16%,2) -> 1181.44 | AO25: =ROUND(AL25*9%,2) -> 664.56 | AP25: =ROUND(AL25*0.5%,2) -> 36.92 | AQ25: 14.77 | AS25: =ROUND(AM25*7%,0) -> 252 | AT25: =ROUND(IF(AL25<24366,AL25*1.5%,24366*1.5%),2) -> 110.76 | AU25: =SUM(AN25:AT25) -> 2260.45 | AV25: =VLOOKUP(D25,[1]布列吉绩效清单!$F$7:$X$28,19,0) -> 158 | AW25: =AU25+Z25+AI25-AJ25+AV25 -> 2418.45 | AY25: -4.13 | AZ25: 工伤利率调整，1月多收2月退 | BA25: 255 | BB25: =ROUND(AW25+BA25+AY25+AX25,2) -> 2669.32 | BC25: =ROUND(BB25*6%,2) -> 160.16 | BD25: =ROUND(SUM(BB25:BC25),2) -> 2829.48
A26: =ROW()-2 -> 24 | B26: 2502 | C26: WB007248 | D26: 魏玲 | E26: 310108198612173363 | F26: 45444 | G26: 45808 | I26: 上海 | Z26: =SUM(J26:Y26) -> 0 | AA26: 7384 | AB26: 590.72 | AC26: 147.68 | AD26: 36.92 | AE26: 6207 | AF26: 434 | AG26: =AB26+AC26+AD26+AF26 -> 1209.32 | AK26: =Z26-AG26-AH26 -> -1209.32 | AL26: 7384 | AM26: 6207 | AN26: =ROUND(AL26*16%,2) -> 1181.44 | AO26: =ROUND(AL26*9%,2) -> 664.56 | AP26: =ROUND(AL26*0.5%,2) -> 36.92 | AQ26: 14.77 | AS26: =ROUND(AM26*7%,0) -> 434 | AT26: =ROUND(IF(AL26<24366,AL26*1.5%,24366*1.5%),2) -> 110.76 | AU26: =SUM(AN26:AT26) -> 2442.45 | AV26: =VLOOKUP(D26,[1]布列吉绩效清单!$F$7:$X$28,19,0) -> 147 | AW26: =AU26+Z26+AI26-AJ26+AV26 -> 2589.45 | AY26: -4.13 | AZ26: 工伤利率调整，1月多收2月退 | BA26: 255 | BB26: =ROUND(AW26+BA26+AY26+AX26,2) -> 2840.32 | BC26: =ROUND(BB26*6%,2) -> 170.42 | BD26: =ROUND(SUM(BB26:BC26),2) -> 3010.74
A27: =ROW()-2 -> 25 | B27: 2502 | C27: WB007254 | D27: 朱焱炎 | E27: 320681198812140829 | F27: 45444 | G27: 45808 | I27: 上海 | Z27: =SUM(J27:Y27) -> 0 | AA27: 7384 | AB27: 590.72 | AC27: 147.68 | AD27: 36.92 | AE27: 4997 | AF27: 350 | AG27: =AB27+AC27+AD27+AF27 -> 1125.32 | AK27: =Z27-AG27-AH27 -> -1125.32 | AL27: 7384 | AM27: 4997 | AN27: =ROUND(AL27*16%,2) -> 1181.44 | AO27: =ROUND(AL27*9%,2) -> 664.56 | AP27: =ROUND(AL27*0.5%,2) -> 36.92 | AQ27: 14.77 | AS27: =ROUND(AM27*7%,0) -> 350 | AT27: =ROUND(IF(AL27<24366,AL27*1.5%,24366*1.5%),2) -> 110.76 | AU27: =SUM(AN27:AT27) -> 2358.45 | AV27: =VLOOKUP(D27,[1]布列吉绩效清单!$F$7:$X$28,19,0) -> 211 | AW27: =AU27+Z27+AI27-AJ27+AV27 -> 2569.45 | AY27: -4.13 | AZ27: 工伤利率调整，1月多收2月退 | BA27: 255 | BB27: =ROUND(AW27+BA27+AY27+AX27,2) -> 2820.32 | BC27: =ROUND(BB27*6%,2) -> 169.22 | BD27: =ROUND(SUM(BB27:BC27),2) -> 2989.54
A28: =ROW()-2 -> 26 | B28: 2502 | C28: WB022966 | D28: 赵杭顺 | E28: 310102198702193618 | F28: 45444 | G28: 45808 | I28: 上海 | Z28: =SUM(J28:Y28) -> 0 | AA28: 11395 | AB28: 911.6 | AC28: 227.9 | AD28: 56.98 | AE28: 11395 | AF28: 798 | AG28: =AB28+AC28+AD28+AF28 -> 1994.48 | AK28: =Z28-AG28-AH28 -> -1994.48 | AL28: 11395 | AM28: 11395 | AN28: =ROUND(AL28*16%,2) -> 1823.2 | AO28: 1025.56 | AP28: =ROUND(AL28*0.5%,2) -> 56.98 | AQ28: 22.79 | AS28: =ROUND(AM28*7%,0) -> 798 | AT28: =ROUND(IF(AL28<24366,AL28*1.5%,24366*1.5%),2) -> 170.93 | AU28: =SUM(AN28:AT28) -> 3897.46 | AV28: =VLOOKUP(D28,[1]布列吉绩效清单!$F$7:$X$28,19,0) -> 195 | AW28: =AU28+Z28+AI28-AJ28+AV28 -> 4092.46 | AY28: -6.38 | AZ28: 工伤利率调整，1月多收2月退 | BA28: 255 | BB28: =ROUND(AW28+BA28+AY28+AX28,2) -> 4341.08 | BC28: =ROUND(BB28*6%,2) -> 260.46 | BD28: =ROUND(SUM(BB28:BC28),2) -> 4601.54
A29: =ROW()-2 -> 27 | B29: 2502 | C29: WB016859 | D29: 陆燕 | E29: 310113197802064324 | F29: 45444 | G29: 45808 | I29: 上海 | Z29: =SUM(J29:Y29) -> 0 | AA29: 7384 | AB29: 590.72 | AC29: 147.68 | AD29: 36.92 | AE29: 6844 | AF29: 479 | AG29: =AB29+AC29+AD29+AF29 -> 1254.32 | AK29: =Z29-AG29-AH29 -> -1254.32 | AL29: 7384 | AM29: 6844 | AN29: =ROUND(AL29*16%,2) -> 1181.44 | AO29: =ROUND(AL29*9%,2) -> 664.56 | AP29: =ROUND(AL29*0.5%,2) -> 36.92 | AQ29: 14.77 | AS29: =ROUND(AM29*7%,0) -> 479 | AT29: =ROUND(IF(AL29<24366,AL29*1.5%,24366*1.5%),2) -> 110.76 | AU29: =SUM(AN29:AT29) -> 2487.45 | AV29: =VLOOKUP(D29,[1]布列吉绩效清单!$F$7:$X$28,19,0) -> 504 | AW29: =AU29+Z29+AI29-AJ29+AV29 -> 2991.45 | AY29: -4.13 | AZ29: 工伤利率调整，1月多收2月退 | BA29: 255 | BB29: =ROUND(AW29+BA29+AY29+AX29,2) -> 3242.32 | BC29: =ROUND(BB29*6%,2) -> 194.54 | BD29: =ROUND(SUM(BB29:BC29),2) -> 3436.86
A30: =ROW()-2 -> 28 | B30: 2502 | C30: WB016826 | D30: 成瀛 | E30: 140103198304204830 | F30: 45444 | G30: 45808 | I30: 上海 | Z30: =SUM(J30:Y30) -> 0 | AA30: 7384 | AB30: 590.72 | AC30: 147.68 | AD30: 36.92 | AE30: 5131 | AF30: 359 | AG30: =AB30+AC30+AD30+AF30 -> 1134.32 | AK30: =Z30-AG30-AH30 -> -1134.32 | AL30: 7384 | AM30: 5131 | AN30: =ROUND(AL30*16%,2) -> 1181.44 | AO30: =ROUND(AL30*9%,2) -> 664.56 | AP30: =ROUND(AL30*0.5%,2) -> 36.92 | AQ30: 14.77 | AS30: =ROUND(AM30*7%,0) -> 359 | AT30: =ROUND(IF(AL30<24366,AL30*1.5%,24366*1.5%),2) -> 110.76 | AU30: =SUM(AN30:AT30) -> 2367.45 | AV30: =VLOOKUP(D30,[1]布列吉绩效清单!$F$7:$X$28,19,0) -> 142 | AW30: =AU30+Z30+AI30-AJ30+AV30 -> 2509.45 | AY30: -4.13 | AZ30: 工伤利率调整，1月多收2月退 | BA30: 255 | BB30: =ROUND(AW30+BA30+AY30+AX30,2) -> 2760.32 | BC30: =ROUND(BB30*6%,2) -> 165.62 | BD30: =ROUND(SUM(BB30:BC30),2) -> 2925.94
A31: =ROW()-2 -> 29 | B31: 2502 | C31: WB044433 | D31: 张枚 | E31: 340223199003157228 | F31: 45444 | G31: 45808 | I31: 上海 | Z31: =SUM(J31:Y31) -> 0 | AA31: 7384 | AB31: 590.72 | AC31: 147.68 | AD31: 36.92 | AE31: 4082 | AF31: 286 | AG31: =AB31+AC31+AD31+AF31 -> 1061.32 | AK31: =Z31-AG31-AH31 -> -1061.32 | AL31: 7384 | AM31: 4082 | AN31: =ROUND(AL31*16%,2) -> 1181.44 | AO31: =ROUND(AL31*9%,2) -> 664.56 | AP31: =ROUND(AL31*0.5%,2) -> 36.92 | AQ31: 14.77 | AS31: =ROUND(AM31*7%,0) -> 286 | AT31: =ROUND(IF(AL31<24366,AL31*1.5%,24366*1.5%),2) -> 110.76 | AU31: =SUM(AN31:AT31) -> 2294.45 | AV31: =VLOOKUP(D31,[1]布列吉绩效清单!$F$7:$X$28,19,0) -> 116 | AW31: =AU31+Z31+AI31-AJ31+AV31 -> 2410.45 | AY31: -4.13 | AZ31: 工伤利率调整，1月多收2月退 | BA31: 255 | BB31: =ROUND(AW31+BA31+AY31+AX31,2) -> 2661.32 | BC31: =ROUND(BB31*6%,2) -> 159.68 | BD31: =ROUND(SUM(BB31:BC31),2) -> 2821
A32: =ROW()-2 -> 30 | B32: 2502 | C32: WB039094 | D32: 张欢 | E32: 340321199602189283 | F32: 45444 | G32: 45808 | I32: 上海 | Z32: =SUM(J32:Y32) -> 0 | AA32: 7384 | AB32: 590.72 | AC32: 147.68 | AD32: 36.92 | AE32: 4035 | AF32: 282 | AG32: =AB32+AC32+AD32+AF32 -> 1057.32 | AK32: =Z32-AG32-AH32 -> -1057.32 | AL32: 7384 | AM32: 4035 | AN32: =ROUND(AL32*16%,2) -> 1181.44 | AO32: =ROUND(AL32*9%,2) -> 664.56 | AP32: =ROUND(AL32*0.5%,2) -> 36.92 | AQ32: 14.77 | AS32: =ROUND(AM32*7%,0) -> 282 | AT32: =ROUND(IF(AL32<24366,AL32*1.5%,24366*1.5%),2) -> 110.76 | AU32: =SUM(AN32:AT32) -> 2290.45 | AV32: =VLOOKUP(D32,[1]布列吉绩效清单!$F$7:$X$28,19,0) -> 76 | AW32: =AU32+Z32+AI32-AJ32+AV32 -> 2366.45 | AY32: -4.13 | AZ32: 工伤利率调整，1月多收2月退 | BA32: 255 | BB32: =ROUND(AW32+BA32+AY32+AX32,2) -> 2617.32 | BC32: =ROUND(BB32*6%,2) -> 157.04 | BD32: =ROUND(SUM(BB32:BC32),2) -> 2774.36
A33: =ROW()-2 -> 31 | B33: 2502 | C33: WB009624 | D33: 金霞 | E33: 310113198309114628 | F33: 45444 | G33: 45808 | I33: 上海 | Z33: =SUM(J33:Y33) -> 0 | AA33: 7384 | AB33: 590.72 | AC33: 147.68 | AD33: 36.92 | AE33: 7287 | AF33: 510 | AG33: =AB33+AC33+AD33+AF33 -> 1285.32 | AK33: =Z33-AG33-AH33 -> -1285.32 | AL33: 7384 | AM33: 7287 | AN33: =ROUND(AL33*16%,2) -> 1181.44 | AO33: =ROUND(AL33*9%,2) -> 664.56 | AP33: =ROUND(AL33*0.5%,2) -> 36.92 | AQ33: 14.77 | AS33: =ROUND(AM33*7%,0) -> 510 | AT33: =ROUND(IF(AL33<24366,AL33*1.5%,24366*1.5%),2) -> 110.76 | AU33: =SUM(AN33:AT33) -> 2518.45 | AV33: =VLOOKUP(D33,[1]布列吉绩效清单!$F$7:$X$28,19,0) -> 162 | AW33: =AU33+Z33+AI33-AJ33+AV33 -> 2680.45 | AY33: -4.13 | AZ33: 工伤利率调整，1月多收2月退 | BA33: 255 | BB33: =ROUND(AW33+BA33+AY33+AX33,2) -> 2931.32 | BC33: =ROUND(BB33*6%,2) -> 175.88 | BD33: =ROUND(SUM(BB33:BC33),2) -> 3107.2
A34: =ROW()-2 -> 32 | B34: 2502 | C34: WB009626 | D34: 殷颖 | E34: 310109198006192026 | F34: 45444 | G34: 45808 | I34: 上海 | Z34: =SUM(J34:Y34) -> 0 | AA34: 7384 | AB34: 590.72 | AC34: 147.68 | AD34: 36.92 | AE34: 6558 | AF34: 459 | AG34: =AB34+AC34+AD34+AF34 -> 1234.32 | AK34: =Z34-AG34-AH34 -> -1234.32 | AL34: 7384 | AM34: 6558 | AN34: =ROUND(AL34*16%,2) -> 1181.44 | AO34: =ROUND(AL34*9%,2) -> 664.56 | AP34: =ROUND(AL34*0.5%,2) -> 36.92 | AQ34: 14.77 | AS34: =ROUND(AM34*7%,0) -> 459 | AT34: =ROUND(IF(AL34<24366,AL34*1.5%,24366*1.5%),2) -> 110.76 | AU34: =SUM(AN34:AT34) -> 2467.45 | AV34: =VLOOKUP(D34,[1]布列吉绩效清单!$F$7:$X$28,19,0) -> 110 | AW34: =AU34+Z34+AI34-AJ34+AV34 -> 2577.45 | AY34: -4.13 | AZ34: 工伤利率调整，1月多收2月退 | BA34: 255 | BB34: =ROUND(AW34+BA34+AY34+AX34,2) -> 2828.32 | BC34: =ROUND(BB34*6%,2) -> 169.7 | BD34: =ROUND(SUM(BB34:BC34),2) -> 2998.02
A35: =ROW()-2 -> 33 | B35: 2502 | C35: WB009627 | D35: 夏士梅 | E35: 310113197707080027 | F35: 45444 | G35: 45808 | I35: 上海 | Z35: =SUM(J35:Y35) -> 0 | AA35: 7399 | AB35: 591.92 | AC35: 147.98 | AD35: 37 | AE35: 7399 | AF35: 518 | AG35: =AB35+AC35+AD35+AF35 -> 1294.9 | AK35: =Z35-AG35-AH35 -> -1294.9 | AL35: 7399 | AM35: 7399 | AN35: =ROUND(AL35*16%,2) -> 1183.84 | AO35: 665.92 | AP35: =ROUND(AL35*0.5%,2) -> 37 | AQ35: 14.8 | AS35: =ROUND(AM35*7%,0) -> 518 | AT35: =ROUND(IF(AL35<24366,AL35*1.5%,24366*1.5%),2) -> 110.99 | AU35: =SUM(AN35:AT35) -> 2530.55 | AV35: =VLOOKUP(D35,[1]布列吉绩效清单!$F$7:$X$28,19,0) -> 164 | AW35: =AU35+Z35+AI35-AJ35+AV35 -> 2694.55 | AY35: -4.14 | AZ35: 工伤利率调整，1月多收2月退 | BA35: 255 | BB35: =ROUND(AW35+BA35+AY35+AX35,2) -> 2945.41 | BC35: =ROUND(BB35*6%,2) -> 176.72 | BD35: =ROUND(SUM(BB35:BC35),2) -> 3122.13
A36: =ROW()-2 -> 34 | B36: 2502 | C36: WB009631 | D36: 杨晨晖 | E36: 310113199401265319 | F36: 45444 | G36: 45808 | I36: 上海 | Z36: =SUM(J36:Y36) -> 0 | AA36: 7384 | AB36: 590.72 | AC36: 147.68 | AD36: 36.92 | AE36: 7155 | AF36: 501 | AG36: =AB36+AC36+AD36+AF36 -> 1276.32 | AK36: =Z36-AG36-AH36 -> -1276.32 | AL36: 7384 | AM36: 7155 | AN36: =ROUND(AL36*16%,2) -> 1181.44 | AO36: =ROUND(AL36*9%,2) -> 664.56 | AP36: =ROUND(AL36*0.5%,2) -> 36.92 | AQ36: 14.77 | AS36: =ROUND(AM36*7%,0) -> 501 | AT36: =ROUND(IF(AL36<24366,AL36*1.5%,24366*1.5%),2) -> 110.76 | AU36: =SUM(AN36:AT36) -> 2509.45 | AV36: =VLOOKUP(D36,[1]布列吉绩效清单!$F$7:$X$28,19,0) -> 169 | AW36: =AU36+Z36+AI36-AJ36+AV36 -> 2678.45 | AY36: -4.13 | AZ36: 工伤利率调整，1月多收2月退 | BA36: 255 | BB36: =ROUND(AW36+BA36+AY36+AX36,2) -> 2929.32 | BC36: =ROUND(BB36*6%,2) -> 175.76 | BD36: =ROUND(SUM(BB36:BC36),2) -> 3105.08
A37: =ROW()-2 -> 35 | B37: 2502 | C37: WB030237 | D37: 顾文君 | E37: 310110198605095645 | F37: 45444 | G37: 45808 | I37: 上海 | Z37: =SUM(J37:Y37) -> 0 | AA37: 13189 | AB37: 1055.12 | AC37: 263.78 | AD37: 65.95 | AE37: 13189 | AF37: 923 | AG37: =AB37+AC37+AD37+AF37 -> 2307.85 | AK37: =Z37-AG37-AH37 -> -2307.85 | AL37: 13189 | AM37: 13189 | AN37: =ROUND(AL37*16%,2) -> 2110.24 | AO37: 1187.02 | AP37: =ROUND(AL37*0.5%,2) -> 65.95 | AQ37: 26.38 | AS37: =ROUND(AM37*7%,0) -> 923 | AT37: =ROUND(IF(AL37<24366,AL37*1.5%,24366*1.5%),2) -> 197.84 | AU37: =SUM(AN37:AT37) -> 4510.43 | AV37: =VLOOKUP(D37,[1]布列吉绩效清单!$F$7:$X$28,19,0) -> 263 | AW37: =AU37+Z37+AI37-AJ37+AV37 -> 4773.43 | AY37: -7.38 | AZ37: 工伤利率调整，1月多收2月退 | BA37: 255 | BB37: =ROUND(AW37+BA37+AY37+AX37,2) -> 5021.05 | BC37: =ROUND(BB37*6%,2) -> 301.26 | BD37: =ROUND(SUM(BB37:BC37),2) -> 5322.31
A38: =ROW()-2 -> 36 | B38: 2502 | C38: WB016896 | D38: 朱琳 | E38: 310115197811118649 | F38: 45444 | G38: 45808 | I38: 上海 | Z38: =SUM(J38:Y38) -> 0 | AA38: 9758 | AB38: 780.64 | AC38: 195.16 | AD38: 48.79 | AE38: 9758 | AF38: 683 | AG38: =AB38+AC38+AD38+AF38 -> 1707.59 | AK38: =Z38-AG38-AH38 -> -1707.59 | AL38: 9758 | AM38: 9758 | AN38: =ROUND(AL38*16%,2) -> 1561.28 | AO38: =ROUND(AL38*9%,2) -> 878.22 | AP38: =ROUND(AL38*0.5%,2) -> 48.79 | AQ38: 19.52 | AS38: =ROUND(AM38*7%,0) -> 683 | AT38: =ROUND(IF(AL38<24366,AL38*1.5%,24366*1.5%),2) -> 146.37 | AU38: =SUM(AN38:AT38) -> 3337.18 | AV38: =VLOOKUP(D38,[1]布列吉绩效清单!$F$7:$X$28,19,0) -> 330 | AW38: =AU38+Z38+AI38-AJ38+AV38 -> 3667.18 | AY38: -5.46 | AZ38: 工伤利率调整，1月多收2月退 | BA38: 60 | BB38: =ROUND(AW38+BA38+AY38+AX38,2) -> 3721.72 | BC38: =ROUND(BB38*6%,2) -> 223.3 | BD38: =ROUND(SUM(BB38:BC38),2) -> 3945.02
A41: 纵向团队合计 | Z41: =SUBTOTAL(9,Z3:Z16) -> 0 | AG41: =SUBTOTAL(9,AG3:AG16) -> 24133.91 | AK41: =SUBTOTAL(9,AK3:AK16) -> -24133.91 | AU41: =SUBTOTAL(9,AU3:AU16) -> 47389.77 | AV41: =SUBTOTAL(9,AV3:AV16) -> 2407 | AW41: =SUBTOTAL(9,AW3:AW16) -> 49796.77 | AX41: =SUBTOTAL(9,AX3:AX16) -> 0 | AY41: =SUBTOTAL(9,AY3:AY16) -> -77.98 | BA41: =SUBTOTAL(9,BA3:BA16) -> 3570 | BB41: =SUBTOTAL(9,BB3:BB16) -> 53288.79 | BC41: =SUBTOTAL(9,BC3:BC16) -> 3197.34 | BD41: =SUBTOTAL(9,BD3:BD16) -> 56486.13
A42: 营业厅合计 | Z42: =SUBTOTAL(9,Z17:Z38) -> 0 | AG42: =SUBTOTAL(9,AG17:AG38) -> 32752.24 | AK42: =SUBTOTAL(9,AK17:AK38) -> -32752.24 | AU42: =SUBTOTAL(9,AU17:AU38) -> 65521.29 | AV42: =SUBTOTAL(9,AV17:AV38) -> 4965 | AW42: =SUBTOTAL(9,AW17:AW38) -> 70486.29 | AX42: =SUBTOTAL(9,AX17:AX38) -> 0 | AY42: =SUBTOTAL(9,AY17:AY38) -> -109.81 | BA42: =SUBTOTAL(9,BA17:BA38) -> 5415 | BB42: =SUBTOTAL(9,BB17:BB38) -> 75791.48 | BC42: =SUBTOTAL(9,BC17:BC38) -> 4547.48 | BD42: =SUBTOTAL(9,BD17:BD38) -> 80338.96
...
