Workbook

Sheet 202501
A1: 序号 | B1: 计薪 周期 | C1: 工号 | D1: 姓名 | E1: 身份证号 | F1: 劳动合同起始日期 | G1: 劳动合同结束日期 | H1: 离职日期 | I1: 社保缴纳地 | J1: 星级费用 | K1: 考核费用 | L1: 量化费用 | M1: 专项费用 | Z1: 当月税前工资合计 | AA1: 社保基数(个人) | AB1: 养老保险(个人) | AC1: 医疗保险(个人) | AD1: 失业保险(个人) | AE1: 公积金基数(个人) | AF1: 住房公积金(个人) | AG1: 员工五险一金合计 | AH1: 本月个人所得税-系统导出 | AI1: 税后增加 | AJ1: 税后扣减 | AK1: 员工实发合计 | AL1: 社保基数 | AM1: 公积金基数 | AN1: 养老缴费 | AO1: 医疗缴费 | AP1: 失业保险 | AQ1: 工伤保险 | AR1: 生育保险 | AS1: 公积金 | AT1: 残保金 | AU1: 企业五险一金合计 | AV1: 工会费 | AW1: 代收付合计 | AX1: 本月垫付下月收 | AY1: 本月多收下月退 | AZ1: 社保备注 | BA1: 外包服务费 | BB1: 税前项合计 | BC1: 增值税 | BD1: 总计
A2: NO. | B2: Salary Cycle | C2: Employee No. | D2: Name | E2: ID No. | F2: Contract Starting Date | G2: Contract Expiry Date | H2: Exit Date | I2: Social Insurance City | J2: Contract Salary | K2: Assessment fees | L2: Quantifying costs | M2: 支局专项 | N2: 部门加奖 | O2: 交通费 | P2: 效能补贴 | Q2: 高温费及清凉饮料费 （6-9月） | R2: 伙食补贴 | S2: 独生子女奖励 | T2: 保险费 | U2: 其他费用 | V2: 补发费用 | W2: 劳防用品 | X2: 保障补差 | Y2: 其他扣款 | Z2: Pre-tax Total | AA2: Social Insurance Base | AB2: Pension Employee | AC2: Medical Employee | AD2: Umemployment Employee | AE2: Housing Fund Base | AF2: Housing Fund Employee | AG2: Total Amount of Social Insurance(EE) | AH2: Personal Income Tax | AI2: Increase After-tax payment | AJ2: Reduction After-tax payment | AK2: After-tax total Income | AL2: Social Insurance Base | AM2: Housing Fund Base | AN2: Pension Employer | AO2: Medical Employer | AP2: Umemployment Employer | AQ2: Injury Employer | AR2: Maternity Insurance Employer | AS2: Housing Fund Employer | AT2: Disabled people&Back pay Fund | AU2: Total Amount of Social Insurance(ER) | AV2: Union Fee | AW2: Payment Total | AZ2: Social Security remark | BA2: Service Fee | BB2: Total | BC2: VAT | BD2: Subtotal
A3: =ROW()-2 -> 1 | B3: 2501 | C3: WB007174 | D3: 傅强 | E3: 342501197805270274 | F3: 45444 | G3: 45808 | I3: 上海 | J3: 950 | L3: 1694.7 | X3: 1281.62 | Z3: =SUM(J3:Y3) -> 3926.32 | AA3: 7384 | AB3: 590.72 | AC3: 147.68 | AD3: 36.92 | AE3: 6520 | AF3: =ROUND(AE3*7%,0) -> 456 | AG3: =AB3+AC3+AD3+AF3 -> 1231.32 | AK3: =Z3-AG3-AH3 -> 2695 | AL3: 7384 | AM3: 6520 | AN3: =ROUND(AL3*16%,2) -> 1181.44 | AO3: =ROUND(AL3*9%,2) -> 664.56 | AP3: =ROUND(AL3*0.5%,2) -> 36.92 | AQ3: 14.77 | AS3: =ROUND(AM3*7%,0) -> 456 | AT3: =ROUND(IF(AL3<22792,AL3*1.5%,22792*1.5%),2) -> 110.76 | AU3: =SUM(AN3:AT3) -> 2464.45 | AV3: 78 | AW3: =AU3+Z3+AI3-AJ3+AV3 -> 6468.77 | AX3: -5 | AY3: 4.13 | AZ3: 1月垫付保障补差5元，2月收，工伤比例调整，1月多收2月退 | BA3: 60 | BB3: =ROUND(AW3+BA3++AY3+AX3,2) -> 6527.9 | BC3: =ROUND(BB3*6%,2) -> 391.67 | BD3: =ROUND(SUM(BB3:BC3),2) -> 6919.57
A4: =ROW()-2 -> 2 | B4: 2501 | C4: WB007141 | D4: 汤熙荣 | E4: 310108197210073613 | F4: 45383 | G4: 45747 | I4: 上海 | J4: 950 | X4: 2986.32 | Z4: =SUM(J4:Y4) -> 3936.32 | AA4: 7384 | AB4: 590.72 | AC4: 147.68 | AD4: 36.92 | AE4: 6653 | AF4: =ROUND(AE4*7%,0) -> 466 | AG4: =AB4+AC4+AD4+AF4 -> 1241.32 | AK4: =Z4-AG4-AH4 -> 2695 | AL4: 7384 | AM4: 6653 | AN4: =ROUND(AL4*16%,2) -> 1181.44 | AO4: =ROUND(AL4*9%,2) -> 664.56 | AP4: =ROUND(AL4*0.5%,2) -> 36.92 | AQ4: 14.77 | AS4: =ROUND(AM4*7%,0) -> 466 | AT4: =ROUND(IF(AL4<22792,AL4*1.5%,22792*1.5%),2) -> 110.76 | AU4: =SUM(AN4:AT4) -> 2474.45 | AV4: 79 | AW4: =AU4+Z4+AI4-AJ4+AV4 -> 6489.77 | AX4: -5 | AY4: 4.13 | AZ4: 1月垫付保障补差5元，2月收，工伤比例调整，1月多收2月退 | BA4: 60 | BB4: =ROUND(AW4+BA4++AY4+AX4,2) -> 6548.9 | BC4: =ROUND(BB4*6%,2) -> 392.93 | BD4: =ROUND(SUM(BB4:BC4),2) -> 6941.83
A6: 合计 | Z6: =SUBTOTAL(9,Z3:Z4) -> 7862.64 | AG6: =SUBTOTAL(9,AG3:AG4) -> 2472.64 | AK6: =SUBTOTAL(9,AK3:AK4) -> 5390 | AU6: =SUBTOTAL(9,AU3:AU4) -> 4938.9 | AV6: =SUM(AV3:AV4) -> 157 | AW6: =SUBTOTAL(9,AW3:AW4) -> 12958.54 | AX6: =SUBTOTAL(9,AX3:AX4) -> -10 | AY6: =SUBTOTAL(9,AY3:AY4) -> 8.26 | BA6: =SUBTOTAL(9,BA3:BA4) -> 120 | BB6: =SUBTOTAL(9,BB3:BB4) -> 13076.8 | BC6: =SUBTOTAL(9,BC3:BC4) -> 784.6 | BD6: =SUBTOTAL(9,BD3:BD4) -> 13861.4
BA8: 实际结算 | BB8: 303434.72
BA9: 差额下月补 | BB9: 111.61
A10: 本月垫付，下月补收
A11: 序号 | B11: 计薪 周期 | C11: 工号 | D11: 姓名 | E11: 身份证号 | F11: 劳动合同起始日期 | G11: 劳动合同结束日期 | H11: 离职日期 | I11: 社保缴纳地 | J11: 本月垫付下月收 | K11: 社保备注
A12: NO. | B12: Salary Cycle | C12: Employee No. | D12: Name | E12: ID No. | F12: Contract Starting Date | G12: Contract Expiry Date | H12: Exit Date | I12: Social Insurance City | K12: Social Security remark
A13: 1 | B13: 2501 | C13: WB007174 | D13: 傅强 | E13: 342501197805270274 | F13: 45444 | G13: 45808 | I13: 上海 | J13: 5 | K13: 1月垫付保障补差5元，2月收
A14: 2 | B14: 2501 | C14: WB007141 | D14: 汤熙荣 | E14: 310108197210073613 | F14: 45383 | G14: 45747 | I14: 上海 | J14: 5 | K14: 1月垫付保障补差5元，2月收
J15: =SUM(J13:J14) -> 10
A16: 本月垫付，下月补收
A17: 序号 | B17: 计薪 周期 | C17: 工号 | D17: 姓名 | E17: 身份证号 | F17: 劳动合同起始日期 | G17: 劳动合同结束日期 | H17: 离职日期 | I17: 社保缴纳地 | J17: 本月垫付下月收 | K17: 社保备注
A18: NO. | B18: Salary Cycle | C18: Employee No. | D18: Name | E18: ID No. | F18: Contract Starting Date | G18: Contract Expiry Date | H18: Exit Date | I18: Social Insurance City | K18: Social Security remark
A19: 1 | B19: 2501 | C19: WB007174 | D19: 傅强 | E19: 342501197805270274 | F19: 45444 | G19: 45808 | I19: 上海 | J19: -4.13 | K19: 工伤比例调整，1月多收2月退
A20: 2 | B20: 2501 | C20: WB007141 | D20: 汤熙荣 | E20: 310108197210073613 | F20: 45383 | G20: 45747 | I20: 上海 | J20: -4.13 | K20: 工伤比例调整，1月多收2月退
J21: =SUM(J19:J20) -> -8.26

Sheet 对账单
A1: 科目 | B1: 手工账单 | C1: 7月速创账单 | D1: 155 | E1: 预收一次性 | F1: 1月工会费 | G1: 本月垫付，下月收 | H1: 本月多收，下月退 | I1: 合计 | J1: 差异
A2: 管理费 | B2: ='202501'!BC6 -> 784.6 | C2: =系统!E18 -> 894.7 | I2: =SUM(C2:G2) -> 894.7 | J2: =B2-C2 -> -110.1
A3: 风险费 | B3: ='202501'!BA6 -> 120 | C3: 0 | I3: =SUM(C3:G3) -> 0 | J3: =B3-C3 -> 120
A4: 个人四金 | B4: ='202501'!AG6 -> 2472.64 | C4: =系统!V18 -> 2472.64 | I4: =SUM(C4:G4) -> 2472.64 | J4: =B4-C4 -> 0
A5: 公司四金 | B5: ='202501'!AU6 -> 4938.9 | C5: =系统!O18 -> 4938.9 | E5: =90.18 -> 90.18 | I5: =SUM(C5:E5) -> 5029.08 | J5: =B5-C5 -> 0
A6: 工伤退费 | C6: =-90.18 -> -90.18 | I6: =SUM(C6:G6) -> -90.18 | J6: =B6-C6 -> 90.18
A7: 代发工资 | B7: ='202501'!AK6 -> 5390 | C7: =系统!W18 -> 5380 | D7: =2*5+8.26-10 -> 8.26 | I7: =SUM(C7:G7) -> 5388.26 | J7: =B7-C7 -> 10
A8: 本月垫付 | B8: ='202501'!AX6 -> -10 | I8: =SUM(C8:G8) -> 0 | J8: =B8-C8 -> -10
A9: 工会费 | B9: ='202501'!AV6 -> 157 | F9: =B9 -> 157 | I9: =SUM(C9:G9) -> 157 | J9: =B9-C9 -> 157
A10: 本月多收 | B10: ='202501'!AY6 -> 8.26 | I10: =SUM(C10:G10) -> 0 | J10: =B10-C10 -> 8.26
A11: 小计 | B11: =SUM(B2:B10) -> 13861.4 | C11: =SUM(C2:C10) -> 13596.06 | D11: =D7 -> 8.26 | E11: =E5 -> 90.18 | F11: =F9 -> 157 | G11: =G9 -> 0 | H11: =H9 -> 0 | I11: =SUM(C11:G11) -> 13851.5
A12: 附加税
A13: 增值税 | D13: =ROUND((D11+D12)*6%,2) -> 0.5 | F13: =ROUND((F11+F12)*6%,2) -> 9.42 | G13: =ROUND((G11+G12)*6%,2) -> 0 | H13: =ROUND((H11+H12)*6%,2) -> 0 | I13: =SUM(C13:G13) -> 9.92
A14: 总计 | B14: =SUM(B11:B13) -> 13861.4 | C14: =SUM(C11:C13) -> 13596.06 | D14: =SUM(D11:D13) -> 8.76 | E14: =E11 -> 90.18 | F14: =SUM(F11:F13) -> 166.42 | G14: =SUM(G11:G13) -> 0 | H14: =SUM(H11:H13) -> 0 | I14: =SUM(C14:H14) -> 13861.42
A15: 给客户账单金额 | I15: =B14 -> 13861.4
A16: 差异 | I16: =I15-I14 -> -0.02
A17: 不含税差异 | I17: =ROUND(I16/1.06,2) -> -0.02

Sheet 系统
A1: 200070
A2: 寄：梅园路77号人才大厦
B3: 中国电信股份有限公司上海分公司 王慧珏 收
D6: 上海外服布列吉科技有限公司
C7: Shanghai Foreign Service Bridge Technology Co,Ltd.
E9: 收款通知书
E10: ADVISE ON COLLECTION
E11: 2025年01月
A13: 公司名称：中国电信股份有限公司上海分公司 | J13: 帐单号：202501CH6596308
A14: 序号 | B14: 姓名 | C14: 发生年月 | D14: 入职日期 | E14: 管理费 | F14: 当月社保基数 | G14: 当月公积金基数 | H14: 社保类 公司支付 Social Insurance Premiums Paid by Employer | N14: 公积金类 公司支付 Provident Fund Paid by Employer | O14: 公司合计 | P14: 社保类 个人支付 Social Insurance Premiums Paid by Employee | U14: 公积金类 个人支付 Provident Fund Paid by Employee | V14: 个人合计 | W14: 代办薪酬 | X14: 历月补收 | Y14: 其他 | Z14: 总计 | AA14: 备注 | AB14: 外服工号 | AC14: 证件号码 | AD14: 应纳税金额 | AE14: 税率 | AF14: 增值税
A15: S/N | B15: Name | C15: YYYYMM | D15: Employment Start Date | E15: Adm Fee | F15: Social Insurance Base Amount of Current Month | G15: Provident Fund Base Amount of Current Month | H15: 养老保险 Endowment | I15: 医疗保险 Medical | J15: 失业保险 Unemploy-ment | K15: 工伤保险 Employment Injury | L15: 医疗生育保险 Medical Maternity | M15: 保障金 Disabled people&Back pay Fund | N15: 公积金 Provident Fund | O15: Subtotal of Employer Payment | P15: 养老保险 Endowment | Q15: 医疗保险 Medical | R15: 失业保险 Unemploy-ment | S15: 工伤保险 Employment Injury | T15: 医疗生育保险 Medical Maternity | U15: 公积金 Provident Fund | V15: Subtotal of Personal Payment | W15: Agency of Wage Payment | Y15: Others | Z15: Total | AA15: Remarks | AB15: SFSC ID | AC15: ID Card | AD15: Taxable Amount | AE15: Tax Rate | AF15: VAT
A16: 1 | B16: 傅强 | C16: 202501 | D16: 2024-06-01 | E16: 446.75 | F16: 7384 | G16: 6520 | H16: 1181.44 | I16: 664.56 | J16: 36.92 | K16: 14.77 | M16: 110.76 | N16: 456 | O16: =SUM(H16:N16) -> 2464.45 | P16: 590.72 | Q16: 147.68 | R16: 36.92 | U16: 456 | V16: =SUM(P16:U16) -> 1231.32 | W16: 2690 | X16: -45.09 | Z16: =SUM(E16,O16,V16:Y16) -> 6787.43 | AB16: 6031699 | AC16: 342501197805270274 | AD16: 6403.22 | AE16: 6% | AF16: 384.21
A17: 2 | B17: 汤熙荣 | C17: 202501 | D17: 2024-04-01 | E17: 447.95 | F17: 7384 | G17: 6653 | H17: 1181.44 | I17: 664.56 | J17: 36.92 | K17: 14.77 | M17: 110.76 | N17: 466 | O17: =SUM(H17:N17) -> 2474.45 | P17: 590.72 | Q17: 147.68 | R17: 36.92 | U17: 466 | V17: =SUM(P17:U17) -> 1241.32 | W17: 2690 | X17: -45.09 | Z17: =SUM(E17,O17,V17:Y17) -> 6808.63 | AB17: 5987320 | AC17: 310108197210073613 | AD17: 6423.22 | AE17: 6% | AF17: 385.41
A18: 合计（RMB） | E18: =SUM(E16:E17) -> 894.7 | H18: =SUM(H16:H17) -> 2362.88 | I18: =SUM(I16:I17) -> 1329.12 | J18: =SUM(J16:J17) -> 73.84 | K18: =SUM(K16:K17) -> 29.54 | L18: =SUM(L16:L17) -> 0 | M18: =SUM(M16:M17) -> 221.52 | N18: =SUM(N16:N17) -> 922 | O18: =SUM(O16:O17) -> 4938.9 | ... Z18: =SUM(Z16:Z17) -> 13596.06 | AD18: =SUM(AD16:AD17) -> 12826.44 | AF18: =SUM(AF16:AF17) -> 769.62
A19: 总计（RMB）已包含历月补收人民币壹万叁仟伍佰玖拾陆圆零陆分 | Z19: 13596.06
A20: 历月补收明细
A21: 序号 | B21: 姓名 | C21: 发生年月 | D21: 入职日期 | E21: 当月社保基数 | F21: 社保类 公司支付 Social Insurance Premiums Paid by Employer | K21: 公司合计 | L21: 社保类 个人支付 Social Insurance Premiums Paid by Employee | Q21: 个人合计 | R21: 其他 | S21: 总计 | T21: 备注 | U21: 外服工号 | V21: 证件号码 | W21: 应纳税金额 | X21: 税率 | Y21: 增值税
A22: S/N | B22: Name | C22: YYYYMM | D22: Employment Start Date | E22: Social Insurance Base Amount of Current Month | F22: 养老保险 Endowment | G22: 医疗保险 Medical | H22: 失业保险 Unemploy-ment | I22: 工伤保险 Employment Injury | J22: 医疗生育保险 Medical Maternity | K22: Subtotal of Employer Payment | L22: 养老保险 Endowment | M22: 医疗保险 Medical | N22: 失业保险 Unemploy-ment | O22: 工伤保险 Employment Injury | P22: 医疗生育保险 Medical Maternity | Q22: Subtotal of Personal Payment | R22: Others | S22: Total | T22: Remarks | U22: SFSC ID | V22: ID Card | W22: Taxable Amount | X22: Tax Rate | Y22: VAT
A23: 1 | B23: 傅强 | C23: 202407 | D23: 2024-06-01 | I23: -7.09 | K23: =SUM(F23:J23) -> -7.09 | Q23: =SUM(L23:P23) -> 0 | S23: =SUM(K23,Q23:R23) -> -7.09 | U23: 6031699 | V23: 342501197805270274 | W23: -7.09 | X23: 6% | Y23: -0.43
B24: 傅强 | C24: 202408 | D24: 2024-06-01 | I24: -7.09 | K24: =SUM(F24:J24) -> -7.09 | Q24: =SUM(L24:P24) -> 0 | S24: =SUM(K24,Q24:R24) -> -7.09 | U24: 6031699 | V24: 342501197805270274 | W24: -7.09 | X24: 6% | Y24: -0.43
B25: 傅强 | C25: 202409 | D25: 2024-06-01 | I25: -7.09 | K25: =SUM(F25:J25) -> -7.09 | Q25: =SUM(L25:P25) -> 0 | S25: =SUM(K25,Q25:R25) -> -7.09 | U25: 6031699 | V25: 342501197805270274 | W25: -7.09 | X25: 6% | Y25: -0.43
B26: 傅强 | C26: 202410 | D26: 2024-06-01 | I26: -7.09 | K26: =SUM(F26:J26) -> -7.09 | Q26: =SUM(L26:P26) -> 0 | S26: =SUM(K26,Q26:R26) -> -7.09 | U26: 6031699 | V26: 342501197805270274 | W26: -7.09 | X26: 6% | Y26: -0.43
B27: 傅强 | C27: 202411 | D27: 2024-06-01 | I27: -7.09 | K27: =SUM(F27:J27) -> -7.09 | Q27: =SUM(L27:P27) -> 0 | S27: =SUM(K27,Q27:R27) -> -7.09 | U27: 6031699 | V27: 342501197805270274 | W27: -7.09 | X27: 6% | Y27: -0.43
B28: 傅强 | C28: 202412 | D28: 2024-06-01 | I28: -7.09 | K28: =SUM(F28:J28) -> -7.09 | Q28: =SUM(L28:P28) -> 0 | S28: =SUM(K28,Q28:R28) -> -7.09 | U28: 6031699 | V28: 342501197805270274 | W28: -7.09 | X28: 6% | Y28: -0.4
A29: 2 | B29: 汤熙荣 | C29: 202407 | D29: 2024-04-01 | I29: -7.09 | K29: =SUM(F29:J29) -> -7.09 | Q29: =SUM(L29:P29) -> 0 | S29: =SUM(K29,Q29:R29) -> -7.09 | U29: 5987320 | V29: 310108197210073613 | W29: -7.09 | X29: 6% | Y29: -0.43
B30: 汤熙荣 | C30: 202408 | D30: 2024-04-01 | I30: -7.09 | K30: =SUM(F30:J30) -> -7.09 | Q30: =SUM(L30:P30) -> 0 | S30: =SUM(K30,Q30:R30) -> -7.09 | U30: 5987320 | V30: 310108197210073613 | W30: -7.09 | X30: 6% | Y30: -0.43
B31: 汤熙荣 | C31: 202409 | D31: 2024-04-01 | I31: -7.09 | K31: =SUM(F31:J31) -> -7.09 | Q31: =SUM(L31:P31) -> 0 | S31: =SUM(K31,Q31:R31) -> -7.09 | U31: 5987320 | V31: 310108197210073613 | W31: -7.09 | X31: 6% | Y31: -0.43
B32: 汤熙荣 | C32: 202410 | D32: 2024-04-01 | I32: -7.09 | K32: =SUM(F32:J32) -> -7.09 | Q32: =SUM(L32:P32) -> 0 | S32: =SUM(K32,Q32:R32) -> -7.09 | U32: 5987320 | V32: 310108197210073613 | W32: -7.09 | X32: 6% | Y32: -0.43
B33: 汤熙荣 | C33: 202411 | D33: 2024-04-01 | I33: -7.09 | K33: =SUM(F33:J33) -> -7.09 | Q33: =SUM(L33:P33) -> 0 | S33: =SUM(K33,Q33:R33) -> -7.09 | U33: 5987320 | V33: 310108197210073613 | W33: -7.09 | X33: 6% | Y33: -0.43
B34: 汤熙荣 | C34: 202412 | D34: 2024-04-01 | I34: -7.09 | K34: =SUM(F34:J34) -> -7.09 | Q34: =SUM(L34:P34) -> 0 | S34: =SUM(K34,Q34:R34) -> -7.09 | U34: 5987320 | V34: 310108197210073613 | W34: -7.09 | X34: 6% | Y34: -0.4
A35: 合计（RMB） | F35: =SUM(F23:F34) -> 0 | G35: =SUM(G23:G34) -> 0 | H35: =SUM(H23:H34) -> 0 | I35: =SUM(I23:I34) -> -85.08 | J35: =SUM(J23:J34) -> 0 | K35: =SUM(K23:K34) -> -85.08 | L35: =SUM(L23:L34) -> 0 | M35: =SUM(M23:M34) -> 0 | ... S35: =SUM(S23:S34) -> -85.08 | W35: =SUM(W23:W34) -> -85.08 | Y35: =SUM(Y23:Y34) -> -5.1
A36: 总计（RMB）人民币负数玖拾圆壹角捌分 | S36: -90.18
A38: 其他费用
A39: 序号 | B39: 发生年月 | C39: 费用项目 | D39: 金额 | E39: 备注 | F39: 应纳税金额 | G39: 税率 | H39: 增值税
A40: S/N | B40: YYYYMM | C40: Item | D40: Amount | E40: Remarks | F40: Taxable Amount | G40: Tax Rate | H40: VAT
A41: 1 | B41: 202501 | C41: 风险金 | D41: 8.76 | F41: 8.26 | G41: 0.06 | H41: 0.5
A42: 2 | B42: 202501 | C42: 服务费 | D42: 166.42 | F42: 157 | G42: 0.06 | H42: 9.42
A43: 3 | B43: 202501 | C43: 税差调整6% | D43: 0 | F43: 0.04 | G43: 0.06 | H43: -0.04
A44: 合计（RMB） | D44: =SUM(D41:D43) -> 175.18 | F44: =SUM(F41:F43) -> 165.3 | H44: =SUM(H41:H43) -> 9.88
A45: 总计（RMB）人民币壹佰柒拾伍圆壹角捌分 | D45: 175.18 | F45: 165.3 | H45: 9.88
...
