Workbook

Sheet 202501
A1: 序号 | B1: 计薪 周期 | C1: 工号 | D1: 姓名 | E1: 身份证号 | F1: 劳动合同起始日期 | G1: 劳动合同结束日期 | H1: 离职日期 | I1: 社保缴纳地 | J1: 星级费用 | K1: 考核费用 | L1: 量化费用 | M1: 专项费用 | Z1: 当月税前工资合计 | AA1: 社保基数(个人) | AB1: 养老保险(个人) | AC1: 医疗保险(个人) | AD1: 失业保险(个人) | AE1: 公积金基数(个人) | AF1: 住房公积金(个人) | AG1: 员工五险一金合计 | AH1: 本月个人所得税-系统导出 | AI1: 税后增加 | AJ1: 税后扣减 | AK1: 员工实发合计 | AL1: 社保基数 | AM1: 公积金基数 | AN1: 养老缴费 | AO1: 医疗缴费 | AP1: 失业保险 | AQ1: 工伤保险 | AR1: 生育保险 | AS1: 公积金 | AT1: 残保金 | AU1: 企业五险一金合计 | AV1: 工会费 | AW1: 代收付合计 | AX1: 本月垫付下月收 | AY1: 本月多收下月退 | AZ1: 社保备注 | BA1: 外包服务费 | BB1: 税前项合计 | BC1: 增值税 | BD1: 总计
A2: NO. | B2: Salary Cycle | C2: Employee No. | D2: Name | E2: ID No. | F2: Contract Starting Date | G2: Contract Expiry Date | H2: Exit Date | I2: Social Insurance City | J2: Contract Salary | K2: Assessment fees | L2: Quantifying costs | M2: 支局专项 | N2: 1+1激励 | O2: 体检费 | P2: 通信费 | Q2: 高温费及清凉饮料费 （6-9月） | R2: 伙食补贴 | S2: 独生子女奖励 | T2: 保险费 | U2: 其他费用 | V2: 补发费用 | W2: 劳防用品 | X2: 保障补差 | Y2: 其他扣款 | Z2: Pre-tax Total | AA2: Social Insurance Base | AB2: Pension Employee | AC2: Medical Employee | AD2: Umemployment Employee | AE2: Housing Fund Base | AF2: Housing Fund Employee | AG2: Total Amount of Social Insurance(EE) | AH2: Personal Income Tax | AI2: Increase After-tax payment | AJ2: Reduction After-tax payment | AK2: After-tax total Income | AL2: Social Insurance Base | AM2: Housing Fund Base | AN2: Pension Employer | AO2: Medical Employer | AP2: Umemployment Employer | AQ2: Injury Employer | AR2: Maternity Insurance Employer | AS2: Housing Fund Employer | AT2: Disabled people&Back pay Fund | AU2: Total Amount of Social Insurance(ER) | AV2: Union Fee | AW2: Payment Total | AZ2: Social Security remark | BA2: Service Fee | BB2: Total | BC2: VAT | BD2: Subtotal
A3: =ROW()-2 -> 1 | B3: 2501 | C3: WB016994 | D3: 王邹强 | E3: 310108198909220554 | F3: 45444 | G3: 45808 | I3: 上海 | J3: 1300 | K3: 5664.8 | L3: 1517.58 | R3: 630 | X3: =IF((SUM(J3:L3,Y3)-AG3)<2695,2695-(SUM(J3:L3,Y3)-AG3),"") | Z3: =SUM(J3:Y3) -> 9112.38 | AA3: 8707 | AB3: 696.56 | AC3: 174.14 | AD3: 43.54 | AE3: 8707 | AF3: =ROUND(AE3*7%,0) -> 609 | AG3: =AB3+AC3+AD3+AF3 -> 1523.24 | AK3: =Z3-AG3-AH3 -> 7589.14 | AL3: 8707 | AM3: 8707 | AN3: =ROUND(AL3*16%,2) -> 1393.12 | AO3: 783.64 | AP3: =ROUND(AL3*0.5%,2) -> 43.54 | AQ3: 17.41 | AS3: =ROUND(AM3*7%,0) -> 609 | AT3: =ROUND(IF(AL3<24366,AL3*1.5%,24366*1.5%),2) -> 130.61 | AU3: =SUM(AN3:AT3) -> 2977.32 | AV3: 170 | AW3: =AU3+Z3+AI3-AJ3+AV3 -> 12259.7 | AY3: 4.88 | AZ3: 工伤利率调整，1月多收2月退 | BA3: 255 | BB3: =ROUND(AW3+BA3+AX3+AY3,2) -> 12519.58 | BC3: =ROUND(BB3*6%,2) -> 751.17 | BD3: =ROUND(SUM(BB3:BC3),2) -> 13270.75
A4: =ROW()-2 -> 2 | B4: 2501 | C4: WB022665 | D4: 熊伟 | E4: 310109198905074533 | F4: 45444 | G4: 45808 | I4: 上海 | J4: 1030 | K4: 760.2 | L4: 501.48 | R4: 630 | X4: =IF((SUM(J4:L4,Y4)-AG4)<2695,2695-(SUM(J4:L4,Y4)-AG4),"") -> 1958.56 | Z4: =SUM(J4:Y4) -> 4880.24 | AA4: 8888 | AB4: 711.04 | AC4: 177.76 | AD4: 44.44 | AE4: 8888 | AF4: =ROUND(AE4*7%,0) -> 622 | AG4: =AB4+AC4+AD4+AF4 -> 1555.24 | AK4: =Z4-AG4-AH4 -> 3325 | AL4: 8888 | AM4: 8888 | AN4: =ROUND(AL4*16%,2) -> 1422.08 | AO4: =ROUND(AL4*9%,2) -> 799.92 | AP4: =ROUND(AL4*0.5%,2) -> 44.44 | AQ4: 17.78 | AS4: =ROUND(AM4*7%,0) -> 622 | AT4: =ROUND(IF(AL4<24366,AL4*1.5%,24366*1.5%),2) -> 133.32 | AU4: =SUM(AN4:AT4) -> 3039.54 | AV4: 85 | AW4: =AU4+Z4+AI4-AJ4+AV4 -> 8004.78 | AX4: =-5 -> -5 | AY4: 4.97 | AZ4: 本月保障补差垫付5元，下月收，工伤利率调整，1月多收2月退 | BA4: 255 | BB4: =ROUND(AW4+BA4+AX4+AY4,2) -> 8259.75 | BC4: =ROUND(BB4*6%,2) -> 495.59 | BD4: =ROUND(SUM(BB4:BC4),2) -> 8755.34
A5: =ROW()-2 -> 3 | B5: 2501 | C5: WB016995 | D5: 杭亮 | E5: 310110198004027057 | F5: 45444 | G5: 45808 | I5: 上海 | J5: 1030 | K5: 3493.56 | L5: 1315.68 | R5: 630 | X5: =IF((SUM(J5:L5,Y5)-AG5)<2695,2695-(SUM(J5:L5,Y5)-AG5),"") | Z5: =SUM(J5:Y5) -> 6469.24 | AA5: 9226 | AB5: 738.08 | AC5: 184.52 | AD5: 46.13 | AE5: 9226 | AF5: =ROUND(AE5*7%,0) -> 646 | AG5: =AB5+AC5+AD5+AF5 -> 1614.73 | AK5: =Z5-AG5-AH5 -> 4854.51 | AL5: 9226 | AM5: 9226 | AN5: =ROUND(AL5*16%,2) -> 1476.16 | AO5: =ROUND(AL5*9%,2) -> 830.34 | AP5: =ROUND(AL5*0.5%,2) -> 46.13 | AQ5: 18.45 | AS5: =ROUND(AM5*7%,0) -> 646 | AT5: =ROUND(IF(AL5<24366,AL5*1.5%,24366*1.5%),2) -> 138.39 | AU5: =SUM(AN5:AT5) -> 3155.47 | AV5: 117 | AW5: =AU5+Z5+AI5-AJ5+AV5 -> 9741.71 | AY5: 5.17 | AZ5: 工伤利率调整，1月多收2月退 | BA5: 255 | BB5: =ROUND(AW5+BA5+AX5+AY5,2) -> 10001.88 | BC5: =ROUND(BB5*6%,2) -> 600.11 | BD5: =ROUND(SUM(BB5:BC5),2) -> 10601.99
A6: =ROW()-2 -> 4 | B6: 2501 | C6: WB007082 | D6: 朱春红 | E6: 310230197703304160 | F6: 45444 | G6: 45808 | I6: 上海 | J6: 1030 | K6: 3600.2 | L6: 3916.62 | R6: 630 | X6: =IF((SUM(J6:L6,Y6)-AG6)<2695,2695-(SUM(J6:L6,Y6)-AG6),"") | Z6: =SUM(J6:Y6) -> 9176.82 | AA6: 10979 | AB6: 878.32 | AC6: 219.58 | AD6: 54.9 | AE6: 10979 | AF6: =ROUND(AE6*7%,0) -> 769 | AG6: =AB6+AC6+AD6+AF6 -> 1921.8 | AK6: =Z6-AG6-AH6 -> 7255.02 | AL6: 10979 | AM6: 10979 | AN6: =ROUND(AL6*16%,2) -> 1756.64 | AO6: 988.12 | AP6: =ROUND(AL6*0.5%,2) -> 54.9 | AQ6: 21.96 | AS6: =ROUND(AM6*7%,0) -> 769 | AT6: =ROUND(IF(AL6<24366,AL6*1.5%,24366*1.5%),2) -> 164.69 | AU6: =SUM(AN6:AT6) -> 3755.31 | AV6: 171 | AW6: =AU6+Z6+AI6-AJ6+AV6 -> 13103.13 | AY6: 6.15 | AZ6: 工伤利率调整，1月多收2月退 | BA6: 255 | BB6: =ROUND(AW6+BA6+AX6+AY6,2) -> 13364.28 | BC6: =ROUND(BB6*6%,2) -> 801.86 | BD6: =ROUND(SUM(BB6:BC6),2) -> 14166.14
A7: =ROW()-2 -> 5 | B7: 2501 | C7: WB017012 | D7: 王一峰 | E7: 310230198106182913 | F7: 45444 | G7: 45808 | I7: 上海 | J7: 1030 | K7: 4660 | L7: 3295.2 | R7: 630 | X7: =IF((SUM(J7:L7,Y7)-AG7)<2695,2695-(SUM(J7:L7,Y7)-AG7),"") | Z7: =SUM(J7:Y7) -> 9615.2 | AA7: 16443 | AB7: 1315.44 | AC7: 328.86 | AD7: 82.22 | AE7: 16443 | AF7: =ROUND(AE7*7%,0) -> 1151 | AG7: =AB7+AC7+AD7+AF7 -> 2877.52 | AK7: =Z7-AG7-AH7 -> 6737.68 | AL7: 16443 | AM7: 16443 | AN7: =ROUND(AL7*16%,2) -> 2630.88 | AO7: 1479.88 | AP7: =ROUND(AL7*0.5%,2) -> 82.22 | AQ7: 32.89 | AS7: =ROUND(AM7*7%,0) -> 1151 | AT7: =ROUND(IF(AL7<24366,AL7*1.5%,24366*1.5%),2) -> 246.65 | AU7: =SUM(AN7:AT7) -> 5623.52 | AV7: 180 | AW7: =AU7+Z7+AI7-AJ7+AV7 -> 15418.72 | AY7: 9.2 | AZ7: 工伤利率调整，1月多收2月退 | BA7: 255 | BB7: =ROUND(AW7+BA7+AX7+AY7,2) -> 15682.92 | BC7: =ROUND(BB7*6%,2) -> 940.98 | BD7: =ROUND(SUM(BB7:BC7),2) -> 16623.9
A8: =ROW()-2 -> 6 | B8: 2501 | C8: WB019180 | D8: 王偲 | E8: 310109198908200531 | F8: 45444 | G8: 45808 | I8: 上海 | J8: 1030 | K8: 2371.2 | L8: 1742.1 | R8: 630 | X8: =IF((SUM(J8:L8,Y8)-AG8)<2695,2695-(SUM(J8:L8,Y8)-AG8),"") | Z8: =SUM(J8:Y8) -> 5773.3 | AA8: 8261 | AB8: 660.88 | AC8: 165.22 | AD8: 41.31 | AE8: 8261 | AF8: =ROUND(AE8*7%,0) -> 578 | AG8: =AB8+AC8+AD8+AF8 -> 1445.41 | AK8: =Z8-AG8-AH8 -> 4327.89 | AL8: 8261 | AM8: 8261 | AN8: =ROUND(AL8*16%,2) -> 1321.76 | AO8: 743.5 | AP8: =ROUND(AL8*0.5%,2) -> 41.31 | AQ8: 16.52 | AS8: =ROUND(AM8*7%,0) -> 578 | AT8: =ROUND(IF(AL8<24366,AL8*1.5%,24366*1.5%),2) -> 123.92 | AU8: =SUM(AN8:AT8) -> 2825.01 | AV8: 103 | AW8: =AU8+Z8+AI8-AJ8+AV8 -> 8701.31 | AY8: 4.63 | AZ8: 工伤利率调整，1月多收2月退 | BA8: 255 | BB8: =ROUND(AW8+BA8+AX8+AY8,2) -> 8960.94 | BC8: =ROUND(BB8*6%,2) -> 537.66 | BD8: =ROUND(SUM(BB8:BC8),2) -> 9498.6
A9: =ROW()-2 -> 7 | B9: 2501 | C9: WB024266 | D9: 王凤凌 | E9: 31011019870909564X | F9: 45444 | G9: 45808 | I9: 上海 | J9: 1030 | K9: 1134 | L9: 664.5 | R9: 630 | X9: =IF((SUM(J9:L9,Y9)-AG9)<2695,2695-(SUM(J9:L9,Y9)-AG9),"") -> 969.82 | Z9: =SUM(J9:Y9) -> 4428.32 | AA9: 7384 | AB9: 590.72 | AC9: 147.68 | AD9: 36.92 | AE9: 4686 | AF9: =ROUND(AE9*7%,0) -> 328 | AG9: =AB9+AC9+AD9+AF9 -> 1103.32 | AK9: =Z9-AG9-AH9 -> 3325 | AL9: 7384 | AM9: 4686 | AN9: =ROUND(AL9*16%,2) -> 1181.44 | AO9: =ROUND(AL9*9%,2) -> 664.56 | AP9: =ROUND(AL9*0.5%,2) -> 36.92 | AQ9: 14.77 | AS9: =ROUND(AM9*7%,0) -> 328 | AT9: =ROUND(IF(AL9<24366,AL9*1.5%,24366*1.5%),2) -> 110.76 | AU9: =SUM(AN9:AT9) -> 2336.45 | AV9: 76 | AW9: =AU9+Z9+AI9-AJ9+AV9 -> 6840.77 | AX9: =-5 -> -5 | AY9: 4.13 | AZ9: 本月保障补差垫付5元，下月收，工伤利率调整，1月多收2月退 | BA9: 255 | BB9: =ROUND(AW9+BA9+AX9+AY9,2) -> 7094.9 | BC9: =ROUND(BB9*6%,2) -> 425.69 | BD9: =ROUND(SUM(BB9:BC9),2) -> 7520.59
A10: =ROW()-2 -> 8 | B10: 2501 | C10: WB033751 | D10: 高雄飞 | E10: 310101198402231014 | F10: 45444 | G10: 45808 | I10: 上海 | J10: 1300 | K10: 7811.4 | L10: 3825.57 | R10: 630 | X10: =IF((SUM(J10:L10,Y10)-AG10)<2695,2695-(SUM(J10:L10,Y10)-AG10),"") | Z10: =SUM(J10:Y10) -> 13566.97 | AA10: 9424 | AB10: 753.92 | AC10: 188.48 | AD10: 47.12 | AE10: 9424 | AF10: =ROUND(AE10*7%,0) -> 660 | AG10: =AB10+AC10+AD10+AF10 -> 1649.52 | AK10: =Z10-AG10-AH10 -> 11917.45 | AL10: 9424 | AM10: 9424 | AN10: =ROUND(AL10*16%,2) -> 1507.84 | AO10: =ROUND(AL10*9%,2) -> 848.16 | AP10: =ROUND(AL10*0.5%,2) -> 47.12 | AQ10: 18.85 | AS10: =ROUND(AM10*7%,0) -> 660 | AT10: =ROUND(IF(AL10<24366,AL10*1.5%,24366*1.5%),2) -> 141.36 | AU10: =SUM(AN10:AT10) -> 3223.33 | AV10: 259 | AW10: =AU10+Z10+AI10-AJ10+AV10 -> 17049.3 | AY10: 5.28 | AZ10: 工伤利率调整，1月多收2月退 | BA10: 255 | BB10: =ROUND(AW10+BA10+AX10+AY10,2) -> 17309.58 | BC10: =ROUND(BB10*6%,2) -> 1038.57 | BD10: =ROUND(SUM(BB10:BC10),2) -> 18348.15
A11: =ROW()-2 -> 9 | B11: 2501 | C11: WB017080 | D11: 季华 | E11: 310115198609170130 | F11: 45444 | G11: 45808 | I11: 上海 | J11: 1300 | K11: 6916 | L11: 2442.9 | R11: 630 | X11: =IF((SUM(J11:L11,Y11)-AG11)<2695,2695-(SUM(J11:L11,Y11)-AG11),"") | Z11: =SUM(J11:Y11) -> 11288.9 | AA11: 10475 | AB11: 838 | AC11: 209.5 | AD11: 52.38 | AE11: 10475 | AF11: =ROUND(AE11*7%,0) -> 733 | AG11: =AB11+AC11+AD11+AF11 -> 1832.88 | AK11: =Z11-AG11-AH11 -> 9456.02 | AL11: 10475 | AM11: 10475 | AN11: =ROUND(AL11*16%,2) -> 1676 | AO11: 942.76 | AP11: =ROUND(AL11*0.5%,2) -> 52.38 | AQ11: 20.95 | AS11: =ROUND(AM11*7%,0) -> 733 | AT11: =ROUND(IF(AL11<24366,AL11*1.5%,24366*1.5%),2) -> 157.13 | AU11: =SUM(AN11:AT11) -> 3582.22 | AV11: 213 | AW11: =AU11+Z11+AI11-AJ11+AV11 -> 15084.12 | AY11: 5.87 | AZ11: 工伤利率调整，1月多收2月退 | BA11: 255 | BB11: =ROUND(AW11+BA11+AX11+AY11,2) -> 15344.99 | BC11: =ROUND(BB11*6%,2) -> 920.7 | BD11: =ROUND(SUM(BB11:BC11),2) -> 16265.69
A12: =ROW()-2 -> 10 | B12: 2501 | C12: WB017076 | D12: 杨晓燕 | E12: 34222519770913404X | F12: 45444 | G12: 45808 | I12: 上海 | J12: 1030 | K12: 2836 | L12: 3042.3 | R12: 630 | X12: =IF((SUM(J12:L12,Y12)-AG12)<2695,2695-(SUM(J12:L12,Y12)-AG12),"") | Z12: =SUM(J12:Y12) -> 7538.3 | AA12: 8472 | AB12: 677.76 | AC12: 169.44 | AD12: 42.36 | AE12: 8472 | AF12: =ROUND(AE12*7%,0) -> 593 | AG12: =AB12+AC12+AD12+AF12 -> 1482.56 | AK12: =Z12-AG12-AH12 -> 6055.74 | AL12: 8472 | AM12: 8472 | AN12: =ROUND(AL12*16%,2) -> 1355.52 | AO12: =ROUND(AL12*9%,2) -> 762.48 | AP12: =ROUND(AL12*0.5%,2) -> 42.36 | AQ12: 16.94 | AS12: =ROUND(AM12*7%,0) -> 593 | AT12: =ROUND(IF(AL12<24366,AL12*1.5%,24366*1.5%),2) -> 127.08 | AU12: =SUM(AN12:AT12) -> 2897.38 | AV12: 138 | AW12: =AU12+Z12+AI12-AJ12+AV12 -> 10573.68 | AY12: 4.75 | AZ12: 工伤利率调整，1月多收2月退 | BA12: 255 | BB12: =ROUND(AW12+BA12+AX12+AY12,2) -> 10833.43 | BC12: =ROUND(BB12*6%,2) -> 650.01 | BD12: =ROUND(SUM(BB12:BC12),2) -> 11483.44
A13: =ROW()-2 -> 11 | B13: 2501 | C13: WB025472 | D13: 孟浩杰 | E13: 510108198209090637 | F13: 45444 | G13: 45808 | I13: 上海 | J13: 1300 | K13: 4329.4 | L13: 3322.02 | R13: 630 | X13: =IF((SUM(J13:L13,Y13)-AG13)<2695,2695-(SUM(J13:L13,Y13)-AG13),"") | Z13: =SUM(J13:Y13) -> 9581.42 | AA13: 9241 | AB13: 739.28 | AC13: 184.82 | AD13: 46.21 | AE13: 9241 | AF13: =ROUND(AE13*7%,0) -> 647 | AG13: =AB13+AC13+AD13+AF13 -> 1617.31 | AK13: =Z13-AG13-AH13 -> 7964.11 | AL13: 9241 | AM13: 9241 | AN13: =ROUND(AL13*16%,2) -> 1478.56 | AO13: 831.7 | AP13: =ROUND(AL13*0.5%,2) -> 46.21 | AQ13: 18.48 | AS13: =ROUND(AM13*7%,0) -> 647 | AT13: =ROUND(IF(AL13<24366,AL13*1.5%,24366*1.5%),2) -> 138.62 | AU13: =SUM(AN13:AT13) -> 3160.57 | AV13: 179 | AW13: =AU13+Z13+AI13-AJ13+AV13 -> 12920.99 | AY13: 5.18 | AZ13: 工伤利率调整，1月多收2月退 | BA13: 255 | BB13: =ROUND(AW13+BA13+AX13+AY13,2) -> 13181.17 | BC13: =ROUND(BB13*6%,2) -> 790.87 | BD13: =ROUND(SUM(BB13:BC13),2) -> 13972.04
A14: =ROW()-2 -> 12 | B14: 2501 | C14: WB021004 | D14: 周雨薇 | E14: 310104199212304829 | F14: 45444 | G14: 45808 | I14: 上海 | J14: 1030 | K14: 2040 | L14: 2301.96 | R14: 630 | X14: =IF((SUM(J14:L14,Y14)-AG14)<2695,2695-(SUM(J14:L14,Y14)-AG14),"") | Z14: =SUM(J14:Y14) -> 6001.96 | AA14: 7384 | AB14: 590.72 | AC14: 147.68 | AD14: 36.92 | AE14: 6830 | AF14: =ROUND(AE14*7%,0) -> 478 | AG14: =AB14+AC14+AD14+AF14 -> 1253.32 | AK14: =Z14-AG14-AH14 -> 4748.64 | AL14: 7384 | AM14: 6830 | AN14: =ROUND(AL14*16%,2) -> 1181.44 | AO14: =ROUND(AL14*9%,2) -> 664.56 | AP14: =ROUND(AL14*0.5%,2) -> 36.92 | AQ14: 14.77 | AS14: =ROUND(AM14*7%,0) -> 478 | AT14: =ROUND(IF(AL14<24366,AL14*1.5%,24366*1.5%),2) -> 110.76 | AU14: =SUM(AN14:AT14) -> 2486.45 | AV14: 107 | AW14: =AU14+Z14+AI14-AJ14+AV14 -> 8595.41 | AY14: 4.13 | AZ14: 工伤利率调整，1月多收2月退 | BA14: 255 | BB14: =ROUND(AW14+BA14+AX14+AY14,2) -> 8854.54 | BC14: =ROUND(BB14*6%,2) -> 531.27 | BD14: =ROUND(SUM(BB14:BC14),2) -> 9385.81
A15: =ROW()-2 -> 13 | B15: 2501 | C15: WB017081 | D15: 王姗姗 | E15: 34112519880604436X | F15: 45444 | G15: 45808 | I15: 上海 | J15: 1300 | K15: 21825 | L15: 7163.64 | R15: 630 | X15: =IF((SUM(J15:L15,Y15)-AG15)<2695,2695-(SUM(J15:L15,Y15)-AG15),"") | Z15: =SUM(J15:Y15) -> 30918.64 | AA15: 18040 | AB15: 1443.2 | AC15: 360.8 | AD15: 90.2 | AE15: 18040 | AF15: =ROUND(AE15*7%,0) -> 1263 | AG15: =AB15+AC15+AD15+AF15 -> 3157.2 | AK15: =Z15-AG15-AH15 -> 27761.44 | AL15: 18040 | AM15: 18040 | AN15: =ROUND(AL15*16%,2) -> 2886.4 | AO15: =ROUND(AL15*9%,2) -> 1623.6 | AP15: =ROUND(AL15*0.5%,2) -> 90.2 | AQ15: 36.08 | AS15: =ROUND(AM15*7%,0) -> 1263 | AT15: =ROUND(IF(AL15<24366,AL15*1.5%,24366*1.5%),2) -> 270.6 | AU15: =SUM(AN15:AT15) -> 6169.88 | AV15: 606 | AW15: =AU15+Z15+AI15-AJ15+AV15 -> 37694.52 | AY15: 10.1 | AZ15: 工伤利率调整，1月多收2月退 | BA15: 255 | BB15: =ROUND(AW15+BA15+AX15+AY15,2) -> 37959.62 | BC15: =ROUND(BB15*6%,2) -> 2277.58 | BD15: =ROUND(SUM(BB15:BC15),2) -> 40237.2
A16: =ROW()-2 -> 14 | B16: 2501 | C16: WB017085 | D16: 邱杭佳 | E16: 31010819830921103X | F16: 45444 | G16: 45808 | I16: 上海 | J16: 1030 | K16: 3545.4 | L16: 1957.14 | R16: 630 | X16: =IF((SUM(J16:L16,Y16)-AG16)<2695,2695-(SUM(J16:L16,Y16)-AG16),"") | Z16: =SUM(J16:Y16) -> 7162.54 | AA16: 7474 | AB16: 597.92 | AC16: 149.48 | AD16: 37.37 | AE16: 7474 | AF16: =ROUND(AE16*7%,0) -> 523 | AG16: =AB16+AC16+AD16+AF16 -> 1307.77 | AK16: =Z16-AG16-AH16 -> 5854.77 | AL16: 7474 | AM16: 7474 | AN16: =ROUND(AL16*16%,2) -> 1195.84 | AO16: =ROUND(AL16*9%,2) -> 672.66 | AP16: =ROUND(AL16*0.5%,2) -> 37.37 | AQ16: 14.95 | AS16: =ROUND(AM16*7%,0) -> 523 | AT16: =ROUND(IF(AL16<24366,AL16*1.5%,24366*1.5%),2) -> 112.11 | AU16: =SUM(AN16:AT16) -> 2555.93 | AV16: 131 | AW16: =AU16+Z16+AI16-AJ16+AV16 -> 9849.47 | AY16: 4.18 | AZ16: 工伤利率调整，1月多收2月退 | BA16: 255 | BB16: =ROUND(AW16+BA16+AX16+AY16,2) -> 10108.65 | BC16: =ROUND(BB16*6%,2) -> 606.52 | BD16: =ROUND(SUM(BB16:BC16),2) -> 10715.17
A17: =ROW()-2 -> 15 | B17: 2501 | C17: WB008065 | D17: 戚继英 | E17: 310102198004243227 | F17: 45444 | G17: 45808 | I17: 上海 | J17: 1300 | K17: 5472 | L17: 4021.68 | R17: 630 | X17: =IF((SUM(J17:L17,Y17)-AG17)<2695,2695-(SUM(J17:L17,Y17)-AG17),"") | Z17: =SUM(J17:Y17) -> 11423.68 | AA17: 11152 | AB17: 892.16 | AC17: 223.04 | AD17: 55.76 | AE17: 11152 | AF17: =ROUND(AE17*7%,0) -> 781 | AG17: =AB17+AC17+AD17+AF17 -> 1951.96 | AK17: =Z17-AG17-AH17 -> 9471.72 | AL17: 11152 | AM17: 11152 | AN17: =ROUND(AL17*16%,2) -> 1784.32 | AO17: =ROUND(AL17*9%,2) -> 1003.68 | AP17: =ROUND(AL17*0.5%,2) -> 55.76 | AQ17: 22.3 | AS17: =ROUND(AM17*7%,0) -> 781 | AT17: =ROUND(IF(AL17<24366,AL17*1.5%,24366*1.5%),2) -> 167.28 | AU17: =SUM(AN17:AT17) -> 3814.34 | AV17: 216 | AW17: =AU17+Z17+AI17-AJ17+AV17 -> 15454.02 | AY17: 6.25 | AZ17: 工伤利率调整，1月多收2月退 | BA17: 255 | BB17: =ROUND(AW17+BA17+AX17+AY17,2) -> 15715.27 | BC17: =ROUND(BB17*6%,2) -> 942.92 | BD17: =ROUND(SUM(BB17:BC17),2) -> 16658.19
A18: =ROW()-2 -> 16 | B18: 2501 | C18: WB045238 | D18: 戈婷婷 | E18: 320821199610185147 | F18: 45444 | G18: 45808 | I18: 上海 | J18: 1030 | K18: 5092.3 | L18: 3844.02 | R18: 630 | X18: =IF((SUM(J18:L18,Y18)-AG18)<2695,2695-(SUM(J18:L18,Y18)-AG18),"") | Z18: =SUM(J18:Y18) -> 10596.32 | AA18: 10443 | AB18: 835.44 | AC18: 208.86 | AD18: 52.22 | AE18: 10443 | AF18: =ROUND(AE18*7%,0) -> 731 | AG18: =AB18+AC18+AD18+AF18 -> 1827.52 | AK18: =Z18-AG18-AH18 -> 8768.8 | AL18: 10443 | AM18: 10443 | AN18: =ROUND(AL18*16%,2) -> 1670.88 | AO18: 939.88 | AP18: =ROUND(AL18*0.5%,2) -> 52.22 | AQ18: 20.89 | AS18: =ROUND(AM18*7%,0) -> 731 | AT18: =ROUND(IF(AL18<24366,AL18*1.5%,24366*1.5%),2) -> 156.65 | AU18: =SUM(AN18:AT18) -> 3571.52 | AV18: 199 | AW18: =AU18+Z18+AI18-AJ18+AV18 -> 14366.84 | AY18: 5.84 | AZ18: 工伤利率调整，1月多收2月退 | BA18: 255 | BB18: =ROUND(AW18+BA18+AX18+AY18,2) -> 14627.68 | BC18: =ROUND(BB18*6%,2) -> 877.66 | BD18: =ROUND(SUM(BB18:BC18),2) -> 15505.34
A19: =ROW()-2 -> 17 | B19: 2501 | C19: WB013266 | D19: 吴裕刚 | E19: 31010219810818361X | F19: 45444 | G19: 45808 | I19: 上海 | J19: 1030 | K19: 5574.64 | L19: 1745.07 | R19: 630 | X19: =IF((SUM(J19:L19,Y19)-AG19)<2695,2695-(SUM(J19:L19,Y19)-AG19),"") | Z19: =SUM(J19:Y19) -> 8979.71 | AA19: 8102 | AB19: 648.16 | AC19: 162.04 | AD19: 40.51 | AE19: 8102 | AF19: =ROUND(AE19*7%,0) -> 567 | AG19: =AB19+AC19+AD19+AF19 -> 1417.71 | AK19: =Z19-AG19-AH19 -> 7562 | AL19: 8102 | AM19: 8102 | AN19: =ROUND(AL19*16%,2) -> 1296.32 | AO19: =ROUND(AL19*9%,2) -> 729.18 | AP19: =ROUND(AL19*0.5%,2) -> 40.51 | AQ19: 16.2 | AS19: =ROUND(AM19*7%,0) -> 567 | AT19: =ROUND(IF(AL19<24366,AL19*1.5%,24366*1.5%),2) -> 121.53 | AU19: =SUM(AN19:AT19) -> 2770.74 | AV19: 167 | AW19: =AU19+Z19+AI19-AJ19+AV19 -> 11917.45 | AY19: 4.54 | AZ19: 工伤利率调整，1月多收2月退 | BA19: 255 | BB19: =ROUND(AW19+BA19+AX19+AY19,2) -> 12176.99 | BC19: =ROUND(BB19*6%,2) -> 730.62 | BD19: =ROUND(SUM(BB19:BC19),2) -> 12907.61
A20: =ROW()-2 -> 18 | B20: 2501 | C20: WB017007 | D20: 贺彦 | E20: 310108198901250513 | F20: 45444 | G20: 45808 | I20: 上海 | J20: 800 | K20: 1955 | L20: 2202 | R20: 630 | X20: =IF((SUM(J20:L20,Y20)-AG20)<2695,2695-(SUM(J20:L20,Y20)-AG20),"") | Z20: =SUM(J20:Y20) -> 5587 | AA20: 7384 | AB20: 590.72 | AC20: 147.68 | AD20: 36.92 | AE20: 4906 | AF20: =ROUND(AE20*7%,0) -> 343 | AG20: =AB20+AC20+AD20+AF20 -> 1118.32 | AK20: =Z20-AG20-AH20 -> 4468.68 | AL20: 7384 | AM20: 4906 | AN20: =ROUND(AL20*16%,2) -> 1181.44 | AO20: =ROUND(AL20*9%,2) -> 664.56 | AP20: =ROUND(AL20*0.5%,2) -> 36.92 | AQ20: 14.77 | AS20: =ROUND(AM20*7%,0) -> 343 | AT20: =ROUND(IF(AL20<24366,AL20*1.5%,24366*1.5%),2) -> 110.76 | AU20: =SUM(AN20:AT20) -> 2351.45 | AV20: 99 | AW20: =AU20+Z20+AI20-AJ20+AV20 -> 8037.45 | AY20: 4.13 | AZ20: 工伤利率调整，1月多收2月退 | BA20: 255 | BB20: =ROUND(AW20+BA20+AX20+AY20,2) -> 8296.58 | BC20: =ROUND(BB20*6%,2) -> 497.79 | BD20: =ROUND(SUM(BB20:BC20),2) -> 8794.37
A21: =ROW()-2 -> 19 | B21: 2501 | C21: WB017000 | D21: 叶毅 | E21: 310110198502133266 | F21: 45444 | G21: 45808 | I21: 上海 | J21: 1030 | K21: 5611 | L21: 760.32 | R21: 630 | X21: =IF((SUM(J21:L21,Y21)-AG21)<2695,2695-(SUM(J21:L21,Y21)-AG21),"") | Z21: =SUM(J21:Y21) -> 8031.32 | AA21: 7759 | AB21: 620.72 | AC21: 155.18 | AD21: 38.8 | AE21: 7759 | AF21: =ROUND(AE21*7%,0) -> 543 | AG21: =AB21+AC21+AD21+AF21 -> 1357.7 | AK21: =Z21-AG21-AH21 -> 6673.62 | AL21: 7759 | AM21: 7759 | AN21: =ROUND(AL21*16%,2) -> 1241.44 | AO21: 698.32 | AP21: =ROUND(AL21*0.5%,2) -> 38.8 | AQ21: 15.52 | AS21: =ROUND(AM21*7%,0) -> 543 | AT21: =ROUND(IF(AL21<24366,AL21*1.5%,24366*1.5%),2) -> 116.39 | AU21: =SUM(AN21:AT21) -> 2653.47 | AV21: 148 | AW21: =AU21+Z21+AI21-AJ21+AV21 -> 10832.79 | AY21: 4.34 | AZ21: 工伤利率调整，1月多收2月退 | BA21: 255 | BB21: =ROUND(AW21+BA21+AX21+AY21,2) -> 11092.13 | BC21: =ROUND(BB21*6%,2) -> 665.53 | BD21: =ROUND(SUM(BB21:BC21),2) -> 11757.66
A22: =ROW()-2 -> 20 | B22: 2501 | C22: WB017001 | D22: 陈世碧 | E22: 513023197709136722 | F22: 45444 | G22: 45808 | I22: 上海 | J22: 1030 | K22: 5024 | L22: 2922.78 | R22: 630 | X22: =IF((SUM(J22:L22,Y22)-AG22)<2695,2695-(SUM(J22:L22,Y22)-AG22),"") | Z22: =SUM(J22:Y22) -> 9606.78 | AA22: 10043 | AB22: 803.44 | AC22: 200.86 | AD22: 50.22 | AE22: 10043 | AF22: =ROUND(AE22*7%,0) -> 703 | AG22: =AB22+AC22+AD22+AF22 -> 1757.52 | AK22: =Z22-AG22-AH22 -> 7849.26 | AL22: 10043 | AM22: 10043 | AN22: =ROUND(AL22*16%,2) -> 1606.88 | AO22: 903.88 | AP22: =ROUND(AL22*0.5%,2) -> 50.22 | AQ22: 20.09 | AS22: =ROUND(AM22*7%,0) -> 703 | AT22: =ROUND(IF(AL22<24366,AL22*1.5%,24366*1.5%),2) -> 150.65 | AU22: =SUM(AN22:AT22) -> 3434.72 | AV22: 180 | AW22: =AU22+Z22+AI22-AJ22+AV22 -> 13221.5 | AY22: 5.62 | AZ22: 工伤利率调整，1月多收2月退 | BA22: 255 | BB22: =ROUND(AW22+BA22+AX22+AY22,2) -> 13482.12 | BC22: =ROUND(BB22*6%,2) -> 808.93 | BD22: =ROUND(SUM(BB22:BC22),2) -> 14291.05
A23: =ROW()-2 -> 21 | B23: 2501 | C23: WB017004 | D23: 顾陆慧 | E23: 310230197904164766 | F23: 45444 | G23: 45808 | I23: 上海 | J23: 1300 | K23: 16282.8 | L23: 874.86 | R23: 630 | X23: =IF((SUM(J23:L23,Y23)-AG23)<2695,2695-(SUM(J23:L23,Y23)-AG23),"") | Z23: =SUM(J23:Y23) -> 19087.66 | AA23: 12136 | AB23: 970.88 | AC23: 242.72 | AD23: 60.68 | AE23: 12136 | AF23: =ROUND(AE23*7%,0) -> 850 | AG23: =AB23+AC23+AD23+AF23 -> 2124.28 | AK23: =Z23-AG23-AH23 -> 16963.38 | AL23: 12136 | AM23: 12136 | AN23: =ROUND(AL23*16%,2) -> 1941.76 | AO23: =ROUND(AL23*9%,2) -> 1092.24 | AP23: =ROUND(AL23*0.5%,2) -> 60.68 | AQ23: 24.27 | AS23: =ROUND(AM23*7%,0) -> 850 | AT23: =ROUND(IF(AL23<24366,AL23*1.5%,24366*1.5%),2) -> 182.04 | AU23: =SUM(AN23:AT23) -> 4150.99 | AV23: 369 | AW23: =AU23+Z23+AI23-AJ23+AV23 -> 23607.65 | AY23: 6.8 | AZ23: 工伤利率调整，1月多收2月退 | BA23: 255 | BB23: =ROUND(AW23+BA23+AX23+AY23,2) -> 23869.45 | BC23: =ROUND(BB23*6%,2) -> 1432.17 | BD23: =ROUND(SUM(BB23:BC23),2) -> 25301.62
A24: =ROW()-2 -> 22 | B24: 2501 | C24: WB017006 | D24: 程祖云 | E24: 411524198609258442 | F24: 45444 | G24: 45808 | I24: 上海 | J24: 1200 | K24: 5853.12 | L24: 1377.24 | R24: 630 | X24: =IF((SUM(J24:L24,Y24)-AG24)<2695,2695-(SUM(J24:L24,Y24)-AG24),"") | Z24: =SUM(J24:Y24) -> 9060.36 | AA24: 9608 | AB24: 768.64 | AC24: 192.16 | AD24: 48.04 | AE24: 9608 | AF24: =ROUND(AE24*7%,0) -> 673 | AG24: =AB24+AC24+AD24+AF24 -> 1681.84 | AK24: =Z24-AG24-AH24 -> 7378.52 | AL24: 9608 | AM24: 9608 | AN24: =ROUND(AL24*16%,2) -> 1537.28 | AO24: =ROUND(AL24*9%,2) -> 864.72 | AP24: =ROUND(AL24*0.5%,2) -> 48.04 | AQ24: 19.22 | AS24: =ROUND(AM24*7%,0) -> 673 | AT24: =ROUND(IF(AL24<24366,AL24*1.5%,24366*1.5%),2) -> 144.12 | AU24: =SUM(AN24:AT24) -> 3286.38 | AV24: 169 | AW24: =AU24+Z24+AI24-AJ24+AV24 -> 12515.74 | AY24: 5.38 | AZ24: 工伤利率调整，1月多收2月退 | BA24: 255 | BB24: =ROUND(AW24+BA24+AX24+AY24,2) -> 12776.12 | BC24: =ROUND(BB24*6%,2) -> 766.57 | BD24: =ROUND(SUM(BB24:BC24),2) -> 13542.69
A25: =ROW()-2 -> 23 | B25: 2501 | C25: WB003572 | D25: 谢俊敏 | E25: 310110198911171036 | F25: 45444 | G25: 45808 | I25: 上海 | J25: 1030 | K25: 5144 | L25: 1489.2 | R25: 630 | X25: =IF((SUM(J25:L25,Y25)-AG25)<2695,2695-(SUM(J25:L25,Y25)-AG25),"") | Z25: =SUM(J25:Y25) -> 8293.2 | AA25: 7974 | AB25: 637.92 | AC25: 159.48 | AD25: 39.87 | AE25: 7974 | AF25: =ROUND(AE25*7%,0) -> 558 | AG25: =AB25+AC25+AD25+AF25 -> 1395.27 | AK25: =Z25-AG25-AH25 -> 6897.93 | AL25: 7974 | AM25: 7974 | AN25: =ROUND(AL25*16%,2) -> 1275.84 | AO25: =ROUND(AL25*9%,2) -> 717.66 | AP25: =ROUND(AL25*0.5%,2) -> 39.87 | AQ25: 15.95 | AS25: =ROUND(AM25*7%,0) -> 558 | AT25: =ROUND(IF(AL25<24366,AL25*1.5%,24366*1.5%),2) -> 119.61 | AU25: =SUM(AN25:AT25) -> 2726.93 | AV25: 153 | AW25: =AU25+Z25+AI25-AJ25+AV25 -> 11173.13 | AY25: 4.46 | AZ25: 工伤利率调整，1月多收2月退 | BA25: 255 | BB25: =ROUND(AW25+BA25+AX25+AY25,2) -> 11432.59 | BC25: =ROUND(BB25*6%,2) -> 685.96 | BD25: =ROUND(SUM(BB25:BC25),2) -> 12118.55
A26: =ROW()-2 -> 24 | B26: 2501 | C26: WB039916 | D26: 梁裔杰 | E26: 310113198509301719 | F26: 45444 | G26: 45808 | I26: 上海 | J26: 1030 | K26: 4616.2 | L26: 2196.18 | R26: 630 | X26: =IF((SUM(J26:L26,Y26)-AG26)<2695,2695-(SUM(J26:L26,Y26)-AG26),"") | Z26: =SUM(J26:Y26) -> 8472.38 | AA26: 7384 | AB26: 590.72 | AC26: 147.68 | AD26: 36.92 | AE26: 7139 | AF26: =ROUND(AE26*7%,0) -> 500 | AG26: =AB26+AC26+AD26+AF26 -> 1275.32 | AK26: =Z26-AG26-AH26 -> 7197.06 | AL26: 7384 | AM26: 7139 | AN26: =ROUND(AL26*16%,2) -> 1181.44 | AO26: =ROUND(AL26*9%,2) -> 664.56 | AP26: =ROUND(AL26*0.5%,2) -> 36.92 | AQ26: 14.77 | AS26: =ROUND(AM26*7%,0) -> 500 | AT26: =ROUND(IF(AL26<24366,AL26*1.5%,24366*1.5%),2) -> 110.76 | AU26: =SUM(AN26:AT26) -> 2508.45 | AV26: 157 | AW26: =AU26+Z26+AI26-AJ26+AV26 -> 11137.83 | AY26: 4.13 | AZ26: 工伤利率调整，1月多收2月退 | BA26: 255 | BB26: =ROUND(AW26+BA26+AX26+AY26,2) -> 11396.96 | BC26: =ROUND(BB26*6%,2) -> 683.82 | BD26: =ROUND(SUM(BB26:BC26),2) -> 12080.78
A27: =ROW()-2 -> 25 | B27: 2501 | C27: WB017057 | D27: 朱云 | E27: 310110198810200045 | F27: 45444 | G27: 45808 | I27: 上海 | J27: 1030 | K27: 1398 | L27: 801.84 | R27: 630 | X27: =IF((SUM(J27:L27,Y27)-AG27)<2695,2695-(SUM(J27:L27,Y27)-AG27),"") -> 1549.61 | Z27: =SUM(J27:Y27) -> 5409.45 | AA27: 11909 | AB27: 952.72 | AC27: 238.18 | AD27: 59.55 | AE27: 11909 | AF27: =ROUND(AE27*7%,0) -> 834 | AG27: =AB27+AC27+AD27+AF27 -> 2084.45 | AK27: =Z27-AG27-AH27 -> 3325 | AL27: 11909 | AM27: 11909 | AN27: =ROUND(AL27*16%,2) -> 1905.44 | AO27: 1071.82 | AP27: =ROUND(AL27*0.5%,2) -> 59.55 | AQ27: 23.82 | AS27: =ROUND(AM27*7%,0) -> 834 | AT27: =ROUND(IF(AL27<24366,AL27*1.5%,24366*1.5%),2) -> 178.64 | AU27: =SUM(AN27:AT27) -> 4073.27 | AV27: 95 | AW27: =AU27+Z27+AI27-AJ27+AV27 -> 9577.72 | AX27: =-5 -> -5 | AY27: 6.67 | AZ27: 本月保障补差垫付5元，下月收，工伤利率调整，1月多收2月退 | BA27: 255 | BB27: =ROUND(AW27+BA27+AX27+AY27,2) -> 9834.39 | BC27: =ROUND(BB27*6%,2) -> 590.06 | BD27: =ROUND(SUM(BB27:BC27),2) -> 10424.45
A28: =ROW()-2 -> 26 | B28: 2501 | C28: WB017068 | D28: 罗文彬 | E28: 310110198902103234 | F28: 45444 | G28: 45808 | I28: 上海 | J28: 1200 | K28: 3421 | L28: 814.5 | R28: 630 | X28: =IF((SUM(J28:L28,Y28)-AG28)<2695,2695-(SUM(J28:L28,Y28)-AG28),"") | Z28: =SUM(J28:Y28) -> 6065.5 | AA28: 14537 | AB28: 1162.96 | AC28: 290.74 | AD28: 72.69 | AE28: 14537 | AF28: =ROUND(AE28*7%,0) -> 1018 | AG28: =AB28+AC28+AD28+AF28 -> 2544.39 | AK28: =Z28-AG28-AH28 -> 3521.11 | AL28: 14537 | AM28: 14537 | AN28: =ROUND(AL28*16%,2) -> 2325.92 | AO28: 1308.34 | AP28: =ROUND(AL28*0.5%,2) -> 72.69 | AQ28: 29.07 | AS28: =ROUND(AM28*7%,0) -> 1018 | AT28: =ROUND(IF(AL28<24366,AL28*1.5%,24366*1.5%),2) -> 218.06 | AU28: =SUM(AN28:AT28) -> 4972.08 | AV28: 109 | AW28: =AU28+Z28+AI28-AJ28+AV28 -> 11146.58 | AY28: 8.14 | AZ28: 工伤利率调整，1月多收2月退 | BA28: 255 | BB28: =ROUND(AW28+BA28+AX28+AY28,2) -> 11409.72 | BC28: =ROUND(BB28*6%,2) -> 684.58 | BD28: =ROUND(SUM(BB28:BC28),2) -> 12094.3
A29: =ROW()-2 -> 27 | B29: 2501 | C29: WB054689 | D29: 张梦诏 | E29: 342423200108298172 | F29: 45444 | G29: 45808 | I29: 上海 | J29: 800 | K29: 3337.75 | L29: 4567.8 | R29: 630 | X29: =IF((SUM(J29:L29,Y29)-AG29)<2695,2695-(SUM(J29:L29,Y29)-AG29),"") | Z29: =SUM(J29:Y29) -> 9335.55 | AA29: 7384 | AB29: 590.72 | AC29: 147.68 | AD29: 36.92 | AE29: 5239 | AF29: =ROUND(AE29*7%,0) -> 367 | AG29: =AB29+AC29+AD29+AF29 -> 1142.32 | AK29: =Z29-AG29-AH29 -> 8193.23 | AL29: 7384 | AM29: 5239 | AN29: =ROUND(AL29*16%,2) -> 1181.44 | AO29: =ROUND(AL29*9%,2) -> 664.56 | AP29: =ROUND(AL29*0.5%,2) -> 36.92 | AQ29: 14.77 | AS29: =ROUND(AM29*7%,0) -> 367 | AT29: =ROUND(IF(AL29<24366,AL29*1.5%,24366*1.5%),2) -> 110.76 | AU29: =SUM(AN29:AT29) -> 2375.45 | AV29: 174 | AW29: =AU29+Z29+AI29-AJ29+AV29 -> 11885 | AY29: 4.13 | AZ29: 工伤利率调整，1月多收2月退 | BA29: 255 | BB29: =ROUND(AW29+BA29+AX29+AY29,2) -> 12144.13 | BC29: =ROUND(BB29*6%,2) -> 728.65 | BD29: =ROUND(SUM(BB29:BC29),2) -> 12872.78
A30: =ROW()-2 -> 28 | B30: 2501 | C30: WB017054 | D30: 胡佳华 | E30: 310109198103142020 | F30: 45658 | G30: 47118 | I30: 上海 | J30: 1300 | K30: 5230 | L30: 1209 | R30: 630 | X30: =IF((SUM(J30:L30,Y30)-AG30)<2695,2695-(SUM(J30:L30,Y30)-AG30),"") | Z30: =SUM(J30:Y30) -> 8369 | AA30: 9575 | AB30: 766 | AC30: 191.5 | AD30: 47.88 | AE30: 9575 | AF30: 670 | AG30: =AB30+AC30+AD30+AF30 -> 1675.38 | AK30: =Z30-AG30-AH30 -> 6693.62 | AL30: 9575 | AM30: 9575 | AN30: 1532 | AO30: 861.76 | AP30: 47.88 | AQ30: 19.15 | AS30: 670 | AT30: 143.63 | AU30: =SUM(AN30:AT30) -> 3274.42 | AV30: 155 | AW30: =AU30+Z30+AI30-AJ30+AV30 -> 11798.42 | AX30: -3.83 | AY30: =0.07 -> 0.07 | AZ30: 本月工伤比例垫付3.83元，下月收，社保尾差调整，1月多收2月退 | BA30: 255 | BB30: =ROUND(AW30+BA30+AX30+AY30,2) -> 12049.66 | BC30: =ROUND(BB30*6%,2) -> 722.98 | BD30: =ROUND(SUM(BB30:BC30),2) -> 12772.64
A31: 合计 | Z31: =SUBTOTAL(9,Z3:Z30) -> 263832.14 | AG31: =SUBTOTAL(9,AG3:AG30) -> 47695.8 | AK31: =SUBTOTAL(9,AK3:AK30) -> 216136.34 | AU31: =SUBTOTAL(9,AU3:AU30) -> 93752.59 | AV31: =SUM(AV3:AV30) -> 4925 | AW31: =SUBTOTAL(9,AW3:AW30) -> 362509.73 | AX31: =SUBTOTAL(9,AX3:AX30) -> -18.83 | AY31: =SUBTOTAL(9,AY3:AY30) -> 149.12 | BA31: =SUBTOTAL(9,BA3:BA30) -> 7140 | BB31: =SUBTOTAL(9,BB3:BB30) -> 369780.02 | BC31: =SUBTOTAL(9,BC3:BC30) -> 22186.82 | BD31: =SUBTOTAL(9,BD3:BD30) -> 391966.84
A33: 本月垫付，下月补收
A34: 序号 | B34: 计薪 周期 | C34: 工号 | D34: 姓名 | E34: 身份证号 | F34: 劳动合同起始日期 | G34: 劳动合同结束日期 | H34: 离职日期 | I34: 社保缴纳地 | J34: 工伤保险 | K34: 本月多收下月退 | L34: 社保备注
A35: NO. | B35: Salary Cycle | C35: Employee No. | D35: Name | E35: ID No. | F35: Contract Starting Date | G35: Contract Expiry Date | H35: Exit Date | I35: Social Insurance City | J35: Injury Employer | L35: Social Security remark
A36: 1 | B36: 2501 | C36: WB016994 | D36: 王邹强 | E36: 310108198909220554 | F36: 45444 | G36: 45808 | I36: 上海 | J36: 17.41 | K36: -4.88 | L36: 工伤利率调整，1月多收2月退
A37: 2 | B37: 2501 | C37: WB022665 | D37: 熊伟 | E37: 310109198905074533 | F37: 45444 | G37: 45808 | I37: 上海 | J37: 17.78 | K37: -4.97 | L37: 工伤利率调整，1月多收2月退
A38: 3 | B38: 2501 | C38: WB016995 | D38: 杭亮 | E38: 310110198004027057 | F38: 45444 | G38: 45808 | I38: 上海 | J38: 18.45 | K38: -5.17 | L38: 工伤利率调整，1月多收2月退
A39: 4 | B39: 2501 | C39: WB007082 | D39: 朱春红 | E39: 310230197703304160 | F39: 45444 | G39: 45808 | I39: 上海 | J39: 21.96 | K39: -6.15 | L39: 工伤利率调整，1月多收2月退
A40: 5 | B40: 2501 | C40: WB017012 | D40: 王一峰 | E40: 310230198106182913 | F40: 45444 | G40: 45808 | I40: 上海 | J40: 32.89 | K40: -9.2 | L40: 工伤利率调整，1月多收2月退
A41: 6 | B41: 2501 | C41: WB019180 | D41: 王偲 | E41: 310109198908200531 | F41: 45444 | G41: 45808 | I41: 上海 | J41: 16.52 | K41: -4.63 | L41: 工伤利率调整，1月多收2月退
...

Sheet 对账单
A1: 科目 | B1: 手工账单 | C1: 速创账单 | D1: 155 | E1: 预收一次性 | F1: 1月工会费 | G1: 本月垫付，下月收 | H1: 本月多收，下月退 | I1: 合计 | J1: 差异
A2: 管理费 | B2: ='202501'!BC31 -> 22186.82 | C2: =系统!E46 -> 24414.71 | D2: =28*155+149.12-18.83 -> 4470.29 | I2: =SUM(C2:G2) -> 28885 | J2: =B2-C2 -> -2227.89
A3: 风险费 | B3: ='202501'!BA31 -> 7140 | C3: 0 | I3: =SUM(C3:G3) -> 0 | J3: =B3-C3 -> 7140
A4: 个人四金 | B4: ='202501'!AG31 -> 47695.8 | C4: =系统!V46 -> 47695.8 | I4: =SUM(C4:G4) -> 47695.8 | J4: =B4-C4 -> 0
A5: 公司四金 | B5: ='202501'!AU31 -> 93752.59 | C5: =系统!O46 -> 93752.59 | E5: =1660.13 -> 1660.13 | I5: =SUM(C5:E5) -> 95412.72 | J5: =B5-C5 -> 0
A6: 工伤退费 | C6: =系统!S218 -> -1660.13 | I6: =SUM(C6:G6) -> -1660.13 | J6: =B6-C6 -> 1660.13
A7: 代发工资 | B7: ='202501'!AK31 -> 216136.34 | C7: =系统!W46 -> 215996.34 | D7: =28*5-0.01 -> 139.99 | I7: =SUM(C7:G7) -> 216136.33 | J7: =B7-C7 -> 140
A8: 本月垫付 | B8: ='202501'!AX31 -> -18.83 | I8: =SUM(C8:G8) -> 0 | J8: =B8-C8 -> -18.83
A9: 工会费 | B9: ='202501'!AV31 -> 4925 | F9: =B9 -> 4925 | I9: =SUM(C9:G9) -> 4925 | J9: =B9-C9 -> 4925
A10: 本月多收 | B10: ='202501'!AY31 -> 149.12 | I10: =SUM(C10:G10) -> 0 | J10: =B10-C10 -> 149.12
A11: 小计 | B11: =SUM(B2:B10) -> 391966.84 | C11: =SUM(C2:C10) -> 380199.31 | D11: =SUM(D2:D10) -> 4610.28 | E11: =E5 -> 1660.13 | F11: =F9 -> 4925 | G11: =G9 -> 0 | H11: =H9 -> 0 | I11: =SUM(C11:G11) -> 391394.72
A12: 附加税
A13: 增值税 | D13: =ROUND((D11+D12)*6%,2) -> 276.62 | F13: =ROUND((F11+F12)*6%,2) -> 295.5 | G13: =ROUND((G11+G12)*6%,2) -> 0 | H13: =ROUND((H11+H12)*6%,2) -> 0 | I13: =SUM(C13:G13) -> 572.12
A14: 总计 | B14: =SUM(B11:B13) -> 391966.84 | C14: =SUM(C11:C13) -> 380199.31 | D14: =SUM(D11:D13) -> 4886.9 | E14: =E11 -> 1660.13 | F14: =SUM(F11:F13) -> 5220.5 | G14: =SUM(G11:G13) -> 0 | H14: =SUM(H11:H13) -> 0 | I14: =SUM(C14:H14) -> 391966.84
A15: 给客户账单金额 | I15: =B14 -> 391966.84
A16: 差异 | I16: =I15-I14 -> 0
A17: 不含税差异 | I17: =ROUND(I16/1.06,2) -> 0

Sheet 系统
A1: 200070
A2: 寄：梅园路77号人才大厦
B3: 中国电信股份有限公司上海分公司 王慧珏 收
D6: 上海外服布列吉科技有限公司
C7: Shanghai Foreign Service Bridge Technology Co,Ltd.
E9: 收款通知书
E10: ADVISE ON COLLECTION
E11: 2025年01月
A13: 公司名称：中国电信股份有限公司上海分公司 | J13: 帐单号：202501CH6594405
A14: 序号 | B14: 姓名 | C14: 发生年月 | D14: 入职日期 | E14: 管理费 | F14: 当月社保基数 | G14: 当月公积金基数 | H14: 社保类 公司支付 Social Insurance Premiums Paid by Employer | N14: 公积金类 公司支付 Provident Fund Paid by Employer | O14: 公司合计 | P14: 社保类 个人支付 Social Insurance Premiums Paid by Employee | U14: 公积金类 个人支付 Provident Fund Paid by Employee | V14: 个人合计 | W14: 代办薪酬 | X14: 历月补收 | Y14: 其他 | Z14: 总计 | AA14: 备注 | AB14: 外服工号 | AC14: 证件号码 | AD14: 应纳税金额 | AE14: 税率 | AF14: 增值税
A15: S/N | B15: Name | C15: YYYYMM | D15: Employment Start Date | E15: Adm Fee | F15: Social Insurance Base Amount of Current Month | G15: Provident Fund Base Amount of Current Month | H15: 养老保险 Endowment | I15: 医疗保险 Medical | J15: 失业保险 Unemploy-ment | K15: 工伤保险 Employment Injury | L15: 医疗生育保险 Medical Maternity | M15: 保障金 Disabled people&Back pay Fund | N15: 公积金 Provident Fund | O15: Subtotal of Employer Payment | P15: 养老保险 Endowment | Q15: 医疗保险 Medical | R15: 失业保险 Unemploy-ment | S15: 工伤保险 Employment Injury | T15: 医疗生育保险 Medical Maternity | U15: 公积金 Provident Fund | V15: Subtotal of Personal Payment | W15: Agency of Wage Payment | Y15: Others | Z15: Total | AA15: Remarks | AB15: SFSC ID | AC15: ID Card | AD15: Taxable Amount | AE15: Tax Rate | AF15: VAT
A16: 1 | B16: 陈世碧 | C16: 202501 | D16: 2024-06-01 | E16: 888.19 | F16: 10043 | G16: 10043 | H16: 1606.88 | I16: 903.88 | J16: 50.22 | K16: 20.09 | M16: 150.65 | N16: 703 | O16: =SUM(H16:N16) -> 3434.72 | P16: 803.44 | Q16: 200.86 | R16: 50.22 | U16: 703 | V16: =SUM(P16:U16) -> 1757.52 | W16: 7844.26 | X16: -61.31 | Z16: =SUM(E16,O16,V16:Y16) -> 13863.38 | AB16: 5861127 | AC16: 513023197709136722 | AD16: 13078.66 | AE16: 6% | AF16: 784.72
A17: 2 | B17: 程祖云 | C17: 202501 | D17: 2024-06-01 | E17: 846.5 | F17: 9608 | G17: 9608 | H17: 1537.28 | I17: 864.72 | J17: 48.04 | K17: 19.22 | M17: 144.12 | N17: 673 | O17: =SUM(H17:N17) -> 3286.38 | P17: 768.64 | Q17: 192.16 | R17: 48.04 | U17: 673 | V17: =SUM(P17:U17) -> 1681.84 | W17: 7373.52 | X17: -58.7 | Z17: =SUM(E17,O17,V17:Y17) -> 13129.54 | AB17: 5861128 | AC17: 411524198609258442 | AD17: 12386.36 | AE17: 6% | AF17: 743.18
A18: 3 | B18: 高雄飞 | C18: 202501 | D18: 2024-06-01 | E18: 1113.12 | F18: 9424 | G18: 9424 | H18: 1507.84 | I18: 848.16 | J18: 47.12 | K18: 18.85 | M18: 141.36 | N18: 660 | O18: =SUM(H18:N18) -> 3223.33 | P18: 753.92 | Q18: 188.48 | R18: 47.12 | U18: 660 | V18: =SUM(P18:U18) -> 1649.52 | W18: 11912.45 | X18: -57.56 | Z18: =SUM(E18,O18,V18:Y18) -> 17840.86 | AB18: 5544585 | AC18: 310101198402231014 | AD18: 16830.99 | AE18: 6% | AF18: 1009.87
A19: 4 | B19: 戈婷婷 | C19: 202501 | D19: 2024-06-01 | E19: 955.77 | F19: 10443 | G19: 10443 | H19: 1670.88 | I19: 939.88 | J19: 52.22 | K19: 20.89 | M19: 156.65 | N19: 731 | O19: =SUM(H19:N19) -> 3571.52 | P19: 835.44 | Q19: 208.86 | R19: 52.22 | U19: 731 | V19: =SUM(P19:U19) -> 1827.52 | W19: 8763.8 | X19: -63.73 | Z19: =SUM(E19,O19,V19:Y19) -> 15054.88 | AB19: 5544594 | AC19: 320821199610185147 | AD19: 14202.73 | AE19: 6% | AF19: 852.15
A20: 5 | B20: 顾陆慧 | C20: 202501 | D20: 2024-06-01 | E20: 1500.02 | F20: 12136 | G20: 12136 | H20: 1941.76 | I20: 1092.24 | J20: 60.68 | K20: 24.27 | M20: 182.04 | N20: 850 | O20: =SUM(H20:N20) -> 4150.99 | P20: 970.88 | Q20: 242.72 | R20: 60.68 | U20: 850 | V20: =SUM(P20:U20) -> 2124.28 | W20: 16958.38 | X20: -74.09 | Z20: =SUM(E20,O20,V20:Y20) -> 24659.58 | AB20: 5863338 | AC20: 310230197904164766 | AD20: 23263.76 | AE20: 6% | AF20: 1395.82
A21: 6 | B21: 杭亮 | C21: 202501 | D21: 2024-06-01 | E21: 683.18 | F21: 9226 | G21: 9226 | H21: 1476.16 | I21: 830.34 | J21: 46.13 | K21: 18.45 | M21: 138.39 | N21: 646 | O21: =SUM(H21:N21) -> 3155.47 | P21: 738.08 | Q21: 184.52 | R21: 46.13 | U21: 646 | V21: =SUM(P21:U21) -> 1614.73 | W21: 4849.51 | X21: -56.35 | Z21: =SUM(E21,O21,V21:Y21) -> 10246.54 | AB21: 5544580 | AC21: 310110198004027057 | AD21: 9666.55 | AE21: 6% | AF21: 579.99
A22: 7 | B22: 贺彦 | C22: 202501 | D22: 2024-06-01 | E22: 582.01 | F22: 7384 | G22: 4906 | H22: 1181.44 | I22: 664.56 | J22: 36.92 | K22: 14.77 | M22: 110.76 | N22: 343 | O22: =SUM(H22:N22) -> 2351.45 | P22: 590.72 | Q22: 147.68 | R22: 36.92 | U22: 343 | V22: =SUM(P22:U22) -> 1118.32 | W22: 4463.68 | X22: -45.09 | Z22: =SUM(E22,O22,V22:Y22) -> 8470.37 | AB22: 5701787 | AC22: 310108198901250513 | AD22: 7990.9 | AE22: 6% | AF22: 479.47
A23: 8 | B23: 胡佳华 | C23: 202501 | D23: 2025-01-01 | E23: 804.31 | F23: 9575 | G23: 9575 | H23: 1532 | I23: 861.76 | J23: 47.88 | K23: 19.15 | M23: 143.63 | N23: 670 | O23: =SUM(H23:N23) -> 3274.42 | P23: 766 | Q23: 191.5 | R23: 47.88 | U23: 670 | V23: =SUM(P23:U23) -> 1675.38 | W23: 6688.62 | Z23: =SUM(E23,O23,V23:Y23) -> 12442.73 | AB23: 6242778 | AC23: 310109198103142020 | AD23: 11738.42 | AE23: 6% | AF23: 704.31
A24: 9 | B24: 季华 | C24: 202501 | D24: 2024-06-01 | E24: 997.97 | F24: 10475 | G24: 10475 | H24: 1676 | I24: 942.76 | J24: 52.38 | K24: 20.95 | M24: 157.13 | N24: 733 | O24: =SUM(H24:N24) -> 3582.22 | P24: 838 | Q24: 209.5 | R24: 52.38 | U24: 733 | V24: =SUM(P24:U24) -> 1832.88 | W24: 9451.02 | X24: -63.98 | Z24: =SUM(E24,O24,V24:Y24) -> 15800.11 | AB24: 5544586 | AC24: 310115198609170130 | AD24: 14905.76 | AE24: 6% | AF24: 894.35
A25: 10 | B25: 梁裔杰 | C25: 202501 | D25: 2024-06-01 | E25: 764.55 | F25: 7384 | G25: 7139 | H25: 1181.44 | I25: 664.56 | J25: 36.92 | K25: 14.77 | M25: 110.76 | N25: 500 | O25: =SUM(H25:N25) -> 2508.45 | P25: 590.72 | Q25: 147.68 | R25: 36.92 | U25: 500 | V25: =SUM(P25:U25) -> 1275.32 | W25: 7192.06 | X25: -45.09 | Z25: =SUM(E25,O25,V25:Y25) -> 11695.29 | AB25: 5861130 | AC25: 310113198509301719 | AD25: 11033.28 | AE25: 6% | AF25: 662.01
A26: 11 | B26: 罗文彬 | C26: 202501 | D26: 2024-06-01 | E26: 767.96 | F26: 14537 | G26: 14537 | H26: 2325.92 | I26: 1308.34 | J26: 72.69 | K26: 29.07 | M26: 218.06 | N26: 1018 | O26: =SUM(H26:N26) -> 4972.08 | P26: 1162.96 | Q26: 290.74 | R26: 72.69 | U26: 1018 | V26: =SUM(P26:U26) -> 2544.39 | W26: 3516.11 | X26: -88.72 | Z26: =SUM(E26,O26,V26:Y26) -> 11711.82 | AB26: 5922255 | AC26: 310110198902103234 | AD26: 11048.89 | AE26: 6% | AF26: 662.93
A27: 12 | B27: 孟浩杰 | C27: 202501 | D27: 2024-06-01 | E27: 870.22 | F27: 9241 | G27: 9241 | H27: 1478.56 | I27: 831.7 | J27: 46.21 | K27: 18.48 | M27: 138.62 | N27: 647 | O27: =SUM(H27:N27) -> 3160.57 | P27: 739.28 | Q27: 184.82 | R27: 46.21 | U27: 647 | V27: =SUM(P27:U27) -> 1617.31 | W27: 7959.11 | X27: -56.41 | Z27: =SUM(E27,O27,V27:Y27) -> 13550.8 | AB27: 5544588 | AC27: 510108198209090637 | AD27: 12783.77 | AE27: 6% | AF27: 767.03
A28: 13 | B28: 戚继英 | C28: 202501 | D28: 2024-06-01 | E28: 1019.98 | F28: 11152 | G28: 11152 | H28: 1784.32 | I28: 1003.68 | J28: 55.76 | K28: 22.3 | M28: 167.28 | N28: 781 | O28: =SUM(H28:N28) -> 3814.34 | P28: 892.16 | Q28: 223.04 | R28: 55.76 | U28: 781 | V28: =SUM(P28:U28) -> 1951.96 | W28: 9466.72 | X28: -68.12 | Z28: =SUM(E28,O28,V28:Y28) -> 16184.88 | AB28: 5544593 | AC28: 310102198004243227 | AD28: 15268.75 | AE28: 6% | AF28: 916.13
A29: 14 | B29: 邱杭佳 | C29: 202501 | D29: 2024-06-01 | E29: 688.81 | F29: 7474 | G29: 7474 | H29: 1195.84 | I29: 672.66 | J29: 37.37 | K29: 14.95 | M29: 112.11 | N29: 523 | O29: =SUM(H29:N29) -> 2555.93 | P29: 597.92 | Q29: 149.48 | R29: 37.37 | U29: 523 | V29: =SUM(P29:U29) -> 1307.77 | W29: 5849.77 | X29: -45.6 | Z29: =SUM(E29,O29,V29:Y29) -> 10356.68 | AB29: 5544592 | AC29: 31010819830921103X | AD29: 9770.44 | AE29: 6% | AF29: 586.24
A30: 15 | B30: 施翎 | C30: 202501 | D30: 2024-06-01 | O30: =SUM(H30:N30) -> 0 | V30: =SUM(P30:U30) -> 0 | X30: -11.99 | Z30: =SUM(E30,O30,V30:Y30) -> -11.99 | AB30: 5922253 | AC30: 310109198401060015 | AD30: -11.31 | AE30: 6% | AF30: -0.68
A31: 16 | B31: 王偲 | C31: 202501 | D31: 2024-06-01 | E31: 621.6 | F31: 8261 | G31: 8261 | H31: 1321.76 | I31: 743.5 | J31: 41.31 | K31: 16.52 | M31: 123.92 | N31: 578 | O31: =SUM(H31:N31) -> 2825.01 | P31: 660.88 | Q31: 165.22 | R31: 41.31 | U31: 578 | V31: =SUM(P31:U31) -> 1445.41 | W31: 4322.89 | X31: -50.43 | Z31: =SUM(E31,O31,V31:Y31) -> 9164.48 | AB31: 5544583 | AC31: 310109198908200531 | AD31: 8645.73 | AE31: 6% | AF31: 518.75
A32: 17 | B32: 王凤凌 | C32: 202501 | D32: 2024-06-01 | E32: 511.59 | F32: 7384 | G32: 4686 | H32: 1181.44 | I32: 664.56 | J32: 36.92 | K32: 14.77 | M32: 110.76 | N32: 328 | O32: =SUM(H32:N32) -> 2336.45 | P32: 590.72 | Q32: 147.68 | R32: 36.92 | U32: 328 | V32: =SUM(P32:U32) -> 1103.32 | W32: 3320 | X32: -45.09 | Z32: =SUM(E32,O32,V32:Y32) -> 7226.27 | AB32: 5544584 | AC32: 31011019870909564X | AD32: 6817.22 | AE32: 6% | AF32: 409.05
A33: 18 | B33: 王一峰 | C33: 202501 | D33: 2024-06-01 | E33: 1020.02 | F33: 16443 | G33: 16443 | H33: 2630.88 | I33: 1479.88 | J33: 82.22 | K33: 32.89 | M33: 246.65 | N33: 1151 | O33: =SUM(H33:N33) -> 5623.52 | P33: 1315.44 | Q33: 328.86 | R33: 82.22 | U33: 1151 | V33: =SUM(P33:U33) -> 2877.52 | W33: 6732.68 | X33: -100.36 | Z33: =SUM(E33,O33,V33:Y33) -> 16153.38 | AB33: 5544582 | AC33: 310230198106182913 | AD33: 15239.05 | AE33: 6% | AF33: 914.33
A34: 19 | B34: 王邹强 | C34: 202501 | D34: 2024-06-01 | E34: 831.08 | F34: 8707 | G34: 8707 | H34: 1393.12 | I34: 783.64 | J34: 43.54 | K34: 17.41 | M34: 130.61 | N34: 609 | O34: =SUM(H34:N34) -> 2977.32 | P34: 696.56 | Q34: 174.14 | R34: 43.54 | U34: 609 | V34: =SUM(P34:U34) -> 1523.24 | W34: 7584.14 | X34: -53.17 | Z34: =SUM(E34,O34,V34:Y34) -> 12862.61 | AB34: 5544577 | AC34: 310108198909220554 | AD34: 12134.54 | AE34: 6% | AF34: 728.07
A35: 20 | B35: 王姗姗 | C35: 202501 | D35: 2024-06-01 | E35: 2331.01 | F35: 18040 | G35: 18040 | H35: 2886.4 | I35: 1623.6 | J35: 90.2 | K35: 36.08 | M35: 270.6 | N35: 1263 | O35: =SUM(H35:N35) -> 6169.88 | P35: 1443.2 | Q35: 360.8 | R35: 90.2 | U35: 1263 | V35: =SUM(P35:U35) -> 3157.2 | W35: 27756.44 | X35: -110.16 | Z35: =SUM(E35,O35,V35:Y35) -> 39304.37 | AB35: 5544591 | AC35: 34112519880604436X | AD35: 37079.6 | AE35: 6% | AF35: 2224.77
A36: 21 | B36: 吴裕刚 | C36: 202501 | D36: 2024-06-01 | E36: 810.73 | F36: 8102 | G36: 8102 | H36: 1296.32 | I36: 729.18 | J36: 40.51 | K36: 16.2 | M36: 121.53 | N36: 567 | O36: =SUM(H36:N36) -> 2770.74 | P36: 648.16 | Q36: 162.04 | R36: 40.51 | U36: 567 | V36: =SUM(P36:U36) -> 1417.71 | W36: 7557 | X36: -49.48 | Z36: =SUM(E36,O36,V36:Y36) -> 12506.7 | AB36: 5544595 | AC36: 31010219810818361X | AD36: 11798.78 | AE36: 6% | AF36: 707.92
A37: 22 | B37: 谢俊敏 | C37: 202501 | D37: 2024-06-01 | E37: 766.91 | F37: 7974 | G37: 7974 | H37: 1275.84 | I37: 717.66 | J37: 39.87 | K37: 15.95 | M37: 119.61 | N37: 558 | O37: =SUM(H37:N37) -> 2726.93 | P37: 637.92 | Q37: 159.48 | R37: 39.87 | U37: 558 | V37: =SUM(P37:U37) -> 1395.27 | W37: 6892.93 | X37: -48.65 | Z37: =SUM(E37,O37,V37:Y37) -> 11733.39 | AB37: 5861129 | AC37: 310110198911171036 | AD37: 11069.22 | AE37: 6% | AF37: 664.17
A38: 23 | B38: 熊伟 | C38: 202501 | D38: 2024-06-01 | E38: 580.89 | F38: 8888 | G38: 8888 | H38: 1422.08 | I38: 799.92 | J38: 44.44 | K38: 17.78 | M38: 133.32 | N38: 622 | O38: =SUM(H38:N38) -> 3039.54 | P38: 711.04 | Q38: 177.76 | R38: 44.44 | U38: 622 | V38: =SUM(P38:U38) -> 1555.24 | W38: 3320 | X38: -54.25 | Z38: =SUM(E38,O38,V38:Y38) -> 8441.42 | AB38: 5544579 | AC38: 310109198905074533 | AD38: 7963.59 | AE38: 6% | AF38: 477.83
A39: 24 | B39: 杨晓燕 | C39: 202501 | D39: 2024-06-01 | E39: 731.84 | F39: 8472 | G39: 8472 | H39: 1355.52 | I39: 762.48 | J39: 42.36 | K39: 16.94 | M39: 127.08 | N39: 593 | O39: =SUM(H39:N39) -> 2897.38 | P39: 677.76 | Q39: 169.44 | R39: 42.36 | U39: 593 | V39: =SUM(P39:U39) -> 1482.56 | W39: 6050.74 | X39: -51.71 | Z39: =SUM(E39,O39,V39:Y39) -> 11110.81 | AB39: 5544587 | AC39: 34222519770913404X | AD39: 10481.9 | AE39: 6% | AF39: 628.91
A40: 25 | B40: 叶毅 | C40: 202501 | D40: 2024-06-01 | E40: 746.79 | F40: 7759 | G40: 7759 | H40: 1241.44 | I40: 698.32 | J40: 38.8 | K40: 15.52 | M40: 116.39 | N40: 543 | O40: =SUM(H40:N40) -> 2653.47 | P40: 620.72 | Q40: 155.18 | R40: 38.8 | U40: 543 | V40: =SUM(P40:U40) -> 1357.7 | W40: 6668.62 | X40: -47.38 | Z40: =SUM(E40,O40,V40:Y40) -> 11379.2 | AB40: 5861126 | AC40: 310110198502133266 | AD40: 10735.09 | AE40: 6% | AF40: 644.11
A41: 26 | B41: 张梦诏 | C41: 202501 | D41: 2024-06-01 | E41: 808.36 | F41: 7384 | G41: 5239 | H41: 1181.44 | I41: 664.56 | J41: 36.92 | K41: 14.77 | M41: 110.76 | N41: 367 | O41: =SUM(H41:N41) -> 2375.45 | P41: 590.72 | Q41: 147.68 | R41: 36.92 | U41: 367 | V41: =SUM(P41:U41) -> 1142.32 | W41: 8188.23 | X41: -45.09 | Z41: =SUM(E41,O41,V41:Y41) -> 12469.27 | AB41: 5726531 | AC41: 342423200108298172 | AD41: 11763.45 | AE41: 6% | AF41: 705.82
A42: 27 | B42: 周雨薇 | C42: 202501 | D42: 2024-06-01 | E42: 615.01 | F42: 7384 | G42: 6830 | H42: 1181.44 | I42: 664.56 | J42: 36.92 | K42: 14.77 | M42: 110.76 | N42: 478 | O42: =SUM(H42:N42) -> 2486.45 | P42: 590.72 | Q42: 147.68 | R42: 36.92 | U42: 478 | V42: =SUM(P42:U42) -> 1253.32 | W42: 4743.64 | X42: -45.09 | Z42: =SUM(E42,O42,V42:Y42) -> 9053.33 | AB42: 5544590 | AC42: 310104199212304829 | AD42: 8540.86 | AE42: 6% | AF42: 512.47
... A44: 29 | B44: 朱云 | C44: 202501 | D44: 2024-06-01 | E44: 674.66 | F44: 11909 | G44: 11909 | H44: 1905.44 | I44: 1071.82 | J44: 59.55 | K44: 23.82 | M44: 178.64 | N44: 834 | O44: =SUM(H44:N44) -> 4073.27 | P44: 952.72 | Q44: 238.18 | R44: 59.55 | U44: 834 | V44: =SUM(P44:U44) -> 2084.45 | W44: 3320 | X44: -72.76 | Z44: =SUM(E44,O44,V44:Y44) -> 10079.62 | AB44: 5922254 | AC44: 310110198810200045 | AD44: 9509.08 | AE44: 6% | AF44: 570.54
A45: 30 | B45: 朱倩 | C45: 202501 | D45: 2024-06-01 | O45: =SUM(H45:N45) -> 0 | V45: =SUM(P45:U45) -> 0 | X45: -22.74 | Z45: =SUM(E45,O45,V45:Y45) -> -22.74 | AB45: 5544589 | AC45: 310108198005121510 | AD45: -21.45 | AE45: 6% | AF45: -1.29
...
