Workbook

Sheet 202411
A1: 序号 | B1: 计薪 周期 | C1: 工号 | D1: 姓名 | E1: 身份证号 | F1: 劳动合同起始日期 | G1: 劳动合同结束日期 | H1: 离职日期 | I1: 社保缴纳地 | J1: 星级费用 | K1: 考核费用 | L1: 量化费用 | M1: 专项费用 | Z1: 当月税前工资合计 | AA1: 社保基数(个人) | AB1: 养老保险(个人) | AC1: 医疗保险(个人) | AD1: 失业保险(个人) | AE1: 公积金基数(个人) | AF1: 住房公积金(个人) | AG1: 员工五险一金合计 | AH1: 本月个人所得税-系统导出 | AI1: 税后增加 | AJ1: 税后扣减 | AK1: 员工实发合计 | AL1: 社保基数 | AM1: 公积金基数 | AN1: 养老缴费 | AO1: 医疗缴费 | AP1: 失业保险 | AQ1: 工伤保险 | AR1: 生育保险 | AS1: 公积金 | AT1: 残保金 | AU1: 企业五险一金合计 | AW1: 工会费 | AX1: 代收付合计 | AY1: 上月垫付 | AZ1: 社保备注 | BA1: 外包服务费 | BB1: 税前项合计 | BC1: 增值税 | BD1: 总计
A2: NO. | B2: Salary Cycle | C2: Employee No. | D2: Name | E2: ID No. | F2: Contract Starting Date | G2: Contract Expiry Date | H2: Exit Date | I2: Social Insurance City | J2: Contract Salary | K2: Assessment fees | L2: Quantifying costs | M2: 支局专项 | N2: 1+1激励 | O2: 交通费 | P2: 效能补贴 | Q2: 高温费及清凉饮料费 （6-9月） | R2: 伙食补贴 | S2: 独生子女奖励 | T2: 保险费 | U2: 其他费用 | V2: 补发费用 | W2: 劳防用品 | X2: 保障多收 | Y2: 其他扣款 | Z2: Pre-tax Total | AA2: Social Insurance Base | AB2: Pension Employee | AC2: Medical Employee | AD2: Umemployment Employee | AE2: Housing Fund Base | AF2: Housing Fund Employee | AG2: Total Amount of Social Insurance(EE) | AH2: Personal Income Tax | AI2: Increase After-tax payment | AJ2: Reduction After-tax payment | AK2: After-tax total Income | AL2: Social Insurance Base | AM2: Housing Fund Base | AN2: Pension Employer | AO2: Medical Employer | AP2: Umemployment Employer | AQ2: Injury Employer | AR2: Maternity Insurance Employer | AS2: Housing Fund Employer | AT2: Disabled people&Back pay Fund | AU2: Total Amount of Social Insurance(ER) | AW2: Union Fee | AX2: Payment Total | AZ2: Social Security remark | BA2: Service Fee | BB2: Total | BC2: VAT | BD2: Subtotal
A3: =ROW()-2 -> 1 | B3: 2411 | C3: WB026139 | D3: 赵梅 | E3: 310227198801262829 | F3: 45413 | G3: 45777 | I3: 上海 | J3: 1200 | K3: 4824.8 | L3: 1984.08 | P3: 200 | R3: 630 | S3: 0 | U3: 742 | V3: 0 | X3: 0 | Y3: 0 | Z3: =SUM(J3:Y3) -> 9580.88 | AA3: 7384 | AB3: 590.72 | AC3: 147.68 | AD3: 36.92 | AE3: 2690 | AF3: =ROUND(AE3*7%,0) -> 188 | AG3: =AB3+AC3+AD3+AF3 -> 963.32 | AK3: =Z3-AG3-AH3 -> 8617.56 | AL3: 7384 | AM3: 2690 | AN3: =ROUND(AL3*16%,2) -> 1181.44 | AO3: =ROUND(AL3*9%,2) -> 664.56 | AP3: =ROUND(AL3*0.5%,2) -> 36.92 | AQ3: =ROUND(AL3*0.256%,2) -> 18.9 | AS3: =ROUND(AM3*7%,0) -> 188 | AT3: =ROUND(IF(AL3<24366,AL3*1.5%,24366*1.5%),2) -> 110.76 | AU3: =SUM(AN3:AT3) -> 2200.58 | AX3: =AU3+Z3+AI3-AJ3+AW3 -> 11781.46 | BA3: 255 | BB3: =ROUND(AX3+BA3+AY3,2) -> 12036.46 | BC3: =ROUND(BB3*6%,2) -> 722.19 | BD3: =ROUND(SUM(BB3:BC3),2) -> 12758.65
A4: =ROW()-2 -> 2 | B4: 2411 | C4: WB032993 | D4: 施梅 | E4: 310227198805293665 | F4: 45413 | G4: 45777 | I4: 上海 | J4: 950 | K4: 1531 | L4: 987.6 | P4: 200 | R4: 630 | S4: 0 | U4: 742 | V4: 0 | X4: 184.72 | Y4: 0 | Z4: =SUM(J4:Y4) -> 5225.32 | AA4: 7384 | AB4: 590.72 | AC4: 147.68 | AD4: 36.92 | AE4: 2690 | AF4: =ROUND(AE4*7%,0) -> 188 | AG4: =AB4+AC4+AD4+AF4 -> 963.32 | AK4: =Z4-AG4-AH4 -> 4262 | AL4: 7384 | AM4: 2690 | AN4: =ROUND(AL4*16%,2) -> 1181.44 | AO4: =ROUND(AL4*9%,2) -> 664.56 | AP4: =ROUND(AL4*0.5%,2) -> 36.92 | AQ4: =ROUND(AL4*0.256%,2) -> 18.9 | AS4: =ROUND(AM4*7%,0) -> 188 | AT4: =ROUND(IF(AL4<24366,AL4*1.5%,24366*1.5%),2) -> 110.76 | AU4: =SUM(AN4:AT4) -> 2200.58 | AX4: =AU4+Z4+AI4-AJ4+AW4 -> 7425.9 | BA4: 255 | BB4: =ROUND(AX4+BA4+AY4,2) -> 7680.9 | BC4: =ROUND(BB4*6%,2) -> 460.85 | BD4: =ROUND(SUM(BB4:BC4),2) -> 8141.75
A5: =ROW()-2 -> 3 | B5: 2411 | C5: WB045273 | D5: 赵燕敏 | E5: 310225198105111629 | F5: 45413 | G5: 45777 | I5: 上海 | J5: 1030 | K5: 1467.4 | L5: 986.64 | P5: 200 | R5: 630 | S5: 0 | U5: 742 | V5: 0 | X5: 169.28 | Y5: 0 | Z5: =SUM(J5:Y5) -> 5225.32 | AA5: 7384 | AB5: 590.72 | AC5: 147.68 | AD5: 36.92 | AE5: 2690 | AF5: =ROUND(AE5*7%,0) -> 188 | AG5: =AB5+AC5+AD5+AF5 -> 963.32 | AK5: =Z5-AG5-AH5 -> 4262 | AL5: 7384 | AM5: 2690 | AN5: =ROUND(AL5*16%,2) -> 1181.44 | AO5: =ROUND(AL5*9%,2) -> 664.56 | AP5: =ROUND(AL5*0.5%,2) -> 36.92 | AQ5: =ROUND(AL5*0.256%,2) -> 18.9 | AS5: =ROUND(AM5*7%,0) -> 188 | AT5: =ROUND(IF(AL5<24366,AL5*1.5%,24366*1.5%),2) -> 110.76 | AU5: =SUM(AN5:AT5) -> 2200.58 | AX5: =AU5+Z5+AI5-AJ5+AW5 -> 7425.9 | BA5: 255 | BB5: =ROUND(AX5+BA5+AY5,2) -> 7680.9 | BC5: =ROUND(BB5*6%,2) -> 460.85 | BD5: =ROUND(SUM(BB5:BC5),2) -> 8141.75
A6: =ROW()-2 -> 4 | B6: 2411 | C6: WB030755 | D6: 谭晓刚 | E6: 310227197503241611 | F6: 45413 | G6: 45777 | I6: 上海 | J6: 950 | K6: 4729.8 | L6: 1187.12 | P6: 200 | R6: 630 | S6: 0 | U6: 742 | V6: 0 | X6: 0 | Y6: 0 | Z6: =SUM(J6:Y6) -> 8438.92 | AA6: 7384 | AB6: 590.72 | AC6: 147.68 | AD6: 36.92 | AE6: 2690 | AF6: =ROUND(AE6*7%,0) -> 188 | AG6: =AB6+AC6+AD6+AF6 -> 963.32 | AK6: =Z6-AG6-AH6 -> 7475.6 | AL6: 7384 | AM6: 2690 | AN6: =ROUND(AL6*16%,2) -> 1181.44 | AO6: =ROUND(AL6*9%,2) -> 664.56 | AP6: =ROUND(AL6*0.5%,2) -> 36.92 | AQ6: =ROUND(AL6*0.256%,2) -> 18.9 | AS6: =ROUND(AM6*7%,0) -> 188 | AT6: =ROUND(IF(AL6<24366,AL6*1.5%,24366*1.5%),2) -> 110.76 | AU6: =SUM(AN6:AT6) -> 2200.58 | AX6: =AU6+Z6+AI6-AJ6+AW6 -> 10639.5 | BA6: 255 | BB6: =ROUND(AX6+BA6+AY6,2) -> 10894.5 | BC6: =ROUND(BB6*6%,2) -> 653.67 | BD6: =ROUND(SUM(BB6:BC6),2) -> 11548.17
A7: =ROW()-2 -> 5 | B7: 2411 | C7: WB046623 | D7: 陆丽伟 | E7: 310227198802293619 | F7: 45413 | G7: 45777 | I7: 上海 | J7: 950 | K7: 2216.24 | L7: 1298.56 | P7: 200 | R7: 630 | S7: 0 | U7: 0 | V7: 0 | X7: 0 | Y7: 0 | Z7: =SUM(J7:Y7) -> 5294.8 | AA7: 7384 | AB7: 590.72 | AC7: 147.68 | AD7: 36.92 | AE7: 2690 | AF7: =ROUND(AE7*7%,0) -> 188 | AG7: =AB7+AC7+AD7+AF7 -> 963.32 | AK7: =Z7-AG7-AH7 -> 4331.48 | AL7: 7384 | AM7: 2690 | AN7: =ROUND(AL7*16%,2) -> 1181.44 | AO7: =ROUND(AL7*9%,2) -> 664.56 | AP7: =ROUND(AL7*0.5%,2) -> 36.92 | AQ7: =ROUND(AL7*0.256%,2) -> 18.9 | AS7: =ROUND(AM7*7%,0) -> 188 | AT7: =ROUND(IF(AL7<24366,AL7*1.5%,24366*1.5%),2) -> 110.76 | AU7: =SUM(AN7:AT7) -> 2200.58 | AX7: =AU7+Z7+AI7-AJ7+AW7 -> 7495.38 | BA7: 255 | BB7: =ROUND(AX7+BA7+AY7,2) -> 7750.38 | BC7: =ROUND(BB7*6%,2) -> 465.02 | BD7: =ROUND(SUM(BB7:BC7),2) -> 8215.4
A8: =ROW()-2 -> 6 | B8: 2411 | C8: WB013255 | D8: 任清丽 | E8: 341223198806062763 | F8: 45444 | G8: 45808 | I8: 上海 | J8: 900 | K8: 2918.2 | L8: 2613.76 | P8: 200 | R8: 630 | S8: 0 | U8: 742 | V8: 0 | X8: 0 | Y8: -200 | Z8: =SUM(J8:Y8) -> 7803.96 | AA8: 7384 | AB8: 590.72 | AC8: 147.68 | AD8: 36.92 | AE8: 6878 | AF8: =ROUND(AE8*7%,0) -> 481 | AG8: =AB8+AC8+AD8+AF8 -> 1256.32 | AK8: =Z8-AG8-AH8 -> 6547.64 | AL8: 7384 | AM8: 6878 | AN8: =ROUND(AL8*16%,2) -> 1181.44 | AO8: =ROUND(AL8*9%,2) -> 664.56 | AP8: =ROUND(AL8*0.5%,2) -> 36.92 | AQ8: =ROUND(AL8*0.256%,2) -> 18.9 | AS8: =ROUND(AM8*7%,0) -> 481 | AT8: =ROUND(IF(AL8<24366,AL8*1.5%,24366*1.5%),2) -> 110.76 | AU8: =SUM(AN8:AT8) -> 2493.58 | AX8: =AU8+Z8+AI8-AJ8+AW8 -> 10297.54 | BA8: 255 | BB8: =ROUND(AX8+BA8+AY8,2) -> 10552.54 | BC8: =ROUND(BB8*6%,2) -> 633.15 | BD8: =ROUND(SUM(BB8:BC8),2) -> 11185.69
A9: =ROW()-2 -> 7 | B9: 2411 | C9: WB022825 | D9: 张晓薇 | E9: 310229199011210247 | F9: 45444 | G9: 45808 | I9: 上海 | J9: 1200 | K9: 2588.7 | L9: 1943.2 | P9: 200 | R9: 630 | S9: 0 | U9: 1113 | V9: 0 | X9: 0 | Y9: -200 | Z9: =SUM(J9:Y9) -> 7474.9 | AA9: 8131 | AB9: 650.48 | AC9: 162.62 | AD9: 40.66 | AE9: 8131 | AF9: =ROUND(AE9*7%,0) -> 569 | AG9: =AB9+AC9+AD9+AF9 -> 1422.76 | AK9: =Z9-AG9-AH9 -> 6052.14 | AL9: 8131 | AM9: 8131 | AN9: =ROUND(AL9*16%,2) -> 1300.96 | AO9: 731.8 | AP9: =ROUND(AL9*0.5%,2) -> 40.66 | AQ9: =ROUND(AL9*0.256%,2) -> 20.82 | AS9: =ROUND(AM9*7%,0) -> 569 | AT9: =ROUND(IF(AL9<24366,AL9*1.5%,24366*1.5%),2) -> 121.97 | AU9: =SUM(AN9:AT9) -> 2785.21 | AX9: =AU9+Z9+AI9-AJ9+AW9 -> 10260.11 | BA9: 255 | BB9: =ROUND(AX9+BA9+AY9,2) -> 10515.11 | BC9: =ROUND(BB9*6%,2) -> 630.91 | BD9: =ROUND(SUM(BB9:BC9),2) -> 11146.02
A10: =ROW()-2 -> 8 | B10: 2411 | C10: WB023998 | D10: 戴连荣 | E10: 310227198411292010 | F10: 45444 | G10: 45808 | I10: 上海 | J10: 1300 | K10: 3528 | L10: 4442.68 | P10: 200 | R10: 630 | S10: 0 | U10: 1113 | V10: 0 | X10: 0 | Y10: 0 | Z10: =SUM(J10:Y10) -> 11213.68 | AA10: 12760 | AB10: 1020.8 | AC10: 255.2 | AD10: 63.8 | AE10: 12760 | AF10: =ROUND(AE10*7%,0) -> 893 | AG10: =AB10+AC10+AD10+AF10 -> 2232.8 | AK10: =Z10-AG10-AH10 -> 8980.88 | AL10: 12760 | AM10: 12760 | AN10: =ROUND(AL10*16%,2) -> 2041.6 | AO10: =ROUND(AL10*9%,2) -> 1148.4 | AP10: =ROUND(AL10*0.5%,2) -> 63.8 | AQ10: =ROUND(AL10*0.256%,2) -> 32.67 | AS10: =ROUND(AM10*7%,0) -> 893 | AT10: =ROUND(IF(AL10<24366,AL10*1.5%,24366*1.5%),2) -> 191.4 | AU10: =SUM(AN10:AT10) -> 4370.87 | AX10: =AU10+Z10+AI10-AJ10+AW10 -> 15584.55 | BA10: 255 | BB10: =ROUND(AX10+BA10+AY10,2) -> 15839.55 | BC10: =ROUND(BB10*6%,2) -> 950.37 | BD10: =ROUND(SUM(BB10:BC10),2) -> 16789.92
A11: =ROW()-2 -> 9 | B11: 2411 | C11: WB025814 | D11: 陶叶丽 | E11: 310227198510132629 | F11: 45444 | G11: 45808 | I11: 上海 | J11: 1030 | K11: 2532.64 | L11: 2216.72 | P11: 200 | R11: 630 | S11: 0 | U11: 742 | V11: 0 | X11: 0 | Y11: -500 | Z11: =SUM(J11:Y11) -> 6851.36 | AA11: 7384 | AB11: 590.72 | AC11: 147.68 | AD11: 36.92 | AE11: 4668 | AF11: =ROUND(AE11*7%,0) -> 327 | AG11: =AB11+AC11+AD11+AF11 -> 1102.32 | AK11: =Z11-AG11-AH11 -> 5749.04 | AL11: 7384 | AM11: 4668 | AN11: =ROUND(AL11*16%,2) -> 1181.44 | AO11: =ROUND(AL11*9%,2) -> 664.56 | AP11: =ROUND(AL11*0.5%,2) -> 36.92 | AQ11: =ROUND(AL11*0.256%,2) -> 18.9 | AS11: =ROUND(AM11*7%,0) -> 327 | AT11: =ROUND(IF(AL11<24366,AL11*1.5%,24366*1.5%),2) -> 110.76 | AU11: =SUM(AN11:AT11) -> 2339.58 | AX11: =AU11+Z11+AI11-AJ11+AW11 -> 9190.94 | BA11: 255 | BB11: =ROUND(AX11+BA11+AY11,2) -> 9445.94 | BC11: =ROUND(BB11*6%,2) -> 566.76 | BD11: =ROUND(SUM(BB11:BC11),2) -> 10012.7
A12: =ROW()-2 -> 10 | B12: 2411 | C12: WB026291 | D12: 何军利 | E12: 310227197512314245 | F12: 45444 | G12: 45808 | I12: 上海 | J12: 1030 | K12: 1357.86 | L12: 678 | P12: 200 | R12: 630 | S12: 0 | U12: 371 | V12: 0 | X12: 699.46 | Y12: 0 | Z12: =SUM(J12:Y12) -> 4966.32 | AA12: 7384 | AB12: 590.72 | AC12: 147.68 | AD12: 36.92 | AE12: 4289 | AF12: =ROUND(AE12*7%,0) -> 300 | AG12: =AB12+AC12+AD12+AF12 -> 1075.32 | AK12: =Z12-AG12-AH12 -> 3891 | AL12: 7384 | AM12: 4289 | AN12: =ROUND(AL12*16%,2) -> 1181.44 | AO12: =ROUND(AL12*9%,2) -> 664.56 | AP12: =ROUND(AL12*0.5%,2) -> 36.92 | AQ12: =ROUND(AL12*0.256%,2) -> 18.9 | AS12: =ROUND(AM12*7%,0) -> 300 | AT12: =ROUND(IF(AL12<24366,AL12*1.5%,24366*1.5%),2) -> 110.76 | AU12: =SUM(AN12:AT12) -> 2312.58 | AX12: =AU12+Z12+AI12-AJ12+AW12 -> 7278.9 | BA12: 255 | BB12: =ROUND(AX12+BA12+AY12,2) -> 7533.9 | BC12: =ROUND(BB12*6%,2) -> 452.03 | BD12: =ROUND(SUM(BB12:BC12),2) -> 7985.93
A13: =ROW()-2 -> 11 | B13: 2411 | C13: WB035661 | D13: 常宇航 | E13: 340321199609230533 | F13: 45444 | G13: 45808 | I13: 上海 | J13: 1030 | K13: 2464.5 | L13: 1412.32 | P13: 200 | R13: 630 | S13: 0 | U13: 1113 | V13: 0 | X13: 0 | Y13: 0 | Z13: =SUM(J13:Y13) -> 6849.82 | AA13: 7384 | AB13: 590.72 | AC13: 147.68 | AD13: 36.92 | AE13: 6644 | AF13: =ROUND(AE13*7%,0) -> 465 | AG13: =AB13+AC13+AD13+AF13 -> 1240.32 | AK13: =Z13-AG13-AH13 -> 5609.5 | AL13: 7384 | AM13: 6644 | AN13: =ROUND(AL13*16%,2) -> 1181.44 | AO13: =ROUND(AL13*9%,2) -> 664.56 | AP13: =ROUND(AL13*0.5%,2) -> 36.92 | AQ13: =ROUND(AL13*0.256%,2) -> 18.9 | AS13: =ROUND(AM13*7%,0) -> 465 | AT13: =ROUND(IF(AL13<24366,AL13*1.5%,24366*1.5%),2) -> 110.76 | AU13: =SUM(AN13:AT13) -> 2477.58 | AX13: =AU13+Z13+AI13-AJ13+AW13 -> 9327.4 | BA13: 255 | BB13: =ROUND(AX13+BA13+AY13,2) -> 9582.4 | BC13: =ROUND(BB13*6%,2) -> 574.94 | BD13: =ROUND(SUM(BB13:BC13),2) -> 10157.34
A14: =ROW()-2 -> 12 | B14: 2411 | C14: WB038776 | D14: 陆晓岚 | E14: 310227199207211222 | F14: 45444 | G14: 45808 | I14: 上海 | J14: 950 | K14: 123.9 | L14: 101.44 | P14: 50 | R14: 630 | S14: 0 | U14: 0 | V14: 0 | X14: 2660.98 | Y14: 0 | Z14: =SUM(J14:Y14) -> 4516.32 | AA14: 7384 | AB14: 590.72 | AC14: 147.68 | AD14: 36.92 | AE14: 5300 | AF14: =ROUND(AE14*7%,0) -> 371 | AG14: =AB14+AC14+AD14+AF14 -> 1146.32 | AK14: =Z14-AG14-AH14 -> 3370 | AL14: 7384 | AM14: 5300 | AN14: =ROUND(AL14*16%,2) -> 1181.44 | AO14: =ROUND(AL14*9%,2) -> 664.56 | AP14: =ROUND(AL14*0.5%,2) -> 36.92 | AQ14: =ROUND(AL14*0.256%,2) -> 18.9 | AS14: =ROUND(AM14*7%,0) -> 371 | AT14: =ROUND(IF(AL14<24366,AL14*1.5%,24366*1.5%),2) -> 110.76 | AU14: =SUM(AN14:AT14) -> 2383.58 | AX14: =AU14+Z14+AI14-AJ14+AW14 -> 6899.9 | BA14: 255 | BB14: =ROUND(AX14+BA14+AY14,2) -> 7154.9 | BC14: =ROUND(BB14*6%,2) -> 429.29 | BD14: =ROUND(SUM(BB14:BC14),2) -> 7584.19
A15: =ROW()-2 -> 13 | B15: 2411 | C15: WB044812 | D15: 曹克洋 | E15: 341226199712081318 | F15: 45444 | G15: 45808 | I15: 上海 | J15: 1200 | K15: 2176.2 | L15: 1387.68 | P15: 200 | R15: 630 | S15: 0 | U15: 1113 | V15: 0 | X15: 0 | Y15: 0 | Z15: =SUM(J15:Y15) -> 6706.88 | AA15: 7384 | AB15: 590.72 | AC15: 147.68 | AD15: 36.92 | AE15: 5351 | AF15: =ROUND(AE15*7%,0) -> 375 | AG15: =AB15+AC15+AD15+AF15 -> 1150.32 | AK15: =Z15-AG15-AH15 -> 5556.56 | AL15: 7384 | AM15: 5351 | AN15: =ROUND(AL15*16%,2) -> 1181.44 | AO15: =ROUND(AL15*9%,2) -> 664.56 | AP15: =ROUND(AL15*0.5%,2) -> 36.92 | AQ15: =ROUND(AL15*0.256%,2) -> 18.9 | AS15: =ROUND(AM15*7%,0) -> 375 | AT15: =ROUND(IF(AL15<24366,AL15*1.5%,24366*1.5%),2) -> 110.76 | AU15: =SUM(AN15:AT15) -> 2387.58 | AX15: =AU15+Z15+AI15-AJ15+AW15 -> 9094.46 | BA15: 255 | BB15: =ROUND(AX15+BA15+AY15,2) -> 9349.46 | BC15: =ROUND(BB15*6%,2) -> 560.97 | BD15: =ROUND(SUM(BB15:BC15),2) -> 9910.43
A16: =ROW()-2 -> 14 | B16: 2411 | C16: WB045176 | D16: 张春花 | E16: 32062619761225622X | F16: 45444 | G16: 45808 | I16: 上海 | J16: 1030 | K16: 4106 | L16: 4382.96 | P16: 200 | R16: 630 | S16: 0 | U16: 0 | V16: 0 | X16: 0 | Y16: 0 | Z16: =SUM(J16:Y16) -> 10348.96 | AA16: 12769 | AB16: 1021.52 | AC16: 255.38 | AD16: 63.85 | AE16: 12769 | AF16: =ROUND(AE16*7%,0) -> 894 | AG16: =AB16+AC16+AD16+AF16 -> 2234.75 | AK16: =Z16-AG16-AH16 -> 8114.21 | AL16: 12769 | AM16: 12769 | AN16: =ROUND(AL16*16%,2) -> 2043.04 | AO16: 1149.22 | AP16: =ROUND(AL16*0.5%,2) -> 63.85 | AQ16: =ROUND(AL16*0.256%,2) -> 32.69 | AS16: =ROUND(AM16*7%,0) -> 894 | AT16: =ROUND(IF(AL16<24366,AL16*1.5%,24366*1.5%),2) -> 191.54 | AU16: =SUM(AN16:AT16) -> 4374.34 | AX16: =AU16+Z16+AI16-AJ16+AW16 -> 14723.3 | BA16: 255 | BB16: =ROUND(AX16+BA16+AY16,2) -> 14978.3 | BC16: =ROUND(BB16*6%,2) -> 898.7 | BD16: =ROUND(SUM(BB16:BC16),2) -> 15877
A17: =ROW()-2 -> 15 | B17: 2411 | C17: WB045370 | D17: 陆智俊 | E17: 310227199807124616 | F17: 45444 | G17: 45808 | I17: 上海 | J17: 1030 | K17: 3007.2 | L17: 1768.4 | P17: 200 | R17: 630 | S17: 0 | U17: 371 | V17: 0 | X17: 0 | Y17: 0 | Z17: =SUM(J17:Y17) -> 7006.6 | AA17: 7556 | AB17: 604.48 | AC17: 151.12 | AD17: 37.78 | AE17: 7556 | AF17: =ROUND(AE17*7%,0) -> 529 | AG17: =AB17+AC17+AD17+AF17 -> 1322.38 | AK17: =Z17-AG17-AH17 -> 5684.22 | AL17: 7556 | AM17: 7556 | AN17: =ROUND(AL17*16%,2) -> 1208.96 | AO17: =ROUND(AL17*9%,2) -> 680.04 | AP17: =ROUND(AL17*0.5%,2) -> 37.78 | AQ17: =ROUND(AL17*0.256%,2) -> 19.34 | AS17: =ROUND(AM17*7%,0) -> 529 | AT17: =ROUND(IF(AL17<24366,AL17*1.5%,24366*1.5%),2) -> 113.34 | AU17: =SUM(AN17:AT17) -> 2588.46 | AX17: =AU17+Z17+AI17-AJ17+AW17 -> 9595.06 | BA17: 255 | BB17: =ROUND(AX17+BA17+AY17,2) -> 9850.06 | BC17: =ROUND(BB17*6%,2) -> 591 | BD17: =ROUND(SUM(BB17:BC17),2) -> 10441.06
A18: =ROW()-2 -> 16 | B18: 2411 | C18: WB045583 | D18: 王春燕 | E18: 310227198405021222 | F18: 45444 | G18: 45808 | I18: 上海 | J18: 1030 | K18: 1685.25 | L18: 1155.04 | P18: 200 | R18: 630 | S18: 0 | U18: 371 | V18: 0 | X18: 157.03 | Y18: -200 | Z18: =SUM(J18:Y18) -> 5028.32 | AA18: 7384 | AB18: 590.72 | AC18: 147.68 | AD18: 36.92 | AE18: 5176 | AF18: =ROUND(AE18*7%,0) -> 362 | AG18: =AB18+AC18+AD18+AF18 -> 1137.32 | AK18: =Z18-AG18-AH18 -> 3891 | AL18: 7384 | AM18: 5176 | AN18: =ROUND(AL18*16%,2) -> 1181.44 | AO18: =ROUND(AL18*9%,2) -> 664.56 | AP18: =ROUND(AL18*0.5%,2) -> 36.92 | AQ18: =ROUND(AL18*0.256%,2) -> 18.9 | AS18: =ROUND(AM18*7%,0) -> 362 | AT18: =ROUND(IF(AL18<24366,AL18*1.5%,24366*1.5%),2) -> 110.76 | AU18: =SUM(AN18:AT18) -> 2374.58 | AX18: =AU18+Z18+AI18-AJ18+AW18 -> 7402.9 | BA18: 255 | BB18: =ROUND(AX18+BA18+AY18,2) -> 7657.9 | BC18: =ROUND(BB18*6%,2) -> 459.47 | BD18: =ROUND(SUM(BB18:BC18),2) -> 8117.37
A19: =ROW()-2 -> 17 | B19: 2411 | C19: WB046624 | D19: 孔祥杰 | E19: 310110198408153236 | F19: 45444 | G19: 45808 | I19: 上海 | J19: 950 | K19: 2563.2 | L19: 2490.48 | P19: 200 | R19: 630 | S19: 0 | U19: 1113 | V19: 0 | X19: 0 | Y19: -500 | Z19: =SUM(J19:Y19) -> 7446.68 | AA19: 7384 | AB19: 590.72 | AC19: 147.68 | AD19: 36.92 | AE19: 7189 | AF19: =ROUND(AE19*7%,0) -> 503 | AG19: =AB19+AC19+AD19+AF19 -> 1278.32 | AK19: =Z19-AG19-AH19 -> 6168.36 | AL19: 7384 | AM19: 7189 | AN19: =ROUND(AL19*16%,2) -> 1181.44 | AO19: =ROUND(AL19*9%,2) -> 664.56 | AP19: =ROUND(AL19*0.5%,2) -> 36.92 | AQ19: =ROUND(AL19*0.256%,2) -> 18.9 | AS19: =ROUND(AM19*7%,0) -> 503 | AT19: =ROUND(IF(AL19<24366,AL19*1.5%,24366*1.5%),2) -> 110.76 | AU19: =SUM(AN19:AT19) -> 2515.58 | AX19: =AU19+Z19+AI19-AJ19+AW19 -> 9962.26 | BA19: 255 | BB19: =ROUND(AX19+BA19+AY19,2) -> 10217.26 | BC19: =ROUND(BB19*6%,2) -> 613.04 | BD19: =ROUND(SUM(BB19:BC19),2) -> 10830.3
A20: =ROW()-2 -> 18 | B20: 2411 | C20: WB047109 | D20: 谢桃丽 | E20: 530322199401231344 | F20: 45444 | G20: 45808 | I20: 上海 | J20: 1030 | K20: 2043.64 | L20: 1991.88 | P20: 200 | R20: 630 | S20: 0 | U20: 0 | V20: 0 | X20: 0 | Y20: 0 | Z20: =SUM(J20:Y20) -> 5895.52 | AA20: 7384 | AB20: 590.72 | AC20: 147.68 | AD20: 36.92 | AE20: 5148 | AF20: =ROUND(AE20*7%,0) -> 360 | AG20: =AB20+AC20+AD20+AF20 -> 1135.32 | AK20: =Z20-AG20-AH20 -> 4760.2 | AL20: 7384 | AM20: 5148 | AN20: =ROUND(AL20*16%,2) -> 1181.44 | AO20: =ROUND(AL20*9%,2) -> 664.56 | AP20: =ROUND(AL20*0.5%,2) -> 36.92 | AQ20: =ROUND(AL20*0.256%,2) -> 18.9 | AS20: =ROUND(AM20*7%,0) -> 360 | AT20: =ROUND(IF(AL20<24366,AL20*1.5%,24366*1.5%),2) -> 110.76 | AU20: =SUM(AN20:AT20) -> 2372.58 | AX20: =AU20+Z20+AI20-AJ20+AW20 -> 8268.1 | BA20: 255 | BB20: =ROUND(AX20+BA20+AY20,2) -> 8523.1 | BC20: =ROUND(BB20*6%,2) -> 511.39 | BD20: =ROUND(SUM(BB20:BC20),2) -> 9034.49
A21: =ROW()-2 -> 19 | B21: 2411 | C21: WB049118 | D21: 顾诗瑶 | E21: 310227199812152021 | F21: 45444 | G21: 45808 | I21: 上海 | J21: 900 | K21: 0 | L21: 280 | P21: 0 | R21: 0 | S21: 0 | U21: 0 | V21: 0 | X21: 2067.32 | Y21: 0 | Z21: =SUM(J21:Y21) -> 3247.32 | AA21: 7384 | AB21: 590.72 | AC21: 147.68 | AD21: 36.92 | AE21: 4570 | AF21: =ROUND(AE21*7%,0) -> 320 | AG21: =AB21+AC21+AD21+AF21 -> 1095.32 | AK21: =Z21-AG21-AH21 -> 2152 | AL21: 7384 | AM21: 4570 | AN21: =ROUND(AL21*16%,2) -> 1181.44 | AO21: =ROUND(AL21*9%,2) -> 664.56 | AP21: =ROUND(AL21*0.5%,2) -> 36.92 | AQ21: =ROUND(AL21*0.256%,2) -> 18.9 | AS21: =ROUND(AM21*7%,0) -> 320 | AT21: =ROUND(IF(AL21<24366,AL21*1.5%,24366*1.5%),2) -> 110.76 | AU21: =SUM(AN21:AT21) -> 2332.58 | AX21: =AU21+Z21+AI21-AJ21+AW21 -> 5579.9 | BA21: 255 | BB21: =ROUND(AX21+BA21+AY21,2) -> 5834.9 | BC21: =ROUND(BB21*6%,2) -> 350.09 | BD21: =ROUND(SUM(BB21:BC21),2) -> 6184.99
A22: =ROW()-2 -> 20 | B22: 2411 | C22: WB049498 | D22: 曾灿 | E22: 362322200010120626 | F22: 45444 | G22: 45808 | I22: 上海 | J22: 900 | K22: 2982.4 | L22: 2275.6 | P22: 200 | R22: 630 | S22: 0 | U22: 0 | V22: 0 | X22: 0 | Y22: 0 | Z22: =SUM(J22:Y22) -> 6988 | AA22: 8182 | AB22: 654.56 | AC22: 163.64 | AD22: 40.91 | AE22: 8182 | AF22: =ROUND(AE22*7%,0) -> 573 | AG22: =AB22+AC22+AD22+AF22 -> 1432.11 | AK22: =Z22-AG22-AH22 -> 5555.89 | AL22: 8182 | AM22: 8182 | AN22: =ROUND(AL22*16%,2) -> 1309.12 | AO22: =ROUND(AL22*9%,2) -> 736.38 | AP22: =ROUND(AL22*0.5%,2) -> 40.91 | AQ22: =ROUND(AL22*0.256%,2) -> 20.95 | AS22: =ROUND(AM22*7%,0) -> 573 | AT22: =ROUND(IF(AL22<24366,AL22*1.5%,24366*1.5%),2) -> 122.73 | AU22: =SUM(AN22:AT22) -> 2803.09 | AX22: =AU22+Z22+AI22-AJ22+AW22 -> 9791.09 | BA22: 255 | BB22: =ROUND(AX22+BA22+AY22,2) -> 10046.09 | BC22: =ROUND(BB22*6%,2) -> 602.77 | BD22: =ROUND(SUM(BB22:BC22),2) -> 10648.86
A23: =ROW()-2 -> 21 | B23: 2411 | C23: WB027831 | D23: 倪跃新 | E23: 310229197208182017 | F23: 45444 | G23: 45808 | I23: 上海 | J23: 950 | K23: 2605.2 | L23: 847.44 | P23: 200 | R23: 630 | S23: 0 | U23: 0 | V23: 0 | X23: 0 | Y23: 0 | Z23: =SUM(J23:Y23) -> 5232.64 | AA23: 7384 | AB23: 590.72 | AC23: 147.68 | AD23: 36.92 | AE23: 6353 | AF23: =ROUND(AE23*7%,0) -> 445 | AG23: =AB23+AC23+AD23+AF23 -> 1220.32 | AK23: =Z23-AG23-AH23 -> 4012.32 | AL23: 7384 | AM23: 6353 | AN23: =ROUND(AL23*16%,2) -> 1181.44 | AO23: =ROUND(AL23*9%,2) -> 664.56 | AP23: =ROUND(AL23*0.5%,2) -> 36.92 | AQ23: =ROUND(AL23*0.256%,2) -> 18.9 | AS23: =ROUND(AM23*7%,0) -> 445 | AT23: =ROUND(IF(AL23<24366,AL23*1.5%,24366*1.5%),2) -> 110.76 | AU23: =SUM(AN23:AT23) -> 2457.58 | AX23: =AU23+Z23+AI23-AJ23+AW23 -> 7690.22 | BA23: 255 | BB23: =ROUND(AX23+BA23+AY23,2) -> 7945.22 | BC23: =ROUND(BB23*6%,2) -> 476.71 | BD23: =ROUND(SUM(BB23:BC23),2) -> 8421.93
A24: =ROW()-2 -> 22 | B24: 2411 | C24: WB046625 | D24: 李秋梅 | E24: 320321198010030887 | F24: 45444 | G24: 45808 | I24: 上海 | J24: 1030 | K24: 1348.2 | L24: 1785.36 | P24: 200 | R24: 630 | S24: 0 | U24: 371 | V24: 0 | X24: 0 | Y24: 0 | Z24: =SUM(J24:Y24) -> 5364.56 | AA24: 7384 | AB24: 590.72 | AC24: 147.68 | AD24: 36.92 | AE24: 7034 | AF24: =ROUND(AE24*7%,0) -> 492 | AG24: =AB24+AC24+AD24+AF24 -> 1267.32 | AK24: =Z24-AG24-AH24 -> 4097.24 | AL24: 7384 | AM24: 7034 | AN24: =ROUND(AL24*16%,2) -> 1181.44 | AO24: =ROUND(AL24*9%,2) -> 664.56 | AP24: =ROUND(AL24*0.5%,2) -> 36.92 | AQ24: =ROUND(AL24*0.256%,2) -> 18.9 | AS24: =ROUND(AM24*7%,0) -> 492 | AT24: =ROUND(IF(AL24<24366,AL24*1.5%,24366*1.5%),2) -> 110.76 | AU24: =SUM(AN24:AT24) -> 2504.58 | AX24: =AU24+Z24+AI24-AJ24+AW24 -> 7869.14 | BA24: 255 | BB24: =ROUND(AX24+BA24+AY24,2) -> 8124.14 | BC24: =ROUND(BB24*6%,2) -> 487.45 | BD24: =ROUND(SUM(BB24:BC24),2) -> 8611.59
A25: =ROW()-2 -> 23 | B25: 2411 | C25: WB037444 | D25: 高国强 | E25: 65010319750517061X | F25: 45444 | G25: 45808 | I25: 上海 | J25: 950 | K25: 993.3 | L25: 825.04 | P25: 200 | R25: 630 | S25: 0 | U25: 0 | V25: 0 | X25: 1038.98 | Y25: 0 | Z25: =SUM(J25:Y25) -> 4637.32 | AA25: 7384 | AB25: 590.72 | AC25: 147.68 | AD25: 36.92 | AE25: 4880 | AF25: =ROUND(AE25*7%,0) -> 342 | AG25: =AB25+AC25+AD25+AF25 -> 1117.32 | AK25: =Z25-AG25-AH25 -> 3520 | AL25: 7384 | AM25: 4880 | AN25: =ROUND(AL25*16%,2) -> 1181.44 | AO25: =ROUND(AL25*9%,2) -> 664.56 | AP25: =ROUND(AL25*0.5%,2) -> 36.92 | AQ25: =ROUND(AL25*0.256%,2) -> 18.9 | AS25: =ROUND(AM25*7%,0) -> 342 | AT25: =ROUND(IF(AL25<24366,AL25*1.5%,24366*1.5%),2) -> 110.76 | AU25: =SUM(AN25:AT25) -> 2354.58 | AX25: =AU25+Z25+AI25-AJ25+AW25 -> 6991.9 | BA25: 255 | BB25: =ROUND(AX25+BA25+AY25,2) -> 7246.9 | BC25: =ROUND(BB25*6%,2) -> 434.81 | BD25: =ROUND(SUM(BB25:BC25),2) -> 7681.71
A26: =ROW()-2 -> 24 | B26: 2411 | C26: WB046626 | D26: 姜金玲 | E26: 310227198902274028 | F26: 45444 | G26: 45808 | I26: 上海 | J26: 950 | K26: 1327.6 | L26: 710 | P26: 200 | R26: 630 | S26: 0 | U26: 742 | V26: 0 | X26: 790.72 | Y26: 0 | Z26: =SUM(J26:Y26) -> 5350.32 | AA26: 7384 | AB26: 590.72 | AC26: 147.68 | AD26: 36.92 | AE26: 4467 | AF26: =ROUND(AE26*7%,0) -> 313 | AG26: =AB26+AC26+AD26+AF26 -> 1088.32 | AK26: =Z26-AG26-AH26 -> 4262 | AL26: 7384 | AM26: 4467 | AN26: =ROUND(AL26*16%,2) -> 1181.44 | AO26: =ROUND(AL26*9%,2) -> 664.56 | AP26: =ROUND(AL26*0.5%,2) -> 36.92 | AQ26: =ROUND(AL26*0.256%,2) -> 18.9 | AS26: =ROUND(AM26*7%,0) -> 313 | AT26: =ROUND(IF(AL26<24366,AL26*1.5%,24366*1.5%),2) -> 110.76 | AU26: =SUM(AN26:AT26) -> 2325.58 | AX26: =AU26+Z26+AI26-AJ26+AW26 -> 7675.9 | BA26: 255 | BB26: =ROUND(AX26+BA26+AY26,2) -> 7930.9 | BC26: =ROUND(BB26*6%,2) -> 475.85 | BD26: =ROUND(SUM(BB26:BC26),2) -> 8406.75
A27: =ROW()-2 -> 25 | B27: 2411 | C27: WB037461 | D27: 牟金丽 | E27: 422802198502180068 | F27: 45444 | G27: 45808 | I27: 上海 | J27: 950 | K27: 2588.16 | L27: 1352.08 | P27: 200 | R27: 630 | S27: 0 | U27: 0 | V27: 0 | X27: 0 | Y27: 0 | Z27: =SUM(J27:Y27) -> 5720.24 | AA27: 7384 | AB27: 590.72 | AC27: 147.68 | AD27: 36.92 | AE27: 4492 | AF27: =ROUND(AE27*7%,0) -> 314 | AG27: =AB27+AC27+AD27+AF27 -> 1089.32 | AK27: =Z27-AG27-AH27 -> 4630.92 | AL27: 7384 | AM27: 4492 | AN27: =ROUND(AL27*16%,2) -> 1181.44 | AO27: =ROUND(AL27*9%,2) -> 664.56 | AP27: =ROUND(AL27*0.5%,2) -> 36.92 | AQ27: =ROUND(AL27*0.256%,2) -> 18.9 | AS27: =ROUND(AM27*7%,0) -> 314 | AT27: =ROUND(IF(AL27<24366,AL27*1.5%,24366*1.5%),2) -> 110.76 | AU27: =SUM(AN27:AT27) -> 2326.58 | AX27: =AU27+Z27+AI27-AJ27+AW27 -> 8046.82 | BA27: 255 | BB27: =ROUND(AX27+BA27+AY27,2) -> 8301.82 | BC27: =ROUND(BB27*6%,2) -> 498.11 | BD27: =ROUND(SUM(BB27:BC27),2) -> 8799.93
A28: =ROW()-2 -> 26 | B28: 2411 | C28: WB047234 | D28: 高峰 | E28: 342501197909046816 | F28: 45444 | G28: 45808 | I28: 上海 | J28: 1030 | K28: 8630 | L28: 5861.04 | P28: 200 | R28: 630 | S28: 30 | U28: 0 | V28: 2000 | X28: 0 | Y28: 0 | Z28: =SUM(J28:Y28) -> 18381.04 | AA28: 13877 | AB28: 1110.16 | AC28: 277.54 | AD28: 69.39 | AE28: 13877 | AF28: =ROUND(AE28*7%,0) -> 971 | AG28: =AB28+AC28+AD28+AF28 -> 2428.09 | AK28: =Z28-AG28-AH28 -> 15952.95 | AL28: 13877 | AM28: 13877 | AN28: =ROUND(AL28*16%,2) -> 2220.32 | AO28: 1248.94 | AP28: =ROUND(AL28*0.5%,2) -> 69.39 | AQ28: =ROUND(AL28*0.256%,2) -> 35.53 | AS28: =ROUND(AM28*7%,0) -> 971 | AT28: =ROUND(IF(AL28<24366,AL28*1.5%,24366*1.5%),2) -> 208.16 | AU28: =SUM(AN28:AT28) -> 4753.34 | AX28: =AU28+Z28+AI28-AJ28+AW28 -> 23134.38 | BA28: 255 | BB28: =ROUND(AX28+BA28+AY28,2) -> 23389.38 | BC28: =ROUND(BB28*6%,2) -> 1403.36 | BD28: =ROUND(SUM(BB28:BC28),2) -> 24792.74
A29: =ROW()-2 -> 27 | B29: 2411 | C29: WB043358 | D29: 李龙燕 | E29: 320681199310316032 | F29: 45444 | G29: 45808 | I29: 上海 | J29: 950 | K29: 8062 | L29: 4369.68 | P29: 200 | R29: 630 | S29: 0 | U29: 0 | V29: 2000 | X29: 0 | Y29: 0 | Z29: =SUM(J29:Y29) -> 16211.68 | AA29: 8878 | AB29: 710.24 | AC29: 177.56 | AD29: 44.39 | AE29: 8878 | AF29: =ROUND(AE29*7%,0) -> 621 | AG29: =AB29+AC29+AD29+AF29 -> 1553.19 | AK29: =Z29-AG29-AH29 -> 14658.49 | AL29: 8878 | AM29: 8878 | AN29: =ROUND(AL29*16%,2) -> 1420.48 | AO29: =ROUND(AL29*9%,2) -> 799.02 | AP29: =ROUND(AL29*0.5%,2) -> 44.39 | AQ29: =ROUND(AL29*0.256%,2) -> 22.73 | AS29: =ROUND(AM29*7%,0) -> 621 | AT29: =ROUND(IF(AL29<24366,AL29*1.5%,24366*1.5%),2) -> 133.17 | AU29: =SUM(AN29:AT29) -> 3040.79 | AX29: =AU29+Z29+AI29-AJ29+AW29 -> 19252.47 | BA29: 255 | BB29: =ROUND(AX29+BA29+AY29,2) -> 19507.47 | BC29: =ROUND(BB29*6%,2) -> 1170.45 | BD29: =ROUND(SUM(BB29:BC29),2) -> 20677.92
A30: =ROW()-2 -> 28 | B30: 2411 | C30: WB027701 | D30: 蒋萍萍 | E30: 310227199108114021 | F30: 45444 | G30: 45808 | I30: 上海 | J30: 950 | K30: 4886 | L30: 3454.88 | P30: 200 | R30: 630 | S30: 0 | U30: 0 | V30: 2000 | X30: 0 | Y30: 0 | Z30: =SUM(J30:Y30) -> 12120.88 | AA30: 8677 | AB30: 694.16 | AC30: 173.54 | AD30: 43.39 | AE30: 8677 | AF30: =ROUND(AE30*7%,0) -> 607 | AG30: =AB30+AC30+AD30+AF30 -> 1518.09 | AK30: =Z30-AG30-AH30 -> 10602.79 | AL30: 8677 | AM30: 8677 | AN30: =ROUND(AL30*16%,2) -> 1388.32 | AO30: 780.94 | AP30: =ROUND(AL30*0.5%,2) -> 43.39 | AQ30: =ROUND(AL30*0.256%,2) -> 22.21 | AS30: =ROUND(AM30*7%,0) -> 607 | AT30: =ROUND(IF(AL30<24366,AL30*1.5%,24366*1.5%),2) -> 130.16 | AU30: =SUM(AN30:AT30) -> 2972.02 | AX30: =AU30+Z30+AI30-AJ30+AW30 -> 15092.9 | BA30: 255 | BB30: =ROUND(AX30+BA30+AY30,2) -> 15347.9 | BC30: =ROUND(BB30*6%,2) -> 920.87 | BD30: =ROUND(SUM(BB30:BC30),2) -> 16268.77
A31: =ROW()-2 -> 29 | B31: 2411 | C31: WB041723 | D31: 封春燕 | E31: 310227198610224213 | F31: 45444 | G31: 45808 | I31: 上海 | J31: 950 | K31: 8394 | L31: 3325.68 | P31: 200 | R31: 630 | S31: 0 | U31: 0 | V31: 2000 | X31: 0 | Y31: 0 | Z31: =SUM(J31:Y31) -> 15499.68 | AA31: 7384 | AB31: 590.72 | AC31: 147.68 | AD31: 36.92 | AE31: 5109 | AF31: =ROUND(AE31*7%,0) -> 358 | AG31: =AB31+AC31+AD31+AF31 -> 1133.32 | AK31: =Z31-AG31-AH31 -> 14366.36 | AL31: 7384 | AM31: 5109 | AN31: =ROUND(AL31*16%,2) -> 1181.44 | AO31: =ROUND(AL31*9%,2) -> 664.56 | AP31: =ROUND(AL31*0.5%,2) -> 36.92 | AQ31: =ROUND(AL31*0.256%,2) -> 18.9 | AS31: =ROUND(AM31*7%,0) -> 358 | AT31: =ROUND(IF(AL31<24366,AL31*1.5%,24366*1.5%),2) -> 110.76 | AU31: =SUM(AN31:AT31) -> 2370.58 | AX31: =AU31+Z31+AI31-AJ31+AW31 -> 17870.26 | BA31: 255 | BB31: =ROUND(AX31+BA31+AY31,2) -> 18125.26 | BC31: =ROUND(BB31*6%,2) -> 1087.52 | BD31: =ROUND(SUM(BB31:BC31),2) -> 19212.78
A32: =ROW()-2 -> 30 | B32: 2411 | C32: WB051748 | D32: 姚臻敏 | E32: 310227198009300019 | F32: 45444 | G32: 45808 | I32: 上海 | J32: 800 | K32: 884.1 | L32: 602.48 | P32: 200 | R32: 630 | S32: 0 | U32: 0 | V32: 0 | X32: 1758.74 | Y32: -200 | Z32: =SUM(J32:Y32) -> 4675.32 | AA32: 7384 | AB32: 590.72 | AC32: 147.68 | AD32: 36.92 | AE32: 5432 | AF32: =ROUND(AE32*7%,0) -> 380 | AG32: =AB32+AC32+AD32+AF32 -> 1155.32 | AK32: =Z32-AG32-AH32 -> 3520 | AL32: 7384 | AM32: 5432 | AN32: =ROUND(AL32*16%,2) -> 1181.44 | AO32: =ROUND(AL32*9%,2) -> 664.56 | AP32: =ROUND(AL32*0.5%,2) -> 36.92 | AQ32: =ROUND(AL32*0.256%,2) -> 18.9 | AS32: =ROUND(AM32*7%,0) -> 380 | AT32: =ROUND(IF(AL32<24366,AL32*1.5%,24366*1.5%),2) -> 110.76 | AU32: =SUM(AN32:AT32) -> 2392.58 | AX32: =AU32+Z32+AI32-AJ32+AW32 -> 7067.9 | BA32: 255 | BB32: =ROUND(AX32+BA32+AY32,2) -> 7322.9 | BC32: =ROUND(BB32*6%,2) -> 439.37 | BD32: =ROUND(SUM(BB32:BC32),2) -> 7762.27
A33: =ROW()-2 -> 31 | B33: 2411 | C33: WB049347 | D33: 王紫怡 | E33: 331082199904274040 | F33: 45444 | G33: 45808 | I33: 上海 | J33: 900 | K33: 2839.85 | L33: 1863.96 | P33: 200 | R33: 630 | S33: 0 | U33: 742 | V33: 0 | X33: 0 | Y33: -500 | Z33: =SUM(J33:Y33) -> 6675.81 | AA33: 7606 | AB33: 608.48 | AC33: 152.12 | AD33: 38.03 | AE33: 7606 | AF33: =ROUND(AE33*7%,0) -> 532 | AG33: =AB33+AC33+AD33+AF33 -> 1330.63 | AK33: =Z33-AG33-AH33 -> 5345.18 | AL33: 7606 | AM33: 7606 | AN33: =ROUND(AL33*16%,2) -> 1216.96 | AO33: =ROUND(AL33*9%,2) -> 684.54 | AP33: =ROUND(AL33*0.5%,2) -> 38.03 | AQ33: =ROUND(AL33*0.256%,2) -> 19.47 | AS33: =ROUND(AM33*7%,0) -> 532 | AT33: =ROUND(IF(AL33<24366,AL33*1.5%,24366*1.5%),2) -> 114.09 | AU33: =SUM(AN33:AT33) -> 2605.09 | AX33: =AU33+Z33+AI33-AJ33+AW33 -> 9280.9 | BA33: 255 | BB33: =ROUND(AX33+BA33+AY33,2) -> 9535.9 | BC33: =ROUND(BB33*6%,2) -> 572.15 | BD33: =ROUND(SUM(BB33:BC33),2) -> 10108.05
A34: =ROW()-2 -> 32 | B34: 2411 | C34: WB034583 | D34: 沈婕妤 | E34: 310230198011070660 | F34: 45444 | G34: 45808 | I34: 上海 | J34: 1030 | K34: 2814 | L34: 2445.92 | P34: 200 | R34: 630 | S34: 0 | U34: 0 | V34: 1800 | X34: 0 | Y34: 0 | Z34: =SUM(J34:Y34) -> 8919.92 | AA34: 7384 | AB34: 590.72 | AC34: 147.68 | AD34: 36.92 | AE34: 5402 | AF34: =ROUND(AE34*7%,0) -> 378 | AG34: =AB34+AC34+AD34+AF34 -> 1153.32 | AK34: =Z34-AG34-AH34 -> 7766.6 | AL34: 7384 | AM34: 5402 | AN34: =ROUND(AL34*16%,2) -> 1181.44 | AO34: =ROUND(AL34*9%,2) -> 664.56 | AP34: =ROUND(AL34*0.5%,2) -> 36.92 | AQ34: =ROUND(AL34*0.256%,2) -> 18.9 | AS34: =ROUND(AM34*7%,0) -> 378 | AT34: =ROUND(IF(AL34<24366,AL34*1.5%,24366*1.5%),2) -> 110.76 | AU34: =SUM(AN34:AT34) -> 2390.58 | AX34: =AU34+Z34+AI34-AJ34+AW34 -> 11310.5 | BA34: 255 | BB34: =ROUND(AX34+BA34+AY34,2) -> 11565.5 | BC34: =ROUND(BB34*6%,2) -> 693.93 | BD34: =ROUND(SUM(BB34:BC34),2) -> 12259.43
A35: =ROW()-2 -> 33 | B35: 2411 | C35: WB026293 | D35: 曹雪晨 | E35: 310227199101043419 | F35: 45444 | G35: 45808 | I35: 上海 | J35: 1030 | K35: 8190 | L35: 4411.2 | P35: 200 | R35: 630 | S35: 0 | U35: 0 | V35: 2000 | X35: 0 | Y35: 0 | Z35: =SUM(J35:Y35) -> 16461.2 | AA35: 10751 | AB35: 860.08 | AC35: 215.02 | AD35: 53.76 | AE35: 10751 | AF35: =ROUND(AE35*7%,0) -> 753 | AG35: =AB35+AC35+AD35+AF35 -> 1881.86 | AK35: =Z35-AG35-AH35 -> 14579.34 | AL35: 10751 | AM35: 10751 | AN35: =ROUND(AL35*16%,2) -> 1720.16 | AO35: 967.6 | AP35: =ROUND(AL35*0.5%,2) -> 53.76 | AQ35: =ROUND(AL35*0.256%,2) -> 27.52 | AS35: =ROUND(AM35*7%,0) -> 753 | AT35: =ROUND(IF(AL35<24366,AL35*1.5%,24366*1.5%),2) -> 161.27 | AU35: =SUM(AN35:AT35) -> 3683.31 | AX35: =AU35+Z35+AI35-AJ35+AW35 -> 20144.51 | BA35: 255 | BB35: =ROUND(AX35+BA35+AY35,2) -> 20399.51 | BC35: =ROUND(BB35*6%,2) -> 1223.97 | BD35: =ROUND(SUM(BB35:BC35),2) -> 21623.48
A36: =ROW()-2 -> 34 | B36: 2411 | C36: WB046608 | D36: 邹莉 | E36: 511126198605207327 | F36: 45444 | G36: 45808 | I36: 上海 | J36: 1030 | K36: 2418 | L36: 2269.08 | P36: 200 | R36: 630 | S36: 0 | U36: 0 | V36: 2000 | X36: 0 | Y36: 0 | Z36: =SUM(J36:Y36) -> 8547.08 | AA36: 7384 | AB36: 590.72 | AC36: 147.68 | AD36: 36.92 | AE36: 4849 | AF36: =ROUND(AE36*7%,0) -> 339 | AG36: =AB36+AC36+AD36+AF36 -> 1114.32 | AK36: =Z36-AG36-AH36 -> 7432.76 | AL36: 7384 | AM36: 4849 | AN36: =ROUND(AL36*16%,2) -> 1181.44 | AO36: =ROUND(AL36*9%,2) -> 664.56 | AP36: =ROUND(AL36*0.5%,2) -> 36.92 | AQ36: =ROUND(AL36*0.256%,2) -> 18.9 | AS36: =ROUND(AM36*7%,0) -> 339 | AT36: =ROUND(IF(AL36<24366,AL36*1.5%,24366*1.5%),2) -> 110.76 | AU36: =SUM(AN36:AT36) -> 2351.58 | AX36: =AU36+Z36+AI36-AJ36+AW36 -> 10898.66 | BA36: 255 | BB36: =ROUND(AX36+BA36+AY36,2) -> 11153.66 | BC36: =ROUND(BB36*6%,2) -> 669.22 | BD36: =ROUND(SUM(BB36:BC36),2) -> 11822.88
A37: =ROW()-2 -> 35 | B37: 2411 | C37: WB005376 | D37: 吴萍萍 | E37: 310227198801103668 | F37: 45444 | G37: 45808 | I37: 上海 | J37: 1510 | K37: 3297.2 | L37: 3068.12 | P37: 200 | R37: 630 | S37: 0 | U37: 1113 | V37: 0 | X37: 0 | Y37: 0 | Z37: =SUM(J37:Y37) -> 9818.32 | AA37: 12662 | AB37: 1012.96 | AC37: 253.24 | AD37: 63.31 | AE37: 12662 | AF37: =ROUND(AE37*7%,0) -> 886 | AG37: =AB37+AC37+AD37+AF37 -> 2215.51 | AK37: =Z37-AG37-AH37 -> 7602.81 | AL37: 12662 | AM37: 12662 | AN37: =ROUND(AL37*16%,2) -> 2025.92 | AO37: =ROUND(AL37*9%,2) -> 1139.58 | AP37: =ROUND(AL37*0.5%,2) -> 63.31 | AQ37: =ROUND(AL37*0.256%,2) -> 32.41 | AS37: =ROUND(AM37*7%,0) -> 886 | AT37: =ROUND(IF(AL37<24366,AL37*1.5%,24366*1.5%),2) -> 189.93 | AU37: =SUM(AN37:AT37) -> 4337.15 | AX37: =AU37+Z37+AI37-AJ37+AW37 -> 14155.47 | BA37: 255 | BB37: =ROUND(AX37+BA37+AY37,2) -> 14410.47 | BC37: =ROUND(BB37*6%,2) -> 864.63 | BD37: =ROUND(SUM(BB37:BC37),2) -> 15275.1
A38: =ROW()-2 -> 36 | B38: 2411 | C38: WB030495 | D38: 马一伟 | E38: 310110198101160036 | F38: 45444 | G38: 45808 | I38: 上海 | J38: 1200 | K38: 2991.6 | L38: 2090.84 | P38: 200 | R38: 630 | S38: 0 | U38: 0 | V38: 0 | X38: 0 | Y38: 0 | Z38: =SUM(J38:Y38) -> 7112.44 | AA38: 7384 | AB38: 590.72 | AC38: 147.68 | AD38: 36.92 | AE38: 2690 | AF38: =ROUND(AE38*7%,0) -> 188 | AG38: =AB38+AC38+AD38+AF38 -> 963.32 | AK38: =Z38-AG38-AH38 -> 6149.12 | AL38: 7384 | AM38: 2690 | AN38: =ROUND(AL38*16%,2) -> 1181.44 | AO38: =ROUND(AL38*9%,2) -> 664.56 | AP38: =ROUND(AL38*0.5%,2) -> 36.92 | AQ38: =ROUND(AL38*0.256%,2) -> 18.9 | AS38: =ROUND(AM38*7%,0) -> 188 | AT38: =ROUND(IF(AL38<24366,AL38*1.5%,24366*1.5%),2) -> 110.76 | AU38: =SUM(AN38:AT38) -> 2200.58 | AX38: =AU38+Z38+AI38-AJ38+AW38 -> 9313.02 | BA38: 255 | BB38: =ROUND(AX38+BA38+AY38,2) -> 9568.02 | BC38: =ROUND(BB38*6%,2) -> 574.08 | BD38: =ROUND(SUM(BB38:BC38),2) -> 10142.1
A39: =ROW()-2 -> 37 | B39: 2411 | C39: WB058986 | D39: 庄佳秋 | E39: 310228198909040431 | F39: 45444 | G39: 45808 | I39: 上海 | J39: 800 | K39: 245.7 | L39: 199.68 | P39: 50 | R39: 630 | S39: 0 | U39: 0 | V39: 0 | X39: 2407.94 | Y39: 0 | Z39: =SUM(J39:Y39) -> 4333.32 | AA39: 7384 | AB39: 590.72 | AC39: 147.68 | AD39: 36.92 | AE39: 2690 | AF39: =ROUND(AE39*7%,0) -> 188 | AG39: =AB39+AC39+AD39+AF39 -> 963.32 | AK39: =Z39-AG39-AH39 -> 3370 | AL39: 7384 | AM39: 2690 | AN39: =ROUND(AL39*16%,2) -> 1181.44 | AO39: =ROUND(AL39*9%,2) -> 664.56 | AP39: =ROUND(AL39*0.5%,2) -> 36.92 | AQ39: =ROUND(AL39*0.256%,2) -> 18.9 | AS39: =ROUND(AM39*7%,0) -> 188 | AT39: =ROUND(IF(AL39<24366,AL39*1.5%,24366*1.5%),2) -> 110.76 | AU39: =SUM(AN39:AT39) -> 2200.58 | AX39: =AU39+Z39+AI39-AJ39+AW39 -> 6533.9 | BA39: 255 | BB39: =ROUND(AX39+BA39+AY39,2) -> 6788.9 | BC39: =ROUND(BB39*6%,2) -> 407.33 | BD39: =ROUND(SUM(BB39:BC39),2) -> 7196.23
A40: =ROW()-2 -> 38 | B40: 2411 | C40: WB038316 | D40: 王乐意 | E40: 310227199806014028 | F40: 45444 | G40: 45808 | I40: 上海 | J40: 950 | K40: 1895.8 | L40: 863.6 | P40: 200 | R40: 630 | S40: 0 | U40: 0 | V40: 0 | X40: 113.92 | Y40: 0 | Z40: =SUM(J40:Y40) -> 4653.32 | AA40: 7384 | AB40: 590.72 | AC40: 147.68 | AD40: 36.92 | AE40: 5121 | AF40: =ROUND(AE40*7%,0) -> 358 | AG40: =AB40+AC40+AD40+AF40 -> 1133.32 | AK40: =Z40-AG40-AH40 -> 3520 | AL40: 7384 | AM40: 5121 | AN40: =ROUND(AL40*16%,2) -> 1181.44 | AO40: =ROUND(AL40*9%,2) -> 664.56 | AP40: =ROUND(AL40*0.5%,2) -> 36.92 | AQ40: =ROUND(AL40*0.256%,2) -> 18.9 | AS40: =ROUND(AM40*7%,0) -> 358 | AT40: =ROUND(IF(AL40<24366,AL40*1.5%,24366*1.5%),2) -> 110.76 | AU40: =SUM(AN40:AT40) -> 2370.58 | AX40: =AU40+Z40+AI40-AJ40+AW40 -> 7023.9 | BA40: 255 | BB40: =ROUND(AX40+BA40+AY40,2) -> 7278.9 | BC40: =ROUND(BB40*6%,2) -> 436.73 | BD40: =ROUND(SUM(BB40:BC40),2) -> 7715.63
...

Sheet 对账单
A1: 科目 | B1: 手工账单 | C1: 7月速创账单 | D1: 155 | E1: 系统已有金额（不做一次性） | F1: 7月少收，8月补 | G1: 8月少收，9月补 | H1: 合计 | I1: 差异
A2: 管理费 | B2: ='202411'!BC50 -> 27378.97 | C2: =系统!E60 -> 31188.31 | D2: =42*155+0.06 -> 6510.06 | H2: =SUM(C2:G2) -> 37698.37 | I2: =B2-C2 -> -3809.34
A3: 风险费 | B3: ='202411'!BA50 -> 10710 | C3: 0 | H3: =SUM(C3:G3) -> 0 | I3: =B3-C3 -> 10710
A4: 个人四金 | B4: ='202411'!AG50 -> 52766.03 | C4: =系统!V60 -> 52766.03 | H4: =SUM(C4:G4) -> 52766.03 | I4: =B4-C4 -> 0
A5: 公司四金 | B5: ='202411'!AU50 -> 108761.39 | C5: =系统!O60 -> 108761.39 | H5: =SUM(C5:E5) -> 108761.39 | I5: =B5-C5 -> 0
A6: 残保金 | H6: =SUM(C6:G6) -> 0 | I6: =B6-C6 -> 0
A7: 代发工资 | B7: ='202411'!AK50 -> 284079.32 | C7: =系统!W60 -> 284079.32 | H7: =SUM(C7:G7) -> 284079.32 | I7: =B7-C7 -> 0
A8: 上月垫付 | H8: =SUM(C8:G8) -> 0 | I8: =B8-C8 -> 0
A9: 报销 | H9: =SUM(C9:G9) -> 0 | I9: =B9-C9 -> 0
A10: 预收（做预收一次性） | H10: =SUM(C10:G10) -> 0 | I10: =B10-C10 -> 0
A11: 小计 | B11: =SUM(B2:B10) -> 483695.71 | C11: =SUM(C2:C10) -> 476795.05 | D11: =SUM(D2:D10) -> 6510.06 | E11: =SUM(E2:E10) -> 0 | F11: =SUM(F2:F10) -> 0 | G11: =SUM(G2:G10) -> 0 | H11: =SUM(C11:G11) -> 483305.11
A12: 附加税 | D12: 0
A13: 增值税 | D13: =ROUND((D10+D11)*6%,2) -> 390.6 | E13: =ROUND((E11+E12)*6%,2) -> 0 | F13: =ROUND((F11+F12)*6%,2) -> 0 | G13: =ROUND((G11+G12)*6%,2) -> 0 | H13: =SUM(C13:G13) -> 390.6
A14: 总计 | B14: =SUM(B11:B13) -> 483695.71 | C14: =SUM(C11:C13) -> 476795.05 | D14: =SUM(D11:D11:D13) -> 6900.66 | E14: =SUM(E11:E13) -> 0 | F14: =SUM(F11:F13) -> 0 | G14: =SUM(G11:G13) -> 0 | H14: =SUM(C14:G14) -> 483695.71
A15: 给客户账单金额 | H15: =B14 -> 483695.71
A16: 差异 | H16: =H15-H14 -> 0
A17: 不含税差异 | H17: =ROUND(H16/1.06,2) -> 0

Sheet 系统
A1: 200070
A2: 寄：梅园路77号人才大厦
B3: 中国电信股份有限公司上海分公司 王慧珏 收
D6: 上海外服布列吉科技有限公司
C7: Shanghai Foreign Service Bridge Technology Co,Ltd.
E9: 收款通知书
E10: ADVISE ON COLLECTION
E11: 2024年11月
A13: 公司名称：中国电信股份有限公司上海分公司 | J13: 帐单号：202411CH6565010
A14: 序号 | B14: 姓名 | C14: 发生年月 | D14: 入职日期 | E14: 管理费 | F14: 当月社保基数 | G14: 当月公积金基数 | H14: 社保类 公司支付 Social Insurance Premiums Paid by Employer | N14: 公积金类 公司支付 Provident Fund Paid by Employer | O14: 公司合计 | P14: 社保类 个人支付 Social Insurance Premiums Paid by Employee | U14: 公积金类 个人支付 Provident Fund Paid by Employee | V14: 个人合计 | W14: 代办薪酬 | X14: 其他 | Y14: 总计 | Z14: 备注 | AA14: 外服工号 | AB14: 证件号码 | AC14: 内部工号 | AD14: 应纳税金额 | AE14: 税率 | AF14: 增值税
A15: S/N | B15: Name | C15: YYYYMM | D15: Employment Start Date | E15: Adm Fee | F15: Social Insurance Base Amount of Current Month | G15: Provident Fund Base Amount of Current Month | H15: 养老保险 Endowment | I15: 医疗保险 Medical | J15: 失业保险 Unemploy-ment | K15: 工伤保险 Employment Injury | L15: 医疗生育保险 Medical Maternity | M15: 保障金 Disabled people&Back pay Fund | N15: 公积金 Provident Fund | O15: Subtotal of Employer Payment | P15: 养老保险 Endowment | Q15: 医疗保险 Medical | R15: 失业保险 Unemploy-ment | S15: 工伤保险 Employment Injury | T15: 医疗生育保险 Medical Maternity | U15: 公积金 Provident Fund | V15: Subtotal of Personal Payment | W15: Agency of Wage Payment | X15: Others | Y15: Total | Z15: Remarks | AA15: SFSC ID | AB15: ID Card | AC15: Internal ID | AD15: Taxable Amount | AE15: Tax Rate | AF15: VAT
A16: 1 | B16: 曹克洋 | C16: 202411 | D16: 2024-06-01 | E16: 651.66 | F16: 7384 | G16: 5351 | H16: 1181.44 | I16: 664.56 | J16: 36.92 | K16: 18.9 | M16: 110.76 | N16: 375 | O16: =SUM(H16:N16) -> 2387.58 | P16: 590.72 | Q16: 147.68 | R16: 36.92 | U16: 375 | V16: =SUM(P16:U16) -> 1150.32 | W16: 5556.56 | Y16: =SUM(E16,O16,V16:X16) -> 9746.12 | AA16: 5545179 | AB16: 341226199712081318 | AD16: 9194.45 | AE16: 6% | AF16: 551.67
A17: 2 | B17: 曹雪晨 | C17: 202411 | D17: 2024-06-01 | E17: 1314.67 | F17: 10751 | G17: 10751 | H17: 1720.16 | I17: 967.6 | J17: 53.76 | K17: 27.52 | M17: 161.27 | N17: 753 | O17: =SUM(H17:N17) -> 3683.31 | P17: 860.08 | Q17: 215.02 | R17: 53.76 | U17: 753 | V17: =SUM(P17:U17) -> 1881.86 | W17: 14579.34 | Y17: =SUM(E17,O17,V17:X17) -> 21459.18 | AA17: 5573404 | AB17: 310227199101043419 | AD17: 20244.5 | AE17: 6% | AF17: 1214.68
A18: 3 | B18: 常宇航 | C18: 202411 | D18: 2024-06-01 | E18: 665.64 | F18: 7384 | G18: 6644 | H18: 1181.44 | I18: 664.56 | J18: 36.92 | K18: 18.9 | M18: 110.76 | N18: 465 | O18: =SUM(H18:N18) -> 2477.58 | P18: 590.72 | Q18: 147.68 | R18: 36.92 | U18: 465 | V18: =SUM(P18:U18) -> 1240.32 | W18: 5609.5 | Y18: =SUM(E18,O18,V18:X18) -> 9993.04 | AA18: 5545178 | AB18: 340321199609230533 | AD18: 9427.39 | AE18: 6% | AF18: 565.65
A19: 4 | B19: 陈喆昕 | C19: 202411 | D19: 2024-07-01 | E19: 857.16 | F19: 7384 | G19: 2690 | H19: 1181.44 | I19: 664.56 | J19: 36.92 | K19: 18.9 | M19: 110.76 | N19: 188 | O19: =SUM(H19:N19) -> 2200.58 | P19: 590.72 | Q19: 147.68 | R19: 36.92 | U19: 188 | V19: =SUM(P19:U19) -> 963.32 | W19: 9355.48 | Y19: =SUM(E19,O19,V19:X19) -> 13376.54 | AA19: 6063573 | AB19: 310227198312160012 | AD19: 12619.37 | AE19: 6% | AF19: 757.17
A20: 5 | B20: 陈秀丽 | C20: 202411 | D20: 2024-06-01 | E20: 106 | O20: =SUM(H20:N20) -> 0 | V20: =SUM(P20:U20) -> 0 | Y20: =SUM(E20,O20,V20:X20) -> 106 | AA20: 5573399 | AB20: 310227199303073421 | AD20: 100 | AE20: 6% | AF20: 6
A21: 6 | B21: 戴连荣 | C21: 202411 | D21: 2024-06-01 | E21: 1041.07 | F21: 12760 | G21: 12760 | H21: 2041.6 | I21: 1148.4 | J21: 63.8 | K21: 32.67 | M21: 191.4 | N21: 893 | O21: =SUM(H21:N21) -> 4370.87 | P21: 1020.8 | Q21: 255.2 | R21: 63.8 | U21: 893 | V21: =SUM(P21:U21) -> 2232.8 | W21: 8980.88 | Y21: =SUM(E21,O21,V21:X21) -> 16625.62 | AA21: 5517492 | AB21: 310227198411292010 | AD21: 15684.55 | AE21: 6% | AF21: 941.07
A22: 7 | B22: 范智超 | C22: 202411 | D22: 2024-06-01 | E22: 75.48 | O22: =SUM(H22:N22) -> 0 | V22: =SUM(P22:U22) -> 0 | W22: 1258 | Y22: =SUM(E22,O22,V22:X22) -> 1333.48 | AA22: 5862529 | AB22: 342623199908103631 | AD22: 1258 | AE22: 6% | AF22: 75.48
A23: 8 | B23: 封春燕 | C23: 202411 | D23: 2024-06-01 | E23: 1178.21 | F23: 7384 | G23: 5109 | H23: 1181.44 | I23: 664.56 | J23: 36.92 | K23: 18.9 | M23: 110.76 | N23: 358 | O23: =SUM(H23:N23) -> 2370.58 | P23: 590.72 | Q23: 147.68 | R23: 36.92 | U23: 358 | V23: =SUM(P23:U23) -> 1133.32 | W23: 14366.36 | Y23: =SUM(E23,O23,V23:X23) -> 19048.47 | AA23: 5573397 | AB23: 310227198610224213 | AD23: 17970.25 | AE23: 6% | AF23: 1078.22
A24: 9 | B24: 高峰 | C24: 202411 | D24: 2024-06-01 | E24: 1494.07 | F24: 13877 | G24: 13877 | H24: 2220.32 | I24: 1248.94 | J24: 69.39 | K24: 35.53 | M24: 208.16 | N24: 971 | O24: =SUM(H24:N24) -> 4753.34 | P24: 1110.16 | Q24: 277.54 | R24: 69.39 | U24: 971 | V24: =SUM(P24:U24) -> 2428.09 | W24: 15952.95 | Y24: =SUM(E24,O24,V24:X24) -> 24628.45 | AA24: 5573394 | AB24: 342501197909046816 | AD24: 23234.39 | AE24: 6% | AF24: 1394.06
A25: 10 | B25: 高国强 | C25: 202411 | D25: 2024-06-01 | E25: 525.51 | F25: 7384 | G25: 4880 | H25: 1181.44 | I25: 664.56 | J25: 36.92 | K25: 18.9 | M25: 110.76 | N25: 342 | O25: =SUM(H25:N25) -> 2354.58 | P25: 590.72 | Q25: 147.68 | R25: 36.92 | U25: 342 | V25: =SUM(P25:U25) -> 1117.32 | W25: 3520 | Y25: =SUM(E25,O25,V25:X25) -> 7517.41 | AA25: 5573388 | AB25: 65010319750517061X | AD25: 7091.89 | AE25: 6% | AF25: 425.52
A26: 11 | B26: 顾诗瑶 | C26: 202411 | D26: 2024-06-01 | E26: 440.79 | F26: 7384 | G26: 4570 | H26: 1181.44 | I26: 664.56 | J26: 36.92 | K26: 18.9 | M26: 110.76 | N26: 320 | O26: =SUM(H26:N26) -> 2332.58 | P26: 590.72 | Q26: 147.68 | R26: 36.92 | U26: 320 | V26: =SUM(P26:U26) -> 1095.32 | W26: 2152 | Y26: =SUM(E26,O26,V26:X26) -> 6020.69 | AA26: 5517495 | AB26: 310227199812152021 | AD26: 5679.89 | AE26: 6% | AF26: 340.8
A27: 12 | B27: 何军利 | C27: 202411 | D27: 2024-06-01 | E27: 542.73 | F27: 7384 | G27: 4289 | H27: 1181.44 | I27: 664.56 | J27: 36.92 | K27: 18.9 | M27: 110.76 | N27: 300 | O27: =SUM(H27:N27) -> 2312.58 | P27: 590.72 | Q27: 147.68 | R27: 36.92 | U27: 300 | V27: =SUM(P27:U27) -> 1075.32 | W27: 3891 | Y27: =SUM(E27,O27,V27:X27) -> 7821.63 | AA27: 5545181 | AB27: 310227197512314245 | AD27: 7378.89 | AE27: 6% | AF27: 442.74
A28: 13 | B28: 姜金玲 | C28: 202411 | D28: 2024-06-01 | E28: 566.55 | F28: 7384 | G28: 4467 | H28: 1181.44 | I28: 664.56 | J28: 36.92 | K28: 18.9 | M28: 110.76 | N28: 313 | O28: =SUM(H28:N28) -> 2325.58 | P28: 590.72 | Q28: 147.68 | R28: 36.92 | U28: 313 | V28: =SUM(P28:U28) -> 1088.32 | W28: 4262 | Y28: =SUM(E28,O28,V28:X28) -> 8242.45 | AA28: 5573391 | AB28: 310227198902274028 | AD28: 7775.89 | AE28: 6% | AF28: 466.56
A29: 14 | B29: 蒋萍萍 | C29: 202411 | D29: 2024-06-01 | E29: 1011.58 | F29: 8677 | G29: 8677 | H29: 1388.32 | I29: 780.94 | J29: 43.39 | K29: 22.21 | M29: 130.16 | N29: 607 | O29: =SUM(H29:N29) -> 2972.02 | P29: 694.16 | Q29: 173.54 | R29: 43.39 | U29: 607 | V29: =SUM(P29:U29) -> 1518.09 | W29: 10602.79 | Y29: =SUM(E29,O29,V29:X29) -> 16104.48 | AA29: 5573396 | AB29: 310227199108114021 | AD29: 15192.91 | AE29: 6% | AF29: 911.57
A30: 15 | B30: 孔祥杰 | C30: 202411 | D30: 2024-06-01 | E30: 703.73 | F30: 7384 | G30: 7189 | H30: 1181.44 | I30: 664.56 | J30: 36.92 | K30: 18.9 | M30: 110.76 | N30: 503 | O30: =SUM(H30:N30) -> 2515.58 | P30: 590.72 | Q30: 147.68 | R30: 36.92 | U30: 503 | V30: =SUM(P30:U30) -> 1278.32 | W30: 6168.36 | Y30: =SUM(E30,O30,V30:X30) -> 10665.99 | AA30: 5545173 | AB30: 310110198408153236 | AD30: 10062.25 | AE30: 6% | AF30: 603.74
A31: 16 | B31: 李龙燕 | C31: 202411 | D31: 2024-06-01 | E31: 1261.15 | F31: 8878 | G31: 8878 | H31: 1420.48 | I31: 799.02 | J31: 44.39 | K31: 22.73 | M31: 133.17 | N31: 621 | O31: =SUM(H31:N31) -> 3040.79 | P31: 710.24 | Q31: 177.56 | R31: 44.39 | U31: 621 | V31: =SUM(P31:U31) -> 1553.19 | W31: 14658.49 | Y31: =SUM(E31,O31,V31:X31) -> 20513.62 | AA31: 5573395 | AB31: 320681199310316032 | AD31: 19352.49 | AE31: 6% | AF31: 1161.13
A32: 17 | B32: 李秋梅 | C32: 202411 | D32: 2024-06-01 | E32: 578.14 | F32: 7384 | G32: 7034 | H32: 1181.44 | I32: 664.56 | J32: 36.92 | K32: 18.9 | M32: 110.76 | N32: 492 | O32: =SUM(H32:N32) -> 2504.58 | P32: 590.72 | Q32: 147.68 | R32: 36.92 | U32: 492 | V32: =SUM(P32:U32) -> 1267.32 | W32: 4097.24 | Y32: =SUM(E32,O32,V32:X32) -> 8447.28 | AA32: 5573387 | AB32: 320321198010030887 | AD32: 7969.13 | AE32: 6% | AF32: 478.15
A33: 18 | B33: 陆丽伟 | C33: 202411 | D33: 2024-05-01 | E33: 555.72 | F33: 7384 | G33: 2690 | H33: 1181.44 | I33: 664.56 | J33: 36.92 | K33: 18.9 | M33: 110.76 | N33: 188 | O33: =SUM(H33:N33) -> 2200.58 | P33: 590.72 | Q33: 147.68 | R33: 36.92 | U33: 188 | V33: =SUM(P33:U33) -> 963.32 | W33: 4331.48 | Y33: =SUM(E33,O33,V33:X33) -> 8051.1 | AA33: 6010738 | AB33: 310227198802293619 | AD33: 7595.37 | AE33: 6% | AF33: 455.73
A34: 19 | B34: 陆晓岚 | C34: 202411 | D34: 2024-06-01 | E34: 519.99 | F34: 7384 | G34: 5300 | H34: 1181.44 | I34: 664.56 | J34: 36.92 | K34: 18.9 | M34: 110.76 | N34: 371 | O34: =SUM(H34:N34) -> 2383.58 | P34: 590.72 | Q34: 147.68 | R34: 36.92 | U34: 371 | V34: =SUM(P34:U34) -> 1146.32 | W34: 3370 | Y34: =SUM(E34,O34,V34:X34) -> 7419.89 | AA34: 1881345 | AB34: 310227199207211222 | AD34: 6999.89 | AE34: 6% | AF34: 420
A35: 20 | B35: 陆智俊 | C35: 202411 | D35: 2024-06-01 | E35: 681.7 | F35: 7556 | G35: 7556 | H35: 1208.96 | I35: 680.04 | J35: 37.78 | K35: 19.34 | M35: 113.34 | N35: 529 | O35: =SUM(H35:N35) -> 2588.46 | P35: 604.48 | Q35: 151.12 | R35: 37.78 | U35: 529 | V35: =SUM(P35:U35) -> 1322.38 | W35: 5684.22 | Y35: =SUM(E35,O35,V35:X35) -> 10276.76 | AA35: 5545180 | AB35: 310227199807124616 | AD35: 9695.05 | AE35: 6% | AF35: 581.71
A36: 21 | B36: 马力 | C36: 202411 | D36: 2024-06-01 | E36: 17.48 | O36: =SUM(H36:N36) -> 0 | V36: =SUM(P36:U36) -> 0 | W36: 291.3 | Y36: =SUM(E36,O36,V36:X36) -> 308.78 | AA36: 5573406 | AB36: 310227198108270433 | AD36: 291.3 | AE36: 6% | AF36: 17.48
A37: 22 | B37: 马一伟 | C37: 202411 | D37: 2024-06-01 | E37: 664.78 | F37: 7384 | G37: 2690 | H37: 1181.44 | I37: 664.56 | J37: 36.92 | K37: 18.9 | M37: 110.76 | N37: 188 | O37: =SUM(H37:N37) -> 2200.58 | P37: 590.72 | Q37: 147.68 | R37: 36.92 | U37: 188 | V37: =SUM(P37:U37) -> 963.32 | W37: 6149.12 | Y37: =SUM(E37,O37,V37:X37) -> 9977.8 | AA37: 5862530 | AB37: 310110198101160036 | AD37: 9413.01 | AE37: 6% | AF37: 564.79
A38: 23 | B38: 牟金丽 | C38: 202411 | D38: 2024-06-01 | E38: 588.81 | F38: 7384 | G38: 4492 | H38: 1181.44 | I38: 664.56 | J38: 36.92 | K38: 18.9 | M38: 110.76 | N38: 314 | O38: =SUM(H38:N38) -> 2326.58 | P38: 590.72 | Q38: 147.68 | R38: 36.92 | U38: 314 | V38: =SUM(P38:U38) -> 1089.32 | W38: 4630.92 | Y38: =SUM(E38,O38,V38:X38) -> 8635.63 | AA38: 5573393 | AB38: 422802198502180068 | AD38: 8146.81 | AE38: 6% | AF38: 488.82
A39: 24 | B39: 倪跃新 | C39: 202411 | D39: 2024-06-01 | E39: 567.41 | F39: 7384 | G39: 6353 | H39: 1181.44 | I39: 664.56 | J39: 36.92 | K39: 18.9 | M39: 110.76 | N39: 445 | O39: =SUM(H39:N39) -> 2457.58 | P39: 590.72 | Q39: 147.68 | R39: 36.92 | U39: 445 | V39: =SUM(P39:U39) -> 1220.32 | W39: 4012.32 | Y39: =SUM(E39,O39,V39:X39) -> 8257.63 | AA39: 5573386 | AB39: 310229197208182017 | AD39: 7790.21 | AE39: 6% | AF39: 467.42
A40: 25 | B40: 潘奇伟 | C40: 202411 | D40: 2024-07-01 | E40: 784.27 | F40: 7384 | G40: 2690 | H40: 1181.44 | I40: 664.56 | J40: 36.92 | K40: 18.9 | M40: 110.76 | N40: 188 | O40: =SUM(H40:N40) -> 2200.58 | P40: 590.72 | Q40: 147.68 | R40: 36.92 | U40: 188 | V40: =SUM(P40:U40) -> 963.32 | W40: 8140.6 | Y40: =SUM(E40,O40,V40:X40) -> 12088.77 | AA40: 6063572 | AB40: 310227199011142819 | AD40: 11404.49 | AE40: 6% | AF40: 684.28
A41: 26 | B41: 任清丽 | C41: 202411 | D41: 2024-06-01 | E41: 723.85 | F41: 7384 | G41: 6878 | H41: 1181.44 | I41: 664.56 | J41: 36.92 | K41: 18.9 | M41: 110.76 | N41: 481 | O41: =SUM(H41:N41) -> 2493.58 | P41: 590.72 | Q41: 147.68 | R41: 36.92 | U41: 481 | V41: =SUM(P41:U41) -> 1256.32 | W41: 6547.64 | Y41: =SUM(E41,O41,V41:X41) -> 11021.39 | AA41: 5517493 | AB41: 341223198806062763 | AD41: 10397.53 | AE41: 6% | AF41: 623.86
A42: 27 | B42: 沈婕妤 | C42: 202411 | D42: 2024-06-01 | E42: 784.63 | F42: 7384 | G42: 5402 | H42: 1181.44 | I42: 664.56 | J42: 36.92 | K42: 18.9 | M42: 110.76 | N42: 378 | O42: =SUM(H42:N42) -> 2390.58 | P42: 590.72 | Q42: 147.68 | R42: 36.92 | U42: 378 | V42: =SUM(P42:U42) -> 1153.32 | W42: 7766.6 | Y42: =SUM(E42,O42,V42:X42) -> 12095.13 | AA42: 5573403 | AB42: 310230198011070660 | AD42: 11410.49 | AE42: 6% | AF42: 684.64
A43: 28 | B43: 施梅 | C43: 202411 | D43: 2024-05-01 | E43: 551.55 | F43: 7384 | G43: 2690 | H43: 1181.44 | I43: 664.56 | J43: 36.92 | K43: 18.9 | M43: 110.76 | N43: 188 | O43: =SUM(H43:N43) -> 2200.58 | P43: 590.72 | Q43: 147.68 | R43: 36.92 | U43: 188 | V43: =SUM(P43:U43) -> 963.32 | W43: 4262 | Y43: =SUM(E43,O43,V43:X43) -> 7977.45 | AA43: 3277855 | AB43: 310227198805293665 | AD43: 7525.89 | AE43: 6% | AF43: 451.56
A44: 29 | B44: 谭晓刚 | C44: 202411 | D44: 2024-05-01 | E44: 744.37 | F44: 7384 | G44: 2690 | H44: 1181.44 | I44: 664.56 | J44: 36.92 | K44: 18.9 | M44: 110.76 | N44: 188 | O44: =SUM(H44:N44) -> 2200.58 | P44: 590.72 | Q44: 147.68 | R44: 36.92 | U44: 188 | V44: =SUM(P44:U44) -> 963.32 | W44: 7475.6 | Y44: =SUM(E44,O44,V44:X44) -> 11383.87 | AA44: 6010737 | AB44: 310227197503241611 | AD44: 10739.49 | AE44: 6% | AF44: 644.38
...
