Workbook

Sheet 202410
A1: 序号 | B1: 计薪 周期 | C1: 工号 | D1: 姓名 | E1: 身份证号 | F1: 劳动合同起始日期 | G1: 劳动合同结束日期 | H1: 离职日期 | I1: 社保缴纳地 | J1: 星级费用 | K1: 考核费用 | L1: OKR费用 | M1: 量化费用 | N1: 专项费用 | AA1: 当月税前工资合计 | AB1: 社保基数(个人) | AC1: 养老保险(个人) | AD1: 医疗保险(个人) | AE1: 失业保险(个人) | AF1: 公积金基数(个人) | AG1: 住房公积金(个人) | AH1: 员工五险一金合计 | AI1: 本月个人所得税-系统导出 | AJ1: 税后增加 | AK1: 税后扣减 | AL1: 员工实发合计 | AM1: 社保基数 | AN1: 公积金基数 | AO1: 养老缴费 | AP1: 医疗缴费 | AQ1: 失业保险 | AR1: 工伤保险 | AS1: 生育保险 | AT1: 公积金 | AU1: 残保金 | AV1: 企业五险一金合计 | AW1: 工会费 | AX1: 代收付合计 | AZ1: 上月垫付 | BA1: 社保备注 | BB1: 外包服务费 | BC1: 税前项合计 | BD1: 增值税 | BE1: 总计
A2: NO. | B2: Salary Cycle | C2: Employee No. | D2: Name | E2: ID No. | F2: Contract Starting Date | G2: Contract Expiry Date | H2: Exit Date | I2: Social Insurance City | J2: Contract Salary | K2: Assessment fees | M2: Quantifying costs | N2: 支局专项 | O2: 1+1激励 | P2: 体检费 | Q2: 通信费 | R2: 高温费及清凉饮料费 （6-9月） | S2: 伙食补贴 | T2: 独生子女奖励 | U2: 保险费 | V2: 其他费用 | W2: 补发费用 | X2: 劳防用品 | Y2: 保障补差 | Z2: 其他扣款 | AA2: Pre-tax Total | AB2: Social Insurance Base | AC2: Pension Employee | AD2: Medical Employee | AE2: Umemployment Employee | AF2: Housing Fund Base | AG2: Housing Fund Employee | AH2: Total Amount of Social Insurance(EE) | AI2: Personal Income Tax | AJ2: Increase After-tax payment | AK2: Reduction After-tax payment | AL2: After-tax total Income | AM2: Social Insurance Base | AN2: Housing Fund Base | AO2: Pension Employer | AP2: Medical Employer | AQ2: Umemployment Employer | AR2: Injury Employer | AS2: Maternity Insurance Employer | AT2: Housing Fund Employer | AU2: Disabled people&Back pay Fund | AV2: Total Amount of Social Insurance(ER) | AW2: Union Fee | AX2: Payment Total | BA2: Social Security remark | BB2: Service Fee | BC2: Total | BD2: VAT | BE2: Subtotal
A3: =ROW()-2 -> 1 | B3: 2410 | C3: WB016994 | D3: 王邹强 | E3: 310108198909220554 | F3: 45444 | G3: 45808 | I3: 上海 | J3: 1300 | K3: 4964 | L3: 1480 | M3: 784.68 | N3: 0 | O3: 0 | P3: 0 | Q3: 0 | R3: 0 | S3: 630 | T3: 0 | U3: 0 | V3: 0 | W3: 0 | X3: 0 | Y3: 0 | Z3: 0 | AA3: =SUM(J3:Z3) -> 9158.68 | AB3: 8707 | AC3: 696.56 | AD3: 174.14 | AE3: 43.54 | AF3: 8707 | AG3: =ROUND(AF3*7%,0) -> 609 | AH3: =AC3+AD3+AE3+AG3 -> 1523.24 | AL3: =AA3-AH3-AI3 -> 7635.44 | AM3: 8707 | AN3: 8707 | AO3: =ROUND(AM3*16%,2) -> 1393.12 | AP3: 783.64 | AQ3: =ROUND(AM3*0.5%,2) -> 43.54 | AR3: =ROUND(AM3*0.256%,2) -> 22.29 | AT3: =ROUND(AN3*7%,0) -> 609 | AU3: =ROUND(IF(AM3<24366,AM3*1.5%,24366*1.5%),2) -> 130.61 | AV3: =SUM(AO3:AU3) -> 2982.2 | AX3: =AV3+AA3+AJ3-AK3+AW3 -> 12140.88 | BB3: 255 | BC3: =ROUND(AX3+BB3+AZ3,2) -> 12395.88 | BD3: =ROUND(BC3*6%,2) -> 743.75 | BE3: =ROUND(SUM(BC3:BD3),2) -> 13139.63
A4: =ROW()-2 -> 2 | B4: 2410 | C4: WB022665 | D4: 熊伟 | E4: 310109198905074533 | F4: 45444 | G4: 45808 | I4: 上海 | J4: 1030 | K4: 1184.4 | L4: 0 | M4: 730.38 | N4: 0 | O4: 0 | P4: 0 | Q4: 0 | R4: 0 | S4: 630 | T4: 0 | U4: 0 | V4: 0 | W4: 0 | X4: 0 | Y4: 1300.46 | Z4: 0 | AA4: =SUM(J4:Z4) -> 4875.24 | AB4: 8888 | AC4: 711.04 | AD4: 177.76 | AE4: 44.44 | AF4: 8888 | AG4: =ROUND(AF4*7%,0) -> 622 | AH4: =AC4+AD4+AE4+AG4 -> 1555.24 | AL4: =AA4-AH4-AI4 -> 3320 | AM4: 8888 | AN4: 8888 | AO4: =ROUND(AM4*16%,2) -> 1422.08 | AP4: =ROUND(AM4*9%,2) -> 799.92 | AQ4: =ROUND(AM4*0.5%,2) -> 44.44 | AR4: =ROUND(AM4*0.256%,2) -> 22.75 | AT4: =ROUND(AN4*7%,0) -> 622 | AU4: =ROUND(IF(AM4<24366,AM4*1.5%,24366*1.5%),2) -> 133.32 | AV4: =SUM(AO4:AU4) -> 3044.51 | AX4: =AV4+AA4+AJ4-AK4+AW4 -> 7919.75 | BB4: 255 | BC4: =ROUND(AX4+BB4+AZ4,2) -> 8174.75 | BD4: =ROUND(BC4*6%,2) -> 490.49 | BE4: =ROUND(SUM(BC4:BD4),2) -> 8665.24
A5: =ROW()-2 -> 3 | B5: 2410 | C5: WB016995 | D5: 杭亮 | E5: 310110198004027057 | F5: 45444 | G5: 45808 | I5: 上海 | J5: 1030 | K5: 3474.8 | L5: 720 | M5: 1279.14 | N5: 0 | O5: 0 | P5: 0 | Q5: 0 | R5: 0 | S5: 630 | T5: 0 | U5: 0 | V5: 0 | W5: 0 | X5: 0 | Y5: 0 | Z5: 0 | AA5: =SUM(J5:Z5) -> 7133.94 | AB5: 9226 | AC5: 738.08 | AD5: 184.52 | AE5: 46.13 | AF5: 9226 | AG5: =ROUND(AF5*7%,0) -> 646 | AH5: =AC5+AD5+AE5+AG5 -> 1614.73 | AL5: =AA5-AH5-AI5 -> 5519.21 | AM5: 9226 | AN5: 9226 | AO5: =ROUND(AM5*16%,2) -> 1476.16 | AP5: =ROUND(AM5*9%,2) -> 830.34 | AQ5: =ROUND(AM5*0.5%,2) -> 46.13 | AR5: =ROUND(AM5*0.256%,2) -> 23.62 | AT5: =ROUND(AN5*7%,0) -> 646 | AU5: =ROUND(IF(AM5<24366,AM5*1.5%,24366*1.5%),2) -> 138.39 | AV5: =SUM(AO5:AU5) -> 3160.64 | AX5: =AV5+AA5+AJ5-AK5+AW5 -> 10294.58 | BB5: 255 | BC5: =ROUND(AX5+BB5+AZ5,2) -> 10549.58 | BD5: =ROUND(BC5*6%,2) -> 632.97 | BE5: =ROUND(SUM(BC5:BD5),2) -> 11182.55
A6: =ROW()-2 -> 4 | B6: 2410 | C6: WB007082 | D6: 朱春红 | E6: 310230197703304160 | F6: 45444 | G6: 45808 | I6: 上海 | J6: 1030 | K6: 3432 | L6: 1080 | M6: 1908.18 | N6: 0 | O6: 0 | P6: 0 | Q6: 0 | R6: 0 | S6: 630 | T6: 0 | U6: 0 | V6: 0 | W6: 0 | X6: 0 | Y6: 0 | Z6: 0 | AA6: =SUM(J6:Z6) -> 8080.18 | AB6: 10979 | AC6: 878.32 | AD6: 219.58 | AE6: 54.9 | AF6: 10979 | AG6: =ROUND(AF6*7%,0) -> 769 | AH6: =AC6+AD6+AE6+AG6 -> 1921.8 | AL6: =AA6-AH6-AI6 -> 6158.38 | AM6: 10979 | AN6: 10979 | AO6: =ROUND(AM6*16%,2) -> 1756.64 | AP6: 988.12 | AQ6: =ROUND(AM6*0.5%,2) -> 54.9 | AR6: =ROUND(AM6*0.256%,2) -> 28.11 | AT6: =ROUND(AN6*7%,0) -> 769 | AU6: =ROUND(IF(AM6<24366,AM6*1.5%,24366*1.5%),2) -> 164.69 | AV6: =SUM(AO6:AU6) -> 3761.46 | AX6: =AV6+AA6+AJ6-AK6+AW6 -> 11841.64 | BB6: 255 | BC6: =ROUND(AX6+BB6+AZ6,2) -> 12096.64 | BD6: =ROUND(BC6*6%,2) -> 725.8 | BE6: =ROUND(SUM(BC6:BD6),2) -> 12822.44
A7: =ROW()-2 -> 5 | B7: 2410 | C7: WB017012 | D7: 王一峰 | E7: 310230198106182913 | F7: 45444 | G7: 45808 | I7: 上海 | J7: 1030 | K7: 3432 | L7: 0 | M7: 3417.9 | N7: 0 | O7: 0 | P7: 0 | Q7: 0 | R7: 0 | S7: 630 | T7: 0 | U7: 0 | V7: 0 | W7: 0 | X7: 0 | Y7: 0 | Z7: 0 | AA7: =SUM(J7:Z7) -> 8509.9 | AB7: 16443 | AC7: 1315.44 | AD7: 328.86 | AE7: 82.22 | AF7: 16443 | AG7: =ROUND(AF7*7%,0) -> 1151 | AH7: =AC7+AD7+AE7+AG7 -> 2877.52 | AL7: =AA7-AH7-AI7 -> 5632.38 | AM7: 16443 | AN7: 16443 | AO7: =ROUND(AM7*16%,2) -> 2630.88 | AP7: 1479.88 | AQ7: =ROUND(AM7*0.5%,2) -> 82.22 | AR7: =ROUND(AM7*0.256%,2) -> 42.09 | AT7: =ROUND(AN7*7%,0) -> 1151 | AU7: =ROUND(IF(AM7<24366,AM7*1.5%,24366*1.5%),2) -> 246.65 | AV7: =SUM(AO7:AU7) -> 5632.72 | AX7: =AV7+AA7+AJ7-AK7+AW7 -> 14142.62 | BB7: 255 | BC7: =ROUND(AX7+BB7+AZ7,2) -> 14397.62 | BD7: =ROUND(BC7*6%,2) -> 863.86 | BE7: =ROUND(SUM(BC7:BD7),2) -> 15261.48
A8: =ROW()-2 -> 6 | B8: 2410 | C8: WB019180 | D8: 王偲 | E8: 310109198908200531 | F8: 45444 | G8: 45808 | I8: 上海 | J8: 1030 | K8: 3432 | L8: 720 | M8: 1943.64 | N8: 0 | O8: 0 | P8: 0 | Q8: 0 | R8: 0 | S8: 630 | T8: 0 | U8: 0 | V8: 0 | W8: 0 | X8: 0 | Y8: 0 | Z8: 0 | AA8: =SUM(J8:Z8) -> 7755.64 | AB8: 8261 | AC8: 660.88 | AD8: 165.22 | AE8: 41.31 | AF8: 8261 | AG8: =ROUND(AF8*7%,0) -> 578 | AH8: =AC8+AD8+AE8+AG8 -> 1445.41 | AL8: =AA8-AH8-AI8 -> 6310.23 | AM8: 8261 | AN8: 8261 | AO8: =ROUND(AM8*16%,2) -> 1321.76 | AP8: 743.5 | AQ8: =ROUND(AM8*0.5%,2) -> 41.31 | AR8: =ROUND(AM8*0.256%,2) -> 21.15 | AT8: =ROUND(AN8*7%,0) -> 578 | AU8: =ROUND(IF(AM8<24366,AM8*1.5%,24366*1.5%),2) -> 123.92 | AV8: =SUM(AO8:AU8) -> 2829.64 | AX8: =AV8+AA8+AJ8-AK8+AW8 -> 10585.28 | BB8: 255 | BC8: =ROUND(AX8+BB8+AZ8,2) -> 10840.28 | BD8: =ROUND(BC8*6%,2) -> 650.42 | BE8: =ROUND(SUM(BC8:BD8),2) -> 11490.7
A9: =ROW()-2 -> 7 | B9: 2410 | C9: WB024266 | D9: 王凤凌 | E9: 31011019870909564X | F9: 45444 | G9: 45808 | I9: 上海 | J9: 1030 | K9: 1260 | L9: 1440 | M9: 680.04 | N9: 0 | O9: 0 | P9: 0 | Q9: 0 | R9: 0 | S9: 630 | T9: 0 | U9: 0 | V9: 0 | W9: 0 | X9: 0 | Y9: 823.28 | Z9: 0 | AA9: =SUM(J9:Z9) -> 5863.32 | AB9: 7384 | AC9: 590.72 | AD9: 147.68 | AE9: 36.92 | AF9: 4686 | AG9: =ROUND(AF9*7%,0) -> 328 | AH9: =AC9+AD9+AE9+AG9 -> 1103.32 | AL9: =AA9-AH9-AI9 -> 4760 | AM9: 7384 | AN9: 4686 | AO9: =ROUND(AM9*16%,2) -> 1181.44 | AP9: =ROUND(AM9*9%,2) -> 664.56 | AQ9: =ROUND(AM9*0.5%,2) -> 36.92 | AR9: =ROUND(AM9*0.256%,2) -> 18.9 | AT9: =ROUND(AN9*7%,0) -> 328 | AU9: =ROUND(IF(AM9<24366,AM9*1.5%,24366*1.5%),2) -> 110.76 | AV9: =SUM(AO9:AU9) -> 2340.58 | AX9: =AV9+AA9+AJ9-AK9+AW9 -> 8203.9 | BB9: 255 | BC9: =ROUND(AX9+BB9+AZ9,2) -> 8458.9 | BD9: =ROUND(BC9*6%,2) -> 507.53 | BE9: =ROUND(SUM(BC9:BD9),2) -> 8966.43
A10: =ROW()-2 -> 8 | B10: 2410 | C10: WB033751 | D10: 高雄飞 | E10: 310101198402231014 | F10: 45444 | G10: 45808 | I10: 上海 | J10: 1300 | K10: 7462.4 | L10: 720 | M10: 663.78 | N10: 0 | O10: 0 | P10: 0 | Q10: 0 | R10: 0 | S10: 630 | T10: 0 | U10: 0 | V10: 0 | W10: 0 | X10: 0 | Y10: 0 | Z10: 0 | AA10: =SUM(J10:Z10) -> 10776.18 | AB10: 9424 | AC10: 753.92 | AD10: 188.48 | AE10: 47.12 | AF10: 9424 | AG10: =ROUND(AF10*7%,0) -> 660 | AH10: =AC10+AD10+AE10+AG10 -> 1649.52 | AL10: =AA10-AH10-AI10 -> 9126.66 | AM10: 9424 | AN10: 9424 | AO10: =ROUND(AM10*16%,2) -> 1507.84 | AP10: =ROUND(AM10*9%,2) -> 848.16 | AQ10: =ROUND(AM10*0.5%,2) -> 47.12 | AR10: =ROUND(AM10*0.256%,2) -> 24.13 | AT10: =ROUND(AN10*7%,0) -> 660 | AU10: =ROUND(IF(AM10<24366,AM10*1.5%,24366*1.5%),2) -> 141.36 | AV10: =SUM(AO10:AU10) -> 3228.61 | AX10: =AV10+AA10+AJ10-AK10+AW10 -> 14004.79 | BB10: 255 | BC10: =ROUND(AX10+BB10+AZ10,2) -> 14259.79 | BD10: =ROUND(BC10*6%,2) -> 855.59 | BE10: =ROUND(SUM(BC10:BD10),2) -> 15115.38
A11: =ROW()-2 -> 9 | B11: 2410 | C11: WB017080 | D11: 季华 | E11: 310115198609170130 | F11: 45444 | G11: 45808 | I11: 上海 | J11: 1300 | K11: 6132 | L11: 1630 | M11: 537.6 | N11: 0 | O11: 0 | P11: 0 | Q11: 0 | R11: 0 | S11: 630 | T11: 0 | U11: 0 | V11: 0 | W11: 0 | X11: 0 | Y11: 0 | Z11: 0 | AA11: =SUM(J11:Z11) -> 10229.6 | AB11: 10475 | AC11: 838 | AD11: 209.5 | AE11: 52.38 | AF11: 10475 | AG11: =ROUND(AF11*7%,0) -> 733 | AH11: =AC11+AD11+AE11+AG11 -> 1832.88 | AL11: =AA11-AH11-AI11 -> 8396.72 | AM11: 10475 | AN11: 10475 | AO11: =ROUND(AM11*16%,2) -> 1676 | AP11: 942.76 | AQ11: =ROUND(AM11*0.5%,2) -> 52.38 | AR11: =ROUND(AM11*0.256%,2) -> 26.82 | AT11: =ROUND(AN11*7%,0) -> 733 | AU11: =ROUND(IF(AM11<24366,AM11*1.5%,24366*1.5%),2) -> 157.13 | AV11: =SUM(AO11:AU11) -> 3588.09 | AX11: =AV11+AA11+AJ11-AK11+AW11 -> 13817.69 | BB11: 255 | BC11: =ROUND(AX11+BB11+AZ11,2) -> 14072.69 | BD11: =ROUND(BC11*6%,2) -> 844.36 | BE11: =ROUND(SUM(BC11:BD11),2) -> 14917.05
A12: =ROW()-2 -> 10 | B12: 2410 | C12: WB017076 | D12: 杨晓燕 | E12: 34222519770913404X | F12: 45444 | G12: 45808 | I12: 上海 | J12: 1030 | K12: 2190 | L12: 1665 | M12: 1603.14 | N12: 0 | O12: 0 | P12: 0 | Q12: 0 | R12: 0 | S12: 630 | T12: 0 | U12: 0 | V12: 0 | W12: 0 | X12: 0 | Y12: 0 | Z12: 0 | AA12: =SUM(J12:Z12) -> 7118.14 | AB12: 8472 | AC12: 677.76 | AD12: 169.44 | AE12: 42.36 | AF12: 8472 | AG12: =ROUND(AF12*7%,0) -> 593 | AH12: =AC12+AD12+AE12+AG12 -> 1482.56 | AL12: =AA12-AH12-AI12 -> 5635.58 | AM12: 8472 | AN12: 8472 | AO12: =ROUND(AM12*16%,2) -> 1355.52 | AP12: =ROUND(AM12*9%,2) -> 762.48 | AQ12: =ROUND(AM12*0.5%,2) -> 42.36 | AR12: =ROUND(AM12*0.256%,2) -> 21.69 | AT12: =ROUND(AN12*7%,0) -> 593 | AU12: =ROUND(IF(AM12<24366,AM12*1.5%,24366*1.5%),2) -> 127.08 | AV12: =SUM(AO12:AU12) -> 2902.13 | AX12: =AV12+AA12+AJ12-AK12+AW12 -> 10020.27 | BB12: 255 | BC12: =ROUND(AX12+BB12+AZ12,2) -> 10275.27 | BD12: =ROUND(BC12*6%,2) -> 616.52 | BE12: =ROUND(SUM(BC12:BD12),2) -> 10891.79
A13: =ROW()-2 -> 11 | B13: 2410 | C13: WB025472 | D13: 孟浩杰 | E13: 510108198209090637 | F13: 45444 | G13: 45808 | I13: 上海 | J13: 1300 | K13: 4410 | L13: 1310 | M13: 1394.76 | N13: 0 | O13: 0 | P13: 0 | Q13: 0 | R13: 0 | S13: 630 | T13: 0 | U13: 0 | V13: 0 | W13: 0 | X13: 0 | Y13: 0 | Z13: 0 | AA13: =SUM(J13:Z13) -> 9044.76 | AB13: 9241 | AC13: 739.28 | AD13: 184.82 | AE13: 46.21 | AF13: 9241 | AG13: =ROUND(AF13*7%,0) -> 647 | AH13: =AC13+AD13+AE13+AG13 -> 1617.31 | AL13: =AA13-AH13-AI13 -> 7427.45 | AM13: 9241 | AN13: 9241 | AO13: =ROUND(AM13*16%,2) -> 1478.56 | AP13: 831.7 | AQ13: =ROUND(AM13*0.5%,2) -> 46.21 | AR13: =ROUND(AM13*0.256%,2) -> 23.66 | AT13: =ROUND(AN13*7%,0) -> 647 | AU13: =ROUND(IF(AM13<24366,AM13*1.5%,24366*1.5%),2) -> 138.62 | AV13: =SUM(AO13:AU13) -> 3165.75 | AX13: =AV13+AA13+AJ13-AK13+AW13 -> 12210.51 | BB13: 255 | BC13: =ROUND(AX13+BB13+AZ13,2) -> 12465.51 | BD13: =ROUND(BC13*6%,2) -> 747.93 | BE13: =ROUND(SUM(BC13:BD13),2) -> 13213.44
A14: =ROW()-2 -> 12 | B14: 2410 | C14: WB017072 | D14: 朱倩 | E14: 310108198005121510 | F14: 45444 | G14: 45808 | H14: 45565 | I14: 上海 | J14: 0 | K14: 1890 | L14: 335 | M14: 849.66 | N14: 0 | O14: 0 | P14: 0 | Q14: 0 | R14: 0 | S14: 0 | T14: 0 | U14: 0 | V14: 0 | W14: 0 | X14: 0 | Y14: 0 | Z14: 0 | AA14: =SUM(J14:Z14) -> 3074.66 | AB14: 0 | AC14: 0 | AD14: 0 | AE14: 0 | AF14: 0 | AG14: 0 | AH14: 0 | AL14: =AA14-AH14-AI14 -> 3074.66 | AM14: 0 | AN14: 0 | AO14: =ROUND(AM14*16%,2) -> 0 | AP14: 0 | AQ14: =ROUND(AM14*0.5%,2) -> 0 | AR14: =ROUND(AM14*0.256%,2) -> 0 | AT14: =ROUND(AN14*7%,0) -> 0 | AU14: =ROUND(IF(AM14<24366,AM14*1.5%,24366*1.5%),2) -> 0 | AV14: =SUM(AO14:AU14) -> 0 | AX14: =AV14+AA14+AJ14-AK14+AW14 -> 3074.66 | BB14: 0 | BC14: =ROUND(AX14+BB14+AZ14,2) -> 3074.66 | BD14: =ROUND(BC14*6%,2) -> 184.48 | BE14: =ROUND(SUM(BC14:BD14),2) -> 3259.14
A15: =ROW()-2 -> 13 | B15: 2410 | C15: WB021004 | D15: 周雨薇 | E15: 310104199212304829 | F15: 45444 | G15: 45808 | I15: 上海 | J15: 1030 | K15: 1620 | L15: 2094 | M15: 1217.4 | N15: 0 | O15: 0 | P15: 0 | Q15: 0 | R15: 0 | S15: 630 | T15: 0 | U15: 0 | V15: 0 | W15: 0 | X15: 0 | Y15: 0 | Z15: 0 | AA15: =SUM(J15:Z15) -> 6591.4 | AB15: 7384 | AC15: 590.72 | AD15: 147.68 | AE15: 36.92 | AF15: 6830 | AG15: =ROUND(AF15*7%,0) -> 478 | AH15: =AC15+AD15+AE15+AG15 -> 1253.32 | AL15: =AA15-AH15-AI15 -> 5338.08 | AM15: 7384 | AN15: 6830 | AO15: =ROUND(AM15*16%,2) -> 1181.44 | AP15: =ROUND(AM15*9%,2) -> 664.56 | AQ15: =ROUND(AM15*0.5%,2) -> 36.92 | AR15: =ROUND(AM15*0.256%,2) -> 18.9 | AT15: =ROUND(AN15*7%,0) -> 478 | AU15: =ROUND(IF(AM15<24366,AM15*1.5%,24366*1.5%),2) -> 110.76 | AV15: =SUM(AO15:AU15) -> 2490.58 | AX15: =AV15+AA15+AJ15-AK15+AW15 -> 9081.98 | BB15: 255 | BC15: =ROUND(AX15+BB15+AZ15,2) -> 9336.98 | BD15: =ROUND(BC15*6%,2) -> 560.22 | BE15: =ROUND(SUM(BC15:BD15),2) -> 9897.2
A16: =ROW()-2 -> 14 | B16: 2410 | C16: WB017081 | D16: 王姗姗 | E16: 34112519880604436X | F16: 45444 | G16: 45808 | I16: 上海 | J16: 1300 | K16: 6522.6 | L16: 4720 | M16: 590.82 | N16: 0 | O16: 0 | P16: 0 | Q16: 0 | R16: 0 | S16: 630 | T16: 0 | U16: 0 | V16: 0 | W16: 0 | X16: 0 | Y16: 0 | Z16: 0 | AA16: =SUM(J16:Z16) -> 13763.42 | AB16: 18040 | AC16: 1443.2 | AD16: 360.8 | AE16: 90.2 | AF16: 18040 | AG16: =ROUND(AF16*7%,0) -> 1263 | AH16: =AC16+AD16+AE16+AG16 -> 3157.2 | AL16: =AA16-AH16-AI16 -> 10606.22 | AM16: 18040 | AN16: 18040 | AO16: =ROUND(AM16*16%,2) -> 2886.4 | AP16: =ROUND(AM16*9%,2) -> 1623.6 | AQ16: =ROUND(AM16*0.5%,2) -> 90.2 | AR16: =ROUND(AM16*0.256%,2) -> 46.18 | AT16: =ROUND(AN16*7%,0) -> 1263 | AU16: =ROUND(IF(AM16<24366,AM16*1.5%,24366*1.5%),2) -> 270.6 | AV16: =SUM(AO16:AU16) -> 6179.98 | AX16: =AV16+AA16+AJ16-AK16+AW16 -> 19943.4 | BB16: 255 | BC16: =ROUND(AX16+BB16+AZ16,2) -> 20198.4 | BD16: =ROUND(BC16*6%,2) -> 1211.9 | BE16: =ROUND(SUM(BC16:BD16),2) -> 21410.3
A17: =ROW()-2 -> 15 | B17: 2410 | C17: WB017085 | D17: 邱杭佳 | E17: 31010819830921103X | F17: 45444 | G17: 45808 | I17: 上海 | J17: 1030 | K17: 2032.5 | L17: 2940 | M17: 1463.7 | N17: 0 | O17: 0 | P17: 0 | Q17: 0 | R17: 0 | S17: 630 | T17: 0 | U17: 0 | V17: 0 | W17: 0 | X17: 0 | Y17: 0 | Z17: 0 | AA17: =SUM(J17:Z17) -> 8096.2 | AB17: 7474 | AC17: 597.92 | AD17: 149.48 | AE17: 37.37 | AF17: 7474 | AG17: =ROUND(AF17*7%,0) -> 523 | AH17: =AC17+AD17+AE17+AG17 -> 1307.77 | AL17: =AA17-AH17-AI17 -> 6788.43 | AM17: 7474 | AN17: 7474 | AO17: =ROUND(AM17*16%,2) -> 1195.84 | AP17: =ROUND(AM17*9%,2) -> 672.66 | AQ17: =ROUND(AM17*0.5%,2) -> 37.37 | AR17: =ROUND(AM17*0.256%,2) -> 19.13 | AT17: =ROUND(AN17*7%,0) -> 523 | AU17: =ROUND(IF(AM17<24366,AM17*1.5%,24366*1.5%),2) -> 112.11 | AV17: =SUM(AO17:AU17) -> 2560.11 | AX17: =AV17+AA17+AJ17-AK17+AW17 -> 10656.31 | BB17: 255 | BC17: =ROUND(AX17+BB17+AZ17,2) -> 10911.31 | BD17: =ROUND(BC17*6%,2) -> 654.68 | BE17: =ROUND(SUM(BC17:BD17),2) -> 11565.99
A18: =ROW()-2 -> 16 | B18: 2410 | C18: WB008065 | D18: 戚继英 | E18: 310102198004243227 | F18: 45444 | G18: 45808 | I18: 上海 | J18: 1300 | K18: 2767.5 | L18: 2580 | M18: 1664.31 | N18: 0 | O18: 0 | P18: 0 | Q18: 0 | R18: 0 | S18: 630 | T18: 0 | U18: 0 | V18: 0 | W18: 0 | X18: 0 | Y18: 0 | Z18: 0 | AA18: =SUM(J18:Z18) -> 8941.81 | AB18: 11152 | AC18: 892.16 | AD18: 223.04 | AE18: 55.76 | AF18: 11152 | AG18: =ROUND(AF18*7%,0) -> 781 | AH18: =AC18+AD18+AE18+AG18 -> 1951.96 | AL18: =AA18-AH18-AI18 -> 6989.85 | AM18: 11152 | AN18: 11152 | AO18: =ROUND(AM18*16%,2) -> 1784.32 | AP18: =ROUND(AM18*9%,2) -> 1003.68 | AQ18: =ROUND(AM18*0.5%,2) -> 55.76 | AR18: =ROUND(AM18*0.256%,2) -> 28.55 | AT18: =ROUND(AN18*7%,0) -> 781 | AU18: =ROUND(IF(AM18<24366,AM18*1.5%,24366*1.5%),2) -> 167.28 | AV18: =SUM(AO18:AU18) -> 3820.59 | AX18: =AV18+AA18+AJ18-AK18+AW18 -> 12762.4 | BB18: 255 | BC18: =ROUND(AX18+BB18+AZ18,2) -> 13017.4 | BD18: =ROUND(BC18*6%,2) -> 781.04 | BE18: =ROUND(SUM(BC18:BD18),2) -> 13798.44
A19: =ROW()-2 -> 17 | B19: 2410 | C19: WB045238 | D19: 戈婷婷 | E19: 320821199610185147 | F19: 45444 | G19: 45808 | I19: 上海 | J19: 1030 | K19: 3597.75 | L19: 2220 | M19: 1487.55 | N19: 0 | O19: 0 | P19: 0 | Q19: 0 | R19: 0 | S19: 630 | T19: 0 | U19: 0 | V19: 0 | W19: 0 | X19: 0 | Y19: 0 | Z19: 0 | AA19: =SUM(J19:Z19) -> 8965.3 | AB19: 10443 | AC19: 835.44 | AD19: 208.86 | AE19: 52.22 | AF19: 10443 | AG19: =ROUND(AF19*7%,0) -> 731 | AH19: =AC19+AD19+AE19+AG19 -> 1827.52 | AL19: =AA19-AH19-AI19 -> 7137.78 | AM19: 10443 | AN19: 10443 | AO19: =ROUND(AM19*16%,2) -> 1670.88 | AP19: 939.88 | AQ19: =ROUND(AM19*0.5%,2) -> 52.22 | AR19: =ROUND(AM19*0.256%,2) -> 26.73 | AT19: =ROUND(AN19*7%,0) -> 731 | AU19: =ROUND(IF(AM19<24366,AM19*1.5%,24366*1.5%),2) -> 156.65 | AV19: =SUM(AO19:AU19) -> 3577.36 | AX19: =AV19+AA19+AJ19-AK19+AW19 -> 12542.66 | BB19: 255 | BC19: =ROUND(AX19+BB19+AZ19,2) -> 12797.66 | BD19: =ROUND(BC19*6%,2) -> 767.86 | BE19: =ROUND(SUM(BC19:BD19),2) -> 13565.52
A20: =ROW()-2 -> 18 | B20: 2410 | C20: WB013266 | D20: 吴裕刚 | E20: 31010219810818361X | F20: 45444 | G20: 45808 | I20: 上海 | J20: 1030 | K20: 4161.86 | L20: 2440 | M20: 607.71 | N20: 0 | O20: 0 | P20: 0 | Q20: 0 | R20: 0 | S20: 630 | T20: 0 | U20: 0 | V20: 0 | W20: 0 | X20: 0 | Y20: 0 | Z20: 0 | AA20: =SUM(J20:Z20) -> 8869.57 | AB20: 8102 | AC20: 648.16 | AD20: 162.04 | AE20: 40.51 | AF20: 8102 | AG20: =ROUND(AF20*7%,0) -> 567 | AH20: =AC20+AD20+AE20+AG20 -> 1417.71 | AL20: =AA20-AH20-AI20 -> 7451.86 | AM20: 8102 | AN20: 8102 | AO20: =ROUND(AM20*16%,2) -> 1296.32 | AP20: =ROUND(AM20*9%,2) -> 729.18 | AQ20: =ROUND(AM20*0.5%,2) -> 40.51 | AR20: =ROUND(AM20*0.256%,2) -> 20.74 | AT20: =ROUND(AN20*7%,0) -> 567 | AU20: =ROUND(IF(AM20<24366,AM20*1.5%,24366*1.5%),2) -> 121.53 | AV20: =SUM(AO20:AU20) -> 2775.28 | AX20: =AV20+AA20+AJ20-AK20+AW20 -> 11644.85 | BB20: 255 | BC20: =ROUND(AX20+BB20+AZ20,2) -> 11899.85 | BD20: =ROUND(BC20*6%,2) -> 713.99 | BE20: =ROUND(SUM(BC20:BD20),2) -> 12613.84
A21: =ROW()-2 -> 19 | B21: 2410 | C21: WB017007 | D21: 贺彦 | E21: 310108198901250513 | F21: 45444 | G21: 45808 | I21: 上海 | J21: 800 | K21: 1704 | L21: 1440 | M21: 785.22 | N21: 0 | O21: 0 | P21: 0 | Q21: 0 | R21: 0 | S21: 630 | T21: 0 | U21: 0 | V21: 0 | W21: 0 | X21: 0 | Y21: 519.1 | Z21: 0 | AA21: =SUM(J21:Z21) -> 5878.32 | AB21: 7384 | AC21: 590.72 | AD21: 147.68 | AE21: 36.92 | AF21: 4906 | AG21: =ROUND(AF21*7%,0) -> 343 | AH21: =AC21+AD21+AE21+AG21 -> 1118.32 | AL21: =AA21-AH21-AI21 -> 4760 | AM21: 7384 | AN21: 4906 | AO21: =ROUND(AM21*16%,2) -> 1181.44 | AP21: =ROUND(AM21*9%,2) -> 664.56 | AQ21: =ROUND(AM21*0.5%,2) -> 36.92 | AR21: =ROUND(AM21*0.256%,2) -> 18.9 | AT21: =ROUND(AN21*7%,0) -> 343 | AU21: =ROUND(IF(AM21<24366,AM21*1.5%,24366*1.5%),2) -> 110.76 | AV21: =SUM(AO21:AU21) -> 2355.58 | AX21: =AV21+AA21+AJ21-AK21+AW21 -> 8233.9 | BB21: 255 | BC21: =ROUND(AX21+BB21+AZ21,2) -> 8488.9 | BD21: =ROUND(BC21*6%,2) -> 509.33 | BE21: =ROUND(SUM(BC21:BD21),2) -> 8998.23
A22: =ROW()-2 -> 20 | B22: 2410 | C22: WB017000 | D22: 叶毅 | E22: 310110198502133266 | F22: 45444 | G22: 45808 | I22: 上海 | J22: 1030 | K22: 2190 | L22: 5420 | M22: 961.5 | N22: 0 | O22: 0 | P22: 0 | Q22: 0 | R22: 0 | S22: 630 | T22: 0 | U22: 0 | V22: 0 | W22: 0 | X22: 0 | Y22: 0 | Z22: 0 | AA22: =SUM(J22:Z22) -> 10231.5 | AB22: 7759 | AC22: 620.72 | AD22: 155.18 | AE22: 38.8 | AF22: 7759 | AG22: =ROUND(AF22*7%,0) -> 543 | AH22: =AC22+AD22+AE22+AG22 -> 1357.7 | AL22: =AA22-AH22-AI22 -> 8873.8 | AM22: 7759 | AN22: 7759 | AO22: =ROUND(AM22*16%,2) -> 1241.44 | AP22: 698.32 | AQ22: =ROUND(AM22*0.5%,2) -> 38.8 | AR22: =ROUND(AM22*0.256%,2) -> 19.86 | AT22: =ROUND(AN22*7%,0) -> 543 | AU22: =ROUND(IF(AM22<24366,AM22*1.5%,24366*1.5%),2) -> 116.39 | AV22: =SUM(AO22:AU22) -> 2657.81 | AX22: =AV22+AA22+AJ22-AK22+AW22 -> 12889.31 | BB22: 255 | BC22: =ROUND(AX22+BB22+AZ22,2) -> 13144.31 | BD22: =ROUND(BC22*6%,2) -> 788.66 | BE22: =ROUND(SUM(BC22:BD22),2) -> 13932.97
A23: =ROW()-2 -> 21 | B23: 2410 | C23: WB017001 | D23: 陈世碧 | E23: 513023197709136722 | F23: 45444 | G23: 45808 | I23: 上海 | J23: 1030 | K23: 2847 | L23: 4128 | M23: 1826.7 | N23: 0 | O23: 0 | P23: 0 | Q23: 0 | R23: 0 | S23: 630 | T23: 0 | U23: 0 | V23: 0 | W23: 0 | X23: 0 | Y23: 0 | Z23: 0 | AA23: =SUM(J23:Z23) -> 10461.7 | AB23: 10043 | AC23: 803.44 | AD23: 200.86 | AE23: 50.22 | AF23: 10043 | AG23: =ROUND(AF23*7%,0) -> 703 | AH23: =AC23+AD23+AE23+AG23 -> 1757.52 | AL23: =AA23-AH23-AI23 -> 8704.18 | AM23: 10043 | AN23: 10043 | AO23: =ROUND(AM23*16%,2) -> 1606.88 | AP23: 903.88 | AQ23: =ROUND(AM23*0.5%,2) -> 50.22 | AR23: =ROUND(AM23*0.256%,2) -> 25.71 | AT23: =ROUND(AN23*7%,0) -> 703 | AU23: =ROUND(IF(AM23<24366,AM23*1.5%,24366*1.5%),2) -> 150.65 | AV23: =SUM(AO23:AU23) -> 3440.34 | AX23: =AV23+AA23+AJ23-AK23+AW23 -> 13902.04 | BB23: 255 | BC23: =ROUND(AX23+BB23+AZ23,2) -> 14157.04 | BD23: =ROUND(BC23*6%,2) -> 849.42 | BE23: =ROUND(SUM(BC23:BD23),2) -> 15006.46
A24: =ROW()-2 -> 22 | B24: 2410 | C24: WB017004 | D24: 顾陆慧 | E24: 310230197904164766 | F24: 45444 | G24: 45808 | I24: 上海 | J24: 1300 | K24: 5548 | L24: 3380 | M24: 596.94 | N24: 0 | O24: 0 | P24: 0 | Q24: 0 | R24: 0 | S24: 630 | T24: 0 | U24: 0 | V24: 0 | W24: 0 | X24: 0 | Y24: 0 | Z24: 0 | AA24: =SUM(J24:Z24) -> 11454.94 | AB24: 12136 | AC24: 970.88 | AD24: 242.72 | AE24: 60.68 | AF24: 12136 | AG24: =ROUND(AF24*7%,0) -> 850 | AH24: =AC24+AD24+AE24+AG24 -> 2124.28 | AL24: =AA24-AH24-AI24 -> 9330.66 | AM24: 12136 | AN24: 12136 | AO24: =ROUND(AM24*16%,2) -> 1941.76 | AP24: =ROUND(AM24*9%,2) -> 1092.24 | AQ24: =ROUND(AM24*0.5%,2) -> 60.68 | AR24: =ROUND(AM24*0.256%,2) -> 31.07 | AT24: =ROUND(AN24*7%,0) -> 850 | AU24: =ROUND(IF(AM24<24366,AM24*1.5%,24366*1.5%),2) -> 182.04 | AV24: =SUM(AO24:AU24) -> 4157.79 | AX24: =AV24+AA24+AJ24-AK24+AW24 -> 15612.73 | BB24: 255 | BC24: =ROUND(AX24+BB24+AZ24,2) -> 15867.73 | BD24: =ROUND(BC24*6%,2) -> 952.06 | BE24: =ROUND(SUM(BC24:BD24),2) -> 16819.79
A25: =ROW()-2 -> 23 | B25: 2410 | C25: WB017006 | D25: 程祖云 | E25: 411524198609258442 | F25: 45444 | G25: 45808 | I25: 上海 | J25: 1200 | K25: 3883.6 | L25: 2256 | M25: 753.18 | N25: 0 | O25: 0 | P25: 0 | Q25: 0 | R25: 0 | S25: 630 | T25: 0 | U25: 0 | V25: 0 | W25: 0 | X25: 0 | Y25: 0 | Z25: 0 | AA25: =SUM(J25:Z25) -> 8722.78 | AB25: 9608 | AC25: 768.64 | AD25: 192.16 | AE25: 48.04 | AF25: 9608 | AG25: =ROUND(AF25*7%,0) -> 673 | AH25: =AC25+AD25+AE25+AG25 -> 1681.84 | AL25: =AA25-AH25-AI25 -> 7040.94 | AM25: 9608 | AN25: 9608 | AO25: =ROUND(AM25*16%,2) -> 1537.28 | AP25: =ROUND(AM25*9%,2) -> 864.72 | AQ25: =ROUND(AM25*0.5%,2) -> 48.04 | AR25: =ROUND(AM25*0.256%,2) -> 24.6 | AT25: =ROUND(AN25*7%,0) -> 673 | AU25: =ROUND(IF(AM25<24366,AM25*1.5%,24366*1.5%),2) -> 144.12 | AV25: =SUM(AO25:AU25) -> 3291.76 | AX25: =AV25+AA25+AJ25-AK25+AW25 -> 12014.54 | BB25: 255 | BC25: =ROUND(AX25+BB25+AZ25,2) -> 12269.54 | BD25: =ROUND(BC25*6%,2) -> 736.17 | BE25: =ROUND(SUM(BC25:BD25),2) -> 13005.71
A26: =ROW()-2 -> 24 | B26: 2410 | C26: WB003572 | D26: 谢俊敏 | E26: 310110198911171036 | F26: 45444 | G26: 45808 | I26: 上海 | J26: 1030 | K26: 1800 | L26: 2232 | M26: 1033.86 | N26: 0 | O26: 0 | P26: 0 | Q26: 0 | R26: 0 | S26: 630 | T26: 0 | U26: 0 | V26: 0 | W26: 0 | X26: 0 | Y26: 0 | Z26: 0 | AA26: =SUM(J26:Z26) -> 6725.86 | AB26: 7974 | AC26: 637.92 | AD26: 159.48 | AE26: 39.87 | AF26: 7974 | AG26: =ROUND(AF26*7%,0) -> 558 | AH26: =AC26+AD26+AE26+AG26 -> 1395.27 | AL26: =AA26-AH26-AI26 -> 5330.59 | AM26: 7974 | AN26: 7974 | AO26: =ROUND(AM26*16%,2) -> 1275.84 | AP26: =ROUND(AM26*9%,2) -> 717.66 | AQ26: =ROUND(AM26*0.5%,2) -> 39.87 | AR26: =ROUND(AM26*0.256%,2) -> 20.41 | AT26: =ROUND(AN26*7%,0) -> 558 | AU26: =ROUND(IF(AM26<24366,AM26*1.5%,24366*1.5%),2) -> 119.61 | AV26: =SUM(AO26:AU26) -> 2731.39 | AX26: =AV26+AA26+AJ26-AK26+AW26 -> 9457.25 | BB26: 255 | BC26: =ROUND(AX26+BB26+AZ26,2) -> 9712.25 | BD26: =ROUND(BC26*6%,2) -> 582.74 | BE26: =ROUND(SUM(BC26:BD26),2) -> 10294.99
A27: =ROW()-2 -> 25 | B27: 2410 | C27: WB039916 | D27: 梁裔杰 | E27: 310113198509301719 | F27: 45444 | G27: 45808 | I27: 上海 | J27: 1030 | K27: 2652 | L27: 1835 | M27: 785.16 | N27: 0 | O27: 0 | P27: 0 | Q27: 0 | R27: 0 | S27: 630 | T27: 0 | U27: 0 | V27: 0 | W27: 0 | X27: 0 | Y27: 0 | Z27: 0 | AA27: =SUM(J27:Z27) -> 6932.16 | AB27: 7384 | AC27: 590.72 | AD27: 147.68 | AE27: 36.92 | AF27: 7139 | AG27: =ROUND(AF27*7%,0) -> 500 | AH27: =AC27+AD27+AE27+AG27 -> 1275.32 | AL27: =AA27-AH27-AI27 -> 5656.84 | AM27: 7384 | AN27: 7139 | AO27: =ROUND(AM27*16%,2) -> 1181.44 | AP27: =ROUND(AM27*9%,2) -> 664.56 | AQ27: =ROUND(AM27*0.5%,2) -> 36.92 | AR27: =ROUND(AM27*0.256%,2) -> 18.9 | AT27: =ROUND(AN27*7%,0) -> 500 | AU27: =ROUND(IF(AM27<24366,AM27*1.5%,24366*1.5%),2) -> 110.76 | AV27: =SUM(AO27:AU27) -> 2512.58 | AX27: =AV27+AA27+AJ27-AK27+AW27 -> 9444.74 | BB27: 255 | BC27: =ROUND(AX27+BB27+AZ27,2) -> 9699.74 | BD27: =ROUND(BC27*6%,2) -> 581.98 | BE27: =ROUND(SUM(BC27:BD27),2) -> 10281.72
A28: =ROW()-2 -> 26 | B28: 2410 | C28: WB017057 | D28: 朱云 | E28: 310110198810200045 | F28: 45444 | G28: 45808 | I28: 上海 | J28: 1030 | K28: 1260 | L28: 70 | M28: 251.76 | N28: 0 | O28: 0 | P28: 0 | Q28: 0 | R28: 0 | S28: 630 | T28: 0 | U28: 0 | V28: 0 | W28: 0 | X28: 0 | Y28: =2162.69 -> 2162.69 | Z28: 0 | AA28: =SUM(J28:Z28) -> 5404.45 | AB28: 11909 | AC28: 952.72 | AD28: 238.18 | AE28: 59.55 | AF28: 11909 | AG28: =ROUND(AF28*7%,0) -> 834 | AH28: =AC28+AD28+AE28+AG28 -> 2084.45 | AL28: =AA28-AH28-AI28 -> 3320 | AM28: 11909 | AN28: 11909 | AO28: =ROUND(AM28*16%,2) -> 1905.44 | AP28: 1071.82 | AQ28: =ROUND(AM28*0.5%,2) -> 59.55 | AR28: =ROUND(AM28*0.256%,2) -> 30.49 | AT28: =ROUND(AN28*7%,0) -> 834 | AU28: =ROUND(IF(AM28<24366,AM28*1.5%,24366*1.5%),2) -> 178.64 | AV28: =SUM(AO28:AU28) -> 4079.94 | AX28: =AV28+AA28+AJ28-AK28+AW28 -> 9484.39 | AZ28: =-Y28 -> -2162.69 | BA28: 10月保障补差2162.69元，11月补 | BB28: 255 | BC28: =ROUND(AX28+BB28+AZ28,2) -> 7576.7 | BD28: =ROUND(BC28*6%,2) -> 454.6 | BE28: =ROUND(SUM(BC28:BD28),2) -> 8031.3
A29: =ROW()-2 -> 27 | B29: 2410 | C29: WB017068 | D29: 罗文彬 | E29: 310110198902103234 | F29: 45444 | G29: 45808 | I29: 上海 | J29: 1200 | K29: 2912 | L29: 1040 | M29: 526.08 | N29: 0 | O29: 0 | P29: 0 | Q29: 0 | R29: 0 | S29: 630 | T29: 0 | U29: 0 | V29: 0 | W29: 0 | X29: 0 | Y29: 0 | Z29: 0 | AA29: =SUM(J29:Z29) -> 6308.08 | AB29: 14537 | AC29: 1162.96 | AD29: 290.74 | AE29: 72.69 | AF29: 14537 | AG29: =ROUND(AF29*7%,0) -> 1018 | AH29: =AC29+AD29+AE29+AG29 -> 2544.39 | AL29: =AA29-AH29-AI29 -> 3763.69 | AM29: 14537 | AN29: 14537 | AO29: =ROUND(AM29*16%,2) -> 2325.92 | AP29: 1308.34 | AQ29: =ROUND(AM29*0.5%,2) -> 72.69 | AR29: =ROUND(AM29*0.256%,2) -> 37.21 | AT29: =ROUND(AN29*7%,0) -> 1018 | AU29: =ROUND(IF(AM29<24366,AM29*1.5%,24366*1.5%),2) -> 218.06 | AV29: =SUM(AO29:AU29) -> 4980.22 | AX29: =AV29+AA29+AJ29-AK29+AW29 -> 11288.3 | BB29: 255 | BC29: =ROUND(AX29+BB29+AZ29,2) -> 11543.3 | BD29: =ROUND(BC29*6%,2) -> 692.6 | BE29: =ROUND(SUM(BC29:BD29),2) -> 12235.9
A30: =ROW()-2 -> 28 | B30: 2410 | C30: WB054689 | D30: 张梦诏 | E30: 342423200108298172 | F30: 45444 | G30: 45808 | I30: 上海 | J30: 800 | K30: 1902.6 | L30: 2580 | M30: 1493.76 | N30: 0 | O30: 0 | P30: 0 | Q30: 0 | R30: 0 | S30: 630 | T30: 0 | U30: 0 | V30: 0 | W30: 0 | X30: 0 | Y30: 0 | Z30: 0 | AA30: =SUM(J30:Z30) -> 7406.36 | AB30: 7384 | AC30: 590.72 | AD30: 147.68 | AE30: 36.92 | AF30: 5239 | AG30: =ROUND(AF30*7%,0) -> 367 | AH30: =AC30+AD30+AE30+AG30 -> 1142.32 | AL30: =AA30-AH30-AI30 -> 6264.04 | AM30: 7384 | AN30: 5239 | AO30: =ROUND(AM30*16%,2) -> 1181.44 | AP30: =ROUND(AM30*9%,2) -> 664.56 | AQ30: =ROUND(AM30*0.5%,2) -> 36.92 | AR30: =ROUND(AM30*0.256%,2) -> 18.9 | AT30: =ROUND(AN30*7%,0) -> 367 | AU30: =ROUND(IF(AM30<24366,AM30*1.5%,24366*1.5%),2) -> 110.76 | AV30: =SUM(AO30:AU30) -> 2379.58 | AX30: =AV30+AA30+AJ30-AK30+AW30 -> 9785.94 | BB30: 255 | BC30: =ROUND(AX30+BB30+AZ30,2) -> 10040.94 | BD30: =ROUND(BC30*6%,2) -> 602.46 | BE30: =ROUND(SUM(BC30:BD30),2) -> 10643.4
A32: 合计 | AA32: =SUBTOTAL(9,AA3:AA30) -> 226374.09 | AH32: =SUBTOTAL(9,AH3:AH30) -> 46020.42 | AL32: =SUBTOTAL(9,AL3:AL30) -> 180353.67 | AV32: =SUBTOTAL(9,AV3:AV30) -> 90627.22 | AX32: =SUBTOTAL(9,AX3:AX30) -> 317001.31 | AZ32: =SUBTOTAL(9,AZ3:AZ30) -> -2162.69 | BB32: =SUBTOTAL(9,BB3:BB30) -> 6885 | BC32: =SUBTOTAL(9,BC3:BC30) -> 321723.62 | BD32: =SUBTOTAL(9,BD3:BD30) -> 19303.41 | BE32: =SUBTOTAL(9,BE3:BE30) -> 341027.03

Sheet 对账单
A1: 科目 | B1: 手工账单 | C1: 7月速创账单 | D1: 155 | E1: 系统已有金额（不做一次性） | F1: 8月少收 | G1: 合计 | H1: 差异
A2: 管理费 | B2: ='202410'!BD32 -> 19303.41 | C2: =系统!E44 -> 21752.28 | D2: =155*27+0.03 -> 4185.03 | G2: =SUM(C2:F2) -> 25937.31 | H2: =B2-C2 -> -2448.87
A3: 风险费 | B3: ='202410'!BB32 -> 6885 | C3: 0 | G3: =SUM(C3:F3) -> 0 | H3: =B3-C3 -> 6885
A4: 个人四金 | B4: ='202410'!AH32 -> 46020.42 | C4: =系统!V44 -> 46020.42 | G4: =SUM(C4:F4) -> 46020.42 | H4: =B4-C4 -> 0
A5: 公司四金 | B5: ='202410'!AV32 -> 90627.22 | C5: =系统!O44 -> 90627.22 | G5: =SUM(C5:E5) -> 90627.22 | H5: =B5-C5 -> 0
A6: 残保金 | G6: =SUM(C6:F6) -> 0 | H6: =B6-C6 -> 0
A7: 代发工资 | B7: ='202410'!AL32 -> 180353.67 | C7: =系统!W44 -> 178190.98 | G7: =SUM(C7:F7) -> 178190.98 | H7: =B7-C7 -> 2162.69
A8: 上月垫付 | G8: =SUM(C8:F8) -> 0 | H8: =B8-C8 -> 0
A9: 报销 | G9: =SUM(C9:F9) -> 0 | H9: =B9-C9 -> 0
A10: 预收（做预收一次性） | G10: =SUM(C10:F10) -> 0 | H10: =B10-C10 -> 0
A11: 小计 | B11: =SUM(B2:B10) -> 343189.72 | C11: =SUM(C2:C10) -> 336590.9 | D11: =SUM(D2:D10) -> 4185.03 | E11: =SUM(E2:E10) -> 0 | F11: =SUM(F2:F10) -> 0 | G11: =SUM(C11:F11) -> 340775.93
A12: 附加税 | D12: 0
A13: 增值税 | D13: =ROUND((D11+D12)*6%,2) -> 251.1 | E13: =ROUND((E11+E12)*6%,2) -> 0 | F13: =ROUND((F11+F12)*6%,2) -> 0 | G13: =SUM(C13:F13) -> 251.1
A14: 总计 | B14: =SUM(B11:B13) -> 343189.72 | C14: =SUM(C11:C13) -> 336590.9 | D14: =SUM(D11:D13) -> 4436.13 | E14: =SUM(E11:E13) -> 0 | F14: =SUM(F11:F13) -> 0 | G14: =SUM(C14:F14) -> 341027.03
A15: 给客户账单金额 | G15: =B14 -> 343189.72
A16: 差异 | G16: =G15-G14 -> 2162.69
A17: 不含税差异 | G17: =ROUND(G16/1.06,2) -> 2040.27

Sheet 系统
A1: 200070
A2: 寄：梅园路77号人才大厦
B3: 中国电信股份有限公司上海分公司 王慧珏 收
D6: 上海外服布列吉科技有限公司
C7: Shanghai Foreign Service Bridge Technology Co,Ltd.
E9: 收款通知书
E10: ADVISE ON COLLECTION
E11: 2024年10月
A13: 公司名称：中国电信股份有限公司上海分公司 | J13: 帐单号：202410CH6594404
A14: 序号 | B14: 姓名 | C14: 发生年月 | D14: 入职日期 | E14: 管理费 | F14: 当月社保基数 | G14: 当月公积金基数 | H14: 社保类 公司支付 Social Insurance Premiums Paid by Employer | N14: 公积金类 公司支付 Provident Fund Paid by Employer | O14: 公司合计 | P14: 社保类 个人支付 Social Insurance Premiums Paid by Employee | U14: 公积金类 个人支付 Provident Fund Paid by Employee | V14: 个人合计 | W14: 代办薪酬 | X14: 其他 | Y14: 总计 | Z14: 备注 | AA14: 外服工号 | AB14: 证件号码 | AC14: 应纳税金额 | AD14: 税率 | AE14: 增值税
A15: S/N | B15: Name | C15: YYYYMM | D15: Employment Start Date | E15: Adm Fee | F15: Social Insurance Base Amount of Current Month | G15: Provident Fund Base Amount of Current Month | H15: 养老保险 Endowment | I15: 医疗保险 Medical | J15: 失业保险 Unemploy-ment | K15: 工伤保险 Employment Injury | L15: 医疗生育保险 Medical Maternity | M15: 保障金 Disabled people&Back pay Fund | N15: 公积金 Provident Fund | O15: Subtotal of Employer Payment | P15: 养老保险 Endowment | Q15: 医疗保险 Medical | R15: 失业保险 Unemploy-ment | S15: 工伤保险 Employment Injury | T15: 医疗生育保险 Medical Maternity | U15: 公积金 Provident Fund | V15: Subtotal of Personal Payment | W15: Agency of Wage Payment | X15: Others | Y15: Total | Z15: Remarks | AA15: SFSC ID | AB15: ID Card | AC15: Taxable Amount | AD15: Tax Rate | AE15: VAT
A16: 1 | B16: 陈世碧 | C16: 202410 | D16: 2024-06-01 | E16: 940.12 | F16: 10043 | G16: 10043 | H16: 1606.88 | I16: 903.88 | J16: 50.22 | K16: 25.71 | M16: 150.65 | N16: 703 | O16: =SUM(H16:N16) -> 3440.34 | P16: 803.44 | Q16: 200.86 | R16: 50.22 | U16: 703 | V16: =SUM(P16:U16) -> 1757.52 | W16: 8704.18 | Y16: =SUM(E16,O16,V16:X16) -> 14842.16 | AA16: 5861127 | AB16: 513023197709136722 | AC16: 14002.05 | AD16: 6% | AE16: 840.11
A17: 2 | B17: 程祖云 | C17: 202410 | D17: 2024-06-01 | E17: 826.88 | F17: 9608 | G17: 9608 | H17: 1537.28 | I17: 864.72 | J17: 48.04 | K17: 24.6 | M17: 144.12 | N17: 673 | O17: =SUM(H17:N17) -> 3291.76 | P17: 768.64 | Q17: 192.16 | R17: 48.04 | U17: 673 | V17: =SUM(P17:U17) -> 1681.84 | W17: 7040.94 | Y17: =SUM(E17,O17,V17:X17) -> 12841.42 | AA17: 5861128 | AB17: 411524198609258442 | AC17: 12114.54 | AD17: 6% | AE17: 726.88
A18: 3 | B18: 高雄飞 | C18: 202410 | D18: 2024-06-01 | E18: 946.29 | F18: 9424 | G18: 9424 | H18: 1507.84 | I18: 848.16 | J18: 47.12 | K18: 24.13 | M18: 141.36 | N18: 660 | O18: =SUM(H18:N18) -> 3228.61 | P18: 753.92 | Q18: 188.48 | R18: 47.12 | U18: 660 | V18: =SUM(P18:U18) -> 1649.52 | W18: 9126.66 | Y18: =SUM(E18,O18,V18:X18) -> 14951.08 | AA18: 5544585 | AB18: 310101198402231014 | AC18: 14104.78 | AD18: 6% | AE18: 846.3
A19: 4 | B19: 戈婷婷 | C19: 202410 | D19: 2024-06-01 | E19: 858.56 | F19: 10443 | G19: 10443 | H19: 1670.88 | I19: 939.88 | J19: 52.22 | K19: 26.73 | M19: 156.65 | N19: 731 | O19: =SUM(H19:N19) -> 3577.36 | P19: 835.44 | Q19: 208.86 | R19: 52.22 | U19: 731 | V19: =SUM(P19:U19) -> 1827.52 | W19: 7137.78 | Y19: =SUM(E19,O19,V19:X19) -> 13401.22 | AA19: 5544594 | AB19: 320821199610185147 | AC19: 12642.67 | AD19: 6% | AE19: 758.55
A20: 5 | B20: 顾陆慧 | C20: 202410 | D20: 2024-06-01 | E20: 1042.76 | F20: 12136 | G20: 12136 | H20: 1941.76 | I20: 1092.24 | J20: 60.68 | K20: 31.07 | M20: 182.04 | N20: 850 | O20: =SUM(H20:N20) -> 4157.79 | P20: 970.88 | Q20: 242.72 | R20: 60.68 | U20: 850 | V20: =SUM(P20:U20) -> 2124.28 | W20: 9330.66 | Y20: =SUM(E20,O20,V20:X20) -> 16655.49 | AA20: 5863338 | AB20: 310230197904164766 | AC20: 15712.74 | AD20: 6% | AE20: 942.75
A21: 6 | B21: 杭亮 | C21: 202410 | D21: 2024-06-01 | E21: 723.67 | F21: 9226 | G21: 9226 | H21: 1476.16 | I21: 830.34 | J21: 46.13 | K21: 23.62 | M21: 138.39 | N21: 646 | O21: =SUM(H21:N21) -> 3160.64 | P21: 738.08 | Q21: 184.52 | R21: 46.13 | U21: 646 | V21: =SUM(P21:U21) -> 1614.73 | W21: 5519.21 | Y21: =SUM(E21,O21,V21:X21) -> 11018.25 | AA21: 5544580 | AB21: 310110198004027057 | AC21: 10394.58 | AD21: 6% | AE21: 623.67
A22: 7 | B22: 贺彦 | C22: 202410 | D22: 2024-06-01 | E22: 600.03 | F22: 7384 | G22: 4906 | H22: 1181.44 | I22: 664.56 | J22: 36.92 | K22: 18.9 | M22: 110.76 | N22: 343 | O22: =SUM(H22:N22) -> 2355.58 | P22: 590.72 | Q22: 147.68 | R22: 36.92 | U22: 343 | V22: =SUM(P22:U22) -> 1118.32 | W22: 4760 | Y22: =SUM(E22,O22,V22:X22) -> 8833.93 | AA22: 5701787 | AB22: 310108198901250513 | AC22: 8333.89 | AD22: 6% | AE22: 500.04
A23: 8 | B23: 季华 | C23: 202410 | D23: 2024-06-01 | E23: 935.06 | F23: 10475 | G23: 10475 | H23: 1676 | I23: 942.76 | J23: 52.38 | K23: 26.82 | M23: 157.13 | N23: 733 | O23: =SUM(H23:N23) -> 3588.09 | P23: 838 | Q23: 209.5 | R23: 52.38 | U23: 733 | V23: =SUM(P23:U23) -> 1832.88 | W23: 8396.72 | Y23: =SUM(E23,O23,V23:X23) -> 14752.75 | AA23: 5544586 | AB23: 310115198609170130 | AC23: 13917.69 | AD23: 6% | AE23: 835.06
A24: 9 | B24: 梁裔杰 | C24: 202410 | D24: 2024-06-01 | E24: 672.68 | F24: 7384 | G24: 7139 | H24: 1181.44 | I24: 664.56 | J24: 36.92 | K24: 18.9 | M24: 110.76 | N24: 500 | O24: =SUM(H24:N24) -> 2512.58 | P24: 590.72 | Q24: 147.68 | R24: 36.92 | U24: 500 | V24: =SUM(P24:U24) -> 1275.32 | W24: 5656.84 | Y24: =SUM(E24,O24,V24:X24) -> 10117.42 | AA24: 5861130 | AB24: 310113198509301719 | AC24: 9544.73 | AD24: 6% | AE24: 572.69
A25: 10 | B25: 罗文彬 | C25: 202410 | D25: 2024-06-01 | E25: 783.3 | F25: 14537 | G25: 14537 | H25: 2325.92 | I25: 1308.34 | J25: 72.69 | K25: 37.21 | M25: 218.06 | N25: 1018 | O25: =SUM(H25:N25) -> 4980.22 | P25: 1162.96 | Q25: 290.74 | R25: 72.69 | U25: 1018 | V25: =SUM(P25:U25) -> 2544.39 | W25: 3763.69 | Y25: =SUM(E25,O25,V25:X25) -> 12071.6 | AA25: 5922255 | AB25: 310110198902103234 | AC25: 11388.31 | AD25: 6% | AE25: 683.29
A26: 11 | B26: 孟浩杰 | C26: 202410 | D26: 2024-06-01 | E26: 838.63 | F26: 9241 | G26: 9241 | H26: 1478.56 | I26: 831.7 | J26: 46.21 | K26: 23.66 | M26: 138.62 | N26: 647 | O26: =SUM(H26:N26) -> 3165.75 | P26: 739.28 | Q26: 184.82 | R26: 46.21 | U26: 647 | V26: =SUM(P26:U26) -> 1617.31 | W26: 7427.45 | Y26: =SUM(E26,O26,V26:X26) -> 13049.14 | AA26: 5544588 | AB26: 510108198209090637 | AC26: 12310.51 | AD26: 6% | AE26: 738.63
A27: 12 | B27: 戚继英 | C27: 202410 | D27: 2024-06-01 | E27: 871.74 | F27: 11152 | G27: 11152 | H27: 1784.32 | I27: 1003.68 | J27: 55.76 | K27: 28.55 | M27: 167.28 | N27: 781 | O27: =SUM(H27:N27) -> 3820.59 | P27: 892.16 | Q27: 223.04 | R27: 55.76 | U27: 781 | V27: =SUM(P27:U27) -> 1951.96 | W27: 6989.85 | Y27: =SUM(E27,O27,V27:X27) -> 13634.14 | AA27: 5544593 | AB27: 310102198004243227 | AC27: 12862.39 | AD27: 6% | AE27: 771.75
... A42: 27 | B42: 朱云 | C42: 202410 | D42: 2024-06-01 | E42: 545.3 | F42: 11909 | G42: 11909 | H42: 1905.44 | I42: 1071.82 | J42: 59.55 | K42: 30.49 | M42: 178.64 | N42: 834 | O42: =SUM(H42:N42) -> 4079.94 | P42: 952.72 | Q42: 238.18 | R42: 59.55 | U42: 834 | V42: =SUM(P42:U42) -> 2084.45 | W42: 1157.31 | Y42: =SUM(E42,O42,V42:X42) -> 7867 | AA42: 5922254 | AB42: 310110198810200045 | AC42: 7421.7 | AD42: 6% | AE42: 445.3
A43: 28 | B43: 朱倩 | C43: 202410 | D43: 2024-06-01 | E43: 184.48 | O43: =SUM(H43:N43) -> 0 | V43: =SUM(P43:U43) -> 0 | W43: 3074.66 | Y43: =SUM(E43,O43,V43:X43) -> 3259.14 | AA43: 5544589 | AB43: 310108198005121510 | AC43: 3074.66 | AD43: 6% | AE43: 184.48
A44: 合计（RMB） | E44: =SUM(E16:E43) -> 21752.28 | H44: =SUM(H16:H43) -> 42594.08 | I44: =SUM(I16:I43) -> 23959.28 | J44: =SUM(J16:J43) -> 1331.12 | K44: =SUM(K16:K43) -> 681.49 | L44: =SUM(L16:L43) -> 0 | M44: =SUM(M16:M43) -> 3993.25 | N44: =SUM(N16:N43) -> 18068 | O44: =SUM(O16:O43) -> 90627.22 | ... Y44: =SUM(Y16:Y43) -> 336590.9 | AC44: =SUM(AC16:AC43) -> 317538.58 | AE44: =SUM(AE16:AE43) -> 19052.32
A45: 总计（RMB）已包含历月补收人民币叁拾叁万陆仟伍佰玖拾圆玖角整 | Y45: 336590.9
A47: 增值税：
A48: 序号 S/N | B48: 应纳税额 | C48: 税率 | D48: 税金
A50: 1 | B50: 317538.58 | C50: 6% | D50: 19052.32
A51: 小计（RMB） | B51: 317538.58 | D51: 19052.32
A52: 总计(RMB) | D52: 19052.32
A53: 本次价税合计(RMB):人民币叁拾叁万陆仟伍佰玖拾圆玖角整
A54: 336590.9
A55: 本月价税合计（RMB）：336590.90 其中已开票336590.90
A57: 本月总计（RMB）人民币叁拾叁万陆仟伍佰玖拾圆玖角整 ￥336590.90
A59: 制单人： | J59: 制单日期：2024-10-20
A61: 户名：上海外服（集团）有限公司 | G61: 户名：上海外服（集团）有限公司
A62: 美金收款账号：449459237031 | G62: 外币/人民币收款账号：083651120100303014006
A63: 开户银行：中国银行上海市分行 | G63: 开户银行：中国光大银行上海分行营业部
...
