Workbook

Sheet 202410
A1: 序号 | B1: 计薪 周期 | C1: 工号 | D1: 姓名 | E1: 身份证号 | F1: 劳动合同起始日期 | G1: 劳动合同结束日期 | H1: 离职日期 | I1: 社保缴纳地 | J1: 星级费用 | K1: 考核费用 | L1: 量化费用 | M1: 专项费用 | Z1: 当月税前工资合计 | AA1: 社保基数(个人) | AB1: 养老保险(个人) | AC1: 医疗保险(个人) | AD1: 失业保险(个人) | AE1: 公积金基数(个人) | AF1: 住房公积金(个人) | AG1: 员工五险一金合计 | AH1: 本月个人所得税-系统导出 | AI1: 税后增加 | AJ1: 税后扣减 | AK1: 员工实发合计 | AL1: 社保基数 | AM1: 公积金基数 | AN1: 养老缴费 | AO1: 医疗缴费 | AP1: 失业保险 | AQ1: 工伤保险 | AR1: 生育保险 | AS1: 公积金 | AT1: 残保金 | AU1: 企业五险一金合计 | AV1: 工会费 | AW1: 代收付合计 | AX1: 上月垫付 | AY1: 社保备注 | AZ1: 外包服务费 | BA1: 税前项合计 | BB1: 增值税 | BC1: 总计
A2: NO. | B2: Salary Cycle | C2: Employee No. | D2: Name | E2: ID No. | F2: Contract Starting Date | G2: Contract Expiry Date | H2: Exit Date | I2: Social Insurance City | J2: Contract Salary | K2: Assessment fees | L2: Quantifying costs | M2: 支局专项 | N2: 1+1激励 | O2: 交通费 | P2: 效能补贴 | Q2: 伙食补贴 | R2: 高温费及清凉饮料费 （6-9月） | S2: 独生子女奖励 | T2: 保险费 | U2: 其他费用 | V2: 补发费用 | W2: 劳防用品 | X2: 保障补差 | Y2: 其他扣款 | Z2: Pre-tax Total | AA2: Social Insurance Base | AB2: Pension Employee | AC2: Medical Employee | AD2: Umemployment Employee | AE2: Housing Fund Base | AF2: Housing Fund Employee | AG2: Total Amount of Social Insurance(EE) | AH2: Personal Income Tax | AI2: Increase After-tax payment | AJ2: Reduction After-tax payment | AK2: After-tax total Income | AL2: Social Insurance Base | AM2: Housing Fund Base | AN2: Pension Employer | AO2: Medical Employer | AP2: Umemployment Employer | AQ2: Injury Employer | AR2: Maternity Insurance Employer | AS2: Housing Fund Employer | AT2: Disabled people&Back pay Fund | AU2: Total Amount of Social Insurance(ER) | AV2: Union Fee | AW2: Payment Total | AY2: Social Security remark | AZ2: Service Fee | BA2: Total | BB2: VAT | BC2: Subtotal
A3: =ROW()-2 -> 1 | B3: 2410 | C3: WB007244 | D3: 周伟丰 | E3: 310107198106192557 | F3: 45444 | G3: 45808 | I3: 上海 | J3: 1400 | K3: 8059 | L3: 2987.45 | M3: 0 | N3: 0 | O3: 0 | P3: 0 | Q3: 630 | R3: 0 | S3: 0 | T3: 0 | U3: 371 | V3: 0 | W3: 0 | X3: =IF((SUM(J3:L3)-AG3)<2690,2690-(SUM(J3:L3)-AG3),"") | Y3: -100 | Z3: =SUM(J3:Y3) -> 13347.45 | AA3: 13804 | AB3: 1104.32 | AC3: 276.08 | AD3: 69.02 | AE3: 13804 | AF3: 966 | AG3: =AB3+AC3+AD3+AF3 -> 2415.42 | AK3: =Z3-AG3-AH3 -> 10932.03 | AL3: 13804 | AM3: 13804 | AN3: =ROUND(AL3*16%,2) -> 2208.64 | AO3: =ROUND(AL3*9%,2) -> 1242.36 | AP3: =ROUND(AL3*0.5%,2) -> 69.02 | AQ3: =ROUND(AL3*0.256%,2) -> 35.34 | AS3: =ROUND(AM3*7%,0) -> 966 | AT3: =ROUND(IF(AL3<24366,AL3*1.5%,24366*1.5%),2) -> 207.06 | AU3: =SUM(AN3:AT3) -> 4728.42 | AW3: =AU3+Z3+AI3-AJ3+AV3 -> 18075.87 | AZ3: 255 | BA3: =ROUND(AW3+AZ3+AX3,2) -> 18330.87 | BB3: =ROUND(BA3*6%,2) -> 1099.85 | BC3: =ROUND(SUM(BA3:BB3),2) -> 19430.72 | BD3: 纵向攻击团队
A4: =ROW()-2 -> 2 | B4: 2410 | C4: WB007262 | D4: 顾燕 | E4: 310113198111034825 | F4: 45444 | G4: 45808 | I4: 上海 | J4: 1030 | K4: 6548 | L4: 1834.7 | M4: 0 | N4: 0 | O4: 0 | P4: 700 | Q4: 630 | R4: 0 | S4: 0 | T4: 0 | U4: 0 | V4: 0 | W4: 0 | X4: =IF((SUM(J4:L4)-AG4)<2690,2690-(SUM(J4:L4)-AG4),"") | Y4: 0 | Z4: =SUM(J4:Y4) -> 10742.7 | AA4: 10363 | AB4: 829.04 | AC4: 207.26 | AD4: 51.82 | AE4: 10363 | AF4: 725 | AG4: =AB4+AC4+AD4+AF4 -> 1813.12 | AK4: =Z4-AG4-AH4 -> 8929.58 | AL4: 10363 | AM4: 10363 | AN4: =ROUND(AL4*16%,2) -> 1658.08 | AO4: 932.68 | AP4: =ROUND(AL4*0.5%,2) -> 51.82 | AQ4: =ROUND(AL4*0.256%,2) -> 26.53 | AS4: =ROUND(AM4*7%,0) -> 725 | AT4: =ROUND(IF(AL4<24366,AL4*1.5%,24366*1.5%),2) -> 155.45 | AU4: =SUM(AN4:AT4) -> 3549.56 | AW4: =AU4+Z4+AI4-AJ4+AV4 -> 14292.26 | AZ4: 255 | BA4: =ROUND(AW4+AZ4+AX4,2) -> 14547.26 | BB4: =ROUND(BA4*6%,2) -> 872.84 | BC4: =ROUND(SUM(BA4:BB4),2) -> 15420.1 | BD4: 纵向攻击团队
A5: =ROW()-2 -> 3 | B5: 2410 | C5: WB026438 | D5: 沈娟娟 | E5: 32068119890825242X | F5: 45444 | G5: 45808 | I5: 上海 | J5: 1200 | K5: 6788 | L5: 2130.4 | M5: 0 | N5: 0 | O5: 0 | P5: 0 | Q5: 630 | R5: 0 | S5: 0 | T5: 0 | U5: 0 | V5: 0 | W5: 0 | X5: =IF((SUM(J5:L5)-AG5)<2690,2690-(SUM(J5:L5)-AG5),"") | Y5: 0 | Z5: =SUM(J5:Y5) -> 10748.4 | AA5: 11829 | AB5: 946.32 | AC5: 236.58 | AD5: 59.15 | AE5: 11829 | AF5: 828 | AG5: =AB5+AC5+AD5+AF5 -> 2070.05 | AK5: =Z5-AG5-AH5 -> 8678.35 | AL5: 11829 | AM5: 11829 | AN5: =ROUND(AL5*16%,2) -> 1892.64 | AO5: 1064.62 | AP5: =ROUND(AL5*0.5%,2) -> 59.15 | AQ5: =ROUND(AL5*0.256%,2) -> 30.28 | AS5: =ROUND(AM5*7%,0) -> 828 | AT5: =ROUND(IF(AL5<24366,AL5*1.5%,24366*1.5%),2) -> 177.44 | AU5: =SUM(AN5:AT5) -> 4052.13 | AW5: =AU5+Z5+AI5-AJ5+AV5 -> 14800.53 | AZ5: 255 | BA5: =ROUND(AW5+AZ5+AX5,2) -> 15055.53 | BB5: =ROUND(BA5*6%,2) -> 903.33 | BC5: =ROUND(SUM(BA5:BB5),2) -> 15958.86 | BD5: 纵向攻击团队
A6: =ROW()-2 -> 4 | B6: 2410 | C6: WB027558 | D6: 陈云 | E6: 320681198911257029 | F6: 45444 | G6: 45808 | I6: 上海 | J6: 1030 | K6: 6403 | L6: 1785.3 | M6: 0 | N6: 0 | O6: 0 | P6: 0 | Q6: 630 | R6: 0 | S6: 0 | T6: 0 | U6: 371 | V6: 0 | W6: 0 | X6: =IF((SUM(J6:L6)-AG6)<2690,2690-(SUM(J6:L6)-AG6),"") | Y6: -100 | Z6: =SUM(J6:Y6) -> 10119.3 | AA6: 11367 | AB6: 909.36 | AC6: 227.34 | AD6: 56.84 | AE6: 11367 | AF6: 796 | AG6: =AB6+AC6+AD6+AF6 -> 1989.54 | AK6: =Z6-AG6-AH6 -> 8129.76 | AL6: 11367 | AM6: 11367 | AN6: =ROUND(AL6*16%,2) -> 1818.72 | AO6: 1023.04 | AP6: =ROUND(AL6*0.5%,2) -> 56.84 | AQ6: =ROUND(AL6*0.256%,2) -> 29.1 | AS6: =ROUND(AM6*7%,0) -> 796 | AT6: =ROUND(IF(AL6<24366,AL6*1.5%,24366*1.5%),2) -> 170.51 | AU6: =SUM(AN6:AT6) -> 3894.21 | AW6: =AU6+Z6+AI6-AJ6+AV6 -> 14013.51 | AZ6: 255 | BA6: =ROUND(AW6+AZ6+AX6,2) -> 14268.51 | BB6: =ROUND(BA6*6%,2) -> 856.11 | BC6: =ROUND(SUM(BA6:BB6),2) -> 15124.62 | BD6: 纵向攻击团队
A7: =ROW()-2 -> 5 | B7: 2410 | C7: WB036282 | D7: 张海荣 | E7: 320681198311146835 | F7: 45444 | G7: 45808 | I7: 上海 | J7: 950 | K7: 3290 | L7: 716.6 | M7: 0 | N7: 0 | O7: 0 | P7: 500 | Q7: 630 | R7: 0 | S7: 0 | T7: 0 | U7: 371 | V7: 0 | W7: 0 | X7: =IF((SUM(J7:L7)-AG7)<2690,2690-(SUM(J7:L7)-AG7),"") | Y7: -100 | Z7: =SUM(J7:Y7) -> 6357.6 | AA7: 11730 | AB7: 938.4 | AC7: 234.6 | AD7: 58.65 | AE7: 11730 | AF7: 821 | AG7: =AB7+AC7+AD7+AF7 -> 2052.65 | AK7: =Z7-AG7-AH7 -> 4304.95 | AL7: 11730 | AM7: 11730 | AN7: =ROUND(AL7*16%,2) -> 1876.8 | AO7: =ROUND(AL7*9%,2) -> 1055.7 | AP7: =ROUND(AL7*0.5%,2) -> 58.65 | AQ7: =ROUND(AL7*0.256%,2) -> 30.03 | AS7: =ROUND(AM7*7%,0) -> 821 | AT7: =ROUND(IF(AL7<24366,AL7*1.5%,24366*1.5%),2) -> 175.95 | AU7: =SUM(AN7:AT7) -> 4018.13 | AW7: =AU7+Z7+AI7-AJ7+AV7 -> 10375.73 | AZ7: 255 | BA7: =ROUND(AW7+AZ7+AX7,2) -> 10630.73 | BB7: =ROUND(BA7*6%,2) -> 637.84 | BC7: =ROUND(SUM(BA7:BB7),2) -> 11268.57 | BD7: 纵向攻击团队
A8: =ROW()-2 -> 6 | B8: 2410 | C8: WB044295 | D8: 龚林花 | E8: 310230198502244987 | F8: 45444 | G8: 45808 | I8: 上海 | J8: 860 | K8: 6933 | L8: 1906.7 | M8: 0 | N8: 0 | O8: 0 | P8: 0 | Q8: 630 | R8: 0 | S8: 0 | T8: 0 | U8: 371 | V8: 0 | W8: 0 | X8: =IF((SUM(J8:L8)-AG8)<2690,2690-(SUM(J8:L8)-AG8),"") | Y8: 0 | Z8: =SUM(J8:Y8) -> 10700.7 | AA8: 7963 | AB8: 637.04 | AC8: 159.26 | AD8: 39.82 | AE8: 7963 | AF8: 557 | AG8: =AB8+AC8+AD8+AF8 -> 1393.12 | AK8: =Z8-AG8-AH8 -> 9307.58 | AL8: 7963 | AM8: 7963 | AN8: =ROUND(AL8*16%,2) -> 1274.08 | AO8: 716.68 | AP8: =ROUND(AL8*0.5%,2) -> 39.82 | AQ8: =ROUND(AL8*0.256%,2) -> 20.39 | AS8: =ROUND(AM8*7%,0) -> 557 | AT8: =ROUND(IF(AL8<24366,AL8*1.5%,24366*1.5%),2) -> 119.45 | AU8: =SUM(AN8:AT8) -> 2727.42 | AW8: =AU8+Z8+AI8-AJ8+AV8 -> 13428.12 | AZ8: 255 | BA8: =ROUND(AW8+AZ8+AX8,2) -> 13683.12 | BB8: =ROUND(BA8*6%,2) -> 820.99 | BC8: =ROUND(SUM(BA8:BB8),2) -> 14504.11 | BD8: 纵向攻击团队
A9: =ROW()-2 -> 7 | B9: 2410 | C9: WB046059 | D9: 宋莉莉 | E9: 370883199010065887 | F9: 45444 | G9: 45808 | I9: 上海 | J9: 800 | K9: 3535 | L9: 912.6 | M9: 0 | N9: 0 | O9: 0 | P9: 0 | Q9: 630 | R9: 0 | S9: 0 | T9: 0 | U9: 0 | V9: 0 | W9: 0 | X9: =IF((SUM(J9:L9)-AG9)<2690,2690-(SUM(J9:L9)-AG9),"") | Y9: 0 | Z9: =SUM(J9:Y9) -> 5877.6 | AA9: 11386 | AB9: 910.88 | AC9: 227.72 | AD9: 56.93 | AE9: 11386 | AF9: 797 | AG9: =AB9+AC9+AD9+AF9 -> 1992.53 | AK9: =Z9-AG9-AH9 -> 3885.07 | AL9: 11386 | AM9: 11386 | AN9: =ROUND(AL9*16%,2) -> 1821.76 | AO9: =ROUND(AL9*9%,2) -> 1024.74 | AP9: =ROUND(AL9*0.5%,2) -> 56.93 | AQ9: =ROUND(AL9*0.256%,2) -> 29.15 | AS9: =ROUND(AM9*7%,0) -> 797 | AT9: =ROUND(IF(AL9<24366,AL9*1.5%,24366*1.5%),2) -> 170.79 | AU9: =SUM(AN9:AT9) -> 3900.37 | AW9: =AU9+Z9+AI9-AJ9+AV9 -> 9777.97 | AZ9: 255 | BA9: =ROUND(AW9+AZ9+AX9,2) -> 10032.97 | BB9: =ROUND(BA9*6%,2) -> 601.98 | BC9: =ROUND(SUM(BA9:BB9),2) -> 10634.95 | BD9: 纵向攻击团队
A10: =ROW()-2 -> 8 | B10: 2410 | C10: WB053301 | D10: 林峰 | E10: 320681199806210215 | F10: 45444 | G10: 45808 | I10: 上海 | J10: 900 | K10: 3780 | L10: 987.9 | M10: 0 | N10: 0 | O10: 0 | P10: 0 | Q10: 630 | R10: 0 | S10: 0 | T10: 0 | U10: 0 | V10: 0 | W10: 0 | X10: =IF((SUM(J10:L10)-AG10)<2690,2690-(SUM(J10:L10)-AG10),"") | Y10: 0 | Z10: =SUM(J10:Y10) -> 6297.9 | AA10: 7546 | AB10: 603.68 | AC10: 150.92 | AD10: 37.73 | AE10: 7546 | AF10: 528 | AG10: =AB10+AC10+AD10+AF10 -> 1320.33 | AK10: =Z10-AG10-AH10 -> 4977.57 | AL10: 7546 | AM10: 7546 | AN10: =ROUND(AL10*16%,2) -> 1207.36 | AO10: =ROUND(AL10*9%,2) -> 679.14 | AP10: =ROUND(AL10*0.5%,2) -> 37.73 | AQ10: =ROUND(AL10*0.256%,2) -> 19.32 | AS10: =ROUND(AM10*7%,0) -> 528 | AT10: =ROUND(IF(AL10<24366,AL10*1.5%,24366*1.5%),2) -> 113.19 | AU10: =SUM(AN10:AT10) -> 2584.74 | AW10: =AU10+Z10+AI10-AJ10+AV10 -> 8882.64 | AZ10: 255 | BA10: =ROUND(AW10+AZ10+AX10,2) -> 9137.64 | BB10: =ROUND(BA10*6%,2) -> 548.26 | BC10: =ROUND(SUM(BA10:BB10),2) -> 9685.9 | BD10: 纵向攻击团队
A11: =ROW()-2 -> 9 | B11: 2410 | C11: WB007259 | D11: 茅柳 | E11: 310230198208264565 | F11: 45444 | G11: 45808 | I11: 上海 | J11: 900 | K11: 4481 | L11: 443.9 | M11: 0 | N11: 0 | O11: 0 | P11: 0 | Q11: 630 | R11: 0 | S11: 0 | T11: 0 | U11: 0 | V11: 0 | W11: 0 | X11: =IF((SUM(J11:L11)-AG11)<2690,2690-(SUM(J11:L11)-AG11),"") | Y11: 0 | Z11: =SUM(J11:Y11) -> 6454.9 | AA11: 7594 | AB11: 607.52 | AC11: 151.88 | AD11: 37.97 | AE11: 7594 | AF11: 532 | AG11: =AB11+AC11+AD11+AF11 -> 1329.37 | AK11: =Z11-AG11-AH11 -> 5125.53 | AL11: 7594 | AM11: 7594 | AN11: =ROUND(AL11*16%,2) -> 1215.04 | AO11: =ROUND(AL11*9%,2) -> 683.46 | AP11: =ROUND(AL11*0.5%,2) -> 37.97 | AQ11: =ROUND(AL11*0.256%,2) -> 19.44 | AS11: =ROUND(AM11*7%,0) -> 532 | AT11: =ROUND(IF(AL11<24366,AL11*1.5%,24366*1.5%),2) -> 113.91 | AU11: =SUM(AN11:AT11) -> 2601.82 | AW11: =AU11+Z11+AI11-AJ11+AV11 -> 9056.72 | AZ11: 255 | BA11: =ROUND(AW11+AZ11+AX11,2) -> 9311.72 | BB11: =ROUND(BA11*6%,2) -> 558.7 | BC11: =ROUND(SUM(BA11:BB11),2) -> 9870.42 | BD11: 纵向攻击团队
A12: =ROW()-2 -> 10 | B12: 2410 | C12: WB045138 | D12: 沙玉莲 | E12: 320681198001296045 | F12: 45444 | G12: 45808 | I12: 上海 | J12: 900 | K12: 9754 | L12: 2024.8 | M12: 0 | N12: 0 | O12: 0 | P12: 0 | Q12: 630 | R12: 0 | S12: 0 | T12: 0 | U12: 0 | V12: 0 | W12: 0 | X12: =IF((SUM(J12:L12)-AG12)<2690,2690-(SUM(J12:L12)-AG12),"") | Y12: 0 | Z12: =SUM(J12:Y12) -> 13308.8 | AA12: 11264 | AB12: 901.12 | AC12: 225.28 | AD12: 56.32 | AE12: 11264 | AF12: 788 | AG12: =AB12+AC12+AD12+AF12 -> 1970.72 | AK12: =Z12-AG12-AH12 -> 11338.08 | AL12: 11264 | AM12: 11264 | AN12: =ROUND(AL12*16%,2) -> 1802.24 | AO12: =ROUND(AL12*9%,2) -> 1013.76 | AP12: =ROUND(AL12*0.5%,2) -> 56.32 | AQ12: =ROUND(AL12*0.256%,2) -> 28.84 | AS12: =ROUND(AM12*7%,0) -> 788 | AT12: =ROUND(IF(AL12<24366,AL12*1.5%,24366*1.5%),2) -> 168.96 | AU12: =SUM(AN12:AT12) -> 3858.12 | AW12: =AU12+Z12+AI12-AJ12+AV12 -> 17166.92 | AZ12: 255 | BA12: =ROUND(AW12+AZ12+AX12,2) -> 17421.92 | BB12: =ROUND(BA12*6%,2) -> 1045.32 | BC12: =ROUND(SUM(BA12:BB12),2) -> 18467.24 | BD12: 纵向攻击团队
A13: =ROW()-2 -> 11 | B13: 2410 | C13: WB044028 | D13: 王凌波 | E13: 320681198005016055 | F13: 45444 | G13: 45808 | I13: 上海 | J13: 900 | K13: 12574 | L13: 2106.6 | M13: 0 | N13: 0 | O13: 0 | P13: 0 | Q13: 630 | R13: 0 | S13: 0 | T13: 0 | U13: 0 | V13: 0 | W13: 0 | X13: =IF((SUM(J13:L13)-AG13)<2690,2690-(SUM(J13:L13)-AG13),"") | Y13: 0 | Z13: =SUM(J13:Y13) -> 16210.6 | AA13: 11463 | AB13: 917.04 | AC13: 229.26 | AD13: 57.32 | AE13: 11463 | AF13: 802 | AG13: =AB13+AC13+AD13+AF13 -> 2005.62 | AK13: =Z13-AG13-AH13 -> 14204.98 | AL13: 11463 | AM13: 11463 | AN13: =ROUND(AL13*16%,2) -> 1834.08 | AO13: 1031.68 | AP13: =ROUND(AL13*0.5%,2) -> 57.32 | AQ13: =ROUND(AL13*0.256%,2) -> 29.35 | AS13: =ROUND(AM13*7%,0) -> 802 | AT13: =ROUND(IF(AL13<24366,AL13*1.5%,24366*1.5%),2) -> 171.95 | AU13: =SUM(AN13:AT13) -> 3926.38 | AW13: =AU13+Z13+AI13-AJ13+AV13 -> 20136.98 | AZ13: 255 | BA13: =ROUND(AW13+AZ13+AX13,2) -> 20391.98 | BB13: =ROUND(BA13*6%,2) -> 1223.52 | BC13: =ROUND(SUM(BA13:BB13),2) -> 21615.5 | BD13: 纵向攻击团队
A14: =ROW()-2 -> 12 | B14: 2410 | C14: WB041713 | D14: 翁杰 | E14: 32068119830326361X | F14: 45444 | G14: 45808 | I14: 上海 | J14: 900 | K14: 8449 | L14: 2146.9 | M14: 0 | N14: 0 | O14: 0 | P14: 0 | Q14: 630 | R14: 0 | S14: 0 | T14: 0 | U14: 0 | V14: 0 | W14: 0 | X14: =IF((SUM(J14:L14)-AG14)<2690,2690-(SUM(J14:L14)-AG14),"") | Y14: 0 | Z14: =SUM(J14:Y14) -> 12125.9 | AA14: 8179 | AB14: 654.32 | AC14: 163.58 | AD14: 40.9 | AE14: 8179 | AF14: 573 | AG14: =AB14+AC14+AD14+AF14 -> 1431.8 | AK14: =Z14-AG14-AH14 -> 10694.1 | AL14: 8179 | AM14: 8179 | AN14: =ROUND(AL14*16%,2) -> 1308.64 | AO14: 736.12 | AP14: =ROUND(AL14*0.5%,2) -> 40.9 | AQ14: =ROUND(AL14*0.256%,2) -> 20.94 | AS14: =ROUND(AM14*7%,0) -> 573 | AT14: =ROUND(IF(AL14<24366,AL14*1.5%,24366*1.5%),2) -> 122.69 | AU14: =SUM(AN14:AT14) -> 2802.29 | AW14: =AU14+Z14+AI14-AJ14+AV14 -> 14928.19 | AZ14: 255 | BA14: =ROUND(AW14+AZ14+AX14,2) -> 15183.19 | BB14: =ROUND(BA14*6%,2) -> 910.99 | BC14: =ROUND(SUM(BA14:BB14),2) -> 16094.18 | BD14: 纵向攻击团队
A15: =ROW()-2 -> 13 | B15: 2410 | C15: WB050058 | D15: 周海松 | E15: 320626197411023016 | F15: 45444 | G15: 45808 | I15: 上海 | J15: 900 | K15: 4906 | L15: 1032.3 | M15: 0 | N15: 0 | O15: 0 | P15: 500 | Q15: 630 | R15: 0 | S15: 0 | T15: 0 | U15: 371 | V15: 0 | W15: 0 | X15: =IF((SUM(J15:L15)-AG15)<2690,2690-(SUM(J15:L15)-AG15),"") | Y15: 0 | Z15: =SUM(J15:Y15) -> 8339.3 | AA15: 7384 | AB15: 590.72 | AC15: 147.68 | AD15: 36.92 | AE15: 4848 | AF15: 339 | AG15: =AB15+AC15+AD15+AF15 -> 1114.32 | AK15: =Z15-AG15-AH15 -> 7224.98 | AL15: 7384 | AM15: 4848 | AN15: =ROUND(AL15*16%,2) -> 1181.44 | AO15: =ROUND(AL15*9%,2) -> 664.56 | AP15: =ROUND(AL15*0.5%,2) -> 36.92 | AQ15: =ROUND(AL15*0.256%,2) -> 18.9 | AS15: =ROUND(AM15*7%,0) -> 339 | AT15: =ROUND(IF(AL15<24366,AL15*1.5%,24366*1.5%),2) -> 110.76 | AU15: =SUM(AN15:AT15) -> 2351.58 | AW15: =AU15+Z15+AI15-AJ15+AV15 -> 10690.88 | AZ15: 255 | BA15: =ROUND(AW15+AZ15+AX15,2) -> 10945.88 | BB15: =ROUND(BA15*6%,2) -> 656.75 | BC15: =ROUND(SUM(BA15:BB15),2) -> 11602.63 | BD15: 纵向攻击团队
A16: =ROW()-2 -> 14 | B16: 2410 | C16: WB048620 | D16: 郁金华 | E16: 320681197812267024 | F16: 45444 | G16: 45808 | I16: 上海 | J16: 800 | K16: 6948 | L16: 2820.1 | M16: 0 | N16: 0 | O16: 0 | P16: 0 | Q16: 630 | R16: 0 | S16: 0 | T16: 0 | U16: 0 | V16: 0 | W16: 0 | X16: =IF((SUM(J16:L16)-AG16)<2690,2690-(SUM(J16:L16)-AG16),"") | Y16: 0 | Z16: =SUM(J16:Y16) -> 11198.1 | AA16: 7384 | AB16: 590.72 | AC16: 147.68 | AD16: 36.92 | AE16: 6573 | AF16: 460 | AG16: =AB16+AC16+AD16+AF16 -> 1235.32 | AK16: =Z16-AG16-AH16 -> 9962.78 | AL16: 7384 | AM16: 6573 | AN16: =ROUND(AL16*16%,2) -> 1181.44 | AO16: =ROUND(AL16*9%,2) -> 664.56 | AP16: =ROUND(AL16*0.5%,2) -> 36.92 | AQ16: =ROUND(AL16*0.256%,2) -> 18.9 | AS16: =ROUND(AM16*7%,0) -> 460 | AT16: =ROUND(IF(AL16<24366,AL16*1.5%,24366*1.5%),2) -> 110.76 | AU16: =SUM(AN16:AT16) -> 2472.58 | AW16: =AU16+Z16+AI16-AJ16+AV16 -> 13670.68 | AZ16: 255 | BA16: =ROUND(AW16+AZ16+AX16,2) -> 13925.68 | BB16: =ROUND(BA16*6%,2) -> 835.54 | BC16: =ROUND(SUM(BA16:BB16),2) -> 14761.22 | BD16: 纵向攻击团队
A17: =ROW()-2 -> 15 | B17: 2410 | C17: WB038749 | D17: 叶挺 | E17: 34080219811208081X | F17: 45413 | G17: 45777 | I17: 上海 | J17: 800 | K17: 4286 | L17: 2055.55 | M17: 0 | N17: 0 | O17: 0 | P17: 500 | Q17: 630 | R17: 0 | S17: 0 | T17: 0 | U17: 0 | V17: 0 | W17: 0 | Y17: 0 | Z17: =SUM(J17:Y17) -> 8271.55 | AA17: 9889 | AB17: 791.12 | AC17: 197.78 | AD17: 49.45 | AE17: 9889 | AF17: 692 | AG17: =AB17+AC17+AD17+AF17 -> 1730.35 | AK17: =Z17-AG17-AH17 -> 6541.2 | AL17: 9889 | AM17: 9889 | AN17: =ROUND(AL17*16%,2) -> 1582.24 | AO17: 890.02 | AP17: =ROUND(AL17*0.5%,2) -> 49.45 | AQ17: =ROUND(AL17*0.256%,2) -> 25.32 | AS17: =ROUND(AM17*7%,0) -> 692 | AT17: =ROUND(IF(AL17<24366,AL17*1.5%,24366*1.5%),2) -> 148.34 | AU17: =SUM(AN17:AT17) -> 3387.37 | AW17: =AU17+Z17+AI17-AJ17+AV17 -> 11658.92 | AZ17: 255 | BA17: =ROUND(AW17+AZ17+AX17,2) -> 11913.92 | BB17: =ROUND(BA17*6%,2) -> 714.84 | BC17: =ROUND(SUM(BA17:BB17),2) -> 12628.76
A18: =ROW()-2 -> 16 | B18: 2410 | C18: WB007457 | D18: 钱善晖 | E18: 341127198508043038 | F18: 45413 | G18: 45777 | I18: 上海 | J18: 1030 | K18: 6253 | L18: =1976.65-1.8 -> 1974.85 | M18: 0 | N18: 0 | O18: 0 | P18: 500 | Q18: 630 | R18: 0 | S18: 0 | T18: 0 | U18: 0 | V18: 0 | W18: 0 | Y18: 0 | Z18: =SUM(J18:Y18) -> 10387.85 | AA18: 7788 | AB18: 623.04 | AC18: 155.76 | AD18: 38.94 | AE18: 7788 | AF18: 545 | AG18: =AB18+AC18+AD18+AF18 -> 1362.74 | AK18: =Z18-AG18-AH18 -> 9025.11 | AL18: 7788 | AM18: 7788 | AN18: =ROUND(AL18*16%,2) -> 1246.08 | AO18: =ROUND(AL18*9%,2) -> 700.92 | AP18: =ROUND(AL18*0.5%,2) -> 38.94 | AQ18: =ROUND(AL18*0.256%,2) -> 19.94 | AS18: =ROUND(AM18*7%,0) -> 545 | AT18: =ROUND(IF(AL18<24366,AL18*1.5%,24366*1.5%),2) -> 116.82 | AU18: =SUM(AN18:AT18) -> 2667.7 | AW18: =AU18+Z18+AI18-AJ18+AV18 -> 13055.55 | AZ18: 255 | BA18: =ROUND(AW18+AZ18+AX18,2) -> 13310.55 | BB18: =ROUND(BA18*6%,2) -> 798.63 | BC18: =ROUND(SUM(BA18:BB18),2) -> 14109.18
A19: =ROW()-2 -> 17 | B19: 2410 | C19: WB068630 | D19: 王艳 | E19: 342222199402106028 | F19: 45427 | G19: 46521 | I19: 上海 | J19: 800 | K19: 16992 | L19: 7477.35 | M19: 0 | N19: 0 | O19: 0 | P19: 0 | Q19: 630 | R19: 0 | S19: 0 | T19: 0 | U19: 0 | V19: 0 | W19: 0 | Y19: 0 | Z19: =SUM(J19:Y19) -> 25899.35 | AA19: 7384 | AB19: 590.72 | AC19: 147.68 | AD19: 36.92 | AE19: 2690 | AF19: 188 | AG19: =AB19+AC19+AD19+AF19 -> 963.32 | AK19: =Z19-AG19-AH19 -> 24936.03 | AL19: 7384 | AM19: 2690 | AN19: =ROUND(AL19*16%,2) -> 1181.44 | AO19: =ROUND(AL19*9%,2) -> 664.56 | AP19: =ROUND(AL19*0.5%,2) -> 36.92 | AQ19: =ROUND(AL19*0.256%,2) -> 18.9 | AS19: =ROUND(AM19*7%,0) -> 188 | AT19: =ROUND(IF(AL19<24366,AL19*1.5%,24366*1.5%),2) -> 110.76 | AU19: =SUM(AN19:AT19) -> 2200.58 | AW19: =AU19+Z19+AI19-AJ19+AV19 -> 28099.93 | AZ19: 255 | BA19: =ROUND(AW19+AZ19+AX19,2) -> 28354.93 | BB19: =ROUND(BA19*6%,2) -> 1701.3 | BC19: =ROUND(SUM(BA19:BB19),2) -> 30056.23
A20: =ROW()-2 -> 18 | B20: 2410 | C20: WB007293 | D20: 王海婷 | E20: 310113198812035548 | F20: 45444 | G20: 45808 | I20: 上海 | J20: 1200 | K20: 5172.6 | L20: 4036.6 | M20: 0 | N20: 0 | O20: 0 | P20: 0 | Q20: 630 | R20: 0 | S20: 0 | T20: 0 | U20: 371 | V20: 0 | W20: 0 | Y20: 0 | Z20: =SUM(J20:Y20) -> 11410.2 | AA20: 7661 | AB20: 612.88 | AC20: 153.22 | AD20: 38.31 | AE20: 7661 | AF20: 536 | AG20: =AB20+AC20+AD20+AF20 -> 1340.41 | AK20: =Z20-AG20-AH20 -> 10069.79 | AL20: 7661 | AM20: 7661 | AN20: =ROUND(AL20*16%,2) -> 1225.76 | AO20: 689.5 | AP20: =ROUND(AL20*0.5%,2) -> 38.31 | AQ20: =ROUND(AL20*0.256%,2) -> 19.61 | AS20: =ROUND(AM20*7%,0) -> 536 | AT20: =ROUND(IF(AL20<24366,AL20*1.5%,24366*1.5%),2) -> 114.92 | AU20: =SUM(AN20:AT20) -> 2624.1 | AW20: =AU20+Z20+AI20-AJ20+AV20 -> 14034.3 | AZ20: 255 | BA20: =ROUND(AW20+AZ20+AX20,2) -> 14289.3 | BB20: =ROUND(BA20*6%,2) -> 857.36 | BC20: =ROUND(SUM(BA20:BB20),2) -> 15146.66
A21: =ROW()-2 -> 19 | B21: 2410 | C21: WB023775 | D21: 张杰 | E21: 31011319860815411X | F21: 45444 | G21: 45808 | I21: 上海 | J21: 1300 | K21: 8546.7 | L21: 4823.8 | M21: 0 | N21: 0 | O21: 0 | P21: 0 | Q21: 630 | R21: 0 | S21: 0 | T21: 0 | U21: 371 | V21: 0 | W21: 0 | Y21: -100 | Z21: =SUM(J21:Y21) -> 15571.5 | AA21: 17497 | AB21: 1399.76 | AC21: 349.94 | AD21: 87.49 | AE21: 17497 | AF21: 1225 | AG21: =AB21+AC21+AD21+AF21 -> 3062.19 | AK21: =Z21-AG21-AH21 -> 12509.31 | AL21: 17497 | AM21: 17497 | AN21: =ROUND(AL21*16%,2) -> 2799.52 | AO21: 1574.74 | AP21: =ROUND(AL21*0.5%,2) -> 87.49 | AQ21: =ROUND(AL21*0.256%,2) -> 44.79 | AS21: =ROUND(AM21*7%,0) -> 1225 | AT21: =ROUND(IF(AL21<24366,AL21*1.5%,24366*1.5%),2) -> 262.46 | AU21: =SUM(AN21:AT21) -> 5994 | AW21: =AU21+Z21+AI21-AJ21+AV21 -> 21565.5 | AZ21: 255 | BA21: =ROUND(AW21+AZ21+AX21,2) -> 21820.5 | BB21: =ROUND(BA21*6%,2) -> 1309.23 | BC21: =ROUND(SUM(BA21:BB21),2) -> 23129.73
A22: =ROW()-2 -> 20 | B22: 2410 | C22: WB030437 | D22: 李娟 | E22: 310230197802072529 | F22: 45444 | G22: 45808 | I22: 上海 | J22: 1030 | K22: 3183.8 | L22: 2659.2 | M22: 0 | N22: 0 | O22: 0 | P22: 0 | Q22: 630 | R22: 0 | S22: 0 | T22: 0 | U22: 0 | V22: 0 | W22: 0 | Y22: 0 | Z22: =SUM(J22:Y22) -> 7503 | AA22: 10038 | AB22: 803.04 | AC22: 200.76 | AD22: 50.19 | AE22: 10038 | AF22: 703 | AG22: =AB22+AC22+AD22+AF22 -> 1756.99 | AK22: =Z22-AG22-AH22 -> 5746.01 | AL22: 10038 | AM22: 10038 | AN22: =ROUND(AL22*16%,2) -> 1606.08 | AO22: =ROUND(AL22*9%,2) -> 903.42 | AP22: =ROUND(AL22*0.5%,2) -> 50.19 | AQ22: =ROUND(AL22*0.256%,2) -> 25.7 | AS22: =ROUND(AM22*7%,0) -> 703 | AT22: =ROUND(IF(AL22<24366,AL22*1.5%,24366*1.5%),2) -> 150.57 | AU22: =SUM(AN22:AT22) -> 3438.96 | AW22: =AU22+Z22+AI22-AJ22+AV22 -> 10941.96 | AZ22: 255 | BA22: =ROUND(AW22+AZ22+AX22,2) -> 11196.96 | BB22: =ROUND(BA22*6%,2) -> 671.82 | BC22: =ROUND(SUM(BA22:BB22),2) -> 11868.78
A23: =ROW()-2 -> 21 | B23: 2410 | C23: WB045407 | D23: 王佳睿 | E23: 320681200309147011 | F23: 45444 | G23: 45808 | I23: 上海 | J23: 900 | K23: 1812.3 | L23: 1716.85 | M23: 0 | N23: 0 | O23: 0 | P23: 0 | Q23: 630 | R23: 0 | S23: 0 | T23: 0 | U23: 371 | V23: 1100 | W23: 0 | Y23: -624 | Z23: =SUM(J23:Y23) -> 5906.15 | AA23: 7384 | AB23: 590.72 | AC23: 147.68 | AD23: 36.92 | AE23: 7375 | AF23: 516 | AG23: =AB23+AC23+AD23+AF23 -> 1291.32 | AK23: =Z23-AG23-AH23 -> 4614.83 | AL23: 7384 | AM23: 7375 | AN23: =ROUND(AL23*16%,2) -> 1181.44 | AO23: 664.56 | AP23: =ROUND(AL23*0.5%,2) -> 36.92 | AQ23: =ROUND(AL23*0.256%,2) -> 18.9 | AS23: =ROUND(AM23*7%,0) -> 516 | AT23: =ROUND(IF(AL23<24366,AL23*1.5%,24366*1.5%),2) -> 110.76 | AU23: =SUM(AN23:AT23) -> 2528.58 | AW23: =AU23+Z23+AI23-AJ23+AV23 -> 8434.73 | AX23: 615.42 | AY23: 9月垫付低保补差，10月收615.42 | AZ23: 255 | BA23: =ROUND(AW23+AZ23+AX23,2) -> 9305.15 | BB23: =ROUND(BA23*6%,2) -> 558.31 | BC23: =ROUND(SUM(BA23:BB23),2) -> 9863.46
A24: =ROW()-2 -> 22 | B24: 2410 | C24: WB033013 | D24: 朱娟 | E24: 310113198511225727 | F24: 45444 | G24: 45808 | I24: 上海 | J24: 970 | K24: 8679 | L24: 2515 | M24: 0 | N24: 0 | O24: 0 | P24: 700 | Q24: 630 | R24: 0 | S24: 0 | T24: 0 | U24: 0 | V24: 0 | W24: 0 | Y24: 0 | Z24: =SUM(J24:Y24) -> 13494 | AA24: 12999 | AB24: 1039.92 | AC24: 259.98 | AD24: 65 | AE24: 12999 | AF24: 910 | AG24: =AB24+AC24+AD24+AF24 -> 2274.9 | AK24: =Z24-AG24-AH24 -> 11219.1 | AL24: 12999 | AM24: 12999 | AN24: =ROUND(AL24*16%,2) -> 2079.84 | AO24: 1169.92 | AP24: =ROUND(AL24*0.5%,2) -> 65 | AQ24: =ROUND(AL24*0.256%,2) -> 33.28 | AS24: =ROUND(AM24*7%,0) -> 910 | AT24: =ROUND(IF(AL24<24366,AL24*1.5%,24366*1.5%),2) -> 194.99 | AU24: =SUM(AN24:AT24) -> 4453.03 | AW24: =AU24+Z24+AI24-AJ24+AV24 -> 17947.03 | AZ24: 255 | BA24: =ROUND(AW24+AZ24+AX24,2) -> 18202.03 | BB24: =ROUND(BA24*6%,2) -> 1092.12 | BC24: =ROUND(SUM(BA24:BB24),2) -> 19294.15
A25: =ROW()-2 -> 23 | B25: 2410 | C25: WB054275 | D25: 姚嘉豪 | E25: 310113199804301716 | F25: 45444 | G25: 45808 | I25: 上海 | J25: 800 | K25: 4892 | L25: 2108.7 | M25: 0 | N25: 0 | O25: 0 | P25: 500 | Q25: 630 | R25: 0 | S25: 0 | T25: 0 | U25: 0 | V25: 0 | W25: 0 | Y25: 0 | Z25: =SUM(J25:Y25) -> 8930.7 | AA25: 7384 | AB25: 590.72 | AC25: 147.68 | AD25: 36.92 | AE25: 3607 | AF25: 252 | AG25: =AB25+AC25+AD25+AF25 -> 1027.32 | AK25: =Z25-AG25-AH25 -> 7903.38 | AL25: 7384 | AM25: 3607 | AN25: =ROUND(AL25*16%,2) -> 1181.44 | AO25: =ROUND(AL25*9%,2) -> 664.56 | AP25: =ROUND(AL25*0.5%,2) -> 36.92 | AQ25: =ROUND(AL25*0.256%,2) -> 18.9 | AS25: =ROUND(AM25*7%,0) -> 252 | AT25: =ROUND(IF(AL25<24366,AL25*1.5%,24366*1.5%),2) -> 110.76 | AU25: =SUM(AN25:AT25) -> 2264.58 | AW25: =AU25+Z25+AI25-AJ25+AV25 -> 11195.28 | AZ25: 255 | BA25: =ROUND(AW25+AZ25+AX25,2) -> 11450.28 | BB25: =ROUND(BA25*6%,2) -> 687.02 | BC25: =ROUND(SUM(BA25:BB25),2) -> 12137.3
A26: =ROW()-2 -> 24 | B26: 2410 | C26: WB007248 | D26: 魏玲 | E26: 310108198612173363 | F26: 45444 | G26: 45808 | I26: 上海 | J26: 1030 | K26: 2829 | L26: 857.7 | M26: 0 | N26: 0 | O26: 0 | P26: 0 | Q26: 630 | R26: 0 | S26: 0 | T26: 0 | U26: 0 | V26: 0 | W26: 0 | Y26: 0 | Z26: =SUM(J26:Y26) -> 5346.7 | AA26: 7384 | AB26: 590.72 | AC26: 147.68 | AD26: 36.92 | AE26: 6207 | AF26: 434 | AG26: =AB26+AC26+AD26+AF26 -> 1209.32 | AK26: =Z26-AG26-AH26 -> 4137.38 | AL26: 7384 | AM26: 6207 | AN26: =ROUND(AL26*16%,2) -> 1181.44 | AO26: =ROUND(AL26*9%,2) -> 664.56 | AP26: =ROUND(AL26*0.5%,2) -> 36.92 | AQ26: =ROUND(AL26*0.256%,2) -> 18.9 | AS26: =ROUND(AM26*7%,0) -> 434 | AT26: =ROUND(IF(AL26<24366,AL26*1.5%,24366*1.5%),2) -> 110.76 | AU26: =SUM(AN26:AT26) -> 2446.58 | AW26: =AU26+Z26+AI26-AJ26+AV26 -> 7793.28 | AZ26: 255 | BA26: =ROUND(AW26+AZ26+AX26,2) -> 8048.28 | BB26: =ROUND(BA26*6%,2) -> 482.9 | BC26: =ROUND(SUM(BA26:BB26),2) -> 8531.18
A27: =ROW()-2 -> 25 | B27: 2410 | C27: WB007254 | D27: 朱焱炎 | E27: 320681198812140829 | F27: 45444 | G27: 45808 | I27: 上海 | J27: 950 | K27: 1080 | L27: 1193.7 | M27: 0 | N27: 0 | O27: 0 | P27: 0 | Q27: 630 | R27: 0 | S27: 0 | T27: 0 | U27: 371 | V27: 0 | W27: 0 | X27: 591.62 | Y27: 0 | Z27: =SUM(J27:Y27) -> 4816.32 | AA27: 7384 | AB27: 590.72 | AC27: 147.68 | AD27: 36.92 | AE27: 4997 | AF27: 350 | AG27: =AB27+AC27+AD27+AF27 -> 1125.32 | AK27: =Z27-AG27-AH27 -> 3691 | AL27: 7384 | AM27: 4997 | AN27: =ROUND(AL27*16%,2) -> 1181.44 | AO27: =ROUND(AL27*9%,2) -> 664.56 | AP27: =ROUND(AL27*0.5%,2) -> 36.92 | AQ27: =ROUND(AL27*0.256%,2) -> 18.9 | AS27: =ROUND(AM27*7%,0) -> 350 | AT27: =ROUND(IF(AL27<24366,AL27*1.5%,24366*1.5%),2) -> 110.76 | AU27: =SUM(AN27:AT27) -> 2362.58 | AW27: =AU27+Z27+AI27-AJ27+AV27 -> 7178.9 | AX27: =-X27 -> -591.62 | AY27: 10月垫付低保补差，11月收 | AZ27: 255 | BA27: =ROUND(AW27+AZ27+AX27,2) -> 6842.28 | BB27: =ROUND(BA27*6%,2) -> 410.54 | BC27: =ROUND(SUM(BA27:BB27),2) -> 7252.82
A28: =ROW()-2 -> 26 | B28: 2410 | C28: WB022966 | D28: 赵杭顺 | E28: 310102198702193618 | F28: 45444 | G28: 45808 | I28: 上海 | J28: 1030 | K28: 4622 | L28: 1971.7 | M28: 0 | N28: 0 | O28: 0 | P28: 0 | Q28: 630 | R28: 0 | S28: 0 | T28: 0 | U28: 371 | V28: 0 | W28: 0 | Y28: 0 | Z28: =SUM(J28:Y28) -> 8624.7 | AA28: 11395 | AB28: 911.6 | AC28: 227.9 | AD28: 56.98 | AE28: 11395 | AF28: 798 | AG28: =AB28+AC28+AD28+AF28 -> 1994.48 | AK28: =Z28-AG28-AH28 -> 6630.22 | AL28: 11395 | AM28: 11395 | AN28: =ROUND(AL28*16%,2) -> 1823.2 | AO28: 1025.56 | AP28: =ROUND(AL28*0.5%,2) -> 56.98 | AQ28: =ROUND(AL28*0.256%,2) -> 29.17 | AS28: =ROUND(AM28*7%,0) -> 798 | AT28: =ROUND(IF(AL28<24366,AL28*1.5%,24366*1.5%),2) -> 170.93 | AU28: =SUM(AN28:AT28) -> 3903.84 | AW28: =AU28+Z28+AI28-AJ28+AV28 -> 12528.54 | AZ28: 255 | BA28: =ROUND(AW28+AZ28+AX28,2) -> 12783.54 | BB28: =ROUND(BA28*6%,2) -> 767.01 | BC28: =ROUND(SUM(BA28:BB28),2) -> 13550.55
A29: =ROW()-2 -> 27 | B29: 2410 | C29: WB016859 | D29: 陆燕 | E29: 310113197802064324 | F29: 45444 | G29: 45808 | I29: 上海 | J29: 1400 | K29: 21720 | L29: 1143.2 | M29: 0 | N29: 0 | O29: 0 | P29: 0 | Q29: 630 | R29: 0 | S29: 0 | T29: 0 | U29: 0 | V29: 0 | W29: 0 | Y29: 0 | Z29: =SUM(J29:Y29) -> 24893.2 | AA29: 7384 | AB29: 590.72 | AC29: 147.68 | AD29: 36.92 | AE29: 6844 | AF29: 479 | AG29: =AB29+AC29+AD29+AF29 -> 1254.32 | AK29: =Z29-AG29-AH29 -> 23638.88 | AL29: 7384 | AM29: 6844 | AN29: =ROUND(AL29*16%,2) -> 1181.44 | AO29: =ROUND(AL29*9%,2) -> 664.56 | AP29: =ROUND(AL29*0.5%,2) -> 36.92 | AQ29: =ROUND(AL29*0.256%,2) -> 18.9 | AS29: =ROUND(AM29*7%,0) -> 479 | AT29: =ROUND(IF(AL29<24366,AL29*1.5%,24366*1.5%),2) -> 110.76 | AU29: =SUM(AN29:AT29) -> 2491.58 | AW29: =AU29+Z29+AI29-AJ29+AV29 -> 27384.78 | AZ29: 255 | BA29: =ROUND(AW29+AZ29+AX29,2) -> 27639.78 | BB29: =ROUND(BA29*6%,2) -> 1658.39 | BC29: =ROUND(SUM(BA29:BB29),2) -> 29298.17
A30: =ROW()-2 -> 28 | B30: 2410 | C30: WB016826 | D30: 成瀛 | E30: 140103198304204830 | F30: 45444 | G30: 45808 | I30: 上海 | J30: 1300 | K30: 3846 | L30: 1377.6 | M30: 0 | N30: 0 | O30: 0 | P30: 0 | Q30: 630 | R30: 0 | S30: 0 | T30: 0 | U30: 371 | V30: 0 | W30: 0 | Y30: 0 | Z30: =SUM(J30:Y30) -> 7524.6 | AA30: 7384 | AB30: 590.72 | AC30: 147.68 | AD30: 36.92 | AE30: 5131 | AF30: 359 | AG30: =AB30+AC30+AD30+AF30 -> 1134.32 | AK30: =Z30-AG30-AH30 -> 6390.28 | AL30: 7384 | AM30: 5131 | AN30: =ROUND(AL30*16%,2) -> 1181.44 | AO30: =ROUND(AL30*9%,2) -> 664.56 | AP30: =ROUND(AL30*0.5%,2) -> 36.92 | AQ30: =ROUND(AL30*0.256%,2) -> 18.9 | AS30: =ROUND(AM30*7%,0) -> 359 | AT30: =ROUND(IF(AL30<24366,AL30*1.5%,24366*1.5%),2) -> 110.76 | AU30: =SUM(AN30:AT30) -> 2371.58 | AW30: =AU30+Z30+AI30-AJ30+AV30 -> 9896.18 | AZ30: 255 | BA30: =ROUND(AW30+AZ30+AX30,2) -> 10151.18 | BB30: =ROUND(BA30*6%,2) -> 609.07 | BC30: =ROUND(SUM(BA30:BB30),2) -> 10760.25
A31: =ROW()-2 -> 29 | B31: 2410 | C31: WB044433 | D31: 张枚 | E31: 340223199003157228 | F31: 45444 | G31: 45808 | I31: 上海 | J31: 1030 | K31: 3476 | L31: 2113.8 | M31: 0 | N31: 0 | O31: 0 | P31: 0 | Q31: 630 | R31: 0 | S31: 0 | T31: 0 | U31: 371 | V31: 0 | W31: 0 | Y31: 0 | Z31: =SUM(J31:Y31) -> 7620.8 | AA31: 7384 | AB31: 590.72 | AC31: 147.68 | AD31: 36.92 | AE31: 4082 | AF31: 286 | AG31: =AB31+AC31+AD31+AF31 -> 1061.32 | AK31: =Z31-AG31-AH31 -> 6559.48 | AL31: 7384 | AM31: 4082 | AN31: =ROUND(AL31*16%,2) -> 1181.44 | AO31: =ROUND(AL31*9%,2) -> 664.56 | AP31: =ROUND(AL31*0.5%,2) -> 36.92 | AQ31: =ROUND(AL31*0.256%,2) -> 18.9 | AS31: =ROUND(AM31*7%,0) -> 286 | AT31: =ROUND(IF(AL31<24366,AL31*1.5%,24366*1.5%),2) -> 110.76 | AU31: =SUM(AN31:AT31) -> 2298.58 | AW31: =AU31+Z31+AI31-AJ31+AV31 -> 9919.38 | AX31: 393.82 | AY31: 9月垫付低保补差，10月收393.82 | AZ31: 255 | BA31: =ROUND(AW31+AZ31+AX31,2) -> 10568.2 | BB31: =ROUND(BA31*6%,2) -> 634.09 | BC31: =ROUND(SUM(BA31:BB31),2) -> 11202.29
A32: =ROW()-2 -> 30 | B32: 2410 | C32: WB039094 | D32: 张欢 | E32: 340321199602189283 | F32: 45444 | G32: 45808 | I32: 上海 | J32: 950 | K32: 3798 | L32: 1300.2 | M32: 0 | N32: 0 | O32: 0 | P32: 0 | Q32: 630 | R32: 0 | S32: 0 | T32: 0 | U32: 0 | V32: 0 | W32: 0 | Y32: 0 | Z32: =SUM(J32:Y32) -> 6678.2 | AA32: 7384 | AB32: 590.72 | AC32: 147.68 | AD32: 36.92 | AE32: 4035 | AF32: 282 | AG32: =AB32+AC32+AD32+AF32 -> 1057.32 | AK32: =Z32-AG32-AH32 -> 5620.88 | AL32: 7384 | AM32: 4035 | AN32: =ROUND(AL32*16%,2) -> 1181.44 | AO32: =ROUND(AL32*9%,2) -> 664.56 | AP32: =ROUND(AL32*0.5%,2) -> 36.92 | AQ32: =ROUND(AL32*0.256%,2) -> 18.9 | AS32: =ROUND(AM32*7%,0) -> 282 | AT32: =ROUND(IF(AL32<24366,AL32*1.5%,24366*1.5%),2) -> 110.76 | AU32: =SUM(AN32:AT32) -> 2294.58 | AW32: =AU32+Z32+AI32-AJ32+AV32 -> 8972.78 | AZ32: 255 | BA32: =ROUND(AW32+AZ32+AX32,2) -> 9227.78 | BB32: =ROUND(BA32*6%,2) -> 553.67 | BC32: =ROUND(SUM(BA32:BB32),2) -> 9781.45
A33: =ROW()-2 -> 31 | B33: 2410 | C33: WB007286 | D33: 张雯 | E33: 310108198311300023 | F33: 45444 | G33: 45808 | I33: 上海 | J33: 1030 | K33: 3270 | L33: 889 | M33: 0 | N33: 0 | O33: 0 | P33: 0 | Q33: 630 | R33: 0 | S33: 0 | T33: 0 | U33: 371 | V33: 0 | W33: 0 | Y33: 0 | Z33: =SUM(J33:Y33) -> 6190 | AA33: 7384 | AB33: 590.72 | AC33: 147.68 | AD33: 36.92 | AE33: 6529 | AF33: 457 | AG33: =AB33+AC33+AD33+AF33 -> 1232.32 | AK33: =Z33-AG33-AH33 -> 4957.68 | AL33: 7384 | AM33: 6529 | AN33: =ROUND(AL33*16%,2) -> 1181.44 | AO33: =ROUND(AL33*9%,2) -> 664.56 | AP33: =ROUND(AL33*0.5%,2) -> 36.92 | AQ33: =ROUND(AL33*0.256%,2) -> 18.9 | AS33: =ROUND(AM33*7%,0) -> 457 | AT33: =ROUND(IF(AL33<24366,AL33*1.5%,24366*1.5%),2) -> 110.76 | AU33: =SUM(AN33:AT33) -> 2469.58 | AW33: =AU33+Z33+AI33-AJ33+AV33 -> 8659.58 | AZ33: 255 | BA33: =ROUND(AW33+AZ33+AX33,2) -> 8914.58 | BB33: =ROUND(BA33*6%,2) -> 534.87 | BC33: =ROUND(SUM(BA33:BB33),2) -> 9449.45
A34: =ROW()-2 -> 32 | B34: 2410 | C34: WB009624 | D34: 金霞 | E34: 310113198309114628 | F34: 45444 | G34: 45808 | I34: 上海 | J34: 1030 | K34: 3374 | L34: 1184.1 | M34: 0 | N34: 0 | O34: 0 | P34: 0 | Q34: 630 | R34: 0 | S34: 0 | T34: 0 | U34: 371 | V34: 0 | W34: 0 | Y34: 0 | Z34: =SUM(J34:Y34) -> 6589.1 | AA34: 7384 | AB34: 590.72 | AC34: 147.68 | AD34: 36.92 | AE34: 7287 | AF34: 510 | AG34: =AB34+AC34+AD34+AF34 -> 1285.32 | AK34: =Z34-AG34-AH34 -> 5303.78 | AL34: 7384 | AM34: 7287 | AN34: =ROUND(AL34*16%,2) -> 1181.44 | AO34: =ROUND(AL34*9%,2) -> 664.56 | AP34: =ROUND(AL34*0.5%,2) -> 36.92 | AQ34: =ROUND(AL34*0.256%,2) -> 18.9 | AS34: =ROUND(AM34*7%,0) -> 510 | AT34: =ROUND(IF(AL34<24366,AL34*1.5%,24366*1.5%),2) -> 110.76 | AU34: =SUM(AN34:AT34) -> 2522.58 | AW34: =AU34+Z34+AI34-AJ34+AV34 -> 9111.68 | AZ34: 255 | BA34: =ROUND(AW34+AZ34+AX34,2) -> 9366.68 | BB34: =ROUND(BA34*6%,2) -> 562 | BC34: =ROUND(SUM(BA34:BB34),2) -> 9928.68
A35: =ROW()-2 -> 33 | B35: 2410 | C35: WB009626 | D35: 殷颖 | E35: 310109198006192026 | F35: 45444 | G35: 45808 | I35: 上海 | J35: 1300 | K35: 2550 | L35: 787.1 | M35: 0 | N35: 0 | O35: 0 | P35: 0 | Q35: 630 | R35: 0 | S35: 0 | T35: 0 | U35: 0 | V35: 0 | W35: 0 | Y35: 0 | Z35: =SUM(J35:Y35) -> 5267.1 | AA35: 7384 | AB35: 590.72 | AC35: 147.68 | AD35: 36.92 | AE35: 6558 | AF35: 459 | AG35: =AB35+AC35+AD35+AF35 -> 1234.32 | AK35: =Z35-AG35-AH35 -> 4032.78 | AL35: 7384 | AM35: 6558 | AN35: =ROUND(AL35*16%,2) -> 1181.44 | AO35: =ROUND(AL35*9%,2) -> 664.56 | AP35: =ROUND(AL35*0.5%,2) -> 36.92 | AQ35: =ROUND(AL35*0.256%,2) -> 18.9 | AS35: =ROUND(AM35*7%,0) -> 459 | AT35: =ROUND(IF(AL35<24366,AL35*1.5%,24366*1.5%),2) -> 110.76 | AU35: =SUM(AN35:AT35) -> 2471.58 | AW35: =AU35+Z35+AI35-AJ35+AV35 -> 7738.68 | AZ35: 255 | BA35: =ROUND(AW35+AZ35+AX35,2) -> 7993.68 | BB35: =ROUND(BA35*6%,2) -> 479.62 | BC35: =ROUND(SUM(BA35:BB35),2) -> 8473.3
A36: =ROW()-2 -> 34 | B36: 2410 | C36: WB009627 | D36: 夏士梅 | E36: 310113197707080027 | F36: 45444 | G36: 45808 | I36: 上海 | J36: 1030 | K36: 3428 | L36: 1621.8 | M36: 0 | N36: 0 | O36: 0 | P36: 700 | Q36: 630 | R36: 0 | S36: 0 | T36: 0 | U36: 0 | V36: 0 | W36: 0 | Y36: 0 | Z36: =SUM(J36:Y36) -> 7409.8 | AA36: 7399 | AB36: 591.92 | AC36: 147.98 | AD36: 37 | AE36: 7399 | AF36: 518 | AG36: =AB36+AC36+AD36+AF36 -> 1294.9 | AK36: =Z36-AG36-AH36 -> 6114.9 | AL36: 7399 | AM36: 7399 | AN36: =ROUND(AL36*16%,2) -> 1183.84 | AO36: 665.92 | AP36: =ROUND(AL36*0.5%,2) -> 37 | AQ36: =ROUND(AL36*0.256%,2) -> 18.94 | AS36: =ROUND(AM36*7%,0) -> 518 | AT36: =ROUND(IF(AL36<24366,AL36*1.5%,24366*1.5%),2) -> 110.99 | AU36: =SUM(AN36:AT36) -> 2534.69 | AW36: =AU36+Z36+AI36-AJ36+AV36 -> 9944.49 | AZ36: 255 | BA36: =ROUND(AW36+AZ36+AX36,2) -> 10199.49 | BB36: =ROUND(BA36*6%,2) -> 611.97 | BC36: =ROUND(SUM(BA36:BB36),2) -> 10811.46
A37: =ROW()-2 -> 35 | B37: 2410 | C37: WB009631 | D37: 杨晨晖 | E37: 310113199401265319 | F37: 45444 | G37: 45808 | I37: 上海 | J37: 1030 | K37: 3158 | L37: 1673.2 | M37: 0 | N37: 0 | O37: 0 | P37: 0 | Q37: 630 | R37: 0 | S37: 0 | T37: 0 | U37: 371 | V37: 0 | W37: 0 | Y37: 0 | Z37: =SUM(J37:Y37) -> 6862.2 | AA37: 7384 | AB37: 590.72 | AC37: 147.68 | AD37: 36.92 | AE37: 7155 | AF37: 501 | AG37: =AB37+AC37+AD37+AF37 -> 1276.32 | AK37: =Z37-AG37-AH37 -> 5585.88 | AL37: 7384 | AM37: 7155 | AN37: =ROUND(AL37*16%,2) -> 1181.44 | AO37: =ROUND(AL37*9%,2) -> 664.56 | AP37: =ROUND(AL37*0.5%,2) -> 36.92 | AQ37: =ROUND(AL37*0.256%,2) -> 18.9 | AS37: =ROUND(AM37*7%,0) -> 501 | AT37: =ROUND(IF(AL37<24366,AL37*1.5%,24366*1.5%),2) -> 110.76 | AU37: =SUM(AN37:AT37) -> 2513.58 | AW37: =AU37+Z37+AI37-AJ37+AV37 -> 9375.78 | AZ37: 255 | BA37: =ROUND(AW37+AZ37+AX37,2) -> 9630.78 | BB37: =ROUND(BA37*6%,2) -> 577.85 | BC37: =ROUND(SUM(BA37:BB37),2) -> 10208.63
A38: =ROW()-2 -> 36 | B38: 2410 | C38: WB030237 | D38: 顾文君 | E38: 310110198605095645 | F38: 45444 | G38: 45808 | I38: 上海 | J38: 1300 | K38: 8872 | L38: 1898.75 | M38: 0 | N38: 0 | O38: 0 | P38: 700 | Q38: 630 | R38: 0 | S38: 0 | T38: 0 | U38: 371 | V38: 0 | W38: 0 | Y38: 0 | Z38: =SUM(J38:Y38) -> 13771.75 | AA38: 13189 | AB38: 1055.12 | AC38: 263.78 | AD38: 65.95 | AE38: 13189 | AF38: 923 | AG38: =AB38+AC38+AD38+AF38 -> 2307.85 | AK38: =Z38-AG38-AH38 -> 11463.9 | AL38: 13189 | AM38: 13189 | AN38: =ROUND(AL38*16%,2) -> 2110.24 | AO38: 1187.02 | AP38: =ROUND(AL38*0.5%,2) -> 65.95 | AQ38: =ROUND(AL38*0.256%,2) -> 33.76 | AS38: =ROUND(AM38*7%,0) -> 923 | AT38: =ROUND(IF(AL38<24366,AL38*1.5%,24366*1.5%),2) -> 197.84 | AU38: =SUM(AN38:AT38) -> 4517.81 | AW38: =AU38+Z38+AI38-AJ38+AV38 -> 18289.56 | AZ38: 255 | BA38: =ROUND(AW38+AZ38+AX38,2) -> 18544.56 | BB38: =ROUND(BA38*6%,2) -> 1112.67 | BC38: =ROUND(SUM(BA38:BB38),2) -> 19657.23
A39: =ROW()-2 -> 37 | B39: 2410 | C39: WB016896 | D39: 朱琳 | E39: 310115197811118649 | F39: 45444 | G39: 45808 | I39: 上海 | J39: 1080 | K39: 0 | L39: 7014 | M39: 0 | N39: 0 | O39: 0 | P39: 0 | Q39: 0 | R39: 0 | S39: 0 | T39: 0 | U39: 0 | V39: 0 | W39: 0 | Y39: 0 | Z39: =SUM(J39:Y39) -> 8094 | AA39: 9758 | AB39: 780.64 | AC39: 195.16 | AD39: 48.79 | AE39: 9758 | AF39: 683 | AG39: =AB39+AC39+AD39+AF39 -> 1707.59 | AK39: =Z39-AG39-AH39 -> 6386.41 | AL39: 9758 | AM39: 9758 | AN39: =ROUND(AL39*16%,2) -> 1561.28 | AO39: =ROUND(AL39*9%,2) -> 878.22 | AP39: =ROUND(AL39*0.5%,2) -> 48.79 | AQ39: =ROUND(AL39*0.256%,2) -> 24.98 | AS39: =ROUND(AM39*7%,0) -> 683 | AT39: =ROUND(IF(AL39<24366,AL39*1.5%,24366*1.5%),2) -> 146.37 | AU39: =SUM(AN39:AT39) -> 3342.64 | AW39: =AU39+Z39+AI39-AJ39+AV39 -> 11436.64 | AZ39: 60 | BA39: =ROUND(AW39+AZ39+AX39,2) -> 11496.64 | BB39: =ROUND(BA39*6%,2) -> 689.8 | BC39: =ROUND(SUM(BA39:BB39),2) -> 12186.44
A42: 纵向团队合计 | Z42: =SUBTOTAL(9,Z3:Z16) -> 141829.25 | AG42: =SUBTOTAL(9,AG3:AG16) -> 24133.91 | AK42: =SUBTOTAL(9,AK3:AK16) -> 117695.34 | AU42: =SUBTOTAL(9,AU3:AU16) -> 47467.75 | AV42: =SUBTOTAL(9,AV3:AV16) -> 0 | AW42: =SUBTOTAL(9,AW3:AW16) -> 189297 | AX42: =SUBTOTAL(9,AX3:AX16) -> 0 | AZ42: =SUBTOTAL(9,AZ3:AZ16) -> 3570 | BA42: =SUBTOTAL(9,BA3:BA16) -> 192867 | BB42: =SUBTOTAL(9,BB3:BB16) -> 11572.02 | BC42: =SUBTOTAL(9,BC3:BC16) -> 204439.02
...

Sheet 对账单
A1: 科目 | B1: 手工账单 | C1: 7月速创账单 | D1: 155 | E1: 系统已有金额（不做一次性） | F1: 9月少收，10月补收 | G1: 10月垫付，11月补收 | H1: 合计 | I1: 差异
A2: 管理费 | B2: ='202410'!BB44 -> 29647.1 | C2: =系统!E53 -> 32947.15 | D2: =36*155+0.09 -> 5580.09 | H2: =SUM(C2:G2) -> 38527.24 | I2: =B2-C2 -> -3300.05
A3: 风险费 | B3: ='202410'!AZ44 -> 9240 | C3: 0 | F3: ='202410'!AX31+'202410'!AX23 -> 1009.24 | G3: ='202410'!AX27 -> -591.62 | H3: =SUM(C3:G3) -> 417.62 | I3: =B3-C3 -> 9240 | K3: 1009.24
A4: 个人四金 | B4: ='202410'!AG44 -> 58118.47 | C4: =系统!V53 -> 58118.47 | H4: =SUM(C4:G4) -> 58118.47 | I4: =B4-C4 -> 0
A5: 公司四金 | B5: ='202410'!AU44 -> 115568.43 | C5: =系统!O53 -> 115568.43 | H5: =SUM(C5:G5) -> 115568.43 | I5: =B5-C5 -> 0
A6: 残保金 | H6: =SUM(C6:G6) -> 0 | I6: =B6-C6 -> 0
A7: 代发工资 | B7: ='202410'!AK44 -> 310773.55 | C7: =系统!W53 -> 310773.55 | H7: =SUM(C7:G7) -> 310773.55 | I7: =B7-C7 -> 0
A8: 上月垫付 | H8: =SUM(C8:G8) -> 0 | I8: =B8-C8 -> 0
A9: 上月垫付本月收 | B9: ='202410'!AX44 -> 417.62 | H9: =SUM(C9:G9) -> 0 | I9: =B9-C9 -> 417.62
A10: 预收（做预收一次性） | H10: =SUM(C10:G10) -> 0 | I10: =B10-C10 -> 0
A11: 小计 | B11: =SUM(B2:B10) -> 523765.17 | C11: =SUM(C2:C10) -> 517407.6 | D11: =SUM(D2:D10) -> 5580.09 | E11: =SUM(E2:E10) -> 0 | F11: =SUM(F2:F10) -> 1009.24 | G11: =SUM(G2:G10) -> -591.62 | H11: =SUM(C11:G11) -> 523405.31
A12: 附加税 | D12: 0
A13: 增值税 | D13: =ROUND((D11+D12)*6%,2) -> 334.81 | E13: =ROUND((E11+E12)*6%,2) -> 0 | F13: =ROUND((F11+F12)*6%,2) -> 60.55 | G13: =ROUND((G11+G12)*6%,2) -> -35.5 | H13: =SUM(C13:G13) -> 359.86 | I13: =D2+F3+G3 -> 5997.71
A14: 总计 | B14: =SUM(B11:B13) -> 523765.17 | C14: =SUM(C11:C13) -> 517407.6 | D14: =SUM(D11:D13) -> 5914.9 | E14: =SUM(E11:E13) -> 0 | F14: =SUM(F11:F13) -> 1069.79 | G14: =SUM(G11:G13) -> -627.12 | H14: =SUM(C14:G14) -> 523765.17
A15: 给客户账单金额 | H15: =B14 -> 523765.17
A16: 差异 | H16: =H15-H14 -> 0
A17: 不含税差异 | H17: =ROUND(H16/1.06,2) -> 0

Sheet 系统
A1: 200070
A2: 寄：梅园路77号人才大厦
B3: 中国电信股份有限公司上海分公司 王慧珏 收
D6: 上海外服布列吉科技有限公司
C7: Shanghai Foreign Service Bridge Technology Co,Ltd.
E9: 收款通知书
E10: ADVISE ON COLLECTION
E11: 2024年10月
A13: 公司名称：中国电信股份有限公司上海分公司 | J13: 帐单号：202410CH6593506
A14: 序号 | B14: 姓名 | C14: 发生年月 | D14: 入职日期 | E14: 管理费 | F14: 当月社保基数 | G14: 当月公积金基数 | H14: 社保类 公司支付 Social Insurance Premiums Paid by Employer | N14: 公积金类 公司支付 Provident Fund Paid by Employer | O14: 公司合计 | P14: 社保类 个人支付 Social Insurance Premiums Paid by Employee | U14: 公积金类 个人支付 Provident Fund Paid by Employee | V14: 个人合计 | W14: 代办薪酬 | X14: 其他 | Y14: 总计 | Z14: 备注 | AA14: 外服工号 | AB14: 证件号码 | AC14: 应纳税金额 | AD14: 税率 | AE14: 增值税
A15: S/N | B15: Name | C15: YYYYMM | D15: Employment Start Date | E15: Adm Fee | F15: Social Insurance Base Amount of Current Month | G15: Provident Fund Base Amount of Current Month | H15: 养老保险 Endowment | I15: 医疗保险 Medical | J15: 失业保险 Unemploy-ment | K15: 工伤保险 Employment Injury | L15: 医疗生育保险 Medical Maternity | M15: 保障金 Disabled people&Back pay Fund | N15: 公积金 Provident Fund | O15: Subtotal of Employer Payment | P15: 养老保险 Endowment | Q15: 医疗保险 Medical | R15: 失业保险 Unemploy-ment | S15: 工伤保险 Employment Injury | T15: 医疗生育保险 Medical Maternity | U15: 公积金 Provident Fund | V15: Subtotal of Personal Payment | W15: Agency of Wage Payment | X15: Others | Y15: Total | Z15: Remarks | AA15: SFSC ID | AB15: ID Card | AC15: Taxable Amount | AD15: Tax Rate | AE15: VAT
A16: 1 | B16: 陈云 | C16: 202410 | D16: 2024-06-01 | E16: 946.82 | F16: 11367 | G16: 11367 | H16: 1818.72 | I16: 1023.04 | J16: 56.84 | K16: 29.1 | M16: 170.51 | N16: 796 | O16: =SUM(H16:N16) -> 3894.21 | P16: 909.36 | Q16: 227.34 | R16: 56.84 | U16: 796 | V16: =SUM(P16:U16) -> 1989.54 | W16: 8129.76 | Y16: =SUM(E16,O16,V16:X16) -> 14960.33 | AA16: 5545723 | AB16: 320681198911257029 | AC16: 14113.52 | AD16: 6% | AE16: 846.81
A17: 2 | B17: 成瀛 | C17: 202410 | D17: 2024-06-01 | E17: 699.77 | F17: 7384 | G17: 5131 | H17: 1181.44 | I17: 664.56 | J17: 36.92 | K17: 18.9 | M17: 110.76 | N17: 359 | O17: =SUM(H17:N17) -> 2371.58 | P17: 590.72 | Q17: 147.68 | R17: 36.92 | U17: 359 | V17: =SUM(P17:U17) -> 1134.32 | W17: 6390.28 | Y17: =SUM(E17,O17,V17:X17) -> 10595.95 | AA17: 5756133 | AB17: 140103198304204830 | AC17: 9996.17 | AD17: 6% | AE17: 599.78
A18: 3 | B18: 龚林花 | C18: 202410 | D18: 2024-06-01 | E18: 911.68 | F18: 7963 | G18: 7963 | H18: 1274.08 | I18: 716.68 | J18: 39.82 | K18: 20.39 | M18: 119.45 | N18: 557 | O18: =SUM(H18:N18) -> 2727.42 | P18: 637.04 | Q18: 159.26 | R18: 39.82 | U18: 557 | V18: =SUM(P18:U18) -> 1393.12 | W18: 9307.58 | Y18: =SUM(E18,O18,V18:X18) -> 14339.8 | AA18: 5545720 | AB18: 310230198502244987 | AC18: 13528.12 | AD18: 6% | AE18: 811.68
A19: 4 | B19: 顾文君 | C19: 202410 | D19: 2024-06-01 | E19: 1203.37 | F19: 13189 | G19: 13189 | H19: 2110.24 | I19: 1187.02 | J19: 65.95 | K19: 33.76 | M19: 197.84 | N19: 923 | O19: =SUM(H19:N19) -> 4517.81 | P19: 1055.12 | Q19: 263.78 | R19: 65.95 | U19: 923 | V19: =SUM(P19:U19) -> 2307.85 | W19: 11463.9 | Y19: =SUM(E19,O19,V19:X19) -> 19492.93 | AA19: 5545704 | AB19: 310110198605095645 | AC19: 18389.55 | AD19: 6% | AE19: 1103.38
A20: 5 | B20: 顾燕 | C20: 202410 | D20: 2024-06-01 | E20: 963.53 | F20: 10363 | G20: 10363 | H20: 1658.08 | I20: 932.68 | J20: 51.82 | K20: 26.53 | M20: 155.45 | N20: 725 | O20: =SUM(H20:N20) -> 3549.56 | P20: 829.04 | Q20: 207.26 | R20: 51.82 | U20: 725 | V20: =SUM(P20:U20) -> 1813.12 | W20: 8929.58 | Y20: =SUM(E20,O20,V20:X20) -> 15255.79 | AA20: 5545718 | AB20: 310113198111034825 | AC20: 14392.26 | AD20: 6% | AE20: 863.53
A21: 6 | B21: 金霞 | C21: 202410 | D21: 2024-06-01 | E21: 652.7 | F21: 7384 | G21: 7287 | H21: 1181.44 | I21: 664.56 | J21: 36.92 | K21: 18.9 | M21: 110.76 | N21: 510 | O21: =SUM(H21:N21) -> 2522.58 | P21: 590.72 | Q21: 147.68 | R21: 36.92 | U21: 510 | V21: =SUM(P21:U21) -> 1285.32 | W21: 5303.78 | Y21: =SUM(E21,O21,V21:X21) -> 9764.38 | AA21: 5545705 | AB21: 310113198309114628 | AC21: 9211.67 | AD21: 6% | AE21: 552.71
A22: 7 | B22: 李娟 | C22: 202410 | D22: 2024-06-01 | E22: 762.52 | F22: 10038 | G22: 10038 | H22: 1606.08 | I22: 903.42 | J22: 50.19 | K22: 25.7 | M22: 150.57 | N22: 703 | O22: =SUM(H22:N22) -> 3438.96 | P22: 803.04 | Q22: 200.76 | R22: 50.19 | U22: 703 | V22: =SUM(P22:U22) -> 1756.99 | W22: 5746.01 | Y22: =SUM(E22,O22,V22:X22) -> 11704.48 | AA22: 5545725 | AB22: 310230197802072529 | AC22: 11041.97 | AD22: 6% | AE22: 662.51
A23: 8 | B23: 林峰 | C23: 202410 | D23: 2024-06-01 | E23: 638.95 | F23: 7546 | G23: 7546 | H23: 1207.36 | I23: 679.14 | J23: 37.73 | K23: 19.32 | M23: 113.19 | N23: 528 | O23: =SUM(H23:N23) -> 2584.74 | P23: 603.68 | Q23: 150.92 | R23: 37.73 | U23: 528 | V23: =SUM(P23:U23) -> 1320.33 | W23: 4977.57 | Y23: =SUM(E23,O23,V23:X23) -> 9521.59 | AA23: 5572476 | AB23: 320681199806210215 | AC23: 8982.64 | AD23: 6% | AE23: 538.95
A24: 9 | B24: 陆燕 | C24: 202410 | D24: 2024-06-01 | E24: 1749.08 | F24: 7384 | G24: 6844 | H24: 1181.44 | I24: 664.56 | J24: 36.92 | K24: 18.9 | M24: 110.76 | N24: 479 | O24: =SUM(H24:N24) -> 2491.58 | P24: 590.72 | Q24: 147.68 | R24: 36.92 | U24: 479 | V24: =SUM(P24:U24) -> 1254.32 | W24: 23638.88 | Y24: =SUM(E24,O24,V24:X24) -> 29133.86 | AA24: 5756132 | AB24: 310113197802064324 | AC24: 27484.77 | AD24: 6% | AE24: 1649.09
A25: 10 | B25: 茅柳 | C25: 202410 | D25: 2024-06-01 | E25: 649.4 | F25: 7594 | G25: 7594 | H25: 1215.04 | I25: 683.46 | J25: 37.97 | K25: 19.44 | M25: 113.91 | N25: 532 | O25: =SUM(H25:N25) -> 2601.82 | P25: 607.52 | Q25: 151.88 | R25: 37.97 | U25: 532 | V25: =SUM(P25:U25) -> 1329.37 | W25: 5125.53 | Y25: =SUM(E25,O25,V25:X25) -> 9706.12 | AA25: 5572477 | AB25: 310230198208264565 | AC25: 9156.72 | AD25: 6% | AE25: 549.4
A26: 11 | B26: 钱善晖 | C26: 202410 | D26: 2024-05-01 | E26: 889.34 | F26: 7788 | G26: 7788 | H26: 1246.08 | I26: 700.92 | J26: 38.94 | K26: 19.94 | M26: 116.82 | N26: 545 | O26: =SUM(H26:N26) -> 2667.7 | P26: 623.04 | Q26: 155.76 | R26: 38.94 | U26: 545 | V26: =SUM(P26:U26) -> 1362.74 | W26: 9025.11 | Y26: =SUM(E26,O26,V26:X26) -> 13944.89 | AA26: 6011055 | AB26: 341127198508043038 | AC26: 13155.54 | AD26: 6% | AE26: 789.35
A27: 12 | B27: 沙玉莲 | C27: 202410 | D27: 2024-06-01 | E27: 1136.01 | F27: 11264 | G27: 11264 | H27: 1802.24 | I27: 1013.76 | J27: 56.32 | K27: 28.84 | M27: 168.96 | N27: 788 | O27: =SUM(H27:N27) -> 3858.12 | P27: 901.12 | Q27: 225.28 | R27: 56.32 | U27: 788 | V27: =SUM(P27:U27) -> 1970.72 | W27: 11338.08 | Y27: =SUM(E27,O27,V27:X27) -> 18302.93 | AA27: 5572479 | AB27: 320681198001296045 | AC27: 17266.91 | AD27: 6% | AE27: 1036.02
... A52: 37 | B52: 朱焱炎 | C52: 202410 | D52: 2024-06-01 | E52: 536.73 | F52: 7384 | G52: 4997 | H52: 1181.44 | I52: 664.56 | J52: 36.92 | K52: 18.9 | M52: 110.76 | N52: 350 | O52: =SUM(H52:N52) -> 2362.58 | P52: 590.72 | Q52: 147.68 | R52: 36.92 | U52: 350 | V52: =SUM(P52:U52) -> 1125.32 | W52: 3691 | Y52: =SUM(E52,O52,V52:X52) -> 7715.63 | AA52: 5545716 | AB52: 320681198812140829 | AC52: 7278.89 | AD52: 6% | AE52: 436.74
A53: 合计（RMB） | E53: =SUM(E16:E52) -> 32947.15 | H53: =SUM(H16:H52) -> 54857.76 | I53: =SUM(I16:I52) -> 30857.62 | J53: =SUM(J16:J52) -> 1714.37 | K53: =SUM(K16:K52) -> 877.7 | L53: =SUM(L16:L52) -> 0 | M53: =SUM(M16:M52) -> 5142.98 | N53: =SUM(N16:N52) -> 22118 | O53: =SUM(O16:O52) -> 115568.43 | ... Y53: =SUM(Y16:Y52) -> 517407.6 | AC53: =SUM(AC16:AC52) -> 488120.23 | AE53: =SUM(AE16:AE52) -> 29287.37
A54: 总计（RMB）已包含历月补收人民币伍拾壹万柒仟肆佰零柒圆陆角整 | Y54: 517407.6
A56: 其他费用
A57: 序号 | B57: 发生年月 | C57: 费用项目 | D57: 金额 | E57: 备注 | F57: 应纳税金额 | G57: 税率 | H57: 增值税
A58: S/N | B58: YYYYMM | C58: Item | D58: Amount | E58: Remarks | F58: Taxable Amount | G58: Tax Rate | H58: VAT
A59: 1 | B59: 202410 | C59: 税差调整6% | D59: 0 | F59: 0.15 | G59: 0.06 | H59: -0.15
A60: 合计（RMB） | D60: =SUM(D59:D59) -> 0 | F60: =SUM(F59:F59) -> 0.15 | H60: =SUM(H59:H59) -> -0.15
A61: 总计（RMB）人民币零 | D61: 0 | F61: 0.15 | H61: -0.15
A63: 增值税：
A64: 序号 S/N | B64: 应纳税额 | C64: 税率 | D64: 税金
A66: 1 | B66: 488120.38 | C66: 6% | D66: 29287.22
A67: 小计（RMB） | B67: 488120.38 | D67: 29287.22
A68: 总计(RMB) | D68: 29287.22
A69: 本次价税合计(RMB):人民币伍拾壹万柒仟肆佰零柒圆陆角整
A70: 517407.6
A71: 本月价税合计（RMB）：517407.60 其中已开票517407.60
...
